I0828 10:49:57.084266       1 flags.go:27] FLAG: --address=""
I0828 10:49:57.084399       1 flags.go:27] FLAG: --algorithm-provider=""
I0828 10:49:57.084406       1 flags.go:27] FLAG: --alsologtostderr="false"
I0828 10:49:57.084413       1 flags.go:27] FLAG: --config=""
I0828 10:49:57.084417       1 flags.go:27] FLAG: --contention-profiling="false"
I0828 10:49:57.084422       1 flags.go:27] FLAG: --failure-domains="kubernetes.io/hostname,failure-domain.beta.kubernetes.io/zone,failure-domain.beta.kubernetes.io/region"
I0828 10:49:57.084433       1 flags.go:27] FLAG: --feature-gates=""
I0828 10:49:57.084440       1 flags.go:27] FLAG: --hard-pod-affinity-symmetric-weight="1"
I0828 10:49:57.084447       1 flags.go:27] FLAG: --help="false"
I0828 10:49:57.084451       1 flags.go:27] FLAG: --kube-api-burst="100"
I0828 10:49:57.084455       1 flags.go:27] FLAG: --kube-api-content-type="application/vnd.kubernetes.protobuf"
I0828 10:49:57.084459       1 flags.go:27] FLAG: --kube-api-qps="50"
I0828 10:49:57.084466       1 flags.go:27] FLAG: --kubeconfig="/etc/srv/kubernetes/kube-scheduler/kubeconfig"
I0828 10:49:57.084471       1 flags.go:27] FLAG: --leader-elect="true"
I0828 10:49:57.084474       1 flags.go:27] FLAG: --leader-elect-lease-duration="15s"
I0828 10:49:57.084480       1 flags.go:27] FLAG: --leader-elect-renew-deadline="10s"
I0828 10:49:57.084484       1 flags.go:27] FLAG: --leader-elect-resource-lock="endpoints"
I0828 10:49:57.084488       1 flags.go:27] FLAG: --leader-elect-retry-period="2s"
I0828 10:49:57.084492       1 flags.go:27] FLAG: --lock-object-name="kube-scheduler"
I0828 10:49:57.084496       1 flags.go:27] FLAG: --lock-object-namespace="kube-system"
I0828 10:49:57.084500       1 flags.go:27] FLAG: --log-backtrace-at=":0"
I0828 10:49:57.084506       1 flags.go:27] FLAG: --log-dir=""
I0828 10:49:57.084510       1 flags.go:27] FLAG: --log-flush-frequency="5s"
I0828 10:49:57.084514       1 flags.go:27] FLAG: --logtostderr="true"
I0828 10:49:57.084533       1 flags.go:27] FLAG: --master=""
I0828 10:49:57.084537       1 flags.go:27] FLAG: --policy-config-file=""
I0828 10:49:57.084540       1 flags.go:27] FLAG: --policy-configmap=""
I0828 10:49:57.084544       1 flags.go:27] FLAG: --policy-configmap-namespace=""
I0828 10:49:57.084548       1 flags.go:27] FLAG: --port="10251"
I0828 10:49:57.084552       1 flags.go:27] FLAG: --profiling="false"
I0828 10:49:57.084555       1 flags.go:27] FLAG: --scheduler-name="default-scheduler"
I0828 10:49:57.084560       1 flags.go:27] FLAG: --stderrthreshold="2"
I0828 10:49:57.084563       1 flags.go:27] FLAG: --use-legacy-policy-config="false"
I0828 10:49:57.084567       1 flags.go:27] FLAG: --v="2"
I0828 10:49:57.084571       1 flags.go:27] FLAG: --version="false"
I0828 10:49:57.084577       1 flags.go:27] FLAG: --vmodule=""
W0828 10:49:57.084588       1 server.go:163] WARNING: all flags other than --config are deprecated. Please begin using a config file ASAP.
I0828 10:49:57.087209       1 server.go:555] Version: v1.10.4
I0828 10:49:57.087410       1 factory.go:922] Creating scheduler from algorithm provider 'DefaultProvider'
I0828 10:49:57.087437       1 factory.go:1022] Creating scheduler with fit predicates 'map[MaxEBSVolumeCount:{} MaxAzureDiskVolumeCount:{} MatchInterPodAffinity:{} GeneralPredicates:{} CheckVolumeBinding:{} NoVolumeZoneConflict:{} MaxGCEPDVolumeCount:{} NoDiskConflict:{} CheckNodeMemoryPressure:{} CheckNodeDiskPressure:{} CheckNodeCondition:{} PodToleratesNodeTaints:{}]' and priority functions 'map[SelectorSpreadPriority:{} InterPodAffinityPriority:{} LeastRequestedPriority:{} BalancedResourceAllocation:{} NodePreferAvoidPodsPriority:{} NodeAffinityPriority:{} TaintTolerationPriority:{}]'
I0828 10:49:57.087933       1 server.go:574] starting healthz server on 0.0.0.0:10251
I0828 10:49:57.989117       1 controller_utils.go:1019] Waiting for caches to sync for scheduler controller
I0828 10:49:58.089398       1 controller_utils.go:1026] Caches are synced for scheduler controller
I0828 10:49:58.089453       1 leaderelection.go:175] attempting to acquire leader lease  kube-system/kube-scheduler...
I0828 10:49:58.094284       1 leaderelection.go:184] successfully acquired lease kube-system/kube-scheduler
I0828 10:50:14.754476       1 scheduler.go:451] ScheduleAlgoTime 3.647596ms Start:2018-08-28 10:50:14.750796052 +0000 UTC m=+17.716905632 End:2018-08-28 10:50:14.754443632 +0000 UTC m=+17.720553228
I0828 10:50:14.754654       1 scheduler.go:454] Total Schedule Algo cumulative time:3.647596ms for 1
I0828 10:50:14.758983       1 scheduler.go:451] ScheduleAlgoTime 3.405199ms Start:2018-08-28 10:50:14.755569569 +0000 UTC m=+17.721679140 End:2018-08-28 10:50:14.758974854 +0000 UTC m=+17.725084339
I0828 10:50:14.759021       1 scheduler.go:454] Total Schedule Algo cumulative time:7.052795ms for 2
I0828 10:50:14.761626       1 scheduler.go:451] ScheduleAlgoTime 2.377373ms Start:2018-08-28 10:50:14.759242486 +0000 UTC m=+17.725351985 End:2018-08-28 10:50:14.761619872 +0000 UTC m=+17.727729358
I0828 10:50:14.761652       1 scheduler.go:454] Total Schedule Algo cumulative time:9.430168ms for 3
I0828 10:50:14.765909       1 scheduler.go:451] ScheduleAlgoTime 4.158446ms Start:2018-08-28 10:50:14.761739976 +0000 UTC m=+17.727849535 End:2018-08-28 10:50:14.765898294 +0000 UTC m=+17.732007981
I0828 10:50:14.765973       1 scheduler.go:454] Total Schedule Algo cumulative time:13.588614ms for 4
I0828 10:50:14.768771       1 scheduler.go:451] ScheduleAlgoTime 2.451749ms Start:2018-08-28 10:50:14.766310757 +0000 UTC m=+17.732420270 End:2018-08-28 10:50:14.768762518 +0000 UTC m=+17.734872019
I0828 10:50:14.768805       1 scheduler.go:454] Total Schedule Algo cumulative time:16.040363ms for 5
I0828 10:50:14.771470       1 scheduler.go:451] ScheduleAlgoTime 2.398974ms Start:2018-08-28 10:50:14.769066007 +0000 UTC m=+17.735175511 End:2018-08-28 10:50:14.771465003 +0000 UTC m=+17.737574485
I0828 10:50:14.771502       1 scheduler.go:454] Total Schedule Algo cumulative time:18.439337ms for 6
I0828 10:50:14.773877       1 scheduler.go:451] ScheduleAlgoTime 2.261094ms Start:2018-08-28 10:50:14.771608994 +0000 UTC m=+17.737718571 End:2018-08-28 10:50:14.773870187 +0000 UTC m=+17.739979665
I0828 10:50:14.773907       1 scheduler.go:454] Total Schedule Algo cumulative time:20.700431ms for 7
I0828 10:50:14.776230       1 scheduler.go:451] ScheduleAlgoTime 2.141999ms Start:2018-08-28 10:50:14.774079948 +0000 UTC m=+17.740189472 End:2018-08-28 10:50:14.776221981 +0000 UTC m=+17.742331471
I0828 10:50:14.776266       1 scheduler.go:454] Total Schedule Algo cumulative time:22.84243ms for 8
I0828 10:50:14.778638       1 scheduler.go:451] ScheduleAlgoTime 2.210377ms Start:2018-08-28 10:50:14.776422416 +0000 UTC m=+17.742531922 End:2018-08-28 10:50:14.778632818 +0000 UTC m=+17.744742299
I0828 10:50:14.778663       1 scheduler.go:454] Total Schedule Algo cumulative time:25.052807ms for 9
I0828 10:50:14.780474       1 scheduler.go:451] ScheduleAlgoTime 1.66691ms Start:2018-08-28 10:50:14.778799035 +0000 UTC m=+17.744908534 End:2018-08-28 10:50:14.780465837 +0000 UTC m=+17.746575444
I0828 10:50:14.780509       1 scheduler.go:454] Total Schedule Algo cumulative time:26.719717ms for 10
I0828 10:50:14.785655       1 scheduler.go:451] ScheduleAlgoTime 5.055276ms Start:2018-08-28 10:50:14.780589202 +0000 UTC m=+17.746698707 End:2018-08-28 10:50:14.785644502 +0000 UTC m=+17.751753983
I0828 10:50:14.785721       1 scheduler.go:454] Total Schedule Algo cumulative time:31.774993ms for 11
I0828 10:50:14.790747       1 scheduler.go:451] ScheduleAlgoTime 4.848105ms Start:2018-08-28 10:50:14.785891571 +0000 UTC m=+17.752001103 End:2018-08-28 10:50:14.790739728 +0000 UTC m=+17.756849208
I0828 10:50:14.790800       1 scheduler.go:454] Total Schedule Algo cumulative time:36.623098ms for 12
I0828 10:50:14.792784       1 scheduler.go:451] ScheduleAlgoTime 1.870072ms Start:2018-08-28 10:50:14.790907545 +0000 UTC m=+17.757017129 End:2018-08-28 10:50:14.792777718 +0000 UTC m=+17.758887201
I0828 10:50:14.792820       1 scheduler.go:454] Total Schedule Algo cumulative time:38.49317ms for 13
I0828 10:50:14.795045       1 scheduler.go:451] ScheduleAlgoTime 2.074069ms Start:2018-08-28 10:50:14.792961896 +0000 UTC m=+17.759071464 End:2018-08-28 10:50:14.795035946 +0000 UTC m=+17.761145533
I0828 10:50:14.795093       1 scheduler.go:454] Total Schedule Algo cumulative time:40.567239ms for 14
I0828 10:50:14.798745       1 scheduler.go:451] ScheduleAlgoTime 2.56922ms Start:2018-08-28 10:50:14.796168646 +0000 UTC m=+17.762278165 End:2018-08-28 10:50:14.798737906 +0000 UTC m=+17.764847385
I0828 10:50:14.798775       1 scheduler.go:454] Total Schedule Algo cumulative time:43.136459ms for 15
I0828 10:50:14.801181       1 scheduler.go:451] ScheduleAlgoTime 2.315009ms Start:2018-08-28 10:50:14.798856134 +0000 UTC m=+17.764965647 End:2018-08-28 10:50:14.80117116 +0000 UTC m=+17.767280656
I0828 10:50:14.801213       1 scheduler.go:454] Total Schedule Algo cumulative time:45.451468ms for 16
I0828 10:50:14.803631       1 scheduler.go:451] ScheduleAlgoTime 2.224818ms Start:2018-08-28 10:50:14.801401022 +0000 UTC m=+17.767510526 End:2018-08-28 10:50:14.803625861 +0000 UTC m=+17.769735344
I0828 10:50:14.803661       1 scheduler.go:454] Total Schedule Algo cumulative time:47.676286ms for 17
I0828 10:50:14.805428       1 scheduler.go:451] ScheduleAlgoTime 1.575132ms Start:2018-08-28 10:50:14.803847784 +0000 UTC m=+17.769957281 End:2018-08-28 10:50:14.805422931 +0000 UTC m=+17.771532413
I0828 10:50:14.805449       1 scheduler.go:454] Total Schedule Algo cumulative time:49.251418ms for 18
I0828 10:50:14.808355       1 scheduler.go:451] ScheduleAlgoTime 2.805819ms Start:2018-08-28 10:50:14.805542586 +0000 UTC m=+17.771652137 End:2018-08-28 10:50:14.808348476 +0000 UTC m=+17.774457956
I0828 10:50:14.808390       1 scheduler.go:454] Total Schedule Algo cumulative time:52.057237ms for 19
I0828 10:50:14.810732       1 scheduler.go:451] ScheduleAlgoTime 2.240502ms Start:2018-08-28 10:50:14.808486383 +0000 UTC m=+17.774595905 End:2018-08-28 10:50:14.810726924 +0000 UTC m=+17.776836407
I0828 10:50:14.810755       1 scheduler.go:454] Total Schedule Algo cumulative time:54.297739ms for 20
I0828 10:50:14.812608       1 scheduler.go:451] ScheduleAlgoTime 1.754043ms Start:2018-08-28 10:50:14.810847327 +0000 UTC m=+17.776956832 End:2018-08-28 10:50:14.812601394 +0000 UTC m=+17.778710875
I0828 10:50:14.812650       1 scheduler.go:454] Total Schedule Algo cumulative time:56.051782ms for 21
I0828 10:50:14.815548       1 scheduler.go:451] ScheduleAlgoTime 2.02332ms Start:2018-08-28 10:50:14.813518485 +0000 UTC m=+17.779627985 End:2018-08-28 10:50:14.815541824 +0000 UTC m=+17.781651305
I0828 10:50:14.815580       1 scheduler.go:454] Total Schedule Algo cumulative time:58.075102ms for 22
I0828 10:50:14.818180       1 scheduler.go:451] ScheduleAlgoTime 2.514593ms Start:2018-08-28 10:50:14.815653606 +0000 UTC m=+17.781763102 End:2018-08-28 10:50:14.818168111 +0000 UTC m=+17.784277695
I0828 10:50:14.818213       1 scheduler.go:454] Total Schedule Algo cumulative time:60.589695ms for 23
I0828 10:50:14.826617       1 scheduler.go:451] ScheduleAlgoTime 8.259769ms Start:2018-08-28 10:50:14.818341952 +0000 UTC m=+17.784451451 End:2018-08-28 10:50:14.826601343 +0000 UTC m=+17.792711220
I0828 10:50:14.826663       1 scheduler.go:454] Total Schedule Algo cumulative time:68.849464ms for 24
I0828 10:50:14.828650       1 scheduler.go:451] ScheduleAlgoTime 1.832849ms Start:2018-08-28 10:50:14.82680093 +0000 UTC m=+17.792910455 End:2018-08-28 10:50:14.828633817 +0000 UTC m=+17.794743304
I0828 10:50:14.828677       1 scheduler.go:454] Total Schedule Algo cumulative time:70.682313ms for 25
I0828 10:50:14.830756       1 scheduler.go:451] ScheduleAlgoTime 1.942062ms Start:2018-08-28 10:50:14.828805701 +0000 UTC m=+17.794915262 End:2018-08-28 10:50:14.830747844 +0000 UTC m=+17.796857324
I0828 10:50:14.830793       1 scheduler.go:454] Total Schedule Algo cumulative time:72.624375ms for 26
I0828 10:50:14.833442       1 scheduler.go:451] ScheduleAlgoTime 2.553562ms Start:2018-08-28 10:50:14.830883076 +0000 UTC m=+17.796992623 End:2018-08-28 10:50:14.833436704 +0000 UTC m=+17.799546185
I0828 10:50:14.833470       1 scheduler.go:454] Total Schedule Algo cumulative time:75.177937ms for 27
I0828 10:50:14.835461       1 scheduler.go:451] ScheduleAlgoTime 1.685196ms Start:2018-08-28 10:50:14.833771684 +0000 UTC m=+17.799881225 End:2018-08-28 10:50:14.83545694 +0000 UTC m=+17.801566421
I0828 10:50:14.835483       1 scheduler.go:454] Total Schedule Algo cumulative time:76.863133ms for 28
I0828 10:50:14.837828       1 scheduler.go:451] ScheduleAlgoTime 2.221495ms Start:2018-08-28 10:50:14.835600076 +0000 UTC m=+17.801709608 End:2018-08-28 10:50:14.837821619 +0000 UTC m=+17.803931103
I0828 10:50:14.837853       1 scheduler.go:454] Total Schedule Algo cumulative time:79.084628ms for 29
I0828 10:50:14.840399       1 scheduler.go:451] ScheduleAlgoTime 2.440833ms Start:2018-08-28 10:50:14.837952494 +0000 UTC m=+17.804062008 End:2018-08-28 10:50:14.840393359 +0000 UTC m=+17.806502841
I0828 10:50:14.840423       1 scheduler.go:454] Total Schedule Algo cumulative time:81.525461ms for 30
I0828 10:50:14.842162       1 scheduler.go:451] ScheduleAlgoTime 1.628687ms Start:2018-08-28 10:50:14.84052838 +0000 UTC m=+17.806637885 End:2018-08-28 10:50:14.842157091 +0000 UTC m=+17.808266572
I0828 10:50:14.842199       1 scheduler.go:454] Total Schedule Algo cumulative time:83.154148ms for 31
I0828 10:50:14.844636       1 scheduler.go:451] ScheduleAlgoTime 2.265487ms Start:2018-08-28 10:50:14.842365112 +0000 UTC m=+17.808474616 End:2018-08-28 10:50:14.844630623 +0000 UTC m=+17.810740103
I0828 10:50:14.844671       1 scheduler.go:454] Total Schedule Algo cumulative time:85.419635ms for 32
I0828 10:50:14.846577       1 scheduler.go:451] ScheduleAlgoTime 1.820288ms Start:2018-08-28 10:50:14.844753063 +0000 UTC m=+17.810862561 End:2018-08-28 10:50:14.846573365 +0000 UTC m=+17.812682849
I0828 10:50:14.846600       1 scheduler.go:454] Total Schedule Algo cumulative time:87.239923ms for 33
I0828 10:50:14.848465       1 scheduler.go:451] ScheduleAlgoTime 1.781298ms Start:2018-08-28 10:50:14.846679248 +0000 UTC m=+17.812788838 End:2018-08-28 10:50:14.848460654 +0000 UTC m=+17.814570136
I0828 10:50:14.848489       1 scheduler.go:454] Total Schedule Algo cumulative time:89.021221ms for 34
I0828 10:50:14.851068       1 scheduler.go:451] ScheduleAlgoTime 2.508681ms Start:2018-08-28 10:50:14.848554028 +0000 UTC m=+17.814663524 End:2018-08-28 10:50:14.851062724 +0000 UTC m=+17.817172205
I0828 10:50:14.851089       1 scheduler.go:454] Total Schedule Algo cumulative time:91.529902ms for 35
I0828 10:50:14.853410       1 scheduler.go:451] ScheduleAlgoTime 2.249847ms Start:2018-08-28 10:50:14.851155668 +0000 UTC m=+17.817265281 End:2018-08-28 10:50:14.85340565 +0000 UTC m=+17.819515128
I0828 10:50:14.853430       1 scheduler.go:454] Total Schedule Algo cumulative time:93.779749ms for 36
I0828 10:50:14.858259       1 scheduler.go:451] ScheduleAlgoTime 4.769237ms Start:2018-08-28 10:50:14.853483949 +0000 UTC m=+17.819593443 End:2018-08-28 10:50:14.858253195 +0000 UTC m=+17.824362680
I0828 10:50:14.858284       1 scheduler.go:454] Total Schedule Algo cumulative time:98.548986ms for 37
I0828 10:50:14.861917       1 scheduler.go:451] ScheduleAlgoTime 3.520366ms Start:2018-08-28 10:50:14.858386519 +0000 UTC m=+17.824496034 End:2018-08-28 10:50:14.86190692 +0000 UTC m=+17.828016400
I0828 10:50:14.861951       1 scheduler.go:454] Total Schedule Algo cumulative time:102.069352ms for 38
I0828 10:50:14.864366       1 scheduler.go:451] ScheduleAlgoTime 2.261447ms Start:2018-08-28 10:50:14.862099156 +0000 UTC m=+17.828208704 End:2018-08-28 10:50:14.864360667 +0000 UTC m=+17.830470151
I0828 10:50:14.864394       1 scheduler.go:454] Total Schedule Algo cumulative time:104.330799ms for 39
I0828 10:50:14.866531       1 scheduler.go:451] ScheduleAlgoTime 2.004861ms Start:2018-08-28 10:50:14.864516403 +0000 UTC m=+17.830625934 End:2018-08-28 10:50:14.866521314 +0000 UTC m=+17.832630795
I0828 10:50:14.866566       1 scheduler.go:454] Total Schedule Algo cumulative time:106.33566ms for 40
I0828 10:50:14.869642       1 scheduler.go:451] ScheduleAlgoTime 2.961878ms Start:2018-08-28 10:50:14.866672926 +0000 UTC m=+17.832782500 End:2018-08-28 10:50:14.869634899 +0000 UTC m=+17.835744378
I0828 10:50:14.869675       1 scheduler.go:454] Total Schedule Algo cumulative time:109.297538ms for 41
I0828 10:50:14.872556       1 scheduler.go:451] ScheduleAlgoTime 2.721408ms Start:2018-08-28 10:50:14.869828387 +0000 UTC m=+17.835937933 End:2018-08-28 10:50:14.872549854 +0000 UTC m=+17.838659341
I0828 10:50:14.872580       1 scheduler.go:454] Total Schedule Algo cumulative time:112.018946ms for 42
I0828 10:50:14.882800       1 scheduler.go:451] ScheduleAlgoTime 10.099134ms Start:2018-08-28 10:50:14.872685009 +0000 UTC m=+17.838794510 End:2018-08-28 10:50:14.88278415 +0000 UTC m=+17.848893644
I0828 10:50:14.882854       1 scheduler.go:454] Total Schedule Algo cumulative time:122.11808ms for 43
I0828 10:50:14.890435       1 scheduler.go:451] ScheduleAlgoTime 7.474653ms Start:2018-08-28 10:50:14.882952456 +0000 UTC m=+17.849061936 End:2018-08-28 10:50:14.890427104 +0000 UTC m=+17.856536589
I0828 10:50:14.890467       1 scheduler.go:454] Total Schedule Algo cumulative time:129.592733ms for 44
I0828 10:50:14.894130       1 scheduler.go:451] ScheduleAlgoTime 1.860175ms Start:2018-08-28 10:50:14.892261671 +0000 UTC m=+17.858371214 End:2018-08-28 10:50:14.894121909 +0000 UTC m=+17.860231389
I0828 10:50:14.894177       1 scheduler.go:454] Total Schedule Algo cumulative time:131.452908ms for 45
I0828 10:50:14.898816       1 scheduler.go:451] ScheduleAlgoTime 4.430954ms Start:2018-08-28 10:50:14.89437508 +0000 UTC m=+17.860484657 End:2018-08-28 10:50:14.89880612 +0000 UTC m=+17.864915611
I0828 10:50:14.898851       1 scheduler.go:454] Total Schedule Algo cumulative time:135.883862ms for 46
I0828 10:50:14.900905       1 scheduler.go:451] ScheduleAlgoTime 1.913448ms Start:2018-08-28 10:50:14.898983459 +0000 UTC m=+17.865092984 End:2018-08-28 10:50:14.900896951 +0000 UTC m=+17.867006432
I0828 10:50:14.900932       1 scheduler.go:454] Total Schedule Algo cumulative time:137.79731ms for 47
I0828 10:50:14.903271       1 scheduler.go:451] ScheduleAlgoTime 2.211145ms Start:2018-08-28 10:50:14.901051035 +0000 UTC m=+17.867160561 End:2018-08-28 10:50:14.903262192 +0000 UTC m=+17.869371706
I0828 10:50:14.903317       1 scheduler.go:454] Total Schedule Algo cumulative time:140.008455ms for 48
I0828 10:50:14.905500       1 scheduler.go:451] ScheduleAlgoTime 2.064271ms Start:2018-08-28 10:50:14.903431083 +0000 UTC m=+17.869540596 End:2018-08-28 10:50:14.905495386 +0000 UTC m=+17.871604867
I0828 10:50:14.905525       1 scheduler.go:454] Total Schedule Algo cumulative time:142.072726ms for 49
I0828 10:50:14.907243       1 scheduler.go:451] ScheduleAlgoTime 1.567109ms Start:2018-08-28 10:50:14.905669138 +0000 UTC m=+17.871778675 End:2018-08-28 10:50:14.907236302 +0000 UTC m=+17.873345784
I0828 10:50:14.907278       1 scheduler.go:454] Total Schedule Algo cumulative time:143.639835ms for 50
I0828 10:50:14.909254       1 scheduler.go:451] ScheduleAlgoTime 1.861453ms Start:2018-08-28 10:50:14.907386347 +0000 UTC m=+17.873495893 End:2018-08-28 10:50:14.909247866 +0000 UTC m=+17.875357346
I0828 10:50:14.909282       1 scheduler.go:454] Total Schedule Algo cumulative time:145.501288ms for 51
I0828 10:50:14.913518       1 scheduler.go:451] ScheduleAlgoTime 4.010708ms Start:2018-08-28 10:50:14.909500932 +0000 UTC m=+17.875610428 End:2018-08-28 10:50:14.913511656 +0000 UTC m=+17.879621136
I0828 10:50:14.913557       1 scheduler.go:454] Total Schedule Algo cumulative time:149.511996ms for 52
I0828 10:50:14.917689       1 scheduler.go:451] ScheduleAlgoTime 3.622127ms Start:2018-08-28 10:50:14.914056845 +0000 UTC m=+17.880166405 End:2018-08-28 10:50:14.917679009 +0000 UTC m=+17.883788532
I0828 10:50:14.917722       1 scheduler.go:454] Total Schedule Algo cumulative time:153.134123ms for 53
I0828 10:50:14.920328       1 scheduler.go:451] ScheduleAlgoTime 2.270605ms Start:2018-08-28 10:50:14.918051337 +0000 UTC m=+17.884160858 End:2018-08-28 10:50:14.920321979 +0000 UTC m=+17.886431463
I0828 10:50:14.920357       1 scheduler.go:454] Total Schedule Algo cumulative time:155.404728ms for 54
I0828 10:50:14.922186       1 scheduler.go:451] ScheduleAlgoTime 1.652186ms Start:2018-08-28 10:50:14.920522185 +0000 UTC m=+17.886631683 End:2018-08-28 10:50:14.922173952 +0000 UTC m=+17.888283869
I0828 10:50:14.922227       1 scheduler.go:454] Total Schedule Algo cumulative time:157.056914ms for 55
I0828 10:50:14.924466       1 scheduler.go:451] ScheduleAlgoTime 2.14789ms Start:2018-08-28 10:50:14.92231316 +0000 UTC m=+17.888422672 End:2018-08-28 10:50:14.924461081 +0000 UTC m=+17.890570562
I0828 10:50:14.924492       1 scheduler.go:454] Total Schedule Algo cumulative time:159.204804ms for 56
I0828 10:50:14.927049       1 scheduler.go:451] ScheduleAlgoTime 2.033126ms Start:2018-08-28 10:50:14.925007417 +0000 UTC m=+17.891117044 End:2018-08-28 10:50:14.927040584 +0000 UTC m=+17.893150170
I0828 10:50:14.927081       1 scheduler.go:454] Total Schedule Algo cumulative time:161.23793ms for 57
I0828 10:50:14.930226       1 scheduler.go:451] ScheduleAlgoTime 3.03379ms Start:2018-08-28 10:50:14.92718698 +0000 UTC m=+17.893296460 End:2018-08-28 10:50:14.930220769 +0000 UTC m=+17.896330250
I0828 10:50:14.930256       1 scheduler.go:454] Total Schedule Algo cumulative time:164.27172ms for 58
I0828 10:50:14.932768       1 scheduler.go:451] ScheduleAlgoTime 2.41893ms Start:2018-08-28 10:50:14.930343577 +0000 UTC m=+17.896453093 End:2018-08-28 10:50:14.932762542 +0000 UTC m=+17.898872023
I0828 10:50:14.932794       1 scheduler.go:454] Total Schedule Algo cumulative time:166.69065ms for 59
I0828 10:50:14.935297       1 scheduler.go:451] ScheduleAlgoTime 2.373918ms Start:2018-08-28 10:50:14.932918697 +0000 UTC m=+17.899028219 End:2018-08-28 10:50:14.935292654 +0000 UTC m=+17.901402137
I0828 10:50:14.935320       1 scheduler.go:454] Total Schedule Algo cumulative time:169.064568ms for 60
I0828 10:50:14.937900       1 scheduler.go:451] ScheduleAlgoTime 2.49797ms Start:2018-08-28 10:50:14.935397574 +0000 UTC m=+17.901507057 End:2018-08-28 10:50:14.937895547 +0000 UTC m=+17.904005027
I0828 10:50:14.937919       1 scheduler.go:454] Total Schedule Algo cumulative time:171.562538ms for 61
I0828 10:50:14.940262       1 scheduler.go:451] ScheduleAlgoTime 2.228708ms Start:2018-08-28 10:50:14.938029773 +0000 UTC m=+17.904139297 End:2018-08-28 10:50:14.940258525 +0000 UTC m=+17.906368005
I0828 10:50:14.940280       1 scheduler.go:454] Total Schedule Algo cumulative time:173.791246ms for 62
I0828 10:50:14.942523       1 scheduler.go:451] ScheduleAlgoTime 2.160122ms Start:2018-08-28 10:50:14.940358913 +0000 UTC m=+17.906468444 End:2018-08-28 10:50:14.942519087 +0000 UTC m=+17.908628566
I0828 10:50:14.942541       1 scheduler.go:454] Total Schedule Algo cumulative time:175.951368ms for 63
I0828 10:50:14.951917       1 scheduler.go:451] ScheduleAlgoTime 9.016499ms Start:2018-08-28 10:50:14.942892094 +0000 UTC m=+17.909001580 End:2018-08-28 10:50:14.951908598 +0000 UTC m=+17.918018079
I0828 10:50:14.951952       1 scheduler.go:454] Total Schedule Algo cumulative time:184.967867ms for 64
I0828 10:50:14.954325       1 scheduler.go:451] ScheduleAlgoTime 2.270661ms Start:2018-08-28 10:50:14.952049281 +0000 UTC m=+17.918158835 End:2018-08-28 10:50:14.954320009 +0000 UTC m=+17.920429496
I0828 10:50:14.954349       1 scheduler.go:454] Total Schedule Algo cumulative time:187.238528ms for 65
I0828 10:50:14.957652       1 scheduler.go:451] ScheduleAlgoTime 3.217805ms Start:2018-08-28 10:50:14.95442555 +0000 UTC m=+17.920535060 End:2018-08-28 10:50:14.957643382 +0000 UTC m=+17.923752865
I0828 10:50:14.957692       1 scheduler.go:454] Total Schedule Algo cumulative time:190.456333ms for 66
I0828 10:50:14.961634       1 scheduler.go:451] ScheduleAlgoTime 1.764913ms Start:2018-08-28 10:50:14.959863893 +0000 UTC m=+17.925973424 End:2018-08-28 10:50:14.961628857 +0000 UTC m=+17.927738337
I0828 10:50:14.961664       1 scheduler.go:454] Total Schedule Algo cumulative time:192.221246ms for 67
I0828 10:50:14.964172       1 scheduler.go:451] ScheduleAlgoTime 2.382214ms Start:2018-08-28 10:50:14.961783439 +0000 UTC m=+17.927892999 End:2018-08-28 10:50:14.964165734 +0000 UTC m=+17.930275213
I0828 10:50:14.964201       1 scheduler.go:454] Total Schedule Algo cumulative time:194.60346ms for 68
I0828 10:50:14.966768       1 scheduler.go:451] ScheduleAlgoTime 1.639636ms Start:2018-08-28 10:50:14.965123649 +0000 UTC m=+17.931233198 End:2018-08-28 10:50:14.966763353 +0000 UTC m=+17.932872834
I0828 10:50:14.966786       1 scheduler.go:454] Total Schedule Algo cumulative time:196.243096ms for 69
I0828 10:50:14.968635       1 scheduler.go:451] ScheduleAlgoTime 1.776422ms Start:2018-08-28 10:50:14.96685482 +0000 UTC m=+17.932964300 End:2018-08-28 10:50:14.968631243 +0000 UTC m=+17.934740722
I0828 10:50:14.968653       1 scheduler.go:454] Total Schedule Algo cumulative time:198.019518ms for 70
I0828 10:50:14.970575       1 scheduler.go:451] ScheduleAlgoTime 1.759658ms Start:2018-08-28 10:50:14.968810788 +0000 UTC m=+17.934920304 End:2018-08-28 10:50:14.970570482 +0000 UTC m=+17.936679962
I0828 10:50:14.970598       1 scheduler.go:454] Total Schedule Algo cumulative time:199.779176ms for 71
I0828 10:50:14.972934       1 scheduler.go:451] ScheduleAlgoTime 2.191478ms Start:2018-08-28 10:50:14.970733183 +0000 UTC m=+17.936842730 End:2018-08-28 10:50:14.972924333 +0000 UTC m=+17.939034208
I0828 10:50:14.972974       1 scheduler.go:454] Total Schedule Algo cumulative time:201.970654ms for 72
I0828 10:50:14.975894       1 scheduler.go:451] ScheduleAlgoTime 2.770373ms Start:2018-08-28 10:50:14.973117308 +0000 UTC m=+17.939226828 End:2018-08-28 10:50:14.975887719 +0000 UTC m=+17.941997201
I0828 10:50:14.975922       1 scheduler.go:454] Total Schedule Algo cumulative time:204.741027ms for 73
I0828 10:50:14.977812       1 scheduler.go:451] ScheduleAlgoTime 1.733437ms Start:2018-08-28 10:50:14.976073267 +0000 UTC m=+17.942182781 End:2018-08-28 10:50:14.977806737 +0000 UTC m=+17.943916218
I0828 10:50:14.977836       1 scheduler.go:454] Total Schedule Algo cumulative time:206.474464ms for 74
I0828 10:50:14.979603       1 scheduler.go:451] ScheduleAlgoTime 1.627422ms Start:2018-08-28 10:50:14.977971231 +0000 UTC m=+17.944080714 End:2018-08-28 10:50:14.979598655 +0000 UTC m=+17.945708136
I0828 10:50:14.979627       1 scheduler.go:454] Total Schedule Algo cumulative time:208.101886ms for 75
I0828 10:50:14.981842       1 scheduler.go:451] ScheduleAlgoTime 2.11299ms Start:2018-08-28 10:50:14.979722374 +0000 UTC m=+17.945831873 End:2018-08-28 10:50:14.981835382 +0000 UTC m=+17.947944863
I0828 10:50:14.981866       1 scheduler.go:454] Total Schedule Algo cumulative time:210.214876ms for 76
I0828 10:50:14.983959       1 scheduler.go:451] ScheduleAlgoTime 1.992287ms Start:2018-08-28 10:50:14.981962072 +0000 UTC m=+17.948071589 End:2018-08-28 10:50:14.983954394 +0000 UTC m=+17.950063876
I0828 10:50:14.983978       1 scheduler.go:454] Total Schedule Algo cumulative time:212.207163ms for 77
I0828 10:50:14.987269       1 scheduler.go:451] ScheduleAlgoTime 2.44544ms Start:2018-08-28 10:50:14.984818518 +0000 UTC m=+17.950928041 End:2018-08-28 10:50:14.987264001 +0000 UTC m=+17.953373481
I0828 10:50:14.987290       1 scheduler.go:454] Total Schedule Algo cumulative time:214.652603ms for 78
I0828 10:50:14.990684       1 scheduler.go:451] ScheduleAlgoTime 3.286733ms Start:2018-08-28 10:50:14.987390223 +0000 UTC m=+17.953499741 End:2018-08-28 10:50:14.99067699 +0000 UTC m=+17.956786474
I0828 10:50:14.990717       1 scheduler.go:454] Total Schedule Algo cumulative time:217.939336ms for 79
I0828 10:50:15.003046       1 scheduler.go:451] ScheduleAlgoTime 12.219771ms Start:2018-08-28 10:50:14.99081864 +0000 UTC m=+17.956928155 End:2018-08-28 10:50:15.003038446 +0000 UTC m=+17.969147926
I0828 10:50:15.003087       1 scheduler.go:454] Total Schedule Algo cumulative time:230.159107ms for 80
I0828 10:50:15.005578       1 scheduler.go:451] ScheduleAlgoTime 2.383035ms Start:2018-08-28 10:50:15.003186216 +0000 UTC m=+17.969295758 End:2018-08-28 10:50:15.005569305 +0000 UTC m=+17.971678793
I0828 10:50:15.005615       1 scheduler.go:454] Total Schedule Algo cumulative time:232.542142ms for 81
I0828 10:50:15.007390       1 scheduler.go:451] ScheduleAlgoTime 1.687833ms Start:2018-08-28 10:50:15.00569582 +0000 UTC m=+17.971805321 End:2018-08-28 10:50:15.007383669 +0000 UTC m=+17.973493154
I0828 10:50:15.007427       1 scheduler.go:454] Total Schedule Algo cumulative time:234.229975ms for 82
I0828 10:50:15.009182       1 scheduler.go:451] ScheduleAlgoTime 1.616461ms Start:2018-08-28 10:50:15.007556504 +0000 UTC m=+17.973666003 End:2018-08-28 10:50:15.009172982 +0000 UTC m=+17.975282464
I0828 10:50:15.009219       1 scheduler.go:454] Total Schedule Algo cumulative time:235.846436ms for 83
I0828 10:50:15.012375       1 scheduler.go:451] ScheduleAlgoTime 3.050831ms Start:2018-08-28 10:50:15.009318459 +0000 UTC m=+17.975427999 End:2018-08-28 10:50:15.012369348 +0000 UTC m=+17.978478830
I0828 10:50:15.012404       1 scheduler.go:454] Total Schedule Algo cumulative time:238.897267ms for 84
I0828 10:50:15.015024       1 scheduler.go:451] ScheduleAlgoTime 2.489952ms Start:2018-08-28 10:50:15.01252848 +0000 UTC m=+17.978638038 End:2018-08-28 10:50:15.015018509 +0000 UTC m=+17.981127990
I0828 10:50:15.015046       1 scheduler.go:454] Total Schedule Algo cumulative time:241.387219ms for 85
I0828 10:50:15.017360       1 scheduler.go:451] ScheduleAlgoTime 2.176611ms Start:2018-08-28 10:50:15.015175456 +0000 UTC m=+17.981284966 End:2018-08-28 10:50:15.01735199 +0000 UTC m=+17.983461577
I0828 10:50:15.017400       1 scheduler.go:454] Total Schedule Algo cumulative time:243.56383ms for 86
I0828 10:50:15.019392       1 scheduler.go:451] ScheduleAlgoTime 1.904613ms Start:2018-08-28 10:50:15.017480886 +0000 UTC m=+17.983590381 End:2018-08-28 10:50:15.019385513 +0000 UTC m=+17.985494994
I0828 10:50:15.019430       1 scheduler.go:454] Total Schedule Algo cumulative time:245.468443ms for 87
I0828 10:50:15.021177       1 scheduler.go:451] ScheduleAlgoTime 1.630654ms Start:2018-08-28 10:50:15.019541672 +0000 UTC m=+17.985651199 End:2018-08-28 10:50:15.021172372 +0000 UTC m=+17.987281853
I0828 10:50:15.021197       1 scheduler.go:454] Total Schedule Algo cumulative time:247.099097ms for 88
I0828 10:50:15.023183       1 scheduler.go:451] ScheduleAlgoTime 1.834006ms Start:2018-08-28 10:50:15.021343286 +0000 UTC m=+17.987452802 End:2018-08-28 10:50:15.023177327 +0000 UTC m=+17.989286808
I0828 10:50:15.023207       1 scheduler.go:454] Total Schedule Algo cumulative time:248.933103ms for 89
I0828 10:50:15.024773       1 scheduler.go:451] ScheduleAlgoTime 1.461092ms Start:2018-08-28 10:50:15.023304164 +0000 UTC m=+17.989413698 End:2018-08-28 10:50:15.024765306 +0000 UTC m=+17.990874790
I0828 10:50:15.024793       1 scheduler.go:454] Total Schedule Algo cumulative time:250.394195ms for 90
I0828 10:50:15.026320       1 scheduler.go:451] ScheduleAlgoTime 1.421323ms Start:2018-08-28 10:50:15.024893856 +0000 UTC m=+17.991003351 End:2018-08-28 10:50:15.026315194 +0000 UTC m=+17.992424674
I0828 10:50:15.026354       1 scheduler.go:454] Total Schedule Algo cumulative time:251.815518ms for 91
I0828 10:50:15.028323       1 scheduler.go:451] ScheduleAlgoTime 1.690015ms Start:2018-08-28 10:50:15.026627776 +0000 UTC m=+17.992737258 End:2018-08-28 10:50:15.02831779 +0000 UTC m=+17.994427273
I0828 10:50:15.028353       1 scheduler.go:454] Total Schedule Algo cumulative time:253.505533ms for 92
I0828 10:50:15.030405       1 scheduler.go:451] ScheduleAlgoTime 1.949425ms Start:2018-08-28 10:50:15.028446816 +0000 UTC m=+17.994556334 End:2018-08-28 10:50:15.030396193 +0000 UTC m=+17.996505759
I0828 10:50:15.030455       1 scheduler.go:454] Total Schedule Algo cumulative time:255.454958ms for 93
I0828 10:50:15.032282       1 scheduler.go:451] ScheduleAlgoTime 1.681538ms Start:2018-08-28 10:50:15.030595687 +0000 UTC m=+17.996705188 End:2018-08-28 10:50:15.032277245 +0000 UTC m=+17.998386726
I0828 10:50:15.032305       1 scheduler.go:454] Total Schedule Algo cumulative time:257.136496ms for 94
I0828 10:50:15.035715       1 scheduler.go:451] ScheduleAlgoTime 3.165993ms Start:2018-08-28 10:50:15.032542743 +0000 UTC m=+17.998652282 End:2018-08-28 10:50:15.035708796 +0000 UTC m=+18.001818275
I0828 10:50:15.035738       1 scheduler.go:454] Total Schedule Algo cumulative time:260.302489ms for 95
I0828 10:50:15.037570       1 scheduler.go:451] ScheduleAlgoTime 1.713424ms Start:2018-08-28 10:50:15.035850275 +0000 UTC m=+18.001959826 End:2018-08-28 10:50:15.037563751 +0000 UTC m=+18.003673250
I0828 10:50:15.037601       1 scheduler.go:454] Total Schedule Algo cumulative time:262.015913ms for 96
I0828 10:50:15.039507       1 scheduler.go:451] ScheduleAlgoTime 1.719753ms Start:2018-08-28 10:50:15.037782446 +0000 UTC m=+18.003891994 End:2018-08-28 10:50:15.039502268 +0000 UTC m=+18.005611747
I0828 10:50:15.039533       1 scheduler.go:454] Total Schedule Algo cumulative time:263.735666ms for 97
I0828 10:50:15.042634       1 scheduler.go:451] ScheduleAlgoTime 2.928265ms Start:2018-08-28 10:50:15.03970056 +0000 UTC m=+18.005810095 End:2018-08-28 10:50:15.042628879 +0000 UTC m=+18.008738360
I0828 10:50:15.042657       1 scheduler.go:454] Total Schedule Algo cumulative time:266.663931ms for 98
I0828 10:50:15.044834       1 scheduler.go:451] ScheduleAlgoTime 2.054876ms Start:2018-08-28 10:50:15.042773459 +0000 UTC m=+18.008882966 End:2018-08-28 10:50:15.044828362 +0000 UTC m=+18.010937842
I0828 10:50:15.044860       1 scheduler.go:454] Total Schedule Algo cumulative time:268.718807ms for 99
I0828 10:50:15.047082       1 scheduler.go:451] ScheduleAlgoTime 2.001722ms Start:2018-08-28 10:50:15.045073246 +0000 UTC m=+18.011182779 End:2018-08-28 10:50:15.04707502 +0000 UTC m=+18.013184501
I0828 10:50:15.047111       1 scheduler.go:454] Total Schedule Algo cumulative time:270.720529ms for 100
I0828 10:50:15.048992       1 scheduler.go:451] ScheduleAlgoTime 1.785624ms Start:2018-08-28 10:50:15.047201037 +0000 UTC m=+18.013310552 End:2018-08-28 10:50:15.048986695 +0000 UTC m=+18.015096176
I0828 10:50:15.049014       1 scheduler.go:454] Total Schedule Algo cumulative time:272.506153ms for 101
I0828 10:50:15.051386       1 scheduler.go:451] ScheduleAlgoTime 2.217868ms Start:2018-08-28 10:50:15.049163604 +0000 UTC m=+18.015273105 End:2018-08-28 10:50:15.051381487 +0000 UTC m=+18.017490973
I0828 10:50:15.051410       1 scheduler.go:454] Total Schedule Algo cumulative time:274.724021ms for 102
I0828 10:50:15.053452       1 scheduler.go:451] ScheduleAlgoTime 1.884117ms Start:2018-08-28 10:50:15.05156055 +0000 UTC m=+18.017670093 End:2018-08-28 10:50:15.053444724 +0000 UTC m=+18.019554210
I0828 10:50:15.053477       1 scheduler.go:454] Total Schedule Algo cumulative time:276.608138ms for 103
I0828 10:50:15.055459       1 scheduler.go:451] ScheduleAlgoTime 1.762963ms Start:2018-08-28 10:50:15.053687149 +0000 UTC m=+18.019796683 End:2018-08-28 10:50:15.055450158 +0000 UTC m=+18.021559646
I0828 10:50:15.055503       1 scheduler.go:454] Total Schedule Algo cumulative time:278.371101ms for 104
I0828 10:50:15.057685       1 scheduler.go:451] ScheduleAlgoTime 1.990875ms Start:2018-08-28 10:50:15.055687951 +0000 UTC m=+18.021797476 End:2018-08-28 10:50:15.057678867 +0000 UTC m=+18.023788351
I0828 10:50:15.057710       1 scheduler.go:454] Total Schedule Algo cumulative time:280.361976ms for 105
I0828 10:50:15.062044       1 scheduler.go:451] ScheduleAlgoTime 4.147549ms Start:2018-08-28 10:50:15.057885897 +0000 UTC m=+18.023995419 End:2018-08-28 10:50:15.062033103 +0000 UTC m=+18.028142968
I0828 10:50:15.062092       1 scheduler.go:454] Total Schedule Algo cumulative time:284.509525ms for 106
I0828 10:50:15.066130       1 scheduler.go:451] ScheduleAlgoTime 3.832239ms Start:2018-08-28 10:50:15.062289721 +0000 UTC m=+18.028399271 End:2018-08-28 10:50:15.066122029 +0000 UTC m=+18.032231510
I0828 10:50:15.066179       1 scheduler.go:454] Total Schedule Algo cumulative time:288.341764ms for 107
I0828 10:50:15.068225       1 scheduler.go:451] ScheduleAlgoTime 1.896271ms Start:2018-08-28 10:50:15.066319723 +0000 UTC m=+18.032429267 End:2018-08-28 10:50:15.068216054 +0000 UTC m=+18.034325538
I0828 10:50:15.068262       1 scheduler.go:454] Total Schedule Algo cumulative time:290.238035ms for 108
I0828 10:50:15.069913       1 scheduler.go:451] ScheduleAlgoTime 1.483212ms Start:2018-08-28 10:50:15.068423143 +0000 UTC m=+18.034532658 End:2018-08-28 10:50:15.069906388 +0000 UTC m=+18.036015870
I0828 10:50:15.069960       1 scheduler.go:454] Total Schedule Algo cumulative time:291.721247ms for 109
I0828 10:50:15.071846       1 scheduler.go:451] ScheduleAlgoTime 1.783874ms Start:2018-08-28 10:50:15.070054406 +0000 UTC m=+18.036163929 End:2018-08-28 10:50:15.071838314 +0000 UTC m=+18.037947803
I0828 10:50:15.071890       1 scheduler.go:454] Total Schedule Algo cumulative time:293.505121ms for 110
I0828 10:50:15.073949       1 scheduler.go:451] ScheduleAlgoTime 1.908827ms Start:2018-08-28 10:50:15.072034206 +0000 UTC m=+18.038143740 End:2018-08-28 10:50:15.073943084 +0000 UTC m=+18.040052567
I0828 10:50:15.073977       1 scheduler.go:454] Total Schedule Algo cumulative time:295.413948ms for 111
I0828 10:50:15.075737       1 scheduler.go:451] ScheduleAlgoTime 1.520405ms Start:2018-08-28 10:50:15.074210833 +0000 UTC m=+18.040320374 End:2018-08-28 10:50:15.075731295 +0000 UTC m=+18.041840779
I0828 10:50:15.075761       1 scheduler.go:454] Total Schedule Algo cumulative time:296.934353ms for 112
I0828 10:50:15.078255       1 scheduler.go:451] ScheduleAlgoTime 2.34276ms Start:2018-08-28 10:50:15.075906686 +0000 UTC m=+18.042016199 End:2018-08-28 10:50:15.078249475 +0000 UTC m=+18.044358959
I0828 10:50:15.078282       1 scheduler.go:454] Total Schedule Algo cumulative time:299.277113ms for 113
I0828 10:50:15.080223       1 scheduler.go:451] ScheduleAlgoTime 1.819298ms Start:2018-08-28 10:50:15.078397054 +0000 UTC m=+18.044506581 End:2018-08-28 10:50:15.080216398 +0000 UTC m=+18.046325879
I0828 10:50:15.080248       1 scheduler.go:454] Total Schedule Algo cumulative time:301.096411ms for 114
I0828 10:50:15.082549       1 scheduler.go:451] ScheduleAlgoTime 2.185463ms Start:2018-08-28 10:50:15.08034914 +0000 UTC m=+18.046458654 End:2018-08-28 10:50:15.082534556 +0000 UTC m=+18.048644117
I0828 10:50:15.082586       1 scheduler.go:454] Total Schedule Algo cumulative time:303.281874ms for 115
I0828 10:50:15.084866       1 scheduler.go:451] ScheduleAlgoTime 2.104139ms Start:2018-08-28 10:50:15.082754966 +0000 UTC m=+18.048864497 End:2018-08-28 10:50:15.084859157 +0000 UTC m=+18.050968636
I0828 10:50:15.084890       1 scheduler.go:454] Total Schedule Algo cumulative time:305.386013ms for 116
I0828 10:50:15.087448       1 scheduler.go:451] ScheduleAlgoTime 2.327555ms Start:2018-08-28 10:50:15.085112596 +0000 UTC m=+18.051222130 End:2018-08-28 10:50:15.087440202 +0000 UTC m=+18.053549685
I0828 10:50:15.087473       1 scheduler.go:454] Total Schedule Algo cumulative time:307.713568ms for 117
I0828 10:50:15.089212       1 scheduler.go:451] ScheduleAlgoTime 1.595585ms Start:2018-08-28 10:50:15.087609212 +0000 UTC m=+18.053718710 End:2018-08-28 10:50:15.089204816 +0000 UTC m=+18.055314295
I0828 10:50:15.089236       1 scheduler.go:454] Total Schedule Algo cumulative time:309.309153ms for 118
I0828 10:50:15.091306       1 scheduler.go:451] ScheduleAlgoTime 1.970506ms Start:2018-08-28 10:50:15.089329753 +0000 UTC m=+18.055439267 End:2018-08-28 10:50:15.091300289 +0000 UTC m=+18.057409773
I0828 10:50:15.091329       1 scheduler.go:454] Total Schedule Algo cumulative time:311.279659ms for 119
I0828 10:50:15.093079       1 scheduler.go:451] ScheduleAlgoTime 1.633945ms Start:2018-08-28 10:50:15.091438416 +0000 UTC m=+18.057547930 End:2018-08-28 10:50:15.093072394 +0000 UTC m=+18.059181875
I0828 10:50:15.093132       1 scheduler.go:454] Total Schedule Algo cumulative time:312.913604ms for 120
I0828 10:50:15.094765       1 scheduler.go:451] ScheduleAlgoTime 1.493422ms Start:2018-08-28 10:50:15.09326738 +0000 UTC m=+18.059376893 End:2018-08-28 10:50:15.094760833 +0000 UTC m=+18.060870315
I0828 10:50:15.094790       1 scheduler.go:454] Total Schedule Algo cumulative time:314.407026ms for 121
I0828 10:50:15.096696       1 scheduler.go:451] ScheduleAlgoTime 1.769762ms Start:2018-08-28 10:50:15.094920105 +0000 UTC m=+18.061029622 End:2018-08-28 10:50:15.096689904 +0000 UTC m=+18.062799384
I0828 10:50:15.096719       1 scheduler.go:454] Total Schedule Algo cumulative time:316.176788ms for 122
I0828 10:50:15.098603       1 scheduler.go:451] ScheduleAlgoTime 1.662847ms Start:2018-08-28 10:50:15.096932137 +0000 UTC m=+18.063041653 End:2018-08-28 10:50:15.098594909 +0000 UTC m=+18.064704500
I0828 10:50:15.098635       1 scheduler.go:454] Total Schedule Algo cumulative time:317.839635ms for 123
I0828 10:50:15.100374       1 scheduler.go:451] ScheduleAlgoTime 1.647166ms Start:2018-08-28 10:50:15.09872112 +0000 UTC m=+18.064830668 End:2018-08-28 10:50:15.100368354 +0000 UTC m=+18.066477834
I0828 10:50:15.100398       1 scheduler.go:454] Total Schedule Algo cumulative time:319.486801ms for 124
I0828 10:50:15.102064       1 scheduler.go:451] ScheduleAlgoTime 1.561245ms Start:2018-08-28 10:50:15.10049756 +0000 UTC m=+18.066607102 End:2018-08-28 10:50:15.102058867 +0000 UTC m=+18.068168347
I0828 10:50:15.102085       1 scheduler.go:454] Total Schedule Algo cumulative time:321.048046ms for 125
I0828 10:50:15.103931       1 scheduler.go:451] ScheduleAlgoTime 1.69959ms Start:2018-08-28 10:50:15.102224907 +0000 UTC m=+18.068334410 End:2018-08-28 10:50:15.103924519 +0000 UTC m=+18.070034000
I0828 10:50:15.103964       1 scheduler.go:454] Total Schedule Algo cumulative time:322.747636ms for 126
I0828 10:50:15.105880       1 scheduler.go:451] ScheduleAlgoTime 1.781524ms Start:2018-08-28 10:50:15.104093555 +0000 UTC m=+18.070203076 End:2018-08-28 10:50:15.10587512 +0000 UTC m=+18.071984600
I0828 10:50:15.105901       1 scheduler.go:454] Total Schedule Algo cumulative time:324.52916ms for 127
I0828 10:50:15.107916       1 scheduler.go:451] ScheduleAlgoTime 1.872952ms Start:2018-08-28 10:50:15.106036972 +0000 UTC m=+18.072146489 End:2018-08-28 10:50:15.107909957 +0000 UTC m=+18.074019441
I0828 10:50:15.107937       1 scheduler.go:454] Total Schedule Algo cumulative time:326.402112ms for 128
I0828 10:50:15.109633       1 scheduler.go:451] ScheduleAlgoTime 1.594822ms Start:2018-08-28 10:50:15.108033078 +0000 UTC m=+18.074142596 End:2018-08-28 10:50:15.109627938 +0000 UTC m=+18.075737418
I0828 10:50:15.109662       1 scheduler.go:454] Total Schedule Algo cumulative time:327.996934ms for 129
I0828 10:50:15.111598       1 scheduler.go:451] ScheduleAlgoTime 1.810885ms Start:2018-08-28 10:50:15.109781062 +0000 UTC m=+18.075890604 End:2018-08-28 10:50:15.111592009 +0000 UTC m=+18.077701489
I0828 10:50:15.111620       1 scheduler.go:454] Total Schedule Algo cumulative time:329.807819ms for 130
I0828 10:50:15.113256       1 scheduler.go:451] ScheduleAlgoTime 1.534221ms Start:2018-08-28 10:50:15.111717547 +0000 UTC m=+18.077827112 End:2018-08-28 10:50:15.113251853 +0000 UTC m=+18.079361333
I0828 10:50:15.113278       1 scheduler.go:454] Total Schedule Algo cumulative time:331.34204ms for 131
I0828 10:50:15.115013       1 scheduler.go:451] ScheduleAlgoTime 1.587698ms Start:2018-08-28 10:50:15.11342087 +0000 UTC m=+18.079530394 End:2018-08-28 10:50:15.115008611 +0000 UTC m=+18.081118092
I0828 10:50:15.115036       1 scheduler.go:454] Total Schedule Algo cumulative time:332.929738ms for 132
I0828 10:50:15.117505       1 scheduler.go:451] ScheduleAlgoTime 2.330029ms Start:2018-08-28 10:50:15.115166883 +0000 UTC m=+18.081276436 End:2018-08-28 10:50:15.117496901 +0000 UTC m=+18.083606465
I0828 10:50:15.117533       1 scheduler.go:454] Total Schedule Algo cumulative time:335.259767ms for 133
I0828 10:50:15.119712       1 scheduler.go:451] ScheduleAlgoTime 1.983321ms Start:2018-08-28 10:50:15.117721496 +0000 UTC m=+18.083831038 End:2018-08-28 10:50:15.119704871 +0000 UTC m=+18.085814359
I0828 10:50:15.119757       1 scheduler.go:454] Total Schedule Algo cumulative time:337.243088ms for 134
I0828 10:50:15.121952       1 scheduler.go:451] ScheduleAlgoTime 2.084421ms Start:2018-08-28 10:50:15.119861973 +0000 UTC m=+18.085971480 End:2018-08-28 10:50:15.121946418 +0000 UTC m=+18.088055901
I0828 10:50:15.121977       1 scheduler.go:454] Total Schedule Algo cumulative time:339.327509ms for 135
I0828 10:50:15.126897       1 scheduler.go:451] ScheduleAlgoTime 4.832639ms Start:2018-08-28 10:50:15.122055631 +0000 UTC m=+18.088165139 End:2018-08-28 10:50:15.126888294 +0000 UTC m=+18.092997778
I0828 10:50:15.126969       1 scheduler.go:454] Total Schedule Algo cumulative time:344.160148ms for 136
I0828 10:50:15.131116       1 scheduler.go:451] ScheduleAlgoTime 4.030975ms Start:2018-08-28 10:50:15.127077706 +0000 UTC m=+18.093187207 End:2018-08-28 10:50:15.131108702 +0000 UTC m=+18.097218182
I0828 10:50:15.131184       1 scheduler.go:454] Total Schedule Algo cumulative time:348.191123ms for 137
I0828 10:50:15.132828       1 scheduler.go:451] ScheduleAlgoTime 1.506077ms Start:2018-08-28 10:50:15.131316576 +0000 UTC m=+18.097426078 End:2018-08-28 10:50:15.132822672 +0000 UTC m=+18.098932155
I0828 10:50:15.132852       1 scheduler.go:454] Total Schedule Algo cumulative time:349.6972ms for 138
I0828 10:50:15.134632       1 scheduler.go:451] ScheduleAlgoTime 1.683823ms Start:2018-08-28 10:50:15.132943461 +0000 UTC m=+18.099053006 End:2018-08-28 10:50:15.134627347 +0000 UTC m=+18.100736829
I0828 10:50:15.134656       1 scheduler.go:454] Total Schedule Algo cumulative time:351.381023ms for 139
I0828 10:50:15.136541       1 scheduler.go:451] ScheduleAlgoTime 1.793948ms Start:2018-08-28 10:50:15.134740667 +0000 UTC m=+18.100850212 End:2018-08-28 10:50:15.136534679 +0000 UTC m=+18.102644160
I0828 10:50:15.136564       1 scheduler.go:454] Total Schedule Algo cumulative time:353.174971ms for 140
I0828 10:50:15.138154       1 scheduler.go:451] ScheduleAlgoTime 1.483265ms Start:2018-08-28 10:50:15.136654878 +0000 UTC m=+18.102764372 End:2018-08-28 10:50:15.138138151 +0000 UTC m=+18.104247637
I0828 10:50:15.138178       1 scheduler.go:454] Total Schedule Algo cumulative time:354.658236ms for 141
I0828 10:50:15.140026       1 scheduler.go:451] ScheduleAlgoTime 1.678281ms Start:2018-08-28 10:50:15.138341929 +0000 UTC m=+18.104451459 End:2018-08-28 10:50:15.14002026 +0000 UTC m=+18.106129740
I0828 10:50:15.140058       1 scheduler.go:454] Total Schedule Algo cumulative time:356.336517ms for 142
I0828 10:50:15.141932       1 scheduler.go:451] ScheduleAlgoTime 1.748825ms Start:2018-08-28 10:50:15.140177838 +0000 UTC m=+18.106287363 End:2018-08-28 10:50:15.141926706 +0000 UTC m=+18.108036188
I0828 10:50:15.141958       1 scheduler.go:454] Total Schedule Algo cumulative time:358.085342ms for 143
I0828 10:50:15.143587       1 scheduler.go:451] ScheduleAlgoTime 1.478041ms Start:2018-08-28 10:50:15.142102693 +0000 UTC m=+18.108212197 End:2018-08-28 10:50:15.143580758 +0000 UTC m=+18.109690238
I0828 10:50:15.143608       1 scheduler.go:454] Total Schedule Algo cumulative time:359.563383ms for 144
I0828 10:50:15.145267       1 scheduler.go:451] ScheduleAlgoTime 1.54155ms Start:2018-08-28 10:50:15.143718961 +0000 UTC m=+18.109828465 End:2018-08-28 10:50:15.145260532 +0000 UTC m=+18.111370015
I0828 10:50:15.145296       1 scheduler.go:454] Total Schedule Algo cumulative time:361.104933ms for 145
I0828 10:50:15.147159       1 scheduler.go:451] ScheduleAlgoTime 1.626067ms Start:2018-08-28 10:50:15.145528064 +0000 UTC m=+18.111637582 End:2018-08-28 10:50:15.147154168 +0000 UTC m=+18.113263649
I0828 10:50:15.147183       1 scheduler.go:454] Total Schedule Algo cumulative time:362.731ms for 146
I0828 10:50:15.149012       1 scheduler.go:451] ScheduleAlgoTime 1.661934ms Start:2018-08-28 10:50:15.147342555 +0000 UTC m=+18.113452078 End:2018-08-28 10:50:15.149004529 +0000 UTC m=+18.115114012
I0828 10:50:15.149040       1 scheduler.go:454] Total Schedule Algo cumulative time:364.392934ms for 147
I0828 10:50:15.150800       1 scheduler.go:451] ScheduleAlgoTime 1.610558ms Start:2018-08-28 10:50:15.14918125 +0000 UTC m=+18.115290759 End:2018-08-28 10:50:15.150791822 +0000 UTC m=+18.116901317
I0828 10:50:15.150825       1 scheduler.go:454] Total Schedule Algo cumulative time:366.003492ms for 148
I0828 10:50:15.152938       1 scheduler.go:451] ScheduleAlgoTime 2.005458ms Start:2018-08-28 10:50:15.150923983 +0000 UTC m=+18.117033552 End:2018-08-28 10:50:15.152929433 +0000 UTC m=+18.119039010
I0828 10:50:15.152966       1 scheduler.go:454] Total Schedule Algo cumulative time:368.00895ms for 149
I0828 10:50:15.154920       1 scheduler.go:451] ScheduleAlgoTime 1.751734ms Start:2018-08-28 10:50:15.153161802 +0000 UTC m=+18.119271292 End:2018-08-28 10:50:15.154913545 +0000 UTC m=+18.121023026
I0828 10:50:15.154943       1 scheduler.go:454] Total Schedule Algo cumulative time:369.760684ms for 150
I0828 10:50:15.156925       1 scheduler.go:451] ScheduleAlgoTime 1.827116ms Start:2018-08-28 10:50:15.155091497 +0000 UTC m=+18.121201068 End:2018-08-28 10:50:15.1569187 +0000 UTC m=+18.123028184
I0828 10:50:15.156952       1 scheduler.go:454] Total Schedule Algo cumulative time:371.5878ms for 151
I0828 10:50:15.158576       1 scheduler.go:451] ScheduleAlgoTime 1.517835ms Start:2018-08-28 10:50:15.157050672 +0000 UTC m=+18.123160188 End:2018-08-28 10:50:15.158568534 +0000 UTC m=+18.124678023
I0828 10:50:15.158609       1 scheduler.go:454] Total Schedule Algo cumulative time:373.105635ms for 152
I0828 10:50:15.160518       1 scheduler.go:451] ScheduleAlgoTime 1.765374ms Start:2018-08-28 10:50:15.158746849 +0000 UTC m=+18.124856357 End:2018-08-28 10:50:15.16051225 +0000 UTC m=+18.126621731
I0828 10:50:15.160544       1 scheduler.go:454] Total Schedule Algo cumulative time:374.871009ms for 153
I0828 10:50:15.162399       1 scheduler.go:451] ScheduleAlgoTime 1.728153ms Start:2018-08-28 10:50:15.16066298 +0000 UTC m=+18.126772501 End:2018-08-28 10:50:15.162391147 +0000 UTC m=+18.128500654
I0828 10:50:15.162430       1 scheduler.go:454] Total Schedule Algo cumulative time:376.599162ms for 154
I0828 10:50:15.164148       1 scheduler.go:451] ScheduleAlgoTime 1.572354ms Start:2018-08-28 10:50:15.162562324 +0000 UTC m=+18.128671880 End:2018-08-28 10:50:15.16413475 +0000 UTC m=+18.130244234
I0828 10:50:15.164171       1 scheduler.go:454] Total Schedule Algo cumulative time:378.171516ms for 155
I0828 10:50:15.165884       1 scheduler.go:451] ScheduleAlgoTime 1.611318ms Start:2018-08-28 10:50:15.164265281 +0000 UTC m=+18.130374778 End:2018-08-28 10:50:15.165876453 +0000 UTC m=+18.131986096
I0828 10:50:15.165931       1 scheduler.go:454] Total Schedule Algo cumulative time:379.782834ms for 156
I0828 10:50:15.167788       1 scheduler.go:451] ScheduleAlgoTime 1.668922ms Start:2018-08-28 10:50:15.166113764 +0000 UTC m=+18.132223329 End:2018-08-28 10:50:15.167782763 +0000 UTC m=+18.133892251
I0828 10:50:15.167811       1 scheduler.go:454] Total Schedule Algo cumulative time:381.451756ms for 157
I0828 10:50:15.169540       1 scheduler.go:451] ScheduleAlgoTime 1.575892ms Start:2018-08-28 10:50:15.167956084 +0000 UTC m=+18.134065604 End:2018-08-28 10:50:15.169531873 +0000 UTC m=+18.135641496
I0828 10:50:15.169570       1 scheduler.go:454] Total Schedule Algo cumulative time:383.027648ms for 158
I0828 10:50:15.171256       1 scheduler.go:451] ScheduleAlgoTime 1.542234ms Start:2018-08-28 10:50:15.169708093 +0000 UTC m=+18.135817594 End:2018-08-28 10:50:15.171250349 +0000 UTC m=+18.137359828
I0828 10:50:15.171277       1 scheduler.go:454] Total Schedule Algo cumulative time:384.569882ms for 159
I0828 10:50:15.172934       1 scheduler.go:451] ScheduleAlgoTime 1.505226ms Start:2018-08-28 10:50:15.171422346 +0000 UTC m=+18.137531886 End:2018-08-28 10:50:15.172927629 +0000 UTC m=+18.139037112
I0828 10:50:15.172954       1 scheduler.go:454] Total Schedule Algo cumulative time:386.075108ms for 160
I0828 10:50:15.174774       1 scheduler.go:451] ScheduleAlgoTime 1.648694ms Start:2018-08-28 10:50:15.173119342 +0000 UTC m=+18.139228860 End:2018-08-28 10:50:15.174768073 +0000 UTC m=+18.140877554
I0828 10:50:15.174796       1 scheduler.go:454] Total Schedule Algo cumulative time:387.723802ms for 161
I0828 10:50:15.176799       1 scheduler.go:451] ScheduleAlgoTime 1.854346ms Start:2018-08-28 10:50:15.174939307 +0000 UTC m=+18.141048816 End:2018-08-28 10:50:15.17679368 +0000 UTC m=+18.142903162
I0828 10:50:15.176820       1 scheduler.go:454] Total Schedule Algo cumulative time:389.578148ms for 162
I0828 10:50:15.178584       1 scheduler.go:451] ScheduleAlgoTime 1.65578ms Start:2018-08-28 10:50:15.176922377 +0000 UTC m=+18.143031904 End:2018-08-28 10:50:15.178578202 +0000 UTC m=+18.144687684
I0828 10:50:15.178616       1 scheduler.go:454] Total Schedule Algo cumulative time:391.233928ms for 163
I0828 10:50:15.180479       1 scheduler.go:451] ScheduleAlgoTime 1.722244ms Start:2018-08-28 10:50:15.178752519 +0000 UTC m=+18.144862036 End:2018-08-28 10:50:15.180474797 +0000 UTC m=+18.146584280
I0828 10:50:15.180518       1 scheduler.go:454] Total Schedule Algo cumulative time:392.956172ms for 164
I0828 10:50:15.182174       1 scheduler.go:451] ScheduleAlgoTime 1.522383ms Start:2018-08-28 10:50:15.180639634 +0000 UTC m=+18.146749192 End:2018-08-28 10:50:15.182162092 +0000 UTC m=+18.148271575
I0828 10:50:15.182195       1 scheduler.go:454] Total Schedule Algo cumulative time:394.478555ms for 165
I0828 10:50:15.183762       1 scheduler.go:451] ScheduleAlgoTime 1.462673ms Start:2018-08-28 10:50:15.182292776 +0000 UTC m=+18.148402344 End:2018-08-28 10:50:15.183755535 +0000 UTC m=+18.149865017
I0828 10:50:15.183790       1 scheduler.go:454] Total Schedule Algo cumulative time:395.941228ms for 166
I0828 10:50:15.185777       1 scheduler.go:451] ScheduleAlgoTime 1.90489ms Start:2018-08-28 10:50:15.1838655 +0000 UTC m=+18.149975024 End:2018-08-28 10:50:15.18577041 +0000 UTC m=+18.151879914
I0828 10:50:15.185802       1 scheduler.go:454] Total Schedule Algo cumulative time:397.846118ms for 167
I0828 10:50:15.187818       1 scheduler.go:451] ScheduleAlgoTime 1.916423ms Start:2018-08-28 10:50:15.185897224 +0000 UTC m=+18.152006787 End:2018-08-28 10:50:15.187813726 +0000 UTC m=+18.153923210
I0828 10:50:15.187841       1 scheduler.go:454] Total Schedule Algo cumulative time:399.762541ms for 168
I0828 10:50:15.193027       1 scheduler.go:451] ScheduleAlgoTime 5.084709ms Start:2018-08-28 10:50:15.187935088 +0000 UTC m=+18.154044568 End:2018-08-28 10:50:15.193019792 +0000 UTC m=+18.159129277
I0828 10:50:15.193064       1 scheduler.go:454] Total Schedule Algo cumulative time:404.84725ms for 169
I0828 10:50:15.195033       1 scheduler.go:451] ScheduleAlgoTime 1.804503ms Start:2018-08-28 10:50:15.193222321 +0000 UTC m=+18.159331844 End:2018-08-28 10:50:15.195026867 +0000 UTC m=+18.161136347
I0828 10:50:15.195065       1 scheduler.go:454] Total Schedule Algo cumulative time:406.651753ms for 170
I0828 10:50:15.196786       1 scheduler.go:451] ScheduleAlgoTime 1.626253ms Start:2018-08-28 10:50:15.195154528 +0000 UTC m=+18.161264038 End:2018-08-28 10:50:15.196780811 +0000 UTC m=+18.162890291
I0828 10:50:15.196822       1 scheduler.go:454] Total Schedule Algo cumulative time:408.278006ms for 171
I0828 10:50:15.199081       1 scheduler.go:451] ScheduleAlgoTime 2.152905ms Start:2018-08-28 10:50:15.196923375 +0000 UTC m=+18.163032877 End:2018-08-28 10:50:15.199076302 +0000 UTC m=+18.165185782
I0828 10:50:15.199107       1 scheduler.go:454] Total Schedule Algo cumulative time:410.430911ms for 172
I0828 10:50:15.201122       1 scheduler.go:451] ScheduleAlgoTime 1.884334ms Start:2018-08-28 10:50:15.199231619 +0000 UTC m=+18.165341178 End:2018-08-28 10:50:15.201116034 +0000 UTC m=+18.167225512
I0828 10:50:15.201169       1 scheduler.go:454] Total Schedule Algo cumulative time:412.315245ms for 173
I0828 10:50:15.202985       1 scheduler.go:451] ScheduleAlgoTime 1.729177ms Start:2018-08-28 10:50:15.201250194 +0000 UTC m=+18.167359689 End:2018-08-28 10:50:15.202979386 +0000 UTC m=+18.169088866
I0828 10:50:15.203023       1 scheduler.go:454] Total Schedule Algo cumulative time:414.044422ms for 174
I0828 10:50:15.204710       1 scheduler.go:451] ScheduleAlgoTime 1.591968ms Start:2018-08-28 10:50:15.203113537 +0000 UTC m=+18.169223082 End:2018-08-28 10:50:15.20470557 +0000 UTC m=+18.170815050
I0828 10:50:15.204737       1 scheduler.go:454] Total Schedule Algo cumulative time:415.63639ms for 175
I0828 10:50:15.206481       1 scheduler.go:451] ScheduleAlgoTime 1.596784ms Start:2018-08-28 10:50:15.204879383 +0000 UTC m=+18.170988906 End:2018-08-28 10:50:15.206476202 +0000 UTC m=+18.172585690
I0828 10:50:15.206515       1 scheduler.go:454] Total Schedule Algo cumulative time:417.233174ms for 176
I0828 10:50:15.208563       1 scheduler.go:451] ScheduleAlgoTime 1.912123ms Start:2018-08-28 10:50:15.206645011 +0000 UTC m=+18.172754542 End:2018-08-28 10:50:15.208557164 +0000 UTC m=+18.174666665
I0828 10:50:15.208590       1 scheduler.go:454] Total Schedule Algo cumulative time:419.145297ms for 177
I0828 10:50:15.210293       1 scheduler.go:451] ScheduleAlgoTime 1.533205ms Start:2018-08-28 10:50:15.208753822 +0000 UTC m=+18.174863351 End:2018-08-28 10:50:15.210287076 +0000 UTC m=+18.176396556
I0828 10:50:15.210328       1 scheduler.go:454] Total Schedule Algo cumulative time:420.678502ms for 178
I0828 10:50:15.212090       1 scheduler.go:451] ScheduleAlgoTime 1.637211ms Start:2018-08-28 10:50:15.210447199 +0000 UTC m=+18.176556742 End:2018-08-28 10:50:15.212084472 +0000 UTC m=+18.178193953
I0828 10:50:15.212119       1 scheduler.go:454] Total Schedule Algo cumulative time:422.315713ms for 179
I0828 10:50:15.213875       1 scheduler.go:451] ScheduleAlgoTime 1.61962ms Start:2018-08-28 10:50:15.212250417 +0000 UTC m=+18.178359989 End:2018-08-28 10:50:15.213870125 +0000 UTC m=+18.179979609
I0828 10:50:15.213899       1 scheduler.go:454] Total Schedule Algo cumulative time:423.935333ms for 180
I0828 10:50:15.215678       1 scheduler.go:451] ScheduleAlgoTime 1.583199ms Start:2018-08-28 10:50:15.214087631 +0000 UTC m=+18.180197191 End:2018-08-28 10:50:15.215670903 +0000 UTC m=+18.181780390
I0828 10:50:15.215705       1 scheduler.go:454] Total Schedule Algo cumulative time:425.518532ms for 181
I0828 10:50:15.217531       1 scheduler.go:451] ScheduleAlgoTime 1.681759ms Start:2018-08-28 10:50:15.215843872 +0000 UTC m=+18.181953428 End:2018-08-28 10:50:15.217525703 +0000 UTC m=+18.183635187
I0828 10:50:15.217556       1 scheduler.go:454] Total Schedule Algo cumulative time:427.200291ms for 182
I0828 10:50:15.219239       1 scheduler.go:451] ScheduleAlgoTime 1.547535ms Start:2018-08-28 10:50:15.21768603 +0000 UTC m=+18.183795558 End:2018-08-28 10:50:15.219233614 +0000 UTC m=+18.185343093
I0828 10:50:15.219278       1 scheduler.go:454] Total Schedule Algo cumulative time:428.747826ms for 183
I0828 10:50:15.220919       1 scheduler.go:451] ScheduleAlgoTime 1.533317ms Start:2018-08-28 10:50:15.219381368 +0000 UTC m=+18.185490888 End:2018-08-28 10:50:15.220914722 +0000 UTC m=+18.187024205
I0828 10:50:15.220942       1 scheduler.go:454] Total Schedule Algo cumulative time:430.281143ms for 184
I0828 10:50:15.222658       1 scheduler.go:451] ScheduleAlgoTime 1.636134ms Start:2018-08-28 10:50:15.221016007 +0000 UTC m=+18.187125541 End:2018-08-28 10:50:15.222652195 +0000 UTC m=+18.188761675
I0828 10:50:15.222690       1 scheduler.go:454] Total Schedule Algo cumulative time:431.917277ms for 185
I0828 10:50:15.224388       1 scheduler.go:451] ScheduleAlgoTime 1.582534ms Start:2018-08-28 10:50:15.222801267 +0000 UTC m=+18.188910782 End:2018-08-28 10:50:15.224383837 +0000 UTC m=+18.190493316
I0828 10:50:15.224417       1 scheduler.go:454] Total Schedule Algo cumulative time:433.499811ms for 186
I0828 10:50:15.226173       1 scheduler.go:451] ScheduleAlgoTime 1.630641ms Start:2018-08-28 10:50:15.224537683 +0000 UTC m=+18.190647197 End:2018-08-28 10:50:15.226168356 +0000 UTC m=+18.192277838
I0828 10:50:15.226195       1 scheduler.go:454] Total Schedule Algo cumulative time:435.130452ms for 187
I0828 10:50:15.227826       1 scheduler.go:451] ScheduleAlgoTime 1.516988ms Start:2018-08-28 10:50:15.22630473 +0000 UTC m=+18.192414244 End:2018-08-28 10:50:15.227821751 +0000 UTC m=+18.193931232
I0828 10:50:15.227845       1 scheduler.go:454] Total Schedule Algo cumulative time:436.64744ms for 188
I0828 10:50:15.229569       1 scheduler.go:451] ScheduleAlgoTime 1.636783ms Start:2018-08-28 10:50:15.227926463 +0000 UTC m=+18.194035991 End:2018-08-28 10:50:15.229563287 +0000 UTC m=+18.195672774
I0828 10:50:15.229593       1 scheduler.go:454] Total Schedule Algo cumulative time:438.284223ms for 189
I0828 10:50:15.231412       1 scheduler.go:451] ScheduleAlgoTime 1.70897ms Start:2018-08-28 10:50:15.229696602 +0000 UTC m=+18.195806139 End:2018-08-28 10:50:15.231405627 +0000 UTC m=+18.197515109
I0828 10:50:15.231447       1 scheduler.go:454] Total Schedule Algo cumulative time:439.993193ms for 190
I0828 10:50:15.233243       1 scheduler.go:451] ScheduleAlgoTime 1.670594ms Start:2018-08-28 10:50:15.231566622 +0000 UTC m=+18.197676138 End:2018-08-28 10:50:15.233237249 +0000 UTC m=+18.199346732
I0828 10:50:15.233267       1 scheduler.go:454] Total Schedule Algo cumulative time:441.663787ms for 191
I0828 10:50:15.235042       1 scheduler.go:451] ScheduleAlgoTime 1.660013ms Start:2018-08-28 10:50:15.233376996 +0000 UTC m=+18.199486495 End:2018-08-28 10:50:15.235037027 +0000 UTC m=+18.201146508
I0828 10:50:15.235065       1 scheduler.go:454] Total Schedule Algo cumulative time:443.3238ms for 192
I0828 10:50:15.236727       1 scheduler.go:451] ScheduleAlgoTime 1.561209ms Start:2018-08-28 10:50:15.235160091 +0000 UTC m=+18.201269599 End:2018-08-28 10:50:15.236721328 +0000 UTC m=+18.202830808
I0828 10:50:15.236755       1 scheduler.go:454] Total Schedule Algo cumulative time:444.885009ms for 193
I0828 10:50:15.238588       1 scheduler.go:451] ScheduleAlgoTime 1.691635ms Start:2018-08-28 10:50:15.236890904 +0000 UTC m=+18.203000435 End:2018-08-28 10:50:15.238582588 +0000 UTC m=+18.204692070
I0828 10:50:15.238612       1 scheduler.go:454] Total Schedule Algo cumulative time:446.576644ms for 194
I0828 10:50:15.240525       1 scheduler.go:451] ScheduleAlgoTime 1.772219ms Start:2018-08-28 10:50:15.238747928 +0000 UTC m=+18.204857485 End:2018-08-28 10:50:15.240520224 +0000 UTC m=+18.206629704
I0828 10:50:15.240552       1 scheduler.go:454] Total Schedule Algo cumulative time:448.348863ms for 195
I0828 10:50:15.242254       1 scheduler.go:451] ScheduleAlgoTime 1.61081ms Start:2018-08-28 10:50:15.240634792 +0000 UTC m=+18.206744293 End:2018-08-28 10:50:15.242245615 +0000 UTC m=+18.208355103
I0828 10:50:15.242286       1 scheduler.go:454] Total Schedule Algo cumulative time:449.959673ms for 196
I0828 10:50:15.244004       1 scheduler.go:451] ScheduleAlgoTime 1.595814ms Start:2018-08-28 10:50:15.242402749 +0000 UTC m=+18.208512283 End:2018-08-28 10:50:15.243998613 +0000 UTC m=+18.210108097
I0828 10:50:15.244027       1 scheduler.go:454] Total Schedule Algo cumulative time:451.555487ms for 197
I0828 10:50:15.245742       1 scheduler.go:451] ScheduleAlgoTime 1.597413ms Start:2018-08-28 10:50:15.244139209 +0000 UTC m=+18.210248721 End:2018-08-28 10:50:15.245736651 +0000 UTC m=+18.211846134
I0828 10:50:15.245765       1 scheduler.go:454] Total Schedule Algo cumulative time:453.1529ms for 198
I0828 10:50:15.247494       1 scheduler.go:451] ScheduleAlgoTime 1.594259ms Start:2018-08-28 10:50:15.245894518 +0000 UTC m=+18.212004030 End:2018-08-28 10:50:15.247488807 +0000 UTC m=+18.213598289
I0828 10:50:15.247513       1 scheduler.go:454] Total Schedule Algo cumulative time:454.747159ms for 199
I0828 10:50:15.249296       1 scheduler.go:451] ScheduleAlgoTime 1.647561ms Start:2018-08-28 10:50:15.247643418 +0000 UTC m=+18.213752968 End:2018-08-28 10:50:15.249291049 +0000 UTC m=+18.215400529
I0828 10:50:15.249324       1 scheduler.go:454] Total Schedule Algo cumulative time:456.39472ms for 200
I0828 10:50:15.250983       1 scheduler.go:451] ScheduleAlgoTime 1.548968ms Start:2018-08-28 10:50:15.249428921 +0000 UTC m=+18.215538456 End:2018-08-28 10:50:15.250977944 +0000 UTC m=+18.217087424
I0828 10:50:15.251003       1 scheduler.go:454] Total Schedule Algo cumulative time:457.943688ms for 201
I0828 10:50:15.252681       1 scheduler.go:451] ScheduleAlgoTime 1.547ms Start:2018-08-28 10:50:15.251128833 +0000 UTC m=+18.217238361 End:2018-08-28 10:50:15.252675882 +0000 UTC m=+18.218785361
I0828 10:50:15.252702       1 scheduler.go:454] Total Schedule Algo cumulative time:459.490688ms for 202
I0828 10:50:15.255109       1 scheduler.go:451] ScheduleAlgoTime 2.282809ms Start:2018-08-28 10:50:15.252821188 +0000 UTC m=+18.218930746 End:2018-08-28 10:50:15.255104076 +0000 UTC m=+18.221213555
I0828 10:50:15.255130       1 scheduler.go:454] Total Schedule Algo cumulative time:461.773497ms for 203
I0828 10:50:15.256944       1 scheduler.go:451] ScheduleAlgoTime 1.622186ms Start:2018-08-28 10:50:15.25531711 +0000 UTC m=+18.221426631 End:2018-08-28 10:50:15.256939335 +0000 UTC m=+18.223048817
I0828 10:50:15.256977       1 scheduler.go:454] Total Schedule Algo cumulative time:463.395683ms for 204
I0828 10:50:15.261538       1 scheduler.go:451] ScheduleAlgoTime 4.121646ms Start:2018-08-28 10:50:15.25740875 +0000 UTC m=+18.223518329 End:2018-08-28 10:50:15.261530496 +0000 UTC m=+18.227639975
I0828 10:50:15.261577       1 scheduler.go:454] Total Schedule Algo cumulative time:467.517329ms for 205
I0828 10:50:15.263691       1 scheduler.go:451] ScheduleAlgoTime 1.984918ms Start:2018-08-28 10:50:15.261698947 +0000 UTC m=+18.227808494 End:2018-08-28 10:50:15.263683931 +0000 UTC m=+18.229793412
I0828 10:50:15.263717       1 scheduler.go:454] Total Schedule Algo cumulative time:469.502247ms for 206
I0828 10:50:15.265433       1 scheduler.go:451] ScheduleAlgoTime 1.585452ms Start:2018-08-28 10:50:15.263840092 +0000 UTC m=+18.229949589 End:2018-08-28 10:50:15.265425561 +0000 UTC m=+18.231535041
I0828 10:50:15.265460       1 scheduler.go:454] Total Schedule Algo cumulative time:471.087699ms for 207
I0828 10:50:15.267085       1 scheduler.go:451] ScheduleAlgoTime 1.505671ms Start:2018-08-28 10:50:15.265573993 +0000 UTC m=+18.231683533 End:2018-08-28 10:50:15.267079725 +0000 UTC m=+18.233189204
I0828 10:50:15.267108       1 scheduler.go:454] Total Schedule Algo cumulative time:472.59337ms for 208
I0828 10:50:15.268633       1 scheduler.go:451] ScheduleAlgoTime 1.399547ms Start:2018-08-28 10:50:15.267228455 +0000 UTC m=+18.233338006 End:2018-08-28 10:50:15.268628074 +0000 UTC m=+18.234737553
I0828 10:50:15.268653       1 scheduler.go:454] Total Schedule Algo cumulative time:473.992917ms for 209
I0828 10:50:15.270353       1 scheduler.go:451] ScheduleAlgoTime 1.578922ms Start:2018-08-28 10:50:15.268768843 +0000 UTC m=+18.234878325 End:2018-08-28 10:50:15.270347764 +0000 UTC m=+18.236457247
I0828 10:50:15.270383       1 scheduler.go:454] Total Schedule Algo cumulative time:475.571839ms for 210
I0828 10:50:15.272170       1 scheduler.go:451] ScheduleAlgoTime 1.68389ms Start:2018-08-28 10:50:15.27047968 +0000 UTC m=+18.236589231 End:2018-08-28 10:50:15.272163637 +0000 UTC m=+18.238273121
I0828 10:50:15.272193       1 scheduler.go:454] Total Schedule Algo cumulative time:477.255729ms for 211
I0828 10:50:15.273815       1 scheduler.go:451] ScheduleAlgoTime 1.48124ms Start:2018-08-28 10:50:15.272327924 +0000 UTC m=+18.238437459 End:2018-08-28 10:50:15.273809218 +0000 UTC m=+18.239918699
I0828 10:50:15.273841       1 scheduler.go:454] Total Schedule Algo cumulative time:478.736969ms for 212
I0828 10:50:15.275726       1 scheduler.go:451] ScheduleAlgoTime 1.743333ms Start:2018-08-28 10:50:15.273978729 +0000 UTC m=+18.240088279 End:2018-08-28 10:50:15.275722132 +0000 UTC m=+18.241831612
I0828 10:50:15.275749       1 scheduler.go:454] Total Schedule Algo cumulative time:480.480302ms for 213
I0828 10:50:15.277355       1 scheduler.go:451] ScheduleAlgoTime 1.509887ms Start:2018-08-28 10:50:15.275838619 +0000 UTC m=+18.241948137 End:2018-08-28 10:50:15.277348543 +0000 UTC m=+18.243458024
I0828 10:50:15.277379       1 scheduler.go:454] Total Schedule Algo cumulative time:481.990189ms for 214
I0828 10:50:15.279028       1 scheduler.go:451] ScheduleAlgoTime 1.519134ms Start:2018-08-28 10:50:15.277504449 +0000 UTC m=+18.243613944 End:2018-08-28 10:50:15.279023593 +0000 UTC m=+18.245133078
I0828 10:50:15.279048       1 scheduler.go:454] Total Schedule Algo cumulative time:483.509323ms for 215
I0828 10:50:15.280779       1 scheduler.go:451] ScheduleAlgoTime 1.625899ms Start:2018-08-28 10:50:15.27914747 +0000 UTC m=+18.245256990 End:2018-08-28 10:50:15.280773406 +0000 UTC m=+18.246882889
I0828 10:50:15.280806       1 scheduler.go:454] Total Schedule Algo cumulative time:485.135222ms for 216
I0828 10:50:15.282694       1 scheduler.go:451] ScheduleAlgoTime 1.748239ms Start:2018-08-28 10:50:15.280940226 +0000 UTC m=+18.247049780 End:2018-08-28 10:50:15.282688537 +0000 UTC m=+18.248798019
I0828 10:50:15.282725       1 scheduler.go:454] Total Schedule Algo cumulative time:486.883461ms for 217
I0828 10:50:15.284573       1 scheduler.go:451] ScheduleAlgoTime 1.739269ms Start:2018-08-28 10:50:15.282828932 +0000 UTC m=+18.248938469 End:2018-08-28 10:50:15.284568258 +0000 UTC m=+18.250677738
I0828 10:50:15.284594       1 scheduler.go:454] Total Schedule Algo cumulative time:488.62273ms for 218
I0828 10:50:15.286397       1 scheduler.go:451] ScheduleAlgoTime 1.695118ms Start:2018-08-28 10:50:15.284696198 +0000 UTC m=+18.250805723 End:2018-08-28 10:50:15.286391362 +0000 UTC m=+18.252500841
I0828 10:50:15.286421       1 scheduler.go:454] Total Schedule Algo cumulative time:490.317848ms for 219
I0828 10:50:15.288176       1 scheduler.go:451] ScheduleAlgoTime 1.622642ms Start:2018-08-28 10:50:15.286546215 +0000 UTC m=+18.252655727 End:2018-08-28 10:50:15.288168785 +0000 UTC m=+18.254278369
I0828 10:50:15.288206       1 scheduler.go:454] Total Schedule Algo cumulative time:491.94049ms for 220
I0828 10:50:15.289937       1 scheduler.go:451] ScheduleAlgoTime 1.581771ms Start:2018-08-28 10:50:15.288349922 +0000 UTC m=+18.254459412 End:2018-08-28 10:50:15.2899317 +0000 UTC m=+18.256041183
I0828 10:50:15.289961       1 scheduler.go:454] Total Schedule Algo cumulative time:493.522261ms for 221
I0828 10:50:15.291688       1 scheduler.go:451] ScheduleAlgoTime 1.612675ms Start:2018-08-28 10:50:15.290070175 +0000 UTC m=+18.256179689 End:2018-08-28 10:50:15.291682879 +0000 UTC m=+18.257792364
I0828 10:50:15.291710       1 scheduler.go:454] Total Schedule Algo cumulative time:495.134936ms for 222
I0828 10:50:15.293378       1 scheduler.go:451] ScheduleAlgoTime 1.507866ms Start:2018-08-28 10:50:15.291864886 +0000 UTC m=+18.257974426 End:2018-08-28 10:50:15.293372804 +0000 UTC m=+18.259482292
I0828 10:50:15.293401       1 scheduler.go:454] Total Schedule Algo cumulative time:496.642802ms for 223
I0828 10:50:15.295096       1 scheduler.go:451] ScheduleAlgoTime 1.550043ms Start:2018-08-28 10:50:15.293540341 +0000 UTC m=+18.259649886 End:2018-08-28 10:50:15.295090448 +0000 UTC m=+18.261199929
I0828 10:50:15.295119       1 scheduler.go:454] Total Schedule Algo cumulative time:498.192845ms for 224
I0828 10:50:15.296579       1 scheduler.go:451] ScheduleAlgoTime 1.36961ms Start:2018-08-28 10:50:15.29520499 +0000 UTC m=+18.261314484 End:2018-08-28 10:50:15.296574614 +0000 UTC m=+18.262684094
I0828 10:50:15.296601       1 scheduler.go:454] Total Schedule Algo cumulative time:499.562455ms for 225
I0828 10:50:15.298495       1 scheduler.go:451] ScheduleAlgoTime 1.763647ms Start:2018-08-28 10:50:15.296723945 +0000 UTC m=+18.262833455 End:2018-08-28 10:50:15.29848761 +0000 UTC m=+18.264597102
I0828 10:50:15.298528       1 scheduler.go:454] Total Schedule Algo cumulative time:501.326102ms for 226
I0828 10:50:15.300300       1 scheduler.go:451] ScheduleAlgoTime 1.6434ms Start:2018-08-28 10:50:15.298651596 +0000 UTC m=+18.264761125 End:2018-08-28 10:50:15.300295045 +0000 UTC m=+18.266404525
I0828 10:50:15.300326       1 scheduler.go:454] Total Schedule Algo cumulative time:502.969502ms for 227
I0828 10:50:15.302222       1 scheduler.go:451] ScheduleAlgoTime 1.783255ms Start:2018-08-28 10:50:15.300433937 +0000 UTC m=+18.266543456 End:2018-08-28 10:50:15.302217226 +0000 UTC m=+18.268326711
I0828 10:50:15.302245       1 scheduler.go:454] Total Schedule Algo cumulative time:504.752757ms for 228
I0828 10:50:15.303983       1 scheduler.go:451] ScheduleAlgoTime 1.628042ms Start:2018-08-28 10:50:15.302348937 +0000 UTC m=+18.268458489 End:2018-08-28 10:50:15.30397705 +0000 UTC m=+18.270086531
I0828 10:50:15.304005       1 scheduler.go:454] Total Schedule Algo cumulative time:506.380799ms for 229
I0828 10:50:15.305828       1 scheduler.go:451] ScheduleAlgoTime 1.714955ms Start:2018-08-28 10:50:15.304107515 +0000 UTC m=+18.270217044 End:2018-08-28 10:50:15.305822512 +0000 UTC m=+18.271931999
I0828 10:50:15.305853       1 scheduler.go:454] Total Schedule Algo cumulative time:508.095754ms for 230
I0828 10:50:15.307417       1 scheduler.go:451] ScheduleAlgoTime 1.434787ms Start:2018-08-28 10:50:15.305975842 +0000 UTC m=+18.272085392 End:2018-08-28 10:50:15.307410698 +0000 UTC m=+18.273520179
I0828 10:50:15.307449       1 scheduler.go:454] Total Schedule Algo cumulative time:509.530541ms for 231
I0828 10:50:15.309206       1 scheduler.go:451] ScheduleAlgoTime 1.465186ms Start:2018-08-28 10:50:15.307735455 +0000 UTC m=+18.273844992 End:2018-08-28 10:50:15.309200695 +0000 UTC m=+18.275310178
I0828 10:50:15.309228       1 scheduler.go:454] Total Schedule Algo cumulative time:510.995727ms for 232
I0828 10:50:15.310960       1 scheduler.go:451] ScheduleAlgoTime 1.591492ms Start:2018-08-28 10:50:15.309363112 +0000 UTC m=+18.275472638 End:2018-08-28 10:50:15.310954648 +0000 UTC m=+18.277064130
I0828 10:50:15.310983       1 scheduler.go:454] Total Schedule Algo cumulative time:512.587219ms for 233
I0828 10:50:15.312712       1 scheduler.go:451] ScheduleAlgoTime 1.609471ms Start:2018-08-28 10:50:15.311095932 +0000 UTC m=+18.277205454 End:2018-08-28 10:50:15.312705445 +0000 UTC m=+18.278814925
I0828 10:50:15.312748       1 scheduler.go:454] Total Schedule Algo cumulative time:514.19669ms for 234
I0828 10:50:15.314607       1 scheduler.go:451] ScheduleAlgoTime 1.656466ms Start:2018-08-28 10:50:15.312946076 +0000 UTC m=+18.279055589 End:2018-08-28 10:50:15.314602573 +0000 UTC m=+18.280712055
I0828 10:50:15.314633       1 scheduler.go:454] Total Schedule Algo cumulative time:515.853156ms for 235
I0828 10:50:15.316387       1 scheduler.go:451] ScheduleAlgoTime 1.549625ms Start:2018-08-28 10:50:15.314833098 +0000 UTC m=+18.280942632 End:2018-08-28 10:50:15.316382773 +0000 UTC m=+18.282492257
I0828 10:50:15.316409       1 scheduler.go:454] Total Schedule Algo cumulative time:517.402781ms for 236
I0828 10:50:15.318199       1 scheduler.go:451] ScheduleAlgoTime 1.659123ms Start:2018-08-28 10:50:15.3165339 +0000 UTC m=+18.282643429 End:2018-08-28 10:50:15.318193072 +0000 UTC m=+18.284302552
I0828 10:50:15.318223       1 scheduler.go:454] Total Schedule Algo cumulative time:519.061904ms for 237
I0828 10:50:15.320031       1 scheduler.go:451] ScheduleAlgoTime 1.716651ms Start:2018-08-28 10:50:15.318307064 +0000 UTC m=+18.284416559 End:2018-08-28 10:50:15.320023711 +0000 UTC m=+18.286133210
I0828 10:50:15.320060       1 scheduler.go:454] Total Schedule Algo cumulative time:520.778555ms for 238
I0828 10:50:15.321951       1 scheduler.go:451] ScheduleAlgoTime 1.634904ms Start:2018-08-28 10:50:15.320309546 +0000 UTC m=+18.286419073 End:2018-08-28 10:50:15.321944497 +0000 UTC m=+18.288053977
I0828 10:50:15.321975       1 scheduler.go:454] Total Schedule Algo cumulative time:522.413459ms for 239
I0828 10:50:15.323803       1 scheduler.go:451] ScheduleAlgoTime 1.706604ms Start:2018-08-28 10:50:15.32209036 +0000 UTC m=+18.288199859 End:2018-08-28 10:50:15.323796983 +0000 UTC m=+18.289906463
I0828 10:50:15.323825       1 scheduler.go:454] Total Schedule Algo cumulative time:524.120063ms for 240
I0828 10:50:15.327905       1 scheduler.go:451] ScheduleAlgoTime 3.998827ms Start:2018-08-28 10:50:15.323898406 +0000 UTC m=+18.290007927 End:2018-08-28 10:50:15.327897231 +0000 UTC m=+18.294006754
I0828 10:50:15.328003       1 scheduler.go:454] Total Schedule Algo cumulative time:528.11889ms for 241
I0828 10:50:15.331069       1 scheduler.go:451] ScheduleAlgoTime 2.875498ms Start:2018-08-28 10:50:15.328187167 +0000 UTC m=+18.294296677 End:2018-08-28 10:50:15.33106269 +0000 UTC m=+18.297172175
I0828 10:50:15.331095       1 scheduler.go:454] Total Schedule Algo cumulative time:530.994388ms for 242
I0828 10:50:15.332783       1 scheduler.go:451] ScheduleAlgoTime 1.544083ms Start:2018-08-28 10:50:15.331231767 +0000 UTC m=+18.297341340 End:2018-08-28 10:50:15.332775941 +0000 UTC m=+18.298885423
I0828 10:50:15.332812       1 scheduler.go:454] Total Schedule Algo cumulative time:532.538471ms for 243
I0828 10:50:15.334450       1 scheduler.go:451] ScheduleAlgoTime 1.50972ms Start:2018-08-28 10:50:15.332935731 +0000 UTC m=+18.299045227 End:2018-08-28 10:50:15.334445467 +0000 UTC m=+18.300554947
I0828 10:50:15.334481       1 scheduler.go:454] Total Schedule Algo cumulative time:534.048191ms for 244
I0828 10:50:15.336243       1 scheduler.go:451] ScheduleAlgoTime 1.657324ms Start:2018-08-28 10:50:15.334580635 +0000 UTC m=+18.300690186 End:2018-08-28 10:50:15.336238027 +0000 UTC m=+18.302347510
I0828 10:50:15.336266       1 scheduler.go:454] Total Schedule Algo cumulative time:535.705515ms for 245
I0828 10:50:15.338147       1 scheduler.go:451] ScheduleAlgoTime 1.786322ms Start:2018-08-28 10:50:15.336346948 +0000 UTC m=+18.302456487 End:2018-08-28 10:50:15.338133329 +0000 UTC m=+18.304242809
I0828 10:50:15.338182       1 scheduler.go:454] Total Schedule Algo cumulative time:537.491837ms for 246
I0828 10:50:15.340125       1 scheduler.go:451] ScheduleAlgoTime 1.819381ms Start:2018-08-28 10:50:15.338300588 +0000 UTC m=+18.304410154 End:2018-08-28 10:50:15.340120055 +0000 UTC m=+18.306229535
I0828 10:50:15.340162       1 scheduler.go:454] Total Schedule Algo cumulative time:539.311218ms for 247
I0828 10:50:15.341998       1 scheduler.go:451] ScheduleAlgoTime 1.728812ms Start:2018-08-28 10:50:15.340264302 +0000 UTC m=+18.306373831 End:2018-08-28 10:50:15.341993162 +0000 UTC m=+18.308102643
I0828 10:50:15.342034       1 scheduler.go:454] Total Schedule Algo cumulative time:541.04003ms for 248
I0828 10:50:15.343534       1 scheduler.go:451] ScheduleAlgoTime 1.414456ms Start:2018-08-28 10:50:15.342114383 +0000 UTC m=+18.308223920 End:2018-08-28 10:50:15.343528892 +0000 UTC m=+18.309638376
I0828 10:50:15.343560       1 scheduler.go:454] Total Schedule Algo cumulative time:542.454486ms for 249
I0828 10:50:15.345200       1 scheduler.go:451] ScheduleAlgoTime 1.524481ms Start:2018-08-28 10:50:15.343669425 +0000 UTC m=+18.309778972 End:2018-08-28 10:50:15.345193974 +0000 UTC m=+18.311303453
I0828 10:50:15.345227       1 scheduler.go:454] Total Schedule Algo cumulative time:543.978967ms for 250
I0828 10:50:15.347028       1 scheduler.go:451] ScheduleAlgoTime 1.65825ms Start:2018-08-28 10:50:15.345364945 +0000 UTC m=+18.311474482 End:2018-08-28 10:50:15.347023251 +0000 UTC m=+18.313132732
I0828 10:50:15.347047       1 scheduler.go:454] Total Schedule Algo cumulative time:545.637217ms for 251
I0828 10:50:15.348877       1 scheduler.go:451] ScheduleAlgoTime 1.661913ms Start:2018-08-28 10:50:15.347209739 +0000 UTC m=+18.313319274 End:2018-08-28 10:50:15.348871703 +0000 UTC m=+18.314981187
I0828 10:50:15.348898       1 scheduler.go:454] Total Schedule Algo cumulative time:547.29913ms for 252
I0828 10:50:15.350713       1 scheduler.go:451] ScheduleAlgoTime 1.718271ms Start:2018-08-28 10:50:15.348988998 +0000 UTC m=+18.315098555 End:2018-08-28 10:50:15.350707345 +0000 UTC m=+18.316816826
I0828 10:50:15.350738       1 scheduler.go:454] Total Schedule Algo cumulative time:549.017401ms for 253
I0828 10:50:15.352303       1 scheduler.go:451] ScheduleAlgoTime 1.43854ms Start:2018-08-28 10:50:15.350859345 +0000 UTC m=+18.316968887 End:2018-08-28 10:50:15.352297946 +0000 UTC m=+18.318407427
I0828 10:50:15.352336       1 scheduler.go:454] Total Schedule Algo cumulative time:550.455941ms for 254
I0828 10:50:15.354023       1 scheduler.go:451] ScheduleAlgoTime 1.566848ms Start:2018-08-28 10:50:15.35245124 +0000 UTC m=+18.318560804 End:2018-08-28 10:50:15.354018172 +0000 UTC m=+18.320127652
I0828 10:50:15.354045       1 scheduler.go:454] Total Schedule Algo cumulative time:552.022789ms for 255
I0828 10:50:15.356092       1 scheduler.go:451] ScheduleAlgoTime 1.916258ms Start:2018-08-28 10:50:15.354166727 +0000 UTC m=+18.320276287 End:2018-08-28 10:50:15.356083053 +0000 UTC m=+18.322192545
I0828 10:50:15.356124       1 scheduler.go:454] Total Schedule Algo cumulative time:553.939047ms for 256
I0828 10:50:15.357831       1 scheduler.go:451] ScheduleAlgoTime 1.550151ms Start:2018-08-28 10:50:15.356272877 +0000 UTC m=+18.322382420 End:2018-08-28 10:50:15.357822951 +0000 UTC m=+18.323932571
I0828 10:50:15.357861       1 scheduler.go:454] Total Schedule Algo cumulative time:555.489198ms for 257
I0828 10:50:15.359907       1 scheduler.go:451] ScheduleAlgoTime 1.91582ms Start:2018-08-28 10:50:15.357984224 +0000 UTC m=+18.324093774 End:2018-08-28 10:50:15.359900105 +0000 UTC m=+18.326009594
I0828 10:50:15.359948       1 scheduler.go:454] Total Schedule Algo cumulative time:557.405018ms for 258
I0828 10:50:15.361828       1 scheduler.go:451] ScheduleAlgoTime 1.754631ms Start:2018-08-28 10:50:15.360065045 +0000 UTC m=+18.326174546 End:2018-08-28 10:50:15.361819611 +0000 UTC m=+18.327929177
I0828 10:50:15.361867       1 scheduler.go:454] Total Schedule Algo cumulative time:559.159649ms for 259
I0828 10:50:15.363604       1 scheduler.go:451] ScheduleAlgoTime 1.617185ms Start:2018-08-28 10:50:15.361981823 +0000 UTC m=+18.328091379 End:2018-08-28 10:50:15.363599085 +0000 UTC m=+18.329708564
I0828 10:50:15.363626       1 scheduler.go:454] Total Schedule Algo cumulative time:560.776834ms for 260
I0828 10:50:15.365340       1 scheduler.go:451] ScheduleAlgoTime 1.612679ms Start:2018-08-28 10:50:15.363722763 +0000 UTC m=+18.329832282 End:2018-08-28 10:50:15.365335479 +0000 UTC m=+18.331444961
I0828 10:50:15.365362       1 scheduler.go:454] Total Schedule Algo cumulative time:562.389513ms for 261
I0828 10:50:15.367061       1 scheduler.go:451] ScheduleAlgoTime 1.602062ms Start:2018-08-28 10:50:15.365453611 +0000 UTC m=+18.331563131 End:2018-08-28 10:50:15.367055712 +0000 UTC m=+18.333165193
I0828 10:50:15.367085       1 scheduler.go:454] Total Schedule Algo cumulative time:563.991575ms for 262
I0828 10:50:15.368788       1 scheduler.go:451] ScheduleAlgoTime 1.568131ms Start:2018-08-28 10:50:15.367214878 +0000 UTC m=+18.333324423 End:2018-08-28 10:50:15.368783073 +0000 UTC m=+18.334892554
I0828 10:50:15.368810       1 scheduler.go:454] Total Schedule Algo cumulative time:565.559706ms for 263
I0828 10:50:15.370539       1 scheduler.go:451] ScheduleAlgoTime 1.614611ms Start:2018-08-28 10:50:15.368918785 +0000 UTC m=+18.335028346 End:2018-08-28 10:50:15.370533477 +0000 UTC m=+18.336642957
I0828 10:50:15.370563       1 scheduler.go:454] Total Schedule Algo cumulative time:567.174317ms for 264
I0828 10:50:15.372314       1 scheduler.go:451] ScheduleAlgoTime 1.613215ms Start:2018-08-28 10:50:15.370695605 +0000 UTC m=+18.336805154 End:2018-08-28 10:50:15.372308887 +0000 UTC m=+18.338418369
I0828 10:50:15.372336       1 scheduler.go:454] Total Schedule Algo cumulative time:568.787532ms for 265
I0828 10:50:15.374046       1 scheduler.go:451] ScheduleAlgoTime 1.596922ms Start:2018-08-28 10:50:15.372444195 +0000 UTC m=+18.338553740 End:2018-08-28 10:50:15.374041183 +0000 UTC m=+18.340150662
I0828 10:50:15.374069       1 scheduler.go:454] Total Schedule Algo cumulative time:570.384454ms for 266
I0828 10:50:15.375948       1 scheduler.go:451] ScheduleAlgoTime 1.706637ms Start:2018-08-28 10:50:15.374236151 +0000 UTC m=+18.340345655 End:2018-08-28 10:50:15.375942812 +0000 UTC m=+18.342052292
I0828 10:50:15.375971       1 scheduler.go:454] Total Schedule Algo cumulative time:572.091091ms for 267
I0828 10:50:15.377801       1 scheduler.go:451] ScheduleAlgoTime 1.722372ms Start:2018-08-28 10:50:15.376073089 +0000 UTC m=+18.342182601 End:2018-08-28 10:50:15.377795493 +0000 UTC m=+18.343904973
I0828 10:50:15.377830       1 scheduler.go:454] Total Schedule Algo cumulative time:573.813463ms for 268
I0828 10:50:15.379468       1 scheduler.go:451] ScheduleAlgoTime 1.517483ms Start:2018-08-28 10:50:15.377943205 +0000 UTC m=+18.344052689 End:2018-08-28 10:50:15.379460517 +0000 UTC m=+18.345570172
I0828 10:50:15.379494       1 scheduler.go:454] Total Schedule Algo cumulative time:575.330946ms for 269
I0828 10:50:15.381416       1 scheduler.go:451] ScheduleAlgoTime 1.81233ms Start:2018-08-28 10:50:15.379598692 +0000 UTC m=+18.345708226 End:2018-08-28 10:50:15.381411078 +0000 UTC m=+18.347520556
I0828 10:50:15.381438       1 scheduler.go:454] Total Schedule Algo cumulative time:577.143276ms for 270
I0828 10:50:15.383053       1 scheduler.go:451] ScheduleAlgoTime 1.480448ms Start:2018-08-28 10:50:15.381565967 +0000 UTC m=+18.347675481 End:2018-08-28 10:50:15.38304645 +0000 UTC m=+18.349155929
I0828 10:50:15.383076       1 scheduler.go:454] Total Schedule Algo cumulative time:578.623724ms for 271
I0828 10:50:15.384972       1 scheduler.go:451] ScheduleAlgoTime 1.725362ms Start:2018-08-28 10:50:15.383239177 +0000 UTC m=+18.349348721 End:2018-08-28 10:50:15.384964587 +0000 UTC m=+18.351074083
I0828 10:50:15.385000       1 scheduler.go:454] Total Schedule Algo cumulative time:580.349086ms for 272
I0828 10:50:15.386841       1 scheduler.go:451] ScheduleAlgoTime 1.621688ms Start:2018-08-28 10:50:15.385213526 +0000 UTC m=+18.351323059 End:2018-08-28 10:50:15.386835267 +0000 UTC m=+18.352944747
I0828 10:50:15.386863       1 scheduler.go:454] Total Schedule Algo cumulative time:581.970774ms for 273
I0828 10:50:15.388710       1 scheduler.go:451] ScheduleAlgoTime 1.689619ms Start:2018-08-28 10:50:15.387015353 +0000 UTC m=+18.353124866 End:2018-08-28 10:50:15.388704999 +0000 UTC m=+18.354814485
I0828 10:50:15.388733       1 scheduler.go:454] Total Schedule Algo cumulative time:583.660393ms for 274
I0828 10:50:15.390481       1 scheduler.go:451] ScheduleAlgoTime 1.672274ms Start:2018-08-28 10:50:15.388802448 +0000 UTC m=+18.354911963 End:2018-08-28 10:50:15.390474756 +0000 UTC m=+18.356584237
I0828 10:50:15.390507       1 scheduler.go:454] Total Schedule Algo cumulative time:585.332667ms for 275
I0828 10:50:15.392355       1 scheduler.go:451] ScheduleAlgoTime 1.690694ms Start:2018-08-28 10:50:15.390658979 +0000 UTC m=+18.356768519 End:2018-08-28 10:50:15.39234973 +0000 UTC m=+18.358459213
I0828 10:50:15.392376       1 scheduler.go:454] Total Schedule Algo cumulative time:587.023361ms for 276
I0828 10:50:15.394226       1 scheduler.go:451] ScheduleAlgoTime 1.754775ms Start:2018-08-28 10:50:15.39246524 +0000 UTC m=+18.358574774 End:2018-08-28 10:50:15.39422007 +0000 UTC m=+18.360329549
I0828 10:50:15.394249       1 scheduler.go:454] Total Schedule Algo cumulative time:588.778136ms for 277
I0828 10:50:15.396129       1 scheduler.go:451] ScheduleAlgoTime 1.767087ms Start:2018-08-28 10:50:15.394353753 +0000 UTC m=+18.360463261 End:2018-08-28 10:50:15.396120774 +0000 UTC m=+18.362230348
I0828 10:50:15.396174       1 scheduler.go:454] Total Schedule Algo cumulative time:590.545223ms for 278
I0828 10:50:15.399745       1 scheduler.go:451] ScheduleAlgoTime 3.440527ms Start:2018-08-28 10:50:15.396297561 +0000 UTC m=+18.362407057 End:2018-08-28 10:50:15.399738103 +0000 UTC m=+18.365847584
I0828 10:50:15.399794       1 scheduler.go:454] Total Schedule Algo cumulative time:593.98575ms for 279
I0828 10:50:15.404060       1 scheduler.go:451] ScheduleAlgoTime 4.098999ms Start:2018-08-28 10:50:15.399953931 +0000 UTC m=+18.366063484 End:2018-08-28 10:50:15.404053001 +0000 UTC m=+18.370162483
I0828 10:50:15.404086       1 scheduler.go:454] Total Schedule Algo cumulative time:598.084749ms for 280
I0828 10:50:15.406032       1 scheduler.go:451] ScheduleAlgoTime 1.811182ms Start:2018-08-28 10:50:15.404214084 +0000 UTC m=+18.370323621 End:2018-08-28 10:50:15.406025322 +0000 UTC m=+18.372134803
I0828 10:50:15.406070       1 scheduler.go:454] Total Schedule Algo cumulative time:599.895931ms for 281
I0828 10:50:15.407995       1 scheduler.go:451] ScheduleAlgoTime 1.782562ms Start:2018-08-28 10:50:15.406204531 +0000 UTC m=+18.372314058 End:2018-08-28 10:50:15.407987118 +0000 UTC m=+18.374096620
I0828 10:50:15.408047       1 scheduler.go:454] Total Schedule Algo cumulative time:601.678493ms for 282
I0828 10:50:15.409841       1 scheduler.go:451] ScheduleAlgoTime 1.653794ms Start:2018-08-28 10:50:15.408180063 +0000 UTC m=+18.374289596 End:2018-08-28 10:50:15.409833905 +0000 UTC m=+18.375943390
I0828 10:50:15.409873       1 scheduler.go:454] Total Schedule Algo cumulative time:603.332287ms for 283
I0828 10:50:15.411638       1 scheduler.go:451] ScheduleAlgoTime 1.481426ms Start:2018-08-28 10:50:15.410150121 +0000 UTC m=+18.376259686 End:2018-08-28 10:50:15.411631629 +0000 UTC m=+18.377741112
I0828 10:50:15.411674       1 scheduler.go:454] Total Schedule Algo cumulative time:604.813713ms for 284
I0828 10:50:15.413309       1 scheduler.go:451] ScheduleAlgoTime 1.525662ms Start:2018-08-28 10:50:15.411777674 +0000 UTC m=+18.377887196 End:2018-08-28 10:50:15.413303377 +0000 UTC m=+18.379412858
I0828 10:50:15.413344       1 scheduler.go:454] Total Schedule Algo cumulative time:606.339375ms for 285
I0828 10:50:15.415230       1 scheduler.go:451] ScheduleAlgoTime 1.658028ms Start:2018-08-28 10:50:15.413566243 +0000 UTC m=+18.379675773 End:2018-08-28 10:50:15.41522432 +0000 UTC m=+18.381333801
I0828 10:50:15.415255       1 scheduler.go:454] Total Schedule Algo cumulative time:607.997403ms for 286
I0828 10:50:15.417059       1 scheduler.go:451] ScheduleAlgoTime 1.675719ms Start:2018-08-28 10:50:15.415374915 +0000 UTC m=+18.381484469 End:2018-08-28 10:50:15.417050681 +0000 UTC m=+18.383160188
I0828 10:50:15.417090       1 scheduler.go:454] Total Schedule Algo cumulative time:609.673122ms for 287
I0828 10:50:15.418820       1 scheduler.go:451] ScheduleAlgoTime 1.56103ms Start:2018-08-28 10:50:15.417254716 +0000 UTC m=+18.383364258 End:2018-08-28 10:50:15.418815807 +0000 UTC m=+18.384925288
I0828 10:50:15.418842       1 scheduler.go:454] Total Schedule Algo cumulative time:611.234152ms for 288
I0828 10:50:15.420655       1 scheduler.go:451] ScheduleAlgoTime 1.709856ms Start:2018-08-28 10:50:15.418940173 +0000 UTC m=+18.385049701 End:2018-08-28 10:50:15.420650077 +0000 UTC m=+18.386759557
I0828 10:50:15.420693       1 scheduler.go:454] Total Schedule Algo cumulative time:612.944008ms for 289
I0828 10:50:15.422237       1 scheduler.go:451] ScheduleAlgoTime 1.424007ms Start:2018-08-28 10:50:15.420802992 +0000 UTC m=+18.386912505 End:2018-08-28 10:50:15.422227032 +0000 UTC m=+18.388336512
I0828 10:50:15.422267       1 scheduler.go:454] Total Schedule Algo cumulative time:614.368015ms for 290
I0828 10:50:15.423986       1 scheduler.go:451] ScheduleAlgoTime 1.598825ms Start:2018-08-28 10:50:15.422379113 +0000 UTC m=+18.388488655 End:2018-08-28 10:50:15.423977998 +0000 UTC m=+18.390087480
I0828 10:50:15.424015       1 scheduler.go:454] Total Schedule Algo cumulative time:615.96684ms for 291
I0828 10:50:15.425671       1 scheduler.go:451] ScheduleAlgoTime 1.53825ms Start:2018-08-28 10:50:15.424127793 +0000 UTC m=+18.390237340 End:2018-08-28 10:50:15.425666111 +0000 UTC m=+18.391775590
I0828 10:50:15.425693       1 scheduler.go:454] Total Schedule Algo cumulative time:617.50509ms for 292
I0828 10:50:15.427348       1 scheduler.go:451] ScheduleAlgoTime 1.554971ms Start:2018-08-28 10:50:15.42578834 +0000 UTC m=+18.391897895 End:2018-08-28 10:50:15.427343387 +0000 UTC m=+18.393452866
I0828 10:50:15.427370       1 scheduler.go:454] Total Schedule Algo cumulative time:619.060061ms for 293
I0828 10:50:15.429255       1 scheduler.go:451] ScheduleAlgoTime 1.779965ms Start:2018-08-28 10:50:15.427469502 +0000 UTC m=+18.393579040 End:2018-08-28 10:50:15.429249522 +0000 UTC m=+18.395359005
I0828 10:50:15.429291       1 scheduler.go:454] Total Schedule Algo cumulative time:620.840026ms for 294
I0828 10:50:15.431159       1 scheduler.go:451] ScheduleAlgoTime 1.733657ms Start:2018-08-28 10:50:15.429419609 +0000 UTC m=+18.395529121 End:2018-08-28 10:50:15.431153297 +0000 UTC m=+18.397262778
I0828 10:50:15.431181       1 scheduler.go:454] Total Schedule Algo cumulative time:622.573683ms for 295
I0828 10:50:15.432926       1 scheduler.go:451] ScheduleAlgoTime 1.639816ms Start:2018-08-28 10:50:15.431281075 +0000 UTC m=+18.397390584 End:2018-08-28 10:50:15.432920917 +0000 UTC m=+18.399030400
I0828 10:50:15.432959       1 scheduler.go:454] Total Schedule Algo cumulative time:624.213499ms for 296
I0828 10:50:15.434658       1 scheduler.go:451] ScheduleAlgoTime 1.581262ms Start:2018-08-28 10:50:15.433072438 +0000 UTC m=+18.399181966 End:2018-08-28 10:50:15.434653746 +0000 UTC m=+18.400763228
I0828 10:50:15.434681       1 scheduler.go:454] Total Schedule Algo cumulative time:625.794761ms for 297
I0828 10:50:15.436400       1 scheduler.go:451] ScheduleAlgoTime 1.558663ms Start:2018-08-28 10:50:15.434837206 +0000 UTC m=+18.400946734 End:2018-08-28 10:50:15.436395912 +0000 UTC m=+18.402505397
I0828 10:50:15.436420       1 scheduler.go:454] Total Schedule Algo cumulative time:627.353424ms for 298
I0828 10:50:15.438067       1 scheduler.go:451] ScheduleAlgoTime 1.515918ms Start:2018-08-28 10:50:15.43654469 +0000 UTC m=+18.402654224 End:2018-08-28 10:50:15.438060663 +0000 UTC m=+18.404170142
I0828 10:50:15.438091       1 scheduler.go:454] Total Schedule Algo cumulative time:628.869342ms for 299
I0828 10:50:15.439866       1 scheduler.go:451] ScheduleAlgoTime 1.639441ms Start:2018-08-28 10:50:15.438221593 +0000 UTC m=+18.404331110 End:2018-08-28 10:50:15.439861066 +0000 UTC m=+18.405970551
I0828 10:50:15.439887       1 scheduler.go:454] Total Schedule Algo cumulative time:630.508783ms for 300
I0828 10:50:15.441524       1 scheduler.go:451] ScheduleAlgoTime 1.495419ms Start:2018-08-28 10:50:15.440024401 +0000 UTC m=+18.406133933 End:2018-08-28 10:50:15.441519872 +0000 UTC m=+18.407629352
I0828 10:50:15.441558       1 scheduler.go:454] Total Schedule Algo cumulative time:632.004202ms for 301
I0828 10:50:15.443184       1 scheduler.go:451] ScheduleAlgoTime 1.52284ms Start:2018-08-28 10:50:15.441656426 +0000 UTC m=+18.407765923 End:2018-08-28 10:50:15.443179279 +0000 UTC m=+18.409288763
I0828 10:50:15.443205       1 scheduler.go:454] Total Schedule Algo cumulative time:633.527042ms for 302
I0828 10:50:15.444732       1 scheduler.go:451] ScheduleAlgoTime 1.430948ms Start:2018-08-28 10:50:15.443295967 +0000 UTC m=+18.409405496 End:2018-08-28 10:50:15.444726959 +0000 UTC m=+18.410836444
I0828 10:50:15.444756       1 scheduler.go:454] Total Schedule Algo cumulative time:634.95799ms for 303
I0828 10:50:15.446643       1 scheduler.go:451] ScheduleAlgoTime 1.779378ms Start:2018-08-28 10:50:15.444858961 +0000 UTC m=+18.410968509 End:2018-08-28 10:50:15.446638407 +0000 UTC m=+18.412747887
I0828 10:50:15.446669       1 scheduler.go:454] Total Schedule Algo cumulative time:636.737368ms for 304
I0828 10:50:15.448279       1 scheduler.go:451] ScheduleAlgoTime 1.491818ms Start:2018-08-28 10:50:15.446770651 +0000 UTC m=+18.412880174 End:2018-08-28 10:50:15.448262512 +0000 UTC m=+18.414371992
I0828 10:50:15.448303       1 scheduler.go:454] Total Schedule Algo cumulative time:638.229186ms for 305
I0828 10:50:15.449992       1 scheduler.go:451] ScheduleAlgoTime 1.574915ms Start:2018-08-28 10:50:15.448412126 +0000 UTC m=+18.414521650 End:2018-08-28 10:50:15.449987085 +0000 UTC m=+18.416096565
I0828 10:50:15.450015       1 scheduler.go:454] Total Schedule Algo cumulative time:639.804101ms for 306
I0828 10:50:15.451610       1 scheduler.go:451] ScheduleAlgoTime 1.493905ms Start:2018-08-28 10:50:15.450111362 +0000 UTC m=+18.416220905 End:2018-08-28 10:50:15.451605324 +0000 UTC m=+18.417714810
I0828 10:50:15.451632       1 scheduler.go:454] Total Schedule Algo cumulative time:641.298006ms for 307
I0828 10:50:15.453278       1 scheduler.go:451] ScheduleAlgoTime 1.536659ms Start:2018-08-28 10:50:15.451735935 +0000 UTC m=+18.417845471 End:2018-08-28 10:50:15.453272643 +0000 UTC m=+18.419382130
I0828 10:50:15.453302       1 scheduler.go:454] Total Schedule Algo cumulative time:642.834665ms for 308
I0828 10:50:15.454983       1 scheduler.go:451] ScheduleAlgoTime 1.542686ms Start:2018-08-28 10:50:15.453435182 +0000 UTC m=+18.419544714 End:2018-08-28 10:50:15.454977919 +0000 UTC m=+18.421087400
I0828 10:50:15.455006       1 scheduler.go:454] Total Schedule Algo cumulative time:644.377351ms for 309
I0828 10:50:15.456892       1 scheduler.go:451] ScheduleAlgoTime 1.757ms Start:2018-08-28 10:50:15.455129603 +0000 UTC m=+18.421239151 End:2018-08-28 10:50:15.45688667 +0000 UTC m=+18.422996151
I0828 10:50:15.456915       1 scheduler.go:454] Total Schedule Algo cumulative time:646.134351ms for 310
I0828 10:50:15.458774       1 scheduler.go:451] ScheduleAlgoTime 1.738748ms Start:2018-08-28 10:50:15.457031056 +0000 UTC m=+18.423140567 End:2018-08-28 10:50:15.458769831 +0000 UTC m=+18.424879315
I0828 10:50:15.458796       1 scheduler.go:454] Total Schedule Algo cumulative time:647.873099ms for 311
I0828 10:50:15.460511       1 scheduler.go:451] ScheduleAlgoTime 1.614084ms Start:2018-08-28 10:50:15.458888947 +0000 UTC m=+18.424998459 End:2018-08-28 10:50:15.460502932 +0000 UTC m=+18.426612543
I0828 10:50:15.460552       1 scheduler.go:454] Total Schedule Algo cumulative time:649.487183ms for 312
I0828 10:50:15.462309       1 scheduler.go:451] ScheduleAlgoTime 1.633408ms Start:2018-08-28 10:50:15.460669826 +0000 UTC m=+18.426779387 End:2018-08-28 10:50:15.462303315 +0000 UTC m=+18.428412795
I0828 10:50:15.462329       1 scheduler.go:454] Total Schedule Algo cumulative time:651.120591ms for 313
I0828 10:50:15.464121       1 scheduler.go:451] ScheduleAlgoTime 1.680854ms Start:2018-08-28 10:50:15.462434177 +0000 UTC m=+18.428543687 End:2018-08-28 10:50:15.46411506 +0000 UTC m=+18.430224541
I0828 10:50:15.464150       1 scheduler.go:454] Total Schedule Algo cumulative time:652.801445ms for 314
I0828 10:50:15.465897       1 scheduler.go:451] ScheduleAlgoTime 1.648802ms Start:2018-08-28 10:50:15.464242312 +0000 UTC m=+18.430351849 End:2018-08-28 10:50:15.465891171 +0000 UTC m=+18.432000651
I0828 10:50:15.465919       1 scheduler.go:454] Total Schedule Algo cumulative time:654.450247ms for 315
I0828 10:50:15.467629       1 scheduler.go:451] ScheduleAlgoTime 1.54743ms Start:2018-08-28 10:50:15.466074647 +0000 UTC m=+18.432184184 End:2018-08-28 10:50:15.467622127 +0000 UTC m=+18.433731614
I0828 10:50:15.467656       1 scheduler.go:454] Total Schedule Algo cumulative time:655.997677ms for 316
I0828 10:50:15.469286       1 scheduler.go:451] ScheduleAlgoTime 1.519838ms Start:2018-08-28 10:50:15.467760567 +0000 UTC m=+18.433870099 End:2018-08-28 10:50:15.469280456 +0000 UTC m=+18.435389937
I0828 10:50:15.469306       1 scheduler.go:454] Total Schedule Algo cumulative time:657.517515ms for 317
I0828 10:50:15.471049       1 scheduler.go:451] ScheduleAlgoTime 1.630652ms Start:2018-08-28 10:50:15.469412614 +0000 UTC m=+18.435522109 End:2018-08-28 10:50:15.471043278 +0000 UTC m=+18.437152761
I0828 10:50:15.471070       1 scheduler.go:454] Total Schedule Algo cumulative time:659.148167ms for 318
I0828 10:50:15.473158       1 scheduler.go:451] ScheduleAlgoTime 1.98741ms Start:2018-08-28 10:50:15.471164516 +0000 UTC m=+18.437274081 End:2018-08-28 10:50:15.473151864 +0000 UTC m=+18.439261491
I0828 10:50:15.473181       1 scheduler.go:454] Total Schedule Algo cumulative time:661.135577ms for 319
I0828 10:50:15.478364       1 scheduler.go:451] ScheduleAlgoTime 5.005396ms Start:2018-08-28 10:50:15.473349964 +0000 UTC m=+18.439459473 End:2018-08-28 10:50:15.478355387 +0000 UTC m=+18.444464869
I0828 10:50:15.478398       1 scheduler.go:454] Total Schedule Algo cumulative time:666.140973ms for 320
I0828 10:50:15.480100       1 scheduler.go:451] ScheduleAlgoTime 1.571949ms Start:2018-08-28 10:50:15.478522966 +0000 UTC m=+18.444632517 End:2018-08-28 10:50:15.480094987 +0000 UTC m=+18.446204466
I0828 10:50:15.480119       1 scheduler.go:454] Total Schedule Algo cumulative time:667.712922ms for 321
I0828 10:50:15.481696       1 scheduler.go:451] ScheduleAlgoTime 1.455892ms Start:2018-08-28 10:50:15.480235242 +0000 UTC m=+18.446344724 End:2018-08-28 10:50:15.481691136 +0000 UTC m=+18.447800616
I0828 10:50:15.481727       1 scheduler.go:454] Total Schedule Algo cumulative time:669.168814ms for 322
I0828 10:50:15.483591       1 scheduler.go:451] ScheduleAlgoTime 1.710568ms Start:2018-08-28 10:50:15.48187262 +0000 UTC m=+18.447982185 End:2018-08-28 10:50:15.483583263 +0000 UTC m=+18.449692753
I0828 10:50:15.483623       1 scheduler.go:454] Total Schedule Algo cumulative time:670.879382ms for 323
I0828 10:50:15.485587       1 scheduler.go:451] ScheduleAlgoTime 1.834375ms Start:2018-08-28 10:50:15.483746281 +0000 UTC m=+18.449855794 End:2018-08-28 10:50:15.485580688 +0000 UTC m=+18.451690169
I0828 10:50:15.485611       1 scheduler.go:454] Total Schedule Algo cumulative time:672.713757ms for 324
I0828 10:50:15.487652       1 scheduler.go:451] ScheduleAlgoTime 1.898145ms Start:2018-08-28 10:50:15.485748774 +0000 UTC m=+18.451858303 End:2018-08-28 10:50:15.48764696 +0000 UTC m=+18.453756448
I0828 10:50:15.487681       1 scheduler.go:454] Total Schedule Algo cumulative time:674.611902ms for 325
I0828 10:50:15.489434       1 scheduler.go:451] ScheduleAlgoTime 1.655013ms Start:2018-08-28 10:50:15.48776906 +0000 UTC m=+18.453878553 End:2018-08-28 10:50:15.489423993 +0000 UTC m=+18.455533566
I0828 10:50:15.489463       1 scheduler.go:454] Total Schedule Algo cumulative time:676.266915ms for 326
I0828 10:50:15.491105       1 scheduler.go:451] ScheduleAlgoTime 1.501837ms Start:2018-08-28 10:50:15.489595035 +0000 UTC m=+18.455704578 End:2018-08-28 10:50:15.491096781 +0000 UTC m=+18.457206415
I0828 10:50:15.491136       1 scheduler.go:454] Total Schedule Algo cumulative time:677.768752ms for 327
I0828 10:50:15.493073       1 scheduler.go:451] ScheduleAlgoTime 1.802891ms Start:2018-08-28 10:50:15.491265067 +0000 UTC m=+18.457374599 End:2018-08-28 10:50:15.49306801 +0000 UTC m=+18.459177490
I0828 10:50:15.493119       1 scheduler.go:454] Total Schedule Algo cumulative time:679.571643ms for 328
I0828 10:50:15.494731       1 scheduler.go:451] ScheduleAlgoTime 1.493445ms Start:2018-08-28 10:50:15.493233214 +0000 UTC m=+18.459342712 End:2018-08-28 10:50:15.494726676 +0000 UTC m=+18.460836157
I0828 10:50:15.494762       1 scheduler.go:454] Total Schedule Algo cumulative time:681.065088ms for 329
I0828 10:50:15.496274       1 scheduler.go:451] ScheduleAlgoTime 1.408212ms Start:2018-08-28 10:50:15.494861058 +0000 UTC m=+18.460970593 End:2018-08-28 10:50:15.496269324 +0000 UTC m=+18.462378805
I0828 10:50:15.496298       1 scheduler.go:454] Total Schedule Algo cumulative time:682.4733ms for 330
I0828 10:50:15.498032       1 scheduler.go:451] ScheduleAlgoTime 1.614391ms Start:2018-08-28 10:50:15.496413243 +0000 UTC m=+18.462522745 End:2018-08-28 10:50:15.498027655 +0000 UTC m=+18.464137136
I0828 10:50:15.498057       1 scheduler.go:454] Total Schedule Algo cumulative time:684.087691ms for 331
I0828 10:50:15.499720       1 scheduler.go:451] ScheduleAlgoTime 1.526584ms Start:2018-08-28 10:50:15.49818699 +0000 UTC m=+18.464296484 End:2018-08-28 10:50:15.499713587 +0000 UTC m=+18.465823068
I0828 10:50:15.499741       1 scheduler.go:454] Total Schedule Algo cumulative time:685.614275ms for 332
I0828 10:50:15.501569       1 scheduler.go:451] ScheduleAlgoTime 1.701658ms Start:2018-08-28 10:50:15.499860642 +0000 UTC m=+18.465970144 End:2018-08-28 10:50:15.501562318 +0000 UTC m=+18.467671802
I0828 10:50:15.501603       1 scheduler.go:454] Total Schedule Algo cumulative time:687.315933ms for 333
I0828 10:50:15.503474       1 scheduler.go:451] ScheduleAlgoTime 1.73931ms Start:2018-08-28 10:50:15.501728374 +0000 UTC m=+18.467837912 End:2018-08-28 10:50:15.503467737 +0000 UTC m=+18.469577222
I0828 10:50:15.503502       1 scheduler.go:454] Total Schedule Algo cumulative time:689.055243ms for 334
I0828 10:50:15.505307       1 scheduler.go:451] ScheduleAlgoTime 1.663331ms Start:2018-08-28 10:50:15.503638199 +0000 UTC m=+18.469747714 End:2018-08-28 10:50:15.505301564 +0000 UTC m=+18.471411045
I0828 10:50:15.505332       1 scheduler.go:454] Total Schedule Algo cumulative time:690.718574ms for 335
I0828 10:50:15.507036       1 scheduler.go:451] ScheduleAlgoTime 1.612304ms Start:2018-08-28 10:50:15.505417816 +0000 UTC m=+18.471527366 End:2018-08-28 10:50:15.507030191 +0000 UTC m=+18.473139670
I0828 10:50:15.507057       1 scheduler.go:454] Total Schedule Algo cumulative time:692.330878ms for 336
I0828 10:50:15.508763       1 scheduler.go:451] ScheduleAlgoTime 1.566591ms Start:2018-08-28 10:50:15.507192445 +0000 UTC m=+18.473301986 End:2018-08-28 10:50:15.508759098 +0000 UTC m=+18.474868577
I0828 10:50:15.508785       1 scheduler.go:454] Total Schedule Algo cumulative time:693.897469ms for 337
I0828 10:50:15.510601       1 scheduler.go:451] ScheduleAlgoTime 1.653178ms Start:2018-08-28 10:50:15.508942851 +0000 UTC m=+18.475052417 End:2018-08-28 10:50:15.510596115 +0000 UTC m=+18.476705595
I0828 10:50:15.510627       1 scheduler.go:454] Total Schedule Algo cumulative time:695.550647ms for 338
I0828 10:50:15.512328       1 scheduler.go:451] ScheduleAlgoTime 1.559472ms Start:2018-08-28 10:50:15.510762519 +0000 UTC m=+18.476872052 End:2018-08-28 10:50:15.512322044 +0000 UTC m=+18.478431524
I0828 10:50:15.512363       1 scheduler.go:454] Total Schedule Algo cumulative time:697.110119ms for 339
I0828 10:50:15.514072       1 scheduler.go:451] ScheduleAlgoTime 1.571579ms Start:2018-08-28 10:50:15.512496045 +0000 UTC m=+18.478605577 End:2018-08-28 10:50:15.514067672 +0000 UTC m=+18.480177156
I0828 10:50:15.514096       1 scheduler.go:454] Total Schedule Algo cumulative time:698.681698ms for 340
I0828 10:50:15.515944       1 scheduler.go:451] ScheduleAlgoTime 1.728693ms Start:2018-08-28 10:50:15.514211113 +0000 UTC m=+18.480320640 End:2018-08-28 10:50:15.515939852 +0000 UTC m=+18.482049333
I0828 10:50:15.515964       1 scheduler.go:454] Total Schedule Algo cumulative time:700.410391ms for 341
I0828 10:50:15.517656       1 scheduler.go:451] ScheduleAlgoTime 1.553854ms Start:2018-08-28 10:50:15.516093961 +0000 UTC m=+18.482203520 End:2018-08-28 10:50:15.517647885 +0000 UTC m=+18.483757374
I0828 10:50:15.517679       1 scheduler.go:454] Total Schedule Algo cumulative time:701.964245ms for 342
I0828 10:50:15.519618       1 scheduler.go:451] ScheduleAlgoTime 1.857559ms Start:2018-08-28 10:50:15.517754021 +0000 UTC m=+18.483863581 End:2018-08-28 10:50:15.519611659 +0000 UTC m=+18.485721140
I0828 10:50:15.519638       1 scheduler.go:454] Total Schedule Algo cumulative time:703.821804ms for 343
I0828 10:50:15.521300       1 scheduler.go:451] ScheduleAlgoTime 1.589417ms Start:2018-08-28 10:50:15.519705317 +0000 UTC m=+18.485814876 End:2018-08-28 10:50:15.521294812 +0000 UTC m=+18.487404293
I0828 10:50:15.521333       1 scheduler.go:454] Total Schedule Algo cumulative time:705.411221ms for 344
I0828 10:50:15.522780       1 scheduler.go:451] ScheduleAlgoTime 1.334145ms Start:2018-08-28 10:50:15.521442209 +0000 UTC m=+18.487551747 End:2018-08-28 10:50:15.522776412 +0000 UTC m=+18.488885892
I0828 10:50:15.522800       1 scheduler.go:454] Total Schedule Algo cumulative time:706.745366ms for 345
I0828 10:50:15.524486       1 scheduler.go:451] ScheduleAlgoTime 1.553375ms Start:2018-08-28 10:50:15.52292655 +0000 UTC m=+18.489036069 End:2018-08-28 10:50:15.524479962 +0000 UTC m=+18.490589444
I0828 10:50:15.524517       1 scheduler.go:454] Total Schedule Algo cumulative time:708.298741ms for 346
I0828 10:50:15.526104       1 scheduler.go:451] ScheduleAlgoTime 1.434232ms Start:2018-08-28 10:50:15.524663918 +0000 UTC m=+18.490773442 End:2018-08-28 10:50:15.52609819 +0000 UTC m=+18.492207674
I0828 10:50:15.526127       1 scheduler.go:454] Total Schedule Algo cumulative time:709.732973ms for 347
I0828 10:50:15.527821       1 scheduler.go:451] ScheduleAlgoTime 1.551667ms Start:2018-08-28 10:50:15.526263932 +0000 UTC m=+18.492373469 End:2018-08-28 10:50:15.527815655 +0000 UTC m=+18.493925136
I0828 10:50:15.527854       1 scheduler.go:454] Total Schedule Algo cumulative time:711.28464ms for 348
I0828 10:50:15.529584       1 scheduler.go:451] ScheduleAlgoTime 1.57816ms Start:2018-08-28 10:50:15.528000208 +0000 UTC m=+18.494109739 End:2018-08-28 10:50:15.529578418 +0000 UTC m=+18.495687899
I0828 10:50:15.529608       1 scheduler.go:454] Total Schedule Algo cumulative time:712.8628ms for 349
I0828 10:50:15.531308       1 scheduler.go:451] ScheduleAlgoTime 1.578097ms Start:2018-08-28 10:50:15.529724749 +0000 UTC m=+18.495834252 End:2018-08-28 10:50:15.53130287 +0000 UTC m=+18.497412349
I0828 10:50:15.531330       1 scheduler.go:454] Total Schedule Algo cumulative time:714.440897ms for 350
I0828 10:50:15.532860       1 scheduler.go:451] ScheduleAlgoTime 1.405746ms Start:2018-08-28 10:50:15.53144939 +0000 UTC m=+18.497558892 End:2018-08-28 10:50:15.532855156 +0000 UTC m=+18.498964638
I0828 10:50:15.532881       1 scheduler.go:454] Total Schedule Algo cumulative time:715.846643ms for 351
I0828 10:50:15.534633       1 scheduler.go:451] ScheduleAlgoTime 1.63471ms Start:2018-08-28 10:50:15.532992911 +0000 UTC m=+18.499102425 End:2018-08-28 10:50:15.534627653 +0000 UTC m=+18.500737135
I0828 10:50:15.534656       1 scheduler.go:454] Total Schedule Algo cumulative time:717.481353ms for 352
I0828 10:50:15.536669       1 scheduler.go:451] ScheduleAlgoTime 1.875513ms Start:2018-08-28 10:50:15.534782093 +0000 UTC m=+18.500891623 End:2018-08-28 10:50:15.536657617 +0000 UTC m=+18.502767136
I0828 10:50:15.536701       1 scheduler.go:454] Total Schedule Algo cumulative time:719.356866ms for 353
I0828 10:50:15.538383       1 scheduler.go:451] ScheduleAlgoTime 1.525627ms Start:2018-08-28 10:50:15.536852091 +0000 UTC m=+18.502961638 End:2018-08-28 10:50:15.538377787 +0000 UTC m=+18.504487265
I0828 10:50:15.538405       1 scheduler.go:454] Total Schedule Algo cumulative time:720.882493ms for 354
I0828 10:50:15.540047       1 scheduler.go:451] ScheduleAlgoTime 1.515315ms Start:2018-08-28 10:50:15.538526245 +0000 UTC m=+18.504635786 End:2018-08-28 10:50:15.540041621 +0000 UTC m=+18.506151101
I0828 10:50:15.540067       1 scheduler.go:454] Total Schedule Algo cumulative time:722.397808ms for 355
I0828 10:50:15.541892       1 scheduler.go:451] ScheduleAlgoTime 1.650804ms Start:2018-08-28 10:50:15.540236212 +0000 UTC m=+18.506345749 End:2018-08-28 10:50:15.541887073 +0000 UTC m=+18.507996553
I0828 10:50:15.541913       1 scheduler.go:454] Total Schedule Algo cumulative time:724.048612ms for 356
I0828 10:50:15.543733       1 scheduler.go:451] ScheduleAlgoTime 1.687641ms Start:2018-08-28 10:50:15.542039345 +0000 UTC m=+18.508148882 End:2018-08-28 10:50:15.543727039 +0000 UTC m=+18.509836523
I0828 10:50:15.543753       1 scheduler.go:454] Total Schedule Algo cumulative time:725.736253ms for 357
I0828 10:50:15.545559       1 scheduler.go:451] ScheduleAlgoTime 1.6832ms Start:2018-08-28 10:50:15.543869266 +0000 UTC m=+18.509978801 End:2018-08-28 10:50:15.545552516 +0000 UTC m=+18.511662001
I0828 10:50:15.545584       1 scheduler.go:454] Total Schedule Algo cumulative time:727.419453ms for 358
I0828 10:50:15.547426       1 scheduler.go:451] ScheduleAlgoTime 1.65811ms Start:2018-08-28 10:50:15.545762545 +0000 UTC m=+18.511872044 End:2018-08-28 10:50:15.54742067 +0000 UTC m=+18.513530154
I0828 10:50:15.547448       1 scheduler.go:454] Total Schedule Algo cumulative time:729.077563ms for 359
I0828 10:50:15.549377       1 scheduler.go:451] ScheduleAlgoTime 1.803317ms Start:2018-08-28 10:50:15.547568702 +0000 UTC m=+18.513678259 End:2018-08-28 10:50:15.54937209 +0000 UTC m=+18.515481576
I0828 10:50:15.549400       1 scheduler.go:454] Total Schedule Algo cumulative time:730.88088ms for 360
I0828 10:50:15.552975       1 scheduler.go:451] ScheduleAlgoTime 3.385368ms Start:2018-08-28 10:50:15.549584059 +0000 UTC m=+18.515693574 End:2018-08-28 10:50:15.552969462 +0000 UTC m=+18.519078942
I0828 10:50:15.553046       1 scheduler.go:454] Total Schedule Algo cumulative time:734.266248ms for 361
I0828 10:50:15.556304       1 scheduler.go:451] ScheduleAlgoTime 3.021324ms Start:2018-08-28 10:50:15.553277085 +0000 UTC m=+18.519386593 End:2018-08-28 10:50:15.556298436 +0000 UTC m=+18.522407917
I0828 10:50:15.556330       1 scheduler.go:454] Total Schedule Algo cumulative time:737.287572ms for 362
I0828 10:50:15.558191       1 scheduler.go:451] ScheduleAlgoTime 1.745622ms Start:2018-08-28 10:50:15.556441454 +0000 UTC m=+18.522550979 End:2018-08-28 10:50:15.558187121 +0000 UTC m=+18.524296601
I0828 10:50:15.558213       1 scheduler.go:454] Total Schedule Algo cumulative time:739.033194ms for 363
I0828 10:50:15.559968       1 scheduler.go:451] ScheduleAlgoTime 1.61804ms Start:2018-08-28 10:50:15.558345244 +0000 UTC m=+18.524454775 End:2018-08-28 10:50:15.559963335 +0000 UTC m=+18.526072815
I0828 10:50:15.559989       1 scheduler.go:454] Total Schedule Algo cumulative time:740.651234ms for 364
I0828 10:50:15.561664       1 scheduler.go:451] ScheduleAlgoTime 1.561624ms Start:2018-08-28 10:50:15.560097834 +0000 UTC m=+18.526207365 End:2018-08-28 10:50:15.561659507 +0000 UTC m=+18.527768989
I0828 10:50:15.561691       1 scheduler.go:454] Total Schedule Algo cumulative time:742.212858ms for 365
I0828 10:50:15.563492       1 scheduler.go:451] ScheduleAlgoTime 1.614528ms Start:2018-08-28 10:50:15.561872361 +0000 UTC m=+18.527981870 End:2018-08-28 10:50:15.563486917 +0000 UTC m=+18.529596398
I0828 10:50:15.563529       1 scheduler.go:454] Total Schedule Algo cumulative time:743.827386ms for 366
I0828 10:50:15.565325       1 scheduler.go:451] ScheduleAlgoTime 1.662641ms Start:2018-08-28 10:50:15.563654856 +0000 UTC m=+18.529764389 End:2018-08-28 10:50:15.565317549 +0000 UTC m=+18.531427030
I0828 10:50:15.565366       1 scheduler.go:454] Total Schedule Algo cumulative time:745.490027ms for 367
I0828 10:50:15.567146       1 scheduler.go:451] ScheduleAlgoTime 1.647469ms Start:2018-08-28 10:50:15.565487419 +0000 UTC m=+18.531596948 End:2018-08-28 10:50:15.56713492 +0000 UTC m=+18.533244417
I0828 10:50:15.567169       1 scheduler.go:454] Total Schedule Algo cumulative time:747.137496ms for 368
I0828 10:50:15.568852       1 scheduler.go:451] ScheduleAlgoTime 1.512295ms Start:2018-08-28 10:50:15.567334885 +0000 UTC m=+18.533444378 End:2018-08-28 10:50:15.56884719 +0000 UTC m=+18.534956673
I0828 10:50:15.568876       1 scheduler.go:454] Total Schedule Algo cumulative time:748.649791ms for 369
I0828 10:50:15.570550       1 scheduler.go:451] ScheduleAlgoTime 1.494435ms Start:2018-08-28 10:50:15.569051582 +0000 UTC m=+18.535161092 End:2018-08-28 10:50:15.570546047 +0000 UTC m=+18.536655527
I0828 10:50:15.570570       1 scheduler.go:454] Total Schedule Algo cumulative time:750.144226ms for 370
I0828 10:50:15.572221       1 scheduler.go:451] ScheduleAlgoTime 1.55498ms Start:2018-08-28 10:50:15.570662014 +0000 UTC m=+18.536771512 End:2018-08-28 10:50:15.572217012 +0000 UTC m=+18.538326492
I0828 10:50:15.572242       1 scheduler.go:454] Total Schedule Algo cumulative time:751.699206ms for 371
I0828 10:50:15.573859       1 scheduler.go:451] ScheduleAlgoTime 1.52117ms Start:2018-08-28 10:50:15.572332684 +0000 UTC m=+18.538442216 End:2018-08-28 10:50:15.573853898 +0000 UTC m=+18.539963386
I0828 10:50:15.573880       1 scheduler.go:454] Total Schedule Algo cumulative time:753.220376ms for 372
I0828 10:50:15.575534       1 scheduler.go:451] ScheduleAlgoTime 1.558989ms Start:2018-08-28 10:50:15.573967943 +0000 UTC m=+18.540077490 End:2018-08-28 10:50:15.575526991 +0000 UTC m=+18.541636479
I0828 10:50:15.575560       1 scheduler.go:454] Total Schedule Algo cumulative time:754.779365ms for 373
I0828 10:50:15.577299       1 scheduler.go:451] ScheduleAlgoTime 1.627938ms Start:2018-08-28 10:50:15.575665503 +0000 UTC m=+18.541775064 End:2018-08-28 10:50:15.577293521 +0000 UTC m=+18.543403002
I0828 10:50:15.577324       1 scheduler.go:454] Total Schedule Algo cumulative time:756.407303ms for 374
I0828 10:50:15.579055       1 scheduler.go:451] ScheduleAlgoTime 1.590891ms Start:2018-08-28 10:50:15.577459428 +0000 UTC m=+18.543568944 End:2018-08-28 10:50:15.579050351 +0000 UTC m=+18.545159835
I0828 10:50:15.579075       1 scheduler.go:454] Total Schedule Algo cumulative time:757.998194ms for 375
I0828 10:50:15.580666       1 scheduler.go:451] ScheduleAlgoTime 1.46727ms Start:2018-08-28 10:50:15.579194029 +0000 UTC m=+18.545303553 End:2018-08-28 10:50:15.580661339 +0000 UTC m=+18.546770823
I0828 10:50:15.580687       1 scheduler.go:454] Total Schedule Algo cumulative time:759.465464ms for 376
I0828 10:50:15.582597       1 scheduler.go:451] ScheduleAlgoTime 1.665473ms Start:2018-08-28 10:50:15.580926188 +0000 UTC m=+18.547035713 End:2018-08-28 10:50:15.582591705 +0000 UTC m=+18.548701186
I0828 10:50:15.582623       1 scheduler.go:454] Total Schedule Algo cumulative time:761.130937ms for 377
I0828 10:50:15.584364       1 scheduler.go:451] ScheduleAlgoTime 1.554257ms Start:2018-08-28 10:50:15.582805424 +0000 UTC m=+18.548914946 End:2018-08-28 10:50:15.584359721 +0000 UTC m=+18.550469203
I0828 10:50:15.584385       1 scheduler.go:454] Total Schedule Algo cumulative time:762.685194ms for 378
I0828 10:50:15.586019       1 scheduler.go:451] ScheduleAlgoTime 1.520553ms Start:2018-08-28 10:50:15.584493595 +0000 UTC m=+18.550603109 End:2018-08-28 10:50:15.586014178 +0000 UTC m=+18.552123662
I0828 10:50:15.586039       1 scheduler.go:454] Total Schedule Algo cumulative time:764.205747ms for 379
I0828 10:50:15.587708       1 scheduler.go:451] ScheduleAlgoTime 1.56745ms Start:2018-08-28 10:50:15.586134186 +0000 UTC m=+18.552243707 End:2018-08-28 10:50:15.587701676 +0000 UTC m=+18.553811157
I0828 10:50:15.587748       1 scheduler.go:454] Total Schedule Algo cumulative time:765.773197ms for 380
I0828 10:50:15.589418       1 scheduler.go:451] ScheduleAlgoTime 1.476379ms Start:2018-08-28 10:50:15.58793601 +0000 UTC m=+18.554045559 End:2018-08-28 10:50:15.589412457 +0000 UTC m=+18.555521938
I0828 10:50:15.589441       1 scheduler.go:454] Total Schedule Algo cumulative time:767.249576ms for 381
I0828 10:50:15.591197       1 scheduler.go:451] ScheduleAlgoTime 1.624022ms Start:2018-08-28 10:50:15.58956746 +0000 UTC m=+18.555677028 End:2018-08-28 10:50:15.591191563 +0000 UTC m=+18.557301050
I0828 10:50:15.591218       1 scheduler.go:454] Total Schedule Algo cumulative time:768.873598ms for 382
I0828 10:50:15.592927       1 scheduler.go:451] ScheduleAlgoTime 1.5754ms Start:2018-08-28 10:50:15.591343713 +0000 UTC m=+18.557453206 End:2018-08-28 10:50:15.592918937 +0000 UTC m=+18.559028606
I0828 10:50:15.592964       1 scheduler.go:454] Total Schedule Algo cumulative time:770.448998ms for 383
I0828 10:50:15.594793       1 scheduler.go:451] ScheduleAlgoTime 1.672056ms Start:2018-08-28 10:50:15.593116555 +0000 UTC m=+18.559226094 End:2018-08-28 10:50:15.594788669 +0000 UTC m=+18.560898150
I0828 10:50:15.594820       1 scheduler.go:454] Total Schedule Algo cumulative time:772.121054ms for 384
I0828 10:50:15.596411       1 scheduler.go:451] ScheduleAlgoTime 1.517234ms Start:2018-08-28 10:50:15.59488824 +0000 UTC m=+18.560997782 End:2018-08-28 10:50:15.596405528 +0000 UTC m=+18.562515016
I0828 10:50:15.596433       1 scheduler.go:454] Total Schedule Algo cumulative time:773.638288ms for 385
I0828 10:50:15.598515       1 scheduler.go:451] ScheduleAlgoTime 1.915497ms Start:2018-08-28 10:50:15.5965943 +0000 UTC m=+18.562703827 End:2018-08-28 10:50:15.598509841 +0000 UTC m=+18.564619324
I0828 10:50:15.598538       1 scheduler.go:454] Total Schedule Algo cumulative time:775.553785ms for 386
I0828 10:50:15.600292       1 scheduler.go:451] ScheduleAlgoTime 1.656117ms Start:2018-08-28 10:50:15.598629109 +0000 UTC m=+18.564738654 End:2018-08-28 10:50:15.600285281 +0000 UTC m=+18.566394771
I0828 10:50:15.600318       1 scheduler.go:454] Total Schedule Algo cumulative time:777.209902ms for 387
I0828 10:50:15.602277       1 scheduler.go:451] ScheduleAlgoTime 1.813714ms Start:2018-08-28 10:50:15.600457985 +0000 UTC m=+18.566567519 End:2018-08-28 10:50:15.602271751 +0000 UTC m=+18.568381233
I0828 10:50:15.602297       1 scheduler.go:454] Total Schedule Algo cumulative time:779.023616ms for 388
I0828 10:50:15.604037       1 scheduler.go:451] ScheduleAlgoTime 1.626045ms Start:2018-08-28 10:50:15.602403989 +0000 UTC m=+18.568513503 End:2018-08-28 10:50:15.604030065 +0000 UTC m=+18.570139548
I0828 10:50:15.604062       1 scheduler.go:454] Total Schedule Algo cumulative time:780.649661ms for 389
I0828 10:50:15.605750       1 scheduler.go:451] ScheduleAlgoTime 1.521599ms Start:2018-08-28 10:50:15.6042229 +0000 UTC m=+18.570332396 End:2018-08-28 10:50:15.60574451 +0000 UTC m=+18.571853995
I0828 10:50:15.605771       1 scheduler.go:454] Total Schedule Algo cumulative time:782.17126ms for 390
I0828 10:50:15.607518       1 scheduler.go:451] ScheduleAlgoTime 1.621942ms Start:2018-08-28 10:50:15.605890997 +0000 UTC m=+18.572000525 End:2018-08-28 10:50:15.607512987 +0000 UTC m=+18.573622467
I0828 10:50:15.607539       1 scheduler.go:454] Total Schedule Algo cumulative time:783.793202ms for 391
I0828 10:50:15.609078       1 scheduler.go:451] ScheduleAlgoTime 1.419255ms Start:2018-08-28 10:50:15.607653449 +0000 UTC m=+18.573762950 End:2018-08-28 10:50:15.609072723 +0000 UTC m=+18.575182205
I0828 10:50:15.609126       1 scheduler.go:454] Total Schedule Algo cumulative time:785.212457ms for 392
I0828 10:50:15.610698       1 scheduler.go:451] ScheduleAlgoTime 1.477803ms Start:2018-08-28 10:50:15.609216197 +0000 UTC m=+18.575325733 End:2018-08-28 10:50:15.610694054 +0000 UTC m=+18.576803536
I0828 10:50:15.610730       1 scheduler.go:454] Total Schedule Algo cumulative time:786.69026ms for 393
I0828 10:50:15.612550       1 scheduler.go:451] ScheduleAlgoTime 1.680986ms Start:2018-08-28 10:50:15.61086409 +0000 UTC m=+18.576973668 End:2018-08-28 10:50:15.61254517 +0000 UTC m=+18.578654654
I0828 10:50:15.612573       1 scheduler.go:454] Total Schedule Algo cumulative time:788.371246ms for 394
I0828 10:50:15.614333       1 scheduler.go:451] ScheduleAlgoTime 1.636548ms Start:2018-08-28 10:50:15.612688955 +0000 UTC m=+18.578798507 End:2018-08-28 10:50:15.614325563 +0000 UTC m=+18.580435055
I0828 10:50:15.614363       1 scheduler.go:454] Total Schedule Algo cumulative time:790.007794ms for 395
I0828 10:50:15.616000       1 scheduler.go:451] ScheduleAlgoTime 1.493816ms Start:2018-08-28 10:50:15.614498206 +0000 UTC m=+18.580607752 End:2018-08-28 10:50:15.615992082 +0000 UTC m=+18.582101568
I0828 10:50:15.616022       1 scheduler.go:454] Total Schedule Algo cumulative time:791.50161ms for 396
I0828 10:50:15.617738       1 scheduler.go:451] ScheduleAlgoTime 1.559609ms Start:2018-08-28 10:50:15.616172405 +0000 UTC m=+18.582281931 End:2018-08-28 10:50:15.617732049 +0000 UTC m=+18.583841540
I0828 10:50:15.617761       1 scheduler.go:454] Total Schedule Algo cumulative time:793.061219ms for 397
I0828 10:50:15.619549       1 scheduler.go:451] ScheduleAlgoTime 1.65143ms Start:2018-08-28 10:50:15.617891842 +0000 UTC m=+18.584001390 End:2018-08-28 10:50:15.61954334 +0000 UTC m=+18.585652820
I0828 10:50:15.619572       1 scheduler.go:454] Total Schedule Algo cumulative time:794.712649ms for 398
I0828 10:50:15.621333       1 scheduler.go:451] ScheduleAlgoTime 1.671304ms Start:2018-08-28 10:50:15.619654459 +0000 UTC m=+18.585763980 End:2018-08-28 10:50:15.621325653 +0000 UTC m=+18.587435284
I0828 10:50:15.621381       1 scheduler.go:454] Total Schedule Algo cumulative time:796.383953ms for 399
I0828 10:50:15.623114       1 scheduler.go:451] ScheduleAlgoTime 1.604348ms Start:2018-08-28 10:50:15.621504408 +0000 UTC m=+18.587613908 End:2018-08-28 10:50:15.623108776 +0000 UTC m=+18.589218256
I0828 10:50:15.623134       1 scheduler.go:454] Total Schedule Algo cumulative time:797.988301ms for 400
I0828 10:50:15.624812       1 scheduler.go:451] ScheduleAlgoTime 1.561659ms Start:2018-08-28 10:50:15.623244969 +0000 UTC m=+18.589354498 End:2018-08-28 10:50:15.624806677 +0000 UTC m=+18.590916157
I0828 10:50:15.624831       1 scheduler.go:454] Total Schedule Algo cumulative time:799.54996ms for 401
I0828 10:50:15.626698       1 scheduler.go:451] ScheduleAlgoTime 1.747083ms Start:2018-08-28 10:50:15.62493946 +0000 UTC m=+18.591049012 End:2018-08-28 10:50:15.626686601 +0000 UTC m=+18.592796095
I0828 10:50:15.626733       1 scheduler.go:454] Total Schedule Algo cumulative time:801.297043ms for 402
I0828 10:50:15.628569       1 scheduler.go:451] ScheduleAlgoTime 1.698452ms Start:2018-08-28 10:50:15.626864117 +0000 UTC m=+18.592973629 End:2018-08-28 10:50:15.6285626 +0000 UTC m=+18.594672081
I0828 10:50:15.628591       1 scheduler.go:454] Total Schedule Algo cumulative time:802.995495ms for 403
I0828 10:50:15.630502       1 scheduler.go:451] ScheduleAlgoTime 1.728338ms Start:2018-08-28 10:50:15.628767883 +0000 UTC m=+18.594877429 End:2018-08-28 10:50:15.630496286 +0000 UTC m=+18.596605767
I0828 10:50:15.630527       1 scheduler.go:454] Total Schedule Algo cumulative time:804.723833ms for 404
I0828 10:50:15.633972       1 scheduler.go:451] ScheduleAlgoTime 3.237523ms Start:2018-08-28 10:50:15.630728026 +0000 UTC m=+18.596837598 End:2018-08-28 10:50:15.633965641 +0000 UTC m=+18.600075121
I0828 10:50:15.634055       1 scheduler.go:454] Total Schedule Algo cumulative time:807.961356ms for 405
I0828 10:50:15.639187       1 scheduler.go:451] ScheduleAlgoTime 4.993488ms Start:2018-08-28 10:50:15.634186513 +0000 UTC m=+18.600296007 End:2018-08-28 10:50:15.639180014 +0000 UTC m=+18.605289495
I0828 10:50:15.639219       1 scheduler.go:454] Total Schedule Algo cumulative time:812.954844ms for 406
I0828 10:50:15.641155       1 scheduler.go:451] ScheduleAlgoTime 1.694808ms Start:2018-08-28 10:50:15.639443289 +0000 UTC m=+18.605552781 End:2018-08-28 10:50:15.641138105 +0000 UTC m=+18.607247589
I0828 10:50:15.641193       1 scheduler.go:454] Total Schedule Algo cumulative time:814.649652ms for 407
I0828 10:50:15.642822       1 scheduler.go:451] ScheduleAlgoTime 1.467116ms Start:2018-08-28 10:50:15.641350797 +0000 UTC m=+18.607460337 End:2018-08-28 10:50:15.642817967 +0000 UTC m=+18.608927453
I0828 10:50:15.642847       1 scheduler.go:454] Total Schedule Algo cumulative time:816.116768ms for 408
I0828 10:50:15.644608       1 scheduler.go:451] ScheduleAlgoTime 1.64003ms Start:2018-08-28 10:50:15.642963198 +0000 UTC m=+18.609072709 End:2018-08-28 10:50:15.644603259 +0000 UTC m=+18.610712739
I0828 10:50:15.644668       1 scheduler.go:454] Total Schedule Algo cumulative time:817.756798ms for 409
I0828 10:50:15.646741       1 scheduler.go:451] ScheduleAlgoTime 1.971309ms Start:2018-08-28 10:50:15.644764752 +0000 UTC m=+18.610874306 End:2018-08-28 10:50:15.646736134 +0000 UTC m=+18.612845615
I0828 10:50:15.646762       1 scheduler.go:454] Total Schedule Algo cumulative time:819.728107ms for 410
I0828 10:50:15.648472       1 scheduler.go:451] ScheduleAlgoTime 1.587287ms Start:2018-08-28 10:50:15.64686755 +0000 UTC m=+18.612977069 End:2018-08-28 10:50:15.648454871 +0000 UTC m=+18.614564356
I0828 10:50:15.648501       1 scheduler.go:454] Total Schedule Algo cumulative time:821.315394ms for 411
I0828 10:50:15.650251       1 scheduler.go:451] ScheduleAlgoTime 1.619163ms Start:2018-08-28 10:50:15.648626056 +0000 UTC m=+18.614735553 End:2018-08-28 10:50:15.650245229 +0000 UTC m=+18.616354716
I0828 10:50:15.650282       1 scheduler.go:454] Total Schedule Algo cumulative time:822.934557ms for 412
I0828 10:50:15.651924       1 scheduler.go:451] ScheduleAlgoTime 1.543986ms Start:2018-08-28 10:50:15.650374845 +0000 UTC m=+18.616484387 End:2018-08-28 10:50:15.651918893 +0000 UTC m=+18.618028373
I0828 10:50:15.651945       1 scheduler.go:454] Total Schedule Algo cumulative time:824.478543ms for 413
I0828 10:50:15.653442       1 scheduler.go:451] ScheduleAlgoTime 1.393542ms Start:2018-08-28 10:50:15.652043462 +0000 UTC m=+18.618152979 End:2018-08-28 10:50:15.653437042 +0000 UTC m=+18.619546521
I0828 10:50:15.653464       1 scheduler.go:454] Total Schedule Algo cumulative time:825.872085ms for 414
I0828 10:50:15.654937       1 scheduler.go:451] ScheduleAlgoTime 1.379136ms Start:2018-08-28 10:50:15.653551805 +0000 UTC m=+18.619661334 End:2018-08-28 10:50:15.654930982 +0000 UTC m=+18.621040470
I0828 10:50:15.654964       1 scheduler.go:454] Total Schedule Algo cumulative time:827.251221ms for 415
I0828 10:50:15.656419       1 scheduler.go:451] ScheduleAlgoTime 1.354272ms Start:2018-08-28 10:50:15.655060074 +0000 UTC m=+18.621169606 End:2018-08-28 10:50:15.656414399 +0000 UTC m=+18.622523878
I0828 10:50:15.656444       1 scheduler.go:454] Total Schedule Algo cumulative time:828.605493ms for 416
I0828 10:50:15.658124       1 scheduler.go:451] ScheduleAlgoTime 1.539584ms Start:2018-08-28 10:50:15.656579465 +0000 UTC m=+18.622688996 End:2018-08-28 10:50:15.658119099 +0000 UTC m=+18.624228580
I0828 10:50:15.658159       1 scheduler.go:454] Total Schedule Algo cumulative time:830.145077ms for 417
I0828 10:50:15.659921       1 scheduler.go:451] ScheduleAlgoTime 1.625631ms Start:2018-08-28 10:50:15.658291456 +0000 UTC m=+18.624400993 End:2018-08-28 10:50:15.659917144 +0000 UTC m=+18.626026624
I0828 10:50:15.659942       1 scheduler.go:454] Total Schedule Algo cumulative time:831.770708ms for 418
I0828 10:50:15.661806       1 scheduler.go:451] ScheduleAlgoTime 1.730331ms Start:2018-08-28 10:50:15.66007022 +0000 UTC m=+18.626179746 End:2018-08-28 10:50:15.661800594 +0000 UTC m=+18.627910077
I0828 10:50:15.661840       1 scheduler.go:454] Total Schedule Algo cumulative time:833.501039ms for 419
I0828 10:50:15.663455       1 scheduler.go:451] ScheduleAlgoTime 1.510568ms Start:2018-08-28 10:50:15.661939984 +0000 UTC m=+18.628049480 End:2018-08-28 10:50:15.663450564 +0000 UTC m=+18.629560048
I0828 10:50:15.663475       1 scheduler.go:454] Total Schedule Algo cumulative time:835.011607ms for 420
I0828 10:50:15.665322       1 scheduler.go:451] ScheduleAlgoTime 1.707195ms Start:2018-08-28 10:50:15.663607763 +0000 UTC m=+18.629717278 End:2018-08-28 10:50:15.665314994 +0000 UTC m=+18.631424473
I0828 10:50:15.665349       1 scheduler.go:454] Total Schedule Algo cumulative time:836.718802ms for 421
I0828 10:50:15.666945       1 scheduler.go:451] ScheduleAlgoTime 1.465623ms Start:2018-08-28 10:50:15.665473798 +0000 UTC m=+18.631583353 End:2018-08-28 10:50:15.666939493 +0000 UTC m=+18.633048976
I0828 10:50:15.666968       1 scheduler.go:454] Total Schedule Algo cumulative time:838.184425ms for 422
I0828 10:50:15.668675       1 scheduler.go:451] ScheduleAlgoTime 1.575561ms Start:2018-08-28 10:50:15.667094214 +0000 UTC m=+18.633203743 End:2018-08-28 10:50:15.668669824 +0000 UTC m=+18.634779304
I0828 10:50:15.668696       1 scheduler.go:454] Total Schedule Algo cumulative time:839.759986ms for 423
I0828 10:50:15.670255       1 scheduler.go:451] ScheduleAlgoTime 1.458407ms Start:2018-08-28 10:50:15.66879196 +0000 UTC m=+18.634901497 End:2018-08-28 10:50:15.670250422 +0000 UTC m=+18.636359904
I0828 10:50:15.670276       1 scheduler.go:454] Total Schedule Algo cumulative time:841.218393ms for 424
I0828 10:50:15.672028       1 scheduler.go:451] ScheduleAlgoTime 1.643175ms Start:2018-08-28 10:50:15.670379815 +0000 UTC m=+18.636489353 End:2018-08-28 10:50:15.672023049 +0000 UTC m=+18.638132528
I0828 10:50:15.672048       1 scheduler.go:454] Total Schedule Algo cumulative time:842.861568ms for 425
I0828 10:50:15.673617       1 scheduler.go:451] ScheduleAlgoTime 1.453052ms Start:2018-08-28 10:50:15.672158386 +0000 UTC m=+18.638267900 End:2018-08-28 10:50:15.673611472 +0000 UTC m=+18.639720952
I0828 10:50:15.673639       1 scheduler.go:454] Total Schedule Algo cumulative time:844.31462ms for 426
I0828 10:50:15.675352       1 scheduler.go:451] ScheduleAlgoTime 1.603391ms Start:2018-08-28 10:50:15.673743482 +0000 UTC m=+18.639853000 End:2018-08-28 10:50:15.67534691 +0000 UTC m=+18.641456391
I0828 10:50:15.675373       1 scheduler.go:454] Total Schedule Algo cumulative time:845.918011ms for 427
I0828 10:50:15.676961       1 scheduler.go:451] ScheduleAlgoTime 1.49113ms Start:2018-08-28 10:50:15.675464677 +0000 UTC m=+18.641574217 End:2018-08-28 10:50:15.676955866 +0000 UTC m=+18.643065347
I0828 10:50:15.676982       1 scheduler.go:454] Total Schedule Algo cumulative time:847.409141ms for 428
I0828 10:50:15.678654       1 scheduler.go:451] ScheduleAlgoTime 1.521953ms Start:2018-08-28 10:50:15.67712545 +0000 UTC m=+18.643234967 End:2018-08-28 10:50:15.678647428 +0000 UTC m=+18.644756920
I0828 10:50:15.678681       1 scheduler.go:454] Total Schedule Algo cumulative time:848.931094ms for 429
I0828 10:50:15.680426       1 scheduler.go:451] ScheduleAlgoTime 1.58615ms Start:2018-08-28 10:50:15.678831676 +0000 UTC m=+18.644941190 End:2018-08-28 10:50:15.680417854 +0000 UTC m=+18.646527340
I0828 10:50:15.680466       1 scheduler.go:454] Total Schedule Algo cumulative time:850.517244ms for 430
I0828 10:50:15.682387       1 scheduler.go:451] ScheduleAlgoTime 1.722731ms Start:2018-08-28 10:50:15.680657404 +0000 UTC m=+18.646766967 End:2018-08-28 10:50:15.682380204 +0000 UTC m=+18.648489698
I0828 10:50:15.682414       1 scheduler.go:454] Total Schedule Algo cumulative time:852.239975ms for 431
I0828 10:50:15.684120       1 scheduler.go:451] ScheduleAlgoTime 1.52894ms Start:2018-08-28 10:50:15.682584056 +0000 UTC m=+18.648693558 End:2018-08-28 10:50:15.684113017 +0000 UTC m=+18.650222498
I0828 10:50:15.684162       1 scheduler.go:454] Total Schedule Algo cumulative time:853.768915ms for 432
I0828 10:50:15.685893       1 scheduler.go:451] ScheduleAlgoTime 1.592514ms Start:2018-08-28 10:50:15.684295358 +0000 UTC m=+18.650404886 End:2018-08-28 10:50:15.685887907 +0000 UTC m=+18.651997400
I0828 10:50:15.685920       1 scheduler.go:454] Total Schedule Algo cumulative time:855.361429ms for 433
I0828 10:50:15.687523       1 scheduler.go:451] ScheduleAlgoTime 1.480128ms Start:2018-08-28 10:50:15.686037385 +0000 UTC m=+18.652146931 End:2018-08-28 10:50:15.687517578 +0000 UTC m=+18.653627059
I0828 10:50:15.687552       1 scheduler.go:454] Total Schedule Algo cumulative time:856.841557ms for 434
I0828 10:50:15.689335       1 scheduler.go:451] ScheduleAlgoTime 1.646414ms Start:2018-08-28 10:50:15.687683609 +0000 UTC m=+18.653793139 End:2018-08-28 10:50:15.689330074 +0000 UTC m=+18.655439553
I0828 10:50:15.689358       1 scheduler.go:454] Total Schedule Algo cumulative time:858.487971ms for 435
I0828 10:50:15.691226       1 scheduler.go:451] ScheduleAlgoTime 1.711141ms Start:2018-08-28 10:50:15.689507958 +0000 UTC m=+18.655617522 End:2018-08-28 10:50:15.691219181 +0000 UTC m=+18.657328663
I0828 10:50:15.691249       1 scheduler.go:454] Total Schedule Algo cumulative time:860.199112ms for 436
I0828 10:50:15.692874       1 scheduler.go:451] ScheduleAlgoTime 1.503875ms Start:2018-08-28 10:50:15.691364967 +0000 UTC m=+18.657474508 End:2018-08-28 10:50:15.692868902 +0000 UTC m=+18.658978383
I0828 10:50:15.692897       1 scheduler.go:454] Total Schedule Algo cumulative time:861.702987ms for 437
I0828 10:50:15.694524       1 scheduler.go:451] ScheduleAlgoTime 1.477064ms Start:2018-08-28 10:50:15.693041692 +0000 UTC m=+18.659151188 End:2018-08-28 10:50:15.694518767 +0000 UTC m=+18.660628252
I0828 10:50:15.694548       1 scheduler.go:454] Total Schedule Algo cumulative time:863.180051ms for 438
I0828 10:50:15.696245       1 scheduler.go:451] ScheduleAlgoTime 1.563555ms Start:2018-08-28 10:50:15.694676943 +0000 UTC m=+18.660786490 End:2018-08-28 10:50:15.696240564 +0000 UTC m=+18.662350045
I0828 10:50:15.696276       1 scheduler.go:454] Total Schedule Algo cumulative time:864.743606ms for 439
I0828 10:50:15.697983       1 scheduler.go:451] ScheduleAlgoTime 1.572826ms Start:2018-08-28 10:50:15.696393764 +0000 UTC m=+18.662503302 End:2018-08-28 10:50:15.697966646 +0000 UTC m=+18.664076128
I0828 10:50:15.698009       1 scheduler.go:454] Total Schedule Algo cumulative time:866.316432ms for 440
I0828 10:50:15.699689       1 scheduler.go:451] ScheduleAlgoTime 1.551571ms Start:2018-08-28 10:50:15.698130946 +0000 UTC m=+18.664240479 End:2018-08-28 10:50:15.699682571 +0000 UTC m=+18.665792050
I0828 10:50:15.699719       1 scheduler.go:454] Total Schedule Algo cumulative time:867.868003ms for 441
I0828 10:50:15.701602       1 scheduler.go:451] ScheduleAlgoTime 1.78813ms Start:2018-08-28 10:50:15.699809177 +0000 UTC m=+18.665918694 End:2018-08-28 10:50:15.701597345 +0000 UTC m=+18.667706824
I0828 10:50:15.701624       1 scheduler.go:454] Total Schedule Algo cumulative time:869.656133ms for 442
I0828 10:50:15.703192       1 scheduler.go:451] ScheduleAlgoTime 1.4554ms Start:2018-08-28 10:50:15.701732232 +0000 UTC m=+18.667841746 End:2018-08-28 10:50:15.703187666 +0000 UTC m=+18.669297146
I0828 10:50:15.703214       1 scheduler.go:454] Total Schedule Algo cumulative time:871.111533ms for 443
I0828 10:50:15.704771       1 scheduler.go:451] ScheduleAlgoTime 1.447868ms Start:2018-08-28 10:50:15.703317032 +0000 UTC m=+18.669426560 End:2018-08-28 10:50:15.704764947 +0000 UTC m=+18.670874428
I0828 10:50:15.704791       1 scheduler.go:454] Total Schedule Algo cumulative time:872.559401ms for 444
I0828 10:50:15.706656       1 scheduler.go:451] ScheduleAlgoTime 1.782283ms Start:2018-08-28 10:50:15.704870179 +0000 UTC m=+18.670979708 End:2018-08-28 10:50:15.706652512 +0000 UTC m=+18.672761991
I0828 10:50:15.706675       1 scheduler.go:454] Total Schedule Algo cumulative time:874.341684ms for 445
I0828 10:50:15.708466       1 scheduler.go:451] ScheduleAlgoTime 1.685586ms Start:2018-08-28 10:50:15.706775186 +0000 UTC m=+18.672884680 End:2018-08-28 10:50:15.708460785 +0000 UTC m=+18.674570266
I0828 10:50:15.708488       1 scheduler.go:454] Total Schedule Algo cumulative time:876.02727ms for 446
I0828 10:50:15.710242       1 scheduler.go:451] ScheduleAlgoTime 1.559822ms Start:2018-08-28 10:50:15.708677256 +0000 UTC m=+18.674786764 End:2018-08-28 10:50:15.710237106 +0000 UTC m=+18.676346586
I0828 10:50:15.710263       1 scheduler.go:454] Total Schedule Algo cumulative time:877.587092ms for 447
I0828 10:50:15.712012       1 scheduler.go:451] ScheduleAlgoTime 1.62853ms Start:2018-08-28 10:50:15.710378545 +0000 UTC m=+18.676488087 End:2018-08-28 10:50:15.712007133 +0000 UTC m=+18.678116617
I0828 10:50:15.712031       1 scheduler.go:454] Total Schedule Algo cumulative time:879.215622ms for 448
I0828 10:50:15.713915       1 scheduler.go:451] ScheduleAlgoTime 1.77571ms Start:2018-08-28 10:50:15.712135474 +0000 UTC m=+18.678244978 End:2018-08-28 10:50:15.713911203 +0000 UTC m=+18.680020688
I0828 10:50:15.713936       1 scheduler.go:454] Total Schedule Algo cumulative time:880.991332ms for 449
I0828 10:50:15.717394       1 scheduler.go:451] ScheduleAlgoTime 3.324589ms Start:2018-08-28 10:50:15.714063357 +0000 UTC m=+18.680172852 End:2018-08-28 10:50:15.71738796 +0000 UTC m=+18.683497441
I0828 10:50:15.717430       1 scheduler.go:454] Total Schedule Algo cumulative time:884.315921ms for 450
I0828 10:50:15.721112       1 scheduler.go:451] ScheduleAlgoTime 3.489468ms Start:2018-08-28 10:50:15.717600697 +0000 UTC m=+18.683710253 End:2018-08-28 10:50:15.721090242 +0000 UTC m=+18.687199721
I0828 10:50:15.721160       1 scheduler.go:454] Total Schedule Algo cumulative time:887.805389ms for 451
I0828 10:50:15.723015       1 scheduler.go:451] ScheduleAlgoTime 1.71406ms Start:2018-08-28 10:50:15.721295429 +0000 UTC m=+18.687404979 End:2018-08-28 10:50:15.72300956 +0000 UTC m=+18.689119039
I0828 10:50:15.723042       1 scheduler.go:454] Total Schedule Algo cumulative time:889.519449ms for 452
I0828 10:50:15.724763       1 scheduler.go:451] ScheduleAlgoTime 1.594002ms Start:2018-08-28 10:50:15.723161268 +0000 UTC m=+18.689270808 End:2018-08-28 10:50:15.72475533 +0000 UTC m=+18.690864810
I0828 10:50:15.724795       1 scheduler.go:454] Total Schedule Algo cumulative time:891.113451ms for 453
I0828 10:50:15.726528       1 scheduler.go:451] ScheduleAlgoTime 1.591205ms Start:2018-08-28 10:50:15.724930495 +0000 UTC m=+18.691040011 End:2018-08-28 10:50:15.726521694 +0000 UTC m=+18.692631216
I0828 10:50:15.726555       1 scheduler.go:454] Total Schedule Algo cumulative time:892.704656ms for 454
I0828 10:50:15.728226       1 scheduler.go:451] ScheduleAlgoTime 1.551641ms Start:2018-08-28 10:50:15.726668382 +0000 UTC m=+18.692777883 End:2018-08-28 10:50:15.728220042 +0000 UTC m=+18.694329524
I0828 10:50:15.728250       1 scheduler.go:454] Total Schedule Algo cumulative time:894.256297ms for 455
I0828 10:50:15.730299       1 scheduler.go:451] ScheduleAlgoTime 1.93252ms Start:2018-08-28 10:50:15.728360453 +0000 UTC m=+18.694470022 End:2018-08-28 10:50:15.730293062 +0000 UTC m=+18.696402542
I0828 10:50:15.730332       1 scheduler.go:454] Total Schedule Algo cumulative time:896.188817ms for 456
I0828 10:50:15.732016       1 scheduler.go:451] ScheduleAlgoTime 1.537539ms Start:2018-08-28 10:50:15.730473109 +0000 UTC m=+18.696582619 End:2018-08-28 10:50:15.732010677 +0000 UTC m=+18.698120158
I0828 10:50:15.732036       1 scheduler.go:454] Total Schedule Algo cumulative time:897.726356ms for 457
I0828 10:50:15.733712       1 scheduler.go:451] ScheduleAlgoTime 1.551893ms Start:2018-08-28 10:50:15.732154677 +0000 UTC m=+18.698264219 End:2018-08-28 10:50:15.733706631 +0000 UTC m=+18.699816112
I0828 10:50:15.733737       1 scheduler.go:454] Total Schedule Algo cumulative time:899.278249ms for 458
I0828 10:50:15.735462       1 scheduler.go:451] ScheduleAlgoTime 1.597564ms Start:2018-08-28 10:50:15.733859813 +0000 UTC m=+18.699969370 End:2018-08-28 10:50:15.735457454 +0000 UTC m=+18.701566934
I0828 10:50:15.735490       1 scheduler.go:454] Total Schedule Algo cumulative time:900.875813ms for 459
I0828 10:50:15.737152       1 scheduler.go:451] ScheduleAlgoTime 1.557931ms Start:2018-08-28 10:50:15.735580425 +0000 UTC m=+18.701689946 End:2018-08-28 10:50:15.737138394 +0000 UTC m=+18.703247877
I0828 10:50:15.737176       1 scheduler.go:454] Total Schedule Algo cumulative time:902.433744ms for 460
I0828 10:50:15.739289       1 scheduler.go:451] ScheduleAlgoTime 1.954887ms Start:2018-08-28 10:50:15.737328329 +0000 UTC m=+18.703437866 End:2018-08-28 10:50:15.739283272 +0000 UTC m=+18.705392753
I0828 10:50:15.739335       1 scheduler.go:454] Total Schedule Algo cumulative time:904.388631ms for 461
I0828 10:50:15.741027       1 scheduler.go:451] ScheduleAlgoTime 1.575189ms Start:2018-08-28 10:50:15.739446351 +0000 UTC m=+18.705555887 End:2018-08-28 10:50:15.741021595 +0000 UTC m=+18.707131076
I0828 10:50:15.741047       1 scheduler.go:454] Total Schedule Algo cumulative time:905.96382ms for 462
I0828 10:50:15.742914       1 scheduler.go:451] ScheduleAlgoTime 1.727248ms Start:2018-08-28 10:50:15.741181598 +0000 UTC m=+18.707291119 End:2018-08-28 10:50:15.742908886 +0000 UTC m=+18.709018367
I0828 10:50:15.742935       1 scheduler.go:454] Total Schedule Algo cumulative time:907.691068ms for 463
I0828 10:50:15.744640       1 scheduler.go:451] ScheduleAlgoTime 1.572752ms Start:2018-08-28 10:50:15.743062949 +0000 UTC m=+18.709172484 End:2018-08-28 10:50:15.744635757 +0000 UTC m=+18.710745236
I0828 10:50:15.744660       1 scheduler.go:454] Total Schedule Algo cumulative time:909.26382ms for 464
I0828 10:50:15.746408       1 scheduler.go:451] ScheduleAlgoTime 1.62159ms Start:2018-08-28 10:50:15.744780735 +0000 UTC m=+18.710890295 End:2018-08-28 10:50:15.746402404 +0000 UTC m=+18.712511885
I0828 10:50:15.746432       1 scheduler.go:454] Total Schedule Algo cumulative time:910.88541ms for 465
I0828 10:50:15.748238       1 scheduler.go:451] ScheduleAlgoTime 1.671338ms Start:2018-08-28 10:50:15.746560365 +0000 UTC m=+18.712669932 End:2018-08-28 10:50:15.74823179 +0000 UTC m=+18.714341270
I0828 10:50:15.748269       1 scheduler.go:454] Total Schedule Algo cumulative time:912.556748ms for 466
I0828 10:50:15.749865       1 scheduler.go:451] ScheduleAlgoTime 1.456893ms Start:2018-08-28 10:50:15.748402507 +0000 UTC m=+18.714512014 End:2018-08-28 10:50:15.749859423 +0000 UTC m=+18.715968907
I0828 10:50:15.749886       1 scheduler.go:454] Total Schedule Algo cumulative time:914.013641ms for 467
I0828 10:50:15.751504       1 scheduler.go:451] ScheduleAlgoTime 1.49986ms Start:2018-08-28 10:50:15.749998783 +0000 UTC m=+18.716108331 End:2018-08-28 10:50:15.751498708 +0000 UTC m=+18.717608191
I0828 10:50:15.751526       1 scheduler.go:454] Total Schedule Algo cumulative time:915.513501ms for 468
I0828 10:50:15.753929       1 scheduler.go:451] ScheduleAlgoTime 2.288976ms Start:2018-08-28 10:50:15.751635753 +0000 UTC m=+18.717745260 End:2018-08-28 10:50:15.753924755 +0000 UTC m=+18.720034236
I0828 10:50:15.753953       1 scheduler.go:454] Total Schedule Algo cumulative time:917.802477ms for 469
I0828 10:50:15.755717       1 scheduler.go:451] ScheduleAlgoTime 1.664603ms Start:2018-08-28 10:50:15.754047131 +0000 UTC m=+18.720156622 End:2018-08-28 10:50:15.755711744 +0000 UTC m=+18.721821225
I0828 10:50:15.755740       1 scheduler.go:454] Total Schedule Algo cumulative time:919.46708ms for 470
I0828 10:50:15.757466       1 scheduler.go:451] ScheduleAlgoTime 1.624858ms Start:2018-08-28 10:50:15.755835332 +0000 UTC m=+18.721944872 End:2018-08-28 10:50:15.757460245 +0000 UTC m=+18.723569730
I0828 10:50:15.757488       1 scheduler.go:454] Total Schedule Algo cumulative time:921.091938ms for 471
I0828 10:50:15.759351       1 scheduler.go:451] ScheduleAlgoTime 1.771909ms Start:2018-08-28 10:50:15.757574154 +0000 UTC m=+18.723683705 End:2018-08-28 10:50:15.759346128 +0000 UTC m=+18.725455614
I0828 10:50:15.759374       1 scheduler.go:454] Total Schedule Algo cumulative time:922.863847ms for 472
I0828 10:50:15.760951       1 scheduler.go:451] ScheduleAlgoTime 1.440888ms Start:2018-08-28 10:50:15.759505163 +0000 UTC m=+18.725614700 End:2018-08-28 10:50:15.760946109 +0000 UTC m=+18.727055588
I0828 10:50:15.760972       1 scheduler.go:454] Total Schedule Algo cumulative time:924.304735ms for 473
I0828 10:50:15.762654       1 scheduler.go:451] ScheduleAlgoTime 1.595501ms Start:2018-08-28 10:50:15.761052318 +0000 UTC m=+18.727161862 End:2018-08-28 10:50:15.762647883 +0000 UTC m=+18.728757363
I0828 10:50:15.762677       1 scheduler.go:454] Total Schedule Algo cumulative time:925.900236ms for 474
I0828 10:50:15.764320       1 scheduler.go:451] ScheduleAlgoTime 1.504099ms Start:2018-08-28 10:50:15.762811436 +0000 UTC m=+18.728920985 End:2018-08-28 10:50:15.764315604 +0000 UTC m=+18.730425084
I0828 10:50:15.764342       1 scheduler.go:454] Total Schedule Algo cumulative time:927.404335ms for 475
I0828 10:50:15.766179       1 scheduler.go:451] ScheduleAlgoTime 1.582559ms Start:2018-08-28 10:50:15.764591145 +0000 UTC m=+18.730700673 End:2018-08-28 10:50:15.766173753 +0000 UTC m=+18.732283232
I0828 10:50:15.766203       1 scheduler.go:454] Total Schedule Algo cumulative time:928.986894ms for 476
I0828 10:50:15.767794       1 scheduler.go:451] ScheduleAlgoTime 1.495336ms Start:2018-08-28 10:50:15.766293606 +0000 UTC m=+18.732403112 End:2018-08-28 10:50:15.767788969 +0000 UTC m=+18.733898448
I0828 10:50:15.767825       1 scheduler.go:454] Total Schedule Algo cumulative time:930.48223ms for 477
I0828 10:50:15.769644       1 scheduler.go:451] ScheduleAlgoTime 1.696908ms Start:2018-08-28 10:50:15.76794184 +0000 UTC m=+18.734051362 End:2018-08-28 10:50:15.769638787 +0000 UTC m=+18.735748270
I0828 10:50:15.769665       1 scheduler.go:454] Total Schedule Algo cumulative time:932.179138ms for 478
I0828 10:50:15.771385       1 scheduler.go:451] ScheduleAlgoTime 1.621306ms Start:2018-08-28 10:50:15.769759009 +0000 UTC m=+18.735868545 End:2018-08-28 10:50:15.771380363 +0000 UTC m=+18.737489851
I0828 10:50:15.771406       1 scheduler.go:454] Total Schedule Algo cumulative time:933.800444ms for 479
I0828 10:50:15.773124       1 scheduler.go:451] ScheduleAlgoTime 1.643025ms Start:2018-08-28 10:50:15.771476673 +0000 UTC m=+18.737586187 End:2018-08-28 10:50:15.773119732 +0000 UTC m=+18.739229212
I0828 10:50:15.773153       1 scheduler.go:454] Total Schedule Algo cumulative time:935.443469ms for 480
I0828 10:50:15.774704       1 scheduler.go:451] ScheduleAlgoTime 1.456805ms Start:2018-08-28 10:50:15.773242345 +0000 UTC m=+18.739351878 End:2018-08-28 10:50:15.774699199 +0000 UTC m=+18.740808683
I0828 10:50:15.774729       1 scheduler.go:454] Total Schedule Algo cumulative time:936.900274ms for 481
I0828 10:50:15.776810       1 scheduler.go:451] ScheduleAlgoTime 1.971376ms Start:2018-08-28 10:50:15.774832267 +0000 UTC m=+18.740941854 End:2018-08-28 10:50:15.776803751 +0000 UTC m=+18.742913230
I0828 10:50:15.776836       1 scheduler.go:454] Total Schedule Algo cumulative time:938.87165ms for 482
I0828 10:50:15.778767       1 scheduler.go:451] ScheduleAlgoTime 1.723003ms Start:2018-08-28 10:50:15.777035967 +0000 UTC m=+18.743145531 End:2018-08-28 10:50:15.778759049 +0000 UTC m=+18.744868534
I0828 10:50:15.778795       1 scheduler.go:454] Total Schedule Algo cumulative time:940.594653ms for 483
I0828 10:50:15.780439       1 scheduler.go:451] ScheduleAlgoTime 1.510248ms Start:2018-08-28 10:50:15.778923168 +0000 UTC m=+18.745032713 End:2018-08-28 10:50:15.780433481 +0000 UTC m=+18.746542961
I0828 10:50:15.780459       1 scheduler.go:454] Total Schedule Algo cumulative time:942.104901ms for 484
I0828 10:50:15.782175       1 scheduler.go:451] ScheduleAlgoTime 1.609517ms Start:2018-08-28 10:50:15.780560516 +0000 UTC m=+18.746670030 End:2018-08-28 10:50:15.782170063 +0000 UTC m=+18.748279547
I0828 10:50:15.782199       1 scheduler.go:454] Total Schedule Algo cumulative time:943.714418ms for 485
I0828 10:50:15.783863       1 scheduler.go:451] ScheduleAlgoTime 1.563259ms Start:2018-08-28 10:50:15.782294799 +0000 UTC m=+18.748404309 End:2018-08-28 10:50:15.783858085 +0000 UTC m=+18.749967568
I0828 10:50:15.783883       1 scheduler.go:454] Total Schedule Algo cumulative time:945.277677ms for 486
I0828 10:50:15.785447       1 scheduler.go:451] ScheduleAlgoTime 1.474354ms Start:2018-08-28 10:50:15.783967992 +0000 UTC m=+18.750077489 End:2018-08-28 10:50:15.785442362 +0000 UTC m=+18.751551843
I0828 10:50:15.785467       1 scheduler.go:454] Total Schedule Algo cumulative time:946.752031ms for 487
I0828 10:50:15.787425       1 scheduler.go:451] ScheduleAlgoTime 1.836841ms Start:2018-08-28 10:50:15.785581865 +0000 UTC m=+18.751691412 End:2018-08-28 10:50:15.78741877 +0000 UTC m=+18.753528253
I0828 10:50:15.787459       1 scheduler.go:454] Total Schedule Algo cumulative time:948.588872ms for 488
I0828 10:50:15.789239       1 scheduler.go:451] ScheduleAlgoTime 1.66595ms Start:2018-08-28 10:50:15.787568282 +0000 UTC m=+18.753677834 End:2018-08-28 10:50:15.789234304 +0000 UTC m=+18.755343784
I0828 10:50:15.789267       1 scheduler.go:454] Total Schedule Algo cumulative time:950.254822ms for 489
I0828 10:50:15.790999       1 scheduler.go:451] ScheduleAlgoTime 1.657217ms Start:2018-08-28 10:50:15.789337243 +0000 UTC m=+18.755446769 End:2018-08-28 10:50:15.790994504 +0000 UTC m=+18.757103986
I0828 10:50:15.791018       1 scheduler.go:454] Total Schedule Algo cumulative time:951.912039ms for 490
I0828 10:50:15.792615       1 scheduler.go:451] ScheduleAlgoTime 1.496455ms Start:2018-08-28 10:50:15.791113075 +0000 UTC m=+18.757222555 End:2018-08-28 10:50:15.792609528 +0000 UTC m=+18.758719010
I0828 10:50:15.792640       1 scheduler.go:454] Total Schedule Algo cumulative time:953.408494ms for 491
I0828 10:50:15.794495       1 scheduler.go:451] ScheduleAlgoTime 1.724422ms Start:2018-08-28 10:50:15.792765658 +0000 UTC m=+18.758875224 End:2018-08-28 10:50:15.794490164 +0000 UTC m=+18.760599646
I0828 10:50:15.794519       1 scheduler.go:454] Total Schedule Algo cumulative time:955.132916ms for 492
I0828 10:50:15.796134       1 scheduler.go:451] ScheduleAlgoTime 1.515851ms Start:2018-08-28 10:50:15.794613077 +0000 UTC m=+18.760722581 End:2018-08-28 10:50:15.796128951 +0000 UTC m=+18.762238432
I0828 10:50:15.796161       1 scheduler.go:454] Total Schedule Algo cumulative time:956.648767ms for 493
I0828 10:50:15.797855       1 scheduler.go:451] ScheduleAlgoTime 1.598769ms Start:2018-08-28 10:50:15.796251471 +0000 UTC m=+18.762360980 End:2018-08-28 10:50:15.79785027 +0000 UTC m=+18.763959749
I0828 10:50:15.797882       1 scheduler.go:454] Total Schedule Algo cumulative time:958.247536ms for 494
I0828 10:50:15.799749       1 scheduler.go:451] ScheduleAlgoTime 1.757803ms Start:2018-08-28 10:50:15.797986114 +0000 UTC m=+18.764095641 End:2018-08-28 10:50:15.799743965 +0000 UTC m=+18.765853444
I0828 10:50:15.799767       1 scheduler.go:454] Total Schedule Algo cumulative time:960.005339ms for 495
I0828 10:50:15.801814       1 scheduler.go:451] ScheduleAlgoTime 1.916992ms Start:2018-08-28 10:50:15.799891696 +0000 UTC m=+18.766001265 End:2018-08-28 10:50:15.801808776 +0000 UTC m=+18.767918257
I0828 10:50:15.801834       1 scheduler.go:454] Total Schedule Algo cumulative time:961.922331ms for 496
I0828 10:50:15.803649       1 scheduler.go:451] ScheduleAlgoTime 1.65352ms Start:2018-08-28 10:50:15.801989096 +0000 UTC m=+18.768098658 End:2018-08-28 10:50:15.803642696 +0000 UTC m=+18.769752178
I0828 10:50:15.803674       1 scheduler.go:454] Total Schedule Algo cumulative time:963.575851ms for 497
I0828 10:50:15.807878       1 scheduler.go:451] ScheduleAlgoTime 4.09868ms Start:2018-08-28 10:50:15.803769029 +0000 UTC m=+18.769878573 End:2018-08-28 10:50:15.807867771 +0000 UTC m=+18.773977253
I0828 10:50:15.807944       1 scheduler.go:454] Total Schedule Algo cumulative time:967.674531ms for 498
I0828 10:50:15.811360       1 scheduler.go:451] ScheduleAlgoTime 3.307094ms Start:2018-08-28 10:50:15.80804698 +0000 UTC m=+18.774156462 End:2018-08-28 10:50:15.811354071 +0000 UTC m=+18.777463556
I0828 10:50:15.811385       1 scheduler.go:454] Total Schedule Algo cumulative time:970.981625ms for 499
I0828 10:50:15.813166       1 scheduler.go:451] ScheduleAlgoTime 1.63367ms Start:2018-08-28 10:50:15.811524992 +0000 UTC m=+18.777634536 End:2018-08-28 10:50:15.813158718 +0000 UTC m=+18.779268206
I0828 10:50:15.813197       1 scheduler.go:454] Total Schedule Algo cumulative time:972.615295ms for 500
I0828 10:50:15.815402       1 scheduler.go:451] ScheduleAlgoTime 2.06456ms Start:2018-08-28 10:50:15.81333229 +0000 UTC m=+18.779441804 End:2018-08-28 10:50:15.815396884 +0000 UTC m=+18.781506364
I0828 10:50:15.815427       1 scheduler.go:454] Total Schedule Algo cumulative time:974.679855ms for 501
I0828 10:50:15.817056       1 scheduler.go:451] ScheduleAlgoTime 1.517594ms Start:2018-08-28 10:50:15.815532301 +0000 UTC m=+18.781641843 End:2018-08-28 10:50:15.817049953 +0000 UTC m=+18.783159437
I0828 10:50:15.817083       1 scheduler.go:454] Total Schedule Algo cumulative time:976.197449ms for 502
I0828 10:50:15.819280       1 scheduler.go:451] ScheduleAlgoTime 2.051252ms Start:2018-08-28 10:50:15.817223483 +0000 UTC m=+18.783333031 End:2018-08-28 10:50:15.819274802 +0000 UTC m=+18.785384283
I0828 10:50:15.819305       1 scheduler.go:454] Total Schedule Algo cumulative time:978.248701ms for 503
I0828 10:50:15.821023       1 scheduler.go:451] ScheduleAlgoTime 1.613592ms Start:2018-08-28 10:50:15.819401817 +0000 UTC m=+18.785511349 End:2018-08-28 10:50:15.821015461 +0000 UTC m=+18.787124941
I0828 10:50:15.821063       1 scheduler.go:454] Total Schedule Algo cumulative time:979.862293ms for 504
I0828 10:50:15.822783       1 scheduler.go:451] ScheduleAlgoTime 1.560507ms Start:2018-08-28 10:50:15.821217188 +0000 UTC m=+18.787326715 End:2018-08-28 10:50:15.822777741 +0000 UTC m=+18.788887222
I0828 10:50:15.822822       1 scheduler.go:454] Total Schedule Algo cumulative time:981.4228ms for 505
I0828 10:50:15.824451       1 scheduler.go:451] ScheduleAlgoTime 1.499598ms Start:2018-08-28 10:50:15.822945641 +0000 UTC m=+18.789055189 End:2018-08-28 10:50:15.824445305 +0000 UTC m=+18.790554787
I0828 10:50:15.824488       1 scheduler.go:454] Total Schedule Algo cumulative time:982.922398ms for 506
I0828 10:50:15.826507       1 scheduler.go:451] ScheduleAlgoTime 1.895174ms Start:2018-08-28 10:50:15.824600383 +0000 UTC m=+18.790709896 End:2018-08-28 10:50:15.826495541 +0000 UTC m=+18.792605070
I0828 10:50:15.826543       1 scheduler.go:454] Total Schedule Algo cumulative time:984.817572ms for 507
I0828 10:50:15.828106       1 scheduler.go:451] ScheduleAlgoTime 1.405015ms Start:2018-08-28 10:50:15.826695198 +0000 UTC m=+18.792804739 End:2018-08-28 10:50:15.82810027 +0000 UTC m=+18.794209754
I0828 10:50:15.828130       1 scheduler.go:454] Total Schedule Algo cumulative time:986.222587ms for 508
I0828 10:50:15.829681       1 scheduler.go:451] ScheduleAlgoTime 1.421233ms Start:2018-08-28 10:50:15.828254748 +0000 UTC m=+18.794364269 End:2018-08-28 10:50:15.829676022 +0000 UTC m=+18.795785502
I0828 10:50:15.829702       1 scheduler.go:454] Total Schedule Algo cumulative time:987.64382ms for 509
I0828 10:50:15.831368       1 scheduler.go:451] ScheduleAlgoTime 1.581556ms Start:2018-08-28 10:50:15.829780097 +0000 UTC m=+18.795889654 End:2018-08-28 10:50:15.831361729 +0000 UTC m=+18.797471210
I0828 10:50:15.831394       1 scheduler.go:454] Total Schedule Algo cumulative time:989.225376ms for 510
I0828 10:50:15.833223       1 scheduler.go:451] ScheduleAlgoTime 1.735888ms Start:2018-08-28 10:50:15.831478476 +0000 UTC m=+18.797588013 End:2018-08-28 10:50:15.83321437 +0000 UTC m=+18.799323901
I0828 10:50:15.833261       1 scheduler.go:454] Total Schedule Algo cumulative time:990.961264ms for 511
I0828 10:50:15.834900       1 scheduler.go:451] ScheduleAlgoTime 1.466907ms Start:2018-08-28 10:50:15.833427059 +0000 UTC m=+18.799536596 End:2018-08-28 10:50:15.834894005 +0000 UTC m=+18.801003503
I0828 10:50:15.834922       1 scheduler.go:454] Total Schedule Algo cumulative time:992.428171ms for 512
I0828 10:50:15.836589       1 scheduler.go:451] ScheduleAlgoTime 1.536651ms Start:2018-08-28 10:50:15.835047276 +0000 UTC m=+18.801156775 End:2018-08-28 10:50:15.836583947 +0000 UTC m=+18.802693426
I0828 10:50:15.836612       1 scheduler.go:454] Total Schedule Algo cumulative time:993.964822ms for 513
I0828 10:50:15.838464       1 scheduler.go:451] ScheduleAlgoTime 1.664212ms Start:2018-08-28 10:50:15.836795009 +0000 UTC m=+18.802904569 End:2018-08-28 10:50:15.838459301 +0000 UTC m=+18.804568781
I0828 10:50:15.838488       1 scheduler.go:454] Total Schedule Algo cumulative time:995.629034ms for 514
I0828 10:50:15.840050       1 scheduler.go:451] ScheduleAlgoTime 1.459873ms Start:2018-08-28 10:50:15.838584696 +0000 UTC m=+18.804694240 End:2018-08-28 10:50:15.84004463 +0000 UTC m=+18.806154113
I0828 10:50:15.840084       1 scheduler.go:454] Total Schedule Algo cumulative time:997.088907ms for 515
I0828 10:50:15.841836       1 scheduler.go:451] ScheduleAlgoTime 1.585239ms Start:2018-08-28 10:50:15.840245969 +0000 UTC m=+18.806355470 End:2018-08-28 10:50:15.841831229 +0000 UTC m=+18.807940709
I0828 10:50:15.841864       1 scheduler.go:454] Total Schedule Algo cumulative time:998.674146ms for 516
I0828 10:50:15.843579       1 scheduler.go:451] ScheduleAlgoTime 1.629297ms Start:2018-08-28 10:50:15.841943754 +0000 UTC m=+18.808053298 End:2018-08-28 10:50:15.843573111 +0000 UTC m=+18.809682595
I0828 10:50:15.843600       1 scheduler.go:454] Total Schedule Algo cumulative time:1.000303443s for 517
I0828 10:50:15.845498       1 scheduler.go:451] ScheduleAlgoTime 1.78435ms Start:2018-08-28 10:50:15.8437079 +0000 UTC m=+18.809817398 End:2018-08-28 10:50:15.845492267 +0000 UTC m=+18.811601748
I0828 10:50:15.845520       1 scheduler.go:454] Total Schedule Algo cumulative time:1.002087793s for 518
I0828 10:50:15.847328       1 scheduler.go:451] ScheduleAlgoTime 1.681643ms Start:2018-08-28 10:50:15.845640301 +0000 UTC m=+18.811749807 End:2018-08-28 10:50:15.84732197 +0000 UTC m=+18.813431450
I0828 10:50:15.847352       1 scheduler.go:454] Total Schedule Algo cumulative time:1.003769436s for 519
I0828 10:50:15.848929       1 scheduler.go:451] ScheduleAlgoTime 1.506951ms Start:2018-08-28 10:50:15.847417876 +0000 UTC m=+18.813527404 End:2018-08-28 10:50:15.848924875 +0000 UTC m=+18.815034355
I0828 10:50:15.848947       1 scheduler.go:454] Total Schedule Algo cumulative time:1.005276387s for 520
I0828 10:50:15.850713       1 scheduler.go:451] ScheduleAlgoTime 1.641964ms Start:2018-08-28 10:50:15.84906611 +0000 UTC m=+18.815175650 End:2018-08-28 10:50:15.850708135 +0000 UTC m=+18.816817614
I0828 10:50:15.850742       1 scheduler.go:454] Total Schedule Algo cumulative time:1.006918351s for 521
I0828 10:50:15.852335       1 scheduler.go:451] ScheduleAlgoTime 1.459774ms Start:2018-08-28 10:50:15.850870614 +0000 UTC m=+18.816980144 End:2018-08-28 10:50:15.852330434 +0000 UTC m=+18.818439918
I0828 10:50:15.852357       1 scheduler.go:454] Total Schedule Algo cumulative time:1.008378125s for 522
I0828 10:50:15.854058       1 scheduler.go:451] ScheduleAlgoTime 1.582873ms Start:2018-08-28 10:50:15.8524682 +0000 UTC m=+18.818577734 End:2018-08-28 10:50:15.854051123 +0000 UTC m=+18.820160607
I0828 10:50:15.854085       1 scheduler.go:454] Total Schedule Algo cumulative time:1.009960998s for 523
I0828 10:50:15.855820       1 scheduler.go:451] ScheduleAlgoTime 1.617795ms Start:2018-08-28 10:50:15.854198068 +0000 UTC m=+18.820307587 End:2018-08-28 10:50:15.855815899 +0000 UTC m=+18.821925382
I0828 10:50:15.855840       1 scheduler.go:454] Total Schedule Algo cumulative time:1.011578793s for 524
I0828 10:50:15.857902       1 scheduler.go:451] ScheduleAlgoTime 1.896787ms Start:2018-08-28 10:50:15.856001468 +0000 UTC m=+18.822111010 End:2018-08-28 10:50:15.857898314 +0000 UTC m=+18.824007797
I0828 10:50:15.857922       1 scheduler.go:454] Total Schedule Algo cumulative time:1.01347558s for 525
I0828 10:50:15.859626       1 scheduler.go:451] ScheduleAlgoTime 1.599755ms Start:2018-08-28 10:50:15.858021457 +0000 UTC m=+18.824130974 End:2018-08-28 10:50:15.859621246 +0000 UTC m=+18.825730729
I0828 10:50:15.859646       1 scheduler.go:454] Total Schedule Algo cumulative time:1.015075335s for 526
I0828 10:50:15.861255       1 scheduler.go:451] ScheduleAlgoTime 1.525875ms Start:2018-08-28 10:50:15.85972432 +0000 UTC m=+18.825833833 End:2018-08-28 10:50:15.861250225 +0000 UTC m=+18.827359708
I0828 10:50:15.861278       1 scheduler.go:454] Total Schedule Algo cumulative time:1.01660121s for 527
I0828 10:50:15.862927       1 scheduler.go:451] ScheduleAlgoTime 1.566651ms Start:2018-08-28 10:50:15.861354386 +0000 UTC m=+18.827463910 End:2018-08-28 10:50:15.862921081 +0000 UTC m=+18.829030561
I0828 10:50:15.862951       1 scheduler.go:454] Total Schedule Algo cumulative time:1.018167861s for 528
I0828 10:50:15.864721       1 scheduler.go:451] ScheduleAlgoTime 1.631139ms Start:2018-08-28 10:50:15.863085081 +0000 UTC m=+18.829194600 End:2018-08-28 10:50:15.864716255 +0000 UTC m=+18.830825739
I0828 10:50:15.864751       1 scheduler.go:454] Total Schedule Algo cumulative time:1.019799s for 529
I0828 10:50:15.866574       1 scheduler.go:451] ScheduleAlgoTime 1.697936ms Start:2018-08-28 10:50:15.864869528 +0000 UTC m=+18.830979050 End:2018-08-28 10:50:15.866567507 +0000 UTC m=+18.832676986
I0828 10:50:15.866597       1 scheduler.go:454] Total Schedule Algo cumulative time:1.021496936s for 530
I0828 10:50:15.868387       1 scheduler.go:451] ScheduleAlgoTime 1.666565ms Start:2018-08-28 10:50:15.866713721 +0000 UTC m=+18.832823239 End:2018-08-28 10:50:15.86838032 +0000 UTC m=+18.834489804
I0828 10:50:15.868415       1 scheduler.go:454] Total Schedule Algo cumulative time:1.023163501s for 531
I0828 10:50:15.870370       1 scheduler.go:451] ScheduleAlgoTime 1.837886ms Start:2018-08-28 10:50:15.868528379 +0000 UTC m=+18.834637899 End:2018-08-28 10:50:15.870366305 +0000 UTC m=+18.836475785
I0828 10:50:15.870395       1 scheduler.go:454] Total Schedule Algo cumulative time:1.025001387s for 532
I0828 10:50:15.872180       1 scheduler.go:451] ScheduleAlgoTime 1.589532ms Start:2018-08-28 10:50:15.870583253 +0000 UTC m=+18.836692790 End:2018-08-28 10:50:15.872172702 +0000 UTC m=+18.838282322
I0828 10:50:15.872208       1 scheduler.go:454] Total Schedule Algo cumulative time:1.026590919s for 533
I0828 10:50:15.873832       1 scheduler.go:451] ScheduleAlgoTime 1.476662ms Start:2018-08-28 10:50:15.872349965 +0000 UTC m=+18.838459447 End:2018-08-28 10:50:15.873826627 +0000 UTC m=+18.839936109
I0828 10:50:15.873854       1 scheduler.go:454] Total Schedule Algo cumulative time:1.028067581s for 534
I0828 10:50:15.875708       1 scheduler.go:451] ScheduleAlgoTime 1.735623ms Start:2018-08-28 10:50:15.873968228 +0000 UTC m=+18.840077766 End:2018-08-28 10:50:15.875703909 +0000 UTC m=+18.841813389
I0828 10:50:15.875728       1 scheduler.go:454] Total Schedule Algo cumulative time:1.029803204s for 535
I0828 10:50:15.877357       1 scheduler.go:451] ScheduleAlgoTime 1.473133ms Start:2018-08-28 10:50:15.875878889 +0000 UTC m=+18.841988429 End:2018-08-28 10:50:15.877352081 +0000 UTC m=+18.843461562
I0828 10:50:15.877378       1 scheduler.go:454] Total Schedule Algo cumulative time:1.031276337s for 536
I0828 10:50:15.878858       1 scheduler.go:451] ScheduleAlgoTime 1.389621ms Start:2018-08-28 10:50:15.87746459 +0000 UTC m=+18.843574086 End:2018-08-28 10:50:15.878854227 +0000 UTC m=+18.844963707
I0828 10:50:15.878878       1 scheduler.go:454] Total Schedule Algo cumulative time:1.032665958s for 537
I0828 10:50:15.880647       1 scheduler.go:451] ScheduleAlgoTime 1.670122ms Start:2018-08-28 10:50:15.878971826 +0000 UTC m=+18.845081372 End:2018-08-28 10:50:15.880642009 +0000 UTC m=+18.846751494
I0828 10:50:15.880667       1 scheduler.go:454] Total Schedule Algo cumulative time:1.03433608s for 538
I0828 10:50:15.882354       1 scheduler.go:451] ScheduleAlgoTime 1.622218ms Start:2018-08-28 10:50:15.88072696 +0000 UTC m=+18.846836497 End:2018-08-28 10:50:15.882349234 +0000 UTC m=+18.848458715
I0828 10:50:15.882378       1 scheduler.go:454] Total Schedule Algo cumulative time:1.035958298s for 539
I0828 10:50:15.884113       1 scheduler.go:451] ScheduleAlgoTime 1.597308ms Start:2018-08-28 10:50:15.882511131 +0000 UTC m=+18.848620674 End:2018-08-28 10:50:15.8841085 +0000 UTC m=+18.850217982
I0828 10:50:15.884133       1 scheduler.go:454] Total Schedule Algo cumulative time:1.037555606s for 540
I0828 10:50:15.885754       1 scheduler.go:451] ScheduleAlgoTime 1.488842ms Start:2018-08-28 10:50:15.884259261 +0000 UTC m=+18.850368801 End:2018-08-28 10:50:15.885748158 +0000 UTC m=+18.851857643
I0828 10:50:15.885775       1 scheduler.go:454] Total Schedule Algo cumulative time:1.039044448s for 541
I0828 10:50:15.887368       1 scheduler.go:451] ScheduleAlgoTime 1.476121ms Start:2018-08-28 10:50:15.885887289 +0000 UTC m=+18.851996789 End:2018-08-28 10:50:15.88736343 +0000 UTC m=+18.853472910
I0828 10:50:15.887396       1 scheduler.go:454] Total Schedule Algo cumulative time:1.040520569s for 542
I0828 10:50:15.889514       1 scheduler.go:451] ScheduleAlgoTime 2.008032ms Start:2018-08-28 10:50:15.8875009 +0000 UTC m=+18.853610423 End:2018-08-28 10:50:15.889508972 +0000 UTC m=+18.855618455
I0828 10:50:15.889537       1 scheduler.go:454] Total Schedule Algo cumulative time:1.042528601s for 543
I0828 10:50:15.891321       1 scheduler.go:451] ScheduleAlgoTime 1.638301ms Start:2018-08-28 10:50:15.889678037 +0000 UTC m=+18.855787538 End:2018-08-28 10:50:15.891316355 +0000 UTC m=+18.857425839
I0828 10:50:15.891342       1 scheduler.go:454] Total Schedule Algo cumulative time:1.044166902s for 544
I0828 10:50:15.893258       1 scheduler.go:451] ScheduleAlgoTime 1.78624ms Start:2018-08-28 10:50:15.891467537 +0000 UTC m=+18.857577044 End:2018-08-28 10:50:15.893253795 +0000 UTC m=+18.859363284
I0828 10:50:15.893296       1 scheduler.go:454] Total Schedule Algo cumulative time:1.045953142s for 545
I0828 10:50:15.894966       1 scheduler.go:451] ScheduleAlgoTime 1.558845ms Start:2018-08-28 10:50:15.89340185 +0000 UTC m=+18.859511358 End:2018-08-28 10:50:15.894960723 +0000 UTC m=+18.861070203
I0828 10:50:15.894986       1 scheduler.go:454] Total Schedule Algo cumulative time:1.047511987s for 546
I0828 10:50:15.896765       1 scheduler.go:451] ScheduleAlgoTime 1.655396ms Start:2018-08-28 10:50:15.895101042 +0000 UTC m=+18.861210560 End:2018-08-28 10:50:15.896756424 +0000 UTC m=+18.862865956
I0828 10:50:15.896795       1 scheduler.go:454] Total Schedule Algo cumulative time:1.049167383s for 547
I0828 10:50:15.903831       1 scheduler.go:451] ScheduleAlgoTime 6.916949ms Start:2018-08-28 10:50:15.89690856 +0000 UTC m=+18.863018106 End:2018-08-28 10:50:15.903825572 +0000 UTC m=+18.869935055
I0828 10:50:15.903862       1 scheduler.go:454] Total Schedule Algo cumulative time:1.056084332s for 548
I0828 10:50:15.905881       1 scheduler.go:451] ScheduleAlgoTime 1.897183ms Start:2018-08-28 10:50:15.903977904 +0000 UTC m=+18.870087441 End:2018-08-28 10:50:15.90587514 +0000 UTC m=+18.871984624
I0828 10:50:15.905908       1 scheduler.go:454] Total Schedule Algo cumulative time:1.057981515s for 549
I0828 10:50:15.908176       1 scheduler.go:451] ScheduleAlgoTime 2.156738ms Start:2018-08-28 10:50:15.906014136 +0000 UTC m=+18.872123698 End:2018-08-28 10:50:15.908170956 +0000 UTC m=+18.874280436
I0828 10:50:15.908202       1 scheduler.go:454] Total Schedule Algo cumulative time:1.060138253s for 550
I0828 10:50:15.910221       1 scheduler.go:451] ScheduleAlgoTime 1.88717ms Start:2018-08-28 10:50:15.908325977 +0000 UTC m=+18.874435472 End:2018-08-28 10:50:15.910213162 +0000 UTC m=+18.876322642
I0828 10:50:15.910253       1 scheduler.go:454] Total Schedule Algo cumulative time:1.062025423s for 551
I0828 10:50:15.912149       1 scheduler.go:451] ScheduleAlgoTime 1.766382ms Start:2018-08-28 10:50:15.910369119 +0000 UTC m=+18.876478616 End:2018-08-28 10:50:15.912135518 +0000 UTC m=+18.878244998
I0828 10:50:15.912171       1 scheduler.go:454] Total Schedule Algo cumulative time:1.063791805s for 552
I0828 10:50:15.914000       1 scheduler.go:451] ScheduleAlgoTime 1.680055ms Start:2018-08-28 10:50:15.912314995 +0000 UTC m=+18.878424518 End:2018-08-28 10:50:15.913995093 +0000 UTC m=+18.880104573
I0828 10:50:15.914024       1 scheduler.go:454] Total Schedule Algo cumulative time:1.06547186s for 553
I0828 10:50:15.915779       1 scheduler.go:451] ScheduleAlgoTime 1.616908ms Start:2018-08-28 10:50:15.914157278 +0000 UTC m=+18.880266833 End:2018-08-28 10:50:15.915774257 +0000 UTC m=+18.881883741
I0828 10:50:15.915806       1 scheduler.go:454] Total Schedule Algo cumulative time:1.067088768s for 554
I0828 10:50:15.917508       1 scheduler.go:451] ScheduleAlgoTime 1.533133ms Start:2018-08-28 10:50:15.915969055 +0000 UTC m=+18.882078583 End:2018-08-28 10:50:15.917502235 +0000 UTC m=+18.883611716
I0828 10:50:15.917538       1 scheduler.go:454] Total Schedule Algo cumulative time:1.068621901s for 555
I0828 10:50:15.919477       1 scheduler.go:451] ScheduleAlgoTime 1.86348ms Start:2018-08-28 10:50:15.917606939 +0000 UTC m=+18.883716483 End:2018-08-28 10:50:15.919470475 +0000 UTC m=+18.885579963
I0828 10:50:15.919514       1 scheduler.go:454] Total Schedule Algo cumulative time:1.070485381s for 556
I0828 10:50:15.921133       1 scheduler.go:451] ScheduleAlgoTime 1.499868ms Start:2018-08-28 10:50:15.919628468 +0000 UTC m=+18.885737988 End:2018-08-28 10:50:15.921128375 +0000 UTC m=+18.887237856
I0828 10:50:15.921168       1 scheduler.go:454] Total Schedule Algo cumulative time:1.071985249s for 557
I0828 10:50:15.923102       1 scheduler.go:451] ScheduleAlgoTime 1.810063ms Start:2018-08-28 10:50:15.921283977 +0000 UTC m=+18.887393560 End:2018-08-28 10:50:15.923094134 +0000 UTC m=+18.889203623
I0828 10:50:15.923129       1 scheduler.go:454] Total Schedule Algo cumulative time:1.073795312s for 558
I0828 10:50:15.924930       1 scheduler.go:451] ScheduleAlgoTime 1.514482ms Start:2018-08-28 10:50:15.923410405 +0000 UTC m=+18.889519932 End:2018-08-28 10:50:15.924924934 +0000 UTC m=+18.891034414
I0828 10:50:15.924955       1 scheduler.go:454] Total Schedule Algo cumulative time:1.075309794s for 559
I0828 10:50:15.926699       1 scheduler.go:451] ScheduleAlgoTime 1.564513ms Start:2018-08-28 10:50:15.925130028 +0000 UTC m=+18.891239539 End:2018-08-28 10:50:15.926694567 +0000 UTC m=+18.892804052
I0828 10:50:15.926722       1 scheduler.go:454] Total Schedule Algo cumulative time:1.076874307s for 560
I0828 10:50:15.928391       1 scheduler.go:451] ScheduleAlgoTime 1.525082ms Start:2018-08-28 10:50:15.926859049 +0000 UTC m=+18.892968568 End:2018-08-28 10:50:15.928384171 +0000 UTC m=+18.894493650
I0828 10:50:15.928418       1 scheduler.go:454] Total Schedule Algo cumulative time:1.078399389s for 561
I0828 10:50:15.930120       1 scheduler.go:451] ScheduleAlgoTime 1.582679ms Start:2018-08-28 10:50:15.928532429 +0000 UTC m=+18.894641947 End:2018-08-28 10:50:15.930115145 +0000 UTC m=+18.896224626
I0828 10:50:15.930149       1 scheduler.go:454] Total Schedule Algo cumulative time:1.079982068s for 562
I0828 10:50:15.931912       1 scheduler.go:451] ScheduleAlgoTime 1.659417ms Start:2018-08-28 10:50:15.930244137 +0000 UTC m=+18.896353712 End:2018-08-28 10:50:15.931903646 +0000 UTC m=+18.898013129
I0828 10:50:15.931942       1 scheduler.go:454] Total Schedule Algo cumulative time:1.081641485s for 563
I0828 10:50:15.933681       1 scheduler.go:451] ScheduleAlgoTime 1.597732ms Start:2018-08-28 10:50:15.932077851 +0000 UTC m=+18.898187382 End:2018-08-28 10:50:15.933675634 +0000 UTC m=+18.899785114
I0828 10:50:15.933704       1 scheduler.go:454] Total Schedule Algo cumulative time:1.083239217s for 564
I0828 10:50:15.935387       1 scheduler.go:451] ScheduleAlgoTime 1.547604ms Start:2018-08-28 10:50:15.933834117 +0000 UTC m=+18.899943665 End:2018-08-28 10:50:15.935381788 +0000 UTC m=+18.901491269
I0828 10:50:15.935408       1 scheduler.go:454] Total Schedule Algo cumulative time:1.084786821s for 565
I0828 10:50:15.937055       1 scheduler.go:451] ScheduleAlgoTime 1.573269ms Start:2018-08-28 10:50:15.935475612 +0000 UTC m=+18.901585112 End:2018-08-28 10:50:15.937048902 +0000 UTC m=+18.903158381
I0828 10:50:15.937079       1 scheduler.go:454] Total Schedule Algo cumulative time:1.08636009s for 566
I0828 10:50:15.938868       1 scheduler.go:451] ScheduleAlgoTime 1.631664ms Start:2018-08-28 10:50:15.937231388 +0000 UTC m=+18.903340934 End:2018-08-28 10:50:15.938863117 +0000 UTC m=+18.904972598
I0828 10:50:15.938890       1 scheduler.go:454] Total Schedule Algo cumulative time:1.087991754s for 567
I0828 10:50:15.940927       1 scheduler.go:451] ScheduleAlgoTime 1.909376ms Start:2018-08-28 10:50:15.939009218 +0000 UTC m=+18.905118768 End:2018-08-28 10:50:15.94091866 +0000 UTC m=+18.907028144
I0828 10:50:15.940955       1 scheduler.go:454] Total Schedule Algo cumulative time:1.08990113s for 568
I0828 10:50:15.942685       1 scheduler.go:451] ScheduleAlgoTime 1.595424ms Start:2018-08-28 10:50:15.941083844 +0000 UTC m=+18.907193379 End:2018-08-28 10:50:15.942679323 +0000 UTC m=+18.908788803
I0828 10:50:15.942706       1 scheduler.go:454] Total Schedule Algo cumulative time:1.091496554s for 569
I0828 10:50:15.944635       1 scheduler.go:451] ScheduleAlgoTime 1.7995ms Start:2018-08-28 10:50:15.942830332 +0000 UTC m=+18.908939841 End:2018-08-28 10:50:15.944629856 +0000 UTC m=+18.910739341
I0828 10:50:15.944661       1 scheduler.go:454] Total Schedule Algo cumulative time:1.093296054s for 570
I0828 10:50:15.946257       1 scheduler.go:451] ScheduleAlgoTime 1.489958ms Start:2018-08-28 10:50:15.944760578 +0000 UTC m=+18.910870174 End:2018-08-28 10:50:15.946250644 +0000 UTC m=+18.912360132
I0828 10:50:15.946284       1 scheduler.go:454] Total Schedule Algo cumulative time:1.094786012s for 571
I0828 10:50:15.947967       1 scheduler.go:451] ScheduleAlgoTime 1.550391ms Start:2018-08-28 10:50:15.946411342 +0000 UTC m=+18.912520870 End:2018-08-28 10:50:15.94796178 +0000 UTC m=+18.914071261
I0828 10:50:15.947995       1 scheduler.go:454] Total Schedule Algo cumulative time:1.096336403s for 572
I0828 10:50:15.949612       1 scheduler.go:451] ScheduleAlgoTime 1.50142ms Start:2018-08-28 10:50:15.94810576 +0000 UTC m=+18.914215260 End:2018-08-28 10:50:15.949607198 +0000 UTC m=+18.915716680
I0828 10:50:15.949637       1 scheduler.go:454] Total Schedule Algo cumulative time:1.097837823s for 573
I0828 10:50:15.951438       1 scheduler.go:451] ScheduleAlgoTime 1.685967ms Start:2018-08-28 10:50:15.949746823 +0000 UTC m=+18.915856345 End:2018-08-28 10:50:15.951432831 +0000 UTC m=+18.917542312
I0828 10:50:15.951460       1 scheduler.go:454] Total Schedule Algo cumulative time:1.09952379s for 574
I0828 10:50:15.953178       1 scheduler.go:451] ScheduleAlgoTime 1.591831ms Start:2018-08-28 10:50:15.951581222 +0000 UTC m=+18.917690763 End:2018-08-28 10:50:15.953173115 +0000 UTC m=+18.919282594
I0828 10:50:15.953200       1 scheduler.go:454] Total Schedule Algo cumulative time:1.101115621s for 575
I0828 10:50:15.955007       1 scheduler.go:451] ScheduleAlgoTime 1.685792ms Start:2018-08-28 10:50:15.953315488 +0000 UTC m=+18.919425035 End:2018-08-28 10:50:15.955001347 +0000 UTC m=+18.921110827
I0828 10:50:15.955027       1 scheduler.go:454] Total Schedule Algo cumulative time:1.102801413s for 576
I0828 10:50:15.956719       1 scheduler.go:451] ScheduleAlgoTime 1.551162ms Start:2018-08-28 10:50:15.955163092 +0000 UTC m=+18.921272609 End:2018-08-28 10:50:15.95671429 +0000 UTC m=+18.922823771
I0828 10:50:15.956744       1 scheduler.go:454] Total Schedule Algo cumulative time:1.104352575s for 577
I0828 10:50:15.958554       1 scheduler.go:451] ScheduleAlgoTime 1.70313ms Start:2018-08-28 10:50:15.956845697 +0000 UTC m=+18.922955206 End:2018-08-28 10:50:15.958548856 +0000 UTC m=+18.924658336
I0828 10:50:15.958578       1 scheduler.go:454] Total Schedule Algo cumulative time:1.106055705s for 578
I0828 10:50:15.960332       1 scheduler.go:451] ScheduleAlgoTime 1.650107ms Start:2018-08-28 10:50:15.958673977 +0000 UTC m=+18.924783620 End:2018-08-28 10:50:15.96032424 +0000 UTC m=+18.926433727
I0828 10:50:15.960359       1 scheduler.go:454] Total Schedule Algo cumulative time:1.107705812s for 579
I0828 10:50:15.962090       1 scheduler.go:451] ScheduleAlgoTime 1.613255ms Start:2018-08-28 10:50:15.960471101 +0000 UTC m=+18.926580640 End:2018-08-28 10:50:15.962084414 +0000 UTC m=+18.928193895
I0828 10:50:15.962123       1 scheduler.go:454] Total Schedule Algo cumulative time:1.109319067s for 580
I0828 10:50:15.964098       1 scheduler.go:451] ScheduleAlgoTime 1.804752ms Start:2018-08-28 10:50:15.962287349 +0000 UTC m=+18.928396863 End:2018-08-28 10:50:15.964092136 +0000 UTC m=+18.930201615
I0828 10:50:15.964120       1 scheduler.go:454] Total Schedule Algo cumulative time:1.111123819s for 581
I0828 10:50:15.965947       1 scheduler.go:451] ScheduleAlgoTime 1.693614ms Start:2018-08-28 10:50:15.964247195 +0000 UTC m=+18.930356729 End:2018-08-28 10:50:15.965940863 +0000 UTC m=+18.932050343
I0828 10:50:15.965972       1 scheduler.go:454] Total Schedule Algo cumulative time:1.112817433s for 582
I0828 10:50:15.967774       1 scheduler.go:451] ScheduleAlgoTime 1.707432ms Start:2018-08-28 10:50:15.966060882 +0000 UTC m=+18.932170389 End:2018-08-28 10:50:15.96776834 +0000 UTC m=+18.933877821
I0828 10:50:15.967803       1 scheduler.go:454] Total Schedule Algo cumulative time:1.114524865s for 583
I0828 10:50:15.969626       1 scheduler.go:451] ScheduleAlgoTime 1.691529ms Start:2018-08-28 10:50:15.967929389 +0000 UTC m=+18.934038887 End:2018-08-28 10:50:15.969620937 +0000 UTC m=+18.935730416
I0828 10:50:15.969650       1 scheduler.go:454] Total Schedule Algo cumulative time:1.116216394s for 584
I0828 10:50:15.971241       1 scheduler.go:451] ScheduleAlgoTime 1.514323ms Start:2018-08-28 10:50:15.969721753 +0000 UTC m=+18.935831287 End:2018-08-28 10:50:15.971236123 +0000 UTC m=+18.937345610
I0828 10:50:15.971261       1 scheduler.go:454] Total Schedule Algo cumulative time:1.117730717s for 585
I0828 10:50:15.973363       1 scheduler.go:451] ScheduleAlgoTime 1.9418ms Start:2018-08-28 10:50:15.97141349 +0000 UTC m=+18.937523024 End:2018-08-28 10:50:15.973355251 +0000 UTC m=+18.939464824
I0828 10:50:15.973394       1 scheduler.go:454] Total Schedule Algo cumulative time:1.119672517s for 586
I0828 10:50:15.975166       1 scheduler.go:451] ScheduleAlgoTime 1.620548ms Start:2018-08-28 10:50:15.973540059 +0000 UTC m=+18.939649567 End:2018-08-28 10:50:15.975160632 +0000 UTC m=+18.941270115
I0828 10:50:15.975190       1 scheduler.go:454] Total Schedule Algo cumulative time:1.121293065s for 587
I0828 10:50:15.976784       1 scheduler.go:451] ScheduleAlgoTime 1.494391ms Start:2018-08-28 10:50:15.97528485 +0000 UTC m=+18.941394386 End:2018-08-28 10:50:15.976779296 +0000 UTC m=+18.942888777
I0828 10:50:15.976812       1 scheduler.go:454] Total Schedule Algo cumulative time:1.122787456s for 588
I0828 10:50:15.978565       1 scheduler.go:451] ScheduleAlgoTime 1.628747ms Start:2018-08-28 10:50:15.976930796 +0000 UTC m=+18.943040325 End:2018-08-28 10:50:15.978559591 +0000 UTC m=+18.944669072
I0828 10:50:15.978589       1 scheduler.go:454] Total Schedule Algo cumulative time:1.124416203s for 589
I0828 10:50:15.980232       1 scheduler.go:451] ScheduleAlgoTime 1.500641ms Start:2018-08-28 10:50:15.978726166 +0000 UTC m=+18.944835703 End:2018-08-28 10:50:15.980226864 +0000 UTC m=+18.946336344
I0828 10:50:15.980254       1 scheduler.go:454] Total Schedule Algo cumulative time:1.125916844s for 590
I0828 10:50:15.982011       1 scheduler.go:451] ScheduleAlgoTime 1.657542ms Start:2018-08-28 10:50:15.980347566 +0000 UTC m=+18.946457085 End:2018-08-28 10:50:15.982005145 +0000 UTC m=+18.948114627
I0828 10:50:15.982033       1 scheduler.go:454] Total Schedule Algo cumulative time:1.127574386s for 591
I0828 10:50:15.983886       1 scheduler.go:451] ScheduleAlgoTime 1.701431ms Start:2018-08-28 10:50:15.982179149 +0000 UTC m=+18.948288692 End:2018-08-28 10:50:15.983880642 +0000 UTC m=+18.949990123
I0828 10:50:15.983906       1 scheduler.go:454] Total Schedule Algo cumulative time:1.129275817s for 592
I0828 10:50:15.985576       1 scheduler.go:451] ScheduleAlgoTime 1.554546ms Start:2018-08-28 10:50:15.984016181 +0000 UTC m=+18.950125690 End:2018-08-28 10:50:15.985570756 +0000 UTC m=+18.951680236
I0828 10:50:15.985601       1 scheduler.go:454] Total Schedule Algo cumulative time:1.130830363s for 593
I0828 10:50:15.987378       1 scheduler.go:451] ScheduleAlgoTime 1.63725ms Start:2018-08-28 10:50:15.985735362 +0000 UTC m=+18.951844914 End:2018-08-28 10:50:15.987372683 +0000 UTC m=+18.953482164
I0828 10:50:15.987400       1 scheduler.go:454] Total Schedule Algo cumulative time:1.132467613s for 594
I0828 10:50:15.989223       1 scheduler.go:451] ScheduleAlgoTime 1.706698ms Start:2018-08-28 10:50:15.987509737 +0000 UTC m=+18.953619267 End:2018-08-28 10:50:15.989216484 +0000 UTC m=+18.955325965
I0828 10:50:15.989253       1 scheduler.go:454] Total Schedule Algo cumulative time:1.134174311s for 595
I0828 10:50:15.990804       1 scheduler.go:451] ScheduleAlgoTime 1.47878ms Start:2018-08-28 10:50:15.98932027 +0000 UTC m=+18.955429840 End:2018-08-28 10:50:15.99079914 +0000 UTC m=+18.956908620
I0828 10:50:15.990823       1 scheduler.go:454] Total Schedule Algo cumulative time:1.135653091s for 596
I0828 10:50:15.992329       1 scheduler.go:451] ScheduleAlgoTime 1.365669ms Start:2018-08-28 10:50:15.990958771 +0000 UTC m=+18.957068306 End:2018-08-28 10:50:15.992324494 +0000 UTC m=+18.958433975
I0828 10:50:15.992350       1 scheduler.go:454] Total Schedule Algo cumulative time:1.13701876s for 597
I0828 10:50:15.994318       1 scheduler.go:451] ScheduleAlgoTime 1.843526ms Start:2018-08-28 10:50:15.992468851 +0000 UTC m=+18.958578389 End:2018-08-28 10:50:15.994312434 +0000 UTC m=+18.960421915
I0828 10:50:15.994338       1 scheduler.go:454] Total Schedule Algo cumulative time:1.138862286s for 598
I0828 10:50:15.997970       1 scheduler.go:451] ScheduleAlgoTime 3.40664ms Start:2018-08-28 10:50:15.994557042 +0000 UTC m=+18.960666549 End:2018-08-28 10:50:15.9979637 +0000 UTC m=+18.964073189
I0828 10:50:15.998013       1 scheduler.go:454] Total Schedule Algo cumulative time:1.142268926s for 599
I0828 10:50:16.001945       1 scheduler.go:451] ScheduleAlgoTime 3.718112ms Start:2018-08-28 10:50:15.998218954 +0000 UTC m=+18.964328535 End:2018-08-28 10:50:16.001937167 +0000 UTC m=+18.968046647
I0828 10:50:16.001981       1 scheduler.go:454] Total Schedule Algo cumulative time:1.145987038s for 600
I0828 10:50:16.004635       1 scheduler.go:451] ScheduleAlgoTime 2.535551ms Start:2018-08-28 10:50:16.002093055 +0000 UTC m=+18.968202551 End:2018-08-28 10:50:16.004628618 +0000 UTC m=+18.970738102
I0828 10:50:16.004667       1 scheduler.go:454] Total Schedule Algo cumulative time:1.148522589s for 601
I0828 10:50:16.006408       1 scheduler.go:451] ScheduleAlgoTime 1.575187ms Start:2018-08-28 10:50:16.00482675 +0000 UTC m=+18.970936245 End:2018-08-28 10:50:16.006401953 +0000 UTC m=+18.972511432
I0828 10:50:16.006442       1 scheduler.go:454] Total Schedule Algo cumulative time:1.150097776s for 602
I0828 10:50:16.008151       1 scheduler.go:451] ScheduleAlgoTime 1.571432ms Start:2018-08-28 10:50:16.006565439 +0000 UTC m=+18.972674958 End:2018-08-28 10:50:16.00813691 +0000 UTC m=+18.974246390
I0828 10:50:16.008188       1 scheduler.go:454] Total Schedule Algo cumulative time:1.151669208s for 603
I0828 10:50:16.010115       1 scheduler.go:451] ScheduleAlgoTime 1.730494ms Start:2018-08-28 10:50:16.008379563 +0000 UTC m=+18.974489092 End:2018-08-28 10:50:16.010110105 +0000 UTC m=+18.976219586
I0828 10:50:16.010150       1 scheduler.go:454] Total Schedule Algo cumulative time:1.153399702s for 604
I0828 10:50:16.011986       1 scheduler.go:451] ScheduleAlgoTime 1.690266ms Start:2018-08-28 10:50:16.0102912 +0000 UTC m=+18.976400715 End:2018-08-28 10:50:16.011981499 +0000 UTC m=+18.978090981
I0828 10:50:16.012008       1 scheduler.go:454] Total Schedule Algo cumulative time:1.155089968s for 605
I0828 10:50:16.013804       1 scheduler.go:451] ScheduleAlgoTime 1.642671ms Start:2018-08-28 10:50:16.012155696 +0000 UTC m=+18.978265244 End:2018-08-28 10:50:16.013798434 +0000 UTC m=+18.979907915
I0828 10:50:16.013833       1 scheduler.go:454] Total Schedule Algo cumulative time:1.156732639s for 606
I0828 10:50:16.015616       1 scheduler.go:451] ScheduleAlgoTime 1.667002ms Start:2018-08-28 10:50:16.013941152 +0000 UTC m=+18.980050693 End:2018-08-28 10:50:16.015608215 +0000 UTC m=+18.981717695
I0828 10:50:16.015647       1 scheduler.go:454] Total Schedule Algo cumulative time:1.158399641s for 607
I0828 10:50:16.017426       1 scheduler.go:451] ScheduleAlgoTime 1.622448ms Start:2018-08-28 10:50:16.015797264 +0000 UTC m=+18.981906815 End:2018-08-28 10:50:16.017419779 +0000 UTC m=+18.983529263
I0828 10:50:16.017462       1 scheduler.go:454] Total Schedule Algo cumulative time:1.160022089s for 608
I0828 10:50:16.019256       1 scheduler.go:451] ScheduleAlgoTime 1.656558ms Start:2018-08-28 10:50:16.01759436 +0000 UTC m=+18.983703884 End:2018-08-28 10:50:16.019250962 +0000 UTC m=+18.985360442
I0828 10:50:16.019280       1 scheduler.go:454] Total Schedule Algo cumulative time:1.161678647s for 609
I0828 10:50:16.021193       1 scheduler.go:451] ScheduleAlgoTime 1.776439ms Start:2018-08-28 10:50:16.019411675 +0000 UTC m=+18.985521169 End:2018-08-28 10:50:16.021188123 +0000 UTC m=+18.987297608
I0828 10:50:16.021234       1 scheduler.go:454] Total Schedule Algo cumulative time:1.163455086s for 610
I0828 10:50:16.022834       1 scheduler.go:451] ScheduleAlgoTime 1.451417ms Start:2018-08-28 10:50:16.021377771 +0000 UTC m=+18.987487316 End:2018-08-28 10:50:16.022829254 +0000 UTC m=+18.988938733
I0828 10:50:16.022857       1 scheduler.go:454] Total Schedule Algo cumulative time:1.164906503s for 611
I0828 10:50:16.024727       1 scheduler.go:451] ScheduleAlgoTime 1.771336ms Start:2018-08-28 10:50:16.022944863 +0000 UTC m=+18.989054404 End:2018-08-28 10:50:16.024716212 +0000 UTC m=+18.990825740
I0828 10:50:16.024760       1 scheduler.go:454] Total Schedule Algo cumulative time:1.166677839s for 612
I0828 10:50:16.026923       1 scheduler.go:451] ScheduleAlgoTime 2.020692ms Start:2018-08-28 10:50:16.024896433 +0000 UTC m=+18.991005996 End:2018-08-28 10:50:16.026917207 +0000 UTC m=+18.993026688
I0828 10:50:16.026949       1 scheduler.go:454] Total Schedule Algo cumulative time:1.168698531s for 613
I0828 10:50:16.028718       1 scheduler.go:451] ScheduleAlgoTime 1.644274ms Start:2018-08-28 10:50:16.027068451 +0000 UTC m=+18.993177976 End:2018-08-28 10:50:16.028712771 +0000 UTC m=+18.994822250
I0828 10:50:16.028737       1 scheduler.go:454] Total Schedule Algo cumulative time:1.170342805s for 614
I0828 10:50:16.030641       1 scheduler.go:451] ScheduleAlgoTime 1.826463ms Start:2018-08-28 10:50:16.028807678 +0000 UTC m=+18.994917221 End:2018-08-28 10:50:16.030634199 +0000 UTC m=+18.996743684
I0828 10:50:16.030668       1 scheduler.go:454] Total Schedule Algo cumulative time:1.172169268s for 615
I0828 10:50:16.032510       1 scheduler.go:451] ScheduleAlgoTime 1.709948ms Start:2018-08-28 10:50:16.030795108 +0000 UTC m=+18.996904621 End:2018-08-28 10:50:16.032505084 +0000 UTC m=+18.998614569
I0828 10:50:16.032532       1 scheduler.go:454] Total Schedule Algo cumulative time:1.173879216s for 616
I0828 10:50:16.034319       1 scheduler.go:451] ScheduleAlgoTime 1.635904ms Start:2018-08-28 10:50:16.032678703 +0000 UTC m=+18.998788242 End:2018-08-28 10:50:16.034314667 +0000 UTC m=+19.000424146
I0828 10:50:16.034342       1 scheduler.go:454] Total Schedule Algo cumulative time:1.17551512s for 617
I0828 10:50:16.036135       1 scheduler.go:451] ScheduleAlgoTime 1.689573ms Start:2018-08-28 10:50:16.034439846 +0000 UTC m=+19.000549414 End:2018-08-28 10:50:16.036129507 +0000 UTC m=+19.002238987
I0828 10:50:16.036164       1 scheduler.go:454] Total Schedule Algo cumulative time:1.177204693s for 618
I0828 10:50:16.037876       1 scheduler.go:451] ScheduleAlgoTime 1.586737ms Start:2018-08-28 10:50:16.036284165 +0000 UTC m=+19.002393645 End:2018-08-28 10:50:16.037870902 +0000 UTC m=+19.003980382
I0828 10:50:16.037899       1 scheduler.go:454] Total Schedule Algo cumulative time:1.17879143s for 619
I0828 10:50:16.039716       1 scheduler.go:451] ScheduleAlgoTime 1.691065ms Start:2018-08-28 10:50:16.03801888 +0000 UTC m=+19.004128407 End:2018-08-28 10:50:16.039709981 +0000 UTC m=+19.005819472
I0828 10:50:16.039742       1 scheduler.go:454] Total Schedule Algo cumulative time:1.180482495s for 620
I0828 10:50:16.041496       1 scheduler.go:451] ScheduleAlgoTime 1.634703ms Start:2018-08-28 10:50:16.039853951 +0000 UTC m=+19.005963498 End:2018-08-28 10:50:16.041488721 +0000 UTC m=+19.007598201
I0828 10:50:16.041525       1 scheduler.go:454] Total Schedule Algo cumulative time:1.182117198s for 621
I0828 10:50:16.043240       1 scheduler.go:451] ScheduleAlgoTime 1.579657ms Start:2018-08-28 10:50:16.041655226 +0000 UTC m=+19.007764739 End:2018-08-28 10:50:16.043234915 +0000 UTC m=+19.009344396
I0828 10:50:16.043262       1 scheduler.go:454] Total Schedule Algo cumulative time:1.183696855s for 622
I0828 10:50:16.045012       1 scheduler.go:451] ScheduleAlgoTime 1.611801ms Start:2018-08-28 10:50:16.04339431 +0000 UTC m=+19.009503809 End:2018-08-28 10:50:16.045006129 +0000 UTC m=+19.011115610
I0828 10:50:16.045032       1 scheduler.go:454] Total Schedule Algo cumulative time:1.185308656s for 623
I0828 10:50:16.046754       1 scheduler.go:451] ScheduleAlgoTime 1.579648ms Start:2018-08-28 10:50:16.04516866 +0000 UTC m=+19.011278163 End:2018-08-28 10:50:16.046748331 +0000 UTC m=+19.012857811
I0828 10:50:16.046781       1 scheduler.go:454] Total Schedule Algo cumulative time:1.186888304s for 624
I0828 10:50:16.048545       1 scheduler.go:451] ScheduleAlgoTime 1.637768ms Start:2018-08-28 10:50:16.046901651 +0000 UTC m=+19.013011233 End:2018-08-28 10:50:16.048539513 +0000 UTC m=+19.014649001
I0828 10:50:16.048568       1 scheduler.go:454] Total Schedule Algo cumulative time:1.188526072s for 625
I0828 10:50:16.050309       1 scheduler.go:451] ScheduleAlgoTime 1.628098ms Start:2018-08-28 10:50:16.048675536 +0000 UTC m=+19.014785098 End:2018-08-28 10:50:16.050303717 +0000 UTC m=+19.016413196
I0828 10:50:16.050331       1 scheduler.go:454] Total Schedule Algo cumulative time:1.19015417s for 626
I0828 10:50:16.051950       1 scheduler.go:451] ScheduleAlgoTime 1.520092ms Start:2018-08-28 10:50:16.05042573 +0000 UTC m=+19.016535301 End:2018-08-28 10:50:16.051945911 +0000 UTC m=+19.018055393
I0828 10:50:16.051969       1 scheduler.go:454] Total Schedule Algo cumulative time:1.191674262s for 627
I0828 10:50:16.053649       1 scheduler.go:451] ScheduleAlgoTime 1.577354ms Start:2018-08-28 10:50:16.052064555 +0000 UTC m=+19.018174053 End:2018-08-28 10:50:16.053641926 +0000 UTC m=+19.019751407
I0828 10:50:16.053674       1 scheduler.go:454] Total Schedule Algo cumulative time:1.193251616s for 628
I0828 10:50:16.055299       1 scheduler.go:451] ScheduleAlgoTime 1.501648ms Start:2018-08-28 10:50:16.053792051 +0000 UTC m=+19.019901563 End:2018-08-28 10:50:16.055293729 +0000 UTC m=+19.021403211
I0828 10:50:16.055320       1 scheduler.go:454] Total Schedule Algo cumulative time:1.194753264s for 629
I0828 10:50:16.056907       1 scheduler.go:451] ScheduleAlgoTime 1.492048ms Start:2018-08-28 10:50:16.055409253 +0000 UTC m=+19.021518791 End:2018-08-28 10:50:16.056901358 +0000 UTC m=+19.023010839
I0828 10:50:16.056929       1 scheduler.go:454] Total Schedule Algo cumulative time:1.196245312s for 630
I0828 10:50:16.058791       1 scheduler.go:451] ScheduleAlgoTime 1.748006ms Start:2018-08-28 10:50:16.05703828 +0000 UTC m=+19.023147817 End:2018-08-28 10:50:16.058786342 +0000 UTC m=+19.024895823
I0828 10:50:16.058814       1 scheduler.go:454] Total Schedule Algo cumulative time:1.197993318s for 631
I0828 10:50:16.060581       1 scheduler.go:451] ScheduleAlgoTime 1.538202ms Start:2018-08-28 10:50:16.059037938 +0000 UTC m=+19.025147470 End:2018-08-28 10:50:16.06057619 +0000 UTC m=+19.026685672
I0828 10:50:16.060600       1 scheduler.go:454] Total Schedule Algo cumulative time:1.19953152s for 632
I0828 10:50:16.062357       1 scheduler.go:451] ScheduleAlgoTime 1.681405ms Start:2018-08-28 10:50:16.060671141 +0000 UTC m=+19.026780686 End:2018-08-28 10:50:16.062352607 +0000 UTC m=+19.028462091
I0828 10:50:16.062378       1 scheduler.go:454] Total Schedule Algo cumulative time:1.201212925s for 633
I0828 10:50:16.063946       1 scheduler.go:451] ScheduleAlgoTime 1.445368ms Start:2018-08-28 10:50:16.062496917 +0000 UTC m=+19.028606453 End:2018-08-28 10:50:16.063942336 +0000 UTC m=+19.030051821
I0828 10:50:16.063965       1 scheduler.go:454] Total Schedule Algo cumulative time:1.202658293s for 634
I0828 10:50:16.065514       1 scheduler.go:451] ScheduleAlgoTime 1.449208ms Start:2018-08-28 10:50:16.064058105 +0000 UTC m=+19.030167629 End:2018-08-28 10:50:16.065507355 +0000 UTC m=+19.031616837
I0828 10:50:16.065544       1 scheduler.go:454] Total Schedule Algo cumulative time:1.204107501s for 635
I0828 10:50:16.067251       1 scheduler.go:451] ScheduleAlgoTime 1.574081ms Start:2018-08-28 10:50:16.065671564 +0000 UTC m=+19.031781068 End:2018-08-28 10:50:16.067245668 +0000 UTC m=+19.033355149
I0828 10:50:16.067275       1 scheduler.go:454] Total Schedule Algo cumulative time:1.205681582s for 636
I0828 10:50:16.069043       1 scheduler.go:451] ScheduleAlgoTime 1.650422ms Start:2018-08-28 10:50:16.067387165 +0000 UTC m=+19.033496698 End:2018-08-28 10:50:16.06903764 +0000 UTC m=+19.035147120
I0828 10:50:16.069075       1 scheduler.go:454] Total Schedule Algo cumulative time:1.207332004s for 637
I0828 10:50:16.070582       1 scheduler.go:451] ScheduleAlgoTime 1.382364ms Start:2018-08-28 10:50:16.069194522 +0000 UTC m=+19.035304039 End:2018-08-28 10:50:16.070576922 +0000 UTC m=+19.036686403
I0828 10:50:16.070604       1 scheduler.go:454] Total Schedule Algo cumulative time:1.208714368s for 638
I0828 10:50:16.072589       1 scheduler.go:451] ScheduleAlgoTime 1.754764ms Start:2018-08-28 10:50:16.070829659 +0000 UTC m=+19.036939174 End:2018-08-28 10:50:16.072584457 +0000 UTC m=+19.038693938
I0828 10:50:16.072611       1 scheduler.go:454] Total Schedule Algo cumulative time:1.210469132s for 639
I0828 10:50:16.074260       1 scheduler.go:451] ScheduleAlgoTime 1.52309ms Start:2018-08-28 10:50:16.072729876 +0000 UTC m=+19.038839387 End:2018-08-28 10:50:16.074252996 +0000 UTC m=+19.040362477
I0828 10:50:16.074284       1 scheduler.go:454] Total Schedule Algo cumulative time:1.211992222s for 640
I0828 10:50:16.076053       1 scheduler.go:451] ScheduleAlgoTime 1.605999ms Start:2018-08-28 10:50:16.074442718 +0000 UTC m=+19.040552236 End:2018-08-28 10:50:16.076048751 +0000 UTC m=+19.042158235
I0828 10:50:16.076074       1 scheduler.go:454] Total Schedule Algo cumulative time:1.213598221s for 641
I0828 10:50:16.077676       1 scheduler.go:451] ScheduleAlgoTime 1.4899ms Start:2018-08-28 10:50:16.076181858 +0000 UTC m=+19.042291355 End:2018-08-28 10:50:16.077671773 +0000 UTC m=+19.043781255
I0828 10:50:16.077699       1 scheduler.go:454] Total Schedule Algo cumulative time:1.215088121s for 642
I0828 10:50:16.079501       1 scheduler.go:451] ScheduleAlgoTime 1.669708ms Start:2018-08-28 10:50:16.077824878 +0000 UTC m=+19.043934441 End:2018-08-28 10:50:16.079494666 +0000 UTC m=+19.045604149
I0828 10:50:16.079526       1 scheduler.go:454] Total Schedule Algo cumulative time:1.216757829s for 643
I0828 10:50:16.081221       1 scheduler.go:451] ScheduleAlgoTime 1.539128ms Start:2018-08-28 10:50:16.079676867 +0000 UTC m=+19.045786423 End:2018-08-28 10:50:16.081216071 +0000 UTC m=+19.047325551
I0828 10:50:16.081243       1 scheduler.go:454] Total Schedule Algo cumulative time:1.218296957s for 644
I0828 10:50:16.082760       1 scheduler.go:451] ScheduleAlgoTime 1.427122ms Start:2018-08-28 10:50:16.081328538 +0000 UTC m=+19.047438082 End:2018-08-28 10:50:16.082755725 +0000 UTC m=+19.048865204
I0828 10:50:16.082781       1 scheduler.go:454] Total Schedule Algo cumulative time:1.219724079s for 645
I0828 10:50:16.084239       1 scheduler.go:451] ScheduleAlgoTime 1.330975ms Start:2018-08-28 10:50:16.082903079 +0000 UTC m=+19.049012595 End:2018-08-28 10:50:16.08423409 +0000 UTC m=+19.050343570
I0828 10:50:16.084259       1 scheduler.go:454] Total Schedule Algo cumulative time:1.221055054s for 646
I0828 10:50:16.085869       1 scheduler.go:451] ScheduleAlgoTime 1.500823ms Start:2018-08-28 10:50:16.084362932 +0000 UTC m=+19.050472473 End:2018-08-28 10:50:16.085863814 +0000 UTC m=+19.051973296
I0828 10:50:16.085890       1 scheduler.go:454] Total Schedule Algo cumulative time:1.222555877s for 647
I0828 10:50:16.087612       1 scheduler.go:451] ScheduleAlgoTime 1.596654ms Start:2018-08-28 10:50:16.086008802 +0000 UTC m=+19.052118306 End:2018-08-28 10:50:16.08760548 +0000 UTC m=+19.053714960
I0828 10:50:16.087638       1 scheduler.go:454] Total Schedule Algo cumulative time:1.224152531s for 648
I0828 10:50:16.089410       1 scheduler.go:451] ScheduleAlgoTime 1.665749ms Start:2018-08-28 10:50:16.08773926 +0000 UTC m=+19.053848781 End:2018-08-28 10:50:16.08940505 +0000 UTC m=+19.055514530
I0828 10:50:16.089441       1 scheduler.go:454] Total Schedule Algo cumulative time:1.22581828s for 649
I0828 10:50:16.091192       1 scheduler.go:451] ScheduleAlgoTime 1.63621ms Start:2018-08-28 10:50:16.089550152 +0000 UTC m=+19.055659685 End:2018-08-28 10:50:16.091186414 +0000 UTC m=+19.057295895
I0828 10:50:16.091228       1 scheduler.go:454] Total Schedule Algo cumulative time:1.22745449s for 650
I0828 10:50:16.096358       1 scheduler.go:451] ScheduleAlgoTime 4.955788ms Start:2018-08-28 10:50:16.091395754 +0000 UTC m=+19.057505307 End:2018-08-28 10:50:16.096351615 +0000 UTC m=+19.062461095
I0828 10:50:16.096389       1 scheduler.go:454] Total Schedule Algo cumulative time:1.232410278s for 651
I0828 10:50:16.098067       1 scheduler.go:451] ScheduleAlgoTime 1.562443ms Start:2018-08-28 10:50:16.096499843 +0000 UTC m=+19.062609349 End:2018-08-28 10:50:16.098062308 +0000 UTC m=+19.064171792
I0828 10:50:16.098094       1 scheduler.go:454] Total Schedule Algo cumulative time:1.233972721s for 652
I0828 10:50:16.100170       1 scheduler.go:451] ScheduleAlgoTime 1.950685ms Start:2018-08-28 10:50:16.098212762 +0000 UTC m=+19.064322290 End:2018-08-28 10:50:16.100163495 +0000 UTC m=+19.066272975
I0828 10:50:16.100197       1 scheduler.go:454] Total Schedule Algo cumulative time:1.235923406s for 653
I0828 10:50:16.102007       1 scheduler.go:451] ScheduleAlgoTime 1.700331ms Start:2018-08-28 10:50:16.100301281 +0000 UTC m=+19.066410821 End:2018-08-28 10:50:16.102001672 +0000 UTC m=+19.068111152
I0828 10:50:16.102034       1 scheduler.go:454] Total Schedule Algo cumulative time:1.237623737s for 654
I0828 10:50:16.103709       1 scheduler.go:451] ScheduleAlgoTime 1.580602ms Start:2018-08-28 10:50:16.102121888 +0000 UTC m=+19.068231414 End:2018-08-28 10:50:16.103702536 +0000 UTC m=+19.069812016
I0828 10:50:16.103743       1 scheduler.go:454] Total Schedule Algo cumulative time:1.239204339s for 655
I0828 10:50:16.105443       1 scheduler.go:451] ScheduleAlgoTime 1.580967ms Start:2018-08-28 10:50:16.10385616 +0000 UTC m=+19.069965666 End:2018-08-28 10:50:16.105437152 +0000 UTC m=+19.071546633
I0828 10:50:16.105470       1 scheduler.go:454] Total Schedule Algo cumulative time:1.240785306s for 656
I0828 10:50:16.107190       1 scheduler.go:451] ScheduleAlgoTime 1.585932ms Start:2018-08-28 10:50:16.105598852 +0000 UTC m=+19.071708389 End:2018-08-28 10:50:16.10718484 +0000 UTC m=+19.073294321
I0828 10:50:16.107219       1 scheduler.go:454] Total Schedule Algo cumulative time:1.242371238s for 657
I0828 10:50:16.108989       1 scheduler.go:451] ScheduleAlgoTime 1.612307ms Start:2018-08-28 10:50:16.107371781 +0000 UTC m=+19.073481275 End:2018-08-28 10:50:16.108984102 +0000 UTC m=+19.075093582
I0828 10:50:16.109012       1 scheduler.go:454] Total Schedule Algo cumulative time:1.243983545s for 658
I0828 10:50:16.110667       1 scheduler.go:451] ScheduleAlgoTime 1.535564ms Start:2018-08-28 10:50:16.109126063 +0000 UTC m=+19.075235598 End:2018-08-28 10:50:16.110661681 +0000 UTC m=+19.076771162
I0828 10:50:16.110697       1 scheduler.go:454] Total Schedule Algo cumulative time:1.245519109s for 659
I0828 10:50:16.112284       1 scheduler.go:451] ScheduleAlgoTime 1.467276ms Start:2018-08-28 10:50:16.110811123 +0000 UTC m=+19.076920686 End:2018-08-28 10:50:16.112278478 +0000 UTC m=+19.078387962
I0828 10:50:16.112305       1 scheduler.go:454] Total Schedule Algo cumulative time:1.246986385s for 660
I0828 10:50:16.113923       1 scheduler.go:451] ScheduleAlgoTime 1.500838ms Start:2018-08-28 10:50:16.112417165 +0000 UTC m=+19.078526707 End:2018-08-28 10:50:16.113918057 +0000 UTC m=+19.080027545
I0828 10:50:16.113971       1 scheduler.go:454] Total Schedule Algo cumulative time:1.248487223s for 661
I0828 10:50:16.115659       1 scheduler.go:451] ScheduleAlgoTime 1.56623ms Start:2018-08-28 10:50:16.114088136 +0000 UTC m=+19.080197659 End:2018-08-28 10:50:16.115654408 +0000 UTC m=+19.081763889
I0828 10:50:16.115682       1 scheduler.go:454] Total Schedule Algo cumulative time:1.250053453s for 662
I0828 10:50:16.117632       1 scheduler.go:451] ScheduleAlgoTime 1.834726ms Start:2018-08-28 10:50:16.115790433 +0000 UTC m=+19.081899973 End:2018-08-28 10:50:16.11762522 +0000 UTC m=+19.083734699
I0828 10:50:16.117667       1 scheduler.go:454] Total Schedule Algo cumulative time:1.251888179s for 663
I0828 10:50:16.119259       1 scheduler.go:451] ScheduleAlgoTime 1.489296ms Start:2018-08-28 10:50:16.117764844 +0000 UTC m=+19.083874338 End:2018-08-28 10:50:16.119254148 +0000 UTC m=+19.085363634
I0828 10:50:16.119288       1 scheduler.go:454] Total Schedule Algo cumulative time:1.253377475s for 664
I0828 10:50:16.121039       1 scheduler.go:451] ScheduleAlgoTime 1.643611ms Start:2018-08-28 10:50:16.119389015 +0000 UTC m=+19.085498576 End:2018-08-28 10:50:16.121032678 +0000 UTC m=+19.087142187
I0828 10:50:16.121059       1 scheduler.go:454] Total Schedule Algo cumulative time:1.255021086s for 665
I0828 10:50:16.122623       1 scheduler.go:451] ScheduleAlgoTime 1.429281ms Start:2018-08-28 10:50:16.121188717 +0000 UTC m=+19.087298256 End:2018-08-28 10:50:16.122618056 +0000 UTC m=+19.088727537
I0828 10:50:16.122649       1 scheduler.go:454] Total Schedule Algo cumulative time:1.256450367s for 666
I0828 10:50:16.124164       1 scheduler.go:451] ScheduleAlgoTime 1.353541ms Start:2018-08-28 10:50:16.122806679 +0000 UTC m=+19.088916180 End:2018-08-28 10:50:16.124160239 +0000 UTC m=+19.090269721
I0828 10:50:16.124190       1 scheduler.go:454] Total Schedule Algo cumulative time:1.257803908s for 667
I0828 10:50:16.125920       1 scheduler.go:451] ScheduleAlgoTime 1.597018ms Start:2018-08-28 10:50:16.124310421 +0000 UTC m=+19.090419965 End:2018-08-28 10:50:16.125907504 +0000 UTC m=+19.092016983
I0828 10:50:16.125942       1 scheduler.go:454] Total Schedule Algo cumulative time:1.259400926s for 668
I0828 10:50:16.127549       1 scheduler.go:451] ScheduleAlgoTime 1.51458ms Start:2018-08-28 10:50:16.126030271 +0000 UTC m=+19.092139789 End:2018-08-28 10:50:16.127544885 +0000 UTC m=+19.093654369
I0828 10:50:16.127572       1 scheduler.go:454] Total Schedule Algo cumulative time:1.260915506s for 669
I0828 10:50:16.129217       1 scheduler.go:451] ScheduleAlgoTime 1.513166ms Start:2018-08-28 10:50:16.127698312 +0000 UTC m=+19.093807872 End:2018-08-28 10:50:16.129211554 +0000 UTC m=+19.095321038
I0828 10:50:16.129239       1 scheduler.go:454] Total Schedule Algo cumulative time:1.262428672s for 670
I0828 10:50:16.130974       1 scheduler.go:451] ScheduleAlgoTime 1.595227ms Start:2018-08-28 10:50:16.129373549 +0000 UTC m=+19.095483045 End:2018-08-28 10:50:16.130968791 +0000 UTC m=+19.097078272
I0828 10:50:16.130995       1 scheduler.go:454] Total Schedule Algo cumulative time:1.264023899s for 671
I0828 10:50:16.132682       1 scheduler.go:451] ScheduleAlgoTime 1.559017ms Start:2018-08-28 10:50:16.131117865 +0000 UTC m=+19.097227393 End:2018-08-28 10:50:16.132676929 +0000 UTC m=+19.098786410
I0828 10:50:16.132704       1 scheduler.go:454] Total Schedule Algo cumulative time:1.265582916s for 672
I0828 10:50:16.134463       1 scheduler.go:451] ScheduleAlgoTime 1.629342ms Start:2018-08-28 10:50:16.132828387 +0000 UTC m=+19.098937919 End:2018-08-28 10:50:16.134457779 +0000 UTC m=+19.100567261
I0828 10:50:16.134486       1 scheduler.go:454] Total Schedule Algo cumulative time:1.267212258s for 673
I0828 10:50:16.136127       1 scheduler.go:451] ScheduleAlgoTime 1.505661ms Start:2018-08-28 10:50:16.134615239 +0000 UTC m=+19.100724739 End:2018-08-28 10:50:16.136120919 +0000 UTC m=+19.102230400
I0828 10:50:16.136159       1 scheduler.go:454] Total Schedule Algo cumulative time:1.268717919s for 674
I0828 10:50:16.137883       1 scheduler.go:451] ScheduleAlgoTime 1.596663ms Start:2018-08-28 10:50:16.136281276 +0000 UTC m=+19.102390824 End:2018-08-28 10:50:16.137878007 +0000 UTC m=+19.103987487
I0828 10:50:16.137904       1 scheduler.go:454] Total Schedule Algo cumulative time:1.270314582s for 675
I0828 10:50:16.139672       1 scheduler.go:451] ScheduleAlgoTime 1.643271ms Start:2018-08-28 10:50:16.138022919 +0000 UTC m=+19.104132428 End:2018-08-28 10:50:16.13966622 +0000 UTC m=+19.105775699
I0828 10:50:16.139695       1 scheduler.go:454] Total Schedule Algo cumulative time:1.271957853s for 676
I0828 10:50:16.141395       1 scheduler.go:451] ScheduleAlgoTime 1.592631ms Start:2018-08-28 10:50:16.139796147 +0000 UTC m=+19.105905643 End:2018-08-28 10:50:16.141388791 +0000 UTC m=+19.107498274
I0828 10:50:16.141419       1 scheduler.go:454] Total Schedule Algo cumulative time:1.273550484s for 677
I0828 10:50:16.143152       1 scheduler.go:451] ScheduleAlgoTime 1.566081ms Start:2018-08-28 10:50:16.141570166 +0000 UTC m=+19.107679690 End:2018-08-28 10:50:16.14313629 +0000 UTC m=+19.109245771
I0828 10:50:16.143174       1 scheduler.go:454] Total Schedule Algo cumulative time:1.275116565s for 678
I0828 10:50:16.144830       1 scheduler.go:451] ScheduleAlgoTime 1.491152ms Start:2018-08-28 10:50:16.14333328 +0000 UTC m=+19.109442828 End:2018-08-28 10:50:16.144824501 +0000 UTC m=+19.110933980
I0828 10:50:16.144852       1 scheduler.go:454] Total Schedule Algo cumulative time:1.276607717s for 679
I0828 10:50:16.146672       1 scheduler.go:451] ScheduleAlgoTime 1.706641ms Start:2018-08-28 10:50:16.144959364 +0000 UTC m=+19.111068886 End:2018-08-28 10:50:16.146666045 +0000 UTC m=+19.112775527
I0828 10:50:16.146694       1 scheduler.go:454] Total Schedule Algo cumulative time:1.278314358s for 680
I0828 10:50:16.148309       1 scheduler.go:451] ScheduleAlgoTime 1.486067ms Start:2018-08-28 10:50:16.146817356 +0000 UTC m=+19.112926892 End:2018-08-28 10:50:16.148303476 +0000 UTC m=+19.114412959
I0828 10:50:16.148332       1 scheduler.go:454] Total Schedule Algo cumulative time:1.279800425s for 681
I0828 10:50:16.150080       1 scheduler.go:451] ScheduleAlgoTime 1.635314ms Start:2018-08-28 10:50:16.148440919 +0000 UTC m=+19.114550449 End:2018-08-28 10:50:16.150076279 +0000 UTC m=+19.116185763
I0828 10:50:16.150102       1 scheduler.go:454] Total Schedule Algo cumulative time:1.281435739s for 682
I0828 10:50:16.151743       1 scheduler.go:451] ScheduleAlgoTime 1.525211ms Start:2018-08-28 10:50:16.150212199 +0000 UTC m=+19.116321731 End:2018-08-28 10:50:16.151737462 +0000 UTC m=+19.117846942
I0828 10:50:16.151764       1 scheduler.go:454] Total Schedule Algo cumulative time:1.28296095s for 683
I0828 10:50:16.153382       1 scheduler.go:451] ScheduleAlgoTime 1.530471ms Start:2018-08-28 10:50:16.151847551 +0000 UTC m=+19.117957041 End:2018-08-28 10:50:16.153378031 +0000 UTC m=+19.119487512
I0828 10:50:16.153404       1 scheduler.go:454] Total Schedule Algo cumulative time:1.284491421s for 684
I0828 10:50:16.155281       1 scheduler.go:451] ScheduleAlgoTime 1.732108ms Start:2018-08-28 10:50:16.153542682 +0000 UTC m=+19.119652229 End:2018-08-28 10:50:16.155274857 +0000 UTC m=+19.121384337
I0828 10:50:16.155322       1 scheduler.go:454] Total Schedule Algo cumulative time:1.286223529s for 685
I0828 10:50:16.157193       1 scheduler.go:451] ScheduleAlgoTime 1.764827ms Start:2018-08-28 10:50:16.155422422 +0000 UTC m=+19.121531994 End:2018-08-28 10:50:16.157187341 +0000 UTC m=+19.123296821
I0828 10:50:16.157216       1 scheduler.go:454] Total Schedule Algo cumulative time:1.287988356s for 686
I0828 10:50:16.158897       1 scheduler.go:451] ScheduleAlgoTime 1.568835ms Start:2018-08-28 10:50:16.157322107 +0000 UTC m=+19.123431620 End:2018-08-28 10:50:16.158890976 +0000 UTC m=+19.125000455
I0828 10:50:16.158920       1 scheduler.go:454] Total Schedule Algo cumulative time:1.289557191s for 687
I0828 10:50:16.160716       1 scheduler.go:451] ScheduleAlgoTime 1.548157ms Start:2018-08-28 10:50:16.159162019 +0000 UTC m=+19.125271521 End:2018-08-28 10:50:16.160710199 +0000 UTC m=+19.126819678
I0828 10:50:16.160737       1 scheduler.go:454] Total Schedule Algo cumulative time:1.291105348s for 688
I0828 10:50:16.162574       1 scheduler.go:451] ScheduleAlgoTime 1.718828ms Start:2018-08-28 10:50:16.160849239 +0000 UTC m=+19.126958783 End:2018-08-28 10:50:16.162568127 +0000 UTC m=+19.128677611
I0828 10:50:16.162597       1 scheduler.go:454] Total Schedule Algo cumulative time:1.292824176s for 689
I0828 10:50:16.164286       1 scheduler.go:451] ScheduleAlgoTime 1.569681ms Start:2018-08-28 10:50:16.162709229 +0000 UTC m=+19.128818740 End:2018-08-28 10:50:16.164278928 +0000 UTC m=+19.130388421
I0828 10:50:16.164313       1 scheduler.go:454] Total Schedule Algo cumulative time:1.294393857s for 690
I0828 10:50:16.166046       1 scheduler.go:451] ScheduleAlgoTime 1.601336ms Start:2018-08-28 10:50:16.164439238 +0000 UTC m=+19.130548739 End:2018-08-28 10:50:16.166040594 +0000 UTC m=+19.132150075
I0828 10:50:16.166084       1 scheduler.go:454] Total Schedule Algo cumulative time:1.295995193s for 691
I0828 10:50:16.167738       1 scheduler.go:451] ScheduleAlgoTime 1.508472ms Start:2018-08-28 10:50:16.1662218 +0000 UTC m=+19.132331337 End:2018-08-28 10:50:16.16773033 +0000 UTC m=+19.133839809
I0828 10:50:16.167802       1 scheduler.go:454] Total Schedule Algo cumulative time:1.297503665s for 692
I0828 10:50:16.169408       1 scheduler.go:451] ScheduleAlgoTime 1.482682ms Start:2018-08-28 10:50:16.167920912 +0000 UTC m=+19.134030452 End:2018-08-28 10:50:16.169403652 +0000 UTC m=+19.135513134
I0828 10:50:16.169435       1 scheduler.go:454] Total Schedule Algo cumulative time:1.298986347s for 693
I0828 10:50:16.171285       1 scheduler.go:451] ScheduleAlgoTime 1.701098ms Start:2018-08-28 10:50:16.169576404 +0000 UTC m=+19.135685931 End:2018-08-28 10:50:16.171277459 +0000 UTC m=+19.137387029
I0828 10:50:16.171313       1 scheduler.go:454] Total Schedule Algo cumulative time:1.300687445s for 694
I0828 10:50:16.173216       1 scheduler.go:451] ScheduleAlgoTime 1.771242ms Start:2018-08-28 10:50:16.171439511 +0000 UTC m=+19.137549027 End:2018-08-28 10:50:16.173210788 +0000 UTC m=+19.139320269
I0828 10:50:16.173236       1 scheduler.go:454] Total Schedule Algo cumulative time:1.302458687s for 695
I0828 10:50:16.174867       1 scheduler.go:451] ScheduleAlgoTime 1.494129ms Start:2018-08-28 10:50:16.173369276 +0000 UTC m=+19.139478839 End:2018-08-28 10:50:16.174863487 +0000 UTC m=+19.140972968
I0828 10:50:16.174885       1 scheduler.go:454] Total Schedule Algo cumulative time:1.303952816s for 696
I0828 10:50:16.176762       1 scheduler.go:451] ScheduleAlgoTime 1.79441ms Start:2018-08-28 10:50:16.174963197 +0000 UTC m=+19.141072727 End:2018-08-28 10:50:16.176757657 +0000 UTC m=+19.142867137
I0828 10:50:16.176786       1 scheduler.go:454] Total Schedule Algo cumulative time:1.305747226s for 697
I0828 10:50:16.178410       1 scheduler.go:451] ScheduleAlgoTime 1.523621ms Start:2018-08-28 10:50:16.176881055 +0000 UTC m=+19.142990579 End:2018-08-28 10:50:16.178404719 +0000 UTC m=+19.144514200
I0828 10:50:16.178432       1 scheduler.go:454] Total Schedule Algo cumulative time:1.307270847s for 698
I0828 10:50:16.180401       1 scheduler.go:451] ScheduleAlgoTime 1.880073ms Start:2018-08-28 10:50:16.178516593 +0000 UTC m=+19.144626103 End:2018-08-28 10:50:16.180396692 +0000 UTC m=+19.146506176
I0828 10:50:16.180423       1 scheduler.go:454] Total Schedule Algo cumulative time:1.30915092s for 699
I0828 10:50:16.182138       1 scheduler.go:451] ScheduleAlgoTime 1.613767ms Start:2018-08-28 10:50:16.180518662 +0000 UTC m=+19.146628204 End:2018-08-28 10:50:16.182132491 +0000 UTC m=+19.148241971
I0828 10:50:16.182171       1 scheduler.go:454] Total Schedule Algo cumulative time:1.310764687s for 700
I0828 10:50:16.183774       1 scheduler.go:451] ScheduleAlgoTime 1.510216ms Start:2018-08-28 10:50:16.182258619 +0000 UTC m=+19.148368145 End:2018-08-28 10:50:16.18376888 +0000 UTC m=+19.149878361
I0828 10:50:16.183793       1 scheduler.go:454] Total Schedule Algo cumulative time:1.312274903s for 701
I0828 10:50:16.185511       1 scheduler.go:451] ScheduleAlgoTime 1.60825ms Start:2018-08-28 10:50:16.183897446 +0000 UTC m=+19.150006976 End:2018-08-28 10:50:16.185505745 +0000 UTC m=+19.151615226
I0828 10:50:16.185536       1 scheduler.go:454] Total Schedule Algo cumulative time:1.313883153s for 702
I0828 10:50:16.187061       1 scheduler.go:451] ScheduleAlgoTime 1.423134ms Start:2018-08-28 10:50:16.185633503 +0000 UTC m=+19.151743018 End:2018-08-28 10:50:16.187056668 +0000 UTC m=+19.153166152
I0828 10:50:16.187082       1 scheduler.go:454] Total Schedule Algo cumulative time:1.315306287s for 703
I0828 10:50:16.188914       1 scheduler.go:451] ScheduleAlgoTime 1.714443ms Start:2018-08-28 10:50:16.187193857 +0000 UTC m=+19.153303415 End:2018-08-28 10:50:16.18890838 +0000 UTC m=+19.155017858
I0828 10:50:16.188937       1 scheduler.go:454] Total Schedule Algo cumulative time:1.31702073s for 704
I0828 10:50:16.192980       1 scheduler.go:451] ScheduleAlgoTime 3.749013ms Start:2018-08-28 10:50:16.189225086 +0000 UTC m=+19.155334640 End:2018-08-28 10:50:16.192974162 +0000 UTC m=+19.159083653
I0828 10:50:16.193058       1 scheduler.go:454] Total Schedule Algo cumulative time:1.320769743s for 705
I0828 10:50:16.196810       1 scheduler.go:451] ScheduleAlgoTime 3.569601ms Start:2018-08-28 10:50:16.193231683 +0000 UTC m=+19.159341193 End:2018-08-28 10:50:16.196801312 +0000 UTC m=+19.162910794
I0828 10:50:16.196848       1 scheduler.go:454] Total Schedule Algo cumulative time:1.324339344s for 706
I0828 10:50:16.198629       1 scheduler.go:451] ScheduleAlgoTime 1.687845ms Start:2018-08-28 10:50:16.196932767 +0000 UTC m=+19.163042311 End:2018-08-28 10:50:16.198620676 +0000 UTC m=+19.164730156
I0828 10:50:16.198669       1 scheduler.go:454] Total Schedule Algo cumulative time:1.326027189s for 707
I0828 10:50:16.200730       1 scheduler.go:451] ScheduleAlgoTime 1.955187ms Start:2018-08-28 10:50:16.198768896 +0000 UTC m=+19.164878415 End:2018-08-28 10:50:16.200724119 +0000 UTC m=+19.166833602
I0828 10:50:16.200758       1 scheduler.go:454] Total Schedule Algo cumulative time:1.327982376s for 708
I0828 10:50:16.202561       1 scheduler.go:451] ScheduleAlgoTime 1.7055ms Start:2018-08-28 10:50:16.200849305 +0000 UTC m=+19.166958813 End:2018-08-28 10:50:16.202554829 +0000 UTC m=+19.168664313
I0828 10:50:16.202584       1 scheduler.go:454] Total Schedule Algo cumulative time:1.329687876s for 709
I0828 10:50:16.204404       1 scheduler.go:451] ScheduleAlgoTime 1.685715ms Start:2018-08-28 10:50:16.202713459 +0000 UTC m=+19.168822978 End:2018-08-28 10:50:16.204399208 +0000 UTC m=+19.170508693
I0828 10:50:16.204441       1 scheduler.go:454] Total Schedule Algo cumulative time:1.331373591s for 710
I0828 10:50:16.206125       1 scheduler.go:451] ScheduleAlgoTime 1.567009ms Start:2018-08-28 10:50:16.204551371 +0000 UTC m=+19.170660874 End:2018-08-28 10:50:16.206118399 +0000 UTC m=+19.172227883
I0828 10:50:16.206163       1 scheduler.go:454] Total Schedule Algo cumulative time:1.3329406s for 711
I0828 10:50:16.208069       1 scheduler.go:451] ScheduleAlgoTime 1.711326ms Start:2018-08-28 10:50:16.206353162 +0000 UTC m=+19.172462662 End:2018-08-28 10:50:16.208064503 +0000 UTC m=+19.174173988
I0828 10:50:16.208093       1 scheduler.go:454] Total Schedule Algo cumulative time:1.334651926s for 712
I0828 10:50:16.209805       1 scheduler.go:451] ScheduleAlgoTime 1.583161ms Start:2018-08-28 10:50:16.208216613 +0000 UTC m=+19.174326124 End:2018-08-28 10:50:16.209799803 +0000 UTC m=+19.175909285
I0828 10:50:16.209826       1 scheduler.go:454] Total Schedule Algo cumulative time:1.336235087s for 713
I0828 10:50:16.211714       1 scheduler.go:451] ScheduleAlgoTime 1.721234ms Start:2018-08-28 10:50:16.20998702 +0000 UTC m=+19.176096575 End:2018-08-28 10:50:16.211708329 +0000 UTC m=+19.177817809
I0828 10:50:16.211738       1 scheduler.go:454] Total Schedule Algo cumulative time:1.337956321s for 714
I0828 10:50:16.213405       1 scheduler.go:451] ScheduleAlgoTime 1.575212ms Start:2018-08-28 10:50:16.211824088 +0000 UTC m=+19.177933627 End:2018-08-28 10:50:16.21339936 +0000 UTC m=+19.179508839
I0828 10:50:16.213429       1 scheduler.go:454] Total Schedule Algo cumulative time:1.339531533s for 715
I0828 10:50:16.215118       1 scheduler.go:451] ScheduleAlgoTime 1.532351ms Start:2018-08-28 10:50:16.213580089 +0000 UTC m=+19.179689626 End:2018-08-28 10:50:16.215112492 +0000 UTC m=+19.181221977
I0828 10:50:16.215153       1 scheduler.go:454] Total Schedule Algo cumulative time:1.341063884s for 716
I0828 10:50:16.216818       1 scheduler.go:451] ScheduleAlgoTime 1.499169ms Start:2018-08-28 10:50:16.215313925 +0000 UTC m=+19.181423435 End:2018-08-28 10:50:16.216813123 +0000 UTC m=+19.182922604
I0828 10:50:16.216847       1 scheduler.go:454] Total Schedule Algo cumulative time:1.342563053s for 717
I0828 10:50:16.218545       1 scheduler.go:451] ScheduleAlgoTime 1.592606ms Start:2018-08-28 10:50:16.216947847 +0000 UTC m=+19.183057363 End:2018-08-28 10:50:16.218540489 +0000 UTC m=+19.184649969
I0828 10:50:16.218572       1 scheduler.go:454] Total Schedule Algo cumulative time:1.344155659s for 718
I0828 10:50:16.220170       1 scheduler.go:451] ScheduleAlgoTime 1.489358ms Start:2018-08-28 10:50:16.218673606 +0000 UTC m=+19.184783107 End:2018-08-28 10:50:16.220162951 +0000 UTC m=+19.186272465
I0828 10:50:16.220197       1 scheduler.go:454] Total Schedule Algo cumulative time:1.345645017s for 719
I0828 10:50:16.221831       1 scheduler.go:451] ScheduleAlgoTime 1.538866ms Start:2018-08-28 10:50:16.220285337 +0000 UTC m=+19.186394850 End:2018-08-28 10:50:16.221824232 +0000 UTC m=+19.187933716
I0828 10:50:16.221855       1 scheduler.go:454] Total Schedule Algo cumulative time:1.347183883s for 720
I0828 10:50:16.223610       1 scheduler.go:451] ScheduleAlgoTime 1.640413ms Start:2018-08-28 10:50:16.221965284 +0000 UTC m=+19.188074775 End:2018-08-28 10:50:16.223605703 +0000 UTC m=+19.189715188
I0828 10:50:16.223646       1 scheduler.go:454] Total Schedule Algo cumulative time:1.348824296s for 721
I0828 10:50:16.225368       1 scheduler.go:451] ScheduleAlgoTime 1.618446ms Start:2018-08-28 10:50:16.223743972 +0000 UTC m=+19.189853451 End:2018-08-28 10:50:16.225362416 +0000 UTC m=+19.191471897
I0828 10:50:16.225391       1 scheduler.go:454] Total Schedule Algo cumulative time:1.350442742s for 722
I0828 10:50:16.227086       1 scheduler.go:451] ScheduleAlgoTime 1.581722ms Start:2018-08-28 10:50:16.225498353 +0000 UTC m=+19.191607875 End:2018-08-28 10:50:16.22708011 +0000 UTC m=+19.193189597
I0828 10:50:16.227116       1 scheduler.go:454] Total Schedule Algo cumulative time:1.352024464s for 723
I0828 10:50:16.228835       1 scheduler.go:451] ScheduleAlgoTime 1.552653ms Start:2018-08-28 10:50:16.227276949 +0000 UTC m=+19.193386493 End:2018-08-28 10:50:16.228829665 +0000 UTC m=+19.194939146
I0828 10:50:16.228856       1 scheduler.go:454] Total Schedule Algo cumulative time:1.353577117s for 724
I0828 10:50:16.230792       1 scheduler.go:451] ScheduleAlgoTime 1.831174ms Start:2018-08-28 10:50:16.228955549 +0000 UTC m=+19.195065086 End:2018-08-28 10:50:16.230786779 +0000 UTC m=+19.196896260
I0828 10:50:16.230825       1 scheduler.go:454] Total Schedule Algo cumulative time:1.355408291s for 725
I0828 10:50:16.232517       1 scheduler.go:451] ScheduleAlgoTime 1.539208ms Start:2018-08-28 10:50:16.230957736 +0000 UTC m=+19.197067291 End:2018-08-28 10:50:16.23249702 +0000 UTC m=+19.198606499
I0828 10:50:16.232541       1 scheduler.go:454] Total Schedule Algo cumulative time:1.356947499s for 726
I0828 10:50:16.234199       1 scheduler.go:451] ScheduleAlgoTime 1.5445ms Start:2018-08-28 10:50:16.232650611 +0000 UTC m=+19.198760110 End:2018-08-28 10:50:16.234195127 +0000 UTC m=+19.200304610
I0828 10:50:16.234231       1 scheduler.go:454] Total Schedule Algo cumulative time:1.358491999s for 727
I0828 10:50:16.235859       1 scheduler.go:451] ScheduleAlgoTime 1.541165ms Start:2018-08-28 10:50:16.234311801 +0000 UTC m=+19.200421330 End:2018-08-28 10:50:16.235853013 +0000 UTC m=+19.201962495
I0828 10:50:16.235881       1 scheduler.go:454] Total Schedule Algo cumulative time:1.360033164s for 728
I0828 10:50:16.237849       1 scheduler.go:451] ScheduleAlgoTime 1.857352ms Start:2018-08-28 10:50:16.23598428 +0000 UTC m=+19.202093840 End:2018-08-28 10:50:16.237841566 +0000 UTC m=+19.203951192
I0828 10:50:16.237879       1 scheduler.go:454] Total Schedule Algo cumulative time:1.361890516s for 729
I0828 10:50:16.239894       1 scheduler.go:451] ScheduleAlgoTime 1.862251ms Start:2018-08-28 10:50:16.238026879 +0000 UTC m=+19.204136437 End:2018-08-28 10:50:16.239889203 +0000 UTC m=+19.205998688
I0828 10:50:16.239914       1 scheduler.go:454] Total Schedule Algo cumulative time:1.363752767s for 730
I0828 10:50:16.241602       1 scheduler.go:451] ScheduleAlgoTime 1.541267ms Start:2018-08-28 10:50:16.240054308 +0000 UTC m=+19.206163848 End:2018-08-28 10:50:16.241595635 +0000 UTC m=+19.207705115
I0828 10:50:16.241627       1 scheduler.go:454] Total Schedule Algo cumulative time:1.365294034s for 731
I0828 10:50:16.243349       1 scheduler.go:451] ScheduleAlgoTime 1.551743ms Start:2018-08-28 10:50:16.24179258 +0000 UTC m=+19.207902071 End:2018-08-28 10:50:16.243344327 +0000 UTC m=+19.209453814
I0828 10:50:16.243379       1 scheduler.go:454] Total Schedule Algo cumulative time:1.366845777s for 732
I0828 10:50:16.244976       1 scheduler.go:451] ScheduleAlgoTime 1.519641ms Start:2018-08-28 10:50:16.243450666 +0000 UTC m=+19.209560156 End:2018-08-28 10:50:16.244970318 +0000 UTC m=+19.211079797
I0828 10:50:16.245000       1 scheduler.go:454] Total Schedule Algo cumulative time:1.368365418s for 733
I0828 10:50:16.246971       1 scheduler.go:451] ScheduleAlgoTime 1.802537ms Start:2018-08-28 10:50:16.245162414 +0000 UTC m=+19.211271915 End:2018-08-28 10:50:16.246964972 +0000 UTC m=+19.213074452
I0828 10:50:16.246994       1 scheduler.go:454] Total Schedule Algo cumulative time:1.370167955s for 734
I0828 10:50:16.248818       1 scheduler.go:451] ScheduleAlgoTime 1.720307ms Start:2018-08-28 10:50:16.247092827 +0000 UTC m=+19.213202359 End:2018-08-28 10:50:16.248813183 +0000 UTC m=+19.214922666
I0828 10:50:16.248840       1 scheduler.go:454] Total Schedule Algo cumulative time:1.371888262s for 735
I0828 10:50:16.250675       1 scheduler.go:451] ScheduleAlgoTime 1.698962ms Start:2018-08-28 10:50:16.248970186 +0000 UTC m=+19.215079751 End:2018-08-28 10:50:16.250669229 +0000 UTC m=+19.216778713
I0828 10:50:16.250700       1 scheduler.go:454] Total Schedule Algo cumulative time:1.373587224s for 736
I0828 10:50:16.252264       1 scheduler.go:451] ScheduleAlgoTime 1.447652ms Start:2018-08-28 10:50:16.25081122 +0000 UTC m=+19.216920743 End:2018-08-28 10:50:16.252258914 +0000 UTC m=+19.218368395
I0828 10:50:16.252285       1 scheduler.go:454] Total Schedule Algo cumulative time:1.375034876s for 737
I0828 10:50:16.253989       1 scheduler.go:451] ScheduleAlgoTime 1.591855ms Start:2018-08-28 10:50:16.252392306 +0000 UTC m=+19.218501907 End:2018-08-28 10:50:16.253984278 +0000 UTC m=+19.220093762
I0828 10:50:16.254010       1 scheduler.go:454] Total Schedule Algo cumulative time:1.376626731s for 738
I0828 10:50:16.255729       1 scheduler.go:451] ScheduleAlgoTime 1.573709ms Start:2018-08-28 10:50:16.25415019 +0000 UTC m=+19.220259712 End:2018-08-28 10:50:16.255723941 +0000 UTC m=+19.221833421
I0828 10:50:16.255752       1 scheduler.go:454] Total Schedule Algo cumulative time:1.37820044s for 739
I0828 10:50:16.257799       1 scheduler.go:451] ScheduleAlgoTime 1.940594ms Start:2018-08-28 10:50:16.255849333 +0000 UTC m=+19.221958854 End:2018-08-28 10:50:16.257789959 +0000 UTC m=+19.223899448
I0828 10:50:16.257833       1 scheduler.go:454] Total Schedule Algo cumulative time:1.380141034s for 740
I0828 10:50:16.259576       1 scheduler.go:451] ScheduleAlgoTime 1.606076ms Start:2018-08-28 10:50:16.257964919 +0000 UTC m=+19.224074433 End:2018-08-28 10:50:16.25957103 +0000 UTC m=+19.225680509
I0828 10:50:16.259599       1 scheduler.go:454] Total Schedule Algo cumulative time:1.38174711s for 741
I0828 10:50:16.261439       1 scheduler.go:451] ScheduleAlgoTime 1.693332ms Start:2018-08-28 10:50:16.259739244 +0000 UTC m=+19.225848751 End:2018-08-28 10:50:16.261432602 +0000 UTC m=+19.227542083
I0828 10:50:16.261463       1 scheduler.go:454] Total Schedule Algo cumulative time:1.383440442s for 742
I0828 10:50:16.263208       1 scheduler.go:451] ScheduleAlgoTime 1.630046ms Start:2018-08-28 10:50:16.26157258 +0000 UTC m=+19.227682344 End:2018-08-28 10:50:16.263202908 +0000 UTC m=+19.229312390
I0828 10:50:16.263232       1 scheduler.go:454] Total Schedule Algo cumulative time:1.385070488s for 743
I0828 10:50:16.264819       1 scheduler.go:451] ScheduleAlgoTime 1.471457ms Start:2018-08-28 10:50:16.263343441 +0000 UTC m=+19.229452989 End:2018-08-28 10:50:16.264814965 +0000 UTC m=+19.230924446
I0828 10:50:16.264840       1 scheduler.go:454] Total Schedule Algo cumulative time:1.386541945s for 744
I0828 10:50:16.266878       1 scheduler.go:451] ScheduleAlgoTime 1.691773ms Start:2018-08-28 10:50:16.26518181 +0000 UTC m=+19.231291354 End:2018-08-28 10:50:16.266873646 +0000 UTC m=+19.232983127
I0828 10:50:16.266907       1 scheduler.go:454] Total Schedule Algo cumulative time:1.388233718s for 745
I0828 10:50:16.268589       1 scheduler.go:451] ScheduleAlgoTime 1.543153ms Start:2018-08-28 10:50:16.267041509 +0000 UTC m=+19.233151050 End:2018-08-28 10:50:16.268584723 +0000 UTC m=+19.234694203
I0828 10:50:16.268610       1 scheduler.go:454] Total Schedule Algo cumulative time:1.389776871s for 746
I0828 10:50:16.270226       1 scheduler.go:451] ScheduleAlgoTime 1.501654ms Start:2018-08-28 10:50:16.26871927 +0000 UTC m=+19.234828766 End:2018-08-28 10:50:16.270220937 +0000 UTC m=+19.236330420
I0828 10:50:16.270255       1 scheduler.go:454] Total Schedule Algo cumulative time:1.391278525s for 747
I0828 10:50:16.272108       1 scheduler.go:451] ScheduleAlgoTime 1.673021ms Start:2018-08-28 10:50:16.270426745 +0000 UTC m=+19.236536273 End:2018-08-28 10:50:16.272099813 +0000 UTC m=+19.238209294
I0828 10:50:16.272135       1 scheduler.go:454] Total Schedule Algo cumulative time:1.392951546s for 748
I0828 10:50:16.274483       1 scheduler.go:451] ScheduleAlgoTime 2.198985ms Start:2018-08-28 10:50:16.272278673 +0000 UTC m=+19.238388223 End:2018-08-28 10:50:16.274477729 +0000 UTC m=+19.240587208
I0828 10:50:16.274508       1 scheduler.go:454] Total Schedule Algo cumulative time:1.395150531s for 749
I0828 10:50:16.276519       1 scheduler.go:451] ScheduleAlgoTime 1.872638ms Start:2018-08-28 10:50:16.274642077 +0000 UTC m=+19.240751628 End:2018-08-28 10:50:16.276514786 +0000 UTC m=+19.242624266
I0828 10:50:16.276548       1 scheduler.go:454] Total Schedule Algo cumulative time:1.397023169s for 750
I0828 10:50:16.278317       1 scheduler.go:451] ScheduleAlgoTime 1.652512ms Start:2018-08-28 10:50:16.276659187 +0000 UTC m=+19.242768720 End:2018-08-28 10:50:16.278311751 +0000 UTC m=+19.244421232
I0828 10:50:16.278337       1 scheduler.go:454] Total Schedule Algo cumulative time:1.398675681s for 751
I0828 10:50:16.279978       1 scheduler.go:451] ScheduleAlgoTime 1.541724ms Start:2018-08-28 10:50:16.278430138 +0000 UTC m=+19.244539654 End:2018-08-28 10:50:16.279971899 +0000 UTC m=+19.246081378
I0828 10:50:16.280003       1 scheduler.go:454] Total Schedule Algo cumulative time:1.400217405s for 752
I0828 10:50:16.281714       1 scheduler.go:451] ScheduleAlgoTime 1.610671ms Start:2018-08-28 10:50:16.280097177 +0000 UTC m=+19.246206770 End:2018-08-28 10:50:16.281707955 +0000 UTC m=+19.247817441
I0828 10:50:16.281738       1 scheduler.go:454] Total Schedule Algo cumulative time:1.401828076s for 753
I0828 10:50:16.283367       1 scheduler.go:451] ScheduleAlgoTime 1.505432ms Start:2018-08-28 10:50:16.281855417 +0000 UTC m=+19.247964956 End:2018-08-28 10:50:16.283360875 +0000 UTC m=+19.249470388
I0828 10:50:16.283396       1 scheduler.go:454] Total Schedule Algo cumulative time:1.403333508s for 754
I0828 10:50:16.285071       1 scheduler.go:451] ScheduleAlgoTime 1.548573ms Start:2018-08-28 10:50:16.283517947 +0000 UTC m=+19.249627463 End:2018-08-28 10:50:16.285066557 +0000 UTC m=+19.251176036
I0828 10:50:16.285119       1 scheduler.go:454] Total Schedule Algo cumulative time:1.404882081s for 755
I0828 10:50:16.287098       1 scheduler.go:451] ScheduleAlgoTime 1.697961ms Start:2018-08-28 10:50:16.285393341 +0000 UTC m=+19.251502838 End:2018-08-28 10:50:16.287091279 +0000 UTC m=+19.253200799
I0828 10:50:16.287122       1 scheduler.go:454] Total Schedule Algo cumulative time:1.406580042s for 756
I0828 10:50:16.289119       1 scheduler.go:451] ScheduleAlgoTime 1.827844ms Start:2018-08-28 10:50:16.287264491 +0000 UTC m=+19.253374011 End:2018-08-28 10:50:16.289092376 +0000 UTC m=+19.255201855
I0828 10:50:16.289153       1 scheduler.go:454] Total Schedule Algo cumulative time:1.408407886s for 757
I0828 10:50:16.290937       1 scheduler.go:451] ScheduleAlgoTime 1.494418ms Start:2018-08-28 10:50:16.289331311 +0000 UTC m=+19.255440832 End:2018-08-28 10:50:16.290825768 +0000 UTC m=+19.256935250
I0828 10:50:16.290959       1 scheduler.go:454] Total Schedule Algo cumulative time:1.409902304s for 758
I0828 10:50:16.292639       1 scheduler.go:451] ScheduleAlgoTime 1.558016ms Start:2018-08-28 10:50:16.291074589 +0000 UTC m=+19.257184117 End:2018-08-28 10:50:16.292632652 +0000 UTC m=+19.258742133
I0828 10:50:16.292670       1 scheduler.go:454] Total Schedule Algo cumulative time:1.41146032s for 759
I0828 10:50:16.294439       1 scheduler.go:451] ScheduleAlgoTime 1.627986ms Start:2018-08-28 10:50:16.292804894 +0000 UTC m=+19.258914432 End:2018-08-28 10:50:16.294432937 +0000 UTC m=+19.260542418
I0828 10:50:16.294463       1 scheduler.go:454] Total Schedule Algo cumulative time:1.413088306s for 760
I0828 10:50:16.296227       1 scheduler.go:451] ScheduleAlgoTime 1.681208ms Start:2018-08-28 10:50:16.294540294 +0000 UTC m=+19.260649818 End:2018-08-28 10:50:16.296221542 +0000 UTC m=+19.262331026
I0828 10:50:16.296250       1 scheduler.go:454] Total Schedule Algo cumulative time:1.414769514s for 761
I0828 10:50:16.305190       1 scheduler.go:451] ScheduleAlgoTime 8.829204ms Start:2018-08-28 10:50:16.296353054 +0000 UTC m=+19.262462572 End:2018-08-28 10:50:16.305182296 +0000 UTC m=+19.271291776
I0828 10:50:16.305231       1 scheduler.go:454] Total Schedule Algo cumulative time:1.423598718s for 762
I0828 10:50:16.308748       1 scheduler.go:451] ScheduleAlgoTime 3.37355ms Start:2018-08-28 10:50:16.305367041 +0000 UTC m=+19.271476549 End:2018-08-28 10:50:16.308740532 +0000 UTC m=+19.274850099
I0828 10:50:16.308784       1 scheduler.go:454] Total Schedule Algo cumulative time:1.426972268s for 763
I0828 10:50:16.310722       1 scheduler.go:451] ScheduleAlgoTime 1.788503ms Start:2018-08-28 10:50:16.308924544 +0000 UTC m=+19.275034048 End:2018-08-28 10:50:16.31071307 +0000 UTC m=+19.276822551
I0828 10:50:16.310756       1 scheduler.go:454] Total Schedule Algo cumulative time:1.428760771s for 764
I0828 10:50:16.312370       1 scheduler.go:451] ScheduleAlgoTime 1.479539ms Start:2018-08-28 10:50:16.310885505 +0000 UTC m=+19.276995025 End:2018-08-28 10:50:16.312365084 +0000 UTC m=+19.278474564
I0828 10:50:16.312408       1 scheduler.go:454] Total Schedule Algo cumulative time:1.43024031s for 765
I0828 10:50:16.314289       1 scheduler.go:451] ScheduleAlgoTime 1.691395ms Start:2018-08-28 10:50:16.312591959 +0000 UTC m=+19.278701514 End:2018-08-28 10:50:16.314283424 +0000 UTC m=+19.280392909
I0828 10:50:16.314321       1 scheduler.go:454] Total Schedule Algo cumulative time:1.431931705s for 766
I0828 10:50:16.316183       1 scheduler.go:451] ScheduleAlgoTime 1.725406ms Start:2018-08-28 10:50:16.314451678 +0000 UTC m=+19.280561192 End:2018-08-28 10:50:16.316177119 +0000 UTC m=+19.282286598
I0828 10:50:16.316215       1 scheduler.go:454] Total Schedule Algo cumulative time:1.433657111s for 767
I0828 10:50:16.318126       1 scheduler.go:451] ScheduleAlgoTime 1.746832ms Start:2018-08-28 10:50:16.316372086 +0000 UTC m=+19.282481605 End:2018-08-28 10:50:16.318118953 +0000 UTC m=+19.284228437
I0828 10:50:16.318170       1 scheduler.go:454] Total Schedule Algo cumulative time:1.435403943s for 768
I0828 10:50:16.319953       1 scheduler.go:451] ScheduleAlgoTime 1.641343ms Start:2018-08-28 10:50:16.318306585 +0000 UTC m=+19.284416126 End:2018-08-28 10:50:16.319947987 +0000 UTC m=+19.286057469
I0828 10:50:16.319981       1 scheduler.go:454] Total Schedule Algo cumulative time:1.437045286s for 769
I0828 10:50:16.322152       1 scheduler.go:451] ScheduleAlgoTime 2.036945ms Start:2018-08-28 10:50:16.320101047 +0000 UTC m=+19.286210558 End:2018-08-28 10:50:16.322138022 +0000 UTC m=+19.288247503
I0828 10:50:16.322174       1 scheduler.go:454] Total Schedule Algo cumulative time:1.439082231s for 770
I0828 10:50:16.323960       1 scheduler.go:451] ScheduleAlgoTime 1.660768ms Start:2018-08-28 10:50:16.322294229 +0000 UTC m=+19.288403785 End:2018-08-28 10:50:16.32395507 +0000 UTC m=+19.290064553
I0828 10:50:16.323984       1 scheduler.go:454] Total Schedule Algo cumulative time:1.440742999s for 771
I0828 10:50:16.325720       1 scheduler.go:451] ScheduleAlgoTime 1.608527ms Start:2018-08-28 10:50:16.324106655 +0000 UTC m=+19.290216197 End:2018-08-28 10:50:16.325715244 +0000 UTC m=+19.291824724
I0828 10:50:16.325764       1 scheduler.go:454] Total Schedule Algo cumulative time:1.442351526s for 772
I0828 10:50:16.327606       1 scheduler.go:451] ScheduleAlgoTime 1.692314ms Start:2018-08-28 10:50:16.325908624 +0000 UTC m=+19.292018141 End:2018-08-28 10:50:16.327600961 +0000 UTC m=+19.293710455
I0828 10:50:16.327629       1 scheduler.go:454] Total Schedule Algo cumulative time:1.44404384s for 773
I0828 10:50:16.329386       1 scheduler.go:451] ScheduleAlgoTime 1.62967ms Start:2018-08-28 10:50:16.327750368 +0000 UTC m=+19.293859909 End:2018-08-28 10:50:16.329380099 +0000 UTC m=+19.295489579
I0828 10:50:16.329417       1 scheduler.go:454] Total Schedule Algo cumulative time:1.44567351s for 774
I0828 10:50:16.331184       1 scheduler.go:451] ScheduleAlgoTime 1.635149ms Start:2018-08-28 10:50:16.329542535 +0000 UTC m=+19.295652071 End:2018-08-28 10:50:16.331177736 +0000 UTC m=+19.297287220
I0828 10:50:16.331213       1 scheduler.go:454] Total Schedule Algo cumulative time:1.447308659s for 775
I0828 10:50:16.333272       1 scheduler.go:451] ScheduleAlgoTime 1.90859ms Start:2018-08-28 10:50:16.331356752 +0000 UTC m=+19.297466325 End:2018-08-28 10:50:16.333265434 +0000 UTC m=+19.299374915
I0828 10:50:16.333297       1 scheduler.go:454] Total Schedule Algo cumulative time:1.449217249s for 776
I0828 10:50:16.335131       1 scheduler.go:451] ScheduleAlgoTime 1.722901ms Start:2018-08-28 10:50:16.333398464 +0000 UTC m=+19.299508064 End:2018-08-28 10:50:16.335121457 +0000 UTC m=+19.301230965
I0828 10:50:16.335165       1 scheduler.go:454] Total Schedule Algo cumulative time:1.45094015s for 777
I0828 10:50:16.337224       1 scheduler.go:451] ScheduleAlgoTime 1.899577ms Start:2018-08-28 10:50:16.335318075 +0000 UTC m=+19.301427608 End:2018-08-28 10:50:16.337217705 +0000 UTC m=+19.303327185
I0828 10:50:16.337248       1 scheduler.go:454] Total Schedule Algo cumulative time:1.452839727s for 778
I0828 10:50:16.338940       1 scheduler.go:451] ScheduleAlgoTime 1.578534ms Start:2018-08-28 10:50:16.337356009 +0000 UTC m=+19.303465520 End:2018-08-28 10:50:16.338934568 +0000 UTC m=+19.305044054
I0828 10:50:16.338963       1 scheduler.go:454] Total Schedule Algo cumulative time:1.454418261s for 779
I0828 10:50:16.340740       1 scheduler.go:451] ScheduleAlgoTime 1.688398ms Start:2018-08-28 10:50:16.339046851 +0000 UTC m=+19.305156405 End:2018-08-28 10:50:16.340735323 +0000 UTC m=+19.306844803
I0828 10:50:16.340759       1 scheduler.go:454] Total Schedule Algo cumulative time:1.456106659s for 780
I0828 10:50:16.342475       1 scheduler.go:451] ScheduleAlgoTime 1.60364ms Start:2018-08-28 10:50:16.34086695 +0000 UTC m=+19.306976445 End:2018-08-28 10:50:16.342470604 +0000 UTC m=+19.308580085
I0828 10:50:16.342499       1 scheduler.go:454] Total Schedule Algo cumulative time:1.457710299s for 781
I0828 10:50:16.344586       1 scheduler.go:451] ScheduleAlgoTime 1.882213ms Start:2018-08-28 10:50:16.342699093 +0000 UTC m=+19.308808588 End:2018-08-28 10:50:16.344581321 +0000 UTC m=+19.310690801
I0828 10:50:16.344605       1 scheduler.go:454] Total Schedule Algo cumulative time:1.459592512s for 782
I0828 10:50:16.346360       1 scheduler.go:451] ScheduleAlgoTime 1.684164ms Start:2018-08-28 10:50:16.344670587 +0000 UTC m=+19.310780108 End:2018-08-28 10:50:16.34635479 +0000 UTC m=+19.312464272
I0828 10:50:16.346383       1 scheduler.go:454] Total Schedule Algo cumulative time:1.461276676s for 783
I0828 10:50:16.348385       1 scheduler.go:451] ScheduleAlgoTime 1.870969ms Start:2018-08-28 10:50:16.346505091 +0000 UTC m=+19.312614648 End:2018-08-28 10:50:16.348376115 +0000 UTC m=+19.314485617
I0828 10:50:16.348418       1 scheduler.go:454] Total Schedule Algo cumulative time:1.463147645s for 784
I0828 10:50:16.350007       1 scheduler.go:451] ScheduleAlgoTime 1.49137ms Start:2018-08-28 10:50:16.348508509 +0000 UTC m=+19.314618020 End:2018-08-28 10:50:16.349999902 +0000 UTC m=+19.316109390
I0828 10:50:16.350042       1 scheduler.go:454] Total Schedule Algo cumulative time:1.464639015s for 785
I0828 10:50:16.351842       1 scheduler.go:451] ScheduleAlgoTime 1.653028ms Start:2018-08-28 10:50:16.350182701 +0000 UTC m=+19.316292248 End:2018-08-28 10:50:16.351835797 +0000 UTC m=+19.317945276
I0828 10:50:16.351881       1 scheduler.go:454] Total Schedule Algo cumulative time:1.466292043s for 786
I0828 10:50:16.353632       1 scheduler.go:451] ScheduleAlgoTime 1.589514ms Start:2018-08-28 10:50:16.352037396 +0000 UTC m=+19.318146928 End:2018-08-28 10:50:16.353626962 +0000 UTC m=+19.319736442
I0828 10:50:16.353655       1 scheduler.go:454] Total Schedule Algo cumulative time:1.467881557s for 787
I0828 10:50:16.355281       1 scheduler.go:451] ScheduleAlgoTime 1.517774ms Start:2018-08-28 10:50:16.353758522 +0000 UTC m=+19.319868003 End:2018-08-28 10:50:16.355276297 +0000 UTC m=+19.321385777
I0828 10:50:16.355305       1 scheduler.go:454] Total Schedule Algo cumulative time:1.469399331s for 788
I0828 10:50:16.357046       1 scheduler.go:451] ScheduleAlgoTime 1.643881ms Start:2018-08-28 10:50:16.355396201 +0000 UTC m=+19.321505695 End:2018-08-28 10:50:16.357040097 +0000 UTC m=+19.323149576
I0828 10:50:16.357067       1 scheduler.go:454] Total Schedule Algo cumulative time:1.471043212s for 789
I0828 10:50:16.358668       1 scheduler.go:451] ScheduleAlgoTime 1.475572ms Start:2018-08-28 10:50:16.357187864 +0000 UTC m=+19.323297375 End:2018-08-28 10:50:16.358663466 +0000 UTC m=+19.324772947
I0828 10:50:16.358691       1 scheduler.go:454] Total Schedule Algo cumulative time:1.472518784s for 790
I0828 10:50:16.360741       1 scheduler.go:451] ScheduleAlgoTime 1.951323ms Start:2018-08-28 10:50:16.358783093 +0000 UTC m=+19.324892590 End:2018-08-28 10:50:16.360734433 +0000 UTC m=+19.326843913
I0828 10:50:16.360766       1 scheduler.go:454] Total Schedule Algo cumulative time:1.474470107s for 791
I0828 10:50:16.362512       1 scheduler.go:451] ScheduleAlgoTime 1.621745ms Start:2018-08-28 10:50:16.360884945 +0000 UTC m=+19.326994483 End:2018-08-28 10:50:16.362506747 +0000 UTC m=+19.328616228
I0828 10:50:16.362536       1 scheduler.go:454] Total Schedule Algo cumulative time:1.476091852s for 792
I0828 10:50:16.364181       1 scheduler.go:451] ScheduleAlgoTime 1.529428ms Start:2018-08-28 10:50:16.362644019 +0000 UTC m=+19.328753538 End:2018-08-28 10:50:16.364173478 +0000 UTC m=+19.330282966
I0828 10:50:16.364208       1 scheduler.go:454] Total Schedule Algo cumulative time:1.47762128s for 793
I0828 10:50:16.366034       1 scheduler.go:451] ScheduleAlgoTime 1.689484ms Start:2018-08-28 10:50:16.3643401 +0000 UTC m=+19.330449615 End:2018-08-28 10:50:16.366029619 +0000 UTC m=+19.332139099
I0828 10:50:16.366057       1 scheduler.go:454] Total Schedule Algo cumulative time:1.479310764s for 794
I0828 10:50:16.367689       1 scheduler.go:451] ScheduleAlgoTime 1.494324ms Start:2018-08-28 10:50:16.366187183 +0000 UTC m=+19.332296713 End:2018-08-28 10:50:16.367681555 +0000 UTC m=+19.333791037
I0828 10:50:16.367715       1 scheduler.go:454] Total Schedule Algo cumulative time:1.480805088s for 795
I0828 10:50:16.369542       1 scheduler.go:451] ScheduleAlgoTime 1.695066ms Start:2018-08-28 10:50:16.367841118 +0000 UTC m=+19.333950630 End:2018-08-28 10:50:16.369536209 +0000 UTC m=+19.335645696
I0828 10:50:16.369565       1 scheduler.go:454] Total Schedule Algo cumulative time:1.482500154s for 796
I0828 10:50:16.371358       1 scheduler.go:451] ScheduleAlgoTime 1.669793ms Start:2018-08-28 10:50:16.36968065 +0000 UTC m=+19.335790182 End:2018-08-28 10:50:16.371350493 +0000 UTC m=+19.337459975
I0828 10:50:16.371382       1 scheduler.go:454] Total Schedule Algo cumulative time:1.484169947s for 797
I0828 10:50:16.373510       1 scheduler.go:451] ScheduleAlgoTime 1.990093ms Start:2018-08-28 10:50:16.371513636 +0000 UTC m=+19.337623186 End:2018-08-28 10:50:16.373503798 +0000 UTC m=+19.339613279
I0828 10:50:16.373534       1 scheduler.go:454] Total Schedule Algo cumulative time:1.48616004s for 798
I0828 10:50:16.375317       1 scheduler.go:451] ScheduleAlgoTime 1.634584ms Start:2018-08-28 10:50:16.373677296 +0000 UTC m=+19.339786867 End:2018-08-28 10:50:16.375311967 +0000 UTC m=+19.341421451
I0828 10:50:16.375342       1 scheduler.go:454] Total Schedule Algo cumulative time:1.487794624s for 799
I0828 10:50:16.377040       1 scheduler.go:451] ScheduleAlgoTime 1.581317ms Start:2018-08-28 10:50:16.375453448 +0000 UTC m=+19.341562958 End:2018-08-28 10:50:16.377034796 +0000 UTC m=+19.343144275
I0828 10:50:16.377061       1 scheduler.go:454] Total Schedule Algo cumulative time:1.489375941s for 800
I0828 10:50:16.378622       1 scheduler.go:451] ScheduleAlgoTime 1.423437ms Start:2018-08-28 10:50:16.377192068 +0000 UTC m=+19.343301563 End:2018-08-28 10:50:16.378615517 +0000 UTC m=+19.344725000
I0828 10:50:16.378648       1 scheduler.go:454] Total Schedule Algo cumulative time:1.490799378s for 801
I0828 10:50:16.380339       1 scheduler.go:451] ScheduleAlgoTime 1.551159ms Start:2018-08-28 10:50:16.378782279 +0000 UTC m=+19.344891814 End:2018-08-28 10:50:16.380333493 +0000 UTC m=+19.346442973
I0828 10:50:16.380361       1 scheduler.go:454] Total Schedule Algo cumulative time:1.492350537s for 802
I0828 10:50:16.382278       1 scheduler.go:451] ScheduleAlgoTime 1.714894ms Start:2018-08-28 10:50:16.380556382 +0000 UTC m=+19.346665952 End:2018-08-28 10:50:16.382271367 +0000 UTC m=+19.348380846
I0828 10:50:16.382302       1 scheduler.go:454] Total Schedule Algo cumulative time:1.494065431s for 803
I0828 10:50:16.384124       1 scheduler.go:451] ScheduleAlgoTime 1.647309ms Start:2018-08-28 10:50:16.382468428 +0000 UTC m=+19.348577986 End:2018-08-28 10:50:16.3841158 +0000 UTC m=+19.350225295
I0828 10:50:16.384166       1 scheduler.go:454] Total Schedule Algo cumulative time:1.49571274s for 804
I0828 10:50:16.386036       1 scheduler.go:451] ScheduleAlgoTime 1.73914ms Start:2018-08-28 10:50:16.384289432 +0000 UTC m=+19.350398991 End:2018-08-28 10:50:16.386028652 +0000 UTC m=+19.352138131
I0828 10:50:16.386062       1 scheduler.go:454] Total Schedule Algo cumulative time:1.49745188s for 805
I0828 10:50:16.387767       1 scheduler.go:451] ScheduleAlgoTime 1.559299ms Start:2018-08-28 10:50:16.386201808 +0000 UTC m=+19.352311328 End:2018-08-28 10:50:16.387761144 +0000 UTC m=+19.353870627
I0828 10:50:16.387794       1 scheduler.go:454] Total Schedule Algo cumulative time:1.499011179s for 806
I0828 10:50:16.389518       1 scheduler.go:451] ScheduleAlgoTime 1.604279ms Start:2018-08-28 10:50:16.387908852 +0000 UTC m=+19.354018389 End:2018-08-28 10:50:16.389513189 +0000 UTC m=+19.355622668
I0828 10:50:16.389540       1 scheduler.go:454] Total Schedule Algo cumulative time:1.500615458s for 807
I0828 10:50:16.391121       1 scheduler.go:451] ScheduleAlgoTime 1.472419ms Start:2018-08-28 10:50:16.389643907 +0000 UTC m=+19.355753445 End:2018-08-28 10:50:16.391116383 +0000 UTC m=+19.357225864
I0828 10:50:16.391150       1 scheduler.go:454] Total Schedule Algo cumulative time:1.502087877s for 808
I0828 10:50:16.392890       1 scheduler.go:451] ScheduleAlgoTime 1.628668ms Start:2018-08-28 10:50:16.391256624 +0000 UTC m=+19.357366179 End:2018-08-28 10:50:16.392885367 +0000 UTC m=+19.358994847
I0828 10:50:16.392911       1 scheduler.go:454] Total Schedule Algo cumulative time:1.503716545s for 809
I0828 10:50:16.394729       1 scheduler.go:451] ScheduleAlgoTime 1.697344ms Start:2018-08-28 10:50:16.393020207 +0000 UTC m=+19.359129728 End:2018-08-28 10:50:16.394717543 +0000 UTC m=+19.360827072
I0828 10:50:16.394766       1 scheduler.go:454] Total Schedule Algo cumulative time:1.505413889s for 810
I0828 10:50:16.396610       1 scheduler.go:451] ScheduleAlgoTime 1.705593ms Start:2018-08-28 10:50:16.394899104 +0000 UTC m=+19.361008637 End:2018-08-28 10:50:16.39660475 +0000 UTC m=+19.362714230
I0828 10:50:16.396632       1 scheduler.go:454] Total Schedule Algo cumulative time:1.507119482s for 811
I0828 10:50:16.398519       1 scheduler.go:451] ScheduleAlgoTime 1.772888ms Start:2018-08-28 10:50:16.396741531 +0000 UTC m=+19.362851048 End:2018-08-28 10:50:16.398514454 +0000 UTC m=+19.364623936
I0828 10:50:16.398540       1 scheduler.go:454] Total Schedule Algo cumulative time:1.50889237s for 812
I0828 10:50:16.400276       1 scheduler.go:451] ScheduleAlgoTime 1.617504ms Start:2018-08-28 10:50:16.398652887 +0000 UTC m=+19.364762367 End:2018-08-28 10:50:16.400270387 +0000 UTC m=+19.366379871
I0828 10:50:16.400310       1 scheduler.go:454] Total Schedule Algo cumulative time:1.510509874s for 813
I0828 10:50:16.402062       1 scheduler.go:451] ScheduleAlgoTime 1.575124ms Start:2018-08-28 10:50:16.400482606 +0000 UTC m=+19.366592092 End:2018-08-28 10:50:16.402057736 +0000 UTC m=+19.368167216
I0828 10:50:16.402092       1 scheduler.go:454] Total Schedule Algo cumulative time:1.512084998s for 814
I0828 10:50:16.403804       1 scheduler.go:451] ScheduleAlgoTime 1.5831ms Start:2018-08-28 10:50:16.402215776 +0000 UTC m=+19.368325285 End:2018-08-28 10:50:16.403798906 +0000 UTC m=+19.369908385
I0828 10:50:16.403825       1 scheduler.go:454] Total Schedule Algo cumulative time:1.513668098s for 815
I0828 10:50:16.405380       1 scheduler.go:451] ScheduleAlgoTime 1.440486ms Start:2018-08-28 10:50:16.403934196 +0000 UTC m=+19.370043729 End:2018-08-28 10:50:16.405374734 +0000 UTC m=+19.371484215
I0828 10:50:16.405403       1 scheduler.go:454] Total Schedule Algo cumulative time:1.515108584s for 816
I0828 10:50:16.407171       1 scheduler.go:451] ScheduleAlgoTime 1.68094ms Start:2018-08-28 10:50:16.405483602 +0000 UTC m=+19.371593140 End:2018-08-28 10:50:16.407164247 +0000 UTC m=+19.373274080
I0828 10:50:16.407199       1 scheduler.go:454] Total Schedule Algo cumulative time:1.516789524s for 817
I0828 10:50:16.408802       1 scheduler.go:451] ScheduleAlgoTime 1.498614ms Start:2018-08-28 10:50:16.407296108 +0000 UTC m=+19.373405615 End:2018-08-28 10:50:16.408794595 +0000 UTC m=+19.374904229
I0828 10:50:16.408828       1 scheduler.go:454] Total Schedule Algo cumulative time:1.518288138s for 818
I0828 10:50:16.410698       1 scheduler.go:451] ScheduleAlgoTime 1.631082ms Start:2018-08-28 10:50:16.409060228 +0000 UTC m=+19.375169744 End:2018-08-28 10:50:16.410691345 +0000 UTC m=+19.376800826
I0828 10:50:16.410722       1 scheduler.go:454] Total Schedule Algo cumulative time:1.51991922s for 819
I0828 10:50:16.412845       1 scheduler.go:451] ScheduleAlgoTime 1.872086ms Start:2018-08-28 10:50:16.410967723 +0000 UTC m=+19.377077285 End:2018-08-28 10:50:16.412839891 +0000 UTC m=+19.378949371
I0828 10:50:16.412866       1 scheduler.go:454] Total Schedule Algo cumulative time:1.521791306s for 820
I0828 10:50:16.417587       1 scheduler.go:451] ScheduleAlgoTime 4.597624ms Start:2018-08-28 10:50:16.41298025 +0000 UTC m=+19.379089798 End:2018-08-28 10:50:16.417577844 +0000 UTC m=+19.383687422
I0828 10:50:16.417632       1 scheduler.go:454] Total Schedule Algo cumulative time:1.52638893s for 821
I0828 10:50:16.420748       1 scheduler.go:451] ScheduleAlgoTime 2.952873ms Start:2018-08-28 10:50:16.417788435 +0000 UTC m=+19.383897950 End:2018-08-28 10:50:16.420741342 +0000 UTC m=+19.386850823
I0828 10:50:16.420781       1 scheduler.go:454] Total Schedule Algo cumulative time:1.529341803s for 822
I0828 10:50:16.422726       1 scheduler.go:451] ScheduleAlgoTime 1.802418ms Start:2018-08-28 10:50:16.420916842 +0000 UTC m=+19.387026324 End:2018-08-28 10:50:16.422719262 +0000 UTC m=+19.388828742
I0828 10:50:16.422755       1 scheduler.go:454] Total Schedule Algo cumulative time:1.531144221s for 823
I0828 10:50:16.425432       1 scheduler.go:451] ScheduleAlgoTime 2.511082ms Start:2018-08-28 10:50:16.422912225 +0000 UTC m=+19.389021790 End:2018-08-28 10:50:16.425423289 +0000 UTC m=+19.391532872
I0828 10:50:16.425478       1 scheduler.go:454] Total Schedule Algo cumulative time:1.533655303s for 824
I0828 10:50:16.427214       1 scheduler.go:451] ScheduleAlgoTime 1.597101ms Start:2018-08-28 10:50:16.425611732 +0000 UTC m=+19.391721245 End:2018-08-28 10:50:16.427208866 +0000 UTC m=+19.393318346
I0828 10:50:16.427234       1 scheduler.go:454] Total Schedule Algo cumulative time:1.535252404s for 825
I0828 10:50:16.429034       1 scheduler.go:451] ScheduleAlgoTime 1.680053ms Start:2018-08-28 10:50:16.427346585 +0000 UTC m=+19.393456128 End:2018-08-28 10:50:16.429026701 +0000 UTC m=+19.395136181
I0828 10:50:16.429071       1 scheduler.go:454] Total Schedule Algo cumulative time:1.536932457s for 826
I0828 10:50:16.430775       1 scheduler.go:451] ScheduleAlgoTime 1.535309ms Start:2018-08-28 10:50:16.429234766 +0000 UTC m=+19.395344303 End:2018-08-28 10:50:16.430770129 +0000 UTC m=+19.396879612
I0828 10:50:16.430799       1 scheduler.go:454] Total Schedule Algo cumulative time:1.538467766s for 827
I0828 10:50:16.432375       1 scheduler.go:451] ScheduleAlgoTime 1.460864ms Start:2018-08-28 10:50:16.43090883 +0000 UTC m=+19.397018362 End:2018-08-28 10:50:16.432369745 +0000 UTC m=+19.398479226
I0828 10:50:16.432404       1 scheduler.go:454] Total Schedule Algo cumulative time:1.53992863s for 828
I0828 10:50:16.433924       1 scheduler.go:451] ScheduleAlgoTime 1.43585ms Start:2018-08-28 10:50:16.43248346 +0000 UTC m=+19.398592971 End:2018-08-28 10:50:16.433919339 +0000 UTC m=+19.400028821
I0828 10:50:16.433948       1 scheduler.go:454] Total Schedule Algo cumulative time:1.54136448s for 829
I0828 10:50:16.435669       1 scheduler.go:451] ScheduleAlgoTime 1.580919ms Start:2018-08-28 10:50:16.434080734 +0000 UTC m=+19.400190249 End:2018-08-28 10:50:16.435661685 +0000 UTC m=+19.401771168
I0828 10:50:16.435694       1 scheduler.go:454] Total Schedule Algo cumulative time:1.542945399s for 830
I0828 10:50:16.437531       1 scheduler.go:451] ScheduleAlgoTime 1.704348ms Start:2018-08-28 10:50:16.435821223 +0000 UTC m=+19.401930764 End:2018-08-28 10:50:16.437525631 +0000 UTC m=+19.403635112
I0828 10:50:16.437560       1 scheduler.go:454] Total Schedule Algo cumulative time:1.544649747s for 831
I0828 10:50:16.439318       1 scheduler.go:451] ScheduleAlgoTime 1.631664ms Start:2018-08-28 10:50:16.437681218 +0000 UTC m=+19.403790722 End:2018-08-28 10:50:16.439312906 +0000 UTC m=+19.405422386
I0828 10:50:16.439343       1 scheduler.go:454] Total Schedule Algo cumulative time:1.546281411s for 832
I0828 10:50:16.441318       1 scheduler.go:451] ScheduleAlgoTime 1.734011ms Start:2018-08-28 10:50:16.439578311 +0000 UTC m=+19.405687857 End:2018-08-28 10:50:16.441312382 +0000 UTC m=+19.407421868
I0828 10:50:16.441341       1 scheduler.go:454] Total Schedule Algo cumulative time:1.548015422s for 833
I0828 10:50:16.443031       1 scheduler.go:451] ScheduleAlgoTime 1.563523ms Start:2018-08-28 10:50:16.441461187 +0000 UTC m=+19.407570727 End:2018-08-28 10:50:16.443024767 +0000 UTC m=+19.409134250
I0828 10:50:16.443060       1 scheduler.go:454] Total Schedule Algo cumulative time:1.549578945s for 834
I0828 10:50:16.444926       1 scheduler.go:451] ScheduleAlgoTime 1.72184ms Start:2018-08-28 10:50:16.443198881 +0000 UTC m=+19.409308417 End:2018-08-28 10:50:16.444920772 +0000 UTC m=+19.411030257
I0828 10:50:16.444957       1 scheduler.go:454] Total Schedule Algo cumulative time:1.551300785s for 835
I0828 10:50:16.446966       1 scheduler.go:451] ScheduleAlgoTime 1.879046ms Start:2018-08-28 10:50:16.445081411 +0000 UTC m=+19.411190947 End:2018-08-28 10:50:16.446960512 +0000 UTC m=+19.413069993
I0828 10:50:16.447021       1 scheduler.go:454] Total Schedule Algo cumulative time:1.553179831s for 836
I0828 10:50:16.448921       1 scheduler.go:451] ScheduleAlgoTime 1.72738ms Start:2018-08-28 10:50:16.447184861 +0000 UTC m=+19.413294405 End:2018-08-28 10:50:16.448912279 +0000 UTC m=+19.415021785
I0828 10:50:16.448953       1 scheduler.go:454] Total Schedule Algo cumulative time:1.554907211s for 837
I0828 10:50:16.450650       1 scheduler.go:451] ScheduleAlgoTime 1.517777ms Start:2018-08-28 10:50:16.449127465 +0000 UTC m=+19.415236998 End:2018-08-28 10:50:16.450645296 +0000 UTC m=+19.416754775
I0828 10:50:16.450677       1 scheduler.go:454] Total Schedule Algo cumulative time:1.556424988s for 838
I0828 10:50:16.452718       1 scheduler.go:451] ScheduleAlgoTime 1.868733ms Start:2018-08-28 10:50:16.450842599 +0000 UTC m=+19.416952113 End:2018-08-28 10:50:16.452711322 +0000 UTC m=+19.418820846
I0828 10:50:16.452746       1 scheduler.go:454] Total Schedule Algo cumulative time:1.558293721s for 839
I0828 10:50:16.454916       1 scheduler.go:451] ScheduleAlgoTime 1.943825ms Start:2018-08-28 10:50:16.452966802 +0000 UTC m=+19.419076286 End:2018-08-28 10:50:16.454910614 +0000 UTC m=+19.421020111
I0828 10:50:16.454950       1 scheduler.go:454] Total Schedule Algo cumulative time:1.560237546s for 840
I0828 10:50:16.458119       1 scheduler.go:451] ScheduleAlgoTime 3.036865ms Start:2018-08-28 10:50:16.455076893 +0000 UTC m=+19.421186392 End:2018-08-28 10:50:16.458113754 +0000 UTC m=+19.424223257
I0828 10:50:16.458155       1 scheduler.go:454] Total Schedule Algo cumulative time:1.563274411s for 841
I0828 10:50:16.461891       1 scheduler.go:451] ScheduleAlgoTime 3.641195ms Start:2018-08-28 10:50:16.458243378 +0000 UTC m=+19.424352882 End:2018-08-28 10:50:16.461884589 +0000 UTC m=+19.427994077
I0828 10:50:16.461916       1 scheduler.go:454] Total Schedule Algo cumulative time:1.566915606s for 842
I0828 10:50:16.464597       1 scheduler.go:451] ScheduleAlgoTime 2.593413ms Start:2018-08-28 10:50:16.46199725 +0000 UTC m=+19.428106772 End:2018-08-28 10:50:16.464590687 +0000 UTC m=+19.430700185
I0828 10:50:16.464621       1 scheduler.go:454] Total Schedule Algo cumulative time:1.569509019s for 843
I0828 10:50:16.467339       1 scheduler.go:451] ScheduleAlgoTime 2.623737ms Start:2018-08-28 10:50:16.464709087 +0000 UTC m=+19.430818594 End:2018-08-28 10:50:16.467332845 +0000 UTC m=+19.433442331
I0828 10:50:16.467364       1 scheduler.go:454] Total Schedule Algo cumulative time:1.572132756s for 844
I0828 10:50:16.471079       1 scheduler.go:451] ScheduleAlgoTime 3.621969ms Start:2018-08-28 10:50:16.46745224 +0000 UTC m=+19.433561742 End:2018-08-28 10:50:16.471074229 +0000 UTC m=+19.437183711
I0828 10:50:16.471100       1 scheduler.go:454] Total Schedule Algo cumulative time:1.575754725s for 845
I0828 10:50:16.473880       1 scheduler.go:451] ScheduleAlgoTime 2.62881ms Start:2018-08-28 10:50:16.471243032 +0000 UTC m=+19.437352555 End:2018-08-28 10:50:16.473871885 +0000 UTC m=+19.439981365
I0828 10:50:16.473910       1 scheduler.go:454] Total Schedule Algo cumulative time:1.578383535s for 846
I0828 10:50:16.475941       1 scheduler.go:451] ScheduleAlgoTime 1.859298ms Start:2018-08-28 10:50:16.474073495 +0000 UTC m=+19.440183068 End:2018-08-28 10:50:16.475932788 +0000 UTC m=+19.442042366
I0828 10:50:16.475972       1 scheduler.go:454] Total Schedule Algo cumulative time:1.580242833s for 847
I0828 10:50:16.477780       1 scheduler.go:451] ScheduleAlgoTime 1.710933ms Start:2018-08-28 10:50:16.476062598 +0000 UTC m=+19.442172112 End:2018-08-28 10:50:16.477773564 +0000 UTC m=+19.443883045
I0828 10:50:16.477804       1 scheduler.go:454] Total Schedule Algo cumulative time:1.581953766s for 848
I0828 10:50:16.480836       1 scheduler.go:451] ScheduleAlgoTime 2.892893ms Start:2018-08-28 10:50:16.477935749 +0000 UTC m=+19.444045323 End:2018-08-28 10:50:16.480828737 +0000 UTC m=+19.446938216
I0828 10:50:16.480875       1 scheduler.go:454] Total Schedule Algo cumulative time:1.584846659s for 849
I0828 10:50:16.482917       1 scheduler.go:451] ScheduleAlgoTime 1.876371ms Start:2018-08-28 10:50:16.48103263 +0000 UTC m=+19.447142181 End:2018-08-28 10:50:16.482909067 +0000 UTC m=+19.449018552
I0828 10:50:16.482948       1 scheduler.go:454] Total Schedule Algo cumulative time:1.58672303s for 850
I0828 10:50:16.485001       1 scheduler.go:451] ScheduleAlgoTime 1.891338ms Start:2018-08-28 10:50:16.48310371 +0000 UTC m=+19.449213214 End:2018-08-28 10:50:16.48499507 +0000 UTC m=+19.451104552
I0828 10:50:16.485023       1 scheduler.go:454] Total Schedule Algo cumulative time:1.588614368s for 851
I0828 10:50:16.486739       1 scheduler.go:451] ScheduleAlgoTime 1.575699ms Start:2018-08-28 10:50:16.485158386 +0000 UTC m=+19.451267894 End:2018-08-28 10:50:16.486734109 +0000 UTC m=+19.452843593
I0828 10:50:16.486768       1 scheduler.go:454] Total Schedule Algo cumulative time:1.590190067s for 852
I0828 10:50:16.488646       1 scheduler.go:451] ScheduleAlgoTime 1.76674ms Start:2018-08-28 10:50:16.486873011 +0000 UTC m=+19.452982560 End:2018-08-28 10:50:16.488639819 +0000 UTC m=+19.454749300
I0828 10:50:16.488670       1 scheduler.go:454] Total Schedule Algo cumulative time:1.591956807s for 853
I0828 10:50:16.490755       1 scheduler.go:451] ScheduleAlgoTime 1.986046ms Start:2018-08-28 10:50:16.488763582 +0000 UTC m=+19.454873152 End:2018-08-28 10:50:16.490749716 +0000 UTC m=+19.456859198
I0828 10:50:16.490777       1 scheduler.go:454] Total Schedule Algo cumulative time:1.593942853s for 854
I0828 10:50:16.492493       1 scheduler.go:451] ScheduleAlgoTime 1.646538ms Start:2018-08-28 10:50:16.490840362 +0000 UTC m=+19.456949842 End:2018-08-28 10:50:16.492486895 +0000 UTC m=+19.458596380
I0828 10:50:16.492520       1 scheduler.go:454] Total Schedule Algo cumulative time:1.595589391s for 855
I0828 10:50:16.494640       1 scheduler.go:451] ScheduleAlgoTime 1.947137ms Start:2018-08-28 10:50:16.492687025 +0000 UTC m=+19.458796556 End:2018-08-28 10:50:16.494634212 +0000 UTC m=+19.460743693
I0828 10:50:16.494663       1 scheduler.go:454] Total Schedule Algo cumulative time:1.597536528s for 856
I0828 10:50:16.496609       1 scheduler.go:451] ScheduleAlgoTime 1.727015ms Start:2018-08-28 10:50:16.494876886 +0000 UTC m=+19.460986382 End:2018-08-28 10:50:16.496603919 +0000 UTC m=+19.462713397
I0828 10:50:16.496631       1 scheduler.go:454] Total Schedule Algo cumulative time:1.599263543s for 857
I0828 10:50:16.499375       1 scheduler.go:451] ScheduleAlgoTime 2.660205ms Start:2018-08-28 10:50:16.496711378 +0000 UTC m=+19.462820882 End:2018-08-28 10:50:16.499371602 +0000 UTC m=+19.465481087
I0828 10:50:16.499396       1 scheduler.go:454] Total Schedule Algo cumulative time:1.601923748s for 858
I0828 10:50:16.503554       1 scheduler.go:451] ScheduleAlgoTime 4.049585ms Start:2018-08-28 10:50:16.499496684 +0000 UTC m=+19.465606178 End:2018-08-28 10:50:16.503546269 +0000 UTC m=+19.469655763
I0828 10:50:16.503583       1 scheduler.go:454] Total Schedule Algo cumulative time:1.605973333s for 859
I0828 10:50:16.511110       1 scheduler.go:451] ScheduleAlgoTime 4.152935ms Start:2018-08-28 10:50:16.506948855 +0000 UTC m=+19.473058388 End:2018-08-28 10:50:16.511101834 +0000 UTC m=+19.477211323
I0828 10:50:16.511153       1 scheduler.go:454] Total Schedule Algo cumulative time:1.610126268s for 860
I0828 10:50:16.517041       1 scheduler.go:451] ScheduleAlgoTime 3.812556ms Start:2018-08-28 10:50:16.513216437 +0000 UTC m=+19.479325966 End:2018-08-28 10:50:16.517028923 +0000 UTC m=+19.483138522
I0828 10:50:16.517083       1 scheduler.go:454] Total Schedule Algo cumulative time:1.613938824s for 861
I0828 10:50:16.522693       1 scheduler.go:451] ScheduleAlgoTime 2.105133ms Start:2018-08-28 10:50:16.520578099 +0000 UTC m=+19.486687636 End:2018-08-28 10:50:16.522683258 +0000 UTC m=+19.488792769
I0828 10:50:16.522738       1 scheduler.go:454] Total Schedule Algo cumulative time:1.616043957s for 862
I0828 10:50:16.529514       1 scheduler.go:451] ScheduleAlgoTime 6.649582ms Start:2018-08-28 10:50:16.522855186 +0000 UTC m=+19.488964685 End:2018-08-28 10:50:16.529504787 +0000 UTC m=+19.495614267
I0828 10:50:16.529550       1 scheduler.go:454] Total Schedule Algo cumulative time:1.622693539s for 863
I0828 10:50:16.535566       1 scheduler.go:451] ScheduleAlgoTime 5.745684ms Start:2018-08-28 10:50:16.529808929 +0000 UTC m=+19.495918410 End:2018-08-28 10:50:16.535554593 +0000 UTC m=+19.501664094
I0828 10:50:16.535603       1 scheduler.go:454] Total Schedule Algo cumulative time:1.628439223s for 864
I0828 10:50:16.539036       1 scheduler.go:451] ScheduleAlgoTime 3.353622ms Start:2018-08-28 10:50:16.535676601 +0000 UTC m=+19.501786089 End:2018-08-28 10:50:16.53903023 +0000 UTC m=+19.505139711
I0828 10:50:16.539063       1 scheduler.go:454] Total Schedule Algo cumulative time:1.631792845s for 865
I0828 10:50:16.541805       1 scheduler.go:451] ScheduleAlgoTime 2.629922ms Start:2018-08-28 10:50:16.539168732 +0000 UTC m=+19.505278214 End:2018-08-28 10:50:16.541798654 +0000 UTC m=+19.507908136
I0828 10:50:16.541832       1 scheduler.go:454] Total Schedule Algo cumulative time:1.634422767s for 866
I0828 10:50:16.545923       1 scheduler.go:451] ScheduleAlgoTime 4.005819ms Start:2018-08-28 10:50:16.541909912 +0000 UTC m=+19.508019393 End:2018-08-28 10:50:16.545915731 +0000 UTC m=+19.512025212
I0828 10:50:16.545952       1 scheduler.go:454] Total Schedule Algo cumulative time:1.638428586s for 867
I0828 10:50:16.548523       1 scheduler.go:451] ScheduleAlgoTime 2.480817ms Start:2018-08-28 10:50:16.546034509 +0000 UTC m=+19.512144079 End:2018-08-28 10:50:16.548515416 +0000 UTC m=+19.514624896
I0828 10:50:16.548551       1 scheduler.go:454] Total Schedule Algo cumulative time:1.640909403s for 868
I0828 10:50:16.550495       1 scheduler.go:451] ScheduleAlgoTime 1.780098ms Start:2018-08-28 10:50:16.548707823 +0000 UTC m=+19.514817383 End:2018-08-28 10:50:16.550488 +0000 UTC m=+19.516597481
I0828 10:50:16.550517       1 scheduler.go:454] Total Schedule Algo cumulative time:1.642689501s for 869
I0828 10:50:16.552408       1 scheduler.go:451] ScheduleAlgoTime 1.75238ms Start:2018-08-28 10:50:16.550649401 +0000 UTC m=+19.516758944 End:2018-08-28 10:50:16.55240184 +0000 UTC m=+19.518511324
I0828 10:50:16.552438       1 scheduler.go:454] Total Schedule Algo cumulative time:1.644441881s for 870
I0828 10:50:16.554400       1 scheduler.go:451] ScheduleAlgoTime 1.830603ms Start:2018-08-28 10:50:16.552561423 +0000 UTC m=+19.518670966 End:2018-08-28 10:50:16.554392087 +0000 UTC m=+19.520501569
I0828 10:50:16.554428       1 scheduler.go:454] Total Schedule Algo cumulative time:1.646272484s for 871
I0828 10:50:16.556659       1 scheduler.go:451] ScheduleAlgoTime 2.077097ms Start:2018-08-28 10:50:16.554575217 +0000 UTC m=+19.520684732 End:2018-08-28 10:50:16.556652236 +0000 UTC m=+19.522761829
I0828 10:50:16.556687       1 scheduler.go:454] Total Schedule Algo cumulative time:1.648349581s for 872
I0828 10:50:16.558476       1 scheduler.go:451] ScheduleAlgoTime 1.592127ms Start:2018-08-28 10:50:16.556878798 +0000 UTC m=+19.522988304 End:2018-08-28 10:50:16.558470952 +0000 UTC m=+19.524580431
I0828 10:50:16.558498       1 scheduler.go:454] Total Schedule Algo cumulative time:1.649941708s for 873
I0828 10:50:16.560178       1 scheduler.go:451] ScheduleAlgoTime 1.597738ms Start:2018-08-28 10:50:16.558571952 +0000 UTC m=+19.524681449 End:2018-08-28 10:50:16.560169706 +0000 UTC m=+19.526279187
I0828 10:50:16.560206       1 scheduler.go:454] Total Schedule Algo cumulative time:1.651539446s for 874
I0828 10:50:16.562002       1 scheduler.go:451] ScheduleAlgoTime 1.661671ms Start:2018-08-28 10:50:16.560334725 +0000 UTC m=+19.526444263 End:2018-08-28 10:50:16.561996454 +0000 UTC m=+19.528105934
I0828 10:50:16.562023       1 scheduler.go:454] Total Schedule Algo cumulative time:1.653201117s for 875
I0828 10:50:16.563961       1 scheduler.go:451] ScheduleAlgoTime 1.844074ms Start:2018-08-28 10:50:16.562111882 +0000 UTC m=+19.528221456 End:2018-08-28 10:50:16.56395605 +0000 UTC m=+19.530065530
I0828 10:50:16.563982       1 scheduler.go:454] Total Schedule Algo cumulative time:1.655045191s for 876
I0828 10:50:16.566030       1 scheduler.go:451] ScheduleAlgoTime 1.912084ms Start:2018-08-28 10:50:16.564113946 +0000 UTC m=+19.530223440 End:2018-08-28 10:50:16.56602604 +0000 UTC m=+19.532135524
I0828 10:50:16.566053       1 scheduler.go:454] Total Schedule Algo cumulative time:1.656957275s for 877
I0828 10:50:16.567964       1 scheduler.go:451] ScheduleAlgoTime 1.756533ms Start:2018-08-28 10:50:16.566201813 +0000 UTC m=+19.532311364 End:2018-08-28 10:50:16.567958417 +0000 UTC m=+19.534067897
I0828 10:50:16.567984       1 scheduler.go:454] Total Schedule Algo cumulative time:1.658713808s for 878
I0828 10:50:16.570151       1 scheduler.go:451] ScheduleAlgoTime 1.863704ms Start:2018-08-28 10:50:16.568272291 +0000 UTC m=+19.534381814 End:2018-08-28 10:50:16.57013604 +0000 UTC m=+19.536245518
I0828 10:50:16.570173       1 scheduler.go:454] Total Schedule Algo cumulative time:1.660577512s for 879
I0828 10:50:16.572526       1 scheduler.go:451] ScheduleAlgoTime 2.185112ms Start:2018-08-28 10:50:16.570333006 +0000 UTC m=+19.536442530 End:2018-08-28 10:50:16.572518143 +0000 UTC m=+19.538627642
I0828 10:50:16.572571       1 scheduler.go:454] Total Schedule Algo cumulative time:1.662762624s for 880
I0828 10:50:16.579264       1 scheduler.go:451] ScheduleAlgoTime 6.405941ms Start:2018-08-28 10:50:16.572699705 +0000 UTC m=+19.538809233 End:2018-08-28 10:50:16.579105686 +0000 UTC m=+19.545215174
I0828 10:50:16.579317       1 scheduler.go:454] Total Schedule Algo cumulative time:1.669168565s for 881
I0828 10:50:16.581235       1 scheduler.go:451] ScheduleAlgoTime 1.792255ms Start:2018-08-28 10:50:16.579434943 +0000 UTC m=+19.545544478 End:2018-08-28 10:50:16.581227251 +0000 UTC m=+19.547336733
I0828 10:50:16.581270       1 scheduler.go:454] Total Schedule Algo cumulative time:1.67096082s for 882
I0828 10:50:16.583139       1 scheduler.go:451] ScheduleAlgoTime 1.774815ms Start:2018-08-28 10:50:16.58135695 +0000 UTC m=+19.547466467 End:2018-08-28 10:50:16.583131725 +0000 UTC m=+19.549241282
I0828 10:50:16.583178       1 scheduler.go:454] Total Schedule Algo cumulative time:1.672735635s for 883
I0828 10:50:16.585222       1 scheduler.go:451] ScheduleAlgoTime 1.887332ms Start:2018-08-28 10:50:16.583324416 +0000 UTC m=+19.549433960 End:2018-08-28 10:50:16.5852118 +0000 UTC m=+19.551321292
I0828 10:50:16.585268       1 scheduler.go:454] Total Schedule Algo cumulative time:1.674622967s for 884
I0828 10:50:16.587196       1 scheduler.go:451] ScheduleAlgoTime 1.770594ms Start:2018-08-28 10:50:16.585419797 +0000 UTC m=+19.551529322 End:2018-08-28 10:50:16.587190429 +0000 UTC m=+19.553299916
I0828 10:50:16.587224       1 scheduler.go:454] Total Schedule Algo cumulative time:1.676393561s for 885
I0828 10:50:16.589025       1 scheduler.go:451] ScheduleAlgoTime 1.653697ms Start:2018-08-28 10:50:16.587366584 +0000 UTC m=+19.553476134 End:2018-08-28 10:50:16.589020352 +0000 UTC m=+19.555129831
I0828 10:50:16.589047       1 scheduler.go:454] Total Schedule Algo cumulative time:1.678047258s for 886
I0828 10:50:16.590755       1 scheduler.go:451] ScheduleAlgoTime 1.592869ms Start:2018-08-28 10:50:16.589155476 +0000 UTC m=+19.555265007 End:2018-08-28 10:50:16.590748396 +0000 UTC m=+19.556857876
I0828 10:50:16.590781       1 scheduler.go:454] Total Schedule Algo cumulative time:1.679640127s for 887
I0828 10:50:16.592867       1 scheduler.go:451] ScheduleAlgoTime 1.957247ms Start:2018-08-28 10:50:16.59090509 +0000 UTC m=+19.557014627 End:2018-08-28 10:50:16.592862395 +0000 UTC m=+19.558971874
I0828 10:50:16.592900       1 scheduler.go:454] Total Schedule Algo cumulative time:1.681597374s for 888
I0828 10:50:16.594783       1 scheduler.go:451] ScheduleAlgoTime 1.658846ms Start:2018-08-28 10:50:16.593118966 +0000 UTC m=+19.559228513 End:2018-08-28 10:50:16.594777876 +0000 UTC m=+19.560887359
I0828 10:50:16.594806       1 scheduler.go:454] Total Schedule Algo cumulative time:1.68325622s for 889
I0828 10:50:16.596593       1 scheduler.go:451] ScheduleAlgoTime 1.643505ms Start:2018-08-28 10:50:16.594944362 +0000 UTC m=+19.561053917 End:2018-08-28 10:50:16.596587939 +0000 UTC m=+19.562697422
I0828 10:50:16.596622       1 scheduler.go:454] Total Schedule Algo cumulative time:1.684899725s for 890
I0828 10:50:16.598522       1 scheduler.go:451] ScheduleAlgoTime 1.791981ms Start:2018-08-28 10:50:16.596723472 +0000 UTC m=+19.562832993 End:2018-08-28 10:50:16.598515494 +0000 UTC m=+19.564624974
I0828 10:50:16.598551       1 scheduler.go:454] Total Schedule Algo cumulative time:1.686691706s for 891
I0828 10:50:16.600861       1 scheduler.go:451] ScheduleAlgoTime 2.170455ms Start:2018-08-28 10:50:16.598682617 +0000 UTC m=+19.564792135 End:2018-08-28 10:50:16.600853011 +0000 UTC m=+19.566962590
I0828 10:50:16.600892       1 scheduler.go:454] Total Schedule Algo cumulative time:1.688862161s for 892
I0828 10:50:16.602650       1 scheduler.go:451] ScheduleAlgoTime 1.632607ms Start:2018-08-28 10:50:16.601012711 +0000 UTC m=+19.567122235 End:2018-08-28 10:50:16.602645358 +0000 UTC m=+19.568754842
I0828 10:50:16.602673       1 scheduler.go:454] Total Schedule Algo cumulative time:1.690494768s for 893
I0828 10:50:16.604456       1 scheduler.go:451] ScheduleAlgoTime 1.66472ms Start:2018-08-28 10:50:16.602786228 +0000 UTC m=+19.568895749 End:2018-08-28 10:50:16.604450988 +0000 UTC m=+19.570560469
I0828 10:50:16.604491       1 scheduler.go:454] Total Schedule Algo cumulative time:1.692159488s for 894
I0828 10:50:16.606245       1 scheduler.go:451] ScheduleAlgoTime 1.587613ms Start:2018-08-28 10:50:16.604652454 +0000 UTC m=+19.570761994 End:2018-08-28 10:50:16.606240126 +0000 UTC m=+19.572349607
I0828 10:50:16.606270       1 scheduler.go:454] Total Schedule Algo cumulative time:1.693747101s for 895
I0828 10:50:16.608565       1 scheduler.go:451] ScheduleAlgoTime 2.169848ms Start:2018-08-28 10:50:16.606390602 +0000 UTC m=+19.572500133 End:2018-08-28 10:50:16.6085605 +0000 UTC m=+19.574669981
I0828 10:50:16.608594       1 scheduler.go:454] Total Schedule Algo cumulative time:1.695916949s for 896
I0828 10:50:16.610725       1 scheduler.go:451] ScheduleAlgoTime 2.008821ms Start:2018-08-28 10:50:16.60870988 +0000 UTC m=+19.574819377 End:2018-08-28 10:50:16.610718692 +0000 UTC m=+19.576828198
I0828 10:50:16.610753       1 scheduler.go:454] Total Schedule Algo cumulative time:1.69792577s for 897
I0828 10:50:16.612573       1 scheduler.go:451] ScheduleAlgoTime 1.710281ms Start:2018-08-28 10:50:16.610858302 +0000 UTC m=+19.576967834 End:2018-08-28 10:50:16.612568634 +0000 UTC m=+19.578678115
I0828 10:50:16.612594       1 scheduler.go:454] Total Schedule Algo cumulative time:1.699636051s for 898
I0828 10:50:16.614266       1 scheduler.go:451] ScheduleAlgoTime 1.571381ms Start:2018-08-28 10:50:16.612690352 +0000 UTC m=+19.578799891 End:2018-08-28 10:50:16.614261789 +0000 UTC m=+19.580371272
I0828 10:50:16.614288       1 scheduler.go:454] Total Schedule Algo cumulative time:1.701207432s for 899
I0828 10:50:16.615983       1 scheduler.go:451] ScheduleAlgoTime 1.607386ms Start:2018-08-28 10:50:16.614367601 +0000 UTC m=+19.580477114 End:2018-08-28 10:50:16.615975014 +0000 UTC m=+19.582084500
I0828 10:50:16.616012       1 scheduler.go:454] Total Schedule Algo cumulative time:1.702814818s for 900
I0828 10:50:16.617613       1 scheduler.go:451] ScheduleAlgoTime 1.507332ms Start:2018-08-28 10:50:16.616100609 +0000 UTC m=+19.582210193 End:2018-08-28 10:50:16.617608045 +0000 UTC m=+19.583717525
I0828 10:50:16.617635       1 scheduler.go:454] Total Schedule Algo cumulative time:1.70432215s for 901
I0828 10:50:16.619402       1 scheduler.go:451] ScheduleAlgoTime 1.662909ms Start:2018-08-28 10:50:16.617734531 +0000 UTC m=+19.583844031 End:2018-08-28 10:50:16.619397458 +0000 UTC m=+19.585506940
I0828 10:50:16.619423       1 scheduler.go:454] Total Schedule Algo cumulative time:1.705985059s for 902
I0828 10:50:16.621077       1 scheduler.go:451] ScheduleAlgoTime 1.516646ms Start:2018-08-28 10:50:16.619554359 +0000 UTC m=+19.585663917 End:2018-08-28 10:50:16.621071083 +0000 UTC m=+19.587180563
I0828 10:50:16.621120       1 scheduler.go:454] Total Schedule Algo cumulative time:1.707501705s for 903
I0828 10:50:16.623333       1 scheduler.go:451] ScheduleAlgoTime 2.112046ms Start:2018-08-28 10:50:16.621216392 +0000 UTC m=+19.587325923 End:2018-08-28 10:50:16.623328483 +0000 UTC m=+19.589437969
I0828 10:50:16.623356       1 scheduler.go:454] Total Schedule Algo cumulative time:1.709613751s for 904
I0828 10:50:16.625501       1 scheduler.go:451] ScheduleAlgoTime 2.010352ms Start:2018-08-28 10:50:16.623481941 +0000 UTC m=+19.589591526 End:2018-08-28 10:50:16.625492397 +0000 UTC m=+19.591601878
I0828 10:50:16.625531       1 scheduler.go:454] Total Schedule Algo cumulative time:1.711624103s for 905
I0828 10:50:16.627301       1 scheduler.go:451] ScheduleAlgoTime 1.617891ms Start:2018-08-28 10:50:16.625677983 +0000 UTC m=+19.591787509 End:2018-08-28 10:50:16.62729592 +0000 UTC m=+19.593405400
I0828 10:50:16.627323       1 scheduler.go:454] Total Schedule Algo cumulative time:1.713241994s for 906
I0828 10:50:16.629022       1 scheduler.go:451] ScheduleAlgoTime 1.570419ms Start:2018-08-28 10:50:16.62744694 +0000 UTC m=+19.593556431 End:2018-08-28 10:50:16.629017369 +0000 UTC m=+19.595126850
I0828 10:50:16.629045       1 scheduler.go:454] Total Schedule Algo cumulative time:1.714812413s for 907
I0828 10:50:16.630830       1 scheduler.go:451] ScheduleAlgoTime 1.66468ms Start:2018-08-28 10:50:16.629156832 +0000 UTC m=+19.595266400 End:2018-08-28 10:50:16.630821584 +0000 UTC m=+19.596931080
I0828 10:50:16.630873       1 scheduler.go:454] Total Schedule Algo cumulative time:1.716477093s for 908
I0828 10:50:16.632817       1 scheduler.go:451] ScheduleAlgoTime 1.78314ms Start:2018-08-28 10:50:16.631027359 +0000 UTC m=+19.597136883 End:2018-08-28 10:50:16.632810537 +0000 UTC m=+19.598920023
I0828 10:50:16.632839       1 scheduler.go:454] Total Schedule Algo cumulative time:1.718260233s for 909
I0828 10:50:16.634446       1 scheduler.go:451] ScheduleAlgoTime 1.479453ms Start:2018-08-28 10:50:16.632961363 +0000 UTC m=+19.599070885 End:2018-08-28 10:50:16.634440857 +0000 UTC m=+19.600550338
I0828 10:50:16.634468       1 scheduler.go:454] Total Schedule Algo cumulative time:1.719739686s for 910
I0828 10:50:16.636479       1 scheduler.go:451] ScheduleAlgoTime 1.884404ms Start:2018-08-28 10:50:16.634589274 +0000 UTC m=+19.600698824 End:2018-08-28 10:50:16.636473748 +0000 UTC m=+19.602583228
I0828 10:50:16.636507       1 scheduler.go:454] Total Schedule Algo cumulative time:1.72162409s for 911
I0828 10:50:16.638438       1 scheduler.go:451] ScheduleAlgoTime 1.803237ms Start:2018-08-28 10:50:16.636628992 +0000 UTC m=+19.602738490 End:2018-08-28 10:50:16.638432246 +0000 UTC m=+19.604541727
I0828 10:50:16.638460       1 scheduler.go:454] Total Schedule Algo cumulative time:1.723427327s for 912
I0828 10:50:16.640280       1 scheduler.go:451] ScheduleAlgoTime 1.694346ms Start:2018-08-28 10:50:16.638578758 +0000 UTC m=+19.604688281 End:2018-08-28 10:50:16.640273017 +0000 UTC m=+19.606382627
I0828 10:50:16.640304       1 scheduler.go:454] Total Schedule Algo cumulative time:1.725121673s for 913
I0828 10:50:16.642221       1 scheduler.go:451] ScheduleAlgoTime 1.792212ms Start:2018-08-28 10:50:16.640422679 +0000 UTC m=+19.606532219 End:2018-08-28 10:50:16.64221495 +0000 UTC m=+19.608324431
I0828 10:50:16.642249       1 scheduler.go:454] Total Schedule Algo cumulative time:1.726913885s for 914
I0828 10:50:16.643877       1 scheduler.go:451] ScheduleAlgoTime 1.512138ms Start:2018-08-28 10:50:16.642360257 +0000 UTC m=+19.608469770 End:2018-08-28 10:50:16.643872428 +0000 UTC m=+19.609981908
I0828 10:50:16.643897       1 scheduler.go:454] Total Schedule Algo cumulative time:1.728426023s for 915
I0828 10:50:16.645829       1 scheduler.go:451] ScheduleAlgoTime 1.756244ms Start:2018-08-28 10:50:16.644066402 +0000 UTC m=+19.610175953 End:2018-08-28 10:50:16.645822715 +0000 UTC m=+19.611932197
I0828 10:50:16.645854       1 scheduler.go:454] Total Schedule Algo cumulative time:1.730182267s for 916
I0828 10:50:16.647699       1 scheduler.go:451] ScheduleAlgoTime 1.736067ms Start:2018-08-28 10:50:16.645959373 +0000 UTC m=+19.612068913 End:2018-08-28 10:50:16.6476955 +0000 UTC m=+19.613804980
I0828 10:50:16.647719       1 scheduler.go:454] Total Schedule Algo cumulative time:1.731918334s for 917
I0828 10:50:16.649429       1 scheduler.go:451] ScheduleAlgoTime 1.577417ms Start:2018-08-28 10:50:16.64784629 +0000 UTC m=+19.613955805 End:2018-08-28 10:50:16.649423741 +0000 UTC m=+19.615533222
I0828 10:50:16.649454       1 scheduler.go:454] Total Schedule Algo cumulative time:1.733495751s for 918
I0828 10:50:16.651166       1 scheduler.go:451] ScheduleAlgoTime 1.589073ms Start:2018-08-28 10:50:16.649571357 +0000 UTC m=+19.615680919 End:2018-08-28 10:50:16.651160512 +0000 UTC m=+19.617269992
I0828 10:50:16.651187       1 scheduler.go:454] Total Schedule Algo cumulative time:1.735084824s for 919
I0828 10:50:16.652925       1 scheduler.go:451] ScheduleAlgoTime 1.581579ms Start:2018-08-28 10:50:16.651338749 +0000 UTC m=+19.617448276 End:2018-08-28 10:50:16.652920369 +0000 UTC m=+19.619029855
I0828 10:50:16.652946       1 scheduler.go:454] Total Schedule Algo cumulative time:1.736666403s for 920
I0828 10:50:16.654616       1 scheduler.go:451] ScheduleAlgoTime 1.535373ms Start:2018-08-28 10:50:16.653075275 +0000 UTC m=+19.619184817 End:2018-08-28 10:50:16.654610705 +0000 UTC m=+19.620720190
I0828 10:50:16.654655       1 scheduler.go:454] Total Schedule Algo cumulative time:1.738201776s for 921
I0828 10:50:16.656557       1 scheduler.go:451] ScheduleAlgoTime 1.757188ms Start:2018-08-28 10:50:16.654793579 +0000 UTC m=+19.620903093 End:2018-08-28 10:50:16.656550802 +0000 UTC m=+19.622660281
I0828 10:50:16.656579       1 scheduler.go:454] Total Schedule Algo cumulative time:1.739958964s for 922
I0828 10:50:16.658296       1 scheduler.go:451] ScheduleAlgoTime 1.574587ms Start:2018-08-28 10:50:16.656716303 +0000 UTC m=+19.622825854 End:2018-08-28 10:50:16.658290957 +0000 UTC m=+19.624400441
I0828 10:50:16.658318       1 scheduler.go:454] Total Schedule Algo cumulative time:1.741533551s for 923
I0828 10:50:16.659991       1 scheduler.go:451] ScheduleAlgoTime 1.610071ms Start:2018-08-28 10:50:16.658375026 +0000 UTC m=+19.624484507 End:2018-08-28 10:50:16.659985097 +0000 UTC m=+19.626094578
I0828 10:50:16.660019       1 scheduler.go:454] Total Schedule Algo cumulative time:1.743143622s for 924
I0828 10:50:16.662045       1 scheduler.go:451] ScheduleAlgoTime 1.911274ms Start:2018-08-28 10:50:16.660127113 +0000 UTC m=+19.626236616 End:2018-08-28 10:50:16.662038405 +0000 UTC m=+19.628147890
I0828 10:50:16.662070       1 scheduler.go:454] Total Schedule Algo cumulative time:1.745054896s for 925
I0828 10:50:16.663767       1 scheduler.go:451] ScheduleAlgoTime 1.585162ms Start:2018-08-28 10:50:16.662176962 +0000 UTC m=+19.628286477 End:2018-08-28 10:50:16.663762155 +0000 UTC m=+19.629871639
I0828 10:50:16.663791       1 scheduler.go:454] Total Schedule Algo cumulative time:1.746640058s for 926
I0828 10:50:16.665340       1 scheduler.go:451] ScheduleAlgoTime 1.451092ms Start:2018-08-28 10:50:16.663881832 +0000 UTC m=+19.629991368 End:2018-08-28 10:50:16.665332678 +0000 UTC m=+19.631442460
I0828 10:50:16.665369       1 scheduler.go:454] Total Schedule Algo cumulative time:1.74809115s for 927
I0828 10:50:16.667168       1 scheduler.go:451] ScheduleAlgoTime 1.592265ms Start:2018-08-28 10:50:16.6655693 +0000 UTC m=+19.631678828 End:2018-08-28 10:50:16.667161611 +0000 UTC m=+19.633271093
I0828 10:50:16.667193       1 scheduler.go:454] Total Schedule Algo cumulative time:1.749683415s for 928
I0828 10:50:16.669052       1 scheduler.go:451] ScheduleAlgoTime 1.678231ms Start:2018-08-28 10:50:16.66736864 +0000 UTC m=+19.633478163 End:2018-08-28 10:50:16.669046914 +0000 UTC m=+19.635156394
I0828 10:50:16.669087       1 scheduler.go:454] Total Schedule Algo cumulative time:1.751361646s for 929
I0828 10:50:16.671351       1 scheduler.go:451] ScheduleAlgoTime 2.055024ms Start:2018-08-28 10:50:16.669289684 +0000 UTC m=+19.635399223 End:2018-08-28 10:50:16.671344766 +0000 UTC m=+19.637454247
I0828 10:50:16.671374       1 scheduler.go:454] Total Schedule Algo cumulative time:1.75341667s for 930
I0828 10:50:16.673161       1 scheduler.go:451] ScheduleAlgoTime 1.683908ms Start:2018-08-28 10:50:16.671472646 +0000 UTC m=+19.637582149 End:2018-08-28 10:50:16.673156573 +0000 UTC m=+19.639266057
I0828 10:50:16.673186       1 scheduler.go:454] Total Schedule Algo cumulative time:1.755100578s for 931
I0828 10:50:16.674979       1 scheduler.go:451] ScheduleAlgoTime 1.684507ms Start:2018-08-28 10:50:16.673289019 +0000 UTC m=+19.639398535 End:2018-08-28 10:50:16.674973558 +0000 UTC m=+19.641083042
I0828 10:50:16.675001       1 scheduler.go:454] Total Schedule Algo cumulative time:1.756785085s for 932
I0828 10:50:16.676666       1 scheduler.go:451] ScheduleAlgoTime 1.532389ms Start:2018-08-28 10:50:16.675127036 +0000 UTC m=+19.641236583 End:2018-08-28 10:50:16.67665949 +0000 UTC m=+19.642768972
I0828 10:50:16.676691       1 scheduler.go:454] Total Schedule Algo cumulative time:1.758317474s for 933
I0828 10:50:16.678534       1 scheduler.go:451] ScheduleAlgoTime 1.703562ms Start:2018-08-28 10:50:16.676824246 +0000 UTC m=+19.642933790 End:2018-08-28 10:50:16.678527868 +0000 UTC m=+19.644637352
I0828 10:50:16.678558       1 scheduler.go:454] Total Schedule Algo cumulative time:1.760021036s for 934
I0828 10:50:16.680401       1 scheduler.go:451] ScheduleAlgoTime 1.735834ms Start:2018-08-28 10:50:16.678659092 +0000 UTC m=+19.644768659 End:2018-08-28 10:50:16.680395012 +0000 UTC m=+19.646504493
I0828 10:50:16.680441       1 scheduler.go:454] Total Schedule Algo cumulative time:1.76175687s for 935
I0828 10:50:16.682425       1 scheduler.go:451] ScheduleAlgoTime 1.888327ms Start:2018-08-28 10:50:16.680530996 +0000 UTC m=+19.646640493 End:2018-08-28 10:50:16.68241934 +0000 UTC m=+19.648528820
I0828 10:50:16.682448       1 scheduler.go:454] Total Schedule Algo cumulative time:1.763645197s for 936
I0828 10:50:16.684088       1 scheduler.go:451] ScheduleAlgoTime 1.50806ms Start:2018-08-28 10:50:16.682573624 +0000 UTC m=+19.648683157 End:2018-08-28 10:50:16.684081734 +0000 UTC m=+19.650191217
I0828 10:50:16.684112       1 scheduler.go:454] Total Schedule Algo cumulative time:1.765153257s for 937
I0828 10:50:16.685701       1 scheduler.go:451] ScheduleAlgoTime 1.446252ms Start:2018-08-28 10:50:16.684250066 +0000 UTC m=+19.650359601 End:2018-08-28 10:50:16.685696373 +0000 UTC m=+19.651805853
I0828 10:50:16.685722       1 scheduler.go:454] Total Schedule Algo cumulative time:1.766599509s for 938
I0828 10:50:16.687592       1 scheduler.go:451] ScheduleAlgoTime 1.756584ms Start:2018-08-28 10:50:16.685829834 +0000 UTC m=+19.651939347 End:2018-08-28 10:50:16.687586452 +0000 UTC m=+19.653695931
I0828 10:50:16.687614       1 scheduler.go:454] Total Schedule Algo cumulative time:1.768356093s for 939
I0828 10:50:16.689473       1 scheduler.go:451] ScheduleAlgoTime 1.686259ms Start:2018-08-28 10:50:16.687781354 +0000 UTC m=+19.653890862 End:2018-08-28 10:50:16.689467637 +0000 UTC m=+19.655577121
I0828 10:50:16.689496       1 scheduler.go:454] Total Schedule Algo cumulative time:1.770042352s for 940
I0828 10:50:16.691341       1 scheduler.go:451] ScheduleAlgoTime 1.722418ms Start:2018-08-28 10:50:16.689611262 +0000 UTC m=+19.655720803 End:2018-08-28 10:50:16.69133363 +0000 UTC m=+19.657443221
I0828 10:50:16.691370       1 scheduler.go:454] Total Schedule Algo cumulative time:1.77176477s for 941
I0828 10:50:16.693393       1 scheduler.go:451] ScheduleAlgoTime 1.788961ms Start:2018-08-28 10:50:16.691593986 +0000 UTC m=+19.657703490 End:2018-08-28 10:50:16.693382914 +0000 UTC m=+19.659492451
I0828 10:50:16.693430       1 scheduler.go:454] Total Schedule Algo cumulative time:1.773553731s for 942
I0828 10:50:16.695189       1 scheduler.go:451] ScheduleAlgoTime 1.617928ms Start:2018-08-28 10:50:16.693564977 +0000 UTC m=+19.659674533 End:2018-08-28 10:50:16.69518298 +0000 UTC m=+19.661292461
I0828 10:50:16.695212       1 scheduler.go:454] Total Schedule Algo cumulative time:1.775171659s for 943
I0828 10:50:16.697749       1 scheduler.go:451] ScheduleAlgoTime 2.433579ms Start:2018-08-28 10:50:16.695310878 +0000 UTC m=+19.661420391 End:2018-08-28 10:50:16.697744477 +0000 UTC m=+19.663853970
I0828 10:50:16.698025       1 scheduler.go:454] Total Schedule Algo cumulative time:1.777605238s for 944
I0828 10:50:16.704269       1 scheduler.go:451] ScheduleAlgoTime 5.948478ms Start:2018-08-28 10:50:16.698313584 +0000 UTC m=+19.664423091 End:2018-08-28 10:50:16.704262088 +0000 UTC m=+19.670371569
I0828 10:50:16.704302       1 scheduler.go:454] Total Schedule Algo cumulative time:1.783553716s for 945
I0828 10:50:16.706221       1 scheduler.go:451] ScheduleAlgoTime 1.740539ms Start:2018-08-28 10:50:16.70447385 +0000 UTC m=+19.670583402 End:2018-08-28 10:50:16.706214461 +0000 UTC m=+19.672323941
I0828 10:50:16.706268       1 scheduler.go:454] Total Schedule Algo cumulative time:1.785294255s for 946
I0828 10:50:16.708192       1 scheduler.go:451] ScheduleAlgoTime 1.790157ms Start:2018-08-28 10:50:16.706395199 +0000 UTC m=+19.672504735 End:2018-08-28 10:50:16.708185408 +0000 UTC m=+19.674294892
I0828 10:50:16.708224       1 scheduler.go:454] Total Schedule Algo cumulative time:1.787084412s for 947
I0828 10:50:16.710177       1 scheduler.go:451] ScheduleAlgoTime 1.800853ms Start:2018-08-28 10:50:16.708370176 +0000 UTC m=+19.674479721 End:2018-08-28 10:50:16.710171095 +0000 UTC m=+19.676280574
I0828 10:50:16.710206       1 scheduler.go:454] Total Schedule Algo cumulative time:1.788885265s for 948
I0828 10:50:16.712086       1 scheduler.go:451] ScheduleAlgoTime 1.699347ms Start:2018-08-28 10:50:16.710379029 +0000 UTC m=+19.676488548 End:2018-08-28 10:50:16.712078233 +0000 UTC m=+19.678187895
I0828 10:50:16.712120       1 scheduler.go:454] Total Schedule Algo cumulative time:1.790584612s for 949
I0828 10:50:16.713854       1 scheduler.go:451] ScheduleAlgoTime 1.615969ms Start:2018-08-28 10:50:16.712231995 +0000 UTC m=+19.678341523 End:2018-08-28 10:50:16.713848008 +0000 UTC m=+19.679957492
I0828 10:50:16.713886       1 scheduler.go:454] Total Schedule Algo cumulative time:1.792200581s for 950
I0828 10:50:16.715723       1 scheduler.go:451] ScheduleAlgoTime 1.714233ms Start:2018-08-28 10:50:16.71400142 +0000 UTC m=+19.680110976 End:2018-08-28 10:50:16.715715717 +0000 UTC m=+19.681825209
I0828 10:50:16.715755       1 scheduler.go:454] Total Schedule Algo cumulative time:1.793914814s for 951
I0828 10:50:16.717751       1 scheduler.go:451] ScheduleAlgoTime 1.85564ms Start:2018-08-28 10:50:16.715889705 +0000 UTC m=+19.681999201 End:2018-08-28 10:50:16.717745358 +0000 UTC m=+19.683854841
I0828 10:50:16.717781       1 scheduler.go:454] Total Schedule Algo cumulative time:1.795770454s for 952
I0828 10:50:16.720153       1 scheduler.go:451] ScheduleAlgoTime 2.247242ms Start:2018-08-28 10:50:16.717889992 +0000 UTC m=+19.683999511 End:2018-08-28 10:50:16.720137272 +0000 UTC m=+19.686246753
I0828 10:50:16.720177       1 scheduler.go:454] Total Schedule Algo cumulative time:1.798017696s for 953
I0828 10:50:16.722092       1 scheduler.go:451] ScheduleAlgoTime 1.772995ms Start:2018-08-28 10:50:16.720313535 +0000 UTC m=+19.686423035 End:2018-08-28 10:50:16.722086546 +0000 UTC m=+19.688196030
I0828 10:50:16.722127       1 scheduler.go:454] Total Schedule Algo cumulative time:1.799790691s for 954
I0828 10:50:16.724212       1 scheduler.go:451] ScheduleAlgoTime 1.958945ms Start:2018-08-28 10:50:16.722245323 +0000 UTC m=+19.688354863 End:2018-08-28 10:50:16.724204326 +0000 UTC m=+19.690313808
I0828 10:50:16.724239       1 scheduler.go:454] Total Schedule Algo cumulative time:1.801749636s for 955
I0828 10:50:16.726167       1 scheduler.go:451] ScheduleAlgoTime 1.775313ms Start:2018-08-28 10:50:16.724386093 +0000 UTC m=+19.690495636 End:2018-08-28 10:50:16.726161465 +0000 UTC m=+19.692270949
I0828 10:50:16.726192       1 scheduler.go:454] Total Schedule Algo cumulative time:1.803524949s for 956
I0828 10:50:16.727962       1 scheduler.go:451] ScheduleAlgoTime 1.596399ms Start:2018-08-28 10:50:16.726359312 +0000 UTC m=+19.692468820 End:2018-08-28 10:50:16.727955738 +0000 UTC m=+19.694065219
I0828 10:50:16.727987       1 scheduler.go:454] Total Schedule Algo cumulative time:1.805121348s for 957
I0828 10:50:16.729808       1 scheduler.go:451] ScheduleAlgoTime 1.721322ms Start:2018-08-28 10:50:16.728081284 +0000 UTC m=+19.694190829 End:2018-08-28 10:50:16.729802664 +0000 UTC m=+19.695912151
I0828 10:50:16.729844       1 scheduler.go:454] Total Schedule Algo cumulative time:1.80684267s for 958
I0828 10:50:16.731561       1 scheduler.go:451] ScheduleAlgoTime 1.617486ms Start:2018-08-28 10:50:16.72993914 +0000 UTC m=+19.696048636 End:2018-08-28 10:50:16.731556642 +0000 UTC m=+19.697666122
I0828 10:50:16.731583       1 scheduler.go:454] Total Schedule Algo cumulative time:1.808460156s for 959
I0828 10:50:16.733395       1 scheduler.go:451] ScheduleAlgoTime 1.695558ms Start:2018-08-28 10:50:16.731694804 +0000 UTC m=+19.697804313 End:2018-08-28 10:50:16.73339039 +0000 UTC m=+19.699499871
I0828 10:50:16.733423       1 scheduler.go:454] Total Schedule Algo cumulative time:1.810155714s for 960
I0828 10:50:16.735469       1 scheduler.go:451] ScheduleAlgoTime 1.833292ms Start:2018-08-28 10:50:16.733628084 +0000 UTC m=+19.699737598 End:2018-08-28 10:50:16.73546117 +0000 UTC m=+19.701570890
I0828 10:50:16.735500       1 scheduler.go:454] Total Schedule Algo cumulative time:1.811989006s for 961
I0828 10:50:16.737332       1 scheduler.go:451] ScheduleAlgoTime 1.691305ms Start:2018-08-28 10:50:16.735635311 +0000 UTC m=+19.701744858 End:2018-08-28 10:50:16.737326682 +0000 UTC m=+19.703436163
I0828 10:50:16.737365       1 scheduler.go:454] Total Schedule Algo cumulative time:1.813680311s for 962
I0828 10:50:16.739088       1 scheduler.go:451] ScheduleAlgoTime 1.622372ms Start:2018-08-28 10:50:16.737460302 +0000 UTC m=+19.703569821 End:2018-08-28 10:50:16.739082711 +0000 UTC m=+19.705192193
I0828 10:50:16.739111       1 scheduler.go:454] Total Schedule Algo cumulative time:1.815302683s for 963
I0828 10:50:16.741683       1 scheduler.go:451] ScheduleAlgoTime 2.417894ms Start:2018-08-28 10:50:16.739258384 +0000 UTC m=+19.705367906 End:2018-08-28 10:50:16.741676321 +0000 UTC m=+19.707785800
I0828 10:50:16.741708       1 scheduler.go:454] Total Schedule Algo cumulative time:1.817720577s for 964
I0828 10:50:16.743471       1 scheduler.go:451] ScheduleAlgoTime 1.668799ms Start:2018-08-28 10:50:16.741795769 +0000 UTC m=+19.707905327 End:2018-08-28 10:50:16.743464642 +0000 UTC m=+19.709574126
I0828 10:50:16.743494       1 scheduler.go:454] Total Schedule Algo cumulative time:1.819389376s for 965
I0828 10:50:16.745177       1 scheduler.go:451] ScheduleAlgoTime 1.5414ms Start:2018-08-28 10:50:16.743629608 +0000 UTC m=+19.709739129 End:2018-08-28 10:50:16.745171049 +0000 UTC m=+19.711280529
I0828 10:50:16.745198       1 scheduler.go:454] Total Schedule Algo cumulative time:1.820930776s for 966
I0828 10:50:16.746971       1 scheduler.go:451] ScheduleAlgoTime 1.659555ms Start:2018-08-28 10:50:16.745306043 +0000 UTC m=+19.711415524 End:2018-08-28 10:50:16.746965598 +0000 UTC m=+19.713075079
I0828 10:50:16.747003       1 scheduler.go:454] Total Schedule Algo cumulative time:1.822590331s for 967
I0828 10:50:16.748844       1 scheduler.go:451] ScheduleAlgoTime 1.650395ms Start:2018-08-28 10:50:16.747187472 +0000 UTC m=+19.713296992 End:2018-08-28 10:50:16.748837901 +0000 UTC m=+19.714947387
I0828 10:50:16.748872       1 scheduler.go:454] Total Schedule Algo cumulative time:1.824240726s for 968
I0828 10:50:16.750756       1 scheduler.go:451] ScheduleAlgoTime 1.742007ms Start:2018-08-28 10:50:16.749008399 +0000 UTC m=+19.715117944 End:2018-08-28 10:50:16.750750468 +0000 UTC m=+19.716859951
I0828 10:50:16.750784       1 scheduler.go:454] Total Schedule Algo cumulative time:1.825982733s for 969
I0828 10:50:16.752692       1 scheduler.go:451] ScheduleAlgoTime 1.792675ms Start:2018-08-28 10:50:16.750894565 +0000 UTC m=+19.717004045 End:2018-08-28 10:50:16.75268724 +0000 UTC m=+19.718796720
I0828 10:50:16.752712       1 scheduler.go:454] Total Schedule Algo cumulative time:1.827775408s for 970
I0828 10:50:16.754546       1 scheduler.go:451] ScheduleAlgoTime 1.719174ms Start:2018-08-28 10:50:16.752822515 +0000 UTC m=+19.718932078 End:2018-08-28 10:50:16.754541768 +0000 UTC m=+19.720651252
I0828 10:50:16.754567       1 scheduler.go:454] Total Schedule Algo cumulative time:1.829494582s for 971
I0828 10:50:16.756135       1 scheduler.go:451] ScheduleAlgoTime 1.44762ms Start:2018-08-28 10:50:16.75468195 +0000 UTC m=+19.720791489 End:2018-08-28 10:50:16.756129629 +0000 UTC m=+19.722239109
I0828 10:50:16.756169       1 scheduler.go:454] Total Schedule Algo cumulative time:1.830942202s for 972
I0828 10:50:16.757871       1 scheduler.go:451] ScheduleAlgoTime 1.576574ms Start:2018-08-28 10:50:16.756288995 +0000 UTC m=+19.722398537 End:2018-08-28 10:50:16.757865631 +0000 UTC m=+19.723975111
I0828 10:50:16.757894       1 scheduler.go:454] Total Schedule Algo cumulative time:1.832518776s for 973
I0828 10:50:16.759608       1 scheduler.go:451] ScheduleAlgoTime 1.604892ms Start:2018-08-28 10:50:16.757998205 +0000 UTC m=+19.724107700 End:2018-08-28 10:50:16.759603112 +0000 UTC m=+19.725712592
I0828 10:50:16.759629       1 scheduler.go:454] Total Schedule Algo cumulative time:1.834123668s for 974
I0828 10:50:16.761446       1 scheduler.go:451] ScheduleAlgoTime 1.702054ms Start:2018-08-28 10:50:16.759738545 +0000 UTC m=+19.725848114 End:2018-08-28 10:50:16.761440688 +0000 UTC m=+19.727550168
I0828 10:50:16.761468       1 scheduler.go:454] Total Schedule Algo cumulative time:1.835825722s for 975
I0828 10:50:16.763260       1 scheduler.go:451] ScheduleAlgoTime 1.661797ms Start:2018-08-28 10:50:16.761581953 +0000 UTC m=+19.727691488 End:2018-08-28 10:50:16.763243804 +0000 UTC m=+19.729353285
I0828 10:50:16.763283       1 scheduler.go:454] Total Schedule Algo cumulative time:1.837487519s for 976
I0828 10:50:16.765546       1 scheduler.go:451] ScheduleAlgoTime 2.172895ms Start:2018-08-28 10:50:16.763366733 +0000 UTC m=+19.729476277 End:2018-08-28 10:50:16.765539692 +0000 UTC m=+19.731649172
I0828 10:50:16.765581       1 scheduler.go:454] Total Schedule Algo cumulative time:1.839660414s for 977
I0828 10:50:16.767333       1 scheduler.go:451] ScheduleAlgoTime 1.614732ms Start:2018-08-28 10:50:16.765714628 +0000 UTC m=+19.731824201 End:2018-08-28 10:50:16.767329451 +0000 UTC m=+19.733438933
I0828 10:50:16.767352       1 scheduler.go:454] Total Schedule Algo cumulative time:1.841275146s for 978
I0828 10:50:16.769301       1 scheduler.go:451] ScheduleAlgoTime 1.833892ms Start:2018-08-28 10:50:16.76746026 +0000 UTC m=+19.733569771 End:2018-08-28 10:50:16.769294174 +0000 UTC m=+19.735403663
I0828 10:50:16.769325       1 scheduler.go:454] Total Schedule Algo cumulative time:1.843109038s for 979
I0828 10:50:16.771435       1 scheduler.go:451] ScheduleAlgoTime 1.952183ms Start:2018-08-28 10:50:16.769477402 +0000 UTC m=+19.735586927 End:2018-08-28 10:50:16.771429626 +0000 UTC m=+19.737539110
I0828 10:50:16.771457       1 scheduler.go:454] Total Schedule Algo cumulative time:1.845061221s for 980
I0828 10:50:16.773558       1 scheduler.go:451] ScheduleAlgoTime 1.967036ms Start:2018-08-28 10:50:16.771582414 +0000 UTC m=+19.737691941 End:2018-08-28 10:50:16.773549468 +0000 UTC m=+19.739658977
I0828 10:50:16.773589       1 scheduler.go:454] Total Schedule Algo cumulative time:1.847028257s for 981
I0828 10:50:16.775351       1 scheduler.go:451] ScheduleAlgoTime 1.579704ms Start:2018-08-28 10:50:16.773765834 +0000 UTC m=+19.739875365 End:2018-08-28 10:50:16.775345588 +0000 UTC m=+19.741455069
I0828 10:50:16.775373       1 scheduler.go:454] Total Schedule Algo cumulative time:1.848607961s for 982
I0828 10:50:16.777255       1 scheduler.go:451] ScheduleAlgoTime 1.774881ms Start:2018-08-28 10:50:16.77547669 +0000 UTC m=+19.741586244 End:2018-08-28 10:50:16.777251641 +0000 UTC m=+19.743361125
I0828 10:50:16.777275       1 scheduler.go:454] Total Schedule Algo cumulative time:1.850382842s for 983
I0828 10:50:16.779009       1 scheduler.go:451] ScheduleAlgoTime 1.626215ms Start:2018-08-28 10:50:16.777376326 +0000 UTC m=+19.743485821 End:2018-08-28 10:50:16.779002552 +0000 UTC m=+19.745112036
I0828 10:50:16.779034       1 scheduler.go:454] Total Schedule Algo cumulative time:1.852009057s for 984
I0828 10:50:16.780815       1 scheduler.go:451] ScheduleAlgoTime 1.660319ms Start:2018-08-28 10:50:16.779148634 +0000 UTC m=+19.745258152 End:2018-08-28 10:50:16.780808986 +0000 UTC m=+19.746918471
I0828 10:50:16.780837       1 scheduler.go:454] Total Schedule Algo cumulative time:1.853669376s for 985
I0828 10:50:16.783379       1 scheduler.go:451] ScheduleAlgoTime 2.418551ms Start:2018-08-28 10:50:16.780954893 +0000 UTC m=+19.747064441 End:2018-08-28 10:50:16.783373513 +0000 UTC m=+19.749482992
I0828 10:50:16.783400       1 scheduler.go:454] Total Schedule Algo cumulative time:1.856087927s for 986
I0828 10:50:16.785362       1 scheduler.go:451] ScheduleAlgoTime 1.852934ms Start:2018-08-28 10:50:16.783500989 +0000 UTC m=+19.749610511 End:2018-08-28 10:50:16.785353836 +0000 UTC m=+19.751463445
I0828 10:50:16.785393       1 scheduler.go:454] Total Schedule Algo cumulative time:1.857940861s for 987
I0828 10:50:16.787167       1 scheduler.go:451] ScheduleAlgoTime 1.632175ms Start:2018-08-28 10:50:16.785530042 +0000 UTC m=+19.751639573 End:2018-08-28 10:50:16.787162265 +0000 UTC m=+19.753271748
I0828 10:50:16.787189       1 scheduler.go:454] Total Schedule Algo cumulative time:1.859573036s for 988
I0828 10:50:16.789034       1 scheduler.go:451] ScheduleAlgoTime 1.672626ms Start:2018-08-28 10:50:16.787355961 +0000 UTC m=+19.753465515 End:2018-08-28 10:50:16.789028662 +0000 UTC m=+19.755138141
I0828 10:50:16.789063       1 scheduler.go:454] Total Schedule Algo cumulative time:1.861245662s for 989
I0828 10:50:16.790800       1 scheduler.go:451] ScheduleAlgoTime 1.633397ms Start:2018-08-28 10:50:16.789160415 +0000 UTC m=+19.755269946 End:2018-08-28 10:50:16.790793863 +0000 UTC m=+19.756903343
I0828 10:50:16.790826       1 scheduler.go:454] Total Schedule Algo cumulative time:1.862879059s for 990
I0828 10:50:16.792775       1 scheduler.go:451] ScheduleAlgoTime 1.847068ms Start:2018-08-28 10:50:16.790922684 +0000 UTC m=+19.757032212 End:2018-08-28 10:50:16.7927698 +0000 UTC m=+19.758879280
I0828 10:50:16.792798       1 scheduler.go:454] Total Schedule Algo cumulative time:1.864726127s for 991
I0828 10:50:16.794871       1 scheduler.go:451] ScheduleAlgoTime 1.915558ms Start:2018-08-28 10:50:16.792948931 +0000 UTC m=+19.759058486 End:2018-08-28 10:50:16.794864559 +0000 UTC m=+19.760974044
I0828 10:50:16.794897       1 scheduler.go:454] Total Schedule Algo cumulative time:1.866641685s for 992
I0828 10:50:16.796948       1 scheduler.go:451] ScheduleAlgoTime 1.934959ms Start:2018-08-28 10:50:16.795006647 +0000 UTC m=+19.761116180 End:2018-08-28 10:50:16.796941659 +0000 UTC m=+19.763051139
I0828 10:50:16.796972       1 scheduler.go:454] Total Schedule Algo cumulative time:1.868576644s for 993
I0828 10:50:16.798599       1 scheduler.go:451] ScheduleAlgoTime 1.502726ms Start:2018-08-28 10:50:16.797090156 +0000 UTC m=+19.763199682 End:2018-08-28 10:50:16.798592924 +0000 UTC m=+19.764702408
I0828 10:50:16.798625       1 scheduler.go:454] Total Schedule Algo cumulative time:1.87007937s for 994
I0828 10:50:16.800388       1 scheduler.go:451] ScheduleAlgoTime 1.677977ms Start:2018-08-28 10:50:16.798704319 +0000 UTC m=+19.764813824 End:2018-08-28 10:50:16.800382321 +0000 UTC m=+19.766491801
I0828 10:50:16.800410       1 scheduler.go:454] Total Schedule Algo cumulative time:1.871757347s for 995
I0828 10:50:16.802297       1 scheduler.go:451] ScheduleAlgoTime 1.752013ms Start:2018-08-28 10:50:16.80053872 +0000 UTC m=+19.766648241 End:2018-08-28 10:50:16.802290774 +0000 UTC m=+19.768400254
I0828 10:50:16.802328       1 scheduler.go:454] Total Schedule Algo cumulative time:1.87350936s for 996
I0828 10:50:16.803997       1 scheduler.go:451] ScheduleAlgoTime 1.522184ms Start:2018-08-28 10:50:16.80246952 +0000 UTC m=+19.768579032 End:2018-08-28 10:50:16.803991732 +0000 UTC m=+19.770101216
I0828 10:50:16.804019       1 scheduler.go:454] Total Schedule Algo cumulative time:1.875031544s for 997
I0828 10:50:16.805940       1 scheduler.go:451] ScheduleAlgoTime 1.55184ms Start:2018-08-28 10:50:16.804382468 +0000 UTC m=+19.770491983 End:2018-08-28 10:50:16.80593434 +0000 UTC m=+19.772043823
I0828 10:50:16.805971       1 scheduler.go:454] Total Schedule Algo cumulative time:1.876583384s for 998
I0828 10:50:16.807701       1 scheduler.go:451] ScheduleAlgoTime 1.618462ms Start:2018-08-28 10:50:16.806077041 +0000 UTC m=+19.772186573 End:2018-08-28 10:50:16.807695555 +0000 UTC m=+19.773805035
I0828 10:50:16.807721       1 scheduler.go:454] Total Schedule Algo cumulative time:1.878201846s for 999
I0828 10:50:16.809510       1 scheduler.go:451] ScheduleAlgoTime 1.686175ms Start:2018-08-28 10:50:16.807818174 +0000 UTC m=+19.773927701 End:2018-08-28 10:50:16.809504395 +0000 UTC m=+19.775613876
I0828 10:50:16.809533       1 scheduler.go:454] Total Schedule Algo cumulative time:1.879888021s for 1000
I0828 10:50:16.811338       1 scheduler.go:451] ScheduleAlgoTime 1.677511ms Start:2018-08-28 10:50:16.809655426 +0000 UTC m=+19.775764948 End:2018-08-28 10:50:16.81133298 +0000 UTC m=+19.777442459
I0828 10:50:16.811361       1 scheduler.go:454] Total Schedule Algo cumulative time:1.881565532s for 1001
I0828 10:50:16.813068       1 scheduler.go:451] ScheduleAlgoTime 1.609441ms Start:2018-08-28 10:50:16.811452623 +0000 UTC m=+19.777562156 End:2018-08-28 10:50:16.813062116 +0000 UTC m=+19.779171597
I0828 10:50:16.813089       1 scheduler.go:454] Total Schedule Algo cumulative time:1.883174973s for 1002
I0828 10:50:16.814819       1 scheduler.go:451] ScheduleAlgoTime 1.547629ms Start:2018-08-28 10:50:16.813265591 +0000 UTC m=+19.779375090 End:2018-08-28 10:50:16.814813239 +0000 UTC m=+19.780922719
I0828 10:50:16.814855       1 scheduler.go:454] Total Schedule Algo cumulative time:1.884722602s for 1003
I0828 10:50:16.816728       1 scheduler.go:451] ScheduleAlgoTime 1.764283ms Start:2018-08-28 10:50:16.81495934 +0000 UTC m=+19.781069107 End:2018-08-28 10:50:16.81672391 +0000 UTC m=+19.782833390
I0828 10:50:16.816750       1 scheduler.go:454] Total Schedule Algo cumulative time:1.886486885s for 1004
I0828 10:50:16.818376       1 scheduler.go:451] ScheduleAlgoTime 1.528771ms Start:2018-08-28 10:50:16.816843567 +0000 UTC m=+19.782953103 End:2018-08-28 10:50:16.818372392 +0000 UTC m=+19.784481874
I0828 10:50:16.818398       1 scheduler.go:454] Total Schedule Algo cumulative time:1.888015656s for 1005
I0828 10:50:16.820013       1 scheduler.go:451] ScheduleAlgoTime 1.536523ms Start:2018-08-28 10:50:16.818471148 +0000 UTC m=+19.784580704 End:2018-08-28 10:50:16.820007745 +0000 UTC m=+19.786117227
I0828 10:50:16.820034       1 scheduler.go:454] Total Schedule Algo cumulative time:1.889552179s for 1006
I0828 10:50:16.821777       1 scheduler.go:451] ScheduleAlgoTime 1.615251ms Start:2018-08-28 10:50:16.820157994 +0000 UTC m=+19.786267506 End:2018-08-28 10:50:16.821773277 +0000 UTC m=+19.787882757
I0828 10:50:16.821800       1 scheduler.go:454] Total Schedule Algo cumulative time:1.89116743s for 1007
I0828 10:50:16.823770       1 scheduler.go:451] ScheduleAlgoTime 1.878476ms Start:2018-08-28 10:50:16.821886001 +0000 UTC m=+19.787995538 End:2018-08-28 10:50:16.823764528 +0000 UTC m=+19.789874014
I0828 10:50:16.823791       1 scheduler.go:454] Total Schedule Algo cumulative time:1.893045906s for 1008
I0828 10:50:16.825741       1 scheduler.go:451] ScheduleAlgoTime 1.784372ms Start:2018-08-28 10:50:16.823951739 +0000 UTC m=+19.790061235 End:2018-08-28 10:50:16.825736127 +0000 UTC m=+19.791845607
I0828 10:50:16.825763       1 scheduler.go:454] Total Schedule Algo cumulative time:1.894830278s for 1009
I0828 10:50:16.833761       1 scheduler.go:451] ScheduleAlgoTime 7.872675ms Start:2018-08-28 10:50:16.825880387 +0000 UTC m=+19.791989942 End:2018-08-28 10:50:16.833753135 +0000 UTC m=+19.799862617
I0828 10:50:16.833815       1 scheduler.go:454] Total Schedule Algo cumulative time:1.902702953s for 1010
I0828 10:50:16.837911       1 scheduler.go:451] ScheduleAlgoTime 3.921145ms Start:2018-08-28 10:50:16.833982641 +0000 UTC m=+19.800092121 End:2018-08-28 10:50:16.837903783 +0000 UTC m=+19.804013266
I0828 10:50:16.837946       1 scheduler.go:454] Total Schedule Algo cumulative time:1.906624098s for 1011
I0828 10:50:16.839614       1 scheduler.go:451] ScheduleAlgoTime 1.552423ms Start:2018-08-28 10:50:16.838055467 +0000 UTC m=+19.804164989 End:2018-08-28 10:50:16.839607931 +0000 UTC m=+19.805717412
I0828 10:50:16.839642       1 scheduler.go:454] Total Schedule Algo cumulative time:1.908176521s for 1012
I0828 10:50:16.842268       1 scheduler.go:451] ScheduleAlgoTime 2.187457ms Start:2018-08-28 10:50:16.840074106 +0000 UTC m=+19.806183625 End:2018-08-28 10:50:16.842261575 +0000 UTC m=+19.808371082
I0828 10:50:16.842302       1 scheduler.go:454] Total Schedule Algo cumulative time:1.910363978s for 1013
I0828 10:50:16.844019       1 scheduler.go:451] ScheduleAlgoTime 1.589044ms Start:2018-08-28 10:50:16.842423507 +0000 UTC m=+19.808532997 End:2018-08-28 10:50:16.844012557 +0000 UTC m=+19.810122041
I0828 10:50:16.844044       1 scheduler.go:454] Total Schedule Algo cumulative time:1.911953022s for 1014
I0828 10:50:16.845870       1 scheduler.go:451] ScheduleAlgoTime 1.727959ms Start:2018-08-28 10:50:16.844136435 +0000 UTC m=+19.810245954 End:2018-08-28 10:50:16.84586443 +0000 UTC m=+19.811973913
I0828 10:50:16.845902       1 scheduler.go:454] Total Schedule Algo cumulative time:1.913680981s for 1015
I0828 10:50:16.847768       1 scheduler.go:451] ScheduleAlgoTime 1.728849ms Start:2018-08-28 10:50:16.846034048 +0000 UTC m=+19.812143573 End:2018-08-28 10:50:16.847762941 +0000 UTC m=+19.813872422
I0828 10:50:16.847812       1 scheduler.go:454] Total Schedule Algo cumulative time:1.91540983s for 1016
I0828 10:50:16.849646       1 scheduler.go:451] ScheduleAlgoTime 1.663967ms Start:2018-08-28 10:50:16.847976267 +0000 UTC m=+19.814085798 End:2018-08-28 10:50:16.849640285 +0000 UTC m=+19.815749765
I0828 10:50:16.849679       1 scheduler.go:454] Total Schedule Algo cumulative time:1.917073797s for 1017
I0828 10:50:16.851352       1 scheduler.go:451] ScheduleAlgoTime 1.54013ms Start:2018-08-28 10:50:16.849805539 +0000 UTC m=+19.815915083 End:2018-08-28 10:50:16.851345725 +0000 UTC m=+19.817455213
I0828 10:50:16.851378       1 scheduler.go:454] Total Schedule Algo cumulative time:1.918613927s for 1018
I0828 10:50:16.853164       1 scheduler.go:451] ScheduleAlgoTime 1.643056ms Start:2018-08-28 10:50:16.851514905 +0000 UTC m=+19.817624422 End:2018-08-28 10:50:16.853157996 +0000 UTC m=+19.819267478
I0828 10:50:16.853189       1 scheduler.go:454] Total Schedule Algo cumulative time:1.920256983s for 1019
I0828 10:50:16.855045       1 scheduler.go:451] ScheduleAlgoTime 1.709169ms Start:2018-08-28 10:50:16.853329713 +0000 UTC m=+19.819439277 End:2018-08-28 10:50:16.855038966 +0000 UTC m=+19.821148446
I0828 10:50:16.855071       1 scheduler.go:454] Total Schedule Algo cumulative time:1.921966152s for 1020
I0828 10:50:16.856866       1 scheduler.go:451] ScheduleAlgoTime 1.662194ms Start:2018-08-28 10:50:16.855198209 +0000 UTC m=+19.821307729 End:2018-08-28 10:50:16.856860433 +0000 UTC m=+19.822969923
I0828 10:50:16.856897       1 scheduler.go:454] Total Schedule Algo cumulative time:1.923628346s for 1021
I0828 10:50:16.858638       1 scheduler.go:451] ScheduleAlgoTime 1.62623ms Start:2018-08-28 10:50:16.857007224 +0000 UTC m=+19.823116748 End:2018-08-28 10:50:16.858633499 +0000 UTC m=+19.824742978
I0828 10:50:16.858663       1 scheduler.go:454] Total Schedule Algo cumulative time:1.925254576s for 1022
I0828 10:50:16.860401       1 scheduler.go:451] ScheduleAlgoTime 1.60116ms Start:2018-08-28 10:50:16.858794608 +0000 UTC m=+19.824904122 End:2018-08-28 10:50:16.860395802 +0000 UTC m=+19.826505282
I0828 10:50:16.860421       1 scheduler.go:454] Total Schedule Algo cumulative time:1.926855736s for 1023
I0828 10:50:16.862224       1 scheduler.go:451] ScheduleAlgoTime 1.65582ms Start:2018-08-28 10:50:16.860562896 +0000 UTC m=+19.826672448 End:2018-08-28 10:50:16.862218785 +0000 UTC m=+19.828328268
I0828 10:50:16.862250       1 scheduler.go:454] Total Schedule Algo cumulative time:1.928511556s for 1024
I0828 10:50:16.863989       1 scheduler.go:451] ScheduleAlgoTime 1.583996ms Start:2018-08-28 10:50:16.862400108 +0000 UTC m=+19.828509639 End:2018-08-28 10:50:16.863984152 +0000 UTC m=+19.830093635
I0828 10:50:16.864029       1 scheduler.go:454] Total Schedule Algo cumulative time:1.930095552s for 1025
I0828 10:50:16.865721       1 scheduler.go:451] ScheduleAlgoTime 1.594853ms Start:2018-08-28 10:50:16.864121221 +0000 UTC m=+19.830230728 End:2018-08-28 10:50:16.865716098 +0000 UTC m=+19.831825581
I0828 10:50:16.865745       1 scheduler.go:454] Total Schedule Algo cumulative time:1.931690405s for 1026
I0828 10:50:16.867501       1 scheduler.go:451] ScheduleAlgoTime 1.653868ms Start:2018-08-28 10:50:16.86584161 +0000 UTC m=+19.831951133 End:2018-08-28 10:50:16.86749552 +0000 UTC m=+19.833605001
I0828 10:50:16.867557       1 scheduler.go:454] Total Schedule Algo cumulative time:1.933344273s for 1027
I0828 10:50:16.869349       1 scheduler.go:451] ScheduleAlgoTime 1.659984ms Start:2018-08-28 10:50:16.867682519 +0000 UTC m=+19.833792062 End:2018-08-28 10:50:16.869342565 +0000 UTC m=+19.835452046
I0828 10:50:16.869374       1 scheduler.go:454] Total Schedule Algo cumulative time:1.935004257s for 1028
I0828 10:50:16.871284       1 scheduler.go:451] ScheduleAlgoTime 1.774989ms Start:2018-08-28 10:50:16.869502464 +0000 UTC m=+19.835611966 End:2018-08-28 10:50:16.871277475 +0000 UTC m=+19.837386955
I0828 10:50:16.871308       1 scheduler.go:454] Total Schedule Algo cumulative time:1.936779246s for 1029
I0828 10:50:16.873077       1 scheduler.go:451] ScheduleAlgoTime 1.594079ms Start:2018-08-28 10:50:16.871477804 +0000 UTC m=+19.837587352 End:2018-08-28 10:50:16.87307195 +0000 UTC m=+19.839181431
I0828 10:50:16.873120       1 scheduler.go:454] Total Schedule Algo cumulative time:1.938373325s for 1030
I0828 10:50:16.874792       1 scheduler.go:451] ScheduleAlgoTime 1.547737ms Start:2018-08-28 10:50:16.873240062 +0000 UTC m=+19.839349638 End:2018-08-28 10:50:16.874787894 +0000 UTC m=+19.840897375
I0828 10:50:16.874813       1 scheduler.go:454] Total Schedule Algo cumulative time:1.939921062s for 1031
I0828 10:50:16.876629       1 scheduler.go:451] ScheduleAlgoTime 1.664378ms Start:2018-08-28 10:50:16.874958723 +0000 UTC m=+19.841068264 End:2018-08-28 10:50:16.876623149 +0000 UTC m=+19.842732642
I0828 10:50:16.876664       1 scheduler.go:454] Total Schedule Algo cumulative time:1.94158544s for 1032
I0828 10:50:16.878391       1 scheduler.go:451] ScheduleAlgoTime 1.568652ms Start:2018-08-28 10:50:16.876817632 +0000 UTC m=+19.842927203 End:2018-08-28 10:50:16.878386374 +0000 UTC m=+19.844495855
I0828 10:50:16.878412       1 scheduler.go:454] Total Schedule Algo cumulative time:1.943154092s for 1033
I0828 10:50:16.879946       1 scheduler.go:451] ScheduleAlgoTime 1.428885ms Start:2018-08-28 10:50:16.878512295 +0000 UTC m=+19.844621818 End:2018-08-28 10:50:16.87994122 +0000 UTC m=+19.846050703
I0828 10:50:16.879969       1 scheduler.go:454] Total Schedule Algo cumulative time:1.944582977s for 1034
I0828 10:50:16.881780       1 scheduler.go:451] ScheduleAlgoTime 1.729895ms Start:2018-08-28 10:50:16.880044721 +0000 UTC m=+19.846154223 End:2018-08-28 10:50:16.881774634 +0000 UTC m=+19.847884118
I0828 10:50:16.881803       1 scheduler.go:454] Total Schedule Algo cumulative time:1.946312872s for 1035
I0828 10:50:16.883569       1 scheduler.go:451] ScheduleAlgoTime 1.637779ms Start:2018-08-28 10:50:16.881922079 +0000 UTC m=+19.848031616 End:2018-08-28 10:50:16.883559797 +0000 UTC m=+19.849669395
I0828 10:50:16.883611       1 scheduler.go:454] Total Schedule Algo cumulative time:1.947950651s for 1036
I0828 10:50:16.885341       1 scheduler.go:451] ScheduleAlgoTime 1.626145ms Start:2018-08-28 10:50:16.883709557 +0000 UTC m=+19.849819076 End:2018-08-28 10:50:16.885335741 +0000 UTC m=+19.851445221
I0828 10:50:16.885362       1 scheduler.go:454] Total Schedule Algo cumulative time:1.949576796s for 1037
I0828 10:50:16.887149       1 scheduler.go:451] ScheduleAlgoTime 1.668761ms Start:2018-08-28 10:50:16.885465569 +0000 UTC m=+19.851575064 End:2018-08-28 10:50:16.887134341 +0000 UTC m=+19.853243825
I0828 10:50:16.887171       1 scheduler.go:454] Total Schedule Algo cumulative time:1.951245557s for 1038
I0828 10:50:16.888883       1 scheduler.go:451] ScheduleAlgoTime 1.546413ms Start:2018-08-28 10:50:16.887330987 +0000 UTC m=+19.853440494 End:2018-08-28 10:50:16.888877426 +0000 UTC m=+19.854986907
I0828 10:50:16.888906       1 scheduler.go:454] Total Schedule Algo cumulative time:1.95279197s for 1039
I0828 10:50:16.890826       1 scheduler.go:451] ScheduleAlgoTime 1.73678ms Start:2018-08-28 10:50:16.889084147 +0000 UTC m=+19.855193702 End:2018-08-28 10:50:16.890820998 +0000 UTC m=+19.856930482
I0828 10:50:16.890848       1 scheduler.go:454] Total Schedule Algo cumulative time:1.95452875s for 1040
I0828 10:50:16.892574       1 scheduler.go:451] ScheduleAlgoTime 1.603238ms Start:2018-08-28 10:50:16.890965098 +0000 UTC m=+19.857074612 End:2018-08-28 10:50:16.892568366 +0000 UTC m=+19.858677850
I0828 10:50:16.892595       1 scheduler.go:454] Total Schedule Algo cumulative time:1.956131988s for 1041
I0828 10:50:16.894442       1 scheduler.go:451] ScheduleAlgoTime 1.718199ms Start:2018-08-28 10:50:16.892715346 +0000 UTC m=+19.858824858 End:2018-08-28 10:50:16.894433561 +0000 UTC m=+19.860543057
I0828 10:50:16.894476       1 scheduler.go:454] Total Schedule Algo cumulative time:1.957850187s for 1042
I0828 10:50:16.896480       1 scheduler.go:451] ScheduleAlgoTime 1.824865ms Start:2018-08-28 10:50:16.894648941 +0000 UTC m=+19.860758510 End:2018-08-28 10:50:16.89647389 +0000 UTC m=+19.862583375
I0828 10:50:16.896522       1 scheduler.go:454] Total Schedule Algo cumulative time:1.959675052s for 1043
I0828 10:50:16.898461       1 scheduler.go:451] ScheduleAlgoTime 1.779054ms Start:2018-08-28 10:50:16.896676466 +0000 UTC m=+19.862786042 End:2018-08-28 10:50:16.898455611 +0000 UTC m=+19.864565096
I0828 10:50:16.898483       1 scheduler.go:454] Total Schedule Algo cumulative time:1.961454106s for 1044
I0828 10:50:16.900174       1 scheduler.go:451] ScheduleAlgoTime 1.58291ms Start:2018-08-28 10:50:16.898584741 +0000 UTC m=+19.864694486 End:2018-08-28 10:50:16.900167913 +0000 UTC m=+19.866277396
I0828 10:50:16.900200       1 scheduler.go:454] Total Schedule Algo cumulative time:1.963037016s for 1045
I0828 10:50:16.901950       1 scheduler.go:451] ScheduleAlgoTime 1.63547ms Start:2018-08-28 10:50:16.900308205 +0000 UTC m=+19.866417741 End:2018-08-28 10:50:16.901943721 +0000 UTC m=+19.868053211
I0828 10:50:16.901978       1 scheduler.go:454] Total Schedule Algo cumulative time:1.964672486s for 1046
I0828 10:50:16.904360       1 scheduler.go:451] ScheduleAlgoTime 2.230139ms Start:2018-08-28 10:50:16.902121617 +0000 UTC m=+19.868231145 End:2018-08-28 10:50:16.904351803 +0000 UTC m=+19.870461284
I0828 10:50:16.904386       1 scheduler.go:454] Total Schedule Algo cumulative time:1.966902625s for 1047
I0828 10:50:16.906288       1 scheduler.go:451] ScheduleAlgoTime 1.735561ms Start:2018-08-28 10:50:16.904543526 +0000 UTC m=+19.870653064 End:2018-08-28 10:50:16.906279097 +0000 UTC m=+19.872388625
I0828 10:50:16.906323       1 scheduler.go:454] Total Schedule Algo cumulative time:1.968638186s for 1048
I0828 10:50:16.908209       1 scheduler.go:451] ScheduleAlgoTime 1.739461ms Start:2018-08-28 10:50:16.906463076 +0000 UTC m=+19.872572612 End:2018-08-28 10:50:16.908202593 +0000 UTC m=+19.874312073
I0828 10:50:16.908236       1 scheduler.go:454] Total Schedule Algo cumulative time:1.970377647s for 1049
I0828 10:50:16.910052       1 scheduler.go:451] ScheduleAlgoTime 1.626644ms Start:2018-08-28 10:50:16.908419039 +0000 UTC m=+19.874528596 End:2018-08-28 10:50:16.91004576 +0000 UTC m=+19.876155240
I0828 10:50:16.910089       1 scheduler.go:454] Total Schedule Algo cumulative time:1.972004291s for 1050
I0828 10:50:16.912002       1 scheduler.go:451] ScheduleAlgoTime 1.678472ms Start:2018-08-28 10:50:16.910318586 +0000 UTC m=+19.876428113 End:2018-08-28 10:50:16.911997106 +0000 UTC m=+19.878106585
I0828 10:50:16.912022       1 scheduler.go:454] Total Schedule Algo cumulative time:1.973682763s for 1051
I0828 10:50:16.914114       1 scheduler.go:451] ScheduleAlgoTime 1.958656ms Start:2018-08-28 10:50:16.912149666 +0000 UTC m=+19.878259211 End:2018-08-28 10:50:16.914108379 +0000 UTC m=+19.880217867
I0828 10:50:16.914136       1 scheduler.go:454] Total Schedule Algo cumulative time:1.975641419s for 1052
I0828 10:50:16.916516       1 scheduler.go:451] ScheduleAlgoTime 2.287532ms Start:2018-08-28 10:50:16.914222692 +0000 UTC m=+19.880332198 End:2018-08-28 10:50:16.916510248 +0000 UTC m=+19.882619730
I0828 10:50:16.916536       1 scheduler.go:454] Total Schedule Algo cumulative time:1.977928951s for 1053
I0828 10:50:16.918442       1 scheduler.go:451] ScheduleAlgoTime 1.805362ms Start:2018-08-28 10:50:16.916632732 +0000 UTC m=+19.882742294 End:2018-08-28 10:50:16.918438174 +0000 UTC m=+19.884547656
I0828 10:50:16.918464       1 scheduler.go:454] Total Schedule Algo cumulative time:1.979734313s for 1054
I0828 10:50:16.920240       1 scheduler.go:451] ScheduleAlgoTime 1.670587ms Start:2018-08-28 10:50:16.918560909 +0000 UTC m=+19.884670480 End:2018-08-28 10:50:16.920231583 +0000 UTC m=+19.886341067
I0828 10:50:16.920267       1 scheduler.go:454] Total Schedule Algo cumulative time:1.9814049s for 1055
I0828 10:50:16.922264       1 scheduler.go:451] ScheduleAlgoTime 1.88703ms Start:2018-08-28 10:50:16.920372203 +0000 UTC m=+19.886481737 End:2018-08-28 10:50:16.922259284 +0000 UTC m=+19.888368767
I0828 10:50:16.922287       1 scheduler.go:454] Total Schedule Algo cumulative time:1.98329193s for 1056
I0828 10:50:16.924117       1 scheduler.go:451] ScheduleAlgoTime 1.729864ms Start:2018-08-28 10:50:16.922381489 +0000 UTC m=+19.888490992 End:2018-08-28 10:50:16.924111375 +0000 UTC m=+19.890220856
I0828 10:50:16.924153       1 scheduler.go:454] Total Schedule Algo cumulative time:1.985021794s for 1057
I0828 10:50:16.925913       1 scheduler.go:451] ScheduleAlgoTime 1.66762ms Start:2018-08-28 10:50:16.924240038 +0000 UTC m=+19.890349590 End:2018-08-28 10:50:16.925907728 +0000 UTC m=+19.892017210
I0828 10:50:16.925936       1 scheduler.go:454] Total Schedule Algo cumulative time:1.986689414s for 1058
I0828 10:50:16.927696       1 scheduler.go:451] ScheduleAlgoTime 1.6184ms Start:2018-08-28 10:50:16.92607209 +0000 UTC m=+19.892181621 End:2018-08-28 10:50:16.927690542 +0000 UTC m=+19.893800021
I0828 10:50:16.927717       1 scheduler.go:454] Total Schedule Algo cumulative time:1.988307814s for 1059
I0828 10:50:16.929688       1 scheduler.go:451] ScheduleAlgoTime 1.859935ms Start:2018-08-28 10:50:16.927822397 +0000 UTC m=+19.893931894 End:2018-08-28 10:50:16.929682344 +0000 UTC m=+19.895791829
I0828 10:50:16.929714       1 scheduler.go:454] Total Schedule Algo cumulative time:1.990167749s for 1060
I0828 10:50:16.931427       1 scheduler.go:451] ScheduleAlgoTime 1.595575ms Start:2018-08-28 10:50:16.929825752 +0000 UTC m=+19.895935291 End:2018-08-28 10:50:16.931421386 +0000 UTC m=+19.897530866
I0828 10:50:16.931446       1 scheduler.go:454] Total Schedule Algo cumulative time:1.991763324s for 1061
I0828 10:50:16.933653       1 scheduler.go:451] ScheduleAlgoTime 2.122269ms Start:2018-08-28 10:50:16.931525178 +0000 UTC m=+19.897634672 End:2018-08-28 10:50:16.933647461 +0000 UTC m=+19.899756941
I0828 10:50:16.933676       1 scheduler.go:454] Total Schedule Algo cumulative time:1.993885593s for 1062
I0828 10:50:16.935518       1 scheduler.go:451] ScheduleAlgoTime 1.658274ms Start:2018-08-28 10:50:16.933854332 +0000 UTC m=+19.899963852 End:2018-08-28 10:50:16.935512646 +0000 UTC m=+19.901622126
I0828 10:50:16.935540       1 scheduler.go:454] Total Schedule Algo cumulative time:1.995543867s for 1063
I0828 10:50:16.937643       1 scheduler.go:451] ScheduleAlgoTime 1.919366ms Start:2018-08-28 10:50:16.935716399 +0000 UTC m=+19.901825913 End:2018-08-28 10:50:16.937635687 +0000 UTC m=+19.903745279
I0828 10:50:16.937671       1 scheduler.go:454] Total Schedule Algo cumulative time:1.997463233s for 1064
I0828 10:50:16.939352       1 scheduler.go:451] ScheduleAlgoTime 1.496669ms Start:2018-08-28 10:50:16.937849565 +0000 UTC m=+19.903959044 End:2018-08-28 10:50:16.939346233 +0000 UTC m=+19.905455713
I0828 10:50:16.939377       1 scheduler.go:454] Total Schedule Algo cumulative time:1.998959902s for 1065
I0828 10:50:16.941465       1 scheduler.go:451] ScheduleAlgoTime 1.964596ms Start:2018-08-28 10:50:16.939492603 +0000 UTC m=+19.905602140 End:2018-08-28 10:50:16.941457167 +0000 UTC m=+19.907566736
I0828 10:50:16.941493       1 scheduler.go:454] Total Schedule Algo cumulative time:2.000924498s for 1066
I0828 10:50:16.943300       1 scheduler.go:451] ScheduleAlgoTime 1.603476ms Start:2018-08-28 10:50:16.941691961 +0000 UTC m=+19.907801533 End:2018-08-28 10:50:16.943295527 +0000 UTC m=+19.909405009
I0828 10:50:16.943323       1 scheduler.go:454] Total Schedule Algo cumulative time:2.002527974s for 1067
I0828 10:50:16.945165       1 scheduler.go:451] ScheduleAlgoTime 1.642292ms Start:2018-08-28 10:50:16.943515594 +0000 UTC m=+19.909625133 End:2018-08-28 10:50:16.945157699 +0000 UTC m=+19.911267425
I0828 10:50:16.945193       1 scheduler.go:454] Total Schedule Algo cumulative time:2.004170266s for 1068
I0828 10:50:16.948009       1 scheduler.go:451] ScheduleAlgoTime 2.486328ms Start:2018-08-28 10:50:16.945508684 +0000 UTC m=+19.911618230 End:2018-08-28 10:50:16.947995078 +0000 UTC m=+19.914104558
I0828 10:50:16.948033       1 scheduler.go:454] Total Schedule Algo cumulative time:2.006656594s for 1069
I0828 10:50:16.949828       1 scheduler.go:451] ScheduleAlgoTime 1.612514ms Start:2018-08-28 10:50:16.948209849 +0000 UTC m=+19.914319373 End:2018-08-28 10:50:16.949822405 +0000 UTC m=+19.915931887
I0828 10:50:16.949861       1 scheduler.go:454] Total Schedule Algo cumulative time:2.008269108s for 1070
I0828 10:50:16.951662       1 scheduler.go:451] ScheduleAlgoTime 1.663951ms Start:2018-08-28 10:50:16.949991488 +0000 UTC m=+19.916101052 End:2018-08-28 10:50:16.951655523 +0000 UTC m=+19.917765003
I0828 10:50:16.951684       1 scheduler.go:454] Total Schedule Algo cumulative time:2.009933059s for 1071
I0828 10:50:16.953573       1 scheduler.go:451] ScheduleAlgoTime 1.753465ms Start:2018-08-28 10:50:16.951814231 +0000 UTC m=+19.917923745 End:2018-08-28 10:50:16.953567718 +0000 UTC m=+19.919677210
I0828 10:50:16.953597       1 scheduler.go:454] Total Schedule Algo cumulative time:2.011686524s for 1072
I0828 10:50:16.955335       1 scheduler.go:451] ScheduleAlgoTime 1.590087ms Start:2018-08-28 10:50:16.953739666 +0000 UTC m=+19.919849236 End:2018-08-28 10:50:16.955329843 +0000 UTC m=+19.921439323
I0828 10:50:16.955357       1 scheduler.go:454] Total Schedule Algo cumulative time:2.013276611s for 1073
I0828 10:50:16.957035       1 scheduler.go:451] ScheduleAlgoTime 1.578149ms Start:2018-08-28 10:50:16.955449779 +0000 UTC m=+19.921559302 End:2018-08-28 10:50:16.957027959 +0000 UTC m=+19.923137451
I0828 10:50:16.957058       1 scheduler.go:454] Total Schedule Algo cumulative time:2.01485476s for 1074
I0828 10:50:16.959063       1 scheduler.go:451] ScheduleAlgoTime 1.844345ms Start:2018-08-28 10:50:16.95721191 +0000 UTC m=+19.923321420 End:2018-08-28 10:50:16.959056284 +0000 UTC m=+19.925165765
I0828 10:50:16.959085       1 scheduler.go:454] Total Schedule Algo cumulative time:2.016699105s for 1075
I0828 10:50:16.960820       1 scheduler.go:451] ScheduleAlgoTime 1.632994ms Start:2018-08-28 10:50:16.959181736 +0000 UTC m=+19.925291278 End:2018-08-28 10:50:16.960814792 +0000 UTC m=+19.926924272
I0828 10:50:16.960858       1 scheduler.go:454] Total Schedule Algo cumulative time:2.018332099s for 1076
I0828 10:50:16.962648       1 scheduler.go:451] ScheduleAlgoTime 1.687281ms Start:2018-08-28 10:50:16.960955471 +0000 UTC m=+19.927064985 End:2018-08-28 10:50:16.96264278 +0000 UTC m=+19.928752266
I0828 10:50:16.962669       1 scheduler.go:454] Total Schedule Algo cumulative time:2.02001938s for 1077
I0828 10:50:16.964637       1 scheduler.go:451] ScheduleAlgoTime 1.875923ms Start:2018-08-28 10:50:16.962757144 +0000 UTC m=+19.928866684 End:2018-08-28 10:50:16.964633121 +0000 UTC m=+19.930742607
I0828 10:50:16.964657       1 scheduler.go:454] Total Schedule Algo cumulative time:2.021895303s for 1078
I0828 10:50:16.969678       1 scheduler.go:451] ScheduleAlgoTime 4.903574ms Start:2018-08-28 10:50:16.964768638 +0000 UTC m=+19.930878159 End:2018-08-28 10:50:16.969672251 +0000 UTC m=+19.935781733
I0828 10:50:16.969724       1 scheduler.go:454] Total Schedule Algo cumulative time:2.026798877s for 1079
I0828 10:50:16.974099       1 scheduler.go:451] ScheduleAlgoTime 4.130824ms Start:2018-08-28 10:50:16.969962756 +0000 UTC m=+19.936072294 End:2018-08-28 10:50:16.974093636 +0000 UTC m=+19.940203118
I0828 10:50:16.974130       1 scheduler.go:454] Total Schedule Algo cumulative time:2.030929701s for 1080
I0828 10:50:16.976022       1 scheduler.go:451] ScheduleAlgoTime 1.743935ms Start:2018-08-28 10:50:16.974271489 +0000 UTC m=+19.940380996 End:2018-08-28 10:50:16.976015452 +0000 UTC m=+19.942124931
I0828 10:50:16.976065       1 scheduler.go:454] Total Schedule Algo cumulative time:2.032673636s for 1081
I0828 10:50:16.978561       1 scheduler.go:451] ScheduleAlgoTime 2.38455ms Start:2018-08-28 10:50:16.976171498 +0000 UTC m=+19.942281016 End:2018-08-28 10:50:16.97855608 +0000 UTC m=+19.944665566
I0828 10:50:16.978589       1 scheduler.go:454] Total Schedule Algo cumulative time:2.035058186s for 1082
I0828 10:50:16.980671       1 scheduler.go:451] ScheduleAlgoTime 1.965863ms Start:2018-08-28 10:50:16.978701047 +0000 UTC m=+19.944810553 End:2018-08-28 10:50:16.980666936 +0000 UTC m=+19.946776416
I0828 10:50:16.980696       1 scheduler.go:454] Total Schedule Algo cumulative time:2.037024049s for 1083
I0828 10:50:16.982612       1 scheduler.go:451] ScheduleAlgoTime 1.758874ms Start:2018-08-28 10:50:16.980847298 +0000 UTC m=+19.946956817 End:2018-08-28 10:50:16.982606209 +0000 UTC m=+19.948715691
I0828 10:50:16.982640       1 scheduler.go:454] Total Schedule Algo cumulative time:2.038782923s for 1084
I0828 10:50:16.984524       1 scheduler.go:451] ScheduleAlgoTime 1.721814ms Start:2018-08-28 10:50:16.982797527 +0000 UTC m=+19.948907037 End:2018-08-28 10:50:16.984519371 +0000 UTC m=+19.950628851
I0828 10:50:16.984547       1 scheduler.go:454] Total Schedule Algo cumulative time:2.040504737s for 1085
I0828 10:50:16.986421       1 scheduler.go:451] ScheduleAlgoTime 1.774031ms Start:2018-08-28 10:50:16.984639172 +0000 UTC m=+19.950748713 End:2018-08-28 10:50:16.986413241 +0000 UTC m=+19.952522744
I0828 10:50:16.986449       1 scheduler.go:454] Total Schedule Algo cumulative time:2.042278768s for 1086
I0828 10:50:16.988424       1 scheduler.go:451] ScheduleAlgoTime 1.826032ms Start:2018-08-28 10:50:16.986592453 +0000 UTC m=+19.952701977 End:2018-08-28 10:50:16.988418525 +0000 UTC m=+19.954528009
I0828 10:50:16.988462       1 scheduler.go:454] Total Schedule Algo cumulative time:2.0441048s for 1087
I0828 10:50:16.990354       1 scheduler.go:451] ScheduleAlgoTime 1.71787ms Start:2018-08-28 10:50:16.988631763 +0000 UTC m=+19.954741296 End:2018-08-28 10:50:16.990349685 +0000 UTC m=+19.956459166
I0828 10:50:16.990379       1 scheduler.go:454] Total Schedule Algo cumulative time:2.04582267s for 1088
I0828 10:50:16.992158       1 scheduler.go:451] ScheduleAlgoTime 1.642276ms Start:2018-08-28 10:50:16.990510065 +0000 UTC m=+19.956619586 End:2018-08-28 10:50:16.99215238 +0000 UTC m=+19.958261862
I0828 10:50:16.992186       1 scheduler.go:454] Total Schedule Algo cumulative time:2.047464946s for 1089
I0828 10:50:16.994009       1 scheduler.go:451] ScheduleAlgoTime 1.662061ms Start:2018-08-28 10:50:16.992342141 +0000 UTC m=+19.958451665 End:2018-08-28 10:50:16.994004243 +0000 UTC m=+19.960113726
I0828 10:50:16.994037       1 scheduler.go:454] Total Schedule Algo cumulative time:2.049127007s for 1090
I0828 10:50:16.995936       1 scheduler.go:451] ScheduleAlgoTime 1.774085ms Start:2018-08-28 10:50:16.994156493 +0000 UTC m=+19.960266027 End:2018-08-28 10:50:16.995930631 +0000 UTC m=+19.962040112
I0828 10:50:16.995958       1 scheduler.go:454] Total Schedule Algo cumulative time:2.050901092s for 1091
I0828 10:50:16.997935       1 scheduler.go:451] ScheduleAlgoTime 1.894295ms Start:2018-08-28 10:50:16.996032849 +0000 UTC m=+19.962142362 End:2018-08-28 10:50:16.997927166 +0000 UTC m=+19.964036657
I0828 10:50:16.997965       1 scheduler.go:454] Total Schedule Algo cumulative time:2.052795387s for 1092
I0828 10:50:16.999728       1 scheduler.go:451] ScheduleAlgoTime 1.666508ms Start:2018-08-28 10:50:16.998057185 +0000 UTC m=+19.964166701 End:2018-08-28 10:50:16.999723728 +0000 UTC m=+19.965833209
I0828 10:50:16.999751       1 scheduler.go:454] Total Schedule Algo cumulative time:2.054461895s for 1093
I0828 10:50:17.001709       1 scheduler.go:451] ScheduleAlgoTime 1.852099ms Start:2018-08-28 10:50:16.999850115 +0000 UTC m=+19.965959642 End:2018-08-28 10:50:17.001702259 +0000 UTC m=+19.967811741
I0828 10:50:17.001735       1 scheduler.go:454] Total Schedule Algo cumulative time:2.056313994s for 1094
I0828 10:50:17.003388       1 scheduler.go:451] ScheduleAlgoTime 1.53938ms Start:2018-08-28 10:50:17.001842825 +0000 UTC m=+19.967952361 End:2018-08-28 10:50:17.003382261 +0000 UTC m=+19.969491741
I0828 10:50:17.003411       1 scheduler.go:454] Total Schedule Algo cumulative time:2.057853374s for 1095
I0828 10:50:17.005258       1 scheduler.go:451] ScheduleAlgoTime 1.735441ms Start:2018-08-28 10:50:17.003515544 +0000 UTC m=+19.969625062 End:2018-08-28 10:50:17.005251022 +0000 UTC m=+19.971360503
I0828 10:50:17.005283       1 scheduler.go:454] Total Schedule Algo cumulative time:2.059588815s for 1096
I0828 10:50:17.007479       1 scheduler.go:451] ScheduleAlgoTime 1.989621ms Start:2018-08-28 10:50:17.005482726 +0000 UTC m=+19.971592285 End:2018-08-28 10:50:17.007472425 +0000 UTC m=+19.973581906
I0828 10:50:17.007513       1 scheduler.go:454] Total Schedule Algo cumulative time:2.061578436s for 1097
I0828 10:50:17.009182       1 scheduler.go:451] ScheduleAlgoTime 1.599502ms Start:2018-08-28 10:50:17.007577449 +0000 UTC m=+19.973686986 End:2018-08-28 10:50:17.009177004 +0000 UTC m=+19.975286488
I0828 10:50:17.009204       1 scheduler.go:454] Total Schedule Algo cumulative time:2.063177938s for 1098
I0828 10:50:17.011157       1 scheduler.go:451] ScheduleAlgoTime 1.818955ms Start:2018-08-28 10:50:17.009333652 +0000 UTC m=+19.975443181 End:2018-08-28 10:50:17.011152657 +0000 UTC m=+19.977262136
I0828 10:50:17.011180       1 scheduler.go:454] Total Schedule Algo cumulative time:2.064996893s for 1099
I0828 10:50:17.012840       1 scheduler.go:451] ScheduleAlgoTime 1.542569ms Start:2018-08-28 10:50:17.01129293 +0000 UTC m=+19.977402458 End:2018-08-28 10:50:17.012835546 +0000 UTC m=+19.978945027
I0828 10:50:17.012863       1 scheduler.go:454] Total Schedule Algo cumulative time:2.066539462s for 1100
I0828 10:50:17.014552       1 scheduler.go:451] ScheduleAlgoTime 1.557306ms Start:2018-08-28 10:50:17.012989624 +0000 UTC m=+19.979099149 End:2018-08-28 10:50:17.014546975 +0000 UTC m=+19.980656455
I0828 10:50:17.014579       1 scheduler.go:454] Total Schedule Algo cumulative time:2.068096768s for 1101
I0828 10:50:17.016706       1 scheduler.go:451] ScheduleAlgoTime 2.00137ms Start:2018-08-28 10:50:17.014697203 +0000 UTC m=+19.980806718 End:2018-08-28 10:50:17.016698606 +0000 UTC m=+19.982808088
I0828 10:50:17.016728       1 scheduler.go:454] Total Schedule Algo cumulative time:2.070098138s for 1102
I0828 10:50:17.018491       1 scheduler.go:451] ScheduleAlgoTime 1.629571ms Start:2018-08-28 10:50:17.016856035 +0000 UTC m=+19.982965577 End:2018-08-28 10:50:17.018485666 +0000 UTC m=+19.984595148
I0828 10:50:17.018515       1 scheduler.go:454] Total Schedule Algo cumulative time:2.071727709s for 1103
I0828 10:50:17.020439       1 scheduler.go:451] ScheduleAlgoTime 1.789138ms Start:2018-08-28 10:50:17.018643128 +0000 UTC m=+19.984752653 End:2018-08-28 10:50:17.020432311 +0000 UTC m=+19.986541791
I0828 10:50:17.020465       1 scheduler.go:454] Total Schedule Algo cumulative time:2.073516847s for 1104
I0828 10:50:17.022362       1 scheduler.go:451] ScheduleAlgoTime 1.702293ms Start:2018-08-28 10:50:17.020652899 +0000 UTC m=+19.986762437 End:2018-08-28 10:50:17.022355251 +0000 UTC m=+19.988464730
I0828 10:50:17.022390       1 scheduler.go:454] Total Schedule Algo cumulative time:2.07521914s for 1105
I0828 10:50:17.024055       1 scheduler.go:451] ScheduleAlgoTime 1.523767ms Start:2018-08-28 10:50:17.022515096 +0000 UTC m=+19.988635529 End:2018-08-28 10:50:17.024049818 +0000 UTC m=+19.990159296
I0828 10:50:17.024079       1 scheduler.go:454] Total Schedule Algo cumulative time:2.076742907s for 1106
I0828 10:50:17.025973       1 scheduler.go:451] ScheduleAlgoTime 1.754017ms Start:2018-08-28 10:50:17.024213797 +0000 UTC m=+19.990323377 End:2018-08-28 10:50:17.025967914 +0000 UTC m=+19.992077394
I0828 10:50:17.025995       1 scheduler.go:454] Total Schedule Algo cumulative time:2.078496924s for 1107
I0828 10:50:17.027851       1 scheduler.go:451] ScheduleAlgoTime 1.753056ms Start:2018-08-28 10:50:17.026093405 +0000 UTC m=+19.992202954 End:2018-08-28 10:50:17.027846529 +0000 UTC m=+19.993956010
I0828 10:50:17.027874       1 scheduler.go:454] Total Schedule Algo cumulative time:2.08024998s for 1108
I0828 10:50:17.029585       1 scheduler.go:451] ScheduleAlgoTime 1.559415ms Start:2018-08-28 10:50:17.028021042 +0000 UTC m=+19.994130585 End:2018-08-28 10:50:17.02958052 +0000 UTC m=+19.995690000
I0828 10:50:17.029605       1 scheduler.go:454] Total Schedule Algo cumulative time:2.081809395s for 1109
I0828 10:50:17.031682       1 scheduler.go:451] ScheduleAlgoTime 1.950864ms Start:2018-08-28 10:50:17.02972425 +0000 UTC m=+19.995833807 End:2018-08-28 10:50:17.031675186 +0000 UTC m=+19.997784671
I0828 10:50:17.031714       1 scheduler.go:454] Total Schedule Algo cumulative time:2.083760259s for 1110
I0828 10:50:17.033593       1 scheduler.go:451] ScheduleAlgoTime 1.696749ms Start:2018-08-28 10:50:17.031890767 +0000 UTC m=+19.998000322 End:2018-08-28 10:50:17.033587585 +0000 UTC m=+19.999697071
I0828 10:50:17.033616       1 scheduler.go:454] Total Schedule Algo cumulative time:2.085457008s for 1111
I0828 10:50:17.035445       1 scheduler.go:451] ScheduleAlgoTime 1.712128ms Start:2018-08-28 10:50:17.03372631 +0000 UTC m=+19.999835839 End:2018-08-28 10:50:17.035438481 +0000 UTC m=+20.001547967
I0828 10:50:17.035471       1 scheduler.go:454] Total Schedule Algo cumulative time:2.087169136s for 1112
I0828 10:50:17.037783       1 scheduler.go:451] ScheduleAlgoTime 2.211195ms Start:2018-08-28 10:50:17.03556619 +0000 UTC m=+20.001675749 End:2018-08-28 10:50:17.037777464 +0000 UTC m=+20.003886944
I0828 10:50:17.037805       1 scheduler.go:454] Total Schedule Algo cumulative time:2.089380331s for 1113
I0828 10:50:17.039854       1 scheduler.go:451] ScheduleAlgoTime 1.921402ms Start:2018-08-28 10:50:17.037926938 +0000 UTC m=+20.004036516 End:2018-08-28 10:50:17.039848437 +0000 UTC m=+20.005957918
I0828 10:50:17.039877       1 scheduler.go:454] Total Schedule Algo cumulative time:2.091301733s for 1114
I0828 10:50:17.041711       1 scheduler.go:451] ScheduleAlgoTime 1.720412ms Start:2018-08-28 10:50:17.039983882 +0000 UTC m=+20.006093414 End:2018-08-28 10:50:17.041704345 +0000 UTC m=+20.007813826
I0828 10:50:17.041736       1 scheduler.go:454] Total Schedule Algo cumulative time:2.093022145s for 1115
I0828 10:50:17.043402       1 scheduler.go:451] ScheduleAlgoTime 1.539203ms Start:2018-08-28 10:50:17.041857123 +0000 UTC m=+20.007966637 End:2018-08-28 10:50:17.043396359 +0000 UTC m=+20.009505840
I0828 10:50:17.043426       1 scheduler.go:454] Total Schedule Algo cumulative time:2.094561348s for 1116
I0828 10:50:17.045043       1 scheduler.go:451] ScheduleAlgoTime 1.504529ms Start:2018-08-28 10:50:17.043534406 +0000 UTC m=+20.009643926 End:2018-08-28 10:50:17.045038976 +0000 UTC m=+20.011148455
I0828 10:50:17.045067       1 scheduler.go:454] Total Schedule Algo cumulative time:2.096065877s for 1117
I0828 10:50:17.046835       1 scheduler.go:451] ScheduleAlgoTime 1.562494ms Start:2018-08-28 10:50:17.045266915 +0000 UTC m=+20.011376464 End:2018-08-28 10:50:17.046829474 +0000 UTC m=+20.012938958
I0828 10:50:17.046860       1 scheduler.go:454] Total Schedule Algo cumulative time:2.097628371s for 1118
I0828 10:50:17.048747       1 scheduler.go:451] ScheduleAlgoTime 1.793279ms Start:2018-08-28 10:50:17.046948432 +0000 UTC m=+20.013058001 End:2018-08-28 10:50:17.048741797 +0000 UTC m=+20.014851280
I0828 10:50:17.048766       1 scheduler.go:454] Total Schedule Algo cumulative time:2.09942165s for 1119
I0828 10:50:17.051167       1 scheduler.go:451] ScheduleAlgoTime 2.322889ms Start:2018-08-28 10:50:17.048837954 +0000 UTC m=+20.014947496 End:2018-08-28 10:50:17.051160905 +0000 UTC m=+20.017270385
I0828 10:50:17.051194       1 scheduler.go:454] Total Schedule Algo cumulative time:2.101744539s for 1120
I0828 10:50:17.052776       1 scheduler.go:451] ScheduleAlgoTime 1.463707ms Start:2018-08-28 10:50:17.051306731 +0000 UTC m=+20.017416258 End:2018-08-28 10:50:17.052770484 +0000 UTC m=+20.018879965
I0828 10:50:17.052797       1 scheduler.go:454] Total Schedule Algo cumulative time:2.103208246s for 1121
I0828 10:50:17.054615       1 scheduler.go:451] ScheduleAlgoTime 1.666839ms Start:2018-08-28 10:50:17.052942016 +0000 UTC m=+20.019051550 End:2018-08-28 10:50:17.054608908 +0000 UTC m=+20.020718389
I0828 10:50:17.054640       1 scheduler.go:454] Total Schedule Algo cumulative time:2.104875085s for 1122
I0828 10:50:17.056393       1 scheduler.go:451] ScheduleAlgoTime 1.624891ms Start:2018-08-28 10:50:17.05476239 +0000 UTC m=+20.020871927 End:2018-08-28 10:50:17.056387339 +0000 UTC m=+20.022496818
I0828 10:50:17.056425       1 scheduler.go:454] Total Schedule Algo cumulative time:2.106499976s for 1123
I0828 10:50:17.058456       1 scheduler.go:451] ScheduleAlgoTime 1.825709ms Start:2018-08-28 10:50:17.056626491 +0000 UTC m=+20.022736049 End:2018-08-28 10:50:17.05845228 +0000 UTC m=+20.024561758
I0828 10:50:17.058487       1 scheduler.go:454] Total Schedule Algo cumulative time:2.108325685s for 1124
I0828 10:50:17.060183       1 scheduler.go:451] ScheduleAlgoTime 1.593215ms Start:2018-08-28 10:50:17.058583088 +0000 UTC m=+20.024692613 End:2018-08-28 10:50:17.060176345 +0000 UTC m=+20.026285828
I0828 10:50:17.060208       1 scheduler.go:454] Total Schedule Algo cumulative time:2.1099189s for 1125
I0828 10:50:17.062462       1 scheduler.go:451] ScheduleAlgoTime 2.157413ms Start:2018-08-28 10:50:17.060298756 +0000 UTC m=+20.026408317 End:2018-08-28 10:50:17.062456227 +0000 UTC m=+20.028565730
I0828 10:50:17.062489       1 scheduler.go:454] Total Schedule Algo cumulative time:2.112076313s for 1126
I0828 10:50:17.064164       1 scheduler.go:451] ScheduleAlgoTime 1.516282ms Start:2018-08-28 10:50:17.062640444 +0000 UTC m=+20.028749959 End:2018-08-28 10:50:17.064156659 +0000 UTC m=+20.030266241
I0828 10:50:17.064192       1 scheduler.go:454] Total Schedule Algo cumulative time:2.113592595s for 1127
I0828 10:50:17.066206       1 scheduler.go:451] ScheduleAlgoTime 1.91458ms Start:2018-08-28 10:50:17.064285503 +0000 UTC m=+20.030395040 End:2018-08-28 10:50:17.06620014 +0000 UTC m=+20.032309620
I0828 10:50:17.066228       1 scheduler.go:454] Total Schedule Algo cumulative time:2.115507175s for 1128
I0828 10:50:17.068385       1 scheduler.go:451] ScheduleAlgoTime 2.041257ms Start:2018-08-28 10:50:17.066335661 +0000 UTC m=+20.032445231 End:2018-08-28 10:50:17.068376996 +0000 UTC m=+20.034486488
I0828 10:50:17.068414       1 scheduler.go:454] Total Schedule Algo cumulative time:2.117548432s for 1129
I0828 10:50:17.070270       1 scheduler.go:451] ScheduleAlgoTime 1.68889ms Start:2018-08-28 10:50:17.068575693 +0000 UTC m=+20.034685234 End:2018-08-28 10:50:17.070264642 +0000 UTC m=+20.036374124
I0828 10:50:17.070293       1 scheduler.go:454] Total Schedule Algo cumulative time:2.119237322s for 1130
I0828 10:50:17.072201       1 scheduler.go:451] ScheduleAlgoTime 1.766023ms Start:2018-08-28 10:50:17.070429347 +0000 UTC m=+20.036538889 End:2018-08-28 10:50:17.072195432 +0000 UTC m=+20.038304912
I0828 10:50:17.072226       1 scheduler.go:454] Total Schedule Algo cumulative time:2.121003345s for 1131
I0828 10:50:17.074376       1 scheduler.go:451] ScheduleAlgoTime 1.984063ms Start:2018-08-28 10:50:17.072384608 +0000 UTC m=+20.038494123 End:2018-08-28 10:50:17.074368631 +0000 UTC m=+20.040478186
I0828 10:50:17.074411       1 scheduler.go:454] Total Schedule Algo cumulative time:2.122987408s for 1132
I0828 10:50:17.076087       1 scheduler.go:451] ScheduleAlgoTime 1.556994ms Start:2018-08-28 10:50:17.074525251 +0000 UTC m=+20.040634787 End:2018-08-28 10:50:17.0760823 +0000 UTC m=+20.042191781
I0828 10:50:17.076109       1 scheduler.go:454] Total Schedule Algo cumulative time:2.124544402s for 1133
I0828 10:50:17.077911       1 scheduler.go:451] ScheduleAlgoTime 1.697475ms Start:2018-08-28 10:50:17.07620848 +0000 UTC m=+20.042318027 End:2018-08-28 10:50:17.077906019 +0000 UTC m=+20.044015502
I0828 10:50:17.077934       1 scheduler.go:454] Total Schedule Algo cumulative time:2.126241877s for 1134
I0828 10:50:17.079937       1 scheduler.go:451] ScheduleAlgoTime 1.929954ms Start:2018-08-28 10:50:17.078001744 +0000 UTC m=+20.044111284 End:2018-08-28 10:50:17.079931756 +0000 UTC m=+20.046041238
I0828 10:50:17.080026       1 scheduler.go:454] Total Schedule Algo cumulative time:2.128171831s for 1135
I0828 10:50:17.081817       1 scheduler.go:451] ScheduleAlgoTime 1.63908ms Start:2018-08-28 10:50:17.080173662 +0000 UTC m=+20.046283143 End:2018-08-28 10:50:17.081812742 +0000 UTC m=+20.047922223
I0828 10:50:17.081837       1 scheduler.go:454] Total Schedule Algo cumulative time:2.129810911s for 1136
I0828 10:50:17.083512       1 scheduler.go:451] ScheduleAlgoTime 1.568237ms Start:2018-08-28 10:50:17.081937823 +0000 UTC m=+20.048047333 End:2018-08-28 10:50:17.083506072 +0000 UTC m=+20.049615570
I0828 10:50:17.083539       1 scheduler.go:454] Total Schedule Algo cumulative time:2.131379148s for 1137
I0828 10:50:17.085416       1 scheduler.go:451] ScheduleAlgoTime 1.727934ms Start:2018-08-28 10:50:17.083681951 +0000 UTC m=+20.049791488 End:2018-08-28 10:50:17.085409938 +0000 UTC m=+20.051519422
I0828 10:50:17.085435       1 scheduler.go:454] Total Schedule Algo cumulative time:2.133107082s for 1138
I0828 10:50:17.087161       1 scheduler.go:451] ScheduleAlgoTime 1.612295ms Start:2018-08-28 10:50:17.085543172 +0000 UTC m=+20.051652670 End:2018-08-28 10:50:17.087155482 +0000 UTC m=+20.053264965
I0828 10:50:17.087184       1 scheduler.go:454] Total Schedule Algo cumulative time:2.134719377s for 1139
I0828 10:50:17.088964       1 scheduler.go:451] ScheduleAlgoTime 1.649288ms Start:2018-08-28 10:50:17.08730984 +0000 UTC m=+20.053419374 End:2018-08-28 10:50:17.088959181 +0000 UTC m=+20.055068662
I0828 10:50:17.088985       1 scheduler.go:454] Total Schedule Algo cumulative time:2.136368665s for 1140
I0828 10:50:17.090680       1 scheduler.go:451] ScheduleAlgoTime 1.606014ms Start:2018-08-28 10:50:17.089068005 +0000 UTC m=+20.055177538 End:2018-08-28 10:50:17.09067407 +0000 UTC m=+20.056783552
I0828 10:50:17.090705       1 scheduler.go:454] Total Schedule Algo cumulative time:2.137974679s for 1141
I0828 10:50:17.093441       1 scheduler.go:451] ScheduleAlgoTime 2.332307ms Start:2018-08-28 10:50:17.091103995 +0000 UTC m=+20.057213535 End:2018-08-28 10:50:17.093436362 +0000 UTC m=+20.059545842
I0828 10:50:17.093464       1 scheduler.go:454] Total Schedule Algo cumulative time:2.140306986s for 1142
I0828 10:50:17.095263       1 scheduler.go:451] ScheduleAlgoTime 1.674262ms Start:2018-08-28 10:50:17.093581292 +0000 UTC m=+20.059690857 End:2018-08-28 10:50:17.095255402 +0000 UTC m=+20.061365119
I0828 10:50:17.095289       1 scheduler.go:454] Total Schedule Algo cumulative time:2.141981248s for 1143
I0828 10:50:17.097157       1 scheduler.go:451] ScheduleAlgoTime 1.762986ms Start:2018-08-28 10:50:17.09538887 +0000 UTC m=+20.061498394 End:2018-08-28 10:50:17.097151899 +0000 UTC m=+20.063261380
I0828 10:50:17.097177       1 scheduler.go:454] Total Schedule Algo cumulative time:2.143744234s for 1144
I0828 10:50:17.098959       1 scheduler.go:451] ScheduleAlgoTime 1.639412ms Start:2018-08-28 10:50:17.097312927 +0000 UTC m=+20.063422437 End:2018-08-28 10:50:17.098952369 +0000 UTC m=+20.065061849
I0828 10:50:17.098983       1 scheduler.go:454] Total Schedule Algo cumulative time:2.145383646s for 1145
I0828 10:50:17.101181       1 scheduler.go:451] ScheduleAlgoTime 2.089223ms Start:2018-08-28 10:50:17.099084915 +0000 UTC m=+20.065194411 End:2018-08-28 10:50:17.101174153 +0000 UTC m=+20.067283634
I0828 10:50:17.101203       1 scheduler.go:454] Total Schedule Algo cumulative time:2.147472869s for 1146
I0828 10:50:17.103118       1 scheduler.go:451] ScheduleAlgoTime 1.72988ms Start:2018-08-28 10:50:17.101383582 +0000 UTC m=+20.067493101 End:2018-08-28 10:50:17.103113502 +0000 UTC m=+20.069222981
I0828 10:50:17.103150       1 scheduler.go:454] Total Schedule Algo cumulative time:2.149202749s for 1147
I0828 10:50:17.105301       1 scheduler.go:451] ScheduleAlgoTime 1.994086ms Start:2018-08-28 10:50:17.103302953 +0000 UTC m=+20.069412487 End:2018-08-28 10:50:17.105297088 +0000 UTC m=+20.071406573
I0828 10:50:17.105326       1 scheduler.go:454] Total Schedule Algo cumulative time:2.151196835s for 1148
I0828 10:50:17.107188       1 scheduler.go:451] ScheduleAlgoTime 1.72439ms Start:2018-08-28 10:50:17.105459179 +0000 UTC m=+20.071568683 End:2018-08-28 10:50:17.107183592 +0000 UTC m=+20.073293073
I0828 10:50:17.107210       1 scheduler.go:454] Total Schedule Algo cumulative time:2.152921225s for 1149
I0828 10:50:17.114570       1 scheduler.go:451] ScheduleAlgoTime 7.262692ms Start:2018-08-28 10:50:17.107300257 +0000 UTC m=+20.073409793 End:2018-08-28 10:50:17.114563003 +0000 UTC m=+20.080672485
I0828 10:50:17.114622       1 scheduler.go:454] Total Schedule Algo cumulative time:2.160183917s for 1150
I0828 10:50:17.118585       1 scheduler.go:451] ScheduleAlgoTime 3.794272ms Start:2018-08-28 10:50:17.114776805 +0000 UTC m=+20.080886341 End:2018-08-28 10:50:17.118571036 +0000 UTC m=+20.084680613
I0828 10:50:17.118688       1 scheduler.go:454] Total Schedule Algo cumulative time:2.163978189s for 1151
I0828 10:50:17.121032       1 scheduler.go:451] ScheduleAlgoTime 2.240811ms Start:2018-08-28 10:50:17.118786622 +0000 UTC m=+20.084896140 End:2018-08-28 10:50:17.12102747 +0000 UTC m=+20.087136951
I0828 10:50:17.121063       1 scheduler.go:454] Total Schedule Algo cumulative time:2.166219s for 1152
I0828 10:50:17.123188       1 scheduler.go:451] ScheduleAlgoTime 1.99877ms Start:2018-08-28 10:50:17.121183508 +0000 UTC m=+20.087293021 End:2018-08-28 10:50:17.123182307 +0000 UTC m=+20.089291791
I0828 10:50:17.123216       1 scheduler.go:454] Total Schedule Algo cumulative time:2.16821777s for 1153
I0828 10:50:17.124992       1 scheduler.go:451] ScheduleAlgoTime 1.616536ms Start:2018-08-28 10:50:17.12336727 +0000 UTC m=+20.089476832 End:2018-08-28 10:50:17.124983807 +0000 UTC m=+20.091093368
I0828 10:50:17.125023       1 scheduler.go:454] Total Schedule Algo cumulative time:2.169834306s for 1154
I0828 10:50:17.126821       1 scheduler.go:451] ScheduleAlgoTime 1.645535ms Start:2018-08-28 10:50:17.125169051 +0000 UTC m=+20.091278620 End:2018-08-28 10:50:17.126814671 +0000 UTC m=+20.092924155
I0828 10:50:17.126846       1 scheduler.go:454] Total Schedule Algo cumulative time:2.171479841s for 1155
I0828 10:50:17.128651       1 scheduler.go:451] ScheduleAlgoTime 1.665771ms Start:2018-08-28 10:50:17.126979534 +0000 UTC m=+20.093089096 End:2018-08-28 10:50:17.128645387 +0000 UTC m=+20.094754867
I0828 10:50:17.128674       1 scheduler.go:454] Total Schedule Algo cumulative time:2.173145612s for 1156
I0828 10:50:17.130497       1 scheduler.go:451] ScheduleAlgoTime 1.6435ms Start:2018-08-28 10:50:17.12884843 +0000 UTC m=+20.094957969 End:2018-08-28 10:50:17.130491988 +0000 UTC m=+20.096601469
I0828 10:50:17.130524       1 scheduler.go:454] Total Schedule Algo cumulative time:2.174789112s for 1157
I0828 10:50:17.132744       1 scheduler.go:451] ScheduleAlgoTime 2.089745ms Start:2018-08-28 10:50:17.130648957 +0000 UTC m=+20.096758478 End:2018-08-28 10:50:17.132738743 +0000 UTC m=+20.098848223
I0828 10:50:17.132768       1 scheduler.go:454] Total Schedule Algo cumulative time:2.176878857s for 1158
I0828 10:50:17.134544       1 scheduler.go:451] ScheduleAlgoTime 1.645027ms Start:2018-08-28 10:50:17.132892888 +0000 UTC m=+20.099002421 End:2018-08-28 10:50:17.134537968 +0000 UTC m=+20.100647448
I0828 10:50:17.134573       1 scheduler.go:454] Total Schedule Algo cumulative time:2.178523884s for 1159
I0828 10:50:17.136407       1 scheduler.go:451] ScheduleAlgoTime 1.687566ms Start:2018-08-28 10:50:17.134714292 +0000 UTC m=+20.100823838 End:2018-08-28 10:50:17.136401925 +0000 UTC m=+20.102511404
I0828 10:50:17.136427       1 scheduler.go:454] Total Schedule Algo cumulative time:2.18021145s for 1160
I0828 10:50:17.138256       1 scheduler.go:451] ScheduleAlgoTime 1.706666ms Start:2018-08-28 10:50:17.136539335 +0000 UTC m=+20.102648843 End:2018-08-28 10:50:17.138246015 +0000 UTC m=+20.104355509
I0828 10:50:17.138287       1 scheduler.go:454] Total Schedule Algo cumulative time:2.181918116s for 1161
I0828 10:50:17.140138       1 scheduler.go:451] ScheduleAlgoTime 1.686829ms Start:2018-08-28 10:50:17.138445778 +0000 UTC m=+20.104555325 End:2018-08-28 10:50:17.140132672 +0000 UTC m=+20.106242154
I0828 10:50:17.140167       1 scheduler.go:454] Total Schedule Algo cumulative time:2.183604945s for 1162
I0828 10:50:17.142083       1 scheduler.go:451] ScheduleAlgoTime 1.755273ms Start:2018-08-28 10:50:17.140320978 +0000 UTC m=+20.106430477 End:2018-08-28 10:50:17.142076238 +0000 UTC m=+20.108185750
I0828 10:50:17.142111       1 scheduler.go:454] Total Schedule Algo cumulative time:2.185360218s for 1163
I0828 10:50:17.143868       1 scheduler.go:451] ScheduleAlgoTime 1.599588ms Start:2018-08-28 10:50:17.142263524 +0000 UTC m=+20.108373053 End:2018-08-28 10:50:17.14386316 +0000 UTC m=+20.109972641
I0828 10:50:17.143890       1 scheduler.go:454] Total Schedule Algo cumulative time:2.186959806s for 1164
I0828 10:50:17.145621       1 scheduler.go:451] ScheduleAlgoTime 1.609524ms Start:2018-08-28 10:50:17.144004057 +0000 UTC m=+20.110113567 End:2018-08-28 10:50:17.145613609 +0000 UTC m=+20.111723091
I0828 10:50:17.145649       1 scheduler.go:454] Total Schedule Algo cumulative time:2.18856933s for 1165
I0828 10:50:17.147454       1 scheduler.go:451] ScheduleAlgoTime 1.68308ms Start:2018-08-28 10:50:17.145767125 +0000 UTC m=+20.111876694 End:2018-08-28 10:50:17.147450293 +0000 UTC m=+20.113559774
I0828 10:50:17.147479       1 scheduler.go:454] Total Schedule Algo cumulative time:2.19025241s for 1166
I0828 10:50:17.148985       1 scheduler.go:451] ScheduleAlgoTime 1.380281ms Start:2018-08-28 10:50:17.147600629 +0000 UTC m=+20.113710168 End:2018-08-28 10:50:17.14898097 +0000 UTC m=+20.115090449
I0828 10:50:17.149006       1 scheduler.go:454] Total Schedule Algo cumulative time:2.191632691s for 1167
I0828 10:50:17.150921       1 scheduler.go:451] ScheduleAlgoTime 1.824234ms Start:2018-08-28 10:50:17.14908987 +0000 UTC m=+20.115199389 End:2018-08-28 10:50:17.150914121 +0000 UTC m=+20.117023623
I0828 10:50:17.150948       1 scheduler.go:454] Total Schedule Algo cumulative time:2.193456925s for 1168
I0828 10:50:17.152836       1 scheduler.go:451] ScheduleAlgoTime 1.740463ms Start:2018-08-28 10:50:17.151090452 +0000 UTC m=+20.117199955 End:2018-08-28 10:50:17.152830938 +0000 UTC m=+20.118940418
I0828 10:50:17.152859       1 scheduler.go:454] Total Schedule Algo cumulative time:2.195197388s for 1169
I0828 10:50:17.154477       1 scheduler.go:451] ScheduleAlgoTime 1.522915ms Start:2018-08-28 10:50:17.152948684 +0000 UTC m=+20.119058225 End:2018-08-28 10:50:17.15447166 +0000 UTC m=+20.120581140
I0828 10:50:17.154502       1 scheduler.go:454] Total Schedule Algo cumulative time:2.196720303s for 1170
I0828 10:50:17.156263       1 scheduler.go:451] ScheduleAlgoTime 1.629818ms Start:2018-08-28 10:50:17.15462714 +0000 UTC m=+20.120736620 End:2018-08-28 10:50:17.156256957 +0000 UTC m=+20.122366438
I0828 10:50:17.156289       1 scheduler.go:454] Total Schedule Algo cumulative time:2.198350121s for 1171
I0828 10:50:17.157903       1 scheduler.go:451] ScheduleAlgoTime 1.537182ms Start:2018-08-28 10:50:17.156360282 +0000 UTC m=+20.122469846 End:2018-08-28 10:50:17.157897546 +0000 UTC m=+20.124007028
I0828 10:50:17.157925       1 scheduler.go:454] Total Schedule Algo cumulative time:2.199887303s for 1172
I0828 10:50:17.159451       1 scheduler.go:451] ScheduleAlgoTime 1.429371ms Start:2018-08-28 10:50:17.15801372 +0000 UTC m=+20.124123291 End:2018-08-28 10:50:17.159443153 +0000 UTC m=+20.125552662
I0828 10:50:17.159507       1 scheduler.go:454] Total Schedule Algo cumulative time:2.201316674s for 1173
I0828 10:50:17.161589       1 scheduler.go:451] ScheduleAlgoTime 1.989242ms Start:2018-08-28 10:50:17.1595953 +0000 UTC m=+20.125704836 End:2018-08-28 10:50:17.161584596 +0000 UTC m=+20.127694078
I0828 10:50:17.161612       1 scheduler.go:454] Total Schedule Algo cumulative time:2.203305916s for 1174
I0828 10:50:17.163093       1 scheduler.go:451] ScheduleAlgoTime 1.402846ms Start:2018-08-28 10:50:17.161685636 +0000 UTC m=+20.127795176 End:2018-08-28 10:50:17.16308854 +0000 UTC m=+20.129198022
I0828 10:50:17.163113       1 scheduler.go:454] Total Schedule Algo cumulative time:2.204708762s for 1175
I0828 10:50:17.164572       1 scheduler.go:451] ScheduleAlgoTime 1.352362ms Start:2018-08-28 10:50:17.16321291 +0000 UTC m=+20.129322489 End:2018-08-28 10:50:17.164565362 +0000 UTC m=+20.130674851
I0828 10:50:17.164599       1 scheduler.go:454] Total Schedule Algo cumulative time:2.206061124s for 1176
I0828 10:50:17.166188       1 scheduler.go:451] ScheduleAlgoTime 1.493612ms Start:2018-08-28 10:50:17.164689658 +0000 UTC m=+20.130799172 End:2018-08-28 10:50:17.166183304 +0000 UTC m=+20.132292784
I0828 10:50:17.166210       1 scheduler.go:454] Total Schedule Algo cumulative time:2.207554736s for 1177
I0828 10:50:17.167851       1 scheduler.go:451] ScheduleAlgoTime 1.559356ms Start:2018-08-28 10:50:17.16628416 +0000 UTC m=+20.132393722 End:2018-08-28 10:50:17.16784359 +0000 UTC m=+20.133953078
I0828 10:50:17.167886       1 scheduler.go:454] Total Schedule Algo cumulative time:2.209114092s for 1178
I0828 10:50:17.169465       1 scheduler.go:451] ScheduleAlgoTime 1.452246ms Start:2018-08-28 10:50:17.168007332 +0000 UTC m=+20.134116880 End:2018-08-28 10:50:17.169459643 +0000 UTC m=+20.135569126
I0828 10:50:17.169487       1 scheduler.go:454] Total Schedule Algo cumulative time:2.210566338s for 1179
I0828 10:50:17.171196       1 scheduler.go:451] ScheduleAlgoTime 1.610715ms Start:2018-08-28 10:50:17.169580375 +0000 UTC m=+20.135689899 End:2018-08-28 10:50:17.171191135 +0000 UTC m=+20.137300614
I0828 10:50:17.171218       1 scheduler.go:454] Total Schedule Algo cumulative time:2.212177053s for 1180
I0828 10:50:17.172676       1 scheduler.go:451] ScheduleAlgoTime 1.359653ms Start:2018-08-28 10:50:17.171309444 +0000 UTC m=+20.137418970 End:2018-08-28 10:50:17.172669137 +0000 UTC m=+20.138778623
I0828 10:50:17.172707       1 scheduler.go:454] Total Schedule Algo cumulative time:2.213536706s for 1181
I0828 10:50:17.174317       1 scheduler.go:451] ScheduleAlgoTime 1.510415ms Start:2018-08-28 10:50:17.172801847 +0000 UTC m=+20.138911407 End:2018-08-28 10:50:17.174312343 +0000 UTC m=+20.140421822
I0828 10:50:17.175090       1 scheduler.go:454] Total Schedule Algo cumulative time:2.215047121s for 1182
I0828 10:50:17.176900       1 scheduler.go:451] ScheduleAlgoTime 1.665239ms Start:2018-08-28 10:50:17.175230553 +0000 UTC m=+20.141340069 End:2018-08-28 10:50:17.176895824 +0000 UTC m=+20.143005308
I0828 10:50:17.176920       1 scheduler.go:454] Total Schedule Algo cumulative time:2.21671236s for 1183
I0828 10:50:17.179028       1 scheduler.go:451] ScheduleAlgoTime 2.025265ms Start:2018-08-28 10:50:17.176995204 +0000 UTC m=+20.143104706 End:2018-08-28 10:50:17.179020487 +0000 UTC m=+20.145129971
I0828 10:50:17.179055       1 scheduler.go:454] Total Schedule Algo cumulative time:2.218737625s for 1184
I0828 10:50:17.181798       1 scheduler.go:451] ScheduleAlgoTime 2.576101ms Start:2018-08-28 10:50:17.179215076 +0000 UTC m=+20.145324589 End:2018-08-28 10:50:17.181791202 +0000 UTC m=+20.147900690
I0828 10:50:17.181823       1 scheduler.go:454] Total Schedule Algo cumulative time:2.221313726s for 1185
I0828 10:50:17.183977       1 scheduler.go:451] ScheduleAlgoTime 2.04525ms Start:2018-08-28 10:50:17.181926495 +0000 UTC m=+20.148036070 End:2018-08-28 10:50:17.18397184 +0000 UTC m=+20.150081320
I0828 10:50:17.184011       1 scheduler.go:454] Total Schedule Algo cumulative time:2.223358976s for 1186
I0828 10:50:17.185584       1 scheduler.go:451] ScheduleAlgoTime 1.485328ms Start:2018-08-28 10:50:17.184093849 +0000 UTC m=+20.150203387 End:2018-08-28 10:50:17.185579233 +0000 UTC m=+20.151688715
I0828 10:50:17.185608       1 scheduler.go:454] Total Schedule Algo cumulative time:2.224844304s for 1187
I0828 10:50:17.187458       1 scheduler.go:451] ScheduleAlgoTime 1.740565ms Start:2018-08-28 10:50:17.185713036 +0000 UTC m=+20.151822578 End:2018-08-28 10:50:17.187453659 +0000 UTC m=+20.153563143
I0828 10:50:17.187479       1 scheduler.go:454] Total Schedule Algo cumulative time:2.226584869s for 1188
I0828 10:50:17.188852       1 scheduler.go:451] ScheduleAlgoTime 1.275633ms Start:2018-08-28 10:50:17.187572114 +0000 UTC m=+20.153681656 End:2018-08-28 10:50:17.188847806 +0000 UTC m=+20.154957289
I0828 10:50:17.188872       1 scheduler.go:454] Total Schedule Algo cumulative time:2.227860502s for 1189
I0828 10:50:17.190182       1 scheduler.go:451] ScheduleAlgoTime 1.26136ms Start:2018-08-28 10:50:17.188916514 +0000 UTC m=+20.155026064 End:2018-08-28 10:50:17.190177944 +0000 UTC m=+20.156287424
I0828 10:50:17.190208       1 scheduler.go:454] Total Schedule Algo cumulative time:2.229121862s for 1190
I0828 10:50:17.191595       1 scheduler.go:451] ScheduleAlgoTime 1.304381ms Start:2018-08-28 10:50:17.190286 +0000 UTC m=+20.156395517 End:2018-08-28 10:50:17.191590416 +0000 UTC m=+20.157699898
I0828 10:50:17.191615       1 scheduler.go:454] Total Schedule Algo cumulative time:2.230426243s for 1191
I0828 10:50:17.193076       1 scheduler.go:451] ScheduleAlgoTime 1.365019ms Start:2018-08-28 10:50:17.191706102 +0000 UTC m=+20.157815642 End:2018-08-28 10:50:17.193071175 +0000 UTC m=+20.159180661
I0828 10:50:17.193110       1 scheduler.go:454] Total Schedule Algo cumulative time:2.231791262s for 1192
I0828 10:50:17.194481       1 scheduler.go:451] ScheduleAlgoTime 1.283349ms Start:2018-08-28 10:50:17.193192444 +0000 UTC m=+20.159301969 End:2018-08-28 10:50:17.194475838 +0000 UTC m=+20.160585318
I0828 10:50:17.194500       1 scheduler.go:454] Total Schedule Algo cumulative time:2.233074611s for 1193
I0828 10:50:17.196044       1 scheduler.go:451] ScheduleAlgoTime 1.469758ms Start:2018-08-28 10:50:17.194569657 +0000 UTC m=+20.160679189 End:2018-08-28 10:50:17.196039464 +0000 UTC m=+20.162148947
I0828 10:50:17.196072       1 scheduler.go:454] Total Schedule Algo cumulative time:2.234544369s for 1194
I0828 10:50:17.197682       1 scheduler.go:451] ScheduleAlgoTime 1.516573ms Start:2018-08-28 10:50:17.196160835 +0000 UTC m=+20.162270373 End:2018-08-28 10:50:17.197677464 +0000 UTC m=+20.163786946
I0828 10:50:17.197782       1 scheduler.go:454] Total Schedule Algo cumulative time:2.236060942s for 1195
I0828 10:50:17.199729       1 scheduler.go:451] ScheduleAlgoTime 1.851932ms Start:2018-08-28 10:50:17.197869269 +0000 UTC m=+20.163978853 End:2018-08-28 10:50:17.199721301 +0000 UTC m=+20.165830785
I0828 10:50:17.199754       1 scheduler.go:454] Total Schedule Algo cumulative time:2.237912874s for 1196
I0828 10:50:17.201893       1 scheduler.go:451] ScheduleAlgoTime 2.068909ms Start:2018-08-28 10:50:17.19981614 +0000 UTC m=+20.165925656 End:2018-08-28 10:50:17.201885075 +0000 UTC m=+20.167994565
I0828 10:50:17.201922       1 scheduler.go:454] Total Schedule Algo cumulative time:2.239981783s for 1197
I0828 10:50:17.203534       1 scheduler.go:451] ScheduleAlgoTime 1.49826ms Start:2018-08-28 10:50:17.202030879 +0000 UTC m=+20.168140409 End:2018-08-28 10:50:17.203529187 +0000 UTC m=+20.169638669
I0828 10:50:17.203554       1 scheduler.go:454] Total Schedule Algo cumulative time:2.241480043s for 1198
I0828 10:50:17.205021       1 scheduler.go:451] ScheduleAlgoTime 1.363432ms Start:2018-08-28 10:50:17.203650377 +0000 UTC m=+20.169759877 End:2018-08-28 10:50:17.205013803 +0000 UTC m=+20.171123309
I0828 10:50:17.205046       1 scheduler.go:454] Total Schedule Algo cumulative time:2.242843475s for 1199
I0828 10:50:17.206454       1 scheduler.go:451] ScheduleAlgoTime 1.310373ms Start:2018-08-28 10:50:17.205139002 +0000 UTC m=+20.171248513 End:2018-08-28 10:50:17.206449406 +0000 UTC m=+20.172558886
I0828 10:50:17.206476       1 scheduler.go:454] Total Schedule Algo cumulative time:2.244153848s for 1200
I0828 10:50:17.208071       1 scheduler.go:451] ScheduleAlgoTime 1.48855ms Start:2018-08-28 10:50:17.206575207 +0000 UTC m=+20.172684779 End:2018-08-28 10:50:17.208063838 +0000 UTC m=+20.174173329
I0828 10:50:17.208096       1 scheduler.go:454] Total Schedule Algo cumulative time:2.245642398s for 1201
I0828 10:50:17.210047       1 scheduler.go:451] ScheduleAlgoTime 1.867088ms Start:2018-08-28 10:50:17.208172806 +0000 UTC m=+20.174282343 End:2018-08-28 10:50:17.210039942 +0000 UTC m=+20.176149431
I0828 10:50:17.210072       1 scheduler.go:454] Total Schedule Algo cumulative time:2.247509486s for 1202
I0828 10:50:17.211552       1 scheduler.go:451] ScheduleAlgoTime 1.360352ms Start:2018-08-28 10:50:17.210186865 +0000 UTC m=+20.176296420 End:2018-08-28 10:50:17.211547292 +0000 UTC m=+20.177656772
I0828 10:50:17.211571       1 scheduler.go:454] Total Schedule Algo cumulative time:2.248869838s for 1203
I0828 10:50:17.213008       1 scheduler.go:451] ScheduleAlgoTime 1.355726ms Start:2018-08-28 10:50:17.211646023 +0000 UTC m=+20.177755549 End:2018-08-28 10:50:17.213001779 +0000 UTC m=+20.179111275
I0828 10:50:17.213042       1 scheduler.go:454] Total Schedule Algo cumulative time:2.250225564s for 1204
I0828 10:50:17.214491       1 scheduler.go:451] ScheduleAlgoTime 1.330479ms Start:2018-08-28 10:50:17.213156797 +0000 UTC m=+20.179266353 End:2018-08-28 10:50:17.214487351 +0000 UTC m=+20.180596832
I0828 10:50:17.214519       1 scheduler.go:454] Total Schedule Algo cumulative time:2.251556043s for 1205
I0828 10:50:17.216634       1 scheduler.go:451] ScheduleAlgoTime 2.031406ms Start:2018-08-28 10:50:17.214596577 +0000 UTC m=+20.180706082 End:2018-08-28 10:50:17.216628 +0000 UTC m=+20.182737488
I0828 10:50:17.216658       1 scheduler.go:454] Total Schedule Algo cumulative time:2.253587449s for 1206
I0828 10:50:17.218237       1 scheduler.go:451] ScheduleAlgoTime 1.510163ms Start:2018-08-28 10:50:17.216721761 +0000 UTC m=+20.182831275 End:2018-08-28 10:50:17.218231954 +0000 UTC m=+20.184341438
I0828 10:50:17.218258       1 scheduler.go:454] Total Schedule Algo cumulative time:2.255097612s for 1207
I0828 10:50:17.220088       1 scheduler.go:451] ScheduleAlgoTime 1.767796ms Start:2018-08-28 10:50:17.218315047 +0000 UTC m=+20.184424531 End:2018-08-28 10:50:17.220082845 +0000 UTC m=+20.186192327
I0828 10:50:17.220106       1 scheduler.go:454] Total Schedule Algo cumulative time:2.256865408s for 1208
I0828 10:50:17.221672       1 scheduler.go:451] ScheduleAlgoTime 1.494317ms Start:2018-08-28 10:50:17.220173621 +0000 UTC m=+20.186283178 End:2018-08-28 10:50:17.221668012 +0000 UTC m=+20.187777495
I0828 10:50:17.221690       1 scheduler.go:454] Total Schedule Algo cumulative time:2.258359725s for 1209
I0828 10:50:17.223197       1 scheduler.go:451] ScheduleAlgoTime 1.418408ms Start:2018-08-28 10:50:17.221771695 +0000 UTC m=+20.187881268 End:2018-08-28 10:50:17.223190189 +0000 UTC m=+20.189299676
I0828 10:50:17.223222       1 scheduler.go:454] Total Schedule Algo cumulative time:2.259778133s for 1210
I0828 10:50:17.224688       1 scheduler.go:451] ScheduleAlgoTime 1.371286ms Start:2018-08-28 10:50:17.223312548 +0000 UTC m=+20.189422066 End:2018-08-28 10:50:17.224683868 +0000 UTC m=+20.190793352
I0828 10:50:17.224708       1 scheduler.go:454] Total Schedule Algo cumulative time:2.261149419s for 1211
I0828 10:50:17.226109       1 scheduler.go:451] ScheduleAlgoTime 1.316644ms Start:2018-08-28 10:50:17.224787949 +0000 UTC m=+20.190897463 End:2018-08-28 10:50:17.226104624 +0000 UTC m=+20.192214107
I0828 10:50:17.226128       1 scheduler.go:454] Total Schedule Algo cumulative time:2.262466063s for 1212
I0828 10:50:17.227554       1 scheduler.go:451] ScheduleAlgoTime 1.346063ms Start:2018-08-28 10:50:17.226190674 +0000 UTC m=+20.192300210 End:2018-08-28 10:50:17.227536792 +0000 UTC m=+20.193646273
I0828 10:50:17.227574       1 scheduler.go:454] Total Schedule Algo cumulative time:2.263812126s for 1213
I0828 10:50:17.229971       1 scheduler.go:451] ScheduleAlgoTime 2.299193ms Start:2018-08-28 10:50:17.22766635 +0000 UTC m=+20.193775893 End:2018-08-28 10:50:17.229965607 +0000 UTC m=+20.196075086
I0828 10:50:17.229990       1 scheduler.go:454] Total Schedule Algo cumulative time:2.266111319s for 1214
I0828 10:50:17.231470       1 scheduler.go:451] ScheduleAlgoTime 1.377029ms Start:2018-08-28 10:50:17.230087872 +0000 UTC m=+20.196197397 End:2018-08-28 10:50:17.231464942 +0000 UTC m=+20.197574426
I0828 10:50:17.231487       1 scheduler.go:454] Total Schedule Algo cumulative time:2.267488348s for 1215
I0828 10:50:17.232924       1 scheduler.go:451] ScheduleAlgoTime 1.352796ms Start:2018-08-28 10:50:17.231566284 +0000 UTC m=+20.197675846 End:2018-08-28 10:50:17.23291916 +0000 UTC m=+20.199028642
I0828 10:50:17.232943       1 scheduler.go:454] Total Schedule Algo cumulative time:2.268841144s for 1216
I0828 10:50:17.234666       1 scheduler.go:451] ScheduleAlgoTime 1.644255ms Start:2018-08-28 10:50:17.233015533 +0000 UTC m=+20.199125059 End:2018-08-28 10:50:17.23465983 +0000 UTC m=+20.200769314
I0828 10:50:17.234691       1 scheduler.go:454] Total Schedule Algo cumulative time:2.270485399s for 1217
I0828 10:50:17.236688       1 scheduler.go:451] ScheduleAlgoTime 1.901638ms Start:2018-08-28 10:50:17.234779041 +0000 UTC m=+20.200888577 End:2018-08-28 10:50:17.236680701 +0000 UTC m=+20.202790215
I0828 10:50:17.236713       1 scheduler.go:454] Total Schedule Algo cumulative time:2.272387037s for 1218
I0828 10:50:17.238201       1 scheduler.go:451] ScheduleAlgoTime 1.391158ms Start:2018-08-28 10:50:17.236805199 +0000 UTC m=+20.202914740 End:2018-08-28 10:50:17.238196418 +0000 UTC m=+20.204305898
I0828 10:50:17.238222       1 scheduler.go:454] Total Schedule Algo cumulative time:2.273778195s for 1219
I0828 10:50:17.240266       1 scheduler.go:451] ScheduleAlgoTime 1.955737ms Start:2018-08-28 10:50:17.23830514 +0000 UTC m=+20.204414695 End:2018-08-28 10:50:17.240260951 +0000 UTC m=+20.206370432
I0828 10:50:17.240284       1 scheduler.go:454] Total Schedule Algo cumulative time:2.275733932s for 1220
I0828 10:50:17.241915       1 scheduler.go:451] ScheduleAlgoTime 1.553054ms Start:2018-08-28 10:50:17.24035705 +0000 UTC m=+20.206466584 End:2018-08-28 10:50:17.241910157 +0000 UTC m=+20.208019638
I0828 10:50:17.241935       1 scheduler.go:454] Total Schedule Algo cumulative time:2.277286986s for 1221
I0828 10:50:17.243536       1 scheduler.go:451] ScheduleAlgoTime 1.528432ms Start:2018-08-28 10:50:17.242002638 +0000 UTC m=+20.208112175 End:2018-08-28 10:50:17.243531123 +0000 UTC m=+20.209640607
I0828 10:50:17.243554       1 scheduler.go:454] Total Schedule Algo cumulative time:2.278815418s for 1222
I0828 10:50:17.245844       1 scheduler.go:451] ScheduleAlgoTime 2.207612ms Start:2018-08-28 10:50:17.243630462 +0000 UTC m=+20.209739978 End:2018-08-28 10:50:17.245838101 +0000 UTC m=+20.211947590
I0828 10:50:17.245871       1 scheduler.go:454] Total Schedule Algo cumulative time:2.28102303s for 1223
I0828 10:50:17.247719       1 scheduler.go:451] ScheduleAlgoTime 1.755194ms Start:2018-08-28 10:50:17.245956674 +0000 UTC m=+20.212066218 End:2018-08-28 10:50:17.24771192 +0000 UTC m=+20.213821412
I0828 10:50:17.247748       1 scheduler.go:454] Total Schedule Algo cumulative time:2.282778224s for 1224
I0828 10:50:17.249480       1 scheduler.go:451] ScheduleAlgoTime 1.616907ms Start:2018-08-28 10:50:17.247858264 +0000 UTC m=+20.213967828 End:2018-08-28 10:50:17.249475255 +0000 UTC m=+20.215584735
I0828 10:50:17.249500       1 scheduler.go:454] Total Schedule Algo cumulative time:2.284395131s for 1225
I0828 10:50:17.253337       1 scheduler.go:451] ScheduleAlgoTime 3.760609ms Start:2018-08-28 10:50:17.24956911 +0000 UTC m=+20.215678641 End:2018-08-28 10:50:17.25332974 +0000 UTC m=+20.219439250
I0828 10:50:17.253387       1 scheduler.go:454] Total Schedule Algo cumulative time:2.28815574s for 1226
I0828 10:50:17.258098       1 scheduler.go:451] ScheduleAlgoTime 4.533097ms Start:2018-08-28 10:50:17.253558099 +0000 UTC m=+20.219667674 End:2018-08-28 10:50:17.258091289 +0000 UTC m=+20.224200771
I0828 10:50:17.258126       1 scheduler.go:454] Total Schedule Algo cumulative time:2.292688837s for 1227
I0828 10:50:17.259588       1 scheduler.go:451] ScheduleAlgoTime 1.381528ms Start:2018-08-28 10:50:17.258201696 +0000 UTC m=+20.224311247 End:2018-08-28 10:50:17.25958329 +0000 UTC m=+20.225692775
I0828 10:50:17.259616       1 scheduler.go:454] Total Schedule Algo cumulative time:2.294070365s for 1228
I0828 10:50:17.262595       1 scheduler.go:451] ScheduleAlgoTime 2.062599ms Start:2018-08-28 10:50:17.260524968 +0000 UTC m=+20.226634476 End:2018-08-28 10:50:17.262587573 +0000 UTC m=+20.228697075
I0828 10:50:17.262620       1 scheduler.go:454] Total Schedule Algo cumulative time:2.296132964s for 1229
I0828 10:50:17.264567       1 scheduler.go:451] ScheduleAlgoTime 1.856969ms Start:2018-08-28 10:50:17.262705464 +0000 UTC m=+20.228814954 End:2018-08-28 10:50:17.264562442 +0000 UTC m=+20.230671923
I0828 10:50:17.264588       1 scheduler.go:454] Total Schedule Algo cumulative time:2.297989933s for 1230
I0828 10:50:17.266165       1 scheduler.go:451] ScheduleAlgoTime 1.480765ms Start:2018-08-28 10:50:17.26467921 +0000 UTC m=+20.230788755 End:2018-08-28 10:50:17.26616004 +0000 UTC m=+20.232269520
I0828 10:50:17.266186       1 scheduler.go:454] Total Schedule Algo cumulative time:2.299470698s for 1231
I0828 10:50:17.268162       1 scheduler.go:451] ScheduleAlgoTime 1.891641ms Start:2018-08-28 10:50:17.266265558 +0000 UTC m=+20.232375072 End:2018-08-28 10:50:17.268157228 +0000 UTC m=+20.234266713
I0828 10:50:17.268188       1 scheduler.go:454] Total Schedule Algo cumulative time:2.301362339s for 1232
I0828 10:50:17.269888       1 scheduler.go:451] ScheduleAlgoTime 1.579272ms Start:2018-08-28 10:50:17.268303992 +0000 UTC m=+20.234413552 End:2018-08-28 10:50:17.269883345 +0000 UTC m=+20.235992824
I0828 10:50:17.269909       1 scheduler.go:454] Total Schedule Algo cumulative time:2.302941611s for 1233
I0828 10:50:17.271655       1 scheduler.go:451] ScheduleAlgoTime 1.640202ms Start:2018-08-28 10:50:17.270007609 +0000 UTC m=+20.236117162 End:2018-08-28 10:50:17.27164786 +0000 UTC m=+20.237757364
I0828 10:50:17.271682       1 scheduler.go:454] Total Schedule Algo cumulative time:2.304581813s for 1234
I0828 10:50:17.273790       1 scheduler.go:451] ScheduleAlgoTime 2.009765ms Start:2018-08-28 10:50:17.271775844 +0000 UTC m=+20.237885377 End:2018-08-28 10:50:17.273785662 +0000 UTC m=+20.239895142
I0828 10:50:17.273816       1 scheduler.go:454] Total Schedule Algo cumulative time:2.306591578s for 1235
I0828 10:50:17.275227       1 scheduler.go:451] ScheduleAlgoTime 1.31874ms Start:2018-08-28 10:50:17.273903824 +0000 UTC m=+20.240013369 End:2018-08-28 10:50:17.275222628 +0000 UTC m=+20.241332109
I0828 10:50:17.275251       1 scheduler.go:454] Total Schedule Algo cumulative time:2.307910318s for 1236
I0828 10:50:17.276678       1 scheduler.go:451] ScheduleAlgoTime 1.357067ms Start:2018-08-28 10:50:17.275315483 +0000 UTC m=+20.241425000 End:2018-08-28 10:50:17.276672585 +0000 UTC m=+20.242782067
I0828 10:50:17.276713       1 scheduler.go:454] Total Schedule Algo cumulative time:2.309267385s for 1237
I0828 10:50:17.278598       1 scheduler.go:451] ScheduleAlgoTime 1.782653ms Start:2018-08-28 10:50:17.276809032 +0000 UTC m=+20.242918553 End:2018-08-28 10:50:17.278591709 +0000 UTC m=+20.244701206
I0828 10:50:17.278627       1 scheduler.go:454] Total Schedule Algo cumulative time:2.311050038s for 1238
I0828 10:50:17.280339       1 scheduler.go:451] ScheduleAlgoTime 1.621076ms Start:2018-08-28 10:50:17.27871283 +0000 UTC m=+20.244822337 End:2018-08-28 10:50:17.28033393 +0000 UTC m=+20.246443413
I0828 10:50:17.280359       1 scheduler.go:454] Total Schedule Algo cumulative time:2.312671114s for 1239
I0828 10:50:17.281982       1 scheduler.go:451] ScheduleAlgoTime 1.547157ms Start:2018-08-28 10:50:17.280430244 +0000 UTC m=+20.246539774 End:2018-08-28 10:50:17.281977449 +0000 UTC m=+20.248086931
I0828 10:50:17.282003       1 scheduler.go:454] Total Schedule Algo cumulative time:2.314218271s for 1240
I0828 10:50:17.283466       1 scheduler.go:451] ScheduleAlgoTime 1.364353ms Start:2018-08-28 10:50:17.282097209 +0000 UTC m=+20.248206737 End:2018-08-28 10:50:17.283461606 +0000 UTC m=+20.249571090
I0828 10:50:17.283491       1 scheduler.go:454] Total Schedule Algo cumulative time:2.315582624s for 1241
I0828 10:50:17.285047       1 scheduler.go:451] ScheduleAlgoTime 1.456864ms Start:2018-08-28 10:50:17.28358238 +0000 UTC m=+20.249691950 End:2018-08-28 10:50:17.28503928 +0000 UTC m=+20.251148814
I0828 10:50:17.285075       1 scheduler.go:454] Total Schedule Algo cumulative time:2.317039488s for 1242
I0828 10:50:17.286500       1 scheduler.go:451] ScheduleAlgoTime 1.311673ms Start:2018-08-28 10:50:17.285183945 +0000 UTC m=+20.251293462 End:2018-08-28 10:50:17.286495656 +0000 UTC m=+20.252605135
I0828 10:50:17.286521       1 scheduler.go:454] Total Schedule Algo cumulative time:2.318351161s for 1243
I0828 10:50:17.287936       1 scheduler.go:451] ScheduleAlgoTime 1.320882ms Start:2018-08-28 10:50:17.286610057 +0000 UTC m=+20.252719567 End:2018-08-28 10:50:17.287930967 +0000 UTC m=+20.254040449
I0828 10:50:17.287961       1 scheduler.go:454] Total Schedule Algo cumulative time:2.319672043s for 1244
I0828 10:50:17.289346       1 scheduler.go:451] ScheduleAlgoTime 1.327542ms Start:2018-08-28 10:50:17.2880133 +0000 UTC m=+20.254122853 End:2018-08-28 10:50:17.289340915 +0000 UTC m=+20.255450395
I0828 10:50:17.289367       1 scheduler.go:454] Total Schedule Algo cumulative time:2.320999585s for 1245
I0828 10:50:17.290749       1 scheduler.go:451] ScheduleAlgoTime 1.302375ms Start:2018-08-28 10:50:17.28944252 +0000 UTC m=+20.255552022 End:2018-08-28 10:50:17.290744913 +0000 UTC m=+20.256854397
I0828 10:50:17.290769       1 scheduler.go:454] Total Schedule Algo cumulative time:2.32230196s for 1246
I0828 10:50:17.292308       1 scheduler.go:451] ScheduleAlgoTime 1.461601ms Start:2018-08-28 10:50:17.290841297 +0000 UTC m=+20.256950832 End:2018-08-28 10:50:17.292302953 +0000 UTC m=+20.258412433
I0828 10:50:17.292326       1 scheduler.go:454] Total Schedule Algo cumulative time:2.323763561s for 1247
I0828 10:50:17.293852       1 scheduler.go:451] ScheduleAlgoTime 1.434523ms Start:2018-08-28 10:50:17.292410682 +0000 UTC m=+20.258520217 End:2018-08-28 10:50:17.293845002 +0000 UTC m=+20.259954740
I0828 10:50:17.293877       1 scheduler.go:454] Total Schedule Algo cumulative time:2.325198084s for 1248
I0828 10:50:17.295314       1 scheduler.go:451] ScheduleAlgoTime 1.343711ms Start:2018-08-28 10:50:17.293961171 +0000 UTC m=+20.260070712 End:2018-08-28 10:50:17.295304937 +0000 UTC m=+20.261414423
I0828 10:50:17.295343       1 scheduler.go:454] Total Schedule Algo cumulative time:2.326541795s for 1249
I0828 10:50:17.296803       1 scheduler.go:451] ScheduleAlgoTime 1.374875ms Start:2018-08-28 10:50:17.295423511 +0000 UTC m=+20.261533050 End:2018-08-28 10:50:17.29679844 +0000 UTC m=+20.262907925
I0828 10:50:17.296822       1 scheduler.go:454] Total Schedule Algo cumulative time:2.32791667s for 1250
I0828 10:50:17.298260       1 scheduler.go:451] ScheduleAlgoTime 1.346963ms Start:2018-08-28 10:50:17.296906306 +0000 UTC m=+20.263015852 End:2018-08-28 10:50:17.298253293 +0000 UTC m=+20.264362815
I0828 10:50:17.298285       1 scheduler.go:454] Total Schedule Algo cumulative time:2.329263633s for 1251
I0828 10:50:17.300798       1 scheduler.go:451] ScheduleAlgoTime 2.36075ms Start:2018-08-28 10:50:17.298429959 +0000 UTC m=+20.264539478 End:2018-08-28 10:50:17.300790725 +0000 UTC m=+20.266900228
I0828 10:50:17.300821       1 scheduler.go:454] Total Schedule Algo cumulative time:2.331624383s for 1252
I0828 10:50:17.302303       1 scheduler.go:451] ScheduleAlgoTime 1.370721ms Start:2018-08-28 10:50:17.300928951 +0000 UTC m=+20.267038461 End:2018-08-28 10:50:17.3022997 +0000 UTC m=+20.268409182
I0828 10:50:17.302326       1 scheduler.go:454] Total Schedule Algo cumulative time:2.332995104s for 1253
I0828 10:50:17.303793       1 scheduler.go:451] ScheduleAlgoTime 1.390874ms Start:2018-08-28 10:50:17.302396662 +0000 UTC m=+20.268506179 End:2018-08-28 10:50:17.303787573 +0000 UTC m=+20.269897053
I0828 10:50:17.303812       1 scheduler.go:454] Total Schedule Algo cumulative time:2.334385978s for 1254
I0828 10:50:17.305243       1 scheduler.go:451] ScheduleAlgoTime 1.357003ms Start:2018-08-28 10:50:17.303878772 +0000 UTC m=+20.269988300 End:2018-08-28 10:50:17.305235783 +0000 UTC m=+20.271345303
I0828 10:50:17.305269       1 scheduler.go:454] Total Schedule Algo cumulative time:2.335742981s for 1255
I0828 10:50:17.306834       1 scheduler.go:451] ScheduleAlgoTime 1.463569ms Start:2018-08-28 10:50:17.305364393 +0000 UTC m=+20.271473884 End:2018-08-28 10:50:17.306827962 +0000 UTC m=+20.272937453
I0828 10:50:17.306860       1 scheduler.go:454] Total Schedule Algo cumulative time:2.33720655s for 1256
I0828 10:50:17.308547       1 scheduler.go:451] ScheduleAlgoTime 1.568746ms Start:2018-08-28 10:50:17.306971866 +0000 UTC m=+20.273081436 End:2018-08-28 10:50:17.308540685 +0000 UTC m=+20.274650182
I0828 10:50:17.308572       1 scheduler.go:454] Total Schedule Algo cumulative time:2.338775296s for 1257
I0828 10:50:17.310056       1 scheduler.go:451] ScheduleAlgoTime 1.400501ms Start:2018-08-28 10:50:17.308648709 +0000 UTC m=+20.274758250 End:2018-08-28 10:50:17.31004925 +0000 UTC m=+20.276158751
I0828 10:50:17.310081       1 scheduler.go:454] Total Schedule Algo cumulative time:2.340175797s for 1258
I0828 10:50:17.311458       1 scheduler.go:451] ScheduleAlgoTime 1.273347ms Start:2018-08-28 10:50:17.310178404 +0000 UTC m=+20.276287934 End:2018-08-28 10:50:17.311451801 +0000 UTC m=+20.277561281
I0828 10:50:17.311484       1 scheduler.go:454] Total Schedule Algo cumulative time:2.341449144s for 1259
I0828 10:50:17.313566       1 scheduler.go:451] ScheduleAlgoTime 1.988746ms Start:2018-08-28 10:50:17.311572384 +0000 UTC m=+20.277681921 End:2018-08-28 10:50:17.313561187 +0000 UTC m=+20.279670667
I0828 10:50:17.313586       1 scheduler.go:454] Total Schedule Algo cumulative time:2.34343789s for 1260
I0828 10:50:17.315544       1 scheduler.go:451] ScheduleAlgoTime 1.880321ms Start:2018-08-28 10:50:17.313657434 +0000 UTC m=+20.279766988 End:2018-08-28 10:50:17.315537819 +0000 UTC m=+20.281647309
I0828 10:50:17.315569       1 scheduler.go:454] Total Schedule Algo cumulative time:2.345318211s for 1261
I0828 10:50:17.317150       1 scheduler.go:451] ScheduleAlgoTime 1.48404ms Start:2018-08-28 10:50:17.315650731 +0000 UTC m=+20.281760237 End:2018-08-28 10:50:17.317134785 +0000 UTC m=+20.283244277
I0828 10:50:17.317175       1 scheduler.go:454] Total Schedule Algo cumulative time:2.346802251s for 1262
I0828 10:50:17.319641       1 scheduler.go:451] ScheduleAlgoTime 1.713765ms Start:2018-08-28 10:50:17.317920921 +0000 UTC m=+20.284030441 End:2018-08-28 10:50:17.319634713 +0000 UTC m=+20.285744206
I0828 10:50:17.319666       1 scheduler.go:454] Total Schedule Algo cumulative time:2.348516016s for 1263
I0828 10:50:17.321213       1 scheduler.go:451] ScheduleAlgoTime 1.43853ms Start:2018-08-28 10:50:17.319769864 +0000 UTC m=+20.285879394 End:2018-08-28 10:50:17.321208443 +0000 UTC m=+20.287317924
I0828 10:50:17.321232       1 scheduler.go:454] Total Schedule Algo cumulative time:2.349954546s for 1264
I0828 10:50:17.322812       1 scheduler.go:451] ScheduleAlgoTime 1.481794ms Start:2018-08-28 10:50:17.321325583 +0000 UTC m=+20.287435180 End:2018-08-28 10:50:17.322807495 +0000 UTC m=+20.288916974
I0828 10:50:17.322832       1 scheduler.go:454] Total Schedule Algo cumulative time:2.35143634s for 1265
I0828 10:50:17.324380       1 scheduler.go:451] ScheduleAlgoTime 1.464926ms Start:2018-08-28 10:50:17.322910575 +0000 UTC m=+20.289020094 End:2018-08-28 10:50:17.32437554 +0000 UTC m=+20.290485020
I0828 10:50:17.324400       1 scheduler.go:454] Total Schedule Algo cumulative time:2.352901266s for 1266
I0828 10:50:17.325975       1 scheduler.go:451] ScheduleAlgoTime 1.488059ms Start:2018-08-28 10:50:17.324482103 +0000 UTC m=+20.290591630 End:2018-08-28 10:50:17.325970208 +0000 UTC m=+20.292079689
I0828 10:50:17.325995       1 scheduler.go:454] Total Schedule Algo cumulative time:2.354389325s for 1267
I0828 10:50:17.327361       1 scheduler.go:451] ScheduleAlgoTime 1.29463ms Start:2018-08-28 10:50:17.326058814 +0000 UTC m=+20.292168346 End:2018-08-28 10:50:17.32735345 +0000 UTC m=+20.293462976
I0828 10:50:17.327384       1 scheduler.go:454] Total Schedule Algo cumulative time:2.355683955s for 1268
I0828 10:50:17.328777       1 scheduler.go:451] ScheduleAlgoTime 1.311384ms Start:2018-08-28 10:50:17.327460791 +0000 UTC m=+20.293570315 End:2018-08-28 10:50:17.32877222 +0000 UTC m=+20.294881699
I0828 10:50:17.328795       1 scheduler.go:454] Total Schedule Algo cumulative time:2.356995339s for 1269
I0828 10:50:17.330320       1 scheduler.go:451] ScheduleAlgoTime 1.429018ms Start:2018-08-28 10:50:17.328884183 +0000 UTC m=+20.294993769 End:2018-08-28 10:50:17.330313304 +0000 UTC m=+20.296422787
I0828 10:50:17.330347       1 scheduler.go:454] Total Schedule Algo cumulative time:2.358424357s for 1270
I0828 10:50:17.332894       1 scheduler.go:451] ScheduleAlgoTime 2.462713ms Start:2018-08-28 10:50:17.330424526 +0000 UTC m=+20.296534012 End:2018-08-28 10:50:17.332887242 +0000 UTC m=+20.298996725
I0828 10:50:17.332929       1 scheduler.go:454] Total Schedule Algo cumulative time:2.36088707s for 1271
I0828 10:50:17.334815       1 scheduler.go:451] ScheduleAlgoTime 1.809158ms Start:2018-08-28 10:50:17.333001057 +0000 UTC m=+20.299110609 End:2018-08-28 10:50:17.334810287 +0000 UTC m=+20.300919767
I0828 10:50:17.334839       1 scheduler.go:454] Total Schedule Algo cumulative time:2.362696228s for 1272
I0828 10:50:17.336462       1 scheduler.go:451] ScheduleAlgoTime 1.512325ms Start:2018-08-28 10:50:17.334944518 +0000 UTC m=+20.301054059 End:2018-08-28 10:50:17.336456902 +0000 UTC m=+20.302566384
I0828 10:50:17.336483       1 scheduler.go:454] Total Schedule Algo cumulative time:2.364208553s for 1273
I0828 10:50:17.338152       1 scheduler.go:451] ScheduleAlgoTime 1.586933ms Start:2018-08-28 10:50:17.33654962 +0000 UTC m=+20.302659155 End:2018-08-28 10:50:17.338136609 +0000 UTC m=+20.304246088
I0828 10:50:17.338172       1 scheduler.go:454] Total Schedule Algo cumulative time:2.365795486s for 1274
I0828 10:50:17.339707       1 scheduler.go:451] ScheduleAlgoTime 1.451314ms Start:2018-08-28 10:50:17.338249059 +0000 UTC m=+20.304358583 End:2018-08-28 10:50:17.33970039 +0000 UTC m=+20.305809897
I0828 10:50:17.339737       1 scheduler.go:454] Total Schedule Algo cumulative time:2.3672468s for 1275
I0828 10:50:17.343087       1 scheduler.go:451] ScheduleAlgoTime 3.236564ms Start:2018-08-28 10:50:17.339845934 +0000 UTC m=+20.305955447 End:2018-08-28 10:50:17.34308253 +0000 UTC m=+20.309192011
I0828 10:50:17.343108       1 scheduler.go:454] Total Schedule Algo cumulative time:2.370483364s for 1276
I0828 10:50:17.344678       1 scheduler.go:451] ScheduleAlgoTime 1.474229ms Start:2018-08-28 10:50:17.343198896 +0000 UTC m=+20.309308408 End:2018-08-28 10:50:17.344673158 +0000 UTC m=+20.310782637
I0828 10:50:17.344697       1 scheduler.go:454] Total Schedule Algo cumulative time:2.371957593s for 1277
I0828 10:50:17.346150       1 scheduler.go:451] ScheduleAlgoTime 1.342429ms Start:2018-08-28 10:50:17.344793268 +0000 UTC m=+20.310902833 End:2018-08-28 10:50:17.346135779 +0000 UTC m=+20.312245262
I0828 10:50:17.346171       1 scheduler.go:454] Total Schedule Algo cumulative time:2.373300022s for 1278
I0828 10:50:17.347627       1 scheduler.go:451] ScheduleAlgoTime 1.378156ms Start:2018-08-28 10:50:17.346243871 +0000 UTC m=+20.312353386 End:2018-08-28 10:50:17.347622061 +0000 UTC m=+20.313731542
I0828 10:50:17.347652       1 scheduler.go:454] Total Schedule Algo cumulative time:2.374678178s for 1279
I0828 10:50:17.349376       1 scheduler.go:451] ScheduleAlgoTime 1.634892ms Start:2018-08-28 10:50:17.347733295 +0000 UTC m=+20.313842866 End:2018-08-28 10:50:17.349368267 +0000 UTC m=+20.315477758
I0828 10:50:17.349402       1 scheduler.go:454] Total Schedule Algo cumulative time:2.37631307s for 1280
I0828 10:50:17.350982       1 scheduler.go:451] ScheduleAlgoTime 1.479984ms Start:2018-08-28 10:50:17.349497073 +0000 UTC m=+20.315606588 End:2018-08-28 10:50:17.350977089 +0000 UTC m=+20.317086572
I0828 10:50:17.351002       1 scheduler.go:454] Total Schedule Algo cumulative time:2.377793054s for 1281
I0828 10:50:17.352763       1 scheduler.go:451] ScheduleAlgoTime 1.683973ms Start:2018-08-28 10:50:17.351073732 +0000 UTC m=+20.317183271 End:2018-08-28 10:50:17.352757762 +0000 UTC m=+20.318867244
I0828 10:50:17.352782       1 scheduler.go:454] Total Schedule Algo cumulative time:2.379477027s for 1282
I0828 10:50:17.354173       1 scheduler.go:451] ScheduleAlgoTime 1.300605ms Start:2018-08-28 10:50:17.35286619 +0000 UTC m=+20.318975732 End:2018-08-28 10:50:17.35416683 +0000 UTC m=+20.320276337
I0828 10:50:17.354208       1 scheduler.go:454] Total Schedule Algo cumulative time:2.380777632s for 1283
I0828 10:50:17.355641       1 scheduler.go:451] ScheduleAlgoTime 1.3415ms Start:2018-08-28 10:50:17.35429488 +0000 UTC m=+20.320404390 End:2018-08-28 10:50:17.355636408 +0000 UTC m=+20.321745890
I0828 10:50:17.355661       1 scheduler.go:454] Total Schedule Algo cumulative time:2.382119132s for 1284
I0828 10:50:17.357118       1 scheduler.go:451] ScheduleAlgoTime 1.374286ms Start:2018-08-28 10:50:17.355738985 +0000 UTC m=+20.321848476 End:2018-08-28 10:50:17.357113283 +0000 UTC m=+20.323222762
I0828 10:50:17.357138       1 scheduler.go:454] Total Schedule Algo cumulative time:2.383493418s for 1285
I0828 10:50:17.358544       1 scheduler.go:451] ScheduleAlgoTime 1.307306ms Start:2018-08-28 10:50:17.357232138 +0000 UTC m=+20.323341695 End:2018-08-28 10:50:17.358539521 +0000 UTC m=+20.324649001
I0828 10:50:17.358572       1 scheduler.go:454] Total Schedule Algo cumulative time:2.384800724s for 1286
I0828 10:50:17.360080       1 scheduler.go:451] ScheduleAlgoTime 1.423781ms Start:2018-08-28 10:50:17.358650118 +0000 UTC m=+20.324759644 End:2018-08-28 10:50:17.360073937 +0000 UTC m=+20.326183425
I0828 10:50:17.360108       1 scheduler.go:454] Total Schedule Algo cumulative time:2.386224505s for 1287
I0828 10:50:17.361683       1 scheduler.go:451] ScheduleAlgoTime 1.469149ms Start:2018-08-28 10:50:17.360207515 +0000 UTC m=+20.326317033 End:2018-08-28 10:50:17.361676691 +0000 UTC m=+20.327786182
I0828 10:50:17.361707       1 scheduler.go:454] Total Schedule Algo cumulative time:2.387693654s for 1288
I0828 10:50:17.363348       1 scheduler.go:451] ScheduleAlgoTime 1.527138ms Start:2018-08-28 10:50:17.361815551 +0000 UTC m=+20.327925087 End:2018-08-28 10:50:17.36334273 +0000 UTC m=+20.329452225
I0828 10:50:17.363372       1 scheduler.go:454] Total Schedule Algo cumulative time:2.389220792s for 1289
I0828 10:50:17.365236       1 scheduler.go:451] ScheduleAlgoTime 1.756401ms Start:2018-08-28 10:50:17.363472172 +0000 UTC m=+20.329581715 End:2018-08-28 10:50:17.365228621 +0000 UTC m=+20.331338116
I0828 10:50:17.365261       1 scheduler.go:454] Total Schedule Algo cumulative time:2.390977193s for 1290
I0828 10:50:17.367421       1 scheduler.go:451] ScheduleAlgoTime 2.089514ms Start:2018-08-28 10:50:17.365327061 +0000 UTC m=+20.331436593 End:2018-08-28 10:50:17.367416625 +0000 UTC m=+20.333526107
I0828 10:50:17.367440       1 scheduler.go:454] Total Schedule Algo cumulative time:2.393066707s for 1291
I0828 10:50:17.369009       1 scheduler.go:451] ScheduleAlgoTime 1.482963ms Start:2018-08-28 10:50:17.367519032 +0000 UTC m=+20.333628542 End:2018-08-28 10:50:17.369002023 +0000 UTC m=+20.335111505
I0828 10:50:17.369047       1 scheduler.go:454] Total Schedule Algo cumulative time:2.39454967s for 1292
I0828 10:50:17.370586       1 scheduler.go:451] ScheduleAlgoTime 1.428252ms Start:2018-08-28 10:50:17.369152936 +0000 UTC m=+20.335262449 End:2018-08-28 10:50:17.370581221 +0000 UTC m=+20.336690701
I0828 10:50:17.370608       1 scheduler.go:454] Total Schedule Algo cumulative time:2.395977922s for 1293
I0828 10:50:17.372438       1 scheduler.go:451] ScheduleAlgoTime 1.740128ms Start:2018-08-28 10:50:17.370692575 +0000 UTC m=+20.336802092 End:2018-08-28 10:50:17.372432739 +0000 UTC m=+20.338542220
I0828 10:50:17.372457       1 scheduler.go:454] Total Schedule Algo cumulative time:2.39771805s for 1294
I0828 10:50:17.374064       1 scheduler.go:451] ScheduleAlgoTime 1.519455ms Start:2018-08-28 10:50:17.372539419 +0000 UTC m=+20.338648928 End:2018-08-28 10:50:17.374058896 +0000 UTC m=+20.340168383
I0828 10:50:17.374086       1 scheduler.go:454] Total Schedule Algo cumulative time:2.399237505s for 1295
I0828 10:50:17.375495       1 scheduler.go:451] ScheduleAlgoTime 1.314969ms Start:2018-08-28 10:50:17.374175724 +0000 UTC m=+20.340285278 End:2018-08-28 10:50:17.375490763 +0000 UTC m=+20.341600247
I0828 10:50:17.375514       1 scheduler.go:454] Total Schedule Algo cumulative time:2.400552474s for 1296
I0828 10:50:17.377574       1 scheduler.go:451] ScheduleAlgoTime 1.973859ms Start:2018-08-28 10:50:17.375593226 +0000 UTC m=+20.341702721 End:2018-08-28 10:50:17.377567097 +0000 UTC m=+20.343676580
I0828 10:50:17.377600       1 scheduler.go:454] Total Schedule Algo cumulative time:2.402526333s for 1297
I0828 10:50:17.379078       1 scheduler.go:451] ScheduleAlgoTime 1.370902ms Start:2018-08-28 10:50:17.377702078 +0000 UTC m=+20.343811614 End:2018-08-28 10:50:17.379073035 +0000 UTC m=+20.345182516
I0828 10:50:17.379096       1 scheduler.go:454] Total Schedule Algo cumulative time:2.403897235s for 1298
I0828 10:50:17.380932       1 scheduler.go:451] ScheduleAlgoTime 1.740094ms Start:2018-08-28 10:50:17.37918596 +0000 UTC m=+20.345295510 End:2018-08-28 10:50:17.380926112 +0000 UTC m=+20.347035604
I0828 10:50:17.380961       1 scheduler.go:454] Total Schedule Algo cumulative time:2.405637329s for 1299
I0828 10:50:17.382929       1 scheduler.go:451] ScheduleAlgoTime 1.874982ms Start:2018-08-28 10:50:17.381049351 +0000 UTC m=+20.347158865 End:2018-08-28 10:50:17.382924363 +0000 UTC m=+20.349033847
I0828 10:50:17.382976       1 scheduler.go:454] Total Schedule Algo cumulative time:2.407512311s for 1300
I0828 10:50:17.384868       1 scheduler.go:451] ScheduleAlgoTime 1.725588ms Start:2018-08-28 10:50:17.383137877 +0000 UTC m=+20.349247427 End:2018-08-28 10:50:17.384863534 +0000 UTC m=+20.350973015
I0828 10:50:17.384887       1 scheduler.go:454] Total Schedule Algo cumulative time:2.409237899s for 1301
I0828 10:50:17.386429       1 scheduler.go:451] ScheduleAlgoTime 1.462184ms Start:2018-08-28 10:50:17.384961832 +0000 UTC m=+20.351071341 End:2018-08-28 10:50:17.386424044 +0000 UTC m=+20.352533525
I0828 10:50:17.386449       1 scheduler.go:454] Total Schedule Algo cumulative time:2.410700083s for 1302
I0828 10:50:17.388458       1 scheduler.go:451] ScheduleAlgoTime 1.914395ms Start:2018-08-28 10:50:17.386537208 +0000 UTC m=+20.352646762 End:2018-08-28 10:50:17.38845167 +0000 UTC m=+20.354561157
I0828 10:50:17.388483       1 scheduler.go:454] Total Schedule Algo cumulative time:2.412614478s for 1303
I0828 10:50:17.390706       1 scheduler.go:451] ScheduleAlgoTime 2.154274ms Start:2018-08-28 10:50:17.388544663 +0000 UTC m=+20.354654218 End:2018-08-28 10:50:17.390699005 +0000 UTC m=+20.356808492
I0828 10:50:17.390731       1 scheduler.go:454] Total Schedule Algo cumulative time:2.414768752s for 1304
I0828 10:50:17.392223       1 scheduler.go:451] ScheduleAlgoTime 1.394935ms Start:2018-08-28 10:50:17.390823004 +0000 UTC m=+20.356932584 End:2018-08-28 10:50:17.39221804 +0000 UTC m=+20.358327519
I0828 10:50:17.392241       1 scheduler.go:454] Total Schedule Algo cumulative time:2.416163687s for 1305
I0828 10:50:17.395508       1 scheduler.go:451] ScheduleAlgoTime 3.198513ms Start:2018-08-28 10:50:17.392301324 +0000 UTC m=+20.358410877 End:2018-08-28 10:50:17.395499887 +0000 UTC m=+20.361609390
I0828 10:50:17.395560       1 scheduler.go:454] Total Schedule Algo cumulative time:2.4193622s for 1306
I0828 10:50:17.402185       1 scheduler.go:451] ScheduleAlgoTime 6.407649ms Start:2018-08-28 10:50:17.395769806 +0000 UTC m=+20.361879375 End:2018-08-28 10:50:17.402177533 +0000 UTC m=+20.368287024
I0828 10:50:17.402218       1 scheduler.go:454] Total Schedule Algo cumulative time:2.425769849s for 1307
I0828 10:50:17.405025       1 scheduler.go:451] ScheduleAlgoTime 2.711781ms Start:2018-08-28 10:50:17.402305179 +0000 UTC m=+20.368414723 End:2018-08-28 10:50:17.40501684 +0000 UTC m=+20.371126504
