I0827 11:11:23.809059       1 flags.go:27] FLAG: --address=""
I0827 11:11:23.809325       1 flags.go:27] FLAG: --algorithm-provider=""
I0827 11:11:23.809342       1 flags.go:27] FLAG: --alsologtostderr="false"
I0827 11:11:23.809352       1 flags.go:27] FLAG: --config=""
I0827 11:11:23.809358       1 flags.go:27] FLAG: --contention-profiling="false"
I0827 11:11:23.809367       1 flags.go:27] FLAG: --failure-domains="kubernetes.io/hostname,failure-domain.beta.kubernetes.io/zone,failure-domain.beta.kubernetes.io/region"
I0827 11:11:23.809380       1 flags.go:27] FLAG: --feature-gates=""
I0827 11:11:23.809392       1 flags.go:27] FLAG: --hard-pod-affinity-symmetric-weight="1"
I0827 11:11:23.809401       1 flags.go:27] FLAG: --help="false"
I0827 11:11:23.809408       1 flags.go:27] FLAG: --kube-api-burst="100"
I0827 11:11:23.809415       1 flags.go:27] FLAG: --kube-api-content-type="application/vnd.kubernetes.protobuf"
I0827 11:11:23.809421       1 flags.go:27] FLAG: --kube-api-qps="50"
I0827 11:11:23.809431       1 flags.go:27] FLAG: --kubeconfig="/etc/srv/kubernetes/kube-scheduler/kubeconfig"
I0827 11:11:23.809438       1 flags.go:27] FLAG: --leader-elect="true"
I0827 11:11:23.809445       1 flags.go:27] FLAG: --leader-elect-lease-duration="15s"
I0827 11:11:23.809453       1 flags.go:27] FLAG: --leader-elect-renew-deadline="10s"
I0827 11:11:23.809459       1 flags.go:27] FLAG: --leader-elect-resource-lock="endpoints"
I0827 11:11:23.809465       1 flags.go:27] FLAG: --leader-elect-retry-period="2s"
I0827 11:11:23.809471       1 flags.go:27] FLAG: --lock-object-name="kube-scheduler"
I0827 11:11:23.809477       1 flags.go:27] FLAG: --lock-object-namespace="kube-system"
I0827 11:11:23.809483       1 flags.go:27] FLAG: --log-backtrace-at=":0"
I0827 11:11:23.809494       1 flags.go:27] FLAG: --log-dir=""
I0827 11:11:23.809501       1 flags.go:27] FLAG: --log-flush-frequency="5s"
I0827 11:11:23.809507       1 flags.go:27] FLAG: --logtostderr="true"
I0827 11:11:23.809513       1 flags.go:27] FLAG: --master=""
I0827 11:11:23.809520       1 flags.go:27] FLAG: --policy-config-file=""
I0827 11:11:23.809526       1 flags.go:27] FLAG: --policy-configmap=""
I0827 11:11:23.809532       1 flags.go:27] FLAG: --policy-configmap-namespace=""
I0827 11:11:23.809538       1 flags.go:27] FLAG: --port="10251"
I0827 11:11:23.809544       1 flags.go:27] FLAG: --profiling="false"
I0827 11:11:23.809550       1 flags.go:27] FLAG: --scheduler-name="default-scheduler"
I0827 11:11:23.809556       1 flags.go:27] FLAG: --stderrthreshold="2"
I0827 11:11:23.809562       1 flags.go:27] FLAG: --use-legacy-policy-config="false"
I0827 11:11:23.809568       1 flags.go:27] FLAG: --v="2"
I0827 11:11:23.809574       1 flags.go:27] FLAG: --version="false"
I0827 11:11:23.809584       1 flags.go:27] FLAG: --vmodule=""
W0827 11:11:23.809599       1 server.go:163] WARNING: all flags other than --config are deprecated. Please begin using a config file ASAP.
I0827 11:11:23.813425       1 server.go:555] Version: v1.10.4
I0827 11:11:23.813638       1 factory.go:922] Creating scheduler from algorithm provider 'DefaultProvider'
I0827 11:11:23.813648       1 factory.go:1022] Creating scheduler with fit predicates 'map[CheckNodeCondition:{} MaxEBSVolumeCount:{} MaxGCEPDVolumeCount:{} MaxAzureDiskVolumeCount:{} NoDiskConflict:{} GeneralPredicates:{} CheckNodeMemoryPressure:{} CheckNodeDiskPressure:{} PodToleratesNodeTaints:{} CheckVolumeBinding:{} NoVolumeZoneConflict:{} MatchInterPodAffinity:{}]' and priority functions 'map[NodePreferAvoidPodsPriority:{} NodeAffinityPriority:{} TaintTolerationPriority:{} SelectorSpreadPriority:{} InterPodAffinityPriority:{} LeastRequestedPriority:{} BalancedResourceAllocation:{}]'
I0827 11:11:23.814063       1 server.go:574] starting healthz server on 0.0.0.0:10251
I0827 11:11:24.716241       1 controller_utils.go:1019] Waiting for caches to sync for scheduler controller
I0827 11:11:24.816557       1 controller_utils.go:1026] Caches are synced for scheduler controller
I0827 11:11:24.816604       1 leaderelection.go:175] attempting to acquire leader lease  kube-system/kube-scheduler...
I0827 11:11:24.822957       1 leaderelection.go:184] successfully acquired lease kube-system/kube-scheduler
I0827 11:12:05.447783       1 scheduler.go:451] ScheduleAlgoTime 2.756183ms Start:2018-08-27 11:12:05.445018452 +0000 UTC m=+41.695399477 End:2018-08-27 11:12:05.447774666 +0000 UTC m=+41.698155660
I0827 11:12:05.447840       1 scheduler.go:454] Total Schedule Algo cumulative time:2.756183ms for 1
I0827 11:15:50.590987       1 scheduler.go:197] Failed to schedule pod: default/nginx-pod-affinity-pod-0-3-p29mr
I0827 11:15:50.591245       1 factory.go:1375] Updating pod condition for default/nginx-pod-affinity-pod-0-3-p29mr to (PodScheduled==False)
I0827 11:15:50.593907       1 scheduler.go:451] ScheduleAlgoTime 17.490529ms Start:2018-08-27 11:15:50.576403249 +0000 UTC m=+266.826784318 End:2018-08-27 11:15:50.593893853 +0000 UTC m=+266.844274847
I0827 11:15:50.593957       1 scheduler.go:454] Total Schedule Algo cumulative time:20.246712ms for 2
I0827 11:15:50.606759       1 scheduler.go:197] Failed to schedule pod: default/nginx-pod-affinity-pod-0-3-p29mr
W0827 11:15:50.606926       1 factory.go:1304] Request for pod default/nginx-pod-affinity-pod-0-3-p29mr already in flight, abandoning
I0827 11:15:50.606967       1 factory.go:1375] Updating pod condition for default/nginx-pod-affinity-pod-0-3-p29mr to (PodScheduled==False)
I0827 11:15:50.606980       1 scheduler.go:451] ScheduleAlgoTime 12.937663ms Start:2018-08-27 11:15:50.594038455 +0000 UTC m=+266.844419540 End:2018-08-27 11:15:50.606976208 +0000 UTC m=+266.857357203
I0827 11:15:50.607000       1 scheduler.go:454] Total Schedule Algo cumulative time:33.184375ms for 3
I0827 11:15:51.609861       1 scheduler.go:197] Failed to schedule pod: default/nginx-pod-affinity-pod-0-3-p29mr
I0827 11:15:51.610102       1 factory.go:1375] Updating pod condition for default/nginx-pod-affinity-pod-0-3-p29mr to (PodScheduled==False)
I0827 11:15:51.610125       1 scheduler.go:451] ScheduleAlgoTime 16.390767ms Start:2018-08-27 11:15:51.593730217 +0000 UTC m=+267.844111215 End:2018-08-27 11:15:51.610120991 +0000 UTC m=+267.860501982
I0827 11:15:51.610143       1 scheduler.go:454] Total Schedule Algo cumulative time:49.575142ms for 4
I0827 11:15:53.625312       1 scheduler.go:197] Failed to schedule pod: default/nginx-pod-affinity-pod-0-3-p29mr
I0827 11:15:53.625546       1 factory.go:1375] Updating pod condition for default/nginx-pod-affinity-pod-0-3-p29mr to (PodScheduled==False)
I0827 11:15:53.625559       1 scheduler.go:451] ScheduleAlgoTime 13.262827ms Start:2018-08-27 11:15:53.612292064 +0000 UTC m=+269.862673071 End:2018-08-27 11:15:53.625554905 +0000 UTC m=+269.875935898
I0827 11:15:53.625576       1 scheduler.go:454] Total Schedule Algo cumulative time:62.837969ms for 5
I0827 11:15:57.640956       1 scheduler.go:197] Failed to schedule pod: default/nginx-pod-affinity-pod-0-3-p29mr
I0827 11:15:57.641235       1 factory.go:1375] Updating pod condition for default/nginx-pod-affinity-pod-0-3-p29mr to (PodScheduled==False)
I0827 11:15:57.641249       1 scheduler.go:451] ScheduleAlgoTime 13.394656ms Start:2018-08-27 11:15:57.627850927 +0000 UTC m=+273.878231960 End:2018-08-27 11:15:57.641245623 +0000 UTC m=+273.891626616
I0827 11:15:57.641272       1 scheduler.go:454] Total Schedule Algo cumulative time:76.232625ms for 6
I0827 11:16:05.657639       1 scheduler.go:197] Failed to schedule pod: default/nginx-pod-affinity-pod-0-3-p29mr
I0827 11:16:05.657878       1 factory.go:1375] Updating pod condition for default/nginx-pod-affinity-pod-0-3-p29mr to (PodScheduled==False)
I0827 11:16:05.657891       1 scheduler.go:451] ScheduleAlgoTime 15.070018ms Start:2018-08-27 11:16:05.642817067 +0000 UTC m=+281.893198083 End:2018-08-27 11:16:05.65788711 +0000 UTC m=+281.908268101
I0827 11:16:05.657908       1 scheduler.go:454] Total Schedule Algo cumulative time:91.302643ms for 7
I0827 11:16:21.673129       1 scheduler.go:197] Failed to schedule pod: default/nginx-pod-affinity-pod-0-3-p29mr
I0827 11:16:21.673350       1 factory.go:1375] Updating pod condition for default/nginx-pod-affinity-pod-0-3-p29mr to (PodScheduled==False)
I0827 11:16:21.673382       1 scheduler.go:451] ScheduleAlgoTime 13.659338ms Start:2018-08-27 11:16:21.659719059 +0000 UTC m=+297.910100113 End:2018-08-27 11:16:21.673378458 +0000 UTC m=+297.923759451
I0827 11:16:21.673400       1 scheduler.go:454] Total Schedule Algo cumulative time:104.961981ms for 8
I0827 11:16:53.689340       1 scheduler.go:197] Failed to schedule pod: default/nginx-pod-affinity-pod-0-3-p29mr
I0827 11:16:53.689578       1 factory.go:1375] Updating pod condition for default/nginx-pod-affinity-pod-0-3-p29mr to (PodScheduled==False)
I0827 11:16:53.689593       1 scheduler.go:451] ScheduleAlgoTime 14.2517ms Start:2018-08-27 11:16:53.675336642 +0000 UTC m=+329.925717657 End:2018-08-27 11:16:53.689588361 +0000 UTC m=+329.939969357
I0827 11:16:53.689609       1 scheduler.go:454] Total Schedule Algo cumulative time:119.213681ms for 9
I0827 11:17:53.706295       1 scheduler.go:197] Failed to schedule pod: default/nginx-pod-affinity-pod-0-3-p29mr
I0827 11:17:53.706511       1 factory.go:1375] Updating pod condition for default/nginx-pod-affinity-pod-0-3-p29mr to (PodScheduled==False)
I0827 11:17:53.706530       1 scheduler.go:451] ScheduleAlgoTime 14.486575ms Start:2018-08-27 11:17:53.692039315 +0000 UTC m=+389.942420389 End:2018-08-27 11:17:53.706525973 +0000 UTC m=+389.956906964
I0827 11:17:53.706546       1 scheduler.go:454] Total Schedule Algo cumulative time:133.700256ms for 10
I0827 11:17:54.721428       1 scheduler.go:197] Failed to schedule pod: default/nginx-pod-affinity-pod-0-3-p29mr
I0827 11:17:54.721691       1 factory.go:1375] Updating pod condition for default/nginx-pod-affinity-pod-0-3-p29mr to (PodScheduled==False)
I0827 11:17:54.721706       1 scheduler.go:451] ScheduleAlgoTime 12.93966ms Start:2018-08-27 11:17:54.708762104 +0000 UTC m=+390.959143311 End:2018-08-27 11:17:54.721701975 +0000 UTC m=+390.972082971
I0827 11:17:54.721727       1 scheduler.go:454] Total Schedule Algo cumulative time:146.639916ms for 11
I0827 11:17:56.737159       1 scheduler.go:197] Failed to schedule pod: default/nginx-pod-affinity-pod-0-3-p29mr
I0827 11:17:56.737360       1 factory.go:1375] Updating pod condition for default/nginx-pod-affinity-pod-0-3-p29mr to (PodScheduled==False)
I0827 11:17:56.737374       1 scheduler.go:451] ScheduleAlgoTime 13.397115ms Start:2018-08-27 11:17:56.723973126 +0000 UTC m=+392.974354120 End:2018-08-27 11:17:56.737370242 +0000 UTC m=+392.987751235
I0827 11:17:56.737390       1 scheduler.go:454] Total Schedule Algo cumulative time:160.037031ms for 12
I0827 11:18:00.752894       1 scheduler.go:197] Failed to schedule pod: default/nginx-pod-affinity-pod-0-3-p29mr
I0827 11:18:00.753111       1 factory.go:1375] Updating pod condition for default/nginx-pod-affinity-pod-0-3-p29mr to (PodScheduled==False)
I0827 11:18:00.753125       1 scheduler.go:451] ScheduleAlgoTime 13.584294ms Start:2018-08-27 11:18:00.739536542 +0000 UTC m=+396.989917548 End:2018-08-27 11:18:00.753120846 +0000 UTC m=+397.003501842
I0827 11:18:00.753142       1 scheduler.go:454] Total Schedule Algo cumulative time:173.621325ms for 13
I0827 11:18:08.768567       1 scheduler.go:197] Failed to schedule pod: default/nginx-pod-affinity-pod-0-3-p29mr
I0827 11:18:08.768853       1 factory.go:1375] Updating pod condition for default/nginx-pod-affinity-pod-0-3-p29mr to (PodScheduled==False)
I0827 11:18:08.768868       1 scheduler.go:451] ScheduleAlgoTime 13.121302ms Start:2018-08-27 11:18:08.755742951 +0000 UTC m=+405.006123947 End:2018-08-27 11:18:08.768864255 +0000 UTC m=+405.019245249
I0827 11:18:08.768884       1 scheduler.go:454] Total Schedule Algo cumulative time:186.742627ms for 14
I0827 11:18:24.784852       1 scheduler.go:197] Failed to schedule pod: default/nginx-pod-affinity-pod-0-3-p29mr
I0827 11:18:24.785084       1 factory.go:1375] Updating pod condition for default/nginx-pod-affinity-pod-0-3-p29mr to (PodScheduled==False)
I0827 11:18:24.785098       1 scheduler.go:451] ScheduleAlgoTime 13.890539ms Start:2018-08-27 11:18:24.771203784 +0000 UTC m=+421.021584783 End:2018-08-27 11:18:24.785094328 +0000 UTC m=+421.035475322
I0827 11:18:24.785139       1 scheduler.go:454] Total Schedule Algo cumulative time:200.633166ms for 15
W0827 11:18:56.787269       1 factory.go:1324] A pod default/nginx-pod-affinity-pod-0-3-p29mr no longer exists
I0827 11:20:24.640405       1 scheduler.go:451] ScheduleAlgoTime 15.328078ms Start:2018-08-27 11:20:24.625063279 +0000 UTC m=+540.875444365 End:2018-08-27 11:20:24.64039145 +0000 UTC m=+540.890772443
I0827 11:20:24.640467       1 scheduler.go:454] Total Schedule Algo cumulative time:215.961244ms for 16
I0827 11:31:54.182670       1 flags.go:27] FLAG: --address=""
I0827 11:31:54.183391       1 flags.go:27] FLAG: --algorithm-provider=""
I0827 11:31:54.183404       1 flags.go:27] FLAG: --alsologtostderr="false"
I0827 11:31:54.183416       1 flags.go:27] FLAG: --config=""
I0827 11:31:54.183424       1 flags.go:27] FLAG: --contention-profiling="false"
I0827 11:31:54.183442       1 flags.go:27] FLAG: --failure-domains="kubernetes.io/hostname,failure-domain.beta.kubernetes.io/zone,failure-domain.beta.kubernetes.io/region"
I0827 11:31:54.183470       1 flags.go:27] FLAG: --feature-gates=""
I0827 11:31:54.183488       1 flags.go:27] FLAG: --hard-pod-affinity-symmetric-weight="1"
I0827 11:31:54.183500       1 flags.go:27] FLAG: --help="false"
I0827 11:31:54.183507       1 flags.go:27] FLAG: --kube-api-burst="100"
I0827 11:31:54.183515       1 flags.go:27] FLAG: --kube-api-content-type="application/vnd.kubernetes.protobuf"
I0827 11:31:54.183523       1 flags.go:27] FLAG: --kube-api-qps="50"
I0827 11:31:54.183535       1 flags.go:27] FLAG: --kubeconfig="/etc/srv/kubernetes/kube-scheduler/kubeconfig"
I0827 11:31:54.183543       1 flags.go:27] FLAG: --leader-elect="true"
I0827 11:31:54.183551       1 flags.go:27] FLAG: --leader-elect-lease-duration="15s"
I0827 11:31:54.183560       1 flags.go:27] FLAG: --leader-elect-renew-deadline="10s"
I0827 11:31:54.183568       1 flags.go:27] FLAG: --leader-elect-resource-lock="endpoints"
I0827 11:31:54.183575       1 flags.go:27] FLAG: --leader-elect-retry-period="2s"
I0827 11:31:54.183583       1 flags.go:27] FLAG: --lock-object-name="kube-scheduler"
I0827 11:31:54.183590       1 flags.go:27] FLAG: --lock-object-namespace="kube-system"
I0827 11:31:54.183597       1 flags.go:27] FLAG: --log-backtrace-at=":0"
I0827 11:31:54.183609       1 flags.go:27] FLAG: --log-dir=""
I0827 11:31:54.183618       1 flags.go:27] FLAG: --log-flush-frequency="5s"
I0827 11:31:54.183625       1 flags.go:27] FLAG: --logtostderr="true"
I0827 11:31:54.183659       1 flags.go:27] FLAG: --master=""
I0827 11:31:54.183668       1 flags.go:27] FLAG: --policy-config-file=""
I0827 11:31:54.183675       1 flags.go:27] FLAG: --policy-configmap=""
I0827 11:31:54.183692       1 flags.go:27] FLAG: --policy-configmap-namespace=""
I0827 11:31:54.183699       1 flags.go:27] FLAG: --port="10251"
I0827 11:31:54.183707       1 flags.go:27] FLAG: --profiling="false"
I0827 11:31:54.183714       1 flags.go:27] FLAG: --scheduler-name="default-scheduler"
I0827 11:31:54.183722       1 flags.go:27] FLAG: --stderrthreshold="2"
I0827 11:31:54.183730       1 flags.go:27] FLAG: --use-legacy-policy-config="false"
I0827 11:31:54.183738       1 flags.go:27] FLAG: --v="2"
I0827 11:31:54.183745       1 flags.go:27] FLAG: --version="false"
I0827 11:31:54.183757       1 flags.go:27] FLAG: --vmodule=""
W0827 11:31:54.183773       1 server.go:163] WARNING: all flags other than --config are deprecated. Please begin using a config file ASAP.
I0827 11:31:54.187095       1 server.go:555] Version: v1.10.4
I0827 11:31:54.187358       1 factory.go:922] Creating scheduler from algorithm provider 'DefaultProvider'
I0827 11:31:54.187369       1 factory.go:1022] Creating scheduler with fit predicates 'map[NoVolumeZoneConflict:{} MaxEBSVolumeCount:{} MaxAzureDiskVolumeCount:{} NoDiskConflict:{} GeneralPredicates:{} MaxGCEPDVolumeCount:{} MatchInterPodAffinity:{} CheckNodeMemoryPressure:{} CheckNodeDiskPressure:{} CheckNodeCondition:{} PodToleratesNodeTaints:{} CheckVolumeBinding:{}]' and priority functions 'map[LeastRequestedPriority:{} BalancedResourceAllocation:{} NodePreferAvoidPodsPriority:{} NodeAffinityPriority:{} TaintTolerationPriority:{} SelectorSpreadPriority:{} InterPodAffinityPriority:{}]'
I0827 11:31:54.188837       1 server.go:574] starting healthz server on 0.0.0.0:10251
I0827 11:31:55.089381       1 controller_utils.go:1019] Waiting for caches to sync for scheduler controller
I0827 11:31:55.189556       1 controller_utils.go:1026] Caches are synced for scheduler controller
I0827 11:31:55.189598       1 leaderelection.go:175] attempting to acquire leader lease  kube-system/kube-scheduler...
I0827 11:32:13.845557       1 leaderelection.go:184] successfully acquired lease kube-system/kube-scheduler
I0827 11:32:22.144167       1 scheduler.go:451] ScheduleAlgoTime 2.985343ms Start:2018-08-27 11:32:22.141171587 +0000 UTC m=+28.010478863 End:2018-08-27 11:32:22.144157024 +0000 UTC m=+28.013464206
I0827 11:32:22.144222       1 scheduler.go:454] Total Schedule Algo cumulative time:2.985343ms for 1
I0827 11:32:22.147341       1 scheduler.go:451] ScheduleAlgoTime 2.584323ms Start:2018-08-27 11:32:22.144744391 +0000 UTC m=+28.014051661 End:2018-08-27 11:32:22.147328791 +0000 UTC m=+28.016635984
I0827 11:32:22.147387       1 scheduler.go:454] Total Schedule Algo cumulative time:5.569666ms for 2
I0827 11:32:22.150954       1 scheduler.go:451] ScheduleAlgoTime 3.369886ms Start:2018-08-27 11:32:22.147572128 +0000 UTC m=+28.016879385 End:2018-08-27 11:32:22.15094207 +0000 UTC m=+28.020249271
I0827 11:32:22.151143       1 scheduler.go:454] Total Schedule Algo cumulative time:8.939552ms for 3
I0827 11:32:22.154773       1 scheduler.go:451] ScheduleAlgoTime 2.205986ms Start:2018-08-27 11:32:22.152558933 +0000 UTC m=+28.021866179 End:2018-08-27 11:32:22.154764982 +0000 UTC m=+28.024072165
I0827 11:32:22.154822       1 scheduler.go:454] Total Schedule Algo cumulative time:11.145538ms for 4
I0827 11:32:22.158070       1 scheduler.go:451] ScheduleAlgoTime 2.898559ms Start:2018-08-27 11:32:22.155163775 +0000 UTC m=+28.024471076 End:2018-08-27 11:32:22.158062453 +0000 UTC m=+28.027369635
I0827 11:32:22.158099       1 scheduler.go:454] Total Schedule Algo cumulative time:14.044097ms for 5
I0827 11:32:22.161058       1 scheduler.go:451] ScheduleAlgoTime 2.617868ms Start:2018-08-27 11:32:22.158430812 +0000 UTC m=+28.027738119 End:2018-08-27 11:32:22.161048789 +0000 UTC m=+28.030355987
I0827 11:32:22.161101       1 scheduler.go:454] Total Schedule Algo cumulative time:16.661965ms for 6
I0827 11:32:22.163506       1 scheduler.go:451] ScheduleAlgoTime 2.07308ms Start:2018-08-27 11:32:22.161425114 +0000 UTC m=+28.030732332 End:2018-08-27 11:32:22.163498228 +0000 UTC m=+28.032805412
I0827 11:32:22.163542       1 scheduler.go:454] Total Schedule Algo cumulative time:18.735045ms for 7
I0827 11:32:22.167142       1 scheduler.go:451] ScheduleAlgoTime 3.342388ms Start:2018-08-27 11:32:22.163790876 +0000 UTC m=+28.033098111 End:2018-08-27 11:32:22.167133315 +0000 UTC m=+28.036440499
I0827 11:32:22.167180       1 scheduler.go:454] Total Schedule Algo cumulative time:22.077433ms for 8
I0827 11:32:22.175916       1 scheduler.go:451] ScheduleAlgoTime 8.288456ms Start:2018-08-27 11:32:22.167616007 +0000 UTC m=+28.036923277 End:2018-08-27 11:32:22.175904413 +0000 UTC m=+28.045211733
I0827 11:32:22.175973       1 scheduler.go:454] Total Schedule Algo cumulative time:30.365889ms for 9
I0827 11:32:22.178161       1 scheduler.go:451] ScheduleAlgoTime 1.983299ms Start:2018-08-27 11:32:22.17617038 +0000 UTC m=+28.045477604 End:2018-08-27 11:32:22.178153714 +0000 UTC m=+28.047460903
I0827 11:32:22.178212       1 scheduler.go:454] Total Schedule Algo cumulative time:32.349188ms for 10
I0827 11:32:22.182101       1 scheduler.go:451] ScheduleAlgoTime 3.66705ms Start:2018-08-27 11:32:22.178425541 +0000 UTC m=+28.047732825 End:2018-08-27 11:32:22.182092691 +0000 UTC m=+28.051399875
I0827 11:32:22.182135       1 scheduler.go:454] Total Schedule Algo cumulative time:36.016238ms for 11
I0827 11:32:22.185345       1 scheduler.go:451] ScheduleAlgoTime 2.866148ms Start:2018-08-27 11:32:22.182472088 +0000 UTC m=+28.051779273 End:2018-08-27 11:32:22.185338237 +0000 UTC m=+28.054645421
I0827 11:32:22.185390       1 scheduler.go:454] Total Schedule Algo cumulative time:38.882386ms for 12
I0827 11:32:22.187735       1 scheduler.go:451] ScheduleAlgoTime 2.230623ms Start:2018-08-27 11:32:22.185494185 +0000 UTC m=+28.054801435 End:2018-08-27 11:32:22.187724874 +0000 UTC m=+28.057032058
I0827 11:32:22.187827       1 scheduler.go:454] Total Schedule Algo cumulative time:41.113009ms for 13
I0827 11:32:22.189928       1 scheduler.go:451] ScheduleAlgoTime 1.905633ms Start:2018-08-27 11:32:22.18801517 +0000 UTC m=+28.057322386 End:2018-08-27 11:32:22.189920836 +0000 UTC m=+28.059228019
I0827 11:32:22.189955       1 scheduler.go:454] Total Schedule Algo cumulative time:43.018642ms for 14
I0827 11:32:22.192374       1 scheduler.go:451] ScheduleAlgoTime 2.183231ms Start:2018-08-27 11:32:22.190179417 +0000 UTC m=+28.059486616 End:2018-08-27 11:32:22.192362647 +0000 UTC m=+28.061669847
I0827 11:32:22.192421       1 scheduler.go:454] Total Schedule Algo cumulative time:45.201873ms for 15
I0827 11:32:22.195468       1 scheduler.go:451] ScheduleAlgoTime 2.812557ms Start:2018-08-27 11:32:22.192649104 +0000 UTC m=+28.061956308 End:2018-08-27 11:32:22.195461684 +0000 UTC m=+28.064768865
I0827 11:32:22.195491       1 scheduler.go:454] Total Schedule Algo cumulative time:48.01443ms for 16
I0827 11:32:22.199032       1 scheduler.go:451] ScheduleAlgoTime 2.900358ms Start:2018-08-27 11:32:22.196121046 +0000 UTC m=+28.065428316 End:2018-08-27 11:32:22.19902148 +0000 UTC m=+28.068328674
I0827 11:32:22.199221       1 scheduler.go:454] Total Schedule Algo cumulative time:50.914788ms for 17
I0827 11:32:22.202898       1 scheduler.go:451] ScheduleAlgoTime 3.500389ms Start:2018-08-27 11:32:22.199392153 +0000 UTC m=+28.068699447 End:2018-08-27 11:32:22.202892651 +0000 UTC m=+28.072199836
I0827 11:32:22.202929       1 scheduler.go:454] Total Schedule Algo cumulative time:54.415177ms for 18
I0827 11:32:22.207008       1 scheduler.go:451] ScheduleAlgoTime 3.835405ms Start:2018-08-27 11:32:22.203163215 +0000 UTC m=+28.072470480 End:2018-08-27 11:32:22.206998702 +0000 UTC m=+28.076305885
I0827 11:32:22.207041       1 scheduler.go:454] Total Schedule Algo cumulative time:58.250582ms for 19
I0827 11:32:22.212473       1 scheduler.go:451] ScheduleAlgoTime 5.125899ms Start:2018-08-27 11:32:22.207335108 +0000 UTC m=+28.076642336 End:2018-08-27 11:32:22.212461036 +0000 UTC m=+28.081768235
I0827 11:32:22.212586       1 scheduler.go:454] Total Schedule Algo cumulative time:63.376481ms for 20
I0827 11:32:22.221861       1 scheduler.go:451] ScheduleAlgoTime 8.964677ms Start:2018-08-27 11:32:22.212884491 +0000 UTC m=+28.082191707 End:2018-08-27 11:32:22.221849189 +0000 UTC m=+28.091156384
I0827 11:32:22.221916       1 scheduler.go:454] Total Schedule Algo cumulative time:72.341158ms for 21
I0827 11:32:22.225617       1 scheduler.go:451] ScheduleAlgoTime 3.097629ms Start:2018-08-27 11:32:22.222510387 +0000 UTC m=+28.091817600 End:2018-08-27 11:32:22.225608048 +0000 UTC m=+28.094915229
I0827 11:32:22.225646       1 scheduler.go:454] Total Schedule Algo cumulative time:75.438787ms for 22
I0827 11:32:22.228200       1 scheduler.go:451] ScheduleAlgoTime 2.249475ms Start:2018-08-27 11:32:22.225940838 +0000 UTC m=+28.095248127 End:2018-08-27 11:32:22.22819041 +0000 UTC m=+28.097497602
I0827 11:32:22.228237       1 scheduler.go:454] Total Schedule Algo cumulative time:77.688262ms for 23
I0827 11:32:22.232674       1 scheduler.go:451] ScheduleAlgoTime 3.077664ms Start:2018-08-27 11:32:22.229588538 +0000 UTC m=+28.098895742 End:2018-08-27 11:32:22.232666225 +0000 UTC m=+28.101973406
I0827 11:32:22.232743       1 scheduler.go:454] Total Schedule Algo cumulative time:80.765926ms for 24
I0827 11:32:22.235520       1 scheduler.go:451] ScheduleAlgoTime 2.618257ms Start:2018-08-27 11:32:22.232890048 +0000 UTC m=+28.102197314 End:2018-08-27 11:32:22.235508289 +0000 UTC m=+28.104815571
I0827 11:32:22.235557       1 scheduler.go:454] Total Schedule Algo cumulative time:83.384183ms for 25
I0827 11:32:22.239724       1 scheduler.go:451] ScheduleAlgoTime 3.698657ms Start:2018-08-27 11:32:22.235970375 +0000 UTC m=+28.105277581 End:2018-08-27 11:32:22.239669041 +0000 UTC m=+28.108976238
I0827 11:32:22.239764       1 scheduler.go:454] Total Schedule Algo cumulative time:87.08284ms for 26
I0827 11:32:22.242015       1 scheduler.go:451] ScheduleAlgoTime 2.15724ms Start:2018-08-27 11:32:22.239850781 +0000 UTC m=+28.109157994 End:2018-08-27 11:32:22.24200805 +0000 UTC m=+28.111315234
I0827 11:32:22.242044       1 scheduler.go:454] Total Schedule Algo cumulative time:89.24008ms for 27
I0827 11:32:22.245109       1 scheduler.go:451] ScheduleAlgoTime 2.384389ms Start:2018-08-27 11:32:22.242717728 +0000 UTC m=+28.112024959 End:2018-08-27 11:32:22.245102165 +0000 UTC m=+28.114409348
I0827 11:32:22.245138       1 scheduler.go:454] Total Schedule Algo cumulative time:91.624469ms for 28
I0827 11:32:22.248431       1 scheduler.go:451] ScheduleAlgoTime 3.009309ms Start:2018-08-27 11:32:22.245412377 +0000 UTC m=+28.114719600 End:2018-08-27 11:32:22.248421716 +0000 UTC m=+28.117728909
I0827 11:32:22.248470       1 scheduler.go:454] Total Schedule Algo cumulative time:94.633778ms for 29
I0827 11:32:22.251450       1 scheduler.go:451] ScheduleAlgoTime 2.784205ms Start:2018-08-27 11:32:22.24865576 +0000 UTC m=+28.117963019 End:2018-08-27 11:32:22.251440029 +0000 UTC m=+28.120747224
I0827 11:32:22.251485       1 scheduler.go:454] Total Schedule Algo cumulative time:97.417983ms for 30
I0827 11:32:22.254646       1 scheduler.go:451] ScheduleAlgoTime 2.917723ms Start:2018-08-27 11:32:22.251720174 +0000 UTC m=+28.121027380 End:2018-08-27 11:32:22.254637918 +0000 UTC m=+28.123945103
I0827 11:32:22.254675       1 scheduler.go:454] Total Schedule Algo cumulative time:100.335706ms for 31
I0827 11:32:22.259172       1 scheduler.go:451] ScheduleAlgoTime 4.203699ms Start:2018-08-27 11:32:22.254956652 +0000 UTC m=+28.124263865 End:2018-08-27 11:32:22.259160373 +0000 UTC m=+28.128467564
I0827 11:32:22.259215       1 scheduler.go:454] Total Schedule Algo cumulative time:104.539405ms for 32
I0827 11:32:22.262790       1 scheduler.go:451] ScheduleAlgoTime 3.372687ms Start:2018-08-27 11:32:22.259405884 +0000 UTC m=+28.128713179 End:2018-08-27 11:32:22.262778569 +0000 UTC m=+28.132085866
I0827 11:32:22.262826       1 scheduler.go:454] Total Schedule Algo cumulative time:107.912092ms for 33
I0827 11:32:22.267498       1 scheduler.go:451] ScheduleAlgoTime 4.364188ms Start:2018-08-27 11:32:22.263122959 +0000 UTC m=+28.132430178 End:2018-08-27 11:32:22.267487075 +0000 UTC m=+28.136794366
I0827 11:32:22.267536       1 scheduler.go:454] Total Schedule Algo cumulative time:112.27628ms for 34
I0827 11:32:22.273268       1 scheduler.go:451] ScheduleAlgoTime 5.540345ms Start:2018-08-27 11:32:22.267712423 +0000 UTC m=+28.137019721 End:2018-08-27 11:32:22.273252873 +0000 UTC m=+28.142560066
I0827 11:32:22.273376       1 scheduler.go:454] Total Schedule Algo cumulative time:117.816625ms for 35
I0827 11:32:22.280985       1 scheduler.go:451] ScheduleAlgoTime 7.106993ms Start:2018-08-27 11:32:22.273866528 +0000 UTC m=+28.143173714 End:2018-08-27 11:32:22.280973513 +0000 UTC m=+28.150280707
I0827 11:32:22.281038       1 scheduler.go:454] Total Schedule Algo cumulative time:124.923618ms for 36
I0827 11:32:22.283996       1 scheduler.go:451] ScheduleAlgoTime 2.546732ms Start:2018-08-27 11:32:22.281440256 +0000 UTC m=+28.150747494 End:2018-08-27 11:32:22.283987044 +0000 UTC m=+28.153294226
I0827 11:32:22.284035       1 scheduler.go:454] Total Schedule Algo cumulative time:127.47035ms for 37
I0827 11:32:22.286777       1 scheduler.go:451] ScheduleAlgoTime 2.329767ms Start:2018-08-27 11:32:22.284432512 +0000 UTC m=+28.153739775 End:2018-08-27 11:32:22.286762353 +0000 UTC m=+28.156069542
I0827 11:32:22.286813       1 scheduler.go:454] Total Schedule Algo cumulative time:129.800117ms for 38
I0827 11:32:22.289488       1 scheduler.go:451] ScheduleAlgoTime 2.194725ms Start:2018-08-27 11:32:22.287284546 +0000 UTC m=+28.156591756 End:2018-08-27 11:32:22.289479298 +0000 UTC m=+28.158786481
I0827 11:32:22.289594       1 scheduler.go:454] Total Schedule Algo cumulative time:131.994842ms for 39
I0827 11:32:22.292193       1 scheduler.go:451] ScheduleAlgoTime 2.360119ms Start:2018-08-27 11:32:22.28982364 +0000 UTC m=+28.159130857 End:2018-08-27 11:32:22.292183792 +0000 UTC m=+28.161490976
I0827 11:32:22.292223       1 scheduler.go:454] Total Schedule Algo cumulative time:134.354961ms for 40
I0827 11:32:22.294504       1 scheduler.go:451] ScheduleAlgoTime 1.882575ms Start:2018-08-27 11:32:22.29260906 +0000 UTC m=+28.161916308 End:2018-08-27 11:32:22.2944917 +0000 UTC m=+28.163798883
I0827 11:32:22.294563       1 scheduler.go:454] Total Schedule Algo cumulative time:136.237536ms for 41
I0827 11:32:22.296779       1 scheduler.go:451] ScheduleAlgoTime 1.943057ms Start:2018-08-27 11:32:22.294826353 +0000 UTC m=+28.164133571 End:2018-08-27 11:32:22.296769384 +0000 UTC m=+28.166076628
I0827 11:32:22.296813       1 scheduler.go:454] Total Schedule Algo cumulative time:138.180593ms for 42
I0827 11:32:22.299438       1 scheduler.go:451] ScheduleAlgoTime 2.357572ms Start:2018-08-27 11:32:22.297071689 +0000 UTC m=+28.166378980 End:2018-08-27 11:32:22.299429098 +0000 UTC m=+28.168736552
I0827 11:32:22.299472       1 scheduler.go:454] Total Schedule Algo cumulative time:140.538165ms for 43
I0827 11:32:22.301597       1 scheduler.go:451] ScheduleAlgoTime 1.865752ms Start:2018-08-27 11:32:22.299723028 +0000 UTC m=+28.169030246 End:2018-08-27 11:32:22.301588814 +0000 UTC m=+28.170895998
I0827 11:32:22.301638       1 scheduler.go:454] Total Schedule Algo cumulative time:142.403917ms for 44
I0827 11:32:22.304203       1 scheduler.go:451] ScheduleAlgoTime 2.239523ms Start:2018-08-27 11:32:22.301954462 +0000 UTC m=+28.171261720 End:2018-08-27 11:32:22.304194058 +0000 UTC m=+28.173501243
I0827 11:32:22.304235       1 scheduler.go:454] Total Schedule Algo cumulative time:144.64344ms for 45
I0827 11:32:22.306507       1 scheduler.go:451] ScheduleAlgoTime 2.024422ms Start:2018-08-27 11:32:22.304471569 +0000 UTC m=+28.173778835 End:2018-08-27 11:32:22.306496062 +0000 UTC m=+28.175803257
I0827 11:32:22.306541       1 scheduler.go:454] Total Schedule Algo cumulative time:146.667862ms for 46
I0827 11:32:22.309674       1 scheduler.go:451] ScheduleAlgoTime 2.844293ms Start:2018-08-27 11:32:22.30681926 +0000 UTC m=+28.176126510 End:2018-08-27 11:32:22.309663615 +0000 UTC m=+28.178970803
I0827 11:32:22.309762       1 scheduler.go:454] Total Schedule Algo cumulative time:149.512155ms for 47
I0827 11:32:22.312155       1 scheduler.go:451] ScheduleAlgoTime 2.0344ms Start:2018-08-27 11:32:22.310113918 +0000 UTC m=+28.179421151 End:2018-08-27 11:32:22.312148368 +0000 UTC m=+28.181455551
I0827 11:32:22.312185       1 scheduler.go:454] Total Schedule Algo cumulative time:151.546555ms for 48
I0827 11:32:22.314892       1 scheduler.go:451] ScheduleAlgoTime 2.542362ms Start:2018-08-27 11:32:22.312339374 +0000 UTC m=+28.181646608 End:2018-08-27 11:32:22.31488132 +0000 UTC m=+28.184188970
I0827 11:32:22.314927       1 scheduler.go:454] Total Schedule Algo cumulative time:154.088917ms for 49
I0827 11:32:22.318266       1 scheduler.go:451] ScheduleAlgoTime 3.000022ms Start:2018-08-27 11:32:22.315257126 +0000 UTC m=+28.184564357 End:2018-08-27 11:32:22.318257197 +0000 UTC m=+28.187564379
I0827 11:32:22.318298       1 scheduler.go:454] Total Schedule Algo cumulative time:157.088939ms for 50
I0827 11:32:22.321405       1 scheduler.go:451] ScheduleAlgoTime 2.876804ms Start:2018-08-27 11:32:22.318520327 +0000 UTC m=+28.187827563 End:2018-08-27 11:32:22.321397179 +0000 UTC m=+28.190704367
I0827 11:32:22.321436       1 scheduler.go:454] Total Schedule Algo cumulative time:159.965743ms for 51
I0827 11:32:22.325273       1 scheduler.go:451] ScheduleAlgoTime 3.234103ms Start:2018-08-27 11:32:22.322029084 +0000 UTC m=+28.191336318 End:2018-08-27 11:32:22.325263231 +0000 UTC m=+28.194570421
I0827 11:32:22.325357       1 scheduler.go:454] Total Schedule Algo cumulative time:163.199846ms for 52
I0827 11:32:22.334840       1 scheduler.go:451] ScheduleAlgoTime 9.250721ms Start:2018-08-27 11:32:22.325578425 +0000 UTC m=+28.194885640 End:2018-08-27 11:32:22.334829179 +0000 UTC m=+28.204136361
I0827 11:32:22.334890       1 scheduler.go:454] Total Schedule Algo cumulative time:172.450567ms for 53
I0827 11:32:22.338463       1 scheduler.go:451] ScheduleAlgoTime 3.341948ms Start:2018-08-27 11:32:22.335111843 +0000 UTC m=+28.204419120 End:2018-08-27 11:32:22.338453886 +0000 UTC m=+28.207761068
I0827 11:32:22.338506       1 scheduler.go:454] Total Schedule Algo cumulative time:175.792515ms for 54
I0827 11:32:22.341088       1 scheduler.go:451] ScheduleAlgoTime 2.295289ms Start:2018-08-27 11:32:22.33878483 +0000 UTC m=+28.208092059 End:2018-08-27 11:32:22.34108016 +0000 UTC m=+28.210387348
I0827 11:32:22.341130       1 scheduler.go:454] Total Schedule Algo cumulative time:178.087804ms for 55
I0827 11:32:22.345906       1 scheduler.go:451] ScheduleAlgoTime 2.948243ms Start:2018-08-27 11:32:22.342946995 +0000 UTC m=+28.212254238 End:2018-08-27 11:32:22.345895286 +0000 UTC m=+28.215202481
I0827 11:32:22.345954       1 scheduler.go:454] Total Schedule Algo cumulative time:181.036047ms for 56
I0827 11:32:22.349492       1 scheduler.go:451] ScheduleAlgoTime 3.216954ms Start:2018-08-27 11:32:22.346266286 +0000 UTC m=+28.215573528 End:2018-08-27 11:32:22.349483286 +0000 UTC m=+28.218790482
I0827 11:32:22.349527       1 scheduler.go:454] Total Schedule Algo cumulative time:184.253001ms for 57
I0827 11:32:22.353595       1 scheduler.go:451] ScheduleAlgoTime 3.844288ms Start:2018-08-27 11:32:22.349739998 +0000 UTC m=+28.219047238 End:2018-08-27 11:32:22.353584343 +0000 UTC m=+28.222891526
I0827 11:32:22.353646       1 scheduler.go:454] Total Schedule Algo cumulative time:188.097289ms for 58
I0827 11:32:22.357002       1 scheduler.go:451] ScheduleAlgoTime 2.942521ms Start:2018-08-27 11:32:22.354047551 +0000 UTC m=+28.223354763 End:2018-08-27 11:32:22.356990064 +0000 UTC m=+28.226297284
I0827 11:32:22.357043       1 scheduler.go:454] Total Schedule Algo cumulative time:191.03981ms for 59
I0827 11:32:22.362414       1 scheduler.go:451] ScheduleAlgoTime 4.997095ms Start:2018-08-27 11:32:22.35740649 +0000 UTC m=+28.226713764 End:2018-08-27 11:32:22.362403676 +0000 UTC m=+28.231710859
I0827 11:32:22.362453       1 scheduler.go:454] Total Schedule Algo cumulative time:196.036905ms for 60
I0827 11:32:22.367375       1 scheduler.go:451] ScheduleAlgoTime 4.689262ms Start:2018-08-27 11:32:22.362671982 +0000 UTC m=+28.231979197 End:2018-08-27 11:32:22.367361185 +0000 UTC m=+28.236668459
I0827 11:32:22.367418       1 scheduler.go:454] Total Schedule Algo cumulative time:200.726167ms for 61
I0827 11:32:22.370034       1 scheduler.go:451] ScheduleAlgoTime 2.304461ms Start:2018-08-27 11:32:22.367722403 +0000 UTC m=+28.237029648 End:2018-08-27 11:32:22.370026927 +0000 UTC m=+28.239334109
I0827 11:32:22.370063       1 scheduler.go:454] Total Schedule Algo cumulative time:203.030628ms for 62
I0827 11:32:22.374119       1 scheduler.go:451] ScheduleAlgoTime 3.571636ms Start:2018-08-27 11:32:22.370536474 +0000 UTC m=+28.239843683 End:2018-08-27 11:32:22.374108138 +0000 UTC m=+28.243415319
I0827 11:32:22.374164       1 scheduler.go:454] Total Schedule Algo cumulative time:206.602264ms for 63
I0827 11:32:22.378804       1 scheduler.go:451] ScheduleAlgoTime 3.547248ms Start:2018-08-27 11:32:22.375248286 +0000 UTC m=+28.244555508 End:2018-08-27 11:32:22.378795573 +0000 UTC m=+28.248102756
I0827 11:32:22.378835       1 scheduler.go:454] Total Schedule Algo cumulative time:210.149512ms for 64
I0827 11:32:22.381174       1 scheduler.go:451] ScheduleAlgoTime 1.944971ms Start:2018-08-27 11:32:22.37922322 +0000 UTC m=+28.248530417 End:2018-08-27 11:32:22.381168206 +0000 UTC m=+28.250475388
I0827 11:32:22.381197       1 scheduler.go:454] Total Schedule Algo cumulative time:212.094483ms for 65
I0827 11:32:22.384136       1 scheduler.go:451] ScheduleAlgoTime 2.829571ms Start:2018-08-27 11:32:22.381298546 +0000 UTC m=+28.250605796 End:2018-08-27 11:32:22.384128185 +0000 UTC m=+28.253435367
I0827 11:32:22.384204       1 scheduler.go:454] Total Schedule Algo cumulative time:214.924054ms for 66
I0827 11:32:22.387390       1 scheduler.go:451] ScheduleAlgoTime 2.901609ms Start:2018-08-27 11:32:22.38448047 +0000 UTC m=+28.253787755 End:2018-08-27 11:32:22.38738218 +0000 UTC m=+28.256689364
I0827 11:32:22.387415       1 scheduler.go:454] Total Schedule Algo cumulative time:217.825663ms for 67
I0827 11:32:22.396945       1 scheduler.go:451] ScheduleAlgoTime 9.271987ms Start:2018-08-27 11:32:22.387658507 +0000 UTC m=+28.256965749 End:2018-08-27 11:32:22.396930352 +0000 UTC m=+28.266237736
I0827 11:32:22.397008       1 scheduler.go:454] Total Schedule Algo cumulative time:227.09765ms for 68
I0827 11:32:22.401603       1 scheduler.go:451] ScheduleAlgoTime 4.272016ms Start:2018-08-27 11:32:22.397317257 +0000 UTC m=+28.266624547 End:2018-08-27 11:32:22.40158927 +0000 UTC m=+28.270896563
I0827 11:32:22.401649       1 scheduler.go:454] Total Schedule Algo cumulative time:231.369666ms for 69
I0827 11:32:22.405755       1 scheduler.go:451] ScheduleAlgoTime 3.616919ms Start:2018-08-27 11:32:22.402125344 +0000 UTC m=+28.271432588 End:2018-08-27 11:32:22.405742247 +0000 UTC m=+28.275049507
I0827 11:32:22.405810       1 scheduler.go:454] Total Schedule Algo cumulative time:234.986585ms for 70
I0827 11:32:22.408888       1 scheduler.go:451] ScheduleAlgoTime 2.857268ms Start:2018-08-27 11:32:22.406021091 +0000 UTC m=+28.275328336 End:2018-08-27 11:32:22.408878421 +0000 UTC m=+28.278185604
I0827 11:32:22.408922       1 scheduler.go:454] Total Schedule Algo cumulative time:237.843853ms for 71
I0827 11:32:22.411767       1 scheduler.go:451] ScheduleAlgoTime 2.585324ms Start:2018-08-27 11:32:22.409168304 +0000 UTC m=+28.278475499 End:2018-08-27 11:32:22.411753551 +0000 UTC m=+28.281060823
I0827 11:32:22.411833       1 scheduler.go:454] Total Schedule Algo cumulative time:240.429177ms for 72
I0827 11:32:22.414058       1 scheduler.go:451] ScheduleAlgoTime 2.001965ms Start:2018-08-27 11:32:22.412048552 +0000 UTC m=+28.281355799 End:2018-08-27 11:32:22.414050579 +0000 UTC m=+28.283357764
I0827 11:32:22.414101       1 scheduler.go:454] Total Schedule Algo cumulative time:242.431142ms for 73
I0827 11:32:22.418558       1 scheduler.go:451] ScheduleAlgoTime 4.168883ms Start:2018-08-27 11:32:22.414378644 +0000 UTC m=+28.283685920 End:2018-08-27 11:32:22.41854762 +0000 UTC m=+28.287854803
I0827 11:32:22.418592       1 scheduler.go:454] Total Schedule Algo cumulative time:246.600025ms for 74
I0827 11:32:22.421600       1 scheduler.go:451] ScheduleAlgoTime 2.819105ms Start:2018-08-27 11:32:22.418772422 +0000 UTC m=+28.288079630 End:2018-08-27 11:32:22.42159155 +0000 UTC m=+28.290898735
I0827 11:32:22.421638       1 scheduler.go:454] Total Schedule Algo cumulative time:249.41913ms for 75
I0827 11:32:22.426033       1 scheduler.go:451] ScheduleAlgoTime 2.538712ms Start:2018-08-27 11:32:22.423482931 +0000 UTC m=+28.292790211 End:2018-08-27 11:32:22.426021742 +0000 UTC m=+28.295328923
I0827 11:32:22.426069       1 scheduler.go:454] Total Schedule Algo cumulative time:251.957842ms for 76
I0827 11:32:22.429083       1 scheduler.go:451] ScheduleAlgoTime 2.666386ms Start:2018-08-27 11:32:22.426409435 +0000 UTC m=+28.295716629 End:2018-08-27 11:32:22.429075832 +0000 UTC m=+28.298383015
I0827 11:32:22.429112       1 scheduler.go:454] Total Schedule Algo cumulative time:254.624228ms for 77
I0827 11:32:22.431795       1 scheduler.go:451] ScheduleAlgoTime 2.310688ms Start:2018-08-27 11:32:22.429475741 +0000 UTC m=+28.298783010 End:2018-08-27 11:32:22.431786449 +0000 UTC m=+28.301093698
I0827 11:32:22.431837       1 scheduler.go:454] Total Schedule Algo cumulative time:256.934916ms for 78
I0827 11:32:22.434305       1 scheduler.go:451] ScheduleAlgoTime 2.01888ms Start:2018-08-27 11:32:22.432278866 +0000 UTC m=+28.301586080 End:2018-08-27 11:32:22.434297776 +0000 UTC m=+28.303604960
I0827 11:32:22.434331       1 scheduler.go:454] Total Schedule Algo cumulative time:258.953796ms for 79
I0827 11:32:22.438006       1 scheduler.go:451] ScheduleAlgoTime 3.134493ms Start:2018-08-27 11:32:22.4348622 +0000 UTC m=+28.304169500 End:2018-08-27 11:32:22.437996811 +0000 UTC m=+28.307303993
I0827 11:32:22.438055       1 scheduler.go:454] Total Schedule Algo cumulative time:262.088289ms for 80
I0827 11:32:22.441244       1 scheduler.go:451] ScheduleAlgoTime 2.377934ms Start:2018-08-27 11:32:22.438857561 +0000 UTC m=+28.308164820 End:2018-08-27 11:32:22.441235569 +0000 UTC m=+28.310542754
I0827 11:32:22.441294       1 scheduler.go:454] Total Schedule Algo cumulative time:264.466223ms for 81
I0827 11:32:22.448079       1 scheduler.go:451] ScheduleAlgoTime 5.202085ms Start:2018-08-27 11:32:22.442865314 +0000 UTC m=+28.312172571 End:2018-08-27 11:32:22.448067327 +0000 UTC m=+28.317374656
I0827 11:32:22.448114       1 scheduler.go:454] Total Schedule Algo cumulative time:269.668308ms for 82
I0827 11:32:22.452325       1 scheduler.go:451] ScheduleAlgoTime 3.657957ms Start:2018-08-27 11:32:22.448655526 +0000 UTC m=+28.317962756 End:2018-08-27 11:32:22.45231352 +0000 UTC m=+28.321620713
I0827 11:32:22.452369       1 scheduler.go:454] Total Schedule Algo cumulative time:273.326265ms for 83
I0827 11:32:22.455898       1 scheduler.go:451] ScheduleAlgoTime 3.19016ms Start:2018-08-27 11:32:22.452698874 +0000 UTC m=+28.322006131 End:2018-08-27 11:32:22.455889109 +0000 UTC m=+28.325196291
I0827 11:32:22.455931       1 scheduler.go:454] Total Schedule Algo cumulative time:276.516425ms for 84
I0827 11:32:22.459089       1 scheduler.go:451] ScheduleAlgoTime 2.81852ms Start:2018-08-27 11:32:22.456261974 +0000 UTC m=+28.325569181 End:2018-08-27 11:32:22.459080519 +0000 UTC m=+28.328387701
I0827 11:32:22.459122       1 scheduler.go:454] Total Schedule Algo cumulative time:279.334945ms for 85
I0827 11:32:22.462426       1 scheduler.go:451] ScheduleAlgoTime 2.98297ms Start:2018-08-27 11:32:22.459432201 +0000 UTC m=+28.328739445 End:2018-08-27 11:32:22.462415093 +0000 UTC m=+28.331722415
I0827 11:32:22.462464       1 scheduler.go:454] Total Schedule Algo cumulative time:282.317915ms for 86
I0827 11:32:22.465758       1 scheduler.go:451] ScheduleAlgoTime 3.000323ms Start:2018-08-27 11:32:22.462750068 +0000 UTC m=+28.332057300 End:2018-08-27 11:32:22.465750439 +0000 UTC m=+28.335057623
I0827 11:32:22.465790       1 scheduler.go:454] Total Schedule Algo cumulative time:285.318238ms for 87
I0827 11:32:22.469220       1 scheduler.go:451] ScheduleAlgoTime 3.327088ms Start:2018-08-27 11:32:22.465882102 +0000 UTC m=+28.335189317 End:2018-08-27 11:32:22.469209215 +0000 UTC m=+28.338516405
I0827 11:32:22.469257       1 scheduler.go:454] Total Schedule Algo cumulative time:288.645326ms for 88
I0827 11:32:22.473739       1 scheduler.go:451] ScheduleAlgoTime 4.160609ms Start:2018-08-27 11:32:22.469567664 +0000 UTC m=+28.338874852 End:2018-08-27 11:32:22.473728249 +0000 UTC m=+28.343035461
I0827 11:32:22.473786       1 scheduler.go:454] Total Schedule Algo cumulative time:292.805935ms for 89
I0827 11:32:22.483321       1 scheduler.go:451] ScheduleAlgoTime 9.109346ms Start:2018-08-27 11:32:22.474199508 +0000 UTC m=+28.343506717 End:2018-08-27 11:32:22.483308869 +0000 UTC m=+28.352616063
I0827 11:32:22.483377       1 scheduler.go:454] Total Schedule Algo cumulative time:301.915281ms for 90
I0827 11:32:22.488119       1 scheduler.go:451] ScheduleAlgoTime 4.563757ms Start:2018-08-27 11:32:22.483539579 +0000 UTC m=+28.352846795 End:2018-08-27 11:32:22.488103176 +0000 UTC m=+28.357410552
I0827 11:32:22.488167       1 scheduler.go:454] Total Schedule Algo cumulative time:306.479038ms for 91
I0827 11:32:22.493189       1 scheduler.go:451] ScheduleAlgoTime 3.217333ms Start:2018-08-27 11:32:22.489960594 +0000 UTC m=+28.359267821 End:2018-08-27 11:32:22.493177622 +0000 UTC m=+28.362485154
I0827 11:32:22.493270       1 scheduler.go:454] Total Schedule Algo cumulative time:309.696371ms for 92
I0827 11:32:22.496553       1 scheduler.go:451] ScheduleAlgoTime 2.983475ms Start:2018-08-27 11:32:22.493559827 +0000 UTC m=+28.362867092 End:2018-08-27 11:32:22.496543307 +0000 UTC m=+28.365850567
I0827 11:32:22.496602       1 scheduler.go:454] Total Schedule Algo cumulative time:312.679846ms for 93
I0827 11:32:22.499268       1 scheduler.go:451] ScheduleAlgoTime 2.417644ms Start:2018-08-27 11:32:22.496838703 +0000 UTC m=+28.366145924 End:2018-08-27 11:32:22.499256382 +0000 UTC m=+28.368563568
I0827 11:32:22.499308       1 scheduler.go:454] Total Schedule Algo cumulative time:315.09749ms for 94
I0827 11:32:22.502090       1 scheduler.go:451] ScheduleAlgoTime 2.489341ms Start:2018-08-27 11:32:22.499590557 +0000 UTC m=+28.368897865 End:2018-08-27 11:32:22.50208002 +0000 UTC m=+28.371387206
I0827 11:32:22.502123       1 scheduler.go:454] Total Schedule Algo cumulative time:317.586831ms for 95
I0827 11:32:22.504565       1 scheduler.go:451] ScheduleAlgoTime 2.143087ms Start:2018-08-27 11:32:22.502409556 +0000 UTC m=+28.371717015 End:2018-08-27 11:32:22.504552808 +0000 UTC m=+28.373860102
I0827 11:32:22.504610       1 scheduler.go:454] Total Schedule Algo cumulative time:319.729918ms for 96
I0827 11:32:22.508135       1 scheduler.go:451] ScheduleAlgoTime 3.096225ms Start:2018-08-27 11:32:22.505029299 +0000 UTC m=+28.374336585 End:2018-08-27 11:32:22.50812563 +0000 UTC m=+28.377432810
I0827 11:32:22.508164       1 scheduler.go:454] Total Schedule Algo cumulative time:322.826143ms for 97
I0827 11:32:22.510793       1 scheduler.go:451] ScheduleAlgoTime 2.50403ms Start:2018-08-27 11:32:22.508282242 +0000 UTC m=+28.377589462 End:2018-08-27 11:32:22.51078631 +0000 UTC m=+28.380093492
I0827 11:32:22.510823       1 scheduler.go:454] Total Schedule Algo cumulative time:325.330173ms for 98
I0827 11:32:22.515170       1 scheduler.go:451] ScheduleAlgoTime 3.589227ms Start:2018-08-27 11:32:22.511571335 +0000 UTC m=+28.380878617 End:2018-08-27 11:32:22.51516066 +0000 UTC m=+28.384467844
I0827 11:32:22.515198       1 scheduler.go:454] Total Schedule Algo cumulative time:328.9194ms for 99
I0827 11:32:22.517861       1 scheduler.go:451] ScheduleAlgoTime 2.467881ms Start:2018-08-27 11:32:22.515382432 +0000 UTC m=+28.384689702 End:2018-08-27 11:32:22.517850398 +0000 UTC m=+28.387157583
I0827 11:32:22.517899       1 scheduler.go:454] Total Schedule Algo cumulative time:331.387281ms for 100
I0827 11:32:22.520865       1 scheduler.go:451] ScheduleAlgoTime 2.724409ms Start:2018-08-27 11:32:22.518128218 +0000 UTC m=+28.387435444 End:2018-08-27 11:32:22.520852541 +0000 UTC m=+28.390159853
I0827 11:32:22.520907       1 scheduler.go:454] Total Schedule Algo cumulative time:334.11169ms for 101
I0827 11:32:22.523984       1 scheduler.go:451] ScheduleAlgoTime 2.767545ms Start:2018-08-27 11:32:22.521206767 +0000 UTC m=+28.390514024 End:2018-08-27 11:32:22.52397438 +0000 UTC m=+28.393281569
I0827 11:32:22.524024       1 scheduler.go:454] Total Schedule Algo cumulative time:336.879235ms for 102
I0827 11:32:22.526545       1 scheduler.go:451] ScheduleAlgoTime 2.27237ms Start:2018-08-27 11:32:22.524262729 +0000 UTC m=+28.393569991 End:2018-08-27 11:32:22.526535174 +0000 UTC m=+28.395842361
I0827 11:32:22.526585       1 scheduler.go:454] Total Schedule Algo cumulative time:339.151605ms for 103
I0827 11:32:22.529309       1 scheduler.go:451] ScheduleAlgoTime 2.423809ms Start:2018-08-27 11:32:22.52687851 +0000 UTC m=+28.396185752 End:2018-08-27 11:32:22.529302376 +0000 UTC m=+28.398609561
I0827 11:32:22.529339       1 scheduler.go:454] Total Schedule Algo cumulative time:341.575414ms for 104
I0827 11:32:22.533287       1 scheduler.go:451] ScheduleAlgoTime 3.456631ms Start:2018-08-27 11:32:22.529817847 +0000 UTC m=+28.399125090 End:2018-08-27 11:32:22.533274532 +0000 UTC m=+28.402581721
I0827 11:32:22.533331       1 scheduler.go:454] Total Schedule Algo cumulative time:345.032045ms for 105
I0827 11:32:22.536807       1 scheduler.go:451] ScheduleAlgoTime 3.322149ms Start:2018-08-27 11:32:22.533475916 +0000 UTC m=+28.402783107 End:2018-08-27 11:32:22.536797975 +0000 UTC m=+28.406105256
I0827 11:32:22.536846       1 scheduler.go:454] Total Schedule Algo cumulative time:348.354194ms for 106
I0827 11:32:22.539180       1 scheduler.go:451] ScheduleAlgoTime 2.158079ms Start:2018-08-27 11:32:22.537012972 +0000 UTC m=+28.406320186 End:2018-08-27 11:32:22.539170989 +0000 UTC m=+28.408478265
I0827 11:32:22.539229       1 scheduler.go:454] Total Schedule Algo cumulative time:350.512273ms for 107
I0827 11:32:22.544433       1 scheduler.go:451] ScheduleAlgoTime 2.805332ms Start:2018-08-27 11:32:22.541617189 +0000 UTC m=+28.410924402 End:2018-08-27 11:32:22.544422552 +0000 UTC m=+28.413729734
I0827 11:32:22.544470       1 scheduler.go:454] Total Schedule Algo cumulative time:353.317605ms for 108
I0827 11:32:22.547484       1 scheduler.go:451] ScheduleAlgoTime 2.661607ms Start:2018-08-27 11:32:22.544813314 +0000 UTC m=+28.414120600 End:2018-08-27 11:32:22.547475021 +0000 UTC m=+28.416782207
I0827 11:32:22.547513       1 scheduler.go:454] Total Schedule Algo cumulative time:355.979212ms for 109
I0827 11:32:22.551411       1 scheduler.go:451] ScheduleAlgoTime 3.588254ms Start:2018-08-27 11:32:22.547813019 +0000 UTC m=+28.417120285 End:2018-08-27 11:32:22.551401353 +0000 UTC m=+28.420708539
I0827 11:32:22.551444       1 scheduler.go:454] Total Schedule Algo cumulative time:359.567466ms for 110
I0827 11:32:22.554139       1 scheduler.go:451] ScheduleAlgoTime 2.462455ms Start:2018-08-27 11:32:22.55166601 +0000 UTC m=+28.420973265 End:2018-08-27 11:32:22.554128528 +0000 UTC m=+28.423435720
I0827 11:32:22.554183       1 scheduler.go:454] Total Schedule Algo cumulative time:362.029921ms for 111
I0827 11:32:22.557390       1 scheduler.go:451] ScheduleAlgoTime 2.907019ms Start:2018-08-27 11:32:22.55447527 +0000 UTC m=+28.423782571 End:2018-08-27 11:32:22.557382404 +0000 UTC m=+28.426689590
I0827 11:32:22.557425       1 scheduler.go:454] Total Schedule Algo cumulative time:364.93694ms for 112
I0827 11:32:22.562819       1 scheduler.go:451] ScheduleAlgoTime 3.57866ms Start:2018-08-27 11:32:22.559229918 +0000 UTC m=+28.428537144 End:2018-08-27 11:32:22.562808535 +0000 UTC m=+28.432115804
I0827 11:32:22.562854       1 scheduler.go:454] Total Schedule Algo cumulative time:368.5156ms for 113
I0827 11:32:22.568005       1 scheduler.go:451] ScheduleAlgoTime 3.460173ms Start:2018-08-27 11:32:22.56453394 +0000 UTC m=+28.433841178 End:2018-08-27 11:32:22.56799417 +0000 UTC m=+28.437301351
I0827 11:32:22.568042       1 scheduler.go:454] Total Schedule Algo cumulative time:371.975773ms for 114
I0827 11:32:22.575489       1 scheduler.go:451] ScheduleAlgoTime 3.722517ms Start:2018-08-27 11:32:22.571755809 +0000 UTC m=+28.441063094 End:2018-08-27 11:32:22.575478427 +0000 UTC m=+28.444785611
I0827 11:32:22.575522       1 scheduler.go:454] Total Schedule Algo cumulative time:375.69829ms for 115
I0827 11:32:22.585171       1 scheduler.go:451] ScheduleAlgoTime 4.651331ms Start:2018-08-27 11:32:22.580510156 +0000 UTC m=+28.449817380 End:2018-08-27 11:32:22.585161525 +0000 UTC m=+28.454468711
I0827 11:32:22.585207       1 scheduler.go:454] Total Schedule Algo cumulative time:380.349621ms for 116
I0827 11:32:22.593123       1 scheduler.go:451] ScheduleAlgoTime 7.678973ms Start:2018-08-27 11:32:22.585436068 +0000 UTC m=+28.454743296 End:2018-08-27 11:32:22.593115084 +0000 UTC m=+28.462422269
I0827 11:32:22.593168       1 scheduler.go:454] Total Schedule Algo cumulative time:388.028594ms for 117
I0827 11:32:22.596973       1 scheduler.go:451] ScheduleAlgoTime 3.593927ms Start:2018-08-27 11:32:22.593368091 +0000 UTC m=+28.462675310 End:2018-08-27 11:32:22.596962056 +0000 UTC m=+28.466269237
I0827 11:32:22.597006       1 scheduler.go:454] Total Schedule Algo cumulative time:391.622521ms for 118
I0827 11:32:22.599293       1 scheduler.go:451] ScheduleAlgoTime 1.898175ms Start:2018-08-27 11:32:22.597386142 +0000 UTC m=+28.466693408 End:2018-08-27 11:32:22.599284399 +0000 UTC m=+28.468591583
I0827 11:32:22.599336       1 scheduler.go:454] Total Schedule Algo cumulative time:393.520696ms for 119
I0827 11:32:22.601589       1 scheduler.go:451] ScheduleAlgoTime 2.036505ms Start:2018-08-27 11:32:22.599542542 +0000 UTC m=+28.468849806 End:2018-08-27 11:32:22.601579123 +0000 UTC m=+28.470886311
I0827 11:32:22.601632       1 scheduler.go:454] Total Schedule Algo cumulative time:395.557201ms for 120
I0827 11:32:22.604645       1 scheduler.go:451] ScheduleAlgoTime 2.707509ms Start:2018-08-27 11:32:22.601925256 +0000 UTC m=+28.471232476 End:2018-08-27 11:32:22.604632769 +0000 UTC m=+28.473939985
I0827 11:32:22.604722       1 scheduler.go:454] Total Schedule Algo cumulative time:398.26471ms for 121
I0827 11:32:22.606998       1 scheduler.go:451] ScheduleAlgoTime 1.996588ms Start:2018-08-27 11:32:22.604993478 +0000 UTC m=+28.474300742 End:2018-08-27 11:32:22.606990148 +0000 UTC m=+28.476297330
I0827 11:32:22.607033       1 scheduler.go:454] Total Schedule Algo cumulative time:400.261298ms for 122
I0827 11:32:22.609589       1 scheduler.go:451] ScheduleAlgoTime 2.354536ms Start:2018-08-27 11:32:22.607224579 +0000 UTC m=+28.476531819 End:2018-08-27 11:32:22.609579174 +0000 UTC m=+28.478886355
I0827 11:32:22.609632       1 scheduler.go:454] Total Schedule Algo cumulative time:402.615834ms for 123
I0827 11:32:22.612198       1 scheduler.go:451] ScheduleAlgoTime 2.251151ms Start:2018-08-27 11:32:22.609938809 +0000 UTC m=+28.479246059 End:2018-08-27 11:32:22.612190027 +0000 UTC m=+28.481497210
I0827 11:32:22.612253       1 scheduler.go:454] Total Schedule Algo cumulative time:404.866985ms for 124
I0827 11:32:22.614837       1 scheduler.go:451] ScheduleAlgoTime 2.40591ms Start:2018-08-27 11:32:22.612421965 +0000 UTC m=+28.481729187 End:2018-08-27 11:32:22.614827902 +0000 UTC m=+28.484135097
I0827 11:32:22.614897       1 scheduler.go:454] Total Schedule Algo cumulative time:407.272895ms for 125
I0827 11:32:22.618914       1 scheduler.go:451] ScheduleAlgoTime 3.765258ms Start:2018-08-27 11:32:22.615138159 +0000 UTC m=+28.484445371 End:2018-08-27 11:32:22.618903434 +0000 UTC m=+28.488210629
I0827 11:32:22.618952       1 scheduler.go:454] Total Schedule Algo cumulative time:411.038153ms for 126
I0827 11:32:22.622340       1 scheduler.go:451] ScheduleAlgoTime 2.770139ms Start:2018-08-27 11:32:22.619561048 +0000 UTC m=+28.488868291 End:2018-08-27 11:32:22.622331241 +0000 UTC m=+28.491638430
I0827 11:32:22.622386       1 scheduler.go:454] Total Schedule Algo cumulative time:413.808292ms for 127
I0827 11:32:22.624872       1 scheduler.go:451] ScheduleAlgoTime 2.324643ms Start:2018-08-27 11:32:22.622538125 +0000 UTC m=+28.491845366 End:2018-08-27 11:32:22.624862821 +0000 UTC m=+28.494170009
I0827 11:32:22.624924       1 scheduler.go:454] Total Schedule Algo cumulative time:416.132935ms for 128
I0827 11:32:22.628066       1 scheduler.go:451] ScheduleAlgoTime 2.990382ms Start:2018-08-27 11:32:22.625068363 +0000 UTC m=+28.494375549 End:2018-08-27 11:32:22.628058749 +0000 UTC m=+28.497365931
I0827 11:32:22.628098       1 scheduler.go:454] Total Schedule Algo cumulative time:419.123317ms for 129
I0827 11:32:22.630728       1 scheduler.go:451] ScheduleAlgoTime 2.492657ms Start:2018-08-27 11:32:22.628226255 +0000 UTC m=+28.497533476 End:2018-08-27 11:32:22.630718951 +0000 UTC m=+28.500026133
I0827 11:32:22.630758       1 scheduler.go:454] Total Schedule Algo cumulative time:421.615974ms for 130
I0827 11:32:22.633211       1 scheduler.go:451] ScheduleAlgoTime 2.166871ms Start:2018-08-27 11:32:22.631036795 +0000 UTC m=+28.500344013 End:2018-08-27 11:32:22.633203701 +0000 UTC m=+28.502510884
I0827 11:32:22.633259       1 scheduler.go:454] Total Schedule Algo cumulative time:423.782845ms for 131
I0827 11:32:22.635252       1 scheduler.go:451] ScheduleAlgoTime 1.835066ms Start:2018-08-27 11:32:22.633409321 +0000 UTC m=+28.502716554 End:2018-08-27 11:32:22.635244438 +0000 UTC m=+28.504551620
I0827 11:32:22.635282       1 scheduler.go:454] Total Schedule Algo cumulative time:425.617911ms for 132
I0827 11:32:22.637874       1 scheduler.go:451] ScheduleAlgoTime 2.345666ms Start:2018-08-27 11:32:22.635519355 +0000 UTC m=+28.504826610 End:2018-08-27 11:32:22.637865092 +0000 UTC m=+28.507172276
I0827 11:32:22.637904       1 scheduler.go:454] Total Schedule Algo cumulative time:427.963577ms for 133
I0827 11:32:22.640475       1 scheduler.go:451] ScheduleAlgoTime 2.281047ms Start:2018-08-27 11:32:22.638186029 +0000 UTC m=+28.507493230 End:2018-08-27 11:32:22.640467096 +0000 UTC m=+28.509774277
I0827 11:32:22.640520       1 scheduler.go:454] Total Schedule Algo cumulative time:430.244624ms for 134
I0827 11:32:22.643074       1 scheduler.go:451] ScheduleAlgoTime 2.258756ms Start:2018-08-27 11:32:22.640804846 +0000 UTC m=+28.510112110 End:2018-08-27 11:32:22.643063679 +0000 UTC m=+28.512370866
I0827 11:32:22.643111       1 scheduler.go:454] Total Schedule Algo cumulative time:432.50338ms for 135
I0827 11:32:22.645386       1 scheduler.go:451] ScheduleAlgoTime 2.05424ms Start:2018-08-27 11:32:22.643325459 +0000 UTC m=+28.512632672 End:2018-08-27 11:32:22.645379729 +0000 UTC m=+28.514686912
I0827 11:32:22.645414       1 scheduler.go:454] Total Schedule Algo cumulative time:434.55762ms for 136
I0827 11:32:22.647586       1 scheduler.go:451] ScheduleAlgoTime 1.942365ms Start:2018-08-27 11:32:22.645634233 +0000 UTC m=+28.514941421 End:2018-08-27 11:32:22.64757658 +0000 UTC m=+28.516883786
I0827 11:32:22.647623       1 scheduler.go:454] Total Schedule Algo cumulative time:436.499985ms for 137
I0827 11:32:22.649954       1 scheduler.go:451] ScheduleAlgoTime 2.02967ms Start:2018-08-27 11:32:22.647915875 +0000 UTC m=+28.517223124 End:2018-08-27 11:32:22.649945552 +0000 UTC m=+28.519252794
I0827 11:32:22.650209       1 scheduler.go:454] Total Schedule Algo cumulative time:438.529655ms for 138
I0827 11:32:22.652272       1 scheduler.go:451] ScheduleAlgoTime 1.882759ms Start:2018-08-27 11:32:22.650383763 +0000 UTC m=+28.519691015 End:2018-08-27 11:32:22.652266591 +0000 UTC m=+28.521573774
I0827 11:32:22.652298       1 scheduler.go:454] Total Schedule Algo cumulative time:440.412414ms for 139
I0827 11:32:22.654326       1 scheduler.go:451] ScheduleAlgoTime 1.776301ms Start:2018-08-27 11:32:22.652543503 +0000 UTC m=+28.521850749 End:2018-08-27 11:32:22.654319865 +0000 UTC m=+28.523627050
I0827 11:32:22.654350       1 scheduler.go:454] Total Schedule Algo cumulative time:442.188715ms for 140
I0827 11:32:22.656343       1 scheduler.go:451] ScheduleAlgoTime 1.784985ms Start:2018-08-27 11:32:22.654550285 +0000 UTC m=+28.523857547 End:2018-08-27 11:32:22.656335346 +0000 UTC m=+28.525642532
I0827 11:32:22.656380       1 scheduler.go:454] Total Schedule Algo cumulative time:443.9737ms for 141
I0827 11:32:22.658524       1 scheduler.go:451] ScheduleAlgoTime 1.85624ms Start:2018-08-27 11:32:22.656662259 +0000 UTC m=+28.525969525 End:2018-08-27 11:32:22.658518581 +0000 UTC m=+28.527825765
I0827 11:32:22.658548       1 scheduler.go:454] Total Schedule Algo cumulative time:445.82994ms for 142
I0827 11:32:22.661192       1 scheduler.go:451] ScheduleAlgoTime 2.428982ms Start:2018-08-27 11:32:22.658752452 +0000 UTC m=+28.528059705 End:2018-08-27 11:32:22.661181428 +0000 UTC m=+28.530488687
I0827 11:32:22.661227       1 scheduler.go:454] Total Schedule Algo cumulative time:448.258922ms for 143
I0827 11:32:22.663850       1 scheduler.go:451] ScheduleAlgoTime 2.333225ms Start:2018-08-27 11:32:22.661507117 +0000 UTC m=+28.530814375 End:2018-08-27 11:32:22.6638404 +0000 UTC m=+28.533147600
I0827 11:32:22.663886       1 scheduler.go:454] Total Schedule Algo cumulative time:450.592147ms for 144
I0827 11:32:22.668306       1 scheduler.go:451] ScheduleAlgoTime 4.31106ms Start:2018-08-27 11:32:22.663986169 +0000 UTC m=+28.533293410 End:2018-08-27 11:32:22.668297287 +0000 UTC m=+28.537604470
I0827 11:32:22.668349       1 scheduler.go:454] Total Schedule Algo cumulative time:454.903207ms for 145
I0827 11:32:22.672024       1 scheduler.go:451] ScheduleAlgoTime 3.453815ms Start:2018-08-27 11:32:22.668561541 +0000 UTC m=+28.537868731 End:2018-08-27 11:32:22.672015361 +0000 UTC m=+28.541322546
I0827 11:32:22.672103       1 scheduler.go:454] Total Schedule Algo cumulative time:458.357022ms for 146
I0827 11:32:22.674570       1 scheduler.go:451] ScheduleAlgoTime 2.2064ms Start:2018-08-27 11:32:22.672355964 +0000 UTC m=+28.541663217 End:2018-08-27 11:32:22.674562435 +0000 UTC m=+28.543869617
I0827 11:32:22.674598       1 scheduler.go:454] Total Schedule Algo cumulative time:460.563422ms for 147
I0827 11:32:22.677217       1 scheduler.go:451] ScheduleAlgoTime 2.370273ms Start:2018-08-27 11:32:22.674838859 +0000 UTC m=+28.544146132 End:2018-08-27 11:32:22.677209223 +0000 UTC m=+28.546516405
I0827 11:32:22.677248       1 scheduler.go:454] Total Schedule Algo cumulative time:462.933695ms for 148
I0827 11:32:22.679259       1 scheduler.go:451] ScheduleAlgoTime 1.795375ms Start:2018-08-27 11:32:22.67745805 +0000 UTC m=+28.546765310 End:2018-08-27 11:32:22.679253502 +0000 UTC m=+28.548560685
I0827 11:32:22.679285       1 scheduler.go:454] Total Schedule Algo cumulative time:464.72907ms for 149
I0827 11:32:22.681351       1 scheduler.go:451] ScheduleAlgoTime 1.842204ms Start:2018-08-27 11:32:22.679500676 +0000 UTC m=+28.548807906 End:2018-08-27 11:32:22.681342926 +0000 UTC m=+28.550650110
I0827 11:32:22.681388       1 scheduler.go:454] Total Schedule Algo cumulative time:466.571274ms for 150
I0827 11:32:22.683259       1 scheduler.go:451] ScheduleAlgoTime 1.74014ms Start:2018-08-27 11:32:22.681510876 +0000 UTC m=+28.550818111 End:2018-08-27 11:32:22.683251056 +0000 UTC m=+28.552558251
I0827 11:32:22.683307       1 scheduler.go:454] Total Schedule Algo cumulative time:468.311414ms for 151
I0827 11:32:22.685500       1 scheduler.go:451] ScheduleAlgoTime 2.023794ms Start:2018-08-27 11:32:22.683469645 +0000 UTC m=+28.552776902 End:2018-08-27 11:32:22.685493512 +0000 UTC m=+28.554800696
I0827 11:32:22.685525       1 scheduler.go:454] Total Schedule Algo cumulative time:470.335208ms for 152
I0827 11:32:22.688129       1 scheduler.go:451] ScheduleAlgoTime 2.539285ms Start:2018-08-27 11:32:22.68557865 +0000 UTC m=+28.554885832 End:2018-08-27 11:32:22.688117778 +0000 UTC m=+28.557425117
I0827 11:32:22.688172       1 scheduler.go:454] Total Schedule Algo cumulative time:472.874493ms for 153
I0827 11:32:22.690069       1 scheduler.go:451] ScheduleAlgoTime 1.641835ms Start:2018-08-27 11:32:22.688418993 +0000 UTC m=+28.557726242 End:2018-08-27 11:32:22.690060831 +0000 UTC m=+28.559368077
I0827 11:32:22.690105       1 scheduler.go:454] Total Schedule Algo cumulative time:474.516328ms for 154
I0827 11:32:22.692345       1 scheduler.go:451] ScheduleAlgoTime 1.99727ms Start:2018-08-27 11:32:22.690341362 +0000 UTC m=+28.559648574 End:2018-08-27 11:32:22.692338662 +0000 UTC m=+28.561645844
I0827 11:32:22.692376       1 scheduler.go:454] Total Schedule Algo cumulative time:476.513598ms for 155
I0827 11:32:22.694785       1 scheduler.go:451] ScheduleAlgoTime 2.126614ms Start:2018-08-27 11:32:22.692597047 +0000 UTC m=+28.561904302 End:2018-08-27 11:32:22.694723645 +0000 UTC m=+28.564030916
I0827 11:32:22.694814       1 scheduler.go:454] Total Schedule Algo cumulative time:478.640212ms for 156
I0827 11:32:22.696895       1 scheduler.go:451] ScheduleAlgoTime 1.79257ms Start:2018-08-27 11:32:22.695096785 +0000 UTC m=+28.564404067 End:2018-08-27 11:32:22.69688945 +0000 UTC m=+28.566196637
I0827 11:32:22.696921       1 scheduler.go:454] Total Schedule Algo cumulative time:480.432782ms for 157
I0827 11:32:22.699243       1 scheduler.go:451] ScheduleAlgoTime 2.029711ms Start:2018-08-27 11:32:22.697205688 +0000 UTC m=+28.566512919 End:2018-08-27 11:32:22.699235447 +0000 UTC m=+28.568542630
I0827 11:32:22.699269       1 scheduler.go:454] Total Schedule Algo cumulative time:482.462493ms for 158
I0827 11:32:22.701522       1 scheduler.go:451] ScheduleAlgoTime 2.023713ms Start:2018-08-27 11:32:22.69948815 +0000 UTC m=+28.568795359 End:2018-08-27 11:32:22.701511758 +0000 UTC m=+28.570819072
I0827 11:32:22.701557       1 scheduler.go:454] Total Schedule Algo cumulative time:484.486206ms for 159
I0827 11:32:22.703971       1 scheduler.go:451] ScheduleAlgoTime 2.108559ms Start:2018-08-27 11:32:22.701856054 +0000 UTC m=+28.571163253 End:2018-08-27 11:32:22.703964631 +0000 UTC m=+28.573271812
I0827 11:32:22.704003       1 scheduler.go:454] Total Schedule Algo cumulative time:486.594765ms for 160
I0827 11:32:22.706051       1 scheduler.go:451] ScheduleAlgoTime 1.843194ms Start:2018-08-27 11:32:22.704201999 +0000 UTC m=+28.573509265 End:2018-08-27 11:32:22.706045276 +0000 UTC m=+28.575352459
I0827 11:32:22.706132       1 scheduler.go:454] Total Schedule Algo cumulative time:488.437959ms for 161
I0827 11:32:22.708285       1 scheduler.go:451] ScheduleAlgoTime 1.932008ms Start:2018-08-27 11:32:22.706344457 +0000 UTC m=+28.575651688 End:2018-08-27 11:32:22.708276467 +0000 UTC m=+28.577583696
I0827 11:32:22.708312       1 scheduler.go:454] Total Schedule Algo cumulative time:490.369967ms for 162
I0827 11:32:22.710251       1 scheduler.go:451] ScheduleAlgoTime 1.731257ms Start:2018-08-27 11:32:22.708513758 +0000 UTC m=+28.577820979 End:2018-08-27 11:32:22.710245054 +0000 UTC m=+28.579552236
I0827 11:32:22.710275       1 scheduler.go:454] Total Schedule Algo cumulative time:492.101224ms for 163
I0827 11:32:22.712250       1 scheduler.go:451] ScheduleAlgoTime 1.778705ms Start:2018-08-27 11:32:22.710464246 +0000 UTC m=+28.579771486 End:2018-08-27 11:32:22.712243009 +0000 UTC m=+28.581550191
I0827 11:32:22.712276       1 scheduler.go:454] Total Schedule Algo cumulative time:493.879929ms for 164
I0827 11:32:22.714843       1 scheduler.go:451] ScheduleAlgoTime 2.363579ms Start:2018-08-27 11:32:22.712470034 +0000 UTC m=+28.581777278 End:2018-08-27 11:32:22.714833462 +0000 UTC m=+28.584140857
I0827 11:32:22.714875       1 scheduler.go:454] Total Schedule Algo cumulative time:496.243508ms for 165
I0827 11:32:22.717073       1 scheduler.go:451] ScheduleAlgoTime 1.840455ms Start:2018-08-27 11:32:22.715222507 +0000 UTC m=+28.584529763 End:2018-08-27 11:32:22.717063006 +0000 UTC m=+28.586370218
I0827 11:32:22.717107       1 scheduler.go:454] Total Schedule Algo cumulative time:498.083963ms for 166
I0827 11:32:22.719043       1 scheduler.go:451] ScheduleAlgoTime 1.746694ms Start:2018-08-27 11:32:22.717290039 +0000 UTC m=+28.586597316 End:2018-08-27 11:32:22.719036828 +0000 UTC m=+28.588344010
I0827 11:32:22.719072       1 scheduler.go:454] Total Schedule Algo cumulative time:499.830657ms for 167
I0827 11:32:22.721638       1 scheduler.go:451] ScheduleAlgoTime 2.229962ms Start:2018-08-27 11:32:22.719402846 +0000 UTC m=+28.588710087 End:2018-08-27 11:32:22.721632868 +0000 UTC m=+28.590940049
I0827 11:32:22.721665       1 scheduler.go:454] Total Schedule Algo cumulative time:502.060619ms for 168
I0827 11:32:22.723762       1 scheduler.go:451] ScheduleAlgoTime 1.856047ms Start:2018-08-27 11:32:22.721900082 +0000 UTC m=+28.591207325 End:2018-08-27 11:32:22.723756191 +0000 UTC m=+28.593063372
I0827 11:32:22.723787       1 scheduler.go:454] Total Schedule Algo cumulative time:503.916666ms for 169
I0827 11:32:22.725620       1 scheduler.go:451] ScheduleAlgoTime 1.619527ms Start:2018-08-27 11:32:22.723994908 +0000 UTC m=+28.593302197 End:2018-08-27 11:32:22.725614542 +0000 UTC m=+28.594921724
I0827 11:32:22.725645       1 scheduler.go:454] Total Schedule Algo cumulative time:505.536193ms for 170
I0827 11:32:22.727850       1 scheduler.go:451] ScheduleAlgoTime 1.989804ms Start:2018-08-27 11:32:22.725855377 +0000 UTC m=+28.595162560 End:2018-08-27 11:32:22.727845182 +0000 UTC m=+28.597152364
I0827 11:32:22.727874       1 scheduler.go:454] Total Schedule Algo cumulative time:507.525997ms for 171
I0827 11:32:22.730108       1 scheduler.go:451] ScheduleAlgoTime 1.952881ms Start:2018-08-27 11:32:22.72814986 +0000 UTC m=+28.597457092 End:2018-08-27 11:32:22.730102789 +0000 UTC m=+28.599409973
I0827 11:32:22.730130       1 scheduler.go:454] Total Schedule Algo cumulative time:509.478878ms for 172
I0827 11:32:22.733317       1 scheduler.go:451] ScheduleAlgoTime 2.933443ms Start:2018-08-27 11:32:22.730371789 +0000 UTC m=+28.599679071 End:2018-08-27 11:32:22.733305332 +0000 UTC m=+28.602612514
I0827 11:32:22.733354       1 scheduler.go:454] Total Schedule Algo cumulative time:512.412321ms for 173
I0827 11:32:22.739877       1 scheduler.go:451] ScheduleAlgoTime 6.227398ms Start:2018-08-27 11:32:22.733636092 +0000 UTC m=+28.602943326 End:2018-08-27 11:32:22.739863527 +0000 UTC m=+28.609170724
I0827 11:32:22.739940       1 scheduler.go:454] Total Schedule Algo cumulative time:518.639719ms for 174
I0827 11:32:22.742399       1 scheduler.go:451] ScheduleAlgoTime 2.242689ms Start:2018-08-27 11:32:22.740149768 +0000 UTC m=+28.609457000 End:2018-08-27 11:32:22.7423925 +0000 UTC m=+28.611699689
I0827 11:32:22.742449       1 scheduler.go:454] Total Schedule Algo cumulative time:520.882408ms for 175
I0827 11:32:22.744517       1 scheduler.go:451] ScheduleAlgoTime 1.890341ms Start:2018-08-27 11:32:22.742618912 +0000 UTC m=+28.611926104 End:2018-08-27 11:32:22.744509263 +0000 UTC m=+28.613816445
I0827 11:32:22.744557       1 scheduler.go:454] Total Schedule Algo cumulative time:522.772749ms for 176
I0827 11:32:22.746921       1 scheduler.go:451] ScheduleAlgoTime 2.076194ms Start:2018-08-27 11:32:22.744835579 +0000 UTC m=+28.614142836 End:2018-08-27 11:32:22.746911826 +0000 UTC m=+28.616219030
I0827 11:32:22.746960       1 scheduler.go:454] Total Schedule Algo cumulative time:524.848943ms for 177
I0827 11:32:22.749040       1 scheduler.go:451] ScheduleAlgoTime 1.796849ms Start:2018-08-27 11:32:22.747235795 +0000 UTC m=+28.616542980 End:2018-08-27 11:32:22.749032525 +0000 UTC m=+28.618339829
I0827 11:32:22.749078       1 scheduler.go:454] Total Schedule Algo cumulative time:526.645792ms for 178
I0827 11:32:22.751868       1 scheduler.go:451] ScheduleAlgoTime 2.577043ms Start:2018-08-27 11:32:22.749282592 +0000 UTC m=+28.618589791 End:2018-08-27 11:32:22.751859639 +0000 UTC m=+28.621166834
I0827 11:32:22.751898       1 scheduler.go:454] Total Schedule Algo cumulative time:529.222835ms for 179
I0827 11:32:22.754085       1 scheduler.go:451] ScheduleAlgoTime 1.891952ms Start:2018-08-27 11:32:22.752186704 +0000 UTC m=+28.621493941 End:2018-08-27 11:32:22.754078709 +0000 UTC m=+28.623385893
I0827 11:32:22.754113       1 scheduler.go:454] Total Schedule Algo cumulative time:531.114787ms for 180
I0827 11:32:22.756290       1 scheduler.go:451] ScheduleAlgoTime 1.947947ms Start:2018-08-27 11:32:22.754337123 +0000 UTC m=+28.623644356 End:2018-08-27 11:32:22.756285118 +0000 UTC m=+28.625592303
I0827 11:32:22.756316       1 scheduler.go:454] Total Schedule Algo cumulative time:533.062734ms for 181
I0827 11:32:22.758104       1 scheduler.go:451] ScheduleAlgoTime 1.66285ms Start:2018-08-27 11:32:22.756430301 +0000 UTC m=+28.625737556 End:2018-08-27 11:32:22.758093214 +0000 UTC m=+28.627400406
I0827 11:32:22.758139       1 scheduler.go:454] Total Schedule Algo cumulative time:534.725584ms for 182
I0827 11:32:22.760093       1 scheduler.go:451] ScheduleAlgoTime 1.73522ms Start:2018-08-27 11:32:22.758349758 +0000 UTC m=+28.627656963 End:2018-08-27 11:32:22.760084987 +0000 UTC m=+28.629392183
I0827 11:32:22.760129       1 scheduler.go:454] Total Schedule Algo cumulative time:536.460804ms for 183
I0827 11:32:22.762184       1 scheduler.go:451] ScheduleAlgoTime 1.849412ms Start:2018-08-27 11:32:22.76032764 +0000 UTC m=+28.629634854 End:2018-08-27 11:32:22.762177084 +0000 UTC m=+28.631484266
I0827 11:32:22.762211       1 scheduler.go:454] Total Schedule Algo cumulative time:538.310216ms for 184
I0827 11:32:22.764628       1 scheduler.go:451] ScheduleAlgoTime 2.145412ms Start:2018-08-27 11:32:22.762470398 +0000 UTC m=+28.631777609 End:2018-08-27 11:32:22.764615802 +0000 UTC m=+28.633923021
I0827 11:32:22.764755       1 scheduler.go:454] Total Schedule Algo cumulative time:540.455628ms for 185
I0827 11:32:22.767446       1 scheduler.go:451] ScheduleAlgoTime 2.396384ms Start:2018-08-27 11:32:22.765041911 +0000 UTC m=+28.634349121 End:2018-08-27 11:32:22.767438324 +0000 UTC m=+28.636745505
I0827 11:32:22.767473       1 scheduler.go:454] Total Schedule Algo cumulative time:542.852012ms for 186
I0827 11:32:22.769840       1 scheduler.go:451] ScheduleAlgoTime 2.105271ms Start:2018-08-27 11:32:22.767725796 +0000 UTC m=+28.637033007 End:2018-08-27 11:32:22.769830978 +0000 UTC m=+28.639138278
I0827 11:32:22.770065       1 scheduler.go:454] Total Schedule Algo cumulative time:544.957283ms for 187
I0827 11:32:22.772609       1 scheduler.go:451] ScheduleAlgoTime 2.281016ms Start:2018-08-27 11:32:22.770321545 +0000 UTC m=+28.639628769 End:2018-08-27 11:32:22.772602597 +0000 UTC m=+28.641909785
I0827 11:32:22.772650       1 scheduler.go:454] Total Schedule Algo cumulative time:547.238299ms for 188
I0827 11:32:22.774798       1 scheduler.go:451] ScheduleAlgoTime 1.845861ms Start:2018-08-27 11:32:22.772944575 +0000 UTC m=+28.642251818 End:2018-08-27 11:32:22.774790495 +0000 UTC m=+28.644097679
I0827 11:32:22.774830       1 scheduler.go:454] Total Schedule Algo cumulative time:549.08416ms for 189
I0827 11:32:22.777128       1 scheduler.go:451] ScheduleAlgoTime 2.079149ms Start:2018-08-27 11:32:22.775040205 +0000 UTC m=+28.644347441 End:2018-08-27 11:32:22.777119402 +0000 UTC m=+28.646426590
I0827 11:32:22.777159       1 scheduler.go:454] Total Schedule Algo cumulative time:551.163309ms for 190
I0827 11:32:22.779368       1 scheduler.go:451] ScheduleAlgoTime 1.839083ms Start:2018-08-27 11:32:22.77752331 +0000 UTC m=+28.646830538 End:2018-08-27 11:32:22.779362439 +0000 UTC m=+28.648669621
I0827 11:32:22.779395       1 scheduler.go:454] Total Schedule Algo cumulative time:553.002392ms for 191
I0827 11:32:22.781668       1 scheduler.go:451] ScheduleAlgoTime 2.010126ms Start:2018-08-27 11:32:22.779650765 +0000 UTC m=+28.648958001 End:2018-08-27 11:32:22.781660946 +0000 UTC m=+28.650968127
I0827 11:32:22.781732       1 scheduler.go:454] Total Schedule Algo cumulative time:555.012518ms for 192
I0827 11:32:22.783516       1 scheduler.go:451] ScheduleAlgoTime 1.548482ms Start:2018-08-27 11:32:22.78195999 +0000 UTC m=+28.651267204 End:2018-08-27 11:32:22.783508504 +0000 UTC m=+28.652815686
I0827 11:32:22.783592       1 scheduler.go:454] Total Schedule Algo cumulative time:556.561ms for 193
I0827 11:32:22.785518       1 scheduler.go:451] ScheduleAlgoTime 1.739196ms Start:2018-08-27 11:32:22.783773615 +0000 UTC m=+28.653080869 End:2018-08-27 11:32:22.785512877 +0000 UTC m=+28.654820065
I0827 11:32:22.785545       1 scheduler.go:454] Total Schedule Algo cumulative time:558.300196ms for 194
I0827 11:32:22.787675       1 scheduler.go:451] ScheduleAlgoTime 1.79305ms Start:2018-08-27 11:32:22.785876126 +0000 UTC m=+28.655183383 End:2018-08-27 11:32:22.78766925 +0000 UTC m=+28.656976433
I0827 11:32:22.787745       1 scheduler.go:454] Total Schedule Algo cumulative time:560.093246ms for 195
I0827 11:32:22.789550       1 scheduler.go:451] ScheduleAlgoTime 1.536751ms Start:2018-08-27 11:32:22.788008493 +0000 UTC m=+28.657315732 End:2018-08-27 11:32:22.789545294 +0000 UTC m=+28.658852483
I0827 11:32:22.789578       1 scheduler.go:454] Total Schedule Algo cumulative time:561.629997ms for 196
I0827 11:32:22.791875       1 scheduler.go:451] ScheduleAlgoTime 2.043004ms Start:2018-08-27 11:32:22.789824486 +0000 UTC m=+28.659131767 End:2018-08-27 11:32:22.791867591 +0000 UTC m=+28.661174771
I0827 11:32:22.791906       1 scheduler.go:454] Total Schedule Algo cumulative time:563.673001ms for 197
I0827 11:32:22.794066       1 scheduler.go:451] ScheduleAlgoTime 1.829226ms Start:2018-08-27 11:32:22.792230907 +0000 UTC m=+28.661538091 End:2018-08-27 11:32:22.794060136 +0000 UTC m=+28.663367317
I0827 11:32:22.794095       1 scheduler.go:454] Total Schedule Algo cumulative time:565.502227ms for 198
I0827 11:32:22.796274       1 scheduler.go:451] ScheduleAlgoTime 1.857541ms Start:2018-08-27 11:32:22.794410743 +0000 UTC m=+28.663718002 End:2018-08-27 11:32:22.79626836 +0000 UTC m=+28.665575543
I0827 11:32:22.796307       1 scheduler.go:454] Total Schedule Algo cumulative time:567.359768ms for 199
I0827 11:32:22.798929       1 scheduler.go:451] ScheduleAlgoTime 2.49947ms Start:2018-08-27 11:32:22.796414467 +0000 UTC m=+28.665721653 End:2018-08-27 11:32:22.798913938 +0000 UTC m=+28.668221123
I0827 11:32:22.798967       1 scheduler.go:454] Total Schedule Algo cumulative time:569.859238ms for 200
I0827 11:32:22.801530       1 scheduler.go:451] ScheduleAlgoTime 2.428578ms Start:2018-08-27 11:32:22.799093963 +0000 UTC m=+28.668401179 End:2018-08-27 11:32:22.801522575 +0000 UTC m=+28.670829757
I0827 11:32:22.801563       1 scheduler.go:454] Total Schedule Algo cumulative time:572.287816ms for 201
I0827 11:32:22.803565       1 scheduler.go:451] ScheduleAlgoTime 1.619401ms Start:2018-08-27 11:32:22.801939472 +0000 UTC m=+28.671246691 End:2018-08-27 11:32:22.803558908 +0000 UTC m=+28.672866092
I0827 11:32:22.803598       1 scheduler.go:454] Total Schedule Algo cumulative time:573.907217ms for 202
I0827 11:32:22.805637       1 scheduler.go:451] ScheduleAlgoTime 1.804134ms Start:2018-08-27 11:32:22.80382495 +0000 UTC m=+28.673132213 End:2018-08-27 11:32:22.805629164 +0000 UTC m=+28.674936347
I0827 11:32:22.805666       1 scheduler.go:454] Total Schedule Algo cumulative time:575.711351ms for 203
I0827 11:32:22.807934       1 scheduler.go:451] ScheduleAlgoTime 1.905192ms Start:2018-08-27 11:32:22.806020793 +0000 UTC m=+28.675328040 End:2018-08-27 11:32:22.807926049 +0000 UTC m=+28.677233232
I0827 11:32:22.807961       1 scheduler.go:454] Total Schedule Algo cumulative time:577.616543ms for 204
I0827 11:32:22.814838       1 scheduler.go:451] ScheduleAlgoTime 6.714683ms Start:2018-08-27 11:32:22.808112509 +0000 UTC m=+28.677419789 End:2018-08-27 11:32:22.814827287 +0000 UTC m=+28.684134472
I0827 11:32:22.814883       1 scheduler.go:454] Total Schedule Algo cumulative time:584.331226ms for 205
I0827 11:32:22.818044       1 scheduler.go:451] ScheduleAlgoTime 2.876224ms Start:2018-08-27 11:32:22.815158284 +0000 UTC m=+28.684465546 End:2018-08-27 11:32:22.818034588 +0000 UTC m=+28.687341770
I0827 11:32:22.818146       1 scheduler.go:454] Total Schedule Algo cumulative time:587.20745ms for 206
I0827 11:32:22.820177       1 scheduler.go:451] ScheduleAlgoTime 1.883364ms Start:2018-08-27 11:32:22.818287405 +0000 UTC m=+28.687594588 End:2018-08-27 11:32:22.820170766 +0000 UTC m=+28.689477952
I0827 11:32:22.820209       1 scheduler.go:454] Total Schedule Algo cumulative time:589.090814ms for 207
I0827 11:32:22.822270       1 scheduler.go:451] ScheduleAlgoTime 1.794351ms Start:2018-08-27 11:32:22.820469784 +0000 UTC m=+28.689777022 End:2018-08-27 11:32:22.822264189 +0000 UTC m=+28.691571373
I0827 11:32:22.822312       1 scheduler.go:454] Total Schedule Algo cumulative time:590.885165ms for 208
I0827 11:32:22.824390       1 scheduler.go:451] ScheduleAlgoTime 1.875008ms Start:2018-08-27 11:32:22.822507523 +0000 UTC m=+28.691814756 End:2018-08-27 11:32:22.824382579 +0000 UTC m=+28.693689764
I0827 11:32:22.824420       1 scheduler.go:454] Total Schedule Algo cumulative time:592.760173ms for 209
I0827 11:32:22.826646       1 scheduler.go:451] ScheduleAlgoTime 1.763907ms Start:2018-08-27 11:32:22.82487481 +0000 UTC m=+28.694182014 End:2018-08-27 11:32:22.826638739 +0000 UTC m=+28.695945921
I0827 11:32:22.826725       1 scheduler.go:454] Total Schedule Algo cumulative time:594.52408ms for 210
I0827 11:32:22.830033       1 scheduler.go:451] ScheduleAlgoTime 3.039662ms Start:2018-08-27 11:32:22.826984727 +0000 UTC m=+28.696291946 End:2018-08-27 11:32:22.830024421 +0000 UTC m=+28.699331608
I0827 11:32:22.830065       1 scheduler.go:454] Total Schedule Algo cumulative time:597.563742ms for 211
I0827 11:32:22.832561       1 scheduler.go:451] ScheduleAlgoTime 2.271465ms Start:2018-08-27 11:32:22.830278164 +0000 UTC m=+28.699585388 End:2018-08-27 11:32:22.832549665 +0000 UTC m=+28.701856853
I0827 11:32:22.832600       1 scheduler.go:454] Total Schedule Algo cumulative time:599.835207ms for 212
I0827 11:32:22.834899       1 scheduler.go:451] ScheduleAlgoTime 2.028334ms Start:2018-08-27 11:32:22.832864362 +0000 UTC m=+28.702171574 End:2018-08-27 11:32:22.834892699 +0000 UTC m=+28.704199908
I0827 11:32:22.834925       1 scheduler.go:454] Total Schedule Algo cumulative time:601.863541ms for 213
I0827 11:32:22.836777       1 scheduler.go:451] ScheduleAlgoTime 1.744035ms Start:2018-08-27 11:32:22.835026843 +0000 UTC m=+28.704334027 End:2018-08-27 11:32:22.836770879 +0000 UTC m=+28.706078062
I0827 11:32:22.836815       1 scheduler.go:454] Total Schedule Algo cumulative time:603.607576ms for 214
I0827 11:32:22.839045       1 scheduler.go:451] ScheduleAlgoTime 2.011625ms Start:2018-08-27 11:32:22.83702796 +0000 UTC m=+28.706335219 End:2018-08-27 11:32:22.839039657 +0000 UTC m=+28.708346844
I0827 11:32:22.839071       1 scheduler.go:454] Total Schedule Algo cumulative time:605.619201ms for 215
I0827 11:32:22.841399       1 scheduler.go:451] ScheduleAlgoTime 2.043584ms Start:2018-08-27 11:32:22.839349398 +0000 UTC m=+28.708656633 End:2018-08-27 11:32:22.841393031 +0000 UTC m=+28.710700217
I0827 11:32:22.841426       1 scheduler.go:454] Total Schedule Algo cumulative time:607.662785ms for 216
I0827 11:32:22.843868       1 scheduler.go:451] ScheduleAlgoTime 2.121984ms Start:2018-08-27 11:32:22.841739696 +0000 UTC m=+28.711046940 End:2018-08-27 11:32:22.84386174 +0000 UTC m=+28.713168924
I0827 11:32:22.843899       1 scheduler.go:454] Total Schedule Algo cumulative time:609.784769ms for 217
I0827 11:32:22.845882       1 scheduler.go:451] ScheduleAlgoTime 1.731226ms Start:2018-08-27 11:32:22.84414435 +0000 UTC m=+28.713451567 End:2018-08-27 11:32:22.845875606 +0000 UTC m=+28.715182793
I0827 11:32:22.845911       1 scheduler.go:454] Total Schedule Algo cumulative time:611.515995ms for 218
I0827 11:32:22.848004       1 scheduler.go:451] ScheduleAlgoTime 2.009544ms Start:2018-08-27 11:32:22.845986585 +0000 UTC m=+28.715293826 End:2018-08-27 11:32:22.847996184 +0000 UTC m=+28.717303370
I0827 11:32:22.848044       1 scheduler.go:454] Total Schedule Algo cumulative time:613.525539ms for 219
I0827 11:32:22.850224       1 scheduler.go:451] ScheduleAlgoTime 1.963318ms Start:2018-08-27 11:32:22.848254073 +0000 UTC m=+28.717561334 End:2018-08-27 11:32:22.850217464 +0000 UTC m=+28.719524652
I0827 11:32:22.850254       1 scheduler.go:454] Total Schedule Algo cumulative time:615.488857ms for 220
I0827 11:32:22.852406       1 scheduler.go:451] ScheduleAlgoTime 1.838935ms Start:2018-08-27 11:32:22.85055781 +0000 UTC m=+28.719865061 End:2018-08-27 11:32:22.852396781 +0000 UTC m=+28.721703996
I0827 11:32:22.852443       1 scheduler.go:454] Total Schedule Algo cumulative time:617.327792ms for 221
I0827 11:32:22.854721       1 scheduler.go:451] ScheduleAlgoTime 2.063025ms Start:2018-08-27 11:32:22.852649141 +0000 UTC m=+28.721956394 End:2018-08-27 11:32:22.854712235 +0000 UTC m=+28.724019419
I0827 11:32:22.854753       1 scheduler.go:454] Total Schedule Algo cumulative time:619.390817ms for 222
I0827 11:32:22.856585       1 scheduler.go:451] ScheduleAlgoTime 1.558306ms Start:2018-08-27 11:32:22.85502101 +0000 UTC m=+28.724328253 End:2018-08-27 11:32:22.856579377 +0000 UTC m=+28.725886559
I0827 11:32:22.856611       1 scheduler.go:454] Total Schedule Algo cumulative time:620.949123ms for 223
I0827 11:32:22.858361       1 scheduler.go:451] ScheduleAlgoTime 1.541059ms Start:2018-08-27 11:32:22.85681481 +0000 UTC m=+28.726122092 End:2018-08-27 11:32:22.858355969 +0000 UTC m=+28.727663151
I0827 11:32:22.858388       1 scheduler.go:454] Total Schedule Algo cumulative time:622.490182ms for 224
I0827 11:32:22.860472       1 scheduler.go:451] ScheduleAlgoTime 1.853419ms Start:2018-08-27 11:32:22.858609701 +0000 UTC m=+28.727916944 End:2018-08-27 11:32:22.860463182 +0000 UTC m=+28.729770363
I0827 11:32:22.860507       1 scheduler.go:454] Total Schedule Algo cumulative time:624.343601ms for 225
I0827 11:32:22.862339       1 scheduler.go:451] ScheduleAlgoTime 1.606652ms Start:2018-08-27 11:32:22.860725776 +0000 UTC m=+28.730033038 End:2018-08-27 11:32:22.862332509 +0000 UTC m=+28.731639690
I0827 11:32:22.862364       1 scheduler.go:454] Total Schedule Algo cumulative time:625.950253ms for 226
I0827 11:32:22.864725       1 scheduler.go:451] ScheduleAlgoTime 2.050365ms Start:2018-08-27 11:32:22.862625534 +0000 UTC m=+28.731932781 End:2018-08-27 11:32:22.864675961 +0000 UTC m=+28.733983146
I0827 11:32:22.864757       1 scheduler.go:454] Total Schedule Algo cumulative time:628.000618ms for 227
I0827 11:32:22.866853       1 scheduler.go:451] ScheduleAlgoTime 1.870738ms Start:2018-08-27 11:32:22.864971987 +0000 UTC m=+28.734279205 End:2018-08-27 11:32:22.86684267 +0000 UTC m=+28.736149943
I0827 11:32:22.866889       1 scheduler.go:454] Total Schedule Algo cumulative time:629.871356ms for 228
I0827 11:32:22.869292       1 scheduler.go:451] ScheduleAlgoTime 2.232451ms Start:2018-08-27 11:32:22.867052315 +0000 UTC m=+28.736359515 End:2018-08-27 11:32:22.869284781 +0000 UTC m=+28.738591966
I0827 11:32:22.869331       1 scheduler.go:454] Total Schedule Algo cumulative time:632.103807ms for 229
I0827 11:32:22.871944       1 scheduler.go:451] ScheduleAlgoTime 2.4108ms Start:2018-08-27 11:32:22.869526467 +0000 UTC m=+28.738833650 End:2018-08-27 11:32:22.871937268 +0000 UTC m=+28.741244450
I0827 11:32:22.871971       1 scheduler.go:454] Total Schedule Algo cumulative time:634.514607ms for 230
I0827 11:32:22.873933       1 scheduler.go:451] ScheduleAlgoTime 1.734515ms Start:2018-08-27 11:32:22.872191409 +0000 UTC m=+28.741498680 End:2018-08-27 11:32:22.873926013 +0000 UTC m=+28.743233195
I0827 11:32:22.873960       1 scheduler.go:454] Total Schedule Algo cumulative time:636.249122ms for 231
I0827 11:32:22.875964       1 scheduler.go:451] ScheduleAlgoTime 1.742978ms Start:2018-08-27 11:32:22.874214252 +0000 UTC m=+28.743521510 End:2018-08-27 11:32:22.875957307 +0000 UTC m=+28.745264488
I0827 11:32:22.875996       1 scheduler.go:454] Total Schedule Algo cumulative time:637.9921ms for 232
I0827 11:32:22.877863       1 scheduler.go:451] ScheduleAlgoTime 1.595983ms Start:2018-08-27 11:32:22.87626055 +0000 UTC m=+28.745567780 End:2018-08-27 11:32:22.877856568 +0000 UTC m=+28.747163763
I0827 11:32:22.877893       1 scheduler.go:454] Total Schedule Algo cumulative time:639.588083ms for 233
I0827 11:32:22.879859       1 scheduler.go:451] ScheduleAlgoTime 1.714854ms Start:2018-08-27 11:32:22.878136216 +0000 UTC m=+28.747443415 End:2018-08-27 11:32:22.879851069 +0000 UTC m=+28.749158269
I0827 11:32:22.879885       1 scheduler.go:454] Total Schedule Algo cumulative time:641.302937ms for 234
I0827 11:32:22.881818       1 scheduler.go:451] ScheduleAlgoTime 1.630235ms Start:2018-08-27 11:32:22.880182888 +0000 UTC m=+28.749490130 End:2018-08-27 11:32:22.88181318 +0000 UTC m=+28.751120365
I0827 11:32:22.881840       1 scheduler.go:454] Total Schedule Algo cumulative time:642.933172ms for 235
I0827 11:32:22.883844       1 scheduler.go:451] ScheduleAlgoTime 1.765198ms Start:2018-08-27 11:32:22.882069802 +0000 UTC m=+28.751377038 End:2018-08-27 11:32:22.883835052 +0000 UTC m=+28.753142236
I0827 11:32:22.883878       1 scheduler.go:454] Total Schedule Algo cumulative time:644.69837ms for 236
I0827 11:32:22.885813       1 scheduler.go:451] ScheduleAlgoTime 1.761598ms Start:2018-08-27 11:32:22.884045182 +0000 UTC m=+28.753352415 End:2018-08-27 11:32:22.88580683 +0000 UTC m=+28.755114013
I0827 11:32:22.885839       1 scheduler.go:454] Total Schedule Algo cumulative time:646.459968ms for 237
I0827 11:32:22.889570       1 scheduler.go:451] ScheduleAlgoTime 3.425858ms Start:2018-08-27 11:32:22.886135131 +0000 UTC m=+28.755442403 End:2018-08-27 11:32:22.889559408 +0000 UTC m=+28.758868261
I0827 11:32:22.889674       1 scheduler.go:454] Total Schedule Algo cumulative time:649.885826ms for 238
I0827 11:32:22.895914       1 scheduler.go:451] ScheduleAlgoTime 5.555794ms Start:2018-08-27 11:32:22.890348762 +0000 UTC m=+28.759656005 End:2018-08-27 11:32:22.895904618 +0000 UTC m=+28.765211799
I0827 11:32:22.895951       1 scheduler.go:454] Total Schedule Algo cumulative time:655.44162ms for 239
I0827 11:32:22.898039       1 scheduler.go:451] ScheduleAlgoTime 1.92603ms Start:2018-08-27 11:32:22.896104751 +0000 UTC m=+28.765411962 End:2018-08-27 11:32:22.898030807 +0000 UTC m=+28.767337992
I0827 11:32:22.898131       1 scheduler.go:454] Total Schedule Algo cumulative time:657.36765ms for 240
I0827 11:32:22.900357       1 scheduler.go:451] ScheduleAlgoTime 1.920746ms Start:2018-08-27 11:32:22.898429323 +0000 UTC m=+28.767736577 End:2018-08-27 11:32:22.90035014 +0000 UTC m=+28.769657323
I0827 11:32:22.900395       1 scheduler.go:454] Total Schedule Algo cumulative time:659.288396ms for 241
I0827 11:32:22.902556       1 scheduler.go:451] ScheduleAlgoTime 2.027998ms Start:2018-08-27 11:32:22.900521704 +0000 UTC m=+28.769828886 End:2018-08-27 11:32:22.902549697 +0000 UTC m=+28.771856884
I0827 11:32:22.902586       1 scheduler.go:454] Total Schedule Algo cumulative time:661.316394ms for 242
I0827 11:32:22.904775       1 scheduler.go:451] ScheduleAlgoTime 1.871798ms Start:2018-08-27 11:32:22.902897477 +0000 UTC m=+28.772204675 End:2018-08-27 11:32:22.904769289 +0000 UTC m=+28.774076473
I0827 11:32:22.904806       1 scheduler.go:454] Total Schedule Algo cumulative time:663.188192ms for 243
I0827 11:32:22.906552       1 scheduler.go:451] ScheduleAlgoTime 1.581135ms Start:2018-08-27 11:32:22.904962288 +0000 UTC m=+28.774269471 End:2018-08-27 11:32:22.906543313 +0000 UTC m=+28.775850606
I0827 11:32:22.906587       1 scheduler.go:454] Total Schedule Algo cumulative time:664.769327ms for 244
I0827 11:32:22.909143       1 scheduler.go:451] ScheduleAlgoTime 2.094883ms Start:2018-08-27 11:32:22.907038247 +0000 UTC m=+28.776345435 End:2018-08-27 11:32:22.909133066 +0000 UTC m=+28.778440318
I0827 11:32:22.909196       1 scheduler.go:454] Total Schedule Algo cumulative time:666.86421ms for 245
I0827 11:32:22.911460       1 scheduler.go:451] ScheduleAlgoTime 1.95087ms Start:2018-08-27 11:32:22.909503052 +0000 UTC m=+28.778810260 End:2018-08-27 11:32:22.911453948 +0000 UTC m=+28.780761130
I0827 11:32:22.911498       1 scheduler.go:454] Total Schedule Algo cumulative time:668.81508ms for 246
I0827 11:32:22.913507       1 scheduler.go:451] ScheduleAlgoTime 1.840117ms Start:2018-08-27 11:32:22.911661563 +0000 UTC m=+28.780968759 End:2018-08-27 11:32:22.913501693 +0000 UTC m=+28.782808876
I0827 11:32:22.913537       1 scheduler.go:454] Total Schedule Algo cumulative time:670.655197ms for 247
I0827 11:32:22.915776       1 scheduler.go:451] ScheduleAlgoTime 1.893731ms Start:2018-08-27 11:32:22.913875788 +0000 UTC m=+28.783183085 End:2018-08-27 11:32:22.915769634 +0000 UTC m=+28.785076816
I0827 11:32:22.915805       1 scheduler.go:454] Total Schedule Algo cumulative time:672.548928ms for 248
I0827 11:32:22.917644       1 scheduler.go:451] ScheduleAlgoTime 1.596846ms Start:2018-08-27 11:32:22.916041798 +0000 UTC m=+28.785349076 End:2018-08-27 11:32:22.917638739 +0000 UTC m=+28.786945922
I0827 11:32:22.917673       1 scheduler.go:454] Total Schedule Algo cumulative time:674.145774ms for 249
I0827 11:32:22.919678       1 scheduler.go:451] ScheduleAlgoTime 1.763523ms Start:2018-08-27 11:32:22.917906613 +0000 UTC m=+28.787213820 End:2018-08-27 11:32:22.919670158 +0000 UTC m=+28.788977343
I0827 11:32:22.919780       1 scheduler.go:454] Total Schedule Algo cumulative time:675.909297ms for 250
I0827 11:32:22.921725       1 scheduler.go:451] ScheduleAlgoTime 1.690543ms Start:2018-08-27 11:32:22.920027612 +0000 UTC m=+28.789334875 End:2018-08-27 11:32:22.921718235 +0000 UTC m=+28.791025418
I0827 11:32:22.921751       1 scheduler.go:454] Total Schedule Algo cumulative time:677.59984ms for 251
I0827 11:32:22.923717       1 scheduler.go:451] ScheduleAlgoTime 1.685052ms Start:2018-08-27 11:32:22.922025891 +0000 UTC m=+28.791333160 End:2018-08-27 11:32:22.923711026 +0000 UTC m=+28.793018212
I0827 11:32:22.923750       1 scheduler.go:454] Total Schedule Algo cumulative time:679.284892ms for 252
I0827 11:32:22.925637       1 scheduler.go:451] ScheduleAlgoTime 1.728358ms Start:2018-08-27 11:32:22.923903202 +0000 UTC m=+28.793210435 End:2018-08-27 11:32:22.925631611 +0000 UTC m=+28.794938793
I0827 11:32:22.925662       1 scheduler.go:454] Total Schedule Algo cumulative time:681.01325ms for 253
I0827 11:32:22.927730       1 scheduler.go:451] ScheduleAlgoTime 1.75809ms Start:2018-08-27 11:32:22.925967043 +0000 UTC m=+28.795274258 End:2018-08-27 11:32:22.927725167 +0000 UTC m=+28.797032348
I0827 11:32:22.927754       1 scheduler.go:454] Total Schedule Algo cumulative time:682.77134ms for 254
I0827 11:32:22.929833       1 scheduler.go:451] ScheduleAlgoTime 1.90396ms Start:2018-08-27 11:32:22.92792052 +0000 UTC m=+28.797227702 End:2018-08-27 11:32:22.929824477 +0000 UTC m=+28.799131662
I0827 11:32:22.929862       1 scheduler.go:454] Total Schedule Algo cumulative time:684.6753ms for 255
I0827 11:32:22.932075       1 scheduler.go:451] ScheduleAlgoTime 2.015946ms Start:2018-08-27 11:32:22.9299882 +0000 UTC m=+28.799295438 End:2018-08-27 11:32:22.932004202 +0000 UTC m=+28.801311384
I0827 11:32:22.932115       1 scheduler.go:454] Total Schedule Algo cumulative time:686.691246ms for 256
I0827 11:32:22.933949       1 scheduler.go:451] ScheduleAlgoTime 1.578642ms Start:2018-08-27 11:32:22.932364562 +0000 UTC m=+28.801671799 End:2018-08-27 11:32:22.933943252 +0000 UTC m=+28.803250441
I0827 11:32:22.933988       1 scheduler.go:454] Total Schedule Algo cumulative time:688.269888ms for 257
I0827 11:32:22.935956       1 scheduler.go:451] ScheduleAlgoTime 1.67813ms Start:2018-08-27 11:32:22.934272215 +0000 UTC m=+28.803579469 End:2018-08-27 11:32:22.935950413 +0000 UTC m=+28.805257599
I0827 11:32:22.935982       1 scheduler.go:454] Total Schedule Algo cumulative time:689.948018ms for 258
I0827 11:32:22.938148       1 scheduler.go:451] ScheduleAlgoTime 2.022604ms Start:2018-08-27 11:32:22.936120812 +0000 UTC m=+28.805428065 End:2018-08-27 11:32:22.938143486 +0000 UTC m=+28.807450669
I0827 11:32:22.938173       1 scheduler.go:454] Total Schedule Algo cumulative time:691.970622ms for 259
I0827 11:32:22.940067       1 scheduler.go:451] ScheduleAlgoTime 1.66039ms Start:2018-08-27 11:32:22.938401164 +0000 UTC m=+28.807708403 End:2018-08-27 11:32:22.940061611 +0000 UTC m=+28.809368793
I0827 11:32:22.940092       1 scheduler.go:454] Total Schedule Algo cumulative time:693.631012ms for 260
I0827 11:32:22.941933       1 scheduler.go:451] ScheduleAlgoTime 1.604026ms Start:2018-08-27 11:32:22.940323885 +0000 UTC m=+28.809631143 End:2018-08-27 11:32:22.941927988 +0000 UTC m=+28.811235169
I0827 11:32:22.941957       1 scheduler.go:454] Total Schedule Algo cumulative time:695.235038ms for 261
I0827 11:32:22.943869       1 scheduler.go:451] ScheduleAlgoTime 1.656775ms Start:2018-08-27 11:32:22.942207179 +0000 UTC m=+28.811514393 End:2018-08-27 11:32:22.943863985 +0000 UTC m=+28.813171168
I0827 11:32:22.943891       1 scheduler.go:454] Total Schedule Algo cumulative time:696.891813ms for 262
I0827 11:32:22.945782       1 scheduler.go:451] ScheduleAlgoTime 1.665155ms Start:2018-08-27 11:32:22.944110804 +0000 UTC m=+28.813418055 End:2018-08-27 11:32:22.945776026 +0000 UTC m=+28.815083210
I0827 11:32:22.945828       1 scheduler.go:454] Total Schedule Algo cumulative time:698.556968ms for 263
I0827 11:32:22.948387       1 scheduler.go:451] ScheduleAlgoTime 2.354324ms Start:2018-08-27 11:32:22.94602465 +0000 UTC m=+28.815331914 End:2018-08-27 11:32:22.948379051 +0000 UTC m=+28.817686238
I0827 11:32:22.948419       1 scheduler.go:454] Total Schedule Algo cumulative time:700.911292ms for 264
I0827 11:32:22.950355       1 scheduler.go:451] ScheduleAlgoTime 1.7418ms Start:2018-08-27 11:32:22.948603948 +0000 UTC m=+28.817911226 End:2018-08-27 11:32:22.9503458 +0000 UTC m=+28.819653026
I0827 11:32:22.950388       1 scheduler.go:454] Total Schedule Algo cumulative time:702.653092ms for 265
I0827 11:32:22.952752       1 scheduler.go:451] ScheduleAlgoTime 2.210682ms Start:2018-08-27 11:32:22.950528614 +0000 UTC m=+28.819835853 End:2018-08-27 11:32:22.952739346 +0000 UTC m=+28.822046535
I0827 11:32:22.952790       1 scheduler.go:454] Total Schedule Algo cumulative time:704.863774ms for 266
I0827 11:32:22.954767       1 scheduler.go:451] ScheduleAlgoTime 1.648949ms Start:2018-08-27 11:32:22.953112362 +0000 UTC m=+28.822419602 End:2018-08-27 11:32:22.954761367 +0000 UTC m=+28.824068551
I0827 11:32:22.954793       1 scheduler.go:454] Total Schedule Algo cumulative time:706.512723ms for 267
I0827 11:32:22.956517       1 scheduler.go:451] ScheduleAlgoTime 1.484749ms Start:2018-08-27 11:32:22.955025788 +0000 UTC m=+28.824333008 End:2018-08-27 11:32:22.956510573 +0000 UTC m=+28.825817757
I0827 11:32:22.956545       1 scheduler.go:454] Total Schedule Algo cumulative time:707.997472ms for 268
I0827 11:32:22.958358       1 scheduler.go:451] ScheduleAlgoTime 1.577168ms Start:2018-08-27 11:32:22.956774722 +0000 UTC m=+28.826081975 End:2018-08-27 11:32:22.95835196 +0000 UTC m=+28.827659143
I0827 11:32:22.958381       1 scheduler.go:454] Total Schedule Algo cumulative time:709.57464ms for 269
I0827 11:32:22.960532       1 scheduler.go:451] ScheduleAlgoTime 1.889494ms Start:2018-08-27 11:32:22.958636414 +0000 UTC m=+28.827943607 End:2018-08-27 11:32:22.960525919 +0000 UTC m=+28.829833101
I0827 11:32:22.960556       1 scheduler.go:454] Total Schedule Algo cumulative time:711.464134ms for 270
I0827 11:32:22.963596       1 scheduler.go:451] ScheduleAlgoTime 2.912353ms Start:2018-08-27 11:32:22.960674432 +0000 UTC m=+28.829981613 End:2018-08-27 11:32:22.963586773 +0000 UTC m=+28.832893966
I0827 11:32:22.963733       1 scheduler.go:454] Total Schedule Algo cumulative time:714.376487ms for 271
I0827 11:32:22.967895       1 scheduler.go:451] ScheduleAlgoTime 3.989392ms Start:2018-08-27 11:32:22.963896685 +0000 UTC m=+28.833203902 End:2018-08-27 11:32:22.967886106 +0000 UTC m=+28.837193294
I0827 11:32:22.967935       1 scheduler.go:454] Total Schedule Algo cumulative time:718.365879ms for 272
I0827 11:32:22.970098       1 scheduler.go:451] ScheduleAlgoTime 1.872169ms Start:2018-08-27 11:32:22.968219396 +0000 UTC m=+28.837526650 End:2018-08-27 11:32:22.970091632 +0000 UTC m=+28.839398819
I0827 11:32:22.970137       1 scheduler.go:454] Total Schedule Algo cumulative time:720.238048ms for 273
I0827 11:32:22.972085       1 scheduler.go:451] ScheduleAlgoTime 1.776947ms Start:2018-08-27 11:32:22.970302631 +0000 UTC m=+28.839609888 End:2018-08-27 11:32:22.972079647 +0000 UTC m=+28.841386835
I0827 11:32:22.972114       1 scheduler.go:454] Total Schedule Algo cumulative time:722.014995ms for 274
I0827 11:32:22.973928       1 scheduler.go:451] ScheduleAlgoTime 1.559974ms Start:2018-08-27 11:32:22.972363143 +0000 UTC m=+28.841670327 End:2018-08-27 11:32:22.973923119 +0000 UTC m=+28.843230301
I0827 11:32:22.973954       1 scheduler.go:454] Total Schedule Algo cumulative time:723.574969ms for 275
I0827 11:32:22.976139       1 scheduler.go:451] ScheduleAlgoTime 2.052475ms Start:2018-08-27 11:32:22.974079369 +0000 UTC m=+28.843386552 End:2018-08-27 11:32:22.976131846 +0000 UTC m=+28.845439027
I0827 11:32:22.976170       1 scheduler.go:454] Total Schedule Algo cumulative time:725.627444ms for 276
I0827 11:32:22.978282       1 scheduler.go:451] ScheduleAlgoTime 1.89801ms Start:2018-08-27 11:32:22.976378468 +0000 UTC m=+28.845685649 End:2018-08-27 11:32:22.978276478 +0000 UTC m=+28.847583659
I0827 11:32:22.978321       1 scheduler.go:454] Total Schedule Algo cumulative time:727.525454ms for 277
I0827 11:32:22.980138       1 scheduler.go:451] ScheduleAlgoTime 1.641576ms Start:2018-08-27 11:32:22.978490996 +0000 UTC m=+28.847798242 End:2018-08-27 11:32:22.980132635 +0000 UTC m=+28.849439818
I0827 11:32:22.980167       1 scheduler.go:454] Total Schedule Algo cumulative time:729.16703ms for 278
I0827 11:32:22.981982       1 scheduler.go:451] ScheduleAlgoTime 1.584648ms Start:2018-08-27 11:32:22.98039279 +0000 UTC m=+28.849700002 End:2018-08-27 11:32:22.98197746 +0000 UTC m=+28.851284650
I0827 11:32:22.982007       1 scheduler.go:454] Total Schedule Algo cumulative time:730.751678ms for 279
I0827 11:32:22.983803       1 scheduler.go:451] ScheduleAlgoTime 1.645943ms Start:2018-08-27 11:32:22.982152268 +0000 UTC m=+28.851459451 End:2018-08-27 11:32:22.983798213 +0000 UTC m=+28.853105394
I0827 11:32:22.983837       1 scheduler.go:454] Total Schedule Algo cumulative time:732.397621ms for 280
I0827 11:32:22.985776       1 scheduler.go:451] ScheduleAlgoTime 1.729814ms Start:2018-08-27 11:32:22.984037709 +0000 UTC m=+28.853344904 End:2018-08-27 11:32:22.985767528 +0000 UTC m=+28.855074718
I0827 11:32:22.985862       1 scheduler.go:454] Total Schedule Algo cumulative time:734.127435ms for 281
I0827 11:32:22.987835       1 scheduler.go:451] ScheduleAlgoTime 1.803665ms Start:2018-08-27 11:32:22.986024644 +0000 UTC m=+28.855331903 End:2018-08-27 11:32:22.987828386 +0000 UTC m=+28.857135568
I0827 11:32:22.987867       1 scheduler.go:454] Total Schedule Algo cumulative time:735.9311ms for 282
I0827 11:32:22.989746       1 scheduler.go:451] ScheduleAlgoTime 1.58708ms Start:2018-08-27 11:32:22.988153318 +0000 UTC m=+28.857460580 End:2018-08-27 11:32:22.989740477 +0000 UTC m=+28.859047660
I0827 11:32:22.989802       1 scheduler.go:454] Total Schedule Algo cumulative time:737.51818ms for 283
I0827 11:32:22.991593       1 scheduler.go:451] ScheduleAlgoTime 1.602672ms Start:2018-08-27 11:32:22.989984823 +0000 UTC m=+28.859292006 End:2018-08-27 11:32:22.991587495 +0000 UTC m=+28.860894678
I0827 11:32:22.991616       1 scheduler.go:454] Total Schedule Algo cumulative time:739.120852ms for 284
I0827 11:32:22.994095       1 scheduler.go:451] ScheduleAlgoTime 2.002311ms Start:2018-08-27 11:32:22.992086612 +0000 UTC m=+28.861393853 End:2018-08-27 11:32:22.994088983 +0000 UTC m=+28.863396164
I0827 11:32:22.994122       1 scheduler.go:454] Total Schedule Algo cumulative time:741.123163ms for 285
I0827 11:32:22.996406       1 scheduler.go:451] ScheduleAlgoTime 2.050387ms Start:2018-08-27 11:32:22.994348768 +0000 UTC m=+28.863655973 End:2018-08-27 11:32:22.996399179 +0000 UTC m=+28.865706360
I0827 11:32:22.996439       1 scheduler.go:454] Total Schedule Algo cumulative time:743.17355ms for 286
I0827 11:32:22.998455       1 scheduler.go:451] ScheduleAlgoTime 1.858671ms Start:2018-08-27 11:32:22.996588804 +0000 UTC m=+28.865896034 End:2018-08-27 11:32:22.99844751 +0000 UTC m=+28.867754705
I0827 11:32:22.998493       1 scheduler.go:454] Total Schedule Algo cumulative time:745.032221ms for 287
I0827 11:32:23.000566       1 scheduler.go:451] ScheduleAlgoTime 1.798759ms Start:2018-08-27 11:32:22.998761064 +0000 UTC m=+28.868068301 End:2018-08-27 11:32:23.000559877 +0000 UTC m=+28.869867060
I0827 11:32:23.000598       1 scheduler.go:454] Total Schedule Algo cumulative time:746.83098ms for 288
I0827 11:32:23.002455       1 scheduler.go:451] ScheduleAlgoTime 1.581585ms Start:2018-08-27 11:32:23.000866254 +0000 UTC m=+28.870173492 End:2018-08-27 11:32:23.002447888 +0000 UTC m=+28.871755077
I0827 11:32:23.002489       1 scheduler.go:454] Total Schedule Algo cumulative time:748.412565ms for 289
I0827 11:32:23.004819       1 scheduler.go:451] ScheduleAlgoTime 1.975915ms Start:2018-08-27 11:32:23.002834395 +0000 UTC m=+28.872141642 End:2018-08-27 11:32:23.004810375 +0000 UTC m=+28.874117557
I0827 11:32:23.004851       1 scheduler.go:454] Total Schedule Algo cumulative time:750.38848ms for 290
I0827 11:32:23.006847       1 scheduler.go:451] ScheduleAlgoTime 1.799236ms Start:2018-08-27 11:32:23.005040179 +0000 UTC m=+28.874347437 End:2018-08-27 11:32:23.00683949 +0000 UTC m=+28.876146673
I0827 11:32:23.006878       1 scheduler.go:454] Total Schedule Algo cumulative time:752.187716ms for 291
I0827 11:32:23.009270       1 scheduler.go:451] ScheduleAlgoTime 2.177996ms Start:2018-08-27 11:32:23.007083573 +0000 UTC m=+28.876390815 End:2018-08-27 11:32:23.009261626 +0000 UTC m=+28.878568811
I0827 11:32:23.009308       1 scheduler.go:454] Total Schedule Algo cumulative time:754.365712ms for 292
I0827 11:32:23.011425       1 scheduler.go:451] ScheduleAlgoTime 1.82117ms Start:2018-08-27 11:32:23.009597128 +0000 UTC m=+28.878904369 End:2018-08-27 11:32:23.011418353 +0000 UTC m=+28.880725539
I0827 11:32:23.011452       1 scheduler.go:454] Total Schedule Algo cumulative time:756.186882ms for 293
I0827 11:32:23.013383       1 scheduler.go:451] ScheduleAlgoTime 1.709922ms Start:2018-08-27 11:32:23.011664335 +0000 UTC m=+28.880971515 End:2018-08-27 11:32:23.013374247 +0000 UTC m=+28.882681437
I0827 11:32:23.013442       1 scheduler.go:454] Total Schedule Algo cumulative time:757.896804ms for 294
I0827 11:32:23.015436       1 scheduler.go:451] ScheduleAlgoTime 1.80794ms Start:2018-08-27 11:32:23.013621716 +0000 UTC m=+28.882928921 End:2018-08-27 11:32:23.015429678 +0000 UTC m=+28.884736861
I0827 11:32:23.015463       1 scheduler.go:454] Total Schedule Algo cumulative time:759.704744ms for 295
I0827 11:32:23.017250       1 scheduler.go:451] ScheduleAlgoTime 1.664205ms Start:2018-08-27 11:32:23.015576124 +0000 UTC m=+28.884883337 End:2018-08-27 11:32:23.017240356 +0000 UTC m=+28.886547542
I0827 11:32:23.017284       1 scheduler.go:454] Total Schedule Algo cumulative time:761.368949ms for 296
I0827 11:32:23.019146       1 scheduler.go:451] ScheduleAlgoTime 1.603349ms Start:2018-08-27 11:32:23.017537223 +0000 UTC m=+28.886844444 End:2018-08-27 11:32:23.019140607 +0000 UTC m=+28.888447793
I0827 11:32:23.019174       1 scheduler.go:454] Total Schedule Algo cumulative time:762.972298ms for 297
I0827 11:32:23.021577       1 scheduler.go:451] ScheduleAlgoTime 2.196125ms Start:2018-08-27 11:32:23.019371502 +0000 UTC m=+28.888678727 End:2018-08-27 11:32:23.021567664 +0000 UTC m=+28.890874852
I0827 11:32:23.021619       1 scheduler.go:454] Total Schedule Algo cumulative time:765.168423ms for 298
I0827 11:32:23.023482       1 scheduler.go:451] ScheduleAlgoTime 1.612804ms Start:2018-08-27 11:32:23.021864149 +0000 UTC m=+28.891171409 End:2018-08-27 11:32:23.023477029 +0000 UTC m=+28.892784213
I0827 11:32:23.023509       1 scheduler.go:454] Total Schedule Algo cumulative time:766.781227ms for 299
I0827 11:32:23.025565       1 scheduler.go:451] ScheduleAlgoTime 1.758545ms Start:2018-08-27 11:32:23.023798491 +0000 UTC m=+28.893105710 End:2018-08-27 11:32:23.025557057 +0000 UTC m=+28.894864255
I0827 11:32:23.025600       1 scheduler.go:454] Total Schedule Algo cumulative time:768.539772ms for 300
I0827 11:32:23.027789       1 scheduler.go:451] ScheduleAlgoTime 1.879535ms Start:2018-08-27 11:32:23.025900397 +0000 UTC m=+28.895207646 End:2018-08-27 11:32:23.027779868 +0000 UTC m=+28.897087181
I0827 11:32:23.027823       1 scheduler.go:454] Total Schedule Algo cumulative time:770.419307ms for 301
I0827 11:32:23.030329       1 scheduler.go:451] ScheduleAlgoTime 2.272405ms Start:2018-08-27 11:32:23.02805052 +0000 UTC m=+28.897357777 End:2018-08-27 11:32:23.030322984 +0000 UTC m=+28.899630182
I0827 11:32:23.030354       1 scheduler.go:454] Total Schedule Algo cumulative time:772.691712ms for 302
I0827 11:32:23.032649       1 scheduler.go:451] ScheduleAlgoTime 2.178112ms Start:2018-08-27 11:32:23.030463205 +0000 UTC m=+28.899770387 End:2018-08-27 11:32:23.032641318 +0000 UTC m=+28.901948499
I0827 11:32:23.032720       1 scheduler.go:454] Total Schedule Algo cumulative time:774.869824ms for 303
I0827 11:32:23.038555       1 scheduler.go:451] ScheduleAlgoTime 5.663294ms Start:2018-08-27 11:32:23.03288073 +0000 UTC m=+28.902187951 End:2018-08-27 11:32:23.03854406 +0000 UTC m=+28.907851245
I0827 11:32:23.038602       1 scheduler.go:454] Total Schedule Algo cumulative time:780.533118ms for 304
I0827 11:32:23.040786       1 scheduler.go:451] ScheduleAlgoTime 1.800211ms Start:2018-08-27 11:32:23.038972167 +0000 UTC m=+28.908279387 End:2018-08-27 11:32:23.040772416 +0000 UTC m=+28.910079598
I0827 11:32:23.040831       1 scheduler.go:454] Total Schedule Algo cumulative time:782.333329ms for 305
I0827 11:32:23.042828       1 scheduler.go:451] ScheduleAlgoTime 1.756135ms Start:2018-08-27 11:32:23.041064847 +0000 UTC m=+28.910372072 End:2018-08-27 11:32:23.042821025 +0000 UTC m=+28.912128207
I0827 11:32:23.042862       1 scheduler.go:454] Total Schedule Algo cumulative time:784.089464ms for 306
I0827 11:32:23.044745       1 scheduler.go:451] ScheduleAlgoTime 1.701431ms Start:2018-08-27 11:32:23.043035651 +0000 UTC m=+28.912342862 End:2018-08-27 11:32:23.044737111 +0000 UTC m=+28.914044293
I0827 11:32:23.044784       1 scheduler.go:454] Total Schedule Algo cumulative time:785.790895ms for 307
I0827 11:32:23.046742       1 scheduler.go:451] ScheduleAlgoTime 1.708773ms Start:2018-08-27 11:32:23.04502668 +0000 UTC m=+28.914333936 End:2018-08-27 11:32:23.046735527 +0000 UTC m=+28.916042709
I0827 11:32:23.046770       1 scheduler.go:454] Total Schedule Algo cumulative time:787.499668ms for 308
I0827 11:32:23.048678       1 scheduler.go:451] ScheduleAlgoTime 1.74786ms Start:2018-08-27 11:32:23.046924904 +0000 UTC m=+28.916232085 End:2018-08-27 11:32:23.048672764 +0000 UTC m=+28.917979945
I0827 11:32:23.048751       1 scheduler.go:454] Total Schedule Algo cumulative time:789.247528ms for 309
I0827 11:32:23.050535       1 scheduler.go:451] ScheduleAlgoTime 1.627405ms Start:2018-08-27 11:32:23.048900136 +0000 UTC m=+28.918207318 End:2018-08-27 11:32:23.05052752 +0000 UTC m=+28.919834723
I0827 11:32:23.050581       1 scheduler.go:454] Total Schedule Algo cumulative time:790.874933ms for 310
I0827 11:32:23.053086       1 scheduler.go:451] ScheduleAlgoTime 2.301637ms Start:2018-08-27 11:32:23.050778052 +0000 UTC m=+28.920085286 End:2018-08-27 11:32:23.05307974 +0000 UTC m=+28.922386923
I0827 11:32:23.053130       1 scheduler.go:454] Total Schedule Algo cumulative time:793.17657ms for 311
I0827 11:32:23.055244       1 scheduler.go:451] ScheduleAlgoTime 1.890837ms Start:2018-08-27 11:32:23.053346075 +0000 UTC m=+28.922653294 End:2018-08-27 11:32:23.055236948 +0000 UTC m=+28.924544131
I0827 11:32:23.055275       1 scheduler.go:454] Total Schedule Algo cumulative time:795.067407ms for 312
I0827 11:32:23.057119       1 scheduler.go:451] ScheduleAlgoTime 1.711007ms Start:2018-08-27 11:32:23.05540118 +0000 UTC m=+28.924708454 End:2018-08-27 11:32:23.057112275 +0000 UTC m=+28.926419461
I0827 11:32:23.057152       1 scheduler.go:454] Total Schedule Algo cumulative time:796.778414ms for 313
I0827 11:32:23.059020       1 scheduler.go:451] ScheduleAlgoTime 1.655563ms Start:2018-08-27 11:32:23.057360012 +0000 UTC m=+28.926667248 End:2018-08-27 11:32:23.059015627 +0000 UTC m=+28.928322811
I0827 11:32:23.059048       1 scheduler.go:454] Total Schedule Algo cumulative time:798.433977ms for 314
I0827 11:32:23.060999       1 scheduler.go:451] ScheduleAlgoTime 1.732686ms Start:2018-08-27 11:32:23.059258507 +0000 UTC m=+28.928565710 End:2018-08-27 11:32:23.060991215 +0000 UTC m=+28.930298396
I0827 11:32:23.061033       1 scheduler.go:454] Total Schedule Algo cumulative time:800.166663ms for 315
I0827 11:32:23.063376       1 scheduler.go:451] ScheduleAlgoTime 1.881061ms Start:2018-08-27 11:32:23.061489678 +0000 UTC m=+28.930796914 End:2018-08-27 11:32:23.063370791 +0000 UTC m=+28.932677975
I0827 11:32:23.063412       1 scheduler.go:454] Total Schedule Algo cumulative time:802.047724ms for 316
I0827 11:32:23.065276       1 scheduler.go:451] ScheduleAlgoTime 1.691728ms Start:2018-08-27 11:32:23.063580388 +0000 UTC m=+28.932887626 End:2018-08-27 11:32:23.065272173 +0000 UTC m=+28.934579354
I0827 11:32:23.065304       1 scheduler.go:454] Total Schedule Algo cumulative time:803.739452ms for 317
I0827 11:32:23.067266       1 scheduler.go:451] ScheduleAlgoTime 1.784674ms Start:2018-08-27 11:32:23.065473933 +0000 UTC m=+28.934781177 End:2018-08-27 11:32:23.067258668 +0000 UTC m=+28.936565851
I0827 11:32:23.067299       1 scheduler.go:454] Total Schedule Algo cumulative time:805.524126ms for 318
I0827 11:32:23.069825       1 scheduler.go:451] ScheduleAlgoTime 2.362657ms Start:2018-08-27 11:32:23.067454695 +0000 UTC m=+28.936761891 End:2018-08-27 11:32:23.069817364 +0000 UTC m=+28.939124548
I0827 11:32:23.069854       1 scheduler.go:454] Total Schedule Algo cumulative time:807.886783ms for 319
I0827 11:32:23.072089       1 scheduler.go:451] ScheduleAlgoTime 1.910443ms Start:2018-08-27 11:32:23.070171887 +0000 UTC m=+28.939479125 End:2018-08-27 11:32:23.072082385 +0000 UTC m=+28.941389568
I0827 11:32:23.072122       1 scheduler.go:454] Total Schedule Algo cumulative time:809.797226ms for 320
I0827 11:32:23.074287       1 scheduler.go:451] ScheduleAlgoTime 1.894807ms Start:2018-08-27 11:32:23.072385022 +0000 UTC m=+28.941692266 End:2018-08-27 11:32:23.074279889 +0000 UTC m=+28.943587073
I0827 11:32:23.074319       1 scheduler.go:454] Total Schedule Algo cumulative time:811.692033ms for 321
I0827 11:32:23.076204       1 scheduler.go:451] ScheduleAlgoTime 1.727917ms Start:2018-08-27 11:32:23.07447036 +0000 UTC m=+28.943777610 End:2018-08-27 11:32:23.076198346 +0000 UTC m=+28.945505527
I0827 11:32:23.076229       1 scheduler.go:454] Total Schedule Algo cumulative time:813.41995ms for 322
I0827 11:32:23.078147       1 scheduler.go:451] ScheduleAlgoTime 1.653296ms Start:2018-08-27 11:32:23.076488574 +0000 UTC m=+28.945795820 End:2018-08-27 11:32:23.078141931 +0000 UTC m=+28.947449116
I0827 11:32:23.078172       1 scheduler.go:454] Total Schedule Algo cumulative time:815.073246ms for 323
I0827 11:32:23.080429       1 scheduler.go:451] ScheduleAlgoTime 1.906655ms Start:2018-08-27 11:32:23.078516463 +0000 UTC m=+28.947823700 End:2018-08-27 11:32:23.080423169 +0000 UTC m=+28.949730355
I0827 11:32:23.080479       1 scheduler.go:454] Total Schedule Algo cumulative time:816.979901ms for 324
I0827 11:32:23.082404       1 scheduler.go:451] ScheduleAlgoTime 1.571157ms Start:2018-08-27 11:32:23.080826903 +0000 UTC m=+28.950134173 End:2018-08-27 11:32:23.082398146 +0000 UTC m=+28.951705330
I0827 11:32:23.082426       1 scheduler.go:454] Total Schedule Algo cumulative time:818.551058ms for 325
I0827 11:32:23.084563       1 scheduler.go:451] ScheduleAlgoTime 1.853477ms Start:2018-08-27 11:32:23.082705059 +0000 UTC m=+28.952012265 End:2018-08-27 11:32:23.08455856 +0000 UTC m=+28.953865742
I0827 11:32:23.084588       1 scheduler.go:454] Total Schedule Algo cumulative time:820.404535ms for 326
I0827 11:32:23.086528       1 scheduler.go:451] ScheduleAlgoTime 1.654587ms Start:2018-08-27 11:32:23.084865633 +0000 UTC m=+28.954172884 End:2018-08-27 11:32:23.08652029 +0000 UTC m=+28.955827471
I0827 11:32:23.086556       1 scheduler.go:454] Total Schedule Algo cumulative time:822.059122ms for 327
I0827 11:32:23.088318       1 scheduler.go:451] ScheduleAlgoTime 1.525313ms Start:2018-08-27 11:32:23.086787352 +0000 UTC m=+28.956094610 End:2018-08-27 11:32:23.08831274 +0000 UTC m=+28.957619923
I0827 11:32:23.088351       1 scheduler.go:454] Total Schedule Algo cumulative time:823.584435ms for 328
I0827 11:32:23.090036       1 scheduler.go:451] ScheduleAlgoTime 1.542704ms Start:2018-08-27 11:32:23.088484389 +0000 UTC m=+28.957791644 End:2018-08-27 11:32:23.09002716 +0000 UTC m=+28.959334348
I0827 11:32:23.090069       1 scheduler.go:454] Total Schedule Algo cumulative time:825.127139ms for 329
I0827 11:32:23.092047       1 scheduler.go:451] ScheduleAlgoTime 1.748499ms Start:2018-08-27 11:32:23.090292624 +0000 UTC m=+28.959599865 End:2018-08-27 11:32:23.092041183 +0000 UTC m=+28.961348364
I0827 11:32:23.092075       1 scheduler.go:454] Total Schedule Algo cumulative time:826.875638ms for 330
I0827 11:32:23.094456       1 scheduler.go:451] ScheduleAlgoTime 2.1094ms Start:2018-08-27 11:32:23.092341512 +0000 UTC m=+28.961648750 End:2018-08-27 11:32:23.094450966 +0000 UTC m=+28.963758150
I0827 11:32:23.094481       1 scheduler.go:454] Total Schedule Algo cumulative time:828.985038ms for 331
I0827 11:32:23.096455       1 scheduler.go:451] ScheduleAlgoTime 1.815784ms Start:2018-08-27 11:32:23.094633151 +0000 UTC m=+28.963940404 End:2018-08-27 11:32:23.096449006 +0000 UTC m=+28.965756188
I0827 11:32:23.096480       1 scheduler.go:454] Total Schedule Algo cumulative time:830.800822ms for 332
I0827 11:32:23.098254       1 scheduler.go:451] ScheduleAlgoTime 1.570739ms Start:2018-08-27 11:32:23.096675988 +0000 UTC m=+28.965983192 End:2018-08-27 11:32:23.098246744 +0000 UTC m=+28.967553931
I0827 11:32:23.098286       1 scheduler.go:454] Total Schedule Algo cumulative time:832.371561ms for 333
I0827 11:32:23.100567       1 scheduler.go:451] ScheduleAlgoTime 2.006308ms Start:2018-08-27 11:32:23.098553765 +0000 UTC m=+28.967861013 End:2018-08-27 11:32:23.10056014 +0000 UTC m=+28.969867321
I0827 11:32:23.100598       1 scheduler.go:454] Total Schedule Algo cumulative time:834.377869ms for 334
I0827 11:32:23.102580       1 scheduler.go:451] ScheduleAlgoTime 1.688876ms Start:2018-08-27 11:32:23.100886305 +0000 UTC m=+28.970193535 End:2018-08-27 11:32:23.102575229 +0000 UTC m=+28.971882411
I0827 11:32:23.102603       1 scheduler.go:454] Total Schedule Algo cumulative time:836.066745ms for 335
I0827 11:32:23.104822       1 scheduler.go:451] ScheduleAlgoTime 2.083772ms Start:2018-08-27 11:32:23.102732814 +0000 UTC m=+28.972039997 End:2018-08-27 11:32:23.104816587 +0000 UTC m=+28.974123769
I0827 11:32:23.104850       1 scheduler.go:454] Total Schedule Algo cumulative time:838.150517ms for 336
I0827 11:32:23.106482       1 scheduler.go:451] ScheduleAlgoTime 1.439442ms Start:2018-08-27 11:32:23.105034246 +0000 UTC m=+28.974341482 End:2018-08-27 11:32:23.106473741 +0000 UTC m=+28.975780924
I0827 11:32:23.106523       1 scheduler.go:454] Total Schedule Algo cumulative time:839.589959ms for 337
I0827 11:32:23.109120       1 scheduler.go:451] ScheduleAlgoTime 2.322302ms Start:2018-08-27 11:32:23.106791386 +0000 UTC m=+28.976098633 End:2018-08-27 11:32:23.109113747 +0000 UTC m=+28.978420935
I0827 11:32:23.109149       1 scheduler.go:454] Total Schedule Algo cumulative time:841.912261ms for 338
I0827 11:32:23.115622       1 scheduler.go:451] ScheduleAlgoTime 5.986282ms Start:2018-08-27 11:32:23.109625712 +0000 UTC m=+28.978932923 End:2018-08-27 11:32:23.115612022 +0000 UTC m=+28.984919205
I0827 11:32:23.115757       1 scheduler.go:454] Total Schedule Algo cumulative time:847.898543ms for 339
I0827 11:32:23.119045       1 scheduler.go:451] ScheduleAlgoTime 3.034205ms Start:2018-08-27 11:32:23.116000587 +0000 UTC m=+28.985307863 End:2018-08-27 11:32:23.119034884 +0000 UTC m=+28.988342068
I0827 11:32:23.119086       1 scheduler.go:454] Total Schedule Algo cumulative time:850.932748ms for 340
I0827 11:32:23.121074       1 scheduler.go:451] ScheduleAlgoTime 1.786668ms Start:2018-08-27 11:32:23.11928043 +0000 UTC m=+28.988587673 End:2018-08-27 11:32:23.121067157 +0000 UTC m=+28.990374341
I0827 11:32:23.121107       1 scheduler.go:454] Total Schedule Algo cumulative time:852.719416ms for 341
I0827 11:32:23.122892       1 scheduler.go:451] ScheduleAlgoTime 1.528167ms Start:2018-08-27 11:32:23.121350207 +0000 UTC m=+28.990657449 End:2018-08-27 11:32:23.122878432 +0000 UTC m=+28.992185616
I0827 11:32:23.122933       1 scheduler.go:454] Total Schedule Algo cumulative time:854.247583ms for 342
I0827 11:32:23.124895       1 scheduler.go:451] ScheduleAlgoTime 1.658006ms Start:2018-08-27 11:32:23.123232372 +0000 UTC m=+28.992539592 End:2018-08-27 11:32:23.124890415 +0000 UTC m=+28.994197598
I0827 11:32:23.124920       1 scheduler.go:454] Total Schedule Algo cumulative time:855.905589ms for 343
I0827 11:32:23.126939       1 scheduler.go:451] ScheduleAlgoTime 1.799986ms Start:2018-08-27 11:32:23.125132019 +0000 UTC m=+28.994439260 End:2018-08-27 11:32:23.126932062 +0000 UTC m=+28.996239246
I0827 11:32:23.126969       1 scheduler.go:454] Total Schedule Algo cumulative time:857.705575ms for 344
I0827 11:32:23.129513       1 scheduler.go:451] ScheduleAlgoTime 2.242704ms Start:2018-08-27 11:32:23.127264038 +0000 UTC m=+28.996571298 End:2018-08-27 11:32:23.129506819 +0000 UTC m=+28.998814002
I0827 11:32:23.129545       1 scheduler.go:454] Total Schedule Algo cumulative time:859.948279ms for 345
I0827 11:32:23.132053       1 scheduler.go:451] ScheduleAlgoTime 2.181267ms Start:2018-08-27 11:32:23.129862261 +0000 UTC m=+28.999169520 End:2018-08-27 11:32:23.132043488 +0000 UTC m=+29.001350787
I0827 11:32:23.132095       1 scheduler.go:454] Total Schedule Algo cumulative time:862.129546ms for 346
I0827 11:32:23.134475       1 scheduler.go:451] ScheduleAlgoTime 2.001794ms Start:2018-08-27 11:32:23.132463158 +0000 UTC m=+29.001770421 End:2018-08-27 11:32:23.134465032 +0000 UTC m=+29.003772215
I0827 11:32:23.134514       1 scheduler.go:454] Total Schedule Algo cumulative time:864.13134ms for 347
I0827 11:32:23.136533       1 scheduler.go:451] ScheduleAlgoTime 1.680688ms Start:2018-08-27 11:32:23.134845295 +0000 UTC m=+29.004152541 End:2018-08-27 11:32:23.136526047 +0000 UTC m=+29.005833229
I0827 11:32:23.136575       1 scheduler.go:454] Total Schedule Algo cumulative time:865.812028ms for 348
I0827 11:32:23.138482       1 scheduler.go:451] ScheduleAlgoTime 1.590863ms Start:2018-08-27 11:32:23.136885982 +0000 UTC m=+29.006193183 End:2018-08-27 11:32:23.138476864 +0000 UTC m=+29.007784046
I0827 11:32:23.138508       1 scheduler.go:454] Total Schedule Algo cumulative time:867.402891ms for 349
I0827 11:32:23.140211       1 scheduler.go:451] ScheduleAlgoTime 1.552766ms Start:2018-08-27 11:32:23.13865268 +0000 UTC m=+29.007959882 End:2018-08-27 11:32:23.140205465 +0000 UTC m=+29.009512648
I0827 11:32:23.140239       1 scheduler.go:454] Total Schedule Algo cumulative time:868.955657ms for 350
I0827 11:32:23.142334       1 scheduler.go:451] ScheduleAlgoTime 1.874888ms Start:2018-08-27 11:32:23.140452726 +0000 UTC m=+29.009759965 End:2018-08-27 11:32:23.142327668 +0000 UTC m=+29.011634853
I0827 11:32:23.142372       1 scheduler.go:454] Total Schedule Algo cumulative time:870.830545ms for 351
I0827 11:32:23.144603       1 scheduler.go:451] ScheduleAlgoTime 1.858831ms Start:2018-08-27 11:32:23.142737591 +0000 UTC m=+29.012044871 End:2018-08-27 11:32:23.144596519 +0000 UTC m=+29.013903702
I0827 11:32:23.144635       1 scheduler.go:454] Total Schedule Algo cumulative time:872.689376ms for 352
I0827 11:32:23.146418       1 scheduler.go:451] ScheduleAlgoTime 1.57034ms Start:2018-08-27 11:32:23.144841079 +0000 UTC m=+29.014148342 End:2018-08-27 11:32:23.146411498 +0000 UTC m=+29.015718682
I0827 11:32:23.146444       1 scheduler.go:454] Total Schedule Algo cumulative time:874.259716ms for 353
I0827 11:32:23.148895       1 scheduler.go:451] ScheduleAlgoTime 2.224448ms Start:2018-08-27 11:32:23.146663366 +0000 UTC m=+29.015970612 End:2018-08-27 11:32:23.148887878 +0000 UTC m=+29.018195060
I0827 11:32:23.148921       1 scheduler.go:454] Total Schedule Algo cumulative time:876.484164ms for 354
I0827 11:32:23.151067       1 scheduler.go:451] ScheduleAlgoTime 1.949466ms Start:2018-08-27 11:32:23.149109465 +0000 UTC m=+29.018416727 End:2018-08-27 11:32:23.151059001 +0000 UTC m=+29.020366193
I0827 11:32:23.151097       1 scheduler.go:454] Total Schedule Algo cumulative time:878.43363ms for 355
I0827 11:32:23.152996       1 scheduler.go:451] ScheduleAlgoTime 1.73721ms Start:2018-08-27 11:32:23.151251034 +0000 UTC m=+29.020558225 End:2018-08-27 11:32:23.152988254 +0000 UTC m=+29.022295435
I0827 11:32:23.153032       1 scheduler.go:454] Total Schedule Algo cumulative time:880.17084ms for 356
I0827 11:32:23.155446       1 scheduler.go:451] ScheduleAlgoTime 2.062893ms Start:2018-08-27 11:32:23.15337672 +0000 UTC m=+29.022683954 End:2018-08-27 11:32:23.155439665 +0000 UTC m=+29.024746847
I0827 11:32:23.155474       1 scheduler.go:454] Total Schedule Algo cumulative time:882.233733ms for 357
I0827 11:32:23.157670       1 scheduler.go:451] ScheduleAlgoTime 1.990519ms Start:2018-08-27 11:32:23.155673333 +0000 UTC m=+29.024980591 End:2018-08-27 11:32:23.157663928 +0000 UTC m=+29.026971110
I0827 11:32:23.157735       1 scheduler.go:454] Total Schedule Algo cumulative time:884.224252ms for 358
I0827 11:32:23.160033       1 scheduler.go:451] ScheduleAlgoTime 2.15307ms Start:2018-08-27 11:32:23.157872684 +0000 UTC m=+29.027179866 End:2018-08-27 11:32:23.160025752 +0000 UTC m=+29.029332936
I0827 11:32:23.160066       1 scheduler.go:454] Total Schedule Algo cumulative time:886.377322ms for 359
I0827 11:32:23.162403       1 scheduler.go:451] ScheduleAlgoTime 2.036983ms Start:2018-08-27 11:32:23.160348307 +0000 UTC m=+29.029655528 End:2018-08-27 11:32:23.162385329 +0000 UTC m=+29.031692511
I0827 11:32:23.162435       1 scheduler.go:454] Total Schedule Algo cumulative time:888.414305ms for 360
I0827 11:32:23.164412       1 scheduler.go:451] ScheduleAlgoTime 1.828935ms Start:2018-08-27 11:32:23.162570291 +0000 UTC m=+29.031877474 End:2018-08-27 11:32:23.164399181 +0000 UTC m=+29.033706409
I0827 11:32:23.164451       1 scheduler.go:454] Total Schedule Algo cumulative time:890.24324ms for 361
I0827 11:32:23.166952       1 scheduler.go:451] ScheduleAlgoTime 2.152272ms Start:2018-08-27 11:32:23.164791535 +0000 UTC m=+29.034098805 End:2018-08-27 11:32:23.166943894 +0000 UTC m=+29.036251077
I0827 11:32:23.166991       1 scheduler.go:454] Total Schedule Algo cumulative time:892.395512ms for 362
I0827 11:32:23.170123       1 scheduler.go:451] ScheduleAlgoTime 2.836091ms Start:2018-08-27 11:32:23.167279019 +0000 UTC m=+29.036586275 End:2018-08-27 11:32:23.170115185 +0000 UTC m=+29.039422366
I0827 11:32:23.170152       1 scheduler.go:454] Total Schedule Algo cumulative time:895.231603ms for 363
I0827 11:32:23.172580       1 scheduler.go:451] ScheduleAlgoTime 2.26089ms Start:2018-08-27 11:32:23.17030673 +0000 UTC m=+29.039613991 End:2018-08-27 11:32:23.172567685 +0000 UTC m=+29.041874881
I0827 11:32:23.172643       1 scheduler.go:454] Total Schedule Algo cumulative time:897.492493ms for 364
I0827 11:32:23.174846       1 scheduler.go:451] ScheduleAlgoTime 1.907533ms Start:2018-08-27 11:32:23.172931339 +0000 UTC m=+29.042238597 End:2018-08-27 11:32:23.174838941 +0000 UTC m=+29.044146130
I0827 11:32:23.174875       1 scheduler.go:454] Total Schedule Algo cumulative time:899.400026ms for 365
I0827 11:32:23.177302       1 scheduler.go:451] ScheduleAlgoTime 2.140545ms Start:2018-08-27 11:32:23.17515196 +0000 UTC m=+29.044459186 End:2018-08-27 11:32:23.177292548 +0000 UTC m=+29.046599731
I0827 11:32:23.177332       1 scheduler.go:454] Total Schedule Algo cumulative time:901.540571ms for 366
I0827 11:32:23.179297       1 scheduler.go:451] ScheduleAlgoTime 1.720413ms Start:2018-08-27 11:32:23.177571147 +0000 UTC m=+29.046878382 End:2018-08-27 11:32:23.179291614 +0000 UTC m=+29.048598795
I0827 11:32:23.179324       1 scheduler.go:454] Total Schedule Algo cumulative time:903.260984ms for 367
I0827 11:32:23.181439       1 scheduler.go:451] ScheduleAlgoTime 1.927502ms Start:2018-08-27 11:32:23.179505749 +0000 UTC m=+29.048812994 End:2018-08-27 11:32:23.181433311 +0000 UTC m=+29.050740496
I0827 11:32:23.181467       1 scheduler.go:454] Total Schedule Algo cumulative time:905.188486ms for 368
I0827 11:32:23.183440       1 scheduler.go:451] ScheduleAlgoTime 1.777179ms Start:2018-08-27 11:32:23.181655971 +0000 UTC m=+29.050963210 End:2018-08-27 11:32:23.183433206 +0000 UTC m=+29.052740389
I0827 11:32:23.183471       1 scheduler.go:454] Total Schedule Algo cumulative time:906.965665ms for 369
I0827 11:32:23.185714       1 scheduler.go:451] ScheduleAlgoTime 1.940496ms Start:2018-08-27 11:32:23.183767569 +0000 UTC m=+29.053074817 End:2018-08-27 11:32:23.185708128 +0000 UTC m=+29.055015313
I0827 11:32:23.185743       1 scheduler.go:454] Total Schedule Algo cumulative time:908.906161ms for 370
I0827 11:32:23.187766       1 scheduler.go:451] ScheduleAlgoTime 1.781719ms Start:2018-08-27 11:32:23.18597702 +0000 UTC m=+29.055284267 End:2018-08-27 11:32:23.187758802 +0000 UTC m=+29.057065986
I0827 11:32:23.187794       1 scheduler.go:454] Total Schedule Algo cumulative time:910.68788ms for 371
I0827 11:32:23.189416       1 scheduler.go:451] ScheduleAlgoTime 1.468731ms Start:2018-08-27 11:32:23.187940954 +0000 UTC m=+29.057248197 End:2018-08-27 11:32:23.189409743 +0000 UTC m=+29.058716928
I0827 11:32:23.189443       1 scheduler.go:454] Total Schedule Algo cumulative time:912.156611ms for 372
I0827 11:32:23.191387       1 scheduler.go:451] ScheduleAlgoTime 1.770269ms Start:2018-08-27 11:32:23.189607881 +0000 UTC m=+29.058915134 End:2018-08-27 11:32:23.191378205 +0000 UTC m=+29.060685403
I0827 11:32:23.191417       1 scheduler.go:454] Total Schedule Algo cumulative time:913.92688ms for 373
I0827 11:32:23.193674       1 scheduler.go:451] ScheduleAlgoTime 2.067533ms Start:2018-08-27 11:32:23.191600402 +0000 UTC m=+29.060907593 End:2018-08-27 11:32:23.193667944 +0000 UTC m=+29.062975126
I0827 11:32:23.193736       1 scheduler.go:454] Total Schedule Algo cumulative time:915.994413ms for 374
I0827 11:32:23.199777       1 scheduler.go:451] ScheduleAlgoTime 5.856183ms Start:2018-08-27 11:32:23.19390889 +0000 UTC m=+29.063216073 End:2018-08-27 11:32:23.19976506 +0000 UTC m=+29.069072256
I0827 11:32:23.199818       1 scheduler.go:454] Total Schedule Algo cumulative time:921.850596ms for 375
I0827 11:32:23.204003       1 scheduler.go:451] ScheduleAlgoTime 3.768226ms Start:2018-08-27 11:32:23.200228444 +0000 UTC m=+29.069535706 End:2018-08-27 11:32:23.203996751 +0000 UTC m=+29.073303932
I0827 11:32:23.204031       1 scheduler.go:454] Total Schedule Algo cumulative time:925.618822ms for 376
I0827 11:32:23.206159       1 scheduler.go:451] ScheduleAlgoTime 1.890014ms Start:2018-08-27 11:32:23.20426041 +0000 UTC m=+29.073567663 End:2018-08-27 11:32:23.206150491 +0000 UTC m=+29.075457677
I0827 11:32:23.206200       1 scheduler.go:454] Total Schedule Algo cumulative time:927.508836ms for 377
I0827 11:32:23.209495       1 scheduler.go:451] ScheduleAlgoTime 2.922668ms Start:2018-08-27 11:32:23.20656479 +0000 UTC m=+29.075872026 End:2018-08-27 11:32:23.209487512 +0000 UTC m=+29.078794694
I0827 11:32:23.209549       1 scheduler.go:454] Total Schedule Algo cumulative time:930.431504ms for 378
I0827 11:32:23.211519       1 scheduler.go:451] ScheduleAlgoTime 1.735382ms Start:2018-08-27 11:32:23.209778692 +0000 UTC m=+29.079085938 End:2018-08-27 11:32:23.21151414 +0000 UTC m=+29.080821320
I0827 11:32:23.211546       1 scheduler.go:454] Total Schedule Algo cumulative time:932.166886ms for 379
I0827 11:32:23.213466       1 scheduler.go:451] ScheduleAlgoTime 1.740601ms Start:2018-08-27 11:32:23.211717085 +0000 UTC m=+29.081024319 End:2018-08-27 11:32:23.213457714 +0000 UTC m=+29.082764920
I0827 11:32:23.213506       1 scheduler.go:454] Total Schedule Algo cumulative time:933.907487ms for 380
I0827 11:32:23.215578       1 scheduler.go:451] ScheduleAlgoTime 1.688587ms Start:2018-08-27 11:32:23.2138841 +0000 UTC m=+29.083191341 End:2018-08-27 11:32:23.215572745 +0000 UTC m=+29.084879928
I0827 11:32:23.215607       1 scheduler.go:454] Total Schedule Algo cumulative time:935.596074ms for 381
I0827 11:32:23.217457       1 scheduler.go:451] ScheduleAlgoTime 1.510056ms Start:2018-08-27 11:32:23.215942084 +0000 UTC m=+29.085249288 End:2018-08-27 11:32:23.217452156 +0000 UTC m=+29.086759344
I0827 11:32:23.217482       1 scheduler.go:454] Total Schedule Algo cumulative time:937.10613ms for 382
I0827 11:32:23.219557       1 scheduler.go:451] ScheduleAlgoTime 1.916059ms Start:2018-08-27 11:32:23.217635079 +0000 UTC m=+29.086942262 End:2018-08-27 11:32:23.219551138 +0000 UTC m=+29.088858321
I0827 11:32:23.219583       1 scheduler.go:454] Total Schedule Algo cumulative time:939.022189ms for 383
I0827 11:32:23.221634       1 scheduler.go:451] ScheduleAlgoTime 1.70381ms Start:2018-08-27 11:32:23.219919732 +0000 UTC m=+29.089226949 End:2018-08-27 11:32:23.221623535 +0000 UTC m=+29.090930759
I0827 11:32:23.221673       1 scheduler.go:454] Total Schedule Algo cumulative time:940.725999ms for 384
I0827 11:32:23.223468       1 scheduler.go:451] ScheduleAlgoTime 1.507996ms Start:2018-08-27 11:32:23.221954418 +0000 UTC m=+29.091261657 End:2018-08-27 11:32:23.223462469 +0000 UTC m=+29.092769653
I0827 11:32:23.223495       1 scheduler.go:454] Total Schedule Algo cumulative time:942.233995ms for 385
I0827 11:32:23.225400       1 scheduler.go:451] ScheduleAlgoTime 1.62629ms Start:2018-08-27 11:32:23.223767374 +0000 UTC m=+29.093074632 End:2018-08-27 11:32:23.22539374 +0000 UTC m=+29.094700922
I0827 11:32:23.225426       1 scheduler.go:454] Total Schedule Algo cumulative time:943.860285ms for 386
I0827 11:32:23.227745       1 scheduler.go:451] ScheduleAlgoTime 2.013096ms Start:2018-08-27 11:32:23.225725427 +0000 UTC m=+29.095032646 End:2018-08-27 11:32:23.22773856 +0000 UTC m=+29.097045742
I0827 11:32:23.227775       1 scheduler.go:454] Total Schedule Algo cumulative time:945.873381ms for 387
I0827 11:32:23.229936       1 scheduler.go:451] ScheduleAlgoTime 1.857408ms Start:2018-08-27 11:32:23.22806686 +0000 UTC m=+29.097374101 End:2018-08-27 11:32:23.229924314 +0000 UTC m=+29.099231509
I0827 11:32:23.229971       1 scheduler.go:454] Total Schedule Algo cumulative time:947.730789ms for 388
I0827 11:32:23.231944       1 scheduler.go:451] ScheduleAlgoTime 1.730514ms Start:2018-08-27 11:32:23.230205932 +0000 UTC m=+29.099513174 End:2018-08-27 11:32:23.231936505 +0000 UTC m=+29.101243688
I0827 11:32:23.231974       1 scheduler.go:454] Total Schedule Algo cumulative time:949.461303ms for 389
I0827 11:32:23.233865       1 scheduler.go:451] ScheduleAlgoTime 1.743938ms Start:2018-08-27 11:32:23.23211596 +0000 UTC m=+29.101423203 End:2018-08-27 11:32:23.233859959 +0000 UTC m=+29.103167141
I0827 11:32:23.233889       1 scheduler.go:454] Total Schedule Algo cumulative time:951.205241ms for 390
I0827 11:32:23.236025       1 scheduler.go:451] ScheduleAlgoTime 1.923714ms Start:2018-08-27 11:32:23.234095821 +0000 UTC m=+29.103403064 End:2018-08-27 11:32:23.236019595 +0000 UTC m=+29.105326778
I0827 11:32:23.236052       1 scheduler.go:454] Total Schedule Algo cumulative time:953.128955ms for 391
I0827 11:32:23.237939       1 scheduler.go:451] ScheduleAlgoTime 1.652729ms Start:2018-08-27 11:32:23.236280711 +0000 UTC m=+29.105587916 End:2018-08-27 11:32:23.237933463 +0000 UTC m=+29.107240645
I0827 11:32:23.237965       1 scheduler.go:454] Total Schedule Algo cumulative time:954.781684ms for 392
I0827 11:32:23.240280       1 scheduler.go:451] ScheduleAlgoTime 2.128355ms Start:2018-08-27 11:32:23.238146267 +0000 UTC m=+29.107453492 End:2018-08-27 11:32:23.240274666 +0000 UTC m=+29.109581847
I0827 11:32:23.240317       1 scheduler.go:454] Total Schedule Algo cumulative time:956.910039ms for 393
I0827 11:32:23.242258       1 scheduler.go:451] ScheduleAlgoTime 1.76504ms Start:2018-08-27 11:32:23.240488253 +0000 UTC m=+29.109795488 End:2018-08-27 11:32:23.242253345 +0000 UTC m=+29.111560528
I0827 11:32:23.242283       1 scheduler.go:454] Total Schedule Algo cumulative time:958.675079ms for 394
I0827 11:32:23.244255       1 scheduler.go:451] ScheduleAlgoTime 1.770448ms Start:2018-08-27 11:32:23.242477136 +0000 UTC m=+29.111784356 End:2018-08-27 11:32:23.244247618 +0000 UTC m=+29.113554804
I0827 11:32:23.244291       1 scheduler.go:454] Total Schedule Algo cumulative time:960.445527ms for 395
I0827 11:32:23.245950       1 scheduler.go:451] ScheduleAlgoTime 1.530413ms Start:2018-08-27 11:32:23.244414365 +0000 UTC m=+29.113721547 End:2018-08-27 11:32:23.245944778 +0000 UTC m=+29.115251960
I0827 11:32:23.245977       1 scheduler.go:454] Total Schedule Algo cumulative time:961.97594ms for 396
I0827 11:32:23.248207       1 scheduler.go:451] ScheduleAlgoTime 2.012016ms Start:2018-08-27 11:32:23.24618937 +0000 UTC m=+29.115496581 End:2018-08-27 11:32:23.248201415 +0000 UTC m=+29.117508597
I0827 11:32:23.248232       1 scheduler.go:454] Total Schedule Algo cumulative time:963.987956ms for 397
I0827 11:32:23.250055       1 scheduler.go:451] ScheduleAlgoTime 1.723482ms Start:2018-08-27 11:32:23.248326758 +0000 UTC m=+29.117633941 End:2018-08-27 11:32:23.25005024 +0000 UTC m=+29.119357423
I0827 11:32:23.250085       1 scheduler.go:454] Total Schedule Algo cumulative time:965.711438ms for 398
I0827 11:32:23.252216       1 scheduler.go:451] ScheduleAlgoTime 1.882197ms Start:2018-08-27 11:32:23.250325281 +0000 UTC m=+29.119632549 End:2018-08-27 11:32:23.252207563 +0000 UTC m=+29.121514746
I0827 11:32:23.252255       1 scheduler.go:454] Total Schedule Algo cumulative time:967.593635ms for 399
I0827 11:32:23.254342       1 scheduler.go:451] ScheduleAlgoTime 1.812875ms Start:2018-08-27 11:32:23.252524533 +0000 UTC m=+29.121831744 End:2018-08-27 11:32:23.254337433 +0000 UTC m=+29.123644619
I0827 11:32:23.254369       1 scheduler.go:454] Total Schedule Algo cumulative time:969.40651ms for 400
I0827 11:32:23.256716       1 scheduler.go:451] ScheduleAlgoTime 2.205997ms Start:2018-08-27 11:32:23.254504158 +0000 UTC m=+29.123811345 End:2018-08-27 11:32:23.256710158 +0000 UTC m=+29.126017342
I0827 11:32:23.256742       1 scheduler.go:454] Total Schedule Algo cumulative time:971.612507ms for 401
I0827 11:32:23.258999       1 scheduler.go:451] ScheduleAlgoTime 1.961148ms Start:2018-08-27 11:32:23.257026652 +0000 UTC m=+29.126333905 End:2018-08-27 11:32:23.258987864 +0000 UTC m=+29.128295053
I0827 11:32:23.259081       1 scheduler.go:454] Total Schedule Algo cumulative time:973.573655ms for 402
I0827 11:32:23.261095       1 scheduler.go:451] ScheduleAlgoTime 1.793217ms Start:2018-08-27 11:32:23.259295189 +0000 UTC m=+29.128602404 End:2018-08-27 11:32:23.261088438 +0000 UTC m=+29.130395621
I0827 11:32:23.261127       1 scheduler.go:454] Total Schedule Algo cumulative time:975.366872ms for 403
I0827 11:32:23.263205       1 scheduler.go:451] ScheduleAlgoTime 1.821479ms Start:2018-08-27 11:32:23.261377924 +0000 UTC m=+29.130685171 End:2018-08-27 11:32:23.263199466 +0000 UTC m=+29.132506650
I0827 11:32:23.263234       1 scheduler.go:454] Total Schedule Algo cumulative time:977.188351ms for 404
I0827 11:32:23.265340       1 scheduler.go:451] ScheduleAlgoTime 1.921179ms Start:2018-08-27 11:32:23.263413145 +0000 UTC m=+29.132720359 End:2018-08-27 11:32:23.265334354 +0000 UTC m=+29.134641538
I0827 11:32:23.265375       1 scheduler.go:454] Total Schedule Algo cumulative time:979.10953ms for 405
I0827 11:32:23.267606       1 scheduler.go:451] ScheduleAlgoTime 2.061644ms Start:2018-08-27 11:32:23.265534958 +0000 UTC m=+29.134842141 End:2018-08-27 11:32:23.267596315 +0000 UTC m=+29.136903785
I0827 11:32:23.267661       1 scheduler.go:454] Total Schedule Algo cumulative time:981.171174ms for 406
I0827 11:32:23.270045       1 scheduler.go:451] ScheduleAlgoTime 2.076189ms Start:2018-08-27 11:32:23.267962526 +0000 UTC m=+29.137269827 End:2018-08-27 11:32:23.270038833 +0000 UTC m=+29.139346016
I0827 11:32:23.270074       1 scheduler.go:454] Total Schedule Algo cumulative time:983.247363ms for 407
I0827 11:32:23.272062       1 scheduler.go:451] ScheduleAlgoTime 1.687548ms Start:2018-08-27 11:32:23.270369166 +0000 UTC m=+29.139676380 End:2018-08-27 11:32:23.272056744 +0000 UTC m=+29.141363928
I0827 11:32:23.272087       1 scheduler.go:454] Total Schedule Algo cumulative time:984.934911ms for 408
I0827 11:32:23.273832       1 scheduler.go:451] ScheduleAlgoTime 1.608109ms Start:2018-08-27 11:32:23.272218501 +0000 UTC m=+29.141525683 End:2018-08-27 11:32:23.273826609 +0000 UTC m=+29.143133792
I0827 11:32:23.273853       1 scheduler.go:454] Total Schedule Algo cumulative time:986.54302ms for 409
I0827 11:32:23.275769       1 scheduler.go:451] ScheduleAlgoTime 1.68929ms Start:2018-08-27 11:32:23.274069793 +0000 UTC m=+29.143377037 End:2018-08-27 11:32:23.275759062 +0000 UTC m=+29.145066327
I0827 11:32:23.275810       1 scheduler.go:454] Total Schedule Algo cumulative time:988.23231ms for 410
I0827 11:32:23.278271       1 scheduler.go:451] ScheduleAlgoTime 2.237386ms Start:2018-08-27 11:32:23.276025101 +0000 UTC m=+29.145332300 End:2018-08-27 11:32:23.278262501 +0000 UTC m=+29.147569686
I0827 11:32:23.278298       1 scheduler.go:454] Total Schedule Algo cumulative time:990.469696ms for 411
I0827 11:32:23.282279       1 scheduler.go:451] ScheduleAlgoTime 3.670634ms Start:2018-08-27 11:32:23.27860043 +0000 UTC m=+29.147907622 End:2018-08-27 11:32:23.282271074 +0000 UTC m=+29.151578256
I0827 11:32:23.282348       1 scheduler.go:454] Total Schedule Algo cumulative time:994.14033ms for 412
I0827 11:32:23.286302       1 scheduler.go:451] ScheduleAlgoTime 3.569328ms Start:2018-08-27 11:32:23.282725295 +0000 UTC m=+29.152032499 End:2018-08-27 11:32:23.286294647 +0000 UTC m=+29.155601827
I0827 11:32:23.286344       1 scheduler.go:454] Total Schedule Algo cumulative time:997.709658ms for 413
I0827 11:32:23.288437       1 scheduler.go:451] ScheduleAlgoTime 1.853137ms Start:2018-08-27 11:32:23.286574106 +0000 UTC m=+29.155881318 End:2018-08-27 11:32:23.288427267 +0000 UTC m=+29.157734455
I0827 11:32:23.288481       1 scheduler.go:454] Total Schedule Algo cumulative time:999.562795ms for 414
I0827 11:32:23.290469       1 scheduler.go:451] ScheduleAlgoTime 1.642034ms Start:2018-08-27 11:32:23.288821724 +0000 UTC m=+29.158128913 End:2018-08-27 11:32:23.290463765 +0000 UTC m=+29.159770947
I0827 11:32:23.290502       1 scheduler.go:454] Total Schedule Algo cumulative time:1.001204829s for 415
I0827 11:32:23.292480       1 scheduler.go:451] ScheduleAlgoTime 1.627956ms Start:2018-08-27 11:32:23.290845923 +0000 UTC m=+29.160153175 End:2018-08-27 11:32:23.292473945 +0000 UTC m=+29.161781131
I0827 11:32:23.292516       1 scheduler.go:454] Total Schedule Algo cumulative time:1.002832785s for 416
I0827 11:32:23.294575       1 scheduler.go:451] ScheduleAlgoTime 1.721083ms Start:2018-08-27 11:32:23.292848091 +0000 UTC m=+29.162155340 End:2018-08-27 11:32:23.294569237 +0000 UTC m=+29.163876423
I0827 11:32:23.294603       1 scheduler.go:454] Total Schedule Algo cumulative time:1.004553868s for 417
I0827 11:32:23.296496       1 scheduler.go:451] ScheduleAlgoTime 1.617744ms Start:2018-08-27 11:32:23.294868618 +0000 UTC m=+29.164175836 End:2018-08-27 11:32:23.29648639 +0000 UTC m=+29.165793580
I0827 11:32:23.296533       1 scheduler.go:454] Total Schedule Algo cumulative time:1.006171612s for 418
I0827 11:32:23.298568       1 scheduler.go:451] ScheduleAlgoTime 1.743955ms Start:2018-08-27 11:32:23.296817707 +0000 UTC m=+29.166124966 End:2018-08-27 11:32:23.298561736 +0000 UTC m=+29.167868921
I0827 11:32:23.298600       1 scheduler.go:454] Total Schedule Algo cumulative time:1.007915567s for 419
I0827 11:32:23.300750       1 scheduler.go:451] ScheduleAlgoTime 1.767947ms Start:2018-08-27 11:32:23.298973326 +0000 UTC m=+29.168280571 End:2018-08-27 11:32:23.300741327 +0000 UTC m=+29.170048518
I0827 11:32:23.300792       1 scheduler.go:454] Total Schedule Algo cumulative time:1.009683514s for 420
I0827 11:32:23.302732       1 scheduler.go:451] ScheduleAlgoTime 1.738813ms Start:2018-08-27 11:32:23.300987715 +0000 UTC m=+29.170294958 End:2018-08-27 11:32:23.302726589 +0000 UTC m=+29.172033771
I0827 11:32:23.302760       1 scheduler.go:454] Total Schedule Algo cumulative time:1.011422327s for 421
I0827 11:32:23.305098       1 scheduler.go:451] ScheduleAlgoTime 2.097576ms Start:2018-08-27 11:32:23.302995074 +0000 UTC m=+29.172302329 End:2018-08-27 11:32:23.305092718 +0000 UTC m=+29.174399905
I0827 11:32:23.305126       1 scheduler.go:454] Total Schedule Algo cumulative time:1.013519903s for 422
I0827 11:32:23.307118       1 scheduler.go:451] ScheduleAlgoTime 1.87029ms Start:2018-08-27 11:32:23.305241901 +0000 UTC m=+29.174549084 End:2018-08-27 11:32:23.307112191 +0000 UTC m=+29.176419374
I0827 11:32:23.307145       1 scheduler.go:454] Total Schedule Algo cumulative time:1.015390193s for 423
I0827 11:32:23.309810       1 scheduler.go:451] ScheduleAlgoTime 2.307466ms Start:2018-08-27 11:32:23.307496461 +0000 UTC m=+29.176803661 End:2018-08-27 11:32:23.309803941 +0000 UTC m=+29.179111127
I0827 11:32:23.309837       1 scheduler.go:454] Total Schedule Algo cumulative time:1.017697659s for 424
I0827 11:32:23.311725       1 scheduler.go:451] ScheduleAlgoTime 1.612672ms Start:2018-08-27 11:32:23.310106854 +0000 UTC m=+29.179414083 End:2018-08-27 11:32:23.311719569 +0000 UTC m=+29.181026755
I0827 11:32:23.311751       1 scheduler.go:454] Total Schedule Algo cumulative time:1.019310331s for 425
I0827 11:32:23.313878       1 scheduler.go:451] ScheduleAlgoTime 1.992664ms Start:2018-08-27 11:32:23.31187917 +0000 UTC m=+29.181186353 End:2018-08-27 11:32:23.313871831 +0000 UTC m=+29.183179017
I0827 11:32:23.313904       1 scheduler.go:454] Total Schedule Algo cumulative time:1.021302995s for 426
I0827 11:32:23.315610       1 scheduler.go:451] ScheduleAlgoTime 1.590504ms Start:2018-08-27 11:32:23.314014389 +0000 UTC m=+29.183321586 End:2018-08-27 11:32:23.315604905 +0000 UTC m=+29.184912090
I0827 11:32:23.315663       1 scheduler.go:454] Total Schedule Algo cumulative time:1.022893499s for 427
I0827 11:32:23.317739       1 scheduler.go:451] ScheduleAlgoTime 1.856519ms Start:2018-08-27 11:32:23.315874295 +0000 UTC m=+29.185181479 End:2018-08-27 11:32:23.317730813 +0000 UTC m=+29.187037998
I0827 11:32:23.317771       1 scheduler.go:454] Total Schedule Algo cumulative time:1.024750018s for 428
I0827 11:32:23.319828       1 scheduler.go:451] ScheduleAlgoTime 1.833027ms Start:2018-08-27 11:32:23.317988602 +0000 UTC m=+29.187295837 End:2018-08-27 11:32:23.31982167 +0000 UTC m=+29.189128864
I0827 11:32:23.319857       1 scheduler.go:454] Total Schedule Algo cumulative time:1.026583045s for 429
I0827 11:32:23.321844       1 scheduler.go:451] ScheduleAlgoTime 1.764448ms Start:2018-08-27 11:32:23.320074514 +0000 UTC m=+29.189381755 End:2018-08-27 11:32:23.321839021 +0000 UTC m=+29.191146203
I0827 11:32:23.321870       1 scheduler.go:454] Total Schedule Algo cumulative time:1.028347493s for 430
I0827 11:32:23.324181       1 scheduler.go:451] ScheduleAlgoTime 2.01634ms Start:2018-08-27 11:32:23.32215377 +0000 UTC m=+29.191460990 End:2018-08-27 11:32:23.32417012 +0000 UTC m=+29.193477330
I0827 11:32:23.324217       1 scheduler.go:454] Total Schedule Algo cumulative time:1.030363833s for 431
I0827 11:32:23.326019       1 scheduler.go:451] ScheduleAlgoTime 1.557465ms Start:2018-08-27 11:32:23.324456099 +0000 UTC m=+29.193763346 End:2018-08-27 11:32:23.326013625 +0000 UTC m=+29.195320811
I0827 11:32:23.326056       1 scheduler.go:454] Total Schedule Algo cumulative time:1.031921298s for 432
I0827 11:32:23.328026       1 scheduler.go:451] ScheduleAlgoTime 1.668809ms Start:2018-08-27 11:32:23.326352711 +0000 UTC m=+29.195659949 End:2018-08-27 11:32:23.328021576 +0000 UTC m=+29.197328758
I0827 11:32:23.328048       1 scheduler.go:454] Total Schedule Algo cumulative time:1.033590107s for 433
I0827 11:32:23.330163       1 scheduler.go:451] ScheduleAlgoTime 1.909505ms Start:2018-08-27 11:32:23.328247446 +0000 UTC m=+29.197554684 End:2018-08-27 11:32:23.330157006 +0000 UTC m=+29.199464189
I0827 11:32:23.330192       1 scheduler.go:454] Total Schedule Algo cumulative time:1.035499612s for 434
I0827 11:32:23.332249       1 scheduler.go:451] ScheduleAlgoTime 1.889594ms Start:2018-08-27 11:32:23.330352736 +0000 UTC m=+29.199659929 End:2018-08-27 11:32:23.33224234 +0000 UTC m=+29.201549523
I0827 11:32:23.332276       1 scheduler.go:454] Total Schedule Algo cumulative time:1.037389206s for 435
I0827 11:32:23.334211       1 scheduler.go:451] ScheduleAlgoTime 1.736395ms Start:2018-08-27 11:32:23.332468126 +0000 UTC m=+29.201775372 End:2018-08-27 11:32:23.33420458 +0000 UTC m=+29.203511767
I0827 11:32:23.334239       1 scheduler.go:454] Total Schedule Algo cumulative time:1.039125601s for 436
I0827 11:32:23.336500       1 scheduler.go:451] ScheduleAlgoTime 1.774895ms Start:2018-08-27 11:32:23.334717759 +0000 UTC m=+29.204024964 End:2018-08-27 11:32:23.336492677 +0000 UTC m=+29.205799859
I0827 11:32:23.336529       1 scheduler.go:454] Total Schedule Algo cumulative time:1.040900496s for 437
I0827 11:32:23.338379       1 scheduler.go:451] ScheduleAlgoTime 1.563483ms Start:2018-08-27 11:32:23.336810217 +0000 UTC m=+29.206117400 End:2018-08-27 11:32:23.338373701 +0000 UTC m=+29.207680883
I0827 11:32:23.338408       1 scheduler.go:454] Total Schedule Algo cumulative time:1.042463979s for 438
I0827 11:32:23.340740       1 scheduler.go:451] ScheduleAlgoTime 2.207928ms Start:2018-08-27 11:32:23.338526546 +0000 UTC m=+29.207833743 End:2018-08-27 11:32:23.340734482 +0000 UTC m=+29.210041671
I0827 11:32:23.340770       1 scheduler.go:454] Total Schedule Algo cumulative time:1.044671907s for 439
I0827 11:32:23.343171       1 scheduler.go:451] ScheduleAlgoTime 2.125029ms Start:2018-08-27 11:32:23.341039462 +0000 UTC m=+29.210346662 End:2018-08-27 11:32:23.343164506 +0000 UTC m=+29.212471691
I0827 11:32:23.343202       1 scheduler.go:454] Total Schedule Algo cumulative time:1.046796936s for 440
I0827 11:32:23.345251       1 scheduler.go:451] ScheduleAlgoTime 1.852346ms Start:2018-08-27 11:32:23.343392438 +0000 UTC m=+29.212699647 End:2018-08-27 11:32:23.345244806 +0000 UTC m=+29.214551993
I0827 11:32:23.345279       1 scheduler.go:454] Total Schedule Algo cumulative time:1.048649282s for 441
I0827 11:32:23.347152       1 scheduler.go:451] ScheduleAlgoTime 1.681565ms Start:2018-08-27 11:32:23.345465365 +0000 UTC m=+29.214772591 End:2018-08-27 11:32:23.347146973 +0000 UTC m=+29.216454156
I0827 11:32:23.347233       1 scheduler.go:454] Total Schedule Algo cumulative time:1.050330847s for 442
I0827 11:32:23.349207       1 scheduler.go:451] ScheduleAlgoTime 1.81632ms Start:2018-08-27 11:32:23.34738453 +0000 UTC m=+29.216691797 End:2018-08-27 11:32:23.349200931 +0000 UTC m=+29.218508117
I0827 11:32:23.349237       1 scheduler.go:454] Total Schedule Algo cumulative time:1.052147167s for 443
I0827 11:32:23.351205       1 scheduler.go:451] ScheduleAlgoTime 1.716148ms Start:2018-08-27 11:32:23.349484137 +0000 UTC m=+29.218791384 End:2018-08-27 11:32:23.351200347 +0000 UTC m=+29.220507532
I0827 11:32:23.351229       1 scheduler.go:454] Total Schedule Algo cumulative time:1.053863315s for 444
I0827 11:32:23.353265       1 scheduler.go:451] ScheduleAlgoTime 1.896888ms Start:2018-08-27 11:32:23.351360527 +0000 UTC m=+29.220667764 End:2018-08-27 11:32:23.353257469 +0000 UTC m=+29.222564652
I0827 11:32:23.353299       1 scheduler.go:454] Total Schedule Algo cumulative time:1.055760203s for 445
I0827 11:32:23.355229       1 scheduler.go:451] ScheduleAlgoTime 1.666138ms Start:2018-08-27 11:32:23.353557822 +0000 UTC m=+29.222865075 End:2018-08-27 11:32:23.35522403 +0000 UTC m=+29.224531213
I0827 11:32:23.355258       1 scheduler.go:454] Total Schedule Algo cumulative time:1.057426341s for 446
I0827 11:32:23.357404       1 scheduler.go:451] ScheduleAlgoTime 1.921638ms Start:2018-08-27 11:32:23.355476038 +0000 UTC m=+29.224783265 End:2018-08-27 11:32:23.357397722 +0000 UTC m=+29.226704903
I0827 11:32:23.357432       1 scheduler.go:454] Total Schedule Algo cumulative time:1.059347979s for 447
I0827 11:32:23.359616       1 scheduler.go:451] ScheduleAlgoTime 1.972639ms Start:2018-08-27 11:32:23.357635578 +0000 UTC m=+29.226942819 End:2018-08-27 11:32:23.359608269 +0000 UTC m=+29.228915458
I0827 11:32:23.359674       1 scheduler.go:454] Total Schedule Algo cumulative time:1.061320618s for 448
I0827 11:32:23.366137       1 scheduler.go:451] ScheduleAlgoTime 6.114135ms Start:2018-08-27 11:32:23.360013141 +0000 UTC m=+29.229320383 End:2018-08-27 11:32:23.366127337 +0000 UTC m=+29.235434518
I0827 11:32:23.366179       1 scheduler.go:454] Total Schedule Algo cumulative time:1.067434753s for 449
I0827 11:32:23.368719       1 scheduler.go:451] ScheduleAlgoTime 2.294086ms Start:2018-08-27 11:32:23.366416401 +0000 UTC m=+29.235723610 End:2018-08-27 11:32:23.368710513 +0000 UTC m=+29.238017696
I0827 11:32:23.368759       1 scheduler.go:454] Total Schedule Algo cumulative time:1.069728839s for 450
I0827 11:32:23.370701       1 scheduler.go:451] ScheduleAlgoTime 1.664414ms Start:2018-08-27 11:32:23.369007788 +0000 UTC m=+29.238315057 End:2018-08-27 11:32:23.370672285 +0000 UTC m=+29.239979471
I0827 11:32:23.370730       1 scheduler.go:454] Total Schedule Algo cumulative time:1.071393253s for 451
I0827 11:32:23.372945       1 scheduler.go:451] ScheduleAlgoTime 1.932948ms Start:2018-08-27 11:32:23.371006885 +0000 UTC m=+29.240314108 End:2018-08-27 11:32:23.372939871 +0000 UTC m=+29.242247056
I0827 11:32:23.372973       1 scheduler.go:454] Total Schedule Algo cumulative time:1.073326201s for 452
I0827 11:32:23.374740       1 scheduler.go:451] ScheduleAlgoTime 1.556263ms Start:2018-08-27 11:32:23.373177995 +0000 UTC m=+29.242485265 End:2018-08-27 11:32:23.374734345 +0000 UTC m=+29.244041528
I0827 11:32:23.374779       1 scheduler.go:454] Total Schedule Algo cumulative time:1.074882464s for 453
I0827 11:32:23.377092       1 scheduler.go:451] ScheduleAlgoTime 2.081535ms Start:2018-08-27 11:32:23.375001559 +0000 UTC m=+29.244308777 End:2018-08-27 11:32:23.37708313 +0000 UTC m=+29.246390312
I0827 11:32:23.377138       1 scheduler.go:454] Total Schedule Algo cumulative time:1.076963999s for 454
I0827 11:32:23.379037       1 scheduler.go:451] ScheduleAlgoTime 1.680476ms Start:2018-08-27 11:32:23.377352005 +0000 UTC m=+29.246659201 End:2018-08-27 11:32:23.379032495 +0000 UTC m=+29.248339677
I0827 11:32:23.379063       1 scheduler.go:454] Total Schedule Algo cumulative time:1.078644475s for 455
I0827 11:32:23.380758       1 scheduler.go:451] ScheduleAlgoTime 1.548329ms Start:2018-08-27 11:32:23.379204911 +0000 UTC m=+29.248512094 End:2018-08-27 11:32:23.380753237 +0000 UTC m=+29.250060423
I0827 11:32:23.380816       1 scheduler.go:454] Total Schedule Algo cumulative time:1.080192804s for 456
I0827 11:32:23.382740       1 scheduler.go:451] ScheduleAlgoTime 1.669986ms Start:2018-08-27 11:32:23.381063143 +0000 UTC m=+29.250370405 End:2018-08-27 11:32:23.382733205 +0000 UTC m=+29.252040391
I0827 11:32:23.382787       1 scheduler.go:454] Total Schedule Algo cumulative time:1.08186279s for 457
I0827 11:32:23.384540       1 scheduler.go:451] ScheduleAlgoTime 1.505442ms Start:2018-08-27 11:32:23.383029232 +0000 UTC m=+29.252336468 End:2018-08-27 11:32:23.384534726 +0000 UTC m=+29.253841910
I0827 11:32:23.384565       1 scheduler.go:454] Total Schedule Algo cumulative time:1.083368232s for 458
I0827 11:32:23.386659       1 scheduler.go:451] ScheduleAlgoTime 1.799815ms Start:2018-08-27 11:32:23.384851222 +0000 UTC m=+29.254158424 End:2018-08-27 11:32:23.386651051 +0000 UTC m=+29.255958239
I0827 11:32:23.386735       1 scheduler.go:454] Total Schedule Algo cumulative time:1.085168047s for 459
I0827 11:32:23.389145       1 scheduler.go:451] ScheduleAlgoTime 1.957424ms Start:2018-08-27 11:32:23.387181094 +0000 UTC m=+29.256488362 End:2018-08-27 11:32:23.389138603 +0000 UTC m=+29.258445786
I0827 11:32:23.389171       1 scheduler.go:454] Total Schedule Algo cumulative time:1.087125471s for 460
I0827 11:32:23.391167       1 scheduler.go:451] ScheduleAlgoTime 1.91763ms Start:2018-08-27 11:32:23.389234854 +0000 UTC m=+29.258542047 End:2018-08-27 11:32:23.391152455 +0000 UTC m=+29.260459677
I0827 11:32:23.391200       1 scheduler.go:454] Total Schedule Algo cumulative time:1.089043101s for 461
I0827 11:32:23.393171       1 scheduler.go:451] ScheduleAlgoTime 1.721954ms Start:2018-08-27 11:32:23.391442554 +0000 UTC m=+29.260749790 End:2018-08-27 11:32:23.393164562 +0000 UTC m=+29.262471744
I0827 11:32:23.393197       1 scheduler.go:454] Total Schedule Algo cumulative time:1.090765055s for 462
I0827 11:32:23.395061       1 scheduler.go:451] ScheduleAlgoTime 1.625772ms Start:2018-08-27 11:32:23.39342579 +0000 UTC m=+29.262733047 End:2018-08-27 11:32:23.395051635 +0000 UTC m=+29.264358819
I0827 11:32:23.395087       1 scheduler.go:454] Total Schedule Algo cumulative time:1.092390827s for 463
I0827 11:32:23.397632       1 scheduler.go:451] ScheduleAlgoTime 2.28637ms Start:2018-08-27 11:32:23.395340375 +0000 UTC m=+29.264647567 End:2018-08-27 11:32:23.397626753 +0000 UTC m=+29.266933937
I0827 11:32:23.397659       1 scheduler.go:454] Total Schedule Algo cumulative time:1.094677197s for 464
I0827 11:32:23.400629       1 scheduler.go:451] ScheduleAlgoTime 2.691931ms Start:2018-08-27 11:32:23.39793131 +0000 UTC m=+29.267238549 End:2018-08-27 11:32:23.400623297 +0000 UTC m=+29.269930480
I0827 11:32:23.400657       1 scheduler.go:454] Total Schedule Algo cumulative time:1.097369128s for 465
I0827 11:32:23.403009       1 scheduler.go:451] ScheduleAlgoTime 1.981866ms Start:2018-08-27 11:32:23.401018069 +0000 UTC m=+29.270325343 End:2018-08-27 11:32:23.403000026 +0000 UTC m=+29.272307209
I0827 11:32:23.403049       1 scheduler.go:454] Total Schedule Algo cumulative time:1.099350994s for 466
I0827 11:32:23.404997       1 scheduler.go:451] ScheduleAlgoTime 1.784647ms Start:2018-08-27 11:32:23.403206698 +0000 UTC m=+29.272513880 End:2018-08-27 11:32:23.404991336 +0000 UTC m=+29.274298527
I0827 11:32:23.405027       1 scheduler.go:454] Total Schedule Algo cumulative time:1.101135641s for 467
I0827 11:32:23.407088       1 scheduler.go:451] ScheduleAlgoTime 1.847947ms Start:2018-08-27 11:32:23.405229651 +0000 UTC m=+29.274536854 End:2018-08-27 11:32:23.407077616 +0000 UTC m=+29.276384801
I0827 11:32:23.407131       1 scheduler.go:454] Total Schedule Algo cumulative time:1.102983588s for 468
I0827 11:32:23.409473       1 scheduler.go:451] ScheduleAlgoTime 2.001883ms Start:2018-08-27 11:32:23.407464018 +0000 UTC m=+29.276771253 End:2018-08-27 11:32:23.409465947 +0000 UTC m=+29.278773136
I0827 11:32:23.409502       1 scheduler.go:454] Total Schedule Algo cumulative time:1.104985471s for 469
I0827 11:32:23.411405       1 scheduler.go:451] ScheduleAlgoTime 1.772982ms Start:2018-08-27 11:32:23.409626946 +0000 UTC m=+29.278934131 End:2018-08-27 11:32:23.411399931 +0000 UTC m=+29.280707113
I0827 11:32:23.411431       1 scheduler.go:454] Total Schedule Algo cumulative time:1.106758453s for 470
I0827 11:32:23.413581       1 scheduler.go:451] ScheduleAlgoTime 1.851829ms Start:2018-08-27 11:32:23.411722912 +0000 UTC m=+29.281030184 End:2018-08-27 11:32:23.413574831 +0000 UTC m=+29.282882013
I0827 11:32:23.413610       1 scheduler.go:454] Total Schedule Algo cumulative time:1.108610282s for 471
I0827 11:32:23.415937       1 scheduler.go:451] ScheduleAlgoTime 2.07326ms Start:2018-08-27 11:32:23.41385653 +0000 UTC m=+29.283163749 End:2018-08-27 11:32:23.415929825 +0000 UTC m=+29.285237009
I0827 11:32:23.415974       1 scheduler.go:454] Total Schedule Algo cumulative time:1.110683542s for 472
I0827 11:32:23.418039       1 scheduler.go:451] ScheduleAlgoTime 1.857827ms Start:2018-08-27 11:32:23.416175524 +0000 UTC m=+29.285482754 End:2018-08-27 11:32:23.418033395 +0000 UTC m=+29.287340581
I0827 11:32:23.418069       1 scheduler.go:454] Total Schedule Algo cumulative time:1.112541369s for 473
I0827 11:32:23.420101       1 scheduler.go:451] ScheduleAlgoTime 1.709782ms Start:2018-08-27 11:32:23.418385453 +0000 UTC m=+29.287692675 End:2018-08-27 11:32:23.420095275 +0000 UTC m=+29.289402457
I0827 11:32:23.420129       1 scheduler.go:454] Total Schedule Algo cumulative time:1.114251151s for 474
I0827 11:32:23.422070       1 scheduler.go:451] ScheduleAlgoTime 1.651279ms Start:2018-08-27 11:32:23.420411562 +0000 UTC m=+29.289718808 End:2018-08-27 11:32:23.422062901 +0000 UTC m=+29.291370087
I0827 11:32:23.422101       1 scheduler.go:454] Total Schedule Algo cumulative time:1.11590243s for 475
I0827 11:32:23.424092       1 scheduler.go:451] ScheduleAlgoTime 1.780882ms Start:2018-08-27 11:32:23.422305183 +0000 UTC m=+29.291612394 End:2018-08-27 11:32:23.424086087 +0000 UTC m=+29.293393276
I0827 11:32:23.424123       1 scheduler.go:454] Total Schedule Algo cumulative time:1.117683312s for 476
I0827 11:32:23.426390       1 scheduler.go:451] ScheduleAlgoTime 2.059277ms Start:2018-08-27 11:32:23.42432465 +0000 UTC m=+29.293631867 End:2018-08-27 11:32:23.426383962 +0000 UTC m=+29.295691144
I0827 11:32:23.426418       1 scheduler.go:454] Total Schedule Algo cumulative time:1.119742589s for 477
I0827 11:32:23.428469       1 scheduler.go:451] ScheduleAlgoTime 1.746674ms Start:2018-08-27 11:32:23.426713985 +0000 UTC m=+29.296021225 End:2018-08-27 11:32:23.428460715 +0000 UTC m=+29.297767899
I0827 11:32:23.428501       1 scheduler.go:454] Total Schedule Algo cumulative time:1.121489263s for 478
I0827 11:32:23.430567       1 scheduler.go:451] ScheduleAlgoTime 1.925739ms Start:2018-08-27 11:32:23.428634566 +0000 UTC m=+29.297941777 End:2018-08-27 11:32:23.430560332 +0000 UTC m=+29.299867516
I0827 11:32:23.430598       1 scheduler.go:454] Total Schedule Algo cumulative time:1.123415002s for 479
I0827 11:32:23.434371       1 scheduler.go:451] ScheduleAlgoTime 3.539828ms Start:2018-08-27 11:32:23.43082202 +0000 UTC m=+29.300129256 End:2018-08-27 11:32:23.434361892 +0000 UTC m=+29.303669084
I0827 11:32:23.434409       1 scheduler.go:454] Total Schedule Algo cumulative time:1.12695483s for 480
I0827 11:32:23.437584       1 scheduler.go:451] ScheduleAlgoTime 3.01997ms Start:2018-08-27 11:32:23.434556949 +0000 UTC m=+29.303864175 End:2018-08-27 11:32:23.43757696 +0000 UTC m=+29.306884145
I0827 11:32:23.437614       1 scheduler.go:454] Total Schedule Algo cumulative time:1.1299748s for 481
I0827 11:32:23.440134       1 scheduler.go:451] ScheduleAlgoTime 2.214219ms Start:2018-08-27 11:32:23.437910572 +0000 UTC m=+29.307217840 End:2018-08-27 11:32:23.440124876 +0000 UTC m=+29.309432059
I0827 11:32:23.440166       1 scheduler.go:454] Total Schedule Algo cumulative time:1.132189019s for 482
I0827 11:32:23.441973       1 scheduler.go:451] ScheduleAlgoTime 1.611701ms Start:2018-08-27 11:32:23.440353673 +0000 UTC m=+29.309660879 End:2018-08-27 11:32:23.441965397 +0000 UTC m=+29.311272580
I0827 11:32:23.441999       1 scheduler.go:454] Total Schedule Algo cumulative time:1.13380072s for 483
I0827 11:32:23.444431       1 scheduler.go:451] ScheduleAlgoTime 2.235195ms Start:2018-08-27 11:32:23.442189421 +0000 UTC m=+29.311496604 End:2018-08-27 11:32:23.444424617 +0000 UTC m=+29.313731799
I0827 11:32:23.444456       1 scheduler.go:454] Total Schedule Algo cumulative time:1.136035915s for 484
I0827 11:32:23.446585       1 scheduler.go:451] ScheduleAlgoTime 1.975626ms Start:2018-08-27 11:32:23.444599638 +0000 UTC m=+29.313906868 End:2018-08-27 11:32:23.446575178 +0000 UTC m=+29.315882494
I0827 11:32:23.446621       1 scheduler.go:454] Total Schedule Algo cumulative time:1.138011541s for 485
I0827 11:32:23.448861       1 scheduler.go:451] ScheduleAlgoTime 1.968228ms Start:2018-08-27 11:32:23.446886029 +0000 UTC m=+29.316193255 End:2018-08-27 11:32:23.448854295 +0000 UTC m=+29.318161483
I0827 11:32:23.448933       1 scheduler.go:454] Total Schedule Algo cumulative time:1.139979769s for 486
I0827 11:32:23.455461       1 scheduler.go:451] ScheduleAlgoTime 6.370142ms Start:2018-08-27 11:32:23.449082964 +0000 UTC m=+29.318390199 End:2018-08-27 11:32:23.455453158 +0000 UTC m=+29.324760341
I0827 11:32:23.455504       1 scheduler.go:454] Total Schedule Algo cumulative time:1.146349911s for 487
I0827 11:32:23.457535       1 scheduler.go:451] ScheduleAlgoTime 1.866548ms Start:2018-08-27 11:32:23.455662043 +0000 UTC m=+29.324969262 End:2018-08-27 11:32:23.457528628 +0000 UTC m=+29.326835810
I0827 11:32:23.457581       1 scheduler.go:454] Total Schedule Algo cumulative time:1.148216459s for 488
I0827 11:32:23.460219       1 scheduler.go:451] ScheduleAlgoTime 2.274533ms Start:2018-08-27 11:32:23.4579378 +0000 UTC m=+29.327245044 End:2018-08-27 11:32:23.460212392 +0000 UTC m=+29.329519577
I0827 11:32:23.460248       1 scheduler.go:454] Total Schedule Algo cumulative time:1.150490992s for 489
I0827 11:32:23.462382       1 scheduler.go:451] ScheduleAlgoTime 1.894555ms Start:2018-08-27 11:32:23.460478749 +0000 UTC m=+29.329785969 End:2018-08-27 11:32:23.462373343 +0000 UTC m=+29.331680524
I0827 11:32:23.462429       1 scheduler.go:454] Total Schedule Algo cumulative time:1.152385547s for 490
I0827 11:32:23.464793       1 scheduler.go:451] ScheduleAlgoTime 2.242269ms Start:2018-08-27 11:32:23.462544756 +0000 UTC m=+29.331852038 End:2018-08-27 11:32:23.464787124 +0000 UTC m=+29.334094307
I0827 11:32:23.464830       1 scheduler.go:454] Total Schedule Algo cumulative time:1.154627816s for 491
I0827 11:32:23.466853       1 scheduler.go:451] ScheduleAlgoTime 1.746558ms Start:2018-08-27 11:32:23.465096795 +0000 UTC m=+29.334404035 End:2018-08-27 11:32:23.46684329 +0000 UTC m=+29.336150593
I0827 11:32:23.466888       1 scheduler.go:454] Total Schedule Algo cumulative time:1.156374374s for 492
I0827 11:32:23.468852       1 scheduler.go:451] ScheduleAlgoTime 1.785103ms Start:2018-08-27 11:32:23.46705972 +0000 UTC m=+29.336366937 End:2018-08-27 11:32:23.46884485 +0000 UTC m=+29.338152040
I0827 11:32:23.468889       1 scheduler.go:454] Total Schedule Algo cumulative time:1.158159477s for 493
I0827 11:32:23.471336       1 scheduler.go:451] ScheduleAlgoTime 2.056821ms Start:2018-08-27 11:32:23.469271017 +0000 UTC m=+29.338578253 End:2018-08-27 11:32:23.47132789 +0000 UTC m=+29.340635074
I0827 11:32:23.471378       1 scheduler.go:454] Total Schedule Algo cumulative time:1.160216298s for 494
I0827 11:32:23.473364       1 scheduler.go:451] ScheduleAlgoTime 1.846264ms Start:2018-08-27 11:32:23.471509772 +0000 UTC m=+29.340816970 End:2018-08-27 11:32:23.473356047 +0000 UTC m=+29.342663234
I0827 11:32:23.473408       1 scheduler.go:454] Total Schedule Algo cumulative time:1.162062562s for 495
I0827 11:32:23.475279       1 scheduler.go:451] ScheduleAlgoTime 1.680592ms Start:2018-08-27 11:32:23.47359293 +0000 UTC m=+29.342900158 End:2018-08-27 11:32:23.475273569 +0000 UTC m=+29.344580750
I0827 11:32:23.475304       1 scheduler.go:454] Total Schedule Algo cumulative time:1.163743154s for 496
I0827 11:32:23.477116       1 scheduler.go:451] ScheduleAlgoTime 1.678572ms Start:2018-08-27 11:32:23.475430735 +0000 UTC m=+29.344737917 End:2018-08-27 11:32:23.477109308 +0000 UTC m=+29.346416489
I0827 11:32:23.477150       1 scheduler.go:454] Total Schedule Algo cumulative time:1.165421726s for 497
I0827 11:32:23.479612       1 scheduler.go:451] ScheduleAlgoTime 2.236831ms Start:2018-08-27 11:32:23.477366245 +0000 UTC m=+29.346673511 End:2018-08-27 11:32:23.479603135 +0000 UTC m=+29.348910342
I0827 11:32:23.479718       1 scheduler.go:454] Total Schedule Algo cumulative time:1.167658557s for 498
I0827 11:32:23.481714       1 scheduler.go:451] ScheduleAlgoTime 1.73117ms Start:2018-08-27 11:32:23.479945579 +0000 UTC m=+29.349252813 End:2018-08-27 11:32:23.481676799 +0000 UTC m=+29.350983983
I0827 11:32:23.481751       1 scheduler.go:454] Total Schedule Algo cumulative time:1.169389727s for 499
I0827 11:32:23.483522       1 scheduler.go:451] ScheduleAlgoTime 1.550386ms Start:2018-08-27 11:32:23.481964769 +0000 UTC m=+29.351271993 End:2018-08-27 11:32:23.483515196 +0000 UTC m=+29.352822379
I0827 11:32:23.483561       1 scheduler.go:454] Total Schedule Algo cumulative time:1.170940113s for 500
I0827 11:32:23.485624       1 scheduler.go:451] ScheduleAlgoTime 1.863424ms Start:2018-08-27 11:32:23.483754577 +0000 UTC m=+29.353061817 End:2018-08-27 11:32:23.485618058 +0000 UTC m=+29.354925241
I0827 11:32:23.485654       1 scheduler.go:454] Total Schedule Algo cumulative time:1.172803537s for 501
I0827 11:32:23.487702       1 scheduler.go:451] ScheduleAlgoTime 1.770643ms Start:2018-08-27 11:32:23.485903624 +0000 UTC m=+29.355210846 End:2018-08-27 11:32:23.487674307 +0000 UTC m=+29.356981489
I0827 11:32:23.487742       1 scheduler.go:454] Total Schedule Algo cumulative time:1.17457418s for 502
I0827 11:32:23.489538       1 scheduler.go:451] ScheduleAlgoTime 1.538293ms Start:2018-08-27 11:32:23.487993497 +0000 UTC m=+29.357300724 End:2018-08-27 11:32:23.489531836 +0000 UTC m=+29.358839017
I0827 11:32:23.489560       1 scheduler.go:454] Total Schedule Algo cumulative time:1.176112473s for 503
I0827 11:32:23.491357       1 scheduler.go:451] ScheduleAlgoTime 1.630259ms Start:2018-08-27 11:32:23.489722001 +0000 UTC m=+29.359029220 End:2018-08-27 11:32:23.491352297 +0000 UTC m=+29.360659479
I0827 11:32:23.491380       1 scheduler.go:454] Total Schedule Algo cumulative time:1.177742732s for 504
I0827 11:32:23.493451       1 scheduler.go:451] ScheduleAlgoTime 1.858478ms Start:2018-08-27 11:32:23.491585201 +0000 UTC m=+29.360892473 End:2018-08-27 11:32:23.493443769 +0000 UTC m=+29.362750951
I0827 11:32:23.493482       1 scheduler.go:454] Total Schedule Algo cumulative time:1.17960121s for 505
I0827 11:32:23.495200       1 scheduler.go:451] ScheduleAlgoTime 1.589883ms Start:2018-08-27 11:32:23.493604724 +0000 UTC m=+29.362911919 End:2018-08-27 11:32:23.495194619 +0000 UTC m=+29.364501802
I0827 11:32:23.495226       1 scheduler.go:454] Total Schedule Algo cumulative time:1.181191093s for 506
I0827 11:32:23.497141       1 scheduler.go:451] ScheduleAlgoTime 1.668624ms Start:2018-08-27 11:32:23.495466125 +0000 UTC m=+29.364773362 End:2018-08-27 11:32:23.497134803 +0000 UTC m=+29.366441986
I0827 11:32:23.497179       1 scheduler.go:454] Total Schedule Algo cumulative time:1.182859717s for 507
I0827 11:32:23.499188       1 scheduler.go:451] ScheduleAlgoTime 1.832631ms Start:2018-08-27 11:32:23.497348037 +0000 UTC m=+29.366655273 End:2018-08-27 11:32:23.499180722 +0000 UTC m=+29.368487904
I0827 11:32:23.499219       1 scheduler.go:454] Total Schedule Algo cumulative time:1.184692348s for 508
I0827 11:32:23.502167       1 scheduler.go:451] ScheduleAlgoTime 2.827216ms Start:2018-08-27 11:32:23.499334253 +0000 UTC m=+29.368641450 End:2018-08-27 11:32:23.502161483 +0000 UTC m=+29.371468666
I0827 11:32:23.502195       1 scheduler.go:454] Total Schedule Algo cumulative time:1.187519564s for 509
I0827 11:32:23.504210       1 scheduler.go:451] ScheduleAlgoTime 1.750863ms Start:2018-08-27 11:32:23.50245211 +0000 UTC m=+29.371759348 End:2018-08-27 11:32:23.504203025 +0000 UTC m=+29.373510211
I0827 11:32:23.504244       1 scheduler.go:454] Total Schedule Algo cumulative time:1.189270427s for 510
I0827 11:32:23.505958       1 scheduler.go:451] ScheduleAlgoTime 1.491875ms Start:2018-08-27 11:32:23.50446003 +0000 UTC m=+29.373767264 End:2018-08-27 11:32:23.505951956 +0000 UTC m=+29.375259139
I0827 11:32:23.505984       1 scheduler.go:454] Total Schedule Algo cumulative time:1.190762302s for 511
I0827 11:32:23.508269       1 scheduler.go:451] ScheduleAlgoTime 2.017489ms Start:2018-08-27 11:32:23.506244475 +0000 UTC m=+29.375551717 End:2018-08-27 11:32:23.508262023 +0000 UTC m=+29.377569206
I0827 11:32:23.508297       1 scheduler.go:454] Total Schedule Algo cumulative time:1.192779791s for 512
I0827 11:32:23.510557       1 scheduler.go:451] ScheduleAlgoTime 1.811104ms Start:2018-08-27 11:32:23.508740273 +0000 UTC m=+29.378047510 End:2018-08-27 11:32:23.510551432 +0000 UTC m=+29.379858614
I0827 11:32:23.510601       1 scheduler.go:454] Total Schedule Algo cumulative time:1.194590895s for 513
I0827 11:32:23.512363       1 scheduler.go:451] ScheduleAlgoTime 1.542048ms Start:2018-08-27 11:32:23.510814507 +0000 UTC m=+29.380121742 End:2018-08-27 11:32:23.512356607 +0000 UTC m=+29.381663790
I0827 11:32:23.512390       1 scheduler.go:454] Total Schedule Algo cumulative time:1.196132943s for 514
I0827 11:32:23.514355       1 scheduler.go:451] ScheduleAlgoTime 1.758314ms Start:2018-08-27 11:32:23.512591484 +0000 UTC m=+29.381898675 End:2018-08-27 11:32:23.514349805 +0000 UTC m=+29.383656989
I0827 11:32:23.514383       1 scheduler.go:454] Total Schedule Algo cumulative time:1.197891257s for 515
I0827 11:32:23.516507       1 scheduler.go:451] ScheduleAlgoTime 1.978372ms Start:2018-08-27 11:32:23.514523383 +0000 UTC m=+29.383830619 End:2018-08-27 11:32:23.51650181 +0000 UTC m=+29.385808991
I0827 11:32:23.516589       1 scheduler.go:454] Total Schedule Algo cumulative time:1.199869629s for 516
I0827 11:32:23.518359       1 scheduler.go:451] ScheduleAlgoTime 1.5378ms Start:2018-08-27 11:32:23.516816979 +0000 UTC m=+29.386124166 End:2018-08-27 11:32:23.518354783 +0000 UTC m=+29.387661966
I0827 11:32:23.518386       1 scheduler.go:454] Total Schedule Algo cumulative time:1.201407429s for 517
I0827 11:32:23.520294       1 scheduler.go:451] ScheduleAlgoTime 1.69245ms Start:2018-08-27 11:32:23.51859641 +0000 UTC m=+29.387903640 End:2018-08-27 11:32:23.520288909 +0000 UTC m=+29.389596090
I0827 11:32:23.520319       1 scheduler.go:454] Total Schedule Algo cumulative time:1.203099879s for 518
I0827 11:32:23.522158       1 scheduler.go:451] ScheduleAlgoTime 1.68787ms Start:2018-08-27 11:32:23.52046367 +0000 UTC m=+29.389770853 End:2018-08-27 11:32:23.52215154 +0000 UTC m=+29.391458723
I0827 11:32:23.522189       1 scheduler.go:454] Total Schedule Algo cumulative time:1.204787749s for 519
I0827 11:32:23.524030       1 scheduler.go:451] ScheduleAlgoTime 1.657802ms Start:2018-08-27 11:32:23.522366364 +0000 UTC m=+29.391673622 End:2018-08-27 11:32:23.524024241 +0000 UTC m=+29.393331424
I0827 11:32:23.524057       1 scheduler.go:454] Total Schedule Algo cumulative time:1.206445551s for 520
I0827 11:32:23.526070       1 scheduler.go:451] ScheduleAlgoTime 1.781353ms Start:2018-08-27 11:32:23.524279169 +0000 UTC m=+29.393586387 End:2018-08-27 11:32:23.526060512 +0000 UTC m=+29.395367740
I0827 11:32:23.526104       1 scheduler.go:454] Total Schedule Algo cumulative time:1.208226904s for 521
I0827 11:32:23.528398       1 scheduler.go:451] ScheduleAlgoTime 2.026714ms Start:2018-08-27 11:32:23.526364073 +0000 UTC m=+29.395671294 End:2018-08-27 11:32:23.528390825 +0000 UTC m=+29.397698008
I0827 11:32:23.528426       1 scheduler.go:454] Total Schedule Algo cumulative time:1.210253618s for 522
I0827 11:32:23.530508       1 scheduler.go:451] ScheduleAlgoTime 1.751188ms Start:2018-08-27 11:32:23.528748825 +0000 UTC m=+29.398056070 End:2018-08-27 11:32:23.530500075 +0000 UTC m=+29.399807258
I0827 11:32:23.530591       1 scheduler.go:454] Total Schedule Algo cumulative time:1.212004806s for 523
I0827 11:32:23.532815       1 scheduler.go:451] ScheduleAlgoTime 1.976224ms Start:2018-08-27 11:32:23.530830341 +0000 UTC m=+29.400137569 End:2018-08-27 11:32:23.532806612 +0000 UTC m=+29.402113793
I0827 11:32:23.532841       1 scheduler.go:454] Total Schedule Algo cumulative time:1.21398103s for 524
I0827 11:32:23.542132       1 scheduler.go:451] ScheduleAlgoTime 9.156778ms Start:2018-08-27 11:32:23.532965819 +0000 UTC m=+29.402273029 End:2018-08-27 11:32:23.542122622 +0000 UTC m=+29.411429807
I0827 11:32:23.542171       1 scheduler.go:454] Total Schedule Algo cumulative time:1.223137808s for 525
I0827 11:32:23.544762       1 scheduler.go:451] ScheduleAlgoTime 2.354261ms Start:2018-08-27 11:32:23.542398485 +0000 UTC m=+29.411705680 End:2018-08-27 11:32:23.544752756 +0000 UTC m=+29.414059941
I0827 11:32:23.544807       1 scheduler.go:454] Total Schedule Algo cumulative time:1.225492069s for 526
I0827 11:32:23.547701       1 scheduler.go:451] ScheduleAlgoTime 2.61583ms Start:2018-08-27 11:32:23.545053679 +0000 UTC m=+29.414360956 End:2018-08-27 11:32:23.547669603 +0000 UTC m=+29.416976786
I0827 11:32:23.547763       1 scheduler.go:454] Total Schedule Algo cumulative time:1.228107899s for 527
I0827 11:32:23.550100       1 scheduler.go:451] ScheduleAlgoTime 2.047678ms Start:2018-08-27 11:32:23.548042399 +0000 UTC m=+29.417349666 End:2018-08-27 11:32:23.550090132 +0000 UTC m=+29.419397344
I0827 11:32:23.550140       1 scheduler.go:454] Total Schedule Algo cumulative time:1.230155577s for 528
I0827 11:32:23.552553       1 scheduler.go:451] ScheduleAlgoTime 2.183906ms Start:2018-08-27 11:32:23.550363551 +0000 UTC m=+29.419670793 End:2018-08-27 11:32:23.552547517 +0000 UTC m=+29.421854699
I0827 11:32:23.552583       1 scheduler.go:454] Total Schedule Algo cumulative time:1.232339483s for 529
I0827 11:32:23.555264       1 scheduler.go:451] ScheduleAlgoTime 2.441314ms Start:2018-08-27 11:32:23.552814152 +0000 UTC m=+29.422121345 End:2018-08-27 11:32:23.555255475 +0000 UTC m=+29.424562659
I0827 11:32:23.555299       1 scheduler.go:454] Total Schedule Algo cumulative time:1.234780797s for 530
I0827 11:32:23.557488       1 scheduler.go:451] ScheduleAlgoTime 1.956662ms Start:2018-08-27 11:32:23.555524113 +0000 UTC m=+29.424831349 End:2018-08-27 11:32:23.55748083 +0000 UTC m=+29.426788011
I0827 11:32:23.557530       1 scheduler.go:454] Total Schedule Algo cumulative time:1.236737459s for 531
I0827 11:32:23.559753       1 scheduler.go:451] ScheduleAlgoTime 1.893651ms Start:2018-08-27 11:32:23.557851353 +0000 UTC m=+29.427158599 End:2018-08-27 11:32:23.559745064 +0000 UTC m=+29.429052250
I0827 11:32:23.559914       1 scheduler.go:454] Total Schedule Algo cumulative time:1.23863111s for 532
I0827 11:32:23.561756       1 scheduler.go:451] ScheduleAlgoTime 1.678912ms Start:2018-08-27 11:32:23.560068875 +0000 UTC m=+29.429376061 End:2018-08-27 11:32:23.561747772 +0000 UTC m=+29.431054973
I0827 11:32:23.561790       1 scheduler.go:454] Total Schedule Algo cumulative time:1.240310022s for 533
I0827 11:32:23.563975       1 scheduler.go:451] ScheduleAlgoTime 1.886428ms Start:2018-08-27 11:32:23.562075744 +0000 UTC m=+29.431382978 End:2018-08-27 11:32:23.563962185 +0000 UTC m=+29.433269406
I0827 11:32:23.564034       1 scheduler.go:454] Total Schedule Algo cumulative time:1.24219645s for 534
I0827 11:32:23.566146       1 scheduler.go:451] ScheduleAlgoTime 1.884724ms Start:2018-08-27 11:32:23.564253797 +0000 UTC m=+29.433561094 End:2018-08-27 11:32:23.566138632 +0000 UTC m=+29.435445818
I0827 11:32:23.566174       1 scheduler.go:454] Total Schedule Algo cumulative time:1.244081174s for 535
I0827 11:32:23.568115       1 scheduler.go:451] ScheduleAlgoTime 1.673484ms Start:2018-08-27 11:32:23.566436139 +0000 UTC m=+29.435743394 End:2018-08-27 11:32:23.568109694 +0000 UTC m=+29.437416878
I0827 11:32:23.568141       1 scheduler.go:454] Total Schedule Algo cumulative time:1.245754658s for 536
I0827 11:32:23.569932       1 scheduler.go:451] ScheduleAlgoTime 1.575944ms Start:2018-08-27 11:32:23.568350305 +0000 UTC m=+29.437657519 End:2018-08-27 11:32:23.569926281 +0000 UTC m=+29.439233463
I0827 11:32:23.569964       1 scheduler.go:454] Total Schedule Algo cumulative time:1.247330602s for 537
I0827 11:32:23.572043       1 scheduler.go:451] ScheduleAlgoTime 1.821562ms Start:2018-08-27 11:32:23.57021615 +0000 UTC m=+29.439523378 End:2018-08-27 11:32:23.572037754 +0000 UTC m=+29.441344940
I0827 11:32:23.572069       1 scheduler.go:454] Total Schedule Algo cumulative time:1.249152164s for 538
I0827 11:32:23.574638       1 scheduler.go:451] ScheduleAlgoTime 2.382655ms Start:2018-08-27 11:32:23.572246001 +0000 UTC m=+29.441553240 End:2018-08-27 11:32:23.574628712 +0000 UTC m=+29.443935895
I0827 11:32:23.574676       1 scheduler.go:454] Total Schedule Algo cumulative time:1.251534819s for 539
I0827 11:32:23.576766       1 scheduler.go:451] ScheduleAlgoTime 1.717195ms Start:2018-08-27 11:32:23.575042043 +0000 UTC m=+29.444349283 End:2018-08-27 11:32:23.576759294 +0000 UTC m=+29.446066478
I0827 11:32:23.576798       1 scheduler.go:454] Total Schedule Algo cumulative time:1.253252014s for 540
I0827 11:32:23.579368       1 scheduler.go:451] ScheduleAlgoTime 2.253084ms Start:2018-08-27 11:32:23.57710695 +0000 UTC m=+29.446414149 End:2018-08-27 11:32:23.579360052 +0000 UTC m=+29.448667233
I0827 11:32:23.579398       1 scheduler.go:454] Total Schedule Algo cumulative time:1.255505098s for 541
I0827 11:32:23.581511       1 scheduler.go:451] ScheduleAlgoTime 1.708601ms Start:2018-08-27 11:32:23.579796392 +0000 UTC m=+29.449103626 End:2018-08-27 11:32:23.581505046 +0000 UTC m=+29.450812227
I0827 11:32:23.581539       1 scheduler.go:454] Total Schedule Algo cumulative time:1.257213699s for 542
I0827 11:32:23.583212       1 scheduler.go:451] ScheduleAlgoTime 1.423072ms Start:2018-08-27 11:32:23.581783762 +0000 UTC m=+29.451090981 End:2018-08-27 11:32:23.583206872 +0000 UTC m=+29.452514053
I0827 11:32:23.583238       1 scheduler.go:454] Total Schedule Algo cumulative time:1.258636771s for 543
I0827 11:32:23.585407       1 scheduler.go:451] ScheduleAlgoTime 1.949211ms Start:2018-08-27 11:32:23.583452002 +0000 UTC m=+29.452759276 End:2018-08-27 11:32:23.585401304 +0000 UTC m=+29.454708487
I0827 11:32:23.585434       1 scheduler.go:454] Total Schedule Algo cumulative time:1.260585982s for 544
I0827 11:32:23.587259       1 scheduler.go:451] ScheduleAlgoTime 1.651974ms Start:2018-08-27 11:32:23.585598222 +0000 UTC m=+29.454905426 End:2018-08-27 11:32:23.587250192 +0000 UTC m=+29.456557400
I0827 11:32:23.587289       1 scheduler.go:454] Total Schedule Algo cumulative time:1.262237956s for 545
I0827 11:32:23.589802       1 scheduler.go:451] ScheduleAlgoTime 2.345615ms Start:2018-08-27 11:32:23.587449626 +0000 UTC m=+29.456756859 End:2018-08-27 11:32:23.58979529 +0000 UTC m=+29.459102474
I0827 11:32:23.589872       1 scheduler.go:454] Total Schedule Algo cumulative time:1.264583571s for 546
I0827 11:32:23.592169       1 scheduler.go:451] ScheduleAlgoTime 2.029089ms Start:2018-08-27 11:32:23.590130815 +0000 UTC m=+29.459438059 End:2018-08-27 11:32:23.592159966 +0000 UTC m=+29.461467148
I0827 11:32:23.592205       1 scheduler.go:454] Total Schedule Algo cumulative time:1.26661266s for 547
I0827 11:32:23.594416       1 scheduler.go:451] ScheduleAlgoTime 2.044532ms Start:2018-08-27 11:32:23.592364514 +0000 UTC m=+29.461671752 End:2018-08-27 11:32:23.594409103 +0000 UTC m=+29.463716284
I0827 11:32:23.594448       1 scheduler.go:454] Total Schedule Algo cumulative time:1.268657192s for 548
I0827 11:32:23.596903       1 scheduler.go:451] ScheduleAlgoTime 2.117551ms Start:2018-08-27 11:32:23.594777841 +0000 UTC m=+29.464085101 End:2018-08-27 11:32:23.596895464 +0000 UTC m=+29.466202652
I0827 11:32:23.596950       1 scheduler.go:454] Total Schedule Algo cumulative time:1.270774743s for 549
I0827 11:32:23.599120       1 scheduler.go:451] ScheduleAlgoTime 1.883247ms Start:2018-08-27 11:32:23.597230009 +0000 UTC m=+29.466537190 End:2018-08-27 11:32:23.599113255 +0000 UTC m=+29.468420437
I0827 11:32:23.599145       1 scheduler.go:454] Total Schedule Algo cumulative time:1.27265799s for 550
I0827 11:32:23.600829       1 scheduler.go:451] ScheduleAlgoTime 1.57515ms Start:2018-08-27 11:32:23.599244767 +0000 UTC m=+29.468551964 End:2018-08-27 11:32:23.600819932 +0000 UTC m=+29.470127114
I0827 11:32:23.600863       1 scheduler.go:454] Total Schedule Algo cumulative time:1.27423314s for 551
I0827 11:32:23.603317       1 scheduler.go:451] ScheduleAlgoTime 2.151789ms Start:2018-08-27 11:32:23.601157471 +0000 UTC m=+29.470464653 End:2018-08-27 11:32:23.603309257 +0000 UTC m=+29.472616442
I0827 11:32:23.603351       1 scheduler.go:454] Total Schedule Algo cumulative time:1.276384929s for 552
I0827 11:32:23.605175       1 scheduler.go:451] ScheduleAlgoTime 1.674229ms Start:2018-08-27 11:32:23.603494103 +0000 UTC m=+29.472801381 End:2018-08-27 11:32:23.605168427 +0000 UTC m=+29.474475610
I0827 11:32:23.605203       1 scheduler.go:454] Total Schedule Algo cumulative time:1.278059158s for 553
I0827 11:32:23.606936       1 scheduler.go:451] ScheduleAlgoTime 1.585902ms Start:2018-08-27 11:32:23.60534463 +0000 UTC m=+29.474651813 End:2018-08-27 11:32:23.606930533 +0000 UTC m=+29.476237715
I0827 11:32:23.606978       1 scheduler.go:454] Total Schedule Algo cumulative time:1.27964506s for 554
I0827 11:32:23.609774       1 scheduler.go:451] ScheduleAlgoTime 2.342891ms Start:2018-08-27 11:32:23.607423333 +0000 UTC m=+29.476730541 End:2018-08-27 11:32:23.609766249 +0000 UTC m=+29.479073432
I0827 11:32:23.609812       1 scheduler.go:454] Total Schedule Algo cumulative time:1.281987951s for 555
I0827 11:32:23.612019       1 scheduler.go:451] ScheduleAlgoTime 1.907413ms Start:2018-08-27 11:32:23.610103969 +0000 UTC m=+29.479411200 End:2018-08-27 11:32:23.61201143 +0000 UTC m=+29.481318613
I0827 11:32:23.612049       1 scheduler.go:454] Total Schedule Algo cumulative time:1.283895364s for 556
I0827 11:32:23.614261       1 scheduler.go:451] ScheduleAlgoTime 2.046699ms Start:2018-08-27 11:32:23.612205814 +0000 UTC m=+29.481513107 End:2018-08-27 11:32:23.614252599 +0000 UTC m=+29.483559806
I0827 11:32:23.614296       1 scheduler.go:454] Total Schedule Algo cumulative time:1.285942063s for 557
I0827 11:32:23.616447       1 scheduler.go:451] ScheduleAlgoTime 1.910656ms Start:2018-08-27 11:32:23.614530144 +0000 UTC m=+29.483837390 End:2018-08-27 11:32:23.616440862 +0000 UTC m=+29.485748046
I0827 11:32:23.616478       1 scheduler.go:454] Total Schedule Algo cumulative time:1.287852719s for 558
I0827 11:32:23.618480       1 scheduler.go:451] ScheduleAlgoTime 1.850661ms Start:2018-08-27 11:32:23.616618539 +0000 UTC m=+29.485928090 End:2018-08-27 11:32:23.618471561 +0000 UTC m=+29.487778751
I0827 11:32:23.618508       1 scheduler.go:454] Total Schedule Algo cumulative time:1.28970338s for 559
I0827 11:32:23.621947       1 scheduler.go:451] ScheduleAlgoTime 3.082348ms Start:2018-08-27 11:32:23.618856222 +0000 UTC m=+29.488163462 End:2018-08-27 11:32:23.621938628 +0000 UTC m=+29.491245810
I0827 11:32:23.621984       1 scheduler.go:454] Total Schedule Algo cumulative time:1.292785728s for 560
I0827 11:32:23.624932       1 scheduler.go:451] ScheduleAlgoTime 2.66775ms Start:2018-08-27 11:32:23.622255469 +0000 UTC m=+29.491562753 End:2018-08-27 11:32:23.624923316 +0000 UTC m=+29.494230503
I0827 11:32:23.624965       1 scheduler.go:454] Total Schedule Algo cumulative time:1.295453478s for 561
I0827 11:32:23.632607       1 scheduler.go:451] ScheduleAlgoTime 7.076306ms Start:2018-08-27 11:32:23.625521962 +0000 UTC m=+29.494829144 End:2018-08-27 11:32:23.632598266 +0000 UTC m=+29.501905450
I0827 11:32:23.632655       1 scheduler.go:454] Total Schedule Algo cumulative time:1.302529784s for 562
I0827 11:32:23.635987       1 scheduler.go:451] ScheduleAlgoTime 2.937155ms Start:2018-08-27 11:32:23.633040032 +0000 UTC m=+29.502347224 End:2018-08-27 11:32:23.635977194 +0000 UTC m=+29.505284379
I0827 11:32:23.636029       1 scheduler.go:454] Total Schedule Algo cumulative time:1.305466939s for 563
I0827 11:32:23.638398       1 scheduler.go:451] ScheduleAlgoTime 2.1478ms Start:2018-08-27 11:32:23.636220341 +0000 UTC m=+29.505527583 End:2018-08-27 11:32:23.638368198 +0000 UTC m=+29.507675383
I0827 11:32:23.638433       1 scheduler.go:454] Total Schedule Algo cumulative time:1.307614739s for 564
I0827 11:32:23.640309       1 scheduler.go:451] ScheduleAlgoTime 1.529495ms Start:2018-08-27 11:32:23.638773123 +0000 UTC m=+29.508080359 End:2018-08-27 11:32:23.640302671 +0000 UTC m=+29.509609854
I0827 11:32:23.640357       1 scheduler.go:454] Total Schedule Algo cumulative time:1.309144234s for 565
I0827 11:32:23.642713       1 scheduler.go:451] ScheduleAlgoTime 2.143639ms Start:2018-08-27 11:32:23.640561054 +0000 UTC m=+29.509868298 End:2018-08-27 11:32:23.642704754 +0000 UTC m=+29.512011937
I0827 11:32:23.642745       1 scheduler.go:454] Total Schedule Algo cumulative time:1.311287873s for 566
I0827 11:32:23.644780       1 scheduler.go:451] ScheduleAlgoTime 1.818401ms Start:2018-08-27 11:32:23.642954948 +0000 UTC m=+29.512262226 End:2018-08-27 11:32:23.644773444 +0000 UTC m=+29.514080627
I0827 11:32:23.644815       1 scheduler.go:454] Total Schedule Algo cumulative time:1.313106274s for 567
I0827 11:32:23.646808       1 scheduler.go:451] ScheduleAlgoTime 1.718518ms Start:2018-08-27 11:32:23.645080175 +0000 UTC m=+29.514387418 End:2018-08-27 11:32:23.646798725 +0000 UTC m=+29.516105936
I0827 11:32:23.646853       1 scheduler.go:454] Total Schedule Algo cumulative time:1.314824792s for 568
I0827 11:32:23.649401       1 scheduler.go:451] ScheduleAlgoTime 2.310678ms Start:2018-08-27 11:32:23.647082213 +0000 UTC m=+29.516389459 End:2018-08-27 11:32:23.649392955 +0000 UTC m=+29.518700137
I0827 11:32:23.649436       1 scheduler.go:454] Total Schedule Algo cumulative time:1.31713547s for 569
I0827 11:32:23.651883       1 scheduler.go:451] ScheduleAlgoTime 2.126498ms Start:2018-08-27 11:32:23.649748733 +0000 UTC m=+29.519055975 End:2018-08-27 11:32:23.651875289 +0000 UTC m=+29.521182473
I0827 11:32:23.651915       1 scheduler.go:454] Total Schedule Algo cumulative time:1.319261968s for 570
I0827 11:32:23.653786       1 scheduler.go:451] ScheduleAlgoTime 1.728745ms Start:2018-08-27 11:32:23.652049158 +0000 UTC m=+29.521356428 End:2018-08-27 11:32:23.653777992 +0000 UTC m=+29.523085173
I0827 11:32:23.653822       1 scheduler.go:454] Total Schedule Algo cumulative time:1.320990713s for 571
I0827 11:32:23.655751       1 scheduler.go:451] ScheduleAlgoTime 1.73861ms Start:2018-08-27 11:32:23.654003954 +0000 UTC m=+29.523311190 End:2018-08-27 11:32:23.655742616 +0000 UTC m=+29.525049800
I0827 11:32:23.655796       1 scheduler.go:454] Total Schedule Algo cumulative time:1.322729323s for 572
I0827 11:32:23.658281       1 scheduler.go:451] ScheduleAlgoTime 2.231696ms Start:2018-08-27 11:32:23.656041465 +0000 UTC m=+29.525348722 End:2018-08-27 11:32:23.658273235 +0000 UTC m=+29.527580418
I0827 11:32:23.658310       1 scheduler.go:454] Total Schedule Algo cumulative time:1.324961019s for 573
I0827 11:32:23.660281       1 scheduler.go:451] ScheduleAlgoTime 1.81617ms Start:2018-08-27 11:32:23.658456811 +0000 UTC m=+29.527764057 End:2018-08-27 11:32:23.660273044 +0000 UTC m=+29.529580227
I0827 11:32:23.660337       1 scheduler.go:454] Total Schedule Algo cumulative time:1.326777189s for 574
I0827 11:32:23.662277       1 scheduler.go:451] ScheduleAlgoTime 1.794346ms Start:2018-08-27 11:32:23.660476278 +0000 UTC m=+29.529783511 End:2018-08-27 11:32:23.662270675 +0000 UTC m=+29.531577857
I0827 11:32:23.662303       1 scheduler.go:454] Total Schedule Algo cumulative time:1.328571535s for 575
I0827 11:32:23.664285       1 scheduler.go:451] ScheduleAlgoTime 1.793501ms Start:2018-08-27 11:32:23.66248462 +0000 UTC m=+29.531791811 End:2018-08-27 11:32:23.664278123 +0000 UTC m=+29.533585312
I0827 11:32:23.664321       1 scheduler.go:454] Total Schedule Algo cumulative time:1.330365036s for 576
I0827 11:32:23.666287       1 scheduler.go:451] ScheduleAlgoTime 1.811977ms Start:2018-08-27 11:32:23.664469793 +0000 UTC m=+29.533776991 End:2018-08-27 11:32:23.666281709 +0000 UTC m=+29.535588968
I0827 11:32:23.666312       1 scheduler.go:454] Total Schedule Algo cumulative time:1.332177013s for 577
I0827 11:32:23.668285       1 scheduler.go:451] ScheduleAlgoTime 1.753881ms Start:2018-08-27 11:32:23.666523016 +0000 UTC m=+29.535830283 End:2018-08-27 11:32:23.668276979 +0000 UTC m=+29.537584164
I0827 11:32:23.668314       1 scheduler.go:454] Total Schedule Algo cumulative time:1.333930894s for 578
I0827 11:32:23.670001       1 scheduler.go:451] ScheduleAlgoTime 1.568414ms Start:2018-08-27 11:32:23.668427604 +0000 UTC m=+29.537734787 End:2018-08-27 11:32:23.669996016 +0000 UTC m=+29.539303201
I0827 11:32:23.670027       1 scheduler.go:454] Total Schedule Algo cumulative time:1.335499308s for 579
I0827 11:32:23.671727       1 scheduler.go:451] ScheduleAlgoTime 1.575714ms Start:2018-08-27 11:32:23.670145422 +0000 UTC m=+29.539452745 End:2018-08-27 11:32:23.67172127 +0000 UTC m=+29.541028459
I0827 11:32:23.671754       1 scheduler.go:454] Total Schedule Algo cumulative time:1.337075022s for 580
I0827 11:32:23.673593       1 scheduler.go:451] ScheduleAlgoTime 1.703502ms Start:2018-08-27 11:32:23.671883669 +0000 UTC m=+29.541190911 End:2018-08-27 11:32:23.67358723 +0000 UTC m=+29.542894413
I0827 11:32:23.673631       1 scheduler.go:454] Total Schedule Algo cumulative time:1.338778524s for 581
I0827 11:32:23.675579       1 scheduler.go:451] ScheduleAlgoTime 1.666448ms Start:2018-08-27 11:32:23.673903549 +0000 UTC m=+29.543210815 End:2018-08-27 11:32:23.675570083 +0000 UTC m=+29.544877263
I0827 11:32:23.675608       1 scheduler.go:454] Total Schedule Algo cumulative time:1.340444972s for 582
I0827 11:32:23.677473       1 scheduler.go:451] ScheduleAlgoTime 1.55253ms Start:2018-08-27 11:32:23.675915127 +0000 UTC m=+29.545222347 End:2018-08-27 11:32:23.677467693 +0000 UTC m=+29.546774877
I0827 11:32:23.677497       1 scheduler.go:454] Total Schedule Algo cumulative time:1.341997502s for 583
I0827 11:32:23.679136       1 scheduler.go:451] ScheduleAlgoTime 1.42085ms Start:2018-08-27 11:32:23.677709553 +0000 UTC m=+29.547016746 End:2018-08-27 11:32:23.67913041 +0000 UTC m=+29.548437596
I0827 11:32:23.679167       1 scheduler.go:454] Total Schedule Algo cumulative time:1.343418352s for 584
I0827 11:32:23.680840       1 scheduler.go:451] ScheduleAlgoTime 1.49855ms Start:2018-08-27 11:32:23.679337334 +0000 UTC m=+29.548644519 End:2018-08-27 11:32:23.680835883 +0000 UTC m=+29.550143069
I0827 11:32:23.680862       1 scheduler.go:454] Total Schedule Algo cumulative time:1.344916902s for 585
I0827 11:32:23.682908       1 scheduler.go:451] ScheduleAlgoTime 1.838167ms Start:2018-08-27 11:32:23.681064911 +0000 UTC m=+29.550372177 End:2018-08-27 11:32:23.682903161 +0000 UTC m=+29.552210344
I0827 11:32:23.682933       1 scheduler.go:454] Total Schedule Algo cumulative time:1.346755069s for 586
I0827 11:32:23.684983       1 scheduler.go:451] ScheduleAlgoTime 1.81877ms Start:2018-08-27 11:32:23.683156648 +0000 UTC m=+29.552463890 End:2018-08-27 11:32:23.684975464 +0000 UTC m=+29.554282660
I0827 11:32:23.685010       1 scheduler.go:454] Total Schedule Algo cumulative time:1.348573839s for 587
I0827 11:32:23.687173       1 scheduler.go:451] ScheduleAlgoTime 1.952643ms Start:2018-08-27 11:32:23.685215709 +0000 UTC m=+29.554522934 End:2018-08-27 11:32:23.687168395 +0000 UTC m=+29.556475577
I0827 11:32:23.687196       1 scheduler.go:454] Total Schedule Algo cumulative time:1.350526482s for 588
I0827 11:32:23.689244       1 scheduler.go:451] ScheduleAlgoTime 1.805635ms Start:2018-08-27 11:32:23.68743288 +0000 UTC m=+29.556740154 End:2018-08-27 11:32:23.689238609 +0000 UTC m=+29.558545789
I0827 11:32:23.689273       1 scheduler.go:454] Total Schedule Algo cumulative time:1.352332117s for 589
I0827 11:32:23.690974       1 scheduler.go:451] ScheduleAlgoTime 1.620263ms Start:2018-08-27 11:32:23.689346814 +0000 UTC m=+29.558654057 End:2018-08-27 11:32:23.690966989 +0000 UTC m=+29.560274320
I0827 11:32:23.691004       1 scheduler.go:454] Total Schedule Algo cumulative time:1.35395238s for 590
I0827 11:32:23.693198       1 scheduler.go:451] ScheduleAlgoTime 1.775351ms Start:2018-08-27 11:32:23.691414512 +0000 UTC m=+29.560721764 End:2018-08-27 11:32:23.693189931 +0000 UTC m=+29.562497115
I0827 11:32:23.693228       1 scheduler.go:454] Total Schedule Algo cumulative time:1.355727731s for 591
I0827 11:32:23.694910       1 scheduler.go:451] ScheduleAlgoTime 1.464478ms Start:2018-08-27 11:32:23.69344073 +0000 UTC m=+29.562747980 End:2018-08-27 11:32:23.694905277 +0000 UTC m=+29.564212458
I0827 11:32:23.694931       1 scheduler.go:454] Total Schedule Algo cumulative time:1.357192209s for 592
I0827 11:32:23.696711       1 scheduler.go:451] ScheduleAlgoTime 1.601777ms Start:2018-08-27 11:32:23.69510338 +0000 UTC m=+29.564410650 End:2018-08-27 11:32:23.696705246 +0000 UTC m=+29.566012427
I0827 11:32:23.696734       1 scheduler.go:454] Total Schedule Algo cumulative time:1.358793986s for 593
I0827 11:32:23.698462       1 scheduler.go:451] ScheduleAlgoTime 1.566463ms Start:2018-08-27 11:32:23.696883141 +0000 UTC m=+29.566190380 End:2018-08-27 11:32:23.698449637 +0000 UTC m=+29.567756843
I0827 11:32:23.698496       1 scheduler.go:454] Total Schedule Algo cumulative time:1.360360449s for 594
I0827 11:32:23.700867       1 scheduler.go:451] ScheduleAlgoTime 2.055772ms Start:2018-08-27 11:32:23.698806785 +0000 UTC m=+29.568114042 End:2018-08-27 11:32:23.700862633 +0000 UTC m=+29.570169814
I0827 11:32:23.700911       1 scheduler.go:454] Total Schedule Algo cumulative time:1.362416221s for 595
I0827 11:32:23.702607       1 scheduler.go:451] ScheduleAlgoTime 1.558525ms Start:2018-08-27 11:32:23.701041141 +0000 UTC m=+29.570348397 End:2018-08-27 11:32:23.70259969 +0000 UTC m=+29.571906922
I0827 11:32:23.702636       1 scheduler.go:454] Total Schedule Algo cumulative time:1.363974746s for 596
I0827 11:32:23.704512       1 scheduler.go:451] ScheduleAlgoTime 1.650067ms Start:2018-08-27 11:32:23.70285426 +0000 UTC m=+29.572161514 End:2018-08-27 11:32:23.704504391 +0000 UTC m=+29.573811581
I0827 11:32:23.704552       1 scheduler.go:454] Total Schedule Algo cumulative time:1.365624813s for 597
I0827 11:32:23.706424       1 scheduler.go:451] ScheduleAlgoTime 1.60612ms Start:2018-08-27 11:32:23.704812821 +0000 UTC m=+29.574120067 End:2018-08-27 11:32:23.706419005 +0000 UTC m=+29.575726187
I0827 11:32:23.706451       1 scheduler.go:454] Total Schedule Algo cumulative time:1.367230933s for 598
I0827 11:32:23.708351       1 scheduler.go:451] ScheduleAlgoTime 1.721237ms Start:2018-08-27 11:32:23.706624183 +0000 UTC m=+29.575931388 End:2018-08-27 11:32:23.708345435 +0000 UTC m=+29.577652625
I0827 11:32:23.708380       1 scheduler.go:454] Total Schedule Algo cumulative time:1.36895217s for 599
I0827 11:32:23.714220       1 scheduler.go:451] ScheduleAlgoTime 5.633627ms Start:2018-08-27 11:32:23.708575735 +0000 UTC m=+29.577882981 End:2018-08-27 11:32:23.714209425 +0000 UTC m=+29.583516608
I0827 11:32:23.714860       1 scheduler.go:454] Total Schedule Algo cumulative time:1.374585797s for 600
I0827 11:32:23.716881       1 scheduler.go:451] ScheduleAlgoTime 1.666863ms Start:2018-08-27 11:32:23.715205978 +0000 UTC m=+29.584513192 End:2018-08-27 11:32:23.716872872 +0000 UTC m=+29.586180055
I0827 11:32:23.716930       1 scheduler.go:454] Total Schedule Algo cumulative time:1.37625266s for 601
I0827 11:32:23.718928       1 scheduler.go:451] ScheduleAlgoTime 1.842567ms Start:2018-08-27 11:32:23.717078014 +0000 UTC m=+29.586385276 End:2018-08-27 11:32:23.718920641 +0000 UTC m=+29.588227843
I0827 11:32:23.718959       1 scheduler.go:454] Total Schedule Algo cumulative time:1.378095227s for 602
I0827 11:32:23.720823       1 scheduler.go:451] ScheduleAlgoTime 1.597006ms Start:2018-08-27 11:32:23.719218921 +0000 UTC m=+29.588526149 End:2018-08-27 11:32:23.720815973 +0000 UTC m=+29.590123155
I0827 11:32:23.720850       1 scheduler.go:454] Total Schedule Algo cumulative time:1.379692233s for 603
I0827 11:32:23.722934       1 scheduler.go:451] ScheduleAlgoTime 1.908992ms Start:2018-08-27 11:32:23.721020459 +0000 UTC m=+29.590327701 End:2018-08-27 11:32:23.722929507 +0000 UTC m=+29.592236693
I0827 11:32:23.722962       1 scheduler.go:454] Total Schedule Algo cumulative time:1.381601225s for 604
I0827 11:32:23.724811       1 scheduler.go:451] ScheduleAlgoTime 1.668338ms Start:2018-08-27 11:32:23.723137859 +0000 UTC m=+29.592445110 End:2018-08-27 11:32:23.724806257 +0000 UTC m=+29.594113448
I0827 11:32:23.724836       1 scheduler.go:454] Total Schedule Algo cumulative time:1.383269563s for 605
I0827 11:32:23.726509       1 scheduler.go:451] ScheduleAlgoTime 1.502008ms Start:2018-08-27 11:32:23.725002255 +0000 UTC m=+29.594309464 End:2018-08-27 11:32:23.726504288 +0000 UTC m=+29.595811472
I0827 11:32:23.726534       1 scheduler.go:454] Total Schedule Algo cumulative time:1.384771571s for 606
I0827 11:32:23.728394       1 scheduler.go:451] ScheduleAlgoTime 1.690299ms Start:2018-08-27 11:32:23.726698273 +0000 UTC m=+29.596005471 End:2018-08-27 11:32:23.728388588 +0000 UTC m=+29.597695770
I0827 11:32:23.728417       1 scheduler.go:454] Total Schedule Algo cumulative time:1.38646187s for 607
I0827 11:32:23.730078       1 scheduler.go:451] ScheduleAlgoTime 1.545998ms Start:2018-08-27 11:32:23.728526345 +0000 UTC m=+29.597833567 End:2018-08-27 11:32:23.730072382 +0000 UTC m=+29.599379565
I0827 11:32:23.730112       1 scheduler.go:454] Total Schedule Algo cumulative time:1.388007868s for 608
I0827 11:32:23.732138       1 scheduler.go:451] ScheduleAlgoTime 1.88274ms Start:2018-08-27 11:32:23.730249796 +0000 UTC m=+29.599556996 End:2018-08-27 11:32:23.732132554 +0000 UTC m=+29.601439736
I0827 11:32:23.732162       1 scheduler.go:454] Total Schedule Algo cumulative time:1.389890608s for 609
I0827 11:32:23.734193       1 scheduler.go:451] ScheduleAlgoTime 1.691785ms Start:2018-08-27 11:32:23.732493024 +0000 UTC m=+29.601800259 End:2018-08-27 11:32:23.734184863 +0000 UTC m=+29.603492044
I0827 11:32:23.734230       1 scheduler.go:454] Total Schedule Algo cumulative time:1.391582393s for 610
I0827 11:32:23.736205       1 scheduler.go:451] ScheduleAlgoTime 1.813382ms Start:2018-08-27 11:32:23.734385727 +0000 UTC m=+29.603692936 End:2018-08-27 11:32:23.736199137 +0000 UTC m=+29.605506318
I0827 11:32:23.736230       1 scheduler.go:454] Total Schedule Algo cumulative time:1.393395775s for 611
I0827 11:32:23.737975       1 scheduler.go:451] ScheduleAlgoTime 1.574089ms Start:2018-08-27 11:32:23.736392515 +0000 UTC m=+29.605699697 End:2018-08-27 11:32:23.737966605 +0000 UTC m=+29.607273786
I0827 11:32:23.738031       1 scheduler.go:454] Total Schedule Algo cumulative time:1.394969864s for 612
I0827 11:32:23.739820       1 scheduler.go:451] ScheduleAlgoTime 1.590907ms Start:2018-08-27 11:32:23.738222975 +0000 UTC m=+29.607530224 End:2018-08-27 11:32:23.739813946 +0000 UTC m=+29.609121131
I0827 11:32:23.739849       1 scheduler.go:454] Total Schedule Algo cumulative time:1.396560771s for 613
I0827 11:32:23.741796       1 scheduler.go:451] ScheduleAlgoTime 1.79912ms Start:2018-08-27 11:32:23.739991885 +0000 UTC m=+29.609299153 End:2018-08-27 11:32:23.741791087 +0000 UTC m=+29.611098273
I0827 11:32:23.741823       1 scheduler.go:454] Total Schedule Algo cumulative time:1.398359891s for 614
I0827 11:32:23.743467       1 scheduler.go:451] ScheduleAlgoTime 1.524178ms Start:2018-08-27 11:32:23.741937035 +0000 UTC m=+29.611244235 End:2018-08-27 11:32:23.74346123 +0000 UTC m=+29.612768413
I0827 11:32:23.743493       1 scheduler.go:454] Total Schedule Algo cumulative time:1.399884069s for 615
I0827 11:32:23.745165       1 scheduler.go:451] ScheduleAlgoTime 1.485434ms Start:2018-08-27 11:32:23.743671391 +0000 UTC m=+29.612978642 End:2018-08-27 11:32:23.745156839 +0000 UTC m=+29.614464076
I0827 11:32:23.745199       1 scheduler.go:454] Total Schedule Algo cumulative time:1.401369503s for 616
I0827 11:32:23.747102       1 scheduler.go:451] ScheduleAlgoTime 1.728734ms Start:2018-08-27 11:32:23.745367634 +0000 UTC m=+29.614674853 End:2018-08-27 11:32:23.747096401 +0000 UTC m=+29.616403587
I0827 11:32:23.747130       1 scheduler.go:454] Total Schedule Algo cumulative time:1.403098237s for 617
I0827 11:32:23.749054       1 scheduler.go:451] ScheduleAlgoTime 1.753303ms Start:2018-08-27 11:32:23.74729585 +0000 UTC m=+29.616603085 End:2018-08-27 11:32:23.749049206 +0000 UTC m=+29.618356388
I0827 11:32:23.749081       1 scheduler.go:454] Total Schedule Algo cumulative time:1.40485154s for 618
I0827 11:32:23.750956       1 scheduler.go:451] ScheduleAlgoTime 1.760593ms Start:2018-08-27 11:32:23.749189403 +0000 UTC m=+29.618496613 End:2018-08-27 11:32:23.750950023 +0000 UTC m=+29.620257206
I0827 11:32:23.750993       1 scheduler.go:454] Total Schedule Algo cumulative time:1.406612133s for 619
I0827 11:32:23.753064       1 scheduler.go:451] ScheduleAlgoTime 1.848191ms Start:2018-08-27 11:32:23.751211268 +0000 UTC m=+29.620518526 End:2018-08-27 11:32:23.753059528 +0000 UTC m=+29.622366717
I0827 11:32:23.753086       1 scheduler.go:454] Total Schedule Algo cumulative time:1.408460324s for 620
I0827 11:32:23.754941       1 scheduler.go:451] ScheduleAlgoTime 1.720101ms Start:2018-08-27 11:32:23.753213987 +0000 UTC m=+29.622521232 End:2018-08-27 11:32:23.754934148 +0000 UTC m=+29.624241333
I0827 11:32:23.754969       1 scheduler.go:454] Total Schedule Algo cumulative time:1.410180425s for 621
I0827 11:32:23.756810       1 scheduler.go:451] ScheduleAlgoTime 1.616356ms Start:2018-08-27 11:32:23.755185356 +0000 UTC m=+29.624492585 End:2018-08-27 11:32:23.756801715 +0000 UTC m=+29.626108941
I0827 11:32:23.756844       1 scheduler.go:454] Total Schedule Algo cumulative time:1.411796781s for 622
I0827 11:32:23.758483       1 scheduler.go:451] ScheduleAlgoTime 1.503635ms Start:2018-08-27 11:32:23.756974968 +0000 UTC m=+29.626282209 End:2018-08-27 11:32:23.758478658 +0000 UTC m=+29.627785844
I0827 11:32:23.758513       1 scheduler.go:454] Total Schedule Algo cumulative time:1.413300416s for 623
I0827 11:32:23.760256       1 scheduler.go:451] ScheduleAlgoTime 1.635275ms Start:2018-08-27 11:32:23.758616829 +0000 UTC m=+29.627924013 End:2018-08-27 11:32:23.760252103 +0000 UTC m=+29.629559288
I0827 11:32:23.760280       1 scheduler.go:454] Total Schedule Algo cumulative time:1.414935691s for 624
I0827 11:32:23.762044       1 scheduler.go:451] ScheduleAlgoTime 1.65969ms Start:2018-08-27 11:32:23.760377816 +0000 UTC m=+29.629685082 End:2018-08-27 11:32:23.76203759 +0000 UTC m=+29.631344772
I0827 11:32:23.762072       1 scheduler.go:454] Total Schedule Algo cumulative time:1.416595381s for 625
I0827 11:32:23.763677       1 scheduler.go:451] ScheduleAlgoTime 1.461996ms Start:2018-08-27 11:32:23.762209673 +0000 UTC m=+29.631516867 End:2018-08-27 11:32:23.763671679 +0000 UTC m=+29.632978863
I0827 11:32:23.763715       1 scheduler.go:454] Total Schedule Algo cumulative time:1.418057377s for 626
I0827 11:32:23.765600       1 scheduler.go:451] ScheduleAlgoTime 1.666582ms Start:2018-08-27 11:32:23.763927423 +0000 UTC m=+29.633234637 End:2018-08-27 11:32:23.765594036 +0000 UTC m=+29.634901219
I0827 11:32:23.765623       1 scheduler.go:454] Total Schedule Algo cumulative time:1.419723959s for 627
I0827 11:32:23.767472       1 scheduler.go:451] ScheduleAlgoTime 1.699415ms Start:2018-08-27 11:32:23.765765329 +0000 UTC m=+29.635072539 End:2018-08-27 11:32:23.767464769 +0000 UTC m=+29.636771954
I0827 11:32:23.767498       1 scheduler.go:454] Total Schedule Algo cumulative time:1.421423374s for 628
I0827 11:32:23.769241       1 scheduler.go:451] ScheduleAlgoTime 1.573823ms Start:2018-08-27 11:32:23.767661783 +0000 UTC m=+29.636969007 End:2018-08-27 11:32:23.769235644 +0000 UTC m=+29.638542830
I0827 11:32:23.769266       1 scheduler.go:454] Total Schedule Algo cumulative time:1.422997197s for 629
I0827 11:32:23.771185       1 scheduler.go:451] ScheduleAlgoTime 1.797157ms Start:2018-08-27 11:32:23.769380457 +0000 UTC m=+29.638687734 End:2018-08-27 11:32:23.77117767 +0000 UTC m=+29.640484891
I0827 11:32:23.771211       1 scheduler.go:454] Total Schedule Algo cumulative time:1.424794354s for 630
I0827 11:32:23.773117       1 scheduler.go:451] ScheduleAlgoTime 1.724178ms Start:2018-08-27 11:32:23.771387225 +0000 UTC m=+29.640694444 End:2018-08-27 11:32:23.773111439 +0000 UTC m=+29.642418622
I0827 11:32:23.773142       1 scheduler.go:454] Total Schedule Algo cumulative time:1.426518532s for 631
I0827 11:32:23.775337       1 scheduler.go:451] ScheduleAlgoTime 1.934869ms Start:2018-08-27 11:32:23.773395335 +0000 UTC m=+29.642702518 End:2018-08-27 11:32:23.775330204 +0000 UTC m=+29.644637387
I0827 11:32:23.775363       1 scheduler.go:454] Total Schedule Algo cumulative time:1.428453401s for 632
I0827 11:32:23.777102       1 scheduler.go:451] ScheduleAlgoTime 1.60062ms Start:2018-08-27 11:32:23.775495339 +0000 UTC m=+29.644802577 End:2018-08-27 11:32:23.777096014 +0000 UTC m=+29.646403197
I0827 11:32:23.777132       1 scheduler.go:454] Total Schedule Algo cumulative time:1.430054021s for 633
I0827 11:32:23.778851       1 scheduler.go:451] ScheduleAlgoTime 1.476694ms Start:2018-08-27 11:32:23.777369688 +0000 UTC m=+29.646676923 End:2018-08-27 11:32:23.778846432 +0000 UTC m=+29.648153617
I0827 11:32:23.778874       1 scheduler.go:454] Total Schedule Algo cumulative time:1.431530715s for 634
I0827 11:32:23.780428       1 scheduler.go:451] ScheduleAlgoTime 1.439668ms Start:2018-08-27 11:32:23.778983045 +0000 UTC m=+29.648290248 End:2018-08-27 11:32:23.780422735 +0000 UTC m=+29.649729916
I0827 11:32:23.780465       1 scheduler.go:454] Total Schedule Algo cumulative time:1.432970383s for 635
I0827 11:32:23.782336       1 scheduler.go:451] ScheduleAlgoTime 1.733924ms Start:2018-08-27 11:32:23.780596969 +0000 UTC m=+29.649904183 End:2018-08-27 11:32:23.782330925 +0000 UTC m=+29.651638107
I0827 11:32:23.782370       1 scheduler.go:454] Total Schedule Algo cumulative time:1.434704307s for 636
I0827 11:32:23.784163       1 scheduler.go:451] ScheduleAlgoTime 1.653772ms Start:2018-08-27 11:32:23.782504181 +0000 UTC m=+29.651811398 End:2018-08-27 11:32:23.78415799 +0000 UTC m=+29.653465170
I0827 11:32:23.784187       1 scheduler.go:454] Total Schedule Algo cumulative time:1.436358079s for 637
I0827 11:32:23.785786       1 scheduler.go:451] ScheduleAlgoTime 1.493425ms Start:2018-08-27 11:32:23.784286199 +0000 UTC m=+29.653593381 End:2018-08-27 11:32:23.785779613 +0000 UTC m=+29.655086806
I0827 11:32:23.785812       1 scheduler.go:454] Total Schedule Algo cumulative time:1.437851504s for 638
I0827 11:32:23.787570       1 scheduler.go:451] ScheduleAlgoTime 1.607459ms Start:2018-08-27 11:32:23.785955859 +0000 UTC m=+29.655263114 End:2018-08-27 11:32:23.78756339 +0000 UTC m=+29.656870573
I0827 11:32:23.787590       1 scheduler.go:454] Total Schedule Algo cumulative time:1.439458963s for 639
I0827 11:32:23.793302       1 scheduler.go:451] ScheduleAlgoTime 5.572704ms Start:2018-08-27 11:32:23.787719169 +0000 UTC m=+29.657026439 End:2018-08-27 11:32:23.793291882 +0000 UTC m=+29.662599143
I0827 11:32:23.793357       1 scheduler.go:454] Total Schedule Algo cumulative time:1.445031667s for 640
I0827 11:32:23.797811       1 scheduler.go:451] ScheduleAlgoTime 4.180222ms Start:2018-08-27 11:32:23.793622299 +0000 UTC m=+29.662929532 End:2018-08-27 11:32:23.797802572 +0000 UTC m=+29.667109754
I0827 11:32:23.797892       1 scheduler.go:454] Total Schedule Algo cumulative time:1.449211889s for 641
I0827 11:32:23.800647       1 scheduler.go:451] ScheduleAlgoTime 2.510515ms Start:2018-08-27 11:32:23.798128254 +0000 UTC m=+29.667435496 End:2018-08-27 11:32:23.800638829 +0000 UTC m=+29.669946011
I0827 11:32:23.800716       1 scheduler.go:454] Total Schedule Algo cumulative time:1.451722404s for 642
I0827 11:32:23.803255       1 scheduler.go:451] ScheduleAlgoTime 2.380954ms Start:2018-08-27 11:32:23.800867757 +0000 UTC m=+29.670174968 End:2018-08-27 11:32:23.803248739 +0000 UTC m=+29.672555922
I0827 11:32:23.803283       1 scheduler.go:454] Total Schedule Algo cumulative time:1.454103358s for 643
I0827 11:32:23.805253       1 scheduler.go:451] ScheduleAlgoTime 1.791869ms Start:2018-08-27 11:32:23.803454007 +0000 UTC m=+29.672761243 End:2018-08-27 11:32:23.805245929 +0000 UTC m=+29.674553112
I0827 11:32:23.805295       1 scheduler.go:454] Total Schedule Algo cumulative time:1.455895227s for 644
I0827 11:32:23.807139       1 scheduler.go:451] ScheduleAlgoTime 1.704944ms Start:2018-08-27 11:32:23.805426679 +0000 UTC m=+29.674733913 End:2018-08-27 11:32:23.807131676 +0000 UTC m=+29.676438857
I0827 11:32:23.807182       1 scheduler.go:454] Total Schedule Algo cumulative time:1.457600171s for 645
I0827 11:32:23.809133       1 scheduler.go:451] ScheduleAlgoTime 1.793395ms Start:2018-08-27 11:32:23.807333549 +0000 UTC m=+29.676640796 End:2018-08-27 11:32:23.80912701 +0000 UTC m=+29.678434191
I0827 11:32:23.809162       1 scheduler.go:454] Total Schedule Algo cumulative time:1.459393566s for 646
I0827 11:32:23.811060       1 scheduler.go:451] ScheduleAlgoTime 1.747345ms Start:2018-08-27 11:32:23.809306089 +0000 UTC m=+29.678613333 End:2018-08-27 11:32:23.811053493 +0000 UTC m=+29.680360678
I0827 11:32:23.811086       1 scheduler.go:454] Total Schedule Algo cumulative time:1.461140911s for 647
I0827 11:32:23.813650       1 scheduler.go:451] ScheduleAlgoTime 2.333907ms Start:2018-08-27 11:32:23.811307487 +0000 UTC m=+29.680614782 End:2018-08-27 11:32:23.813641506 +0000 UTC m=+29.682948689
I0827 11:32:23.813690       1 scheduler.go:454] Total Schedule Algo cumulative time:1.463474818s for 648
I0827 11:32:23.815527       1 scheduler.go:451] ScheduleAlgoTime 1.664533ms Start:2018-08-27 11:32:23.813854734 +0000 UTC m=+29.683161981 End:2018-08-27 11:32:23.815519333 +0000 UTC m=+29.684826514
I0827 11:32:23.815562       1 scheduler.go:454] Total Schedule Algo cumulative time:1.465139351s for 649
I0827 11:32:23.817411       1 scheduler.go:451] ScheduleAlgoTime 1.646156ms Start:2018-08-27 11:32:23.815759322 +0000 UTC m=+29.685066559 End:2018-08-27 11:32:23.817405535 +0000 UTC m=+29.686712715
I0827 11:32:23.817443       1 scheduler.go:454] Total Schedule Algo cumulative time:1.466785507s for 650
I0827 11:32:23.819349       1 scheduler.go:451] ScheduleAlgoTime 1.757791ms Start:2018-08-27 11:32:23.817585095 +0000 UTC m=+29.686892334 End:2018-08-27 11:32:23.819342938 +0000 UTC m=+29.688650125
I0827 11:32:23.819385       1 scheduler.go:454] Total Schedule Algo cumulative time:1.468543298s for 651
I0827 11:32:23.821610       1 scheduler.go:451] ScheduleAlgoTime 2.082169ms Start:2018-08-27 11:32:23.819516667 +0000 UTC m=+29.688823910 End:2018-08-27 11:32:23.821598893 +0000 UTC m=+29.690906079
I0827 11:32:23.821646       1 scheduler.go:454] Total Schedule Algo cumulative time:1.470625467s for 652
I0827 11:32:23.824048       1 scheduler.go:451] ScheduleAlgoTime 2.175367ms Start:2018-08-27 11:32:23.821864995 +0000 UTC m=+29.691172215 End:2018-08-27 11:32:23.824040399 +0000 UTC m=+29.693347582
I0827 11:32:23.824076       1 scheduler.go:454] Total Schedule Algo cumulative time:1.472800834s for 653
I0827 11:32:23.826105       1 scheduler.go:451] ScheduleAlgoTime 1.89489ms Start:2018-08-27 11:32:23.824204318 +0000 UTC m=+29.693511575 End:2018-08-27 11:32:23.826099282 +0000 UTC m=+29.695406465
I0827 11:32:23.826127       1 scheduler.go:454] Total Schedule Algo cumulative time:1.474695724s for 654
I0827 11:32:23.828104       1 scheduler.go:451] ScheduleAlgoTime 1.750968ms Start:2018-08-27 11:32:23.826344229 +0000 UTC m=+29.695651478 End:2018-08-27 11:32:23.828095162 +0000 UTC m=+29.697402446
I0827 11:32:23.828153       1 scheduler.go:454] Total Schedule Algo cumulative time:1.476446692s for 655
I0827 11:32:23.830103       1 scheduler.go:451] ScheduleAlgoTime 1.732904ms Start:2018-08-27 11:32:23.828362059 +0000 UTC m=+29.697669255 End:2018-08-27 11:32:23.830094968 +0000 UTC m=+29.699402159
I0827 11:32:23.830124       1 scheduler.go:454] Total Schedule Algo cumulative time:1.478179596s for 656
I0827 11:32:23.832099       1 scheduler.go:451] ScheduleAlgoTime 1.840676ms Start:2018-08-27 11:32:23.830251562 +0000 UTC m=+29.699558760 End:2018-08-27 11:32:23.832092253 +0000 UTC m=+29.701399436
I0827 11:32:23.832131       1 scheduler.go:454] Total Schedule Algo cumulative time:1.480020272s for 657
I0827 11:32:23.833819       1 scheduler.go:451] ScheduleAlgoTime 1.562457ms Start:2018-08-27 11:32:23.832251026 +0000 UTC m=+29.701558279 End:2018-08-27 11:32:23.833813553 +0000 UTC m=+29.703120736
I0827 11:32:23.833845       1 scheduler.go:454] Total Schedule Algo cumulative time:1.481582729s for 658
I0827 11:32:23.835691       1 scheduler.go:451] ScheduleAlgoTime 1.671463ms Start:2018-08-27 11:32:23.834006136 +0000 UTC m=+29.703313433 End:2018-08-27 11:32:23.835677713 +0000 UTC m=+29.704984896
I0827 11:32:23.835716       1 scheduler.go:454] Total Schedule Algo cumulative time:1.483254192s for 659
I0827 11:32:23.837620       1 scheduler.go:451] ScheduleAlgoTime 1.770904ms Start:2018-08-27 11:32:23.835843205 +0000 UTC m=+29.705150436 End:2018-08-27 11:32:23.837614158 +0000 UTC m=+29.706921340
I0827 11:32:23.837649       1 scheduler.go:454] Total Schedule Algo cumulative time:1.485025096s for 660
I0827 11:32:23.839888       1 scheduler.go:451] ScheduleAlgoTime 2.076857ms Start:2018-08-27 11:32:23.837801746 +0000 UTC m=+29.707109004 End:2018-08-27 11:32:23.839878572 +0000 UTC m=+29.709185861
I0827 11:32:23.839923       1 scheduler.go:454] Total Schedule Algo cumulative time:1.487101953s for 661
I0827 11:32:23.841983       1 scheduler.go:451] ScheduleAlgoTime 1.86461ms Start:2018-08-27 11:32:23.840111314 +0000 UTC m=+29.709418512 End:2018-08-27 11:32:23.841975937 +0000 UTC m=+29.711283122
I0827 11:32:23.842024       1 scheduler.go:454] Total Schedule Algo cumulative time:1.488966563s for 662
I0827 11:32:23.843605       1 scheduler.go:451] ScheduleAlgoTime 1.450926ms Start:2018-08-27 11:32:23.842147556 +0000 UTC m=+29.711454774 End:2018-08-27 11:32:23.843598518 +0000 UTC m=+29.712905700
I0827 11:32:23.843632       1 scheduler.go:454] Total Schedule Algo cumulative time:1.490417489s for 663
I0827 11:32:23.845379       1 scheduler.go:451] ScheduleAlgoTime 1.529772ms Start:2018-08-27 11:32:23.843844356 +0000 UTC m=+29.713151554 End:2018-08-27 11:32:23.845374141 +0000 UTC m=+29.714681326
I0827 11:32:23.845403       1 scheduler.go:454] Total Schedule Algo cumulative time:1.491947261s for 664
I0827 11:32:23.847305       1 scheduler.go:451] ScheduleAlgoTime 1.751716ms Start:2018-08-27 11:32:23.845546507 +0000 UTC m=+29.714853758 End:2018-08-27 11:32:23.847298291 +0000 UTC m=+29.716605474
I0827 11:32:23.847332       1 scheduler.go:454] Total Schedule Algo cumulative time:1.493698977s for 665
I0827 11:32:23.849308       1 scheduler.go:451] ScheduleAlgoTime 1.79185ms Start:2018-08-27 11:32:23.847510552 +0000 UTC m=+29.716817756 End:2018-08-27 11:32:23.849302418 +0000 UTC m=+29.718609606
I0827 11:32:23.849334       1 scheduler.go:454] Total Schedule Algo cumulative time:1.495490827s for 666
I0827 11:32:23.850957       1 scheduler.go:451] ScheduleAlgoTime 1.455296ms Start:2018-08-27 11:32:23.849496782 +0000 UTC m=+29.718804003 End:2018-08-27 11:32:23.850952118 +0000 UTC m=+29.720259299
I0827 11:32:23.850983       1 scheduler.go:454] Total Schedule Algo cumulative time:1.496946123s for 667
I0827 11:32:23.852880       1 scheduler.go:451] ScheduleAlgoTime 1.697155ms Start:2018-08-27 11:32:23.851177688 +0000 UTC m=+29.720484869 End:2018-08-27 11:32:23.852874838 +0000 UTC m=+29.722182024
I0827 11:32:23.852904       1 scheduler.go:454] Total Schedule Algo cumulative time:1.498643278s for 668
I0827 11:32:23.854634       1 scheduler.go:451] ScheduleAlgoTime 1.577039ms Start:2018-08-27 11:32:23.853050314 +0000 UTC m=+29.722357513 End:2018-08-27 11:32:23.8546273 +0000 UTC m=+29.723934552
I0827 11:32:23.854661       1 scheduler.go:454] Total Schedule Algo cumulative time:1.500220317s for 669
I0827 11:32:23.856468       1 scheduler.go:451] ScheduleAlgoTime 1.646379ms Start:2018-08-27 11:32:23.854817199 +0000 UTC m=+29.724124400 End:2018-08-27 11:32:23.856463591 +0000 UTC m=+29.725770779
I0827 11:32:23.856493       1 scheduler.go:454] Total Schedule Algo cumulative time:1.501866696s for 670
I0827 11:32:23.858068       1 scheduler.go:451] ScheduleAlgoTime 1.469021ms Start:2018-08-27 11:32:23.856592032 +0000 UTC m=+29.725899275 End:2018-08-27 11:32:23.858061114 +0000 UTC m=+29.727368296
I0827 11:32:23.858096       1 scheduler.go:454] Total Schedule Algo cumulative time:1.503335717s for 671
I0827 11:32:23.859945       1 scheduler.go:451] ScheduleAlgoTime 1.691055ms Start:2018-08-27 11:32:23.858248132 +0000 UTC m=+29.727555380 End:2018-08-27 11:32:23.859939252 +0000 UTC m=+29.729246435
I0827 11:32:23.859969       1 scheduler.go:454] Total Schedule Algo cumulative time:1.505026772s for 672
I0827 11:32:23.861925       1 scheduler.go:451] ScheduleAlgoTime 1.817848ms Start:2018-08-27 11:32:23.860101276 +0000 UTC m=+29.729408494 End:2018-08-27 11:32:23.861919161 +0000 UTC m=+29.731226342
I0827 11:32:23.861950       1 scheduler.go:454] Total Schedule Algo cumulative time:1.50684462s for 673
I0827 11:32:23.863627       1 scheduler.go:451] ScheduleAlgoTime 1.541844ms Start:2018-08-27 11:32:23.862080869 +0000 UTC m=+29.731388111 End:2018-08-27 11:32:23.863622772 +0000 UTC m=+29.732929955
I0827 11:32:23.863673       1 scheduler.go:454] Total Schedule Algo cumulative time:1.508386464s for 674
I0827 11:32:23.865274       1 scheduler.go:451] ScheduleAlgoTime 1.417011ms Start:2018-08-27 11:32:23.863851776 +0000 UTC m=+29.733158994 End:2018-08-27 11:32:23.865268823 +0000 UTC m=+29.734576005
I0827 11:32:23.865298       1 scheduler.go:454] Total Schedule Algo cumulative time:1.509803475s for 675
I0827 11:32:23.866866       1 scheduler.go:451] ScheduleAlgoTime 1.425435ms Start:2018-08-27 11:32:23.865432098 +0000 UTC m=+29.734739324 End:2018-08-27 11:32:23.866857574 +0000 UTC m=+29.736164759
I0827 11:32:23.866897       1 scheduler.go:454] Total Schedule Algo cumulative time:1.51122891s for 676
I0827 11:32:23.868700       1 scheduler.go:451] ScheduleAlgoTime 1.673791ms Start:2018-08-27 11:32:23.867019923 +0000 UTC m=+29.736327145 End:2018-08-27 11:32:23.868693746 +0000 UTC m=+29.738000936
I0827 11:32:23.868730       1 scheduler.go:454] Total Schedule Algo cumulative time:1.512902701s for 677
I0827 11:32:23.870399       1 scheduler.go:451] ScheduleAlgoTime 1.461596ms Start:2018-08-27 11:32:23.868932145 +0000 UTC m=+29.738239351 End:2018-08-27 11:32:23.870393762 +0000 UTC m=+29.739700947
I0827 11:32:23.870421       1 scheduler.go:454] Total Schedule Algo cumulative time:1.514364297s for 678
I0827 11:32:23.872393       1 scheduler.go:451] ScheduleAlgoTime 1.856205ms Start:2018-08-27 11:32:23.870531233 +0000 UTC m=+29.739838448 End:2018-08-27 11:32:23.872387468 +0000 UTC m=+29.741694653
I0827 11:32:23.872415       1 scheduler.go:454] Total Schedule Algo cumulative time:1.516220502s for 679
I0827 11:32:23.877904       1 scheduler.go:451] ScheduleAlgoTime 5.381402ms Start:2018-08-27 11:32:23.872515468 +0000 UTC m=+29.741822670 End:2018-08-27 11:32:23.877896885 +0000 UTC m=+29.747204072
I0827 11:32:23.877937       1 scheduler.go:454] Total Schedule Algo cumulative time:1.521601904s for 680
I0827 11:32:23.880671       1 scheduler.go:451] ScheduleAlgoTime 2.498189ms Start:2018-08-27 11:32:23.878163849 +0000 UTC m=+29.747471101 End:2018-08-27 11:32:23.880662108 +0000 UTC m=+29.749969290
I0827 11:32:23.880722       1 scheduler.go:454] Total Schedule Algo cumulative time:1.524100093s for 681
I0827 11:32:23.882511       1 scheduler.go:451] ScheduleAlgoTime 1.65626ms Start:2018-08-27 11:32:23.880849566 +0000 UTC m=+29.750156803 End:2018-08-27 11:32:23.882505876 +0000 UTC m=+29.751813063
I0827 11:32:23.882551       1 scheduler.go:454] Total Schedule Algo cumulative time:1.525756353s for 682
I0827 11:32:23.884336       1 scheduler.go:451] ScheduleAlgoTime 1.638566ms Start:2018-08-27 11:32:23.882691222 +0000 UTC m=+29.751998441 End:2018-08-27 11:32:23.884329824 +0000 UTC m=+29.753637007
I0827 11:32:23.884373       1 scheduler.go:454] Total Schedule Algo cumulative time:1.527394919s for 683
I0827 11:32:23.886343       1 scheduler.go:451] ScheduleAlgoTime 1.874892ms Start:2018-08-27 11:32:23.884459226 +0000 UTC m=+29.753766422 End:2018-08-27 11:32:23.886334029 +0000 UTC m=+29.755641314
I0827 11:32:23.886373       1 scheduler.go:454] Total Schedule Algo cumulative time:1.529269811s for 684
I0827 11:32:23.888273       1 scheduler.go:451] ScheduleAlgoTime 1.732254ms Start:2018-08-27 11:32:23.886535633 +0000 UTC m=+29.755842919 End:2018-08-27 11:32:23.88826799 +0000 UTC m=+29.757575173
I0827 11:32:23.888307       1 scheduler.go:454] Total Schedule Algo cumulative time:1.531002065s for 685
I0827 11:32:23.890094       1 scheduler.go:451] ScheduleAlgoTime 1.712814ms Start:2018-08-27 11:32:23.888376338 +0000 UTC m=+29.757683551 End:2018-08-27 11:32:23.89008918 +0000 UTC m=+29.759396365
I0827 11:32:23.890118       1 scheduler.go:454] Total Schedule Algo cumulative time:1.532714879s for 686
I0827 11:32:23.892425       1 scheduler.go:451] ScheduleAlgoTime 2.187722ms Start:2018-08-27 11:32:23.890229931 +0000 UTC m=+29.759537181 End:2018-08-27 11:32:23.89241772 +0000 UTC m=+29.761724903
I0827 11:32:23.892459       1 scheduler.go:454] Total Schedule Algo cumulative time:1.534902601s for 687
I0827 11:32:23.894564       1 scheduler.go:451] ScheduleAlgoTime 1.961669ms Start:2018-08-27 11:32:23.892595171 +0000 UTC m=+29.761902376 End:2018-08-27 11:32:23.894556862 +0000 UTC m=+29.763864045
I0827 11:32:23.894591       1 scheduler.go:454] Total Schedule Algo cumulative time:1.53686427s for 688
I0827 11:32:23.896603       1 scheduler.go:451] ScheduleAlgoTime 1.881849ms Start:2018-08-27 11:32:23.894714087 +0000 UTC m=+29.764021346 End:2018-08-27 11:32:23.896596015 +0000 UTC m=+29.765903195
I0827 11:32:23.896639       1 scheduler.go:454] Total Schedule Algo cumulative time:1.538746119s for 689
I0827 11:32:23.898152       1 scheduler.go:451] ScheduleAlgoTime 1.368027ms Start:2018-08-27 11:32:23.896778675 +0000 UTC m=+29.766085880 End:2018-08-27 11:32:23.898146722 +0000 UTC m=+29.767453907
I0827 11:32:23.898175       1 scheduler.go:454] Total Schedule Algo cumulative time:1.540114146s for 690
I0827 11:32:23.900072       1 scheduler.go:451] ScheduleAlgoTime 1.754923ms Start:2018-08-27 11:32:23.898312492 +0000 UTC m=+29.767619711 End:2018-08-27 11:32:23.900067453 +0000 UTC m=+29.769374634
I0827 11:32:23.900109       1 scheduler.go:454] Total Schedule Algo cumulative time:1.541869069s for 691
I0827 11:32:23.902485       1 scheduler.go:451] ScheduleAlgoTime 2.163233ms Start:2018-08-27 11:32:23.900315328 +0000 UTC m=+29.769622558 End:2018-08-27 11:32:23.902478605 +0000 UTC m=+29.771785791
I0827 11:32:23.902514       1 scheduler.go:454] Total Schedule Algo cumulative time:1.544032302s for 692
I0827 11:32:23.904281       1 scheduler.go:451] ScheduleAlgoTime 1.616814ms Start:2018-08-27 11:32:23.902658812 +0000 UTC m=+29.771966063 End:2018-08-27 11:32:23.904275694 +0000 UTC m=+29.773582877
I0827 11:32:23.904308       1 scheduler.go:454] Total Schedule Algo cumulative time:1.545649116s for 693
I0827 11:32:23.906125       1 scheduler.go:451] ScheduleAlgoTime 1.678773ms Start:2018-08-27 11:32:23.904440569 +0000 UTC m=+29.773747811 End:2018-08-27 11:32:23.906119401 +0000 UTC m=+29.775426584
I0827 11:32:23.906151       1 scheduler.go:454] Total Schedule Algo cumulative time:1.547327889s for 694
I0827 11:32:23.907964       1 scheduler.go:451] ScheduleAlgoTime 1.57244ms Start:2018-08-27 11:32:23.906385561 +0000 UTC m=+29.775692782 End:2018-08-27 11:32:23.907958034 +0000 UTC m=+29.777265222
I0827 11:32:23.907990       1 scheduler.go:454] Total Schedule Algo cumulative time:1.548900329s for 695
I0827 11:32:23.910068       1 scheduler.go:451] ScheduleAlgoTime 1.885174ms Start:2018-08-27 11:32:23.908176564 +0000 UTC m=+29.777483784 End:2018-08-27 11:32:23.910061776 +0000 UTC m=+29.779368958
I0827 11:32:23.910134       1 scheduler.go:454] Total Schedule Algo cumulative time:1.550785503s for 696
I0827 11:32:23.911755       1 scheduler.go:451] ScheduleAlgoTime 1.511466ms Start:2018-08-27 11:32:23.910239296 +0000 UTC m=+29.779546543 End:2018-08-27 11:32:23.911750828 +0000 UTC m=+29.781058009
I0827 11:32:23.911777       1 scheduler.go:454] Total Schedule Algo cumulative time:1.552296969s for 697
I0827 11:32:23.913370       1 scheduler.go:451] ScheduleAlgoTime 1.466924ms Start:2018-08-27 11:32:23.911897685 +0000 UTC m=+29.781204888 End:2018-08-27 11:32:23.913364629 +0000 UTC m=+29.782671812
I0827 11:32:23.913398       1 scheduler.go:454] Total Schedule Algo cumulative time:1.553763893s for 698
I0827 11:32:23.914986       1 scheduler.go:451] ScheduleAlgoTime 1.460208ms Start:2018-08-27 11:32:23.913521375 +0000 UTC m=+29.782828717 End:2018-08-27 11:32:23.914981736 +0000 UTC m=+29.784288925
I0827 11:32:23.915008       1 scheduler.go:454] Total Schedule Algo cumulative time:1.555224101s for 699
I0827 11:32:23.916812       1 scheduler.go:451] ScheduleAlgoTime 1.700058ms Start:2018-08-27 11:32:23.91510535 +0000 UTC m=+29.784412532 End:2018-08-27 11:32:23.916805407 +0000 UTC m=+29.786112590
I0827 11:32:23.916836       1 scheduler.go:454] Total Schedule Algo cumulative time:1.556924159s for 700
I0827 11:32:23.918554       1 scheduler.go:451] ScheduleAlgoTime 1.537565ms Start:2018-08-27 11:32:23.917011204 +0000 UTC m=+29.786318387 End:2018-08-27 11:32:23.91854877 +0000 UTC m=+29.787855952
I0827 11:32:23.918575       1 scheduler.go:454] Total Schedule Algo cumulative time:1.558461724s for 701
I0827 11:32:23.920375       1 scheduler.go:451] ScheduleAlgoTime 1.605397ms Start:2018-08-27 11:32:23.918764816 +0000 UTC m=+29.788072045 End:2018-08-27 11:32:23.920370257 +0000 UTC m=+29.789677442
I0827 11:32:23.920399       1 scheduler.go:454] Total Schedule Algo cumulative time:1.560067121s for 702
I0827 11:32:23.922063       1 scheduler.go:451] ScheduleAlgoTime 1.5508ms Start:2018-08-27 11:32:23.920507326 +0000 UTC m=+29.789814509 End:2018-08-27 11:32:23.922058127 +0000 UTC m=+29.791365309
I0827 11:32:23.922101       1 scheduler.go:454] Total Schedule Algo cumulative time:1.561617921s for 703
I0827 11:32:23.923878       1 scheduler.go:451] ScheduleAlgoTime 1.539491ms Start:2018-08-27 11:32:23.922333304 +0000 UTC m=+29.791640528 End:2018-08-27 11:32:23.923872837 +0000 UTC m=+29.793180019
I0827 11:32:23.923903       1 scheduler.go:454] Total Schedule Algo cumulative time:1.563157412s for 704
I0827 11:32:23.925706       1 scheduler.go:451] ScheduleAlgoTime 1.618702ms Start:2018-08-27 11:32:23.92408283 +0000 UTC m=+29.793390049 End:2018-08-27 11:32:23.925701568 +0000 UTC m=+29.795008751
I0827 11:32:23.925729       1 scheduler.go:454] Total Schedule Algo cumulative time:1.564776114s for 705
I0827 11:32:23.927686       1 scheduler.go:451] ScheduleAlgoTime 1.724002ms Start:2018-08-27 11:32:23.925947945 +0000 UTC m=+29.795255175 End:2018-08-27 11:32:23.927671993 +0000 UTC m=+29.796979177
I0827 11:32:23.927712       1 scheduler.go:454] Total Schedule Algo cumulative time:1.566500116s for 706
I0827 11:32:23.929390       1 scheduler.go:451] ScheduleAlgoTime 1.511974ms Start:2018-08-27 11:32:23.927873977 +0000 UTC m=+29.797181159 End:2018-08-27 11:32:23.929385947 +0000 UTC m=+29.798693133
I0827 11:32:23.929413       1 scheduler.go:454] Total Schedule Algo cumulative time:1.56801209s for 707
I0827 11:32:23.931131       1 scheduler.go:451] ScheduleAlgoTime 1.525833ms Start:2018-08-27 11:32:23.929599757 +0000 UTC m=+29.798907014 End:2018-08-27 11:32:23.931125664 +0000 UTC m=+29.800432847
I0827 11:32:23.931156       1 scheduler.go:454] Total Schedule Algo cumulative time:1.569537923s for 708
I0827 11:32:23.932916       1 scheduler.go:451] ScheduleAlgoTime 1.61817ms Start:2018-08-27 11:32:23.93129241 +0000 UTC m=+29.800599614 End:2018-08-27 11:32:23.932910601 +0000 UTC m=+29.802217784
I0827 11:32:23.932940       1 scheduler.go:454] Total Schedule Algo cumulative time:1.571156093s for 709
I0827 11:32:23.934692       1 scheduler.go:451] ScheduleAlgoTime 1.66113ms Start:2018-08-27 11:32:23.933026039 +0000 UTC m=+29.802333247 End:2018-08-27 11:32:23.934687195 +0000 UTC m=+29.803994377
I0827 11:32:23.934712       1 scheduler.go:454] Total Schedule Algo cumulative time:1.572817223s for 710
I0827 11:32:23.936272       1 scheduler.go:451] ScheduleAlgoTime 1.439859ms Start:2018-08-27 11:32:23.934827883 +0000 UTC m=+29.804135094 End:2018-08-27 11:32:23.93626777 +0000 UTC m=+29.805574953
I0827 11:32:23.936294       1 scheduler.go:454] Total Schedule Algo cumulative time:1.574257082s for 711
I0827 11:32:23.938037       1 scheduler.go:451] ScheduleAlgoTime 1.632988ms Start:2018-08-27 11:32:23.936398016 +0000 UTC m=+29.805705260 End:2018-08-27 11:32:23.938031065 +0000 UTC m=+29.807338248
I0827 11:32:23.938061       1 scheduler.go:454] Total Schedule Algo cumulative time:1.57589007s for 712
I0827 11:32:23.939615       1 scheduler.go:451] ScheduleAlgoTime 1.434482ms Start:2018-08-27 11:32:23.938175764 +0000 UTC m=+29.807482991 End:2018-08-27 11:32:23.939610291 +0000 UTC m=+29.808917473
I0827 11:32:23.939659       1 scheduler.go:454] Total Schedule Algo cumulative time:1.577324552s for 713
I0827 11:32:23.941203       1 scheduler.go:451] ScheduleAlgoTime 1.400421ms Start:2018-08-27 11:32:23.939797961 +0000 UTC m=+29.809105208 End:2018-08-27 11:32:23.941198447 +0000 UTC m=+29.810505629
I0827 11:32:23.941222       1 scheduler.go:454] Total Schedule Algo cumulative time:1.578724973s for 714
I0827 11:32:23.942812       1 scheduler.go:451] ScheduleAlgoTime 1.486288ms Start:2018-08-27 11:32:23.941322437 +0000 UTC m=+29.810629662 End:2018-08-27 11:32:23.942808768 +0000 UTC m=+29.812115950
I0827 11:32:23.942831       1 scheduler.go:454] Total Schedule Algo cumulative time:1.580211261s for 715
I0827 11:32:23.944547       1 scheduler.go:451] ScheduleAlgoTime 1.589915ms Start:2018-08-27 11:32:23.94295057 +0000 UTC m=+29.812257753 End:2018-08-27 11:32:23.944540487 +0000 UTC m=+29.813847668
I0827 11:32:23.944582       1 scheduler.go:454] Total Schedule Algo cumulative time:1.581801176s for 716
I0827 11:32:23.946233       1 scheduler.go:451] ScheduleAlgoTime 1.539556ms Start:2018-08-27 11:32:23.944688079 +0000 UTC m=+29.813995302 End:2018-08-27 11:32:23.946227671 +0000 UTC m=+29.815534858
I0827 11:32:23.946260       1 scheduler.go:454] Total Schedule Algo cumulative time:1.583340732s for 717
I0827 11:32:23.948041       1 scheduler.go:451] ScheduleAlgoTime 1.636928ms Start:2018-08-27 11:32:23.946399552 +0000 UTC m=+29.815706776 End:2018-08-27 11:32:23.948036517 +0000 UTC m=+29.817343704
I0827 11:32:23.948066       1 scheduler.go:454] Total Schedule Algo cumulative time:1.58497766s for 718
I0827 11:32:23.951843       1 scheduler.go:451] ScheduleAlgoTime 3.641871ms Start:2018-08-27 11:32:23.948190692 +0000 UTC m=+29.817497875 End:2018-08-27 11:32:23.951832443 +0000 UTC m=+29.821139746
I0827 11:32:23.951961       1 scheduler.go:454] Total Schedule Algo cumulative time:1.588619531s for 719
I0827 11:32:23.956305       1 scheduler.go:451] ScheduleAlgoTime 3.852722ms Start:2018-08-27 11:32:23.95244396 +0000 UTC m=+29.821751148 End:2018-08-27 11:32:23.956296688 +0000 UTC m=+29.825603870
I0827 11:32:23.956342       1 scheduler.go:454] Total Schedule Algo cumulative time:1.592472253s for 720
I0827 11:32:23.958506       1 scheduler.go:451] ScheduleAlgoTime 2.010264ms Start:2018-08-27 11:32:23.956488943 +0000 UTC m=+29.825796192 End:2018-08-27 11:32:23.958499274 +0000 UTC m=+29.827806456
I0827 11:32:23.958533       1 scheduler.go:454] Total Schedule Algo cumulative time:1.594482517s for 721
I0827 11:32:23.960335       1 scheduler.go:451] ScheduleAlgoTime 1.68869ms Start:2018-08-27 11:32:23.95863982 +0000 UTC m=+29.827947078 End:2018-08-27 11:32:23.960328579 +0000 UTC m=+29.829635768
I0827 11:32:23.960372       1 scheduler.go:454] Total Schedule Algo cumulative time:1.596171207s for 722
I0827 11:32:23.962231       1 scheduler.go:451] ScheduleAlgoTime 1.699767ms Start:2018-08-27 11:32:23.960523166 +0000 UTC m=+29.829830457 End:2018-08-27 11:32:23.962223042 +0000 UTC m=+29.831530224
I0827 11:32:23.962278       1 scheduler.go:454] Total Schedule Algo cumulative time:1.597870974s for 723
I0827 11:32:23.963802       1 scheduler.go:451] ScheduleAlgoTime 1.377124ms Start:2018-08-27 11:32:23.962418837 +0000 UTC m=+29.831726073 End:2018-08-27 11:32:23.963796014 +0000 UTC m=+29.833103197
I0827 11:32:23.963842       1 scheduler.go:454] Total Schedule Algo cumulative time:1.599248098s for 724
I0827 11:32:23.965451       1 scheduler.go:451] ScheduleAlgoTime 1.511741ms Start:2018-08-27 11:32:23.963934687 +0000 UTC m=+29.833241909 End:2018-08-27 11:32:23.965446467 +0000 UTC m=+29.834753650
I0827 11:32:23.965492       1 scheduler.go:454] Total Schedule Algo cumulative time:1.600759839s for 725
I0827 11:32:23.967276       1 scheduler.go:451] ScheduleAlgoTime 1.681278ms Start:2018-08-27 11:32:23.965589869 +0000 UTC m=+29.834897105 End:2018-08-27 11:32:23.9672712 +0000 UTC m=+29.836578383
I0827 11:32:23.967301       1 scheduler.go:454] Total Schedule Algo cumulative time:1.602441117s for 726
I0827 11:32:23.969107       1 scheduler.go:451] ScheduleAlgoTime 1.672006ms Start:2018-08-27 11:32:23.967427893 +0000 UTC m=+29.836735151 End:2018-08-27 11:32:23.969099967 +0000 UTC m=+29.838407157
I0827 11:32:23.969140       1 scheduler.go:454] Total Schedule Algo cumulative time:1.604113123s for 727
I0827 11:32:23.971361       1 scheduler.go:451] ScheduleAlgoTime 2.067686ms Start:2018-08-27 11:32:23.969285964 +0000 UTC m=+29.838593193 End:2018-08-27 11:32:23.971353693 +0000 UTC m=+29.840660879
I0827 11:32:23.971394       1 scheduler.go:454] Total Schedule Algo cumulative time:1.606180809s for 728
I0827 11:32:23.973213       1 scheduler.go:451] ScheduleAlgoTime 1.681857ms Start:2018-08-27 11:32:23.97152463 +0000 UTC m=+29.840831879 End:2018-08-27 11:32:23.973206553 +0000 UTC m=+29.842513736
I0827 11:32:23.973235       1 scheduler.go:454] Total Schedule Algo cumulative time:1.607862666s for 729
I0827 11:32:23.974877       1 scheduler.go:451] ScheduleAlgoTime 1.515576ms Start:2018-08-27 11:32:23.973352552 +0000 UTC m=+29.842659800 End:2018-08-27 11:32:23.974868101 +0000 UTC m=+29.844175376
I0827 11:32:23.974928       1 scheduler.go:454] Total Schedule Algo cumulative time:1.609378242s for 730
I0827 11:32:23.976979       1 scheduler.go:451] ScheduleAlgoTime 1.881931ms Start:2018-08-27 11:32:23.975091859 +0000 UTC m=+29.844399083 End:2018-08-27 11:32:23.976973824 +0000 UTC m=+29.846281014
I0827 11:32:23.977005       1 scheduler.go:454] Total Schedule Algo cumulative time:1.611260173s for 731
I0827 11:32:23.978597       1 scheduler.go:451] ScheduleAlgoTime 1.409616ms Start:2018-08-27 11:32:23.977180291 +0000 UTC m=+29.846487537 End:2018-08-27 11:32:23.978589971 +0000 UTC m=+29.847897153
I0827 11:32:23.978627       1 scheduler.go:454] Total Schedule Algo cumulative time:1.612669789s for 732
I0827 11:32:23.980147       1 scheduler.go:451] ScheduleAlgoTime 1.363555ms Start:2018-08-27 11:32:23.978778583 +0000 UTC m=+29.848085813 End:2018-08-27 11:32:23.980142184 +0000 UTC m=+29.849449368
I0827 11:32:23.980171       1 scheduler.go:454] Total Schedule Algo cumulative time:1.614033344s for 733
I0827 11:32:23.981739       1 scheduler.go:451] ScheduleAlgoTime 1.422391ms Start:2018-08-27 11:32:23.980311053 +0000 UTC m=+29.849618257 End:2018-08-27 11:32:23.981733465 +0000 UTC m=+29.851040648
I0827 11:32:23.981766       1 scheduler.go:454] Total Schedule Algo cumulative time:1.615455735s for 734
I0827 11:32:23.983201       1 scheduler.go:451] ScheduleAlgoTime 1.317626ms Start:2018-08-27 11:32:23.981878856 +0000 UTC m=+29.851186110 End:2018-08-27 11:32:23.983196556 +0000 UTC m=+29.852503736
I0827 11:32:23.983224       1 scheduler.go:454] Total Schedule Algo cumulative time:1.616773361s for 735
I0827 11:32:23.984838       1 scheduler.go:451] ScheduleAlgoTime 1.502563ms Start:2018-08-27 11:32:23.983329841 +0000 UTC m=+29.852637046 End:2018-08-27 11:32:23.984832428 +0000 UTC m=+29.854139609
I0827 11:32:23.984864       1 scheduler.go:454] Total Schedule Algo cumulative time:1.618275924s for 736
I0827 11:32:23.986608       1 scheduler.go:451] ScheduleAlgoTime 1.624613ms Start:2018-08-27 11:32:23.984975447 +0000 UTC m=+29.854282648 End:2018-08-27 11:32:23.98660007 +0000 UTC m=+29.855907261
I0827 11:32:23.986637       1 scheduler.go:454] Total Schedule Algo cumulative time:1.619900537s for 737
I0827 11:32:23.988509       1 scheduler.go:451] ScheduleAlgoTime 1.703271ms Start:2018-08-27 11:32:23.986800404 +0000 UTC m=+29.856107650 End:2018-08-27 11:32:23.988503734 +0000 UTC m=+29.857810921
I0827 11:32:23.988534       1 scheduler.go:454] Total Schedule Algo cumulative time:1.621603808s for 738
I0827 11:32:23.990227       1 scheduler.go:451] ScheduleAlgoTime 1.576671ms Start:2018-08-27 11:32:23.988645106 +0000 UTC m=+29.857952325 End:2018-08-27 11:32:23.990221814 +0000 UTC m=+29.859528996
I0827 11:32:23.990249       1 scheduler.go:454] Total Schedule Algo cumulative time:1.623180479s for 739
I0827 11:32:23.991981       1 scheduler.go:451] ScheduleAlgoTime 1.591572ms Start:2018-08-27 11:32:23.990383479 +0000 UTC m=+29.859690677 End:2018-08-27 11:32:23.991975067 +0000 UTC m=+29.861282249
I0827 11:32:23.992007       1 scheduler.go:454] Total Schedule Algo cumulative time:1.624772051s for 740
I0827 11:32:23.993847       1 scheduler.go:451] ScheduleAlgoTime 1.697157ms Start:2018-08-27 11:32:23.992144254 +0000 UTC m=+29.861451529 End:2018-08-27 11:32:23.993841502 +0000 UTC m=+29.863148686
I0827 11:32:23.993870       1 scheduler.go:454] Total Schedule Algo cumulative time:1.626469208s for 741
I0827 11:32:23.995716       1 scheduler.go:451] ScheduleAlgoTime 1.72312ms Start:2018-08-27 11:32:23.993983087 +0000 UTC m=+29.863290284 End:2018-08-27 11:32:23.995706218 +0000 UTC m=+29.865013404
I0827 11:32:23.995753       1 scheduler.go:454] Total Schedule Algo cumulative time:1.628192328s for 742
I0827 11:32:23.997779       1 scheduler.go:451] ScheduleAlgoTime 1.864433ms Start:2018-08-27 11:32:23.995909717 +0000 UTC m=+29.865216914 End:2018-08-27 11:32:23.997774165 +0000 UTC m=+29.867081347
I0827 11:32:23.997840       1 scheduler.go:454] Total Schedule Algo cumulative time:1.630056761s for 743
I0827 11:32:23.999504       1 scheduler.go:451] ScheduleAlgoTime 1.438903ms Start:2018-08-27 11:32:23.99806037 +0000 UTC m=+29.867367583 End:2018-08-27 11:32:23.999499305 +0000 UTC m=+29.868806486
I0827 11:32:23.999526       1 scheduler.go:454] Total Schedule Algo cumulative time:1.631495664s for 744
I0827 11:32:24.001085       1 scheduler.go:451] ScheduleAlgoTime 1.456043ms Start:2018-08-27 11:32:23.999623913 +0000 UTC m=+29.868931152 End:2018-08-27 11:32:24.001080012 +0000 UTC m=+29.870387195
I0827 11:32:24.001107       1 scheduler.go:454] Total Schedule Algo cumulative time:1.632951707s for 745
I0827 11:32:24.003030       1 scheduler.go:451] ScheduleAlgoTime 1.820342ms Start:2018-08-27 11:32:24.001206103 +0000 UTC m=+29.870513314 End:2018-08-27 11:32:24.003026473 +0000 UTC m=+29.872333656
I0827 11:32:24.003052       1 scheduler.go:454] Total Schedule Algo cumulative time:1.634772049s for 746
I0827 11:32:24.004660       1 scheduler.go:451] ScheduleAlgoTime 1.494375ms Start:2018-08-27 11:32:24.003157814 +0000 UTC m=+29.872465062 End:2018-08-27 11:32:24.004652254 +0000 UTC m=+29.873959437
I0827 11:32:24.004720       1 scheduler.go:454] Total Schedule Algo cumulative time:1.636266424s for 747
I0827 11:32:24.006825       1 scheduler.go:451] ScheduleAlgoTime 1.959709ms Start:2018-08-27 11:32:24.004857253 +0000 UTC m=+29.874164502 End:2018-08-27 11:32:24.006817021 +0000 UTC m=+29.876124211
I0827 11:32:24.006858       1 scheduler.go:454] Total Schedule Algo cumulative time:1.638226133s for 748
I0827 11:32:24.008947       1 scheduler.go:451] ScheduleAlgoTime 1.924888ms Start:2018-08-27 11:32:24.007016952 +0000 UTC m=+29.876324157 End:2018-08-27 11:32:24.008941862 +0000 UTC m=+29.878249045
I0827 11:32:24.008968       1 scheduler.go:454] Total Schedule Algo cumulative time:1.640151021s for 749
I0827 11:32:24.010956       1 scheduler.go:451] ScheduleAlgoTime 1.704222ms Start:2018-08-27 11:32:24.009242579 +0000 UTC m=+29.878549814 End:2018-08-27 11:32:24.010946754 +0000 UTC m=+29.880254036
I0827 11:32:24.010991       1 scheduler.go:454] Total Schedule Algo cumulative time:1.641855243s for 750
I0827 11:32:24.013216       1 scheduler.go:451] ScheduleAlgoTime 1.996076ms Start:2018-08-27 11:32:24.011213991 +0000 UTC m=+29.880521244 End:2018-08-27 11:32:24.013210134 +0000 UTC m=+29.882517320
I0827 11:32:24.013242       1 scheduler.go:454] Total Schedule Algo cumulative time:1.643851319s for 751
I0827 11:32:24.015522       1 scheduler.go:451] ScheduleAlgoTime 2.152895ms Start:2018-08-27 11:32:24.013362634 +0000 UTC m=+29.882669832 End:2018-08-27 11:32:24.015515544 +0000 UTC m=+29.884822727
I0827 11:32:24.015565       1 scheduler.go:454] Total Schedule Algo cumulative time:1.646004214s for 752
I0827 11:32:24.017853       1 scheduler.go:451] ScheduleAlgoTime 2.136862ms Start:2018-08-27 11:32:24.015709448 +0000 UTC m=+29.885016684 End:2018-08-27 11:32:24.017846362 +0000 UTC m=+29.887153546
I0827 11:32:24.017879       1 scheduler.go:454] Total Schedule Algo cumulative time:1.648141076s for 753
I0827 11:32:24.019701       1 scheduler.go:451] ScheduleAlgoTime 1.71338ms Start:2018-08-27 11:32:24.017982707 +0000 UTC m=+29.887289945 End:2018-08-27 11:32:24.019696143 +0000 UTC m=+29.889003325
I0827 11:32:24.019723       1 scheduler.go:454] Total Schedule Algo cumulative time:1.649854456s for 754
I0827 11:32:24.021535       1 scheduler.go:451] ScheduleAlgoTime 1.678256ms Start:2018-08-27 11:32:24.019846963 +0000 UTC m=+29.889154227 End:2018-08-27 11:32:24.021525107 +0000 UTC m=+29.890832483
I0827 11:32:24.021577       1 scheduler.go:454] Total Schedule Algo cumulative time:1.651532712s for 755
I0827 11:32:24.023763       1 scheduler.go:451] ScheduleAlgoTime 1.971452ms Start:2018-08-27 11:32:24.021785626 +0000 UTC m=+29.891092832 End:2018-08-27 11:32:24.023757103 +0000 UTC m=+29.893064284
I0827 11:32:24.023791       1 scheduler.go:454] Total Schedule Algo cumulative time:1.653504164s for 756
I0827 11:32:24.025823       1 scheduler.go:451] ScheduleAlgoTime 1.888509ms Start:2018-08-27 11:32:24.023928504 +0000 UTC m=+29.893235746 End:2018-08-27 11:32:24.025817073 +0000 UTC m=+29.895124255
I0827 11:32:24.025858       1 scheduler.go:454] Total Schedule Algo cumulative time:1.655392673s for 757
I0827 11:32:24.027711       1 scheduler.go:451] ScheduleAlgoTime 1.606479ms Start:2018-08-27 11:32:24.026099008 +0000 UTC m=+29.895406270 End:2018-08-27 11:32:24.027705566 +0000 UTC m=+29.897012749
I0827 11:32:24.027735       1 scheduler.go:454] Total Schedule Algo cumulative time:1.656999152s for 758
I0827 11:32:24.029291       1 scheduler.go:451] ScheduleAlgoTime 1.451044ms Start:2018-08-27 11:32:24.027835177 +0000 UTC m=+29.897142376 End:2018-08-27 11:32:24.029286235 +0000 UTC m=+29.898593420
I0827 11:32:24.029314       1 scheduler.go:454] Total Schedule Algo cumulative time:1.658450196s for 759
I0827 11:32:24.035385       1 scheduler.go:451] ScheduleAlgoTime 5.932961ms Start:2018-08-27 11:32:24.029440957 +0000 UTC m=+29.898748217 End:2018-08-27 11:32:24.035373994 +0000 UTC m=+29.904681178
I0827 11:32:24.035427       1 scheduler.go:454] Total Schedule Algo cumulative time:1.664383157s for 760
I0827 11:32:24.038044       1 scheduler.go:451] ScheduleAlgoTime 2.459152ms Start:2018-08-27 11:32:24.035576756 +0000 UTC m=+29.904884008 End:2018-08-27 11:32:24.038035975 +0000 UTC m=+29.907343160
I0827 11:32:24.038122       1 scheduler.go:454] Total Schedule Algo cumulative time:1.666842309s for 761
I0827 11:32:24.040087       1 scheduler.go:451] ScheduleAlgoTime 1.795432ms Start:2018-08-27 11:32:24.038280307 +0000 UTC m=+29.907587574 End:2018-08-27 11:32:24.04007582 +0000 UTC m=+29.909383006
I0827 11:32:24.040114       1 scheduler.go:454] Total Schedule Algo cumulative time:1.668637741s for 762
I0827 11:32:24.041830       1 scheduler.go:451] ScheduleAlgoTime 1.59455ms Start:2018-08-27 11:32:24.040227864 +0000 UTC m=+29.909535115 End:2018-08-27 11:32:24.041822479 +0000 UTC m=+29.911129665
I0827 11:32:24.041906       1 scheduler.go:454] Total Schedule Algo cumulative time:1.670232291s for 763
I0827 11:32:24.044052       1 scheduler.go:451] ScheduleAlgoTime 1.915676ms Start:2018-08-27 11:32:24.04212994 +0000 UTC m=+29.911437140 End:2018-08-27 11:32:24.044045635 +0000 UTC m=+29.913352816
I0827 11:32:24.044079       1 scheduler.go:454] Total Schedule Algo cumulative time:1.672147967s for 764
I0827 11:32:24.045789       1 scheduler.go:451] ScheduleAlgoTime 1.56122ms Start:2018-08-27 11:32:24.044221816 +0000 UTC m=+29.913529046 End:2018-08-27 11:32:24.045783083 +0000 UTC m=+29.915090266
I0827 11:32:24.045812       1 scheduler.go:454] Total Schedule Algo cumulative time:1.673709187s for 765
I0827 11:32:24.047560       1 scheduler.go:451] ScheduleAlgoTime 1.607045ms Start:2018-08-27 11:32:24.045948075 +0000 UTC m=+29.915255334 End:2018-08-27 11:32:24.047555196 +0000 UTC m=+29.916862379
I0827 11:32:24.047595       1 scheduler.go:454] Total Schedule Algo cumulative time:1.675316232s for 766
I0827 11:32:24.049674       1 scheduler.go:451] ScheduleAlgoTime 1.909085ms Start:2018-08-27 11:32:24.047758872 +0000 UTC m=+29.917066087 End:2018-08-27 11:32:24.049667987 +0000 UTC m=+29.918975172
I0827 11:32:24.049719       1 scheduler.go:454] Total Schedule Algo cumulative time:1.677225317s for 767
I0827 11:32:24.051655       1 scheduler.go:451] ScheduleAlgoTime 1.766322ms Start:2018-08-27 11:32:24.049861443 +0000 UTC m=+29.919168699 End:2018-08-27 11:32:24.051627839 +0000 UTC m=+29.920935021
I0827 11:32:24.051688       1 scheduler.go:454] Total Schedule Algo cumulative time:1.678991639s for 768
I0827 11:32:24.053620       1 scheduler.go:451] ScheduleAlgoTime 1.772728ms Start:2018-08-27 11:32:24.051841338 +0000 UTC m=+29.921148549 End:2018-08-27 11:32:24.053614097 +0000 UTC m=+29.922921277
I0827 11:32:24.053652       1 scheduler.go:454] Total Schedule Algo cumulative time:1.680764367s for 769
I0827 11:32:24.055209       1 scheduler.go:451] ScheduleAlgoTime 1.437679ms Start:2018-08-27 11:32:24.053763804 +0000 UTC m=+29.923070987 End:2018-08-27 11:32:24.055201483 +0000 UTC m=+29.924508666
I0827 11:32:24.055240       1 scheduler.go:454] Total Schedule Algo cumulative time:1.682202046s for 770
I0827 11:32:24.057030       1 scheduler.go:451] ScheduleAlgoTime 1.63953ms Start:2018-08-27 11:32:24.055385533 +0000 UTC m=+29.924692759 End:2018-08-27 11:32:24.057025107 +0000 UTC m=+29.926332289
I0827 11:32:24.057056       1 scheduler.go:454] Total Schedule Algo cumulative time:1.683841576s for 771
I0827 11:32:24.058803       1 scheduler.go:451] ScheduleAlgoTime 1.607075ms Start:2018-08-27 11:32:24.057190764 +0000 UTC m=+29.926498024 End:2018-08-27 11:32:24.058797915 +0000 UTC m=+29.928105099
I0827 11:32:24.058832       1 scheduler.go:454] Total Schedule Algo cumulative time:1.685448651s for 772
I0827 11:32:24.060517       1 scheduler.go:451] ScheduleAlgoTime 1.572074ms Start:2018-08-27 11:32:24.058938243 +0000 UTC m=+29.928245429 End:2018-08-27 11:32:24.060510315 +0000 UTC m=+29.929817503
I0827 11:32:24.060553       1 scheduler.go:454] Total Schedule Algo cumulative time:1.687020725s for 773
I0827 11:32:24.062206       1 scheduler.go:451] ScheduleAlgoTime 1.498671ms Start:2018-08-27 11:32:24.060702884 +0000 UTC m=+29.930010147 End:2018-08-27 11:32:24.062201633 +0000 UTC m=+29.931508818
I0827 11:32:24.062233       1 scheduler.go:454] Total Schedule Algo cumulative time:1.688519396s for 774
I0827 11:32:24.064063       1 scheduler.go:451] ScheduleAlgoTime 1.686247ms Start:2018-08-27 11:32:24.062371681 +0000 UTC m=+29.931678917 End:2018-08-27 11:32:24.064057981 +0000 UTC m=+29.933365164
I0827 11:32:24.064087       1 scheduler.go:454] Total Schedule Algo cumulative time:1.690205643s for 775
I0827 11:32:24.066193       1 scheduler.go:451] ScheduleAlgoTime 1.944545ms Start:2018-08-27 11:32:24.064240394 +0000 UTC m=+29.933547600 End:2018-08-27 11:32:24.066184959 +0000 UTC m=+29.935492145
I0827 11:32:24.066222       1 scheduler.go:454] Total Schedule Algo cumulative time:1.692150188s for 776
I0827 11:32:24.068504       1 scheduler.go:451] ScheduleAlgoTime 2.139805ms Start:2018-08-27 11:32:24.066355153 +0000 UTC m=+29.935662386 End:2018-08-27 11:32:24.068495008 +0000 UTC m=+29.937802191
I0827 11:32:24.068547       1 scheduler.go:454] Total Schedule Algo cumulative time:1.694289993s for 777
I0827 11:32:24.070297       1 scheduler.go:451] ScheduleAlgoTime 1.60006ms Start:2018-08-27 11:32:24.068689712 +0000 UTC m=+29.937996929 End:2018-08-27 11:32:24.070289798 +0000 UTC m=+29.939596989
I0827 11:32:24.070327       1 scheduler.go:454] Total Schedule Algo cumulative time:1.695890053s for 778
I0827 11:32:24.072231       1 scheduler.go:451] ScheduleAlgoTime 1.78586ms Start:2018-08-27 11:32:24.070439199 +0000 UTC m=+29.939746400 End:2018-08-27 11:32:24.072225075 +0000 UTC m=+29.941532260
I0827 11:32:24.072256       1 scheduler.go:454] Total Schedule Algo cumulative time:1.697675913s for 779
I0827 11:32:24.074399       1 scheduler.go:451] ScheduleAlgoTime 2.012076ms Start:2018-08-27 11:32:24.072381376 +0000 UTC m=+29.941688619 End:2018-08-27 11:32:24.074393513 +0000 UTC m=+29.943700695
I0827 11:32:24.074424       1 scheduler.go:454] Total Schedule Algo cumulative time:1.699687989s for 780
I0827 11:32:24.076228       1 scheduler.go:451] ScheduleAlgoTime 1.648037ms Start:2018-08-27 11:32:24.074575463 +0000 UTC m=+29.943882691 End:2018-08-27 11:32:24.07622354 +0000 UTC m=+29.945530728
I0827 11:32:24.076251       1 scheduler.go:454] Total Schedule Algo cumulative time:1.701336026s for 781
I0827 11:32:24.078061       1 scheduler.go:451] ScheduleAlgoTime 1.682445ms Start:2018-08-27 11:32:24.076373721 +0000 UTC m=+29.945680926 End:2018-08-27 11:32:24.078056188 +0000 UTC m=+29.947363371
I0827 11:32:24.078082       1 scheduler.go:454] Total Schedule Algo cumulative time:1.703018471s for 782
I0827 11:32:24.079898       1 scheduler.go:451] ScheduleAlgoTime 1.680538ms Start:2018-08-27 11:32:24.078212708 +0000 UTC m=+29.947519983 End:2018-08-27 11:32:24.079893331 +0000 UTC m=+29.949200521
I0827 11:32:24.079926       1 scheduler.go:454] Total Schedule Algo cumulative time:1.704699009s for 783
I0827 11:32:24.081788       1 scheduler.go:451] ScheduleAlgoTime 1.669217ms Start:2018-08-27 11:32:24.080110064 +0000 UTC m=+29.949417297 End:2018-08-27 11:32:24.081779331 +0000 UTC m=+29.951086514
I0827 11:32:24.081826       1 scheduler.go:454] Total Schedule Algo cumulative time:1.706368226s for 784
I0827 11:32:24.084070       1 scheduler.go:451] ScheduleAlgoTime 2.066239ms Start:2018-08-27 11:32:24.081992465 +0000 UTC m=+29.951299680 End:2018-08-27 11:32:24.084058736 +0000 UTC m=+29.953365919
I0827 11:32:24.084098       1 scheduler.go:454] Total Schedule Algo cumulative time:1.708434465s for 785
I0827 11:32:24.086251       1 scheduler.go:451] ScheduleAlgoTime 1.966859ms Start:2018-08-27 11:32:24.084276784 +0000 UTC m=+29.953584014 End:2018-08-27 11:32:24.086243689 +0000 UTC m=+29.955550873
I0827 11:32:24.086277       1 scheduler.go:454] Total Schedule Algo cumulative time:1.710401324s for 786
I0827 11:32:24.088093       1 scheduler.go:451] ScheduleAlgoTime 1.732654ms Start:2018-08-27 11:32:24.086354272 +0000 UTC m=+29.955661504 End:2018-08-27 11:32:24.088086976 +0000 UTC m=+29.957394158
I0827 11:32:24.088118       1 scheduler.go:454] Total Schedule Algo cumulative time:1.712133978s for 787
I0827 11:32:24.089953       1 scheduler.go:451] ScheduleAlgoTime 1.646384ms Start:2018-08-27 11:32:24.088298779 +0000 UTC m=+29.957606006 End:2018-08-27 11:32:24.089945208 +0000 UTC m=+29.959252390
I0827 11:32:24.089978       1 scheduler.go:454] Total Schedule Algo cumulative time:1.713780362s for 788
I0827 11:32:24.091848       1 scheduler.go:451] ScheduleAlgoTime 1.705339ms Start:2018-08-27 11:32:24.090136013 +0000 UTC m=+29.959443218 End:2018-08-27 11:32:24.091841375 +0000 UTC m=+29.961148557
I0827 11:32:24.091872       1 scheduler.go:454] Total Schedule Algo cumulative time:1.715485701s for 789
I0827 11:32:24.093754       1 scheduler.go:451] ScheduleAlgoTime 1.728547ms Start:2018-08-27 11:32:24.092020302 +0000 UTC m=+29.961327492 End:2018-08-27 11:32:24.093748856 +0000 UTC m=+29.963056039
I0827 11:32:24.093800       1 scheduler.go:454] Total Schedule Algo cumulative time:1.717214248s for 790
I0827 11:32:24.095509       1 scheduler.go:451] ScheduleAlgoTime 1.563096ms Start:2018-08-27 11:32:24.093940404 +0000 UTC m=+29.963247608 End:2018-08-27 11:32:24.095503518 +0000 UTC m=+29.964810704
I0827 11:32:24.095535       1 scheduler.go:454] Total Schedule Algo cumulative time:1.718777344s for 791
I0827 11:32:24.097417       1 scheduler.go:451] ScheduleAlgoTime 1.741968ms Start:2018-08-27 11:32:24.09566797 +0000 UTC m=+29.964975229 End:2018-08-27 11:32:24.097410015 +0000 UTC m=+29.966717197
I0827 11:32:24.097443       1 scheduler.go:454] Total Schedule Algo cumulative time:1.720519312s for 792
I0827 11:32:24.099084       1 scheduler.go:451] ScheduleAlgoTime 1.517537ms Start:2018-08-27 11:32:24.097558047 +0000 UTC m=+29.966865228 End:2018-08-27 11:32:24.099075554 +0000 UTC m=+29.968382765
I0827 11:32:24.099114       1 scheduler.go:454] Total Schedule Algo cumulative time:1.722036849s for 793
I0827 11:32:24.101292       1 scheduler.go:451] ScheduleAlgoTime 2.021643ms Start:2018-08-27 11:32:24.099265635 +0000 UTC m=+29.968572893 End:2018-08-27 11:32:24.101287355 +0000 UTC m=+29.970594536
I0827 11:32:24.101317       1 scheduler.go:454] Total Schedule Algo cumulative time:1.724058492s for 794
I0827 11:32:24.103195       1 scheduler.go:451] ScheduleAlgoTime 1.759357ms Start:2018-08-27 11:32:24.101428122 +0000 UTC m=+29.970735359 End:2018-08-27 11:32:24.103187532 +0000 UTC m=+29.972494716
I0827 11:32:24.103223       1 scheduler.go:454] Total Schedule Algo cumulative time:1.725817849s for 795
I0827 11:32:24.105109       1 scheduler.go:451] ScheduleAlgoTime 1.751227ms Start:2018-08-27 11:32:24.103349521 +0000 UTC m=+29.972656793 End:2018-08-27 11:32:24.105100825 +0000 UTC m=+29.974408020
I0827 11:32:24.105139       1 scheduler.go:454] Total Schedule Algo cumulative time:1.727569076s for 796
I0827 11:32:24.106902       1 scheduler.go:451] ScheduleAlgoTime 1.601699ms Start:2018-08-27 11:32:24.105293209 +0000 UTC m=+29.974600431 End:2018-08-27 11:32:24.106894945 +0000 UTC m=+29.976202130
I0827 11:32:24.106934       1 scheduler.go:454] Total Schedule Algo cumulative time:1.729170775s for 797
I0827 11:32:24.109146       1 scheduler.go:451] ScheduleAlgoTime 2.093078ms Start:2018-08-27 11:32:24.107046677 +0000 UTC m=+29.976353899 End:2018-08-27 11:32:24.109139795 +0000 UTC m=+29.978446977
I0827 11:32:24.109173       1 scheduler.go:454] Total Schedule Algo cumulative time:1.731263853s for 798
I0827 11:32:24.110952       1 scheduler.go:451] ScheduleAlgoTime 1.624184ms Start:2018-08-27 11:32:24.109318915 +0000 UTC m=+29.978626097 End:2018-08-27 11:32:24.110943096 +0000 UTC m=+29.980250281
I0827 11:32:24.110981       1 scheduler.go:454] Total Schedule Algo cumulative time:1.732888037s for 799
I0827 11:32:24.112945       1 scheduler.go:451] ScheduleAlgoTime 1.69001ms Start:2018-08-27 11:32:24.111247676 +0000 UTC m=+29.980554927 End:2018-08-27 11:32:24.112937752 +0000 UTC m=+29.982244937
I0827 11:32:24.112970       1 scheduler.go:454] Total Schedule Algo cumulative time:1.734578047s for 800
I0827 11:32:24.116977       1 scheduler.go:451] ScheduleAlgoTime 3.850496ms Start:2018-08-27 11:32:24.113088723 +0000 UTC m=+29.982395935 End:2018-08-27 11:32:24.116939248 +0000 UTC m=+29.986246431
I0827 11:32:24.117033       1 scheduler.go:454] Total Schedule Algo cumulative time:1.738428543s for 801
I0827 11:32:24.122278       1 scheduler.go:451] ScheduleAlgoTime 4.936682ms Start:2018-08-27 11:32:24.117333559 +0000 UTC m=+29.986640810 End:2018-08-27 11:32:24.12227031 +0000 UTC m=+29.991577492
I0827 11:32:24.122313       1 scheduler.go:454] Total Schedule Algo cumulative time:1.743365225s for 802
I0827 11:32:24.124090       1 scheduler.go:451] ScheduleAlgoTime 1.526452ms Start:2018-08-27 11:32:24.122556005 +0000 UTC m=+29.991863233 End:2018-08-27 11:32:24.124082501 +0000 UTC m=+29.993389685
I0827 11:32:24.124122       1 scheduler.go:454] Total Schedule Algo cumulative time:1.744891677s for 803
I0827 11:32:24.125958       1 scheduler.go:451] ScheduleAlgoTime 1.69202ms Start:2018-08-27 11:32:24.124259573 +0000 UTC m=+29.993566804 End:2018-08-27 11:32:24.125951644 +0000 UTC m=+29.995258824
I0827 11:32:24.125987       1 scheduler.go:454] Total Schedule Algo cumulative time:1.746583697s for 804
I0827 11:32:24.127880       1 scheduler.go:451] ScheduleAlgoTime 1.742438ms Start:2018-08-27 11:32:24.126130636 +0000 UTC m=+29.995437879 End:2018-08-27 11:32:24.127873126 +0000 UTC m=+29.997180317
I0827 11:32:24.127923       1 scheduler.go:454] Total Schedule Algo cumulative time:1.748326135s for 805
I0827 11:32:24.129783       1 scheduler.go:451] ScheduleAlgoTime 1.693831ms Start:2018-08-27 11:32:24.128081668 +0000 UTC m=+29.997388925 End:2018-08-27 11:32:24.129775574 +0000 UTC m=+29.999082756
I0827 11:32:24.129810       1 scheduler.go:454] Total Schedule Algo cumulative time:1.750019966s for 806
I0827 11:32:24.131540       1 scheduler.go:451] ScheduleAlgoTime 1.59455ms Start:2018-08-27 11:32:24.129940608 +0000 UTC m=+29.999247835 End:2018-08-27 11:32:24.131535202 +0000 UTC m=+30.000842385
I0827 11:32:24.131576       1 scheduler.go:454] Total Schedule Algo cumulative time:1.751614516s for 807
I0827 11:32:24.133315       1 scheduler.go:451] ScheduleAlgoTime 1.604579ms Start:2018-08-27 11:32:24.131705558 +0000 UTC m=+30.001012793 End:2018-08-27 11:32:24.133310179 +0000 UTC m=+30.002617372
I0827 11:32:24.133339       1 scheduler.go:454] Total Schedule Algo cumulative time:1.753219095s for 808
I0827 11:32:24.136630       1 scheduler.go:451] ScheduleAlgoTime 3.106729ms Start:2018-08-27 11:32:24.133515644 +0000 UTC m=+30.002822889 End:2018-08-27 11:32:24.136622428 +0000 UTC m=+30.005929618
I0827 11:32:24.136663       1 scheduler.go:454] Total Schedule Algo cumulative time:1.756325824s for 809
I0827 11:32:24.138727       1 scheduler.go:451] ScheduleAlgoTime 1.974564ms Start:2018-08-27 11:32:24.136745875 +0000 UTC m=+30.006053079 End:2018-08-27 11:32:24.138720458 +0000 UTC m=+30.008027643
I0827 11:32:24.138755       1 scheduler.go:454] Total Schedule Algo cumulative time:1.758300388s for 810
I0827 11:32:24.140709       1 scheduler.go:451] ScheduleAlgoTime 1.817365ms Start:2018-08-27 11:32:24.138883304 +0000 UTC m=+30.008190567 End:2018-08-27 11:32:24.140700749 +0000 UTC m=+30.010007932
I0827 11:32:24.140752       1 scheduler.go:454] Total Schedule Algo cumulative time:1.760117753s for 811
I0827 11:32:24.142704       1 scheduler.go:451] ScheduleAlgoTime 1.770032ms Start:2018-08-27 11:32:24.140927848 +0000 UTC m=+30.010235044 End:2018-08-27 11:32:24.142697893 +0000 UTC m=+30.012005076
I0827 11:32:24.142731       1 scheduler.go:454] Total Schedule Algo cumulative time:1.761887785s for 812
I0827 11:32:24.144793       1 scheduler.go:451] ScheduleAlgoTime 1.878803ms Start:2018-08-27 11:32:24.142907717 +0000 UTC m=+30.012214969 End:2018-08-27 11:32:24.144786588 +0000 UTC m=+30.014093772
I0827 11:32:24.144821       1 scheduler.go:454] Total Schedule Algo cumulative time:1.763766588s for 813
I0827 11:32:24.146604       1 scheduler.go:451] ScheduleAlgoTime 1.639042ms Start:2018-08-27 11:32:24.14495902 +0000 UTC m=+30.014266225 End:2018-08-27 11:32:24.146598081 +0000 UTC m=+30.015905267
I0827 11:32:24.146629       1 scheduler.go:454] Total Schedule Algo cumulative time:1.76540563s for 814
I0827 11:32:24.148377       1 scheduler.go:451] ScheduleAlgoTime 1.601518ms Start:2018-08-27 11:32:24.146770204 +0000 UTC m=+30.016077452 End:2018-08-27 11:32:24.148371787 +0000 UTC m=+30.017678970
I0827 11:32:24.148401       1 scheduler.go:454] Total Schedule Algo cumulative time:1.767007148s for 815
I0827 11:32:24.150171       1 scheduler.go:451] ScheduleAlgoTime 1.587782ms Start:2018-08-27 11:32:24.148576905 +0000 UTC m=+30.017884125 End:2018-08-27 11:32:24.150164721 +0000 UTC m=+30.019471907
I0827 11:32:24.150199       1 scheduler.go:454] Total Schedule Algo cumulative time:1.76859493s for 816
I0827 11:32:24.152179       1 scheduler.go:451] ScheduleAlgoTime 1.879787ms Start:2018-08-27 11:32:24.150290142 +0000 UTC m=+30.019597342 End:2018-08-27 11:32:24.15216994 +0000 UTC m=+30.021477129
I0827 11:32:24.152216       1 scheduler.go:454] Total Schedule Algo cumulative time:1.770474717s for 817
I0827 11:32:24.154139       1 scheduler.go:451] ScheduleAlgoTime 1.757034ms Start:2018-08-27 11:32:24.152376089 +0000 UTC m=+30.021683373 End:2018-08-27 11:32:24.154133222 +0000 UTC m=+30.023440407
I0827 11:32:24.154163       1 scheduler.go:454] Total Schedule Algo cumulative time:1.772231751s for 818
I0827 11:32:24.155803       1 scheduler.go:451] ScheduleAlgoTime 1.503171ms Start:2018-08-27 11:32:24.154295205 +0000 UTC m=+30.023602438 End:2018-08-27 11:32:24.155798427 +0000 UTC m=+30.025105609
I0827 11:32:24.155827       1 scheduler.go:454] Total Schedule Algo cumulative time:1.773734922s for 819
I0827 11:32:24.157776       1 scheduler.go:451] ScheduleAlgoTime 1.796159ms Start:2018-08-27 11:32:24.155974457 +0000 UTC m=+30.025281721 End:2018-08-27 11:32:24.157770699 +0000 UTC m=+30.027077880
I0827 11:32:24.157800       1 scheduler.go:454] Total Schedule Algo cumulative time:1.775531081s for 820
I0827 11:32:24.159834       1 scheduler.go:451] ScheduleAlgoTime 1.895594ms Start:2018-08-27 11:32:24.157933159 +0000 UTC m=+30.027240411 End:2018-08-27 11:32:24.159828821 +0000 UTC m=+30.029136005
I0827 11:32:24.159870       1 scheduler.go:454] Total Schedule Algo cumulative time:1.777426675s for 821
I0827 11:32:24.161570       1 scheduler.go:451] ScheduleAlgoTime 1.563878ms Start:2018-08-27 11:32:24.159998964 +0000 UTC m=+30.029306226 End:2018-08-27 11:32:24.161562886 +0000 UTC m=+30.030870104
I0827 11:32:24.161596       1 scheduler.go:454] Total Schedule Algo cumulative time:1.778990553s for 822
I0827 11:32:24.163548       1 scheduler.go:451] ScheduleAlgoTime 1.826599ms Start:2018-08-27 11:32:24.161714069 +0000 UTC m=+30.031021313 End:2018-08-27 11:32:24.163540711 +0000 UTC m=+30.032847912
I0827 11:32:24.163572       1 scheduler.go:454] Total Schedule Algo cumulative time:1.780817152s for 823
I0827 11:32:24.165470       1 scheduler.go:451] ScheduleAlgoTime 1.741231ms Start:2018-08-27 11:32:24.163723881 +0000 UTC m=+30.033031086 End:2018-08-27 11:32:24.165465135 +0000 UTC m=+30.034772317
I0827 11:32:24.165497       1 scheduler.go:454] Total Schedule Algo cumulative time:1.782558383s for 824
I0827 11:32:24.167286       1 scheduler.go:451] ScheduleAlgoTime 1.645692ms Start:2018-08-27 11:32:24.165632497 +0000 UTC m=+30.034939737 End:2018-08-27 11:32:24.167278247 +0000 UTC m=+30.036585429
I0827 11:32:24.167315       1 scheduler.go:454] Total Schedule Algo cumulative time:1.784204075s for 825
I0827 11:32:24.169396       1 scheduler.go:451] ScheduleAlgoTime 1.964169ms Start:2018-08-27 11:32:24.167426927 +0000 UTC m=+30.036734174 End:2018-08-27 11:32:24.169391158 +0000 UTC m=+30.038698343
I0827 11:32:24.169422       1 scheduler.go:454] Total Schedule Algo cumulative time:1.786168244s for 826
I0827 11:32:24.171250       1 scheduler.go:451] ScheduleAlgoTime 1.666411ms Start:2018-08-27 11:32:24.169577055 +0000 UTC m=+30.038884291 End:2018-08-27 11:32:24.171243518 +0000 UTC m=+30.040550702
I0827 11:32:24.171278       1 scheduler.go:454] Total Schedule Algo cumulative time:1.787834655s for 827
I0827 11:32:24.172948       1 scheduler.go:451] ScheduleAlgoTime 1.545763ms Start:2018-08-27 11:32:24.171397195 +0000 UTC m=+30.040704436 End:2018-08-27 11:32:24.172943016 +0000 UTC m=+30.042250199
I0827 11:32:24.172997       1 scheduler.go:454] Total Schedule Algo cumulative time:1.789380418s for 828
I0827 11:32:24.174740       1 scheduler.go:451] ScheduleAlgoTime 1.622319ms Start:2018-08-27 11:32:24.173112367 +0000 UTC m=+30.042419550 End:2018-08-27 11:32:24.174734686 +0000 UTC m=+30.044041869
I0827 11:32:24.174763       1 scheduler.go:454] Total Schedule Algo cumulative time:1.791002737s for 829
I0827 11:32:24.177147       1 scheduler.go:451] ScheduleAlgoTime 2.226265ms Start:2018-08-27 11:32:24.174915666 +0000 UTC m=+30.044222915 End:2018-08-27 11:32:24.177141998 +0000 UTC m=+30.046449180
I0827 11:32:24.177172       1 scheduler.go:454] Total Schedule Algo cumulative time:1.793229002s for 830
I0827 11:32:24.179244       1 scheduler.go:451] ScheduleAlgoTime 1.952907ms Start:2018-08-27 11:32:24.177285473 +0000 UTC m=+30.046592721 End:2018-08-27 11:32:24.179238446 +0000 UTC m=+30.048545628
I0827 11:32:24.179268       1 scheduler.go:454] Total Schedule Algo cumulative time:1.795181909s for 831
I0827 11:32:24.181155       1 scheduler.go:451] ScheduleAlgoTime 1.679819ms Start:2018-08-27 11:32:24.179425788 +0000 UTC m=+30.048733045 End:2018-08-27 11:32:24.181105675 +0000 UTC m=+30.050412864
I0827 11:32:24.181178       1 scheduler.go:454] Total Schedule Algo cumulative time:1.796861728s for 832
I0827 11:32:24.182783       1 scheduler.go:451] ScheduleAlgoTime 1.481999ms Start:2018-08-27 11:32:24.181294547 +0000 UTC m=+30.050601763 End:2018-08-27 11:32:24.18277658 +0000 UTC m=+30.052083762
I0827 11:32:24.182813       1 scheduler.go:454] Total Schedule Algo cumulative time:1.798343727s for 833
I0827 11:32:24.184713       1 scheduler.go:451] ScheduleAlgoTime 1.713684ms Start:2018-08-27 11:32:24.182990641 +0000 UTC m=+30.052297861 End:2018-08-27 11:32:24.184704358 +0000 UTC m=+30.054011545
I0827 11:32:24.184769       1 scheduler.go:454] Total Schedule Algo cumulative time:1.800057411s for 834
I0827 11:32:24.187051       1 scheduler.go:451] ScheduleAlgoTime 2.120051ms Start:2018-08-27 11:32:24.18492524 +0000 UTC m=+30.054232636 End:2018-08-27 11:32:24.187045504 +0000 UTC m=+30.056352687
I0827 11:32:24.187076       1 scheduler.go:454] Total Schedule Algo cumulative time:1.802177462s for 835
I0827 11:32:24.189179       1 scheduler.go:451] ScheduleAlgoTime 1.859068ms Start:2018-08-27 11:32:24.187312027 +0000 UTC m=+30.056619291 End:2018-08-27 11:32:24.189171173 +0000 UTC m=+30.058478359
I0827 11:32:24.189210       1 scheduler.go:454] Total Schedule Algo cumulative time:1.80403653s for 836
I0827 11:32:24.191034       1 scheduler.go:451] ScheduleAlgoTime 1.548166ms Start:2018-08-27 11:32:24.189420728 +0000 UTC m=+30.058727913 End:2018-08-27 11:32:24.190968893 +0000 UTC m=+30.060276079
I0827 11:32:24.191059       1 scheduler.go:454] Total Schedule Algo cumulative time:1.805584696s for 837
I0827 11:32:24.192617       1 scheduler.go:451] ScheduleAlgoTime 1.373181ms Start:2018-08-27 11:32:24.191235523 +0000 UTC m=+30.060542776 End:2018-08-27 11:32:24.192608775 +0000 UTC m=+30.061915957
I0827 11:32:24.192656       1 scheduler.go:454] Total Schedule Algo cumulative time:1.806957877s for 838
I0827 11:32:24.194396       1 scheduler.go:451] ScheduleAlgoTime 1.599695ms Start:2018-08-27 11:32:24.192787849 +0000 UTC m=+30.062095091 End:2018-08-27 11:32:24.19438759 +0000 UTC m=+30.063694786
I0827 11:32:24.194428       1 scheduler.go:454] Total Schedule Algo cumulative time:1.808557572s for 839
I0827 11:32:24.196322       1 scheduler.go:451] ScheduleAlgoTime 1.760904ms Start:2018-08-27 11:32:24.194555659 +0000 UTC m=+30.063862864 End:2018-08-27 11:32:24.196316586 +0000 UTC m=+30.065623768
I0827 11:32:24.196357       1 scheduler.go:454] Total Schedule Algo cumulative time:1.810318476s for 840
I0827 11:32:24.205102       1 scheduler.go:451] ScheduleAlgoTime 8.417226ms Start:2018-08-27 11:32:24.196675682 +0000 UTC m=+30.065982896 End:2018-08-27 11:32:24.205092936 +0000 UTC m=+30.074400122
I0827 11:32:24.205131       1 scheduler.go:454] Total Schedule Algo cumulative time:1.818735702s for 841
I0827 11:32:24.207713       1 scheduler.go:451] ScheduleAlgoTime 2.243731ms Start:2018-08-27 11:32:24.205375119 +0000 UTC m=+30.074682359 End:2018-08-27 11:32:24.207618901 +0000 UTC m=+30.076926090
I0827 11:32:24.207761       1 scheduler.go:454] Total Schedule Algo cumulative time:1.820979433s for 842
I0827 11:32:24.209867       1 scheduler.go:451] ScheduleAlgoTime 1.950801ms Start:2018-08-27 11:32:24.207907991 +0000 UTC m=+30.077215240 End:2018-08-27 11:32:24.209858855 +0000 UTC m=+30.079166041
I0827 11:32:24.209899       1 scheduler.go:454] Total Schedule Algo cumulative time:1.822930234s for 843
I0827 11:32:24.211795       1 scheduler.go:451] ScheduleAlgoTime 1.79062ms Start:2018-08-27 11:32:24.209996797 +0000 UTC m=+30.079304070 End:2018-08-27 11:32:24.211787504 +0000 UTC m=+30.081094690
I0827 11:32:24.211835       1 scheduler.go:454] Total Schedule Algo cumulative time:1.824720854s for 844
I0827 11:32:24.213446       1 scheduler.go:451] ScheduleAlgoTime 1.472847ms Start:2018-08-27 11:32:24.211966538 +0000 UTC m=+30.081273742 End:2018-08-27 11:32:24.213439408 +0000 UTC m=+30.082746589
I0827 11:32:24.213471       1 scheduler.go:454] Total Schedule Algo cumulative time:1.826193701s for 845
I0827 11:32:24.215486       1 scheduler.go:451] ScheduleAlgoTime 1.906279ms Start:2018-08-27 11:32:24.213574675 +0000 UTC m=+30.082881905 End:2018-08-27 11:32:24.215481002 +0000 UTC m=+30.084788184
I0827 11:32:24.215509       1 scheduler.go:454] Total Schedule Algo cumulative time:1.82809998s for 846
I0827 11:32:24.217164       1 scheduler.go:451] ScheduleAlgoTime 1.504918ms Start:2018-08-27 11:32:24.215654084 +0000 UTC m=+30.084961331 End:2018-08-27 11:32:24.217159063 +0000 UTC m=+30.086466249
I0827 11:32:24.217186       1 scheduler.go:454] Total Schedule Algo cumulative time:1.829604898s for 847
I0827 11:32:24.218739       1 scheduler.go:451] ScheduleAlgoTime 1.436448ms Start:2018-08-27 11:32:24.2172954 +0000 UTC m=+30.086602636 End:2018-08-27 11:32:24.218731902 +0000 UTC m=+30.088039084
I0827 11:32:24.218770       1 scheduler.go:454] Total Schedule Algo cumulative time:1.831041346s for 848
I0827 11:32:24.220426       1 scheduler.go:451] ScheduleAlgoTime 1.501438ms Start:2018-08-27 11:32:24.218919718 +0000 UTC m=+30.088226948 End:2018-08-27 11:32:24.220421203 +0000 UTC m=+30.089728386
I0827 11:32:24.220458       1 scheduler.go:454] Total Schedule Algo cumulative time:1.832542784s for 849
I0827 11:32:24.221961       1 scheduler.go:451] ScheduleAlgoTime 1.368274ms Start:2018-08-27 11:32:24.220586998 +0000 UTC m=+30.089894209 End:2018-08-27 11:32:24.221955301 +0000 UTC m=+30.091262483
I0827 11:32:24.221988       1 scheduler.go:454] Total Schedule Algo cumulative time:1.833911058s for 850
I0827 11:32:24.223574       1 scheduler.go:451] ScheduleAlgoTime 1.446232ms Start:2018-08-27 11:32:24.222121674 +0000 UTC m=+30.091428898 End:2018-08-27 11:32:24.223567942 +0000 UTC m=+30.092875130
I0827 11:32:24.223600       1 scheduler.go:454] Total Schedule Algo cumulative time:1.83535729s for 851
I0827 11:32:24.225264       1 scheduler.go:451] ScheduleAlgoTime 1.500411ms Start:2018-08-27 11:32:24.223758343 +0000 UTC m=+30.093065526 End:2018-08-27 11:32:24.22525875 +0000 UTC m=+30.094565937
I0827 11:32:24.225290       1 scheduler.go:454] Total Schedule Algo cumulative time:1.836857701s for 852
I0827 11:32:24.226743       1 scheduler.go:451] ScheduleAlgoTime 1.334823ms Start:2018-08-27 11:32:24.225403401 +0000 UTC m=+30.094710627 End:2018-08-27 11:32:24.226738269 +0000 UTC m=+30.096045450
I0827 11:32:24.226767       1 scheduler.go:454] Total Schedule Algo cumulative time:1.838192524s for 853
I0827 11:32:24.228533       1 scheduler.go:451] ScheduleAlgoTime 1.573251ms Start:2018-08-27 11:32:24.22695404 +0000 UTC m=+30.096261259 End:2018-08-27 11:32:24.228527327 +0000 UTC m=+30.097834510
I0827 11:32:24.228562       1 scheduler.go:454] Total Schedule Algo cumulative time:1.839765775s for 854
I0827 11:32:24.230104       1 scheduler.go:451] ScheduleAlgoTime 1.445436ms Start:2018-08-27 11:32:24.228653783 +0000 UTC m=+30.097961017 End:2018-08-27 11:32:24.230099271 +0000 UTC m=+30.099406453
I0827 11:32:24.230131       1 scheduler.go:454] Total Schedule Algo cumulative time:1.841211211s for 855
I0827 11:32:24.231903       1 scheduler.go:451] ScheduleAlgoTime 1.627571ms Start:2018-08-27 11:32:24.230269567 +0000 UTC m=+30.099576777 End:2018-08-27 11:32:24.231897165 +0000 UTC m=+30.101204348
I0827 11:32:24.231928       1 scheduler.go:454] Total Schedule Algo cumulative time:1.842838782s for 856
I0827 11:32:24.233894       1 scheduler.go:451] ScheduleAlgoTime 1.808398ms Start:2018-08-27 11:32:24.232079988 +0000 UTC m=+30.101387200 End:2018-08-27 11:32:24.233888412 +0000 UTC m=+30.103195598
I0827 11:32:24.233951       1 scheduler.go:454] Total Schedule Algo cumulative time:1.84464718s for 857
I0827 11:32:24.235698       1 scheduler.go:451] ScheduleAlgoTime 1.569498ms Start:2018-08-27 11:32:24.234108221 +0000 UTC m=+30.103415458 End:2018-08-27 11:32:24.235677739 +0000 UTC m=+30.104984956
I0827 11:32:24.235728       1 scheduler.go:454] Total Schedule Algo cumulative time:1.846216678s for 858
I0827 11:32:24.237725       1 scheduler.go:451] ScheduleAlgoTime 1.845239ms Start:2018-08-27 11:32:24.235874205 +0000 UTC m=+30.105181448 End:2018-08-27 11:32:24.2377195 +0000 UTC m=+30.107026687
I0827 11:32:24.237806       1 scheduler.go:454] Total Schedule Algo cumulative time:1.848061917s for 859
I0827 11:32:24.239885       1 scheduler.go:451] ScheduleAlgoTime 1.760069ms Start:2018-08-27 11:32:24.238118906 +0000 UTC m=+30.107426191 End:2018-08-27 11:32:24.239879078 +0000 UTC m=+30.109186260
I0827 11:32:24.239908       1 scheduler.go:454] Total Schedule Algo cumulative time:1.849821986s for 860
I0827 11:32:24.241457       1 scheduler.go:451] ScheduleAlgoTime 1.396014ms Start:2018-08-27 11:32:24.240055146 +0000 UTC m=+30.109362386 End:2018-08-27 11:32:24.241451217 +0000 UTC m=+30.110758400
I0827 11:32:24.241479       1 scheduler.go:454] Total Schedule Algo cumulative time:1.851218s for 861
I0827 11:32:24.243378       1 scheduler.go:451] ScheduleAlgoTime 1.758917ms Start:2018-08-27 11:32:24.241612248 +0000 UTC m=+30.110919452 End:2018-08-27 11:32:24.243371186 +0000 UTC m=+30.112678369
I0827 11:32:24.243405       1 scheduler.go:454] Total Schedule Algo cumulative time:1.852976917s for 862
I0827 11:32:24.245158       1 scheduler.go:451] ScheduleAlgoTime 1.629294ms Start:2018-08-27 11:32:24.243524114 +0000 UTC m=+30.112831356 End:2018-08-27 11:32:24.24515347 +0000 UTC m=+30.114460650
I0827 11:32:24.245182       1 scheduler.go:454] Total Schedule Algo cumulative time:1.854606211s for 863
I0827 11:32:24.246821       1 scheduler.go:451] ScheduleAlgoTime 1.529944ms Start:2018-08-27 11:32:24.245286156 +0000 UTC m=+30.114593412 End:2018-08-27 11:32:24.246816174 +0000 UTC m=+30.116123356
I0827 11:32:24.246843       1 scheduler.go:454] Total Schedule Algo cumulative time:1.856136155s for 864
I0827 11:32:24.248827       1 scheduler.go:451] ScheduleAlgoTime 1.774558ms Start:2018-08-27 11:32:24.247044359 +0000 UTC m=+30.116351654 End:2018-08-27 11:32:24.24881903 +0000 UTC m=+30.118126212
I0827 11:32:24.248868       1 scheduler.go:454] Total Schedule Algo cumulative time:1.857910713s for 865
I0827 11:32:24.250825       1 scheduler.go:451] ScheduleAlgoTime 1.819564ms Start:2018-08-27 11:32:24.248999702 +0000 UTC m=+30.118306907 End:2018-08-27 11:32:24.250819288 +0000 UTC m=+30.120126471
I0827 11:32:24.250848       1 scheduler.go:454] Total Schedule Algo cumulative time:1.859730277s for 866
I0827 11:32:24.252523       1 scheduler.go:451] ScheduleAlgoTime 1.519137ms Start:2018-08-27 11:32:24.250998706 +0000 UTC m=+30.120305934 End:2018-08-27 11:32:24.252517885 +0000 UTC m=+30.121825071
I0827 11:32:24.252546       1 scheduler.go:454] Total Schedule Algo cumulative time:1.861249414s for 867
I0827 11:32:24.254365       1 scheduler.go:451] ScheduleAlgoTime 1.563721ms Start:2018-08-27 11:32:24.252794018 +0000 UTC m=+30.122101285 End:2018-08-27 11:32:24.254357817 +0000 UTC m=+30.123665006
I0827 11:32:24.254393       1 scheduler.go:454] Total Schedule Algo cumulative time:1.862813135s for 868
I0827 11:32:24.256422       1 scheduler.go:451] ScheduleAlgoTime 1.917215ms Start:2018-08-27 11:32:24.254498444 +0000 UTC m=+30.123805649 End:2018-08-27 11:32:24.256415679 +0000 UTC m=+30.125722864
I0827 11:32:24.256448       1 scheduler.go:454] Total Schedule Algo cumulative time:1.86473035s for 869
I0827 11:32:24.258125       1 scheduler.go:451] ScheduleAlgoTime 1.526608ms Start:2018-08-27 11:32:24.256593541 +0000 UTC m=+30.125900743 End:2018-08-27 11:32:24.258120167 +0000 UTC m=+30.127427351
I0827 11:32:24.258200       1 scheduler.go:454] Total Schedule Algo cumulative time:1.866256958s for 870
I0827 11:32:24.260121       1 scheduler.go:451] ScheduleAlgoTime 1.820336ms Start:2018-08-27 11:32:24.258295616 +0000 UTC m=+30.127602820 End:2018-08-27 11:32:24.260115967 +0000 UTC m=+30.129423156
I0827 11:32:24.260145       1 scheduler.go:454] Total Schedule Algo cumulative time:1.868077294s for 871
I0827 11:32:24.262034       1 scheduler.go:451] ScheduleAlgoTime 1.74774ms Start:2018-08-27 11:32:24.260280788 +0000 UTC m=+30.129588021 End:2018-08-27 11:32:24.262028576 +0000 UTC m=+30.131335761
I0827 11:32:24.262056       1 scheduler.go:454] Total Schedule Algo cumulative time:1.869825034s for 872
I0827 11:32:24.263856       1 scheduler.go:451] ScheduleAlgoTime 1.64845ms Start:2018-08-27 11:32:24.262203343 +0000 UTC m=+30.131510594 End:2018-08-27 11:32:24.263851861 +0000 UTC m=+30.133159044
I0827 11:32:24.263878       1 scheduler.go:454] Total Schedule Algo cumulative time:1.871473484s for 873
I0827 11:32:24.265492       1 scheduler.go:451] ScheduleAlgoTime 1.434912ms Start:2018-08-27 11:32:24.264050156 +0000 UTC m=+30.133357392 End:2018-08-27 11:32:24.265485122 +0000 UTC m=+30.134792304
I0827 11:32:24.265521       1 scheduler.go:454] Total Schedule Algo cumulative time:1.872908396s for 874
I0827 11:32:24.267073       1 scheduler.go:451] ScheduleAlgoTime 1.438989ms Start:2018-08-27 11:32:24.265629675 +0000 UTC m=+30.134936891 End:2018-08-27 11:32:24.267068698 +0000 UTC m=+30.136375880
I0827 11:32:24.267097       1 scheduler.go:454] Total Schedule Algo cumulative time:1.874347385s for 875
I0827 11:32:24.268745       1 scheduler.go:451] ScheduleAlgoTime 1.486295ms Start:2018-08-27 11:32:24.267252522 +0000 UTC m=+30.136559706 End:2018-08-27 11:32:24.268738818 +0000 UTC m=+30.138046001
I0827 11:32:24.268772       1 scheduler.go:454] Total Schedule Algo cumulative time:1.87583368s for 876
I0827 11:32:24.270595       1 scheduler.go:451] ScheduleAlgoTime 1.716469ms Start:2018-08-27 11:32:24.268874079 +0000 UTC m=+30.138181307 End:2018-08-27 11:32:24.270590587 +0000 UTC m=+30.139897776
I0827 11:32:24.270659       1 scheduler.go:454] Total Schedule Algo cumulative time:1.877550149s for 877
I0827 11:32:24.272706       1 scheduler.go:451] ScheduleAlgoTime 1.890568ms Start:2018-08-27 11:32:24.270810784 +0000 UTC m=+30.140118046 End:2018-08-27 11:32:24.272701431 +0000 UTC m=+30.142008614
I0827 11:32:24.272728       1 scheduler.go:454] Total Schedule Algo cumulative time:1.879440717s for 878
I0827 11:32:24.274275       1 scheduler.go:451] ScheduleAlgoTime 1.417095ms Start:2018-08-27 11:32:24.272852823 +0000 UTC m=+30.142160073 End:2018-08-27 11:32:24.274269986 +0000 UTC m=+30.143577168
I0827 11:32:24.274309       1 scheduler.go:454] Total Schedule Algo cumulative time:1.880857812s for 879
I0827 11:32:24.276631       1 scheduler.go:451] ScheduleAlgoTime 2.176184ms Start:2018-08-27 11:32:24.274449718 +0000 UTC m=+30.143756973 End:2018-08-27 11:32:24.276625975 +0000 UTC m=+30.145933157
I0827 11:32:24.276653       1 scheduler.go:454] Total Schedule Algo cumulative time:1.883033996s for 880
I0827 11:32:24.278235       1 scheduler.go:451] ScheduleAlgoTime 1.450447ms Start:2018-08-27 11:32:24.276777217 +0000 UTC m=+30.146084427 End:2018-08-27 11:32:24.278227693 +0000 UTC m=+30.147534874
I0827 11:32:24.278263       1 scheduler.go:454] Total Schedule Algo cumulative time:1.884484443s for 881
I0827 11:32:24.280077       1 scheduler.go:451] ScheduleAlgoTime 1.658564ms Start:2018-08-27 11:32:24.278413775 +0000 UTC m=+30.147721022 End:2018-08-27 11:32:24.280072405 +0000 UTC m=+30.149379586
I0827 11:32:24.280100       1 scheduler.go:454] Total Schedule Algo cumulative time:1.886143007s for 882
I0827 11:32:24.285646       1 scheduler.go:451] ScheduleAlgoTime 5.316748ms Start:2018-08-27 11:32:24.280321291 +0000 UTC m=+30.149628487 End:2018-08-27 11:32:24.285638038 +0000 UTC m=+30.154945235
I0827 11:32:24.285724       1 scheduler.go:454] Total Schedule Algo cumulative time:1.891459755s for 883
I0827 11:32:24.288926       1 scheduler.go:451] ScheduleAlgoTime 2.325972ms Start:2018-08-27 11:32:24.286591391 +0000 UTC m=+30.155898655 End:2018-08-27 11:32:24.288917445 +0000 UTC m=+30.158224627
I0827 11:32:24.288955       1 scheduler.go:454] Total Schedule Algo cumulative time:1.893785727s for 884
I0827 11:32:24.290734       1 scheduler.go:451] ScheduleAlgoTime 1.690405ms Start:2018-08-27 11:32:24.289037368 +0000 UTC m=+30.158344592 End:2018-08-27 11:32:24.290727815 +0000 UTC m=+30.160034997
I0827 11:32:24.290758       1 scheduler.go:454] Total Schedule Algo cumulative time:1.895476132s for 885
I0827 11:32:24.292926       1 scheduler.go:451] ScheduleAlgoTime 2.036479ms Start:2018-08-27 11:32:24.290883251 +0000 UTC m=+30.160190455 End:2018-08-27 11:32:24.292919751 +0000 UTC m=+30.162226934
I0827 11:32:24.292954       1 scheduler.go:454] Total Schedule Algo cumulative time:1.897512611s for 886
I0827 11:32:24.294852       1 scheduler.go:451] ScheduleAlgoTime 1.754191ms Start:2018-08-27 11:32:24.293092256 +0000 UTC m=+30.162399505 End:2018-08-27 11:32:24.294846508 +0000 UTC m=+30.164153696
I0827 11:32:24.294874       1 scheduler.go:454] Total Schedule Algo cumulative time:1.899266802s for 887
I0827 11:32:24.296404       1 scheduler.go:451] ScheduleAlgoTime 1.412181ms Start:2018-08-27 11:32:24.294984203 +0000 UTC m=+30.164291433 End:2018-08-27 11:32:24.296396401 +0000 UTC m=+30.165703614
I0827 11:32:24.296428       1 scheduler.go:454] Total Schedule Algo cumulative time:1.900678983s for 888
I0827 11:32:24.298235       1 scheduler.go:451] ScheduleAlgoTime 1.632805ms Start:2018-08-27 11:32:24.296596945 +0000 UTC m=+30.165904142 End:2018-08-27 11:32:24.298229764 +0000 UTC m=+30.167536947
I0827 11:32:24.298264       1 scheduler.go:454] Total Schedule Algo cumulative time:1.902311788s for 889
I0827 11:32:24.299921       1 scheduler.go:451] ScheduleAlgoTime 1.521209ms Start:2018-08-27 11:32:24.298394916 +0000 UTC m=+30.167702178 End:2018-08-27 11:32:24.299916206 +0000 UTC m=+30.169223387
I0827 11:32:24.299946       1 scheduler.go:454] Total Schedule Algo cumulative time:1.903832997s for 890
I0827 11:32:24.301462       1 scheduler.go:451] ScheduleAlgoTime 1.404567ms Start:2018-08-27 11:32:24.300053264 +0000 UTC m=+30.169360445 End:2018-08-27 11:32:24.301457822 +0000 UTC m=+30.170765012
I0827 11:32:24.301492       1 scheduler.go:454] Total Schedule Algo cumulative time:1.905237564s for 891
I0827 11:32:24.303052       1 scheduler.go:451] ScheduleAlgoTime 1.43302ms Start:2018-08-27 11:32:24.301613682 +0000 UTC m=+30.170920903 End:2018-08-27 11:32:24.30304674 +0000 UTC m=+30.172353923
I0827 11:32:24.303094       1 scheduler.go:454] Total Schedule Algo cumulative time:1.906670584s for 892
I0827 11:32:24.305120       1 scheduler.go:451] ScheduleAlgoTime 1.928952ms Start:2018-08-27 11:32:24.303186207 +0000 UTC m=+30.172493428 End:2018-08-27 11:32:24.305115198 +0000 UTC m=+30.174422380
I0827 11:32:24.305142       1 scheduler.go:454] Total Schedule Algo cumulative time:1.908599536s for 893
I0827 11:32:24.306847       1 scheduler.go:451] ScheduleAlgoTime 1.506405ms Start:2018-08-27 11:32:24.305334886 +0000 UTC m=+30.174642172 End:2018-08-27 11:32:24.306841396 +0000 UTC m=+30.176148577
I0827 11:32:24.306869       1 scheduler.go:454] Total Schedule Algo cumulative time:1.910105941s for 894
I0827 11:32:24.308407       1 scheduler.go:451] ScheduleAlgoTime 1.429701ms Start:2018-08-27 11:32:24.306972713 +0000 UTC m=+30.176279898 End:2018-08-27 11:32:24.308402413 +0000 UTC m=+30.177709599
I0827 11:32:24.308431       1 scheduler.go:454] Total Schedule Algo cumulative time:1.911535642s for 895
I0827 11:32:24.310223       1 scheduler.go:451] ScheduleAlgoTime 1.630937ms Start:2018-08-27 11:32:24.308587802 +0000 UTC m=+30.177895053 End:2018-08-27 11:32:24.310218804 +0000 UTC m=+30.179525990
I0827 11:32:24.310247       1 scheduler.go:454] Total Schedule Algo cumulative time:1.913166579s for 896
I0827 11:32:24.312033       1 scheduler.go:451] ScheduleAlgoTime 1.615994ms Start:2018-08-27 11:32:24.310410401 +0000 UTC m=+30.179717642 End:2018-08-27 11:32:24.312026454 +0000 UTC m=+30.181333636
I0827 11:32:24.312058       1 scheduler.go:454] Total Schedule Algo cumulative time:1.914782573s for 897
I0827 11:32:24.313789       1 scheduler.go:451] ScheduleAlgoTime 1.581744ms Start:2018-08-27 11:32:24.312201262 +0000 UTC m=+30.181508446 End:2018-08-27 11:32:24.313783007 +0000 UTC m=+30.183090190
I0827 11:32:24.313813       1 scheduler.go:454] Total Schedule Algo cumulative time:1.916364317s for 898
I0827 11:32:24.315580       1 scheduler.go:451] ScheduleAlgoTime 1.624796ms Start:2018-08-27 11:32:24.313949294 +0000 UTC m=+30.183256564 End:2018-08-27 11:32:24.315574179 +0000 UTC m=+30.184881360
I0827 11:32:24.315606       1 scheduler.go:454] Total Schedule Algo cumulative time:1.917989113s for 899
I0827 11:32:24.317313       1 scheduler.go:451] ScheduleAlgoTime 1.417456ms Start:2018-08-27 11:32:24.315889773 +0000 UTC m=+30.185197010 End:2018-08-27 11:32:24.31730728 +0000 UTC m=+30.186614466
I0827 11:32:24.317347       1 scheduler.go:454] Total Schedule Algo cumulative time:1.919406569s for 900
I0827 11:32:24.318985       1 scheduler.go:451] ScheduleAlgoTime 1.534127ms Start:2018-08-27 11:32:24.317443414 +0000 UTC m=+30.186750655 End:2018-08-27 11:32:24.318977599 +0000 UTC m=+30.188284782
I0827 11:32:24.319008       1 scheduler.go:454] Total Schedule Algo cumulative time:1.920940696s for 901
I0827 11:32:24.320897       1 scheduler.go:451] ScheduleAlgoTime 1.776479ms Start:2018-08-27 11:32:24.319114241 +0000 UTC m=+30.188421495 End:2018-08-27 11:32:24.320890784 +0000 UTC m=+30.190197974
I0827 11:32:24.320924       1 scheduler.go:454] Total Schedule Algo cumulative time:1.922717175s for 902
I0827 11:32:24.322657       1 scheduler.go:451] ScheduleAlgoTime 1.556519ms Start:2018-08-27 11:32:24.321094899 +0000 UTC m=+30.190402132 End:2018-08-27 11:32:24.322651468 +0000 UTC m=+30.191958651
I0827 11:32:24.322695       1 scheduler.go:454] Total Schedule Algo cumulative time:1.924273694s for 903
I0827 11:32:24.324442       1 scheduler.go:451] ScheduleAlgoTime 1.60276ms Start:2018-08-27 11:32:24.322831038 +0000 UTC m=+30.192138243 End:2018-08-27 11:32:24.32443369 +0000 UTC m=+30.193741003
I0827 11:32:24.324480       1 scheduler.go:454] Total Schedule Algo cumulative time:1.925876454s for 904
I0827 11:32:24.326145       1 scheduler.go:451] ScheduleAlgoTime 1.543156ms Start:2018-08-27 11:32:24.324596688 +0000 UTC m=+30.193903909 End:2018-08-27 11:32:24.326139879 +0000 UTC m=+30.195447065
I0827 11:32:24.326169       1 scheduler.go:454] Total Schedule Algo cumulative time:1.92741961s for 905
I0827 11:32:24.328341       1 scheduler.go:451] ScheduleAlgoTime 2.035109ms Start:2018-08-27 11:32:24.326300682 +0000 UTC m=+30.195607899 End:2018-08-27 11:32:24.328335825 +0000 UTC m=+30.197643008
I0827 11:32:24.328375       1 scheduler.go:454] Total Schedule Algo cumulative time:1.929454719s for 906
I0827 11:32:24.330056       1 scheduler.go:451] ScheduleAlgoTime 1.595722ms Start:2018-08-27 11:32:24.328454271 +0000 UTC m=+30.197761522 End:2018-08-27 11:32:24.330050062 +0000 UTC m=+30.199357244
I0827 11:32:24.330081       1 scheduler.go:454] Total Schedule Algo cumulative time:1.931050441s for 907
I0827 11:32:24.331763       1 scheduler.go:451] ScheduleAlgoTime 1.522135ms Start:2018-08-27 11:32:24.330235634 +0000 UTC m=+30.199542867 End:2018-08-27 11:32:24.331757821 +0000 UTC m=+30.201065002
I0827 11:32:24.331790       1 scheduler.go:454] Total Schedule Algo cumulative time:1.932572576s for 908
I0827 11:32:24.333278       1 scheduler.go:451] ScheduleAlgoTime 1.381486ms Start:2018-08-27 11:32:24.331891889 +0000 UTC m=+30.201199146 End:2018-08-27 11:32:24.33327345 +0000 UTC m=+30.202580632
I0827 11:32:24.333298       1 scheduler.go:454] Total Schedule Algo cumulative time:1.933954062s for 909
I0827 11:32:24.335118       1 scheduler.go:451] ScheduleAlgoTime 1.729558ms Start:2018-08-27 11:32:24.333382713 +0000 UTC m=+30.202689969 End:2018-08-27 11:32:24.335112344 +0000 UTC m=+30.204419527
I0827 11:32:24.335142       1 scheduler.go:454] Total Schedule Algo cumulative time:1.93568362s for 910
I0827 11:32:24.336852       1 scheduler.go:451] ScheduleAlgoTime 1.579699ms Start:2018-08-27 11:32:24.335264367 +0000 UTC m=+30.204571582 End:2018-08-27 11:32:24.336844052 +0000 UTC m=+30.206151281
I0827 11:32:24.336880       1 scheduler.go:454] Total Schedule Algo cumulative time:1.937263319s for 911
I0827 11:32:24.338414       1 scheduler.go:451] ScheduleAlgoTime 1.393697ms Start:2018-08-27 11:32:24.337013088 +0000 UTC m=+30.206320352 End:2018-08-27 11:32:24.338406864 +0000 UTC m=+30.207714049
I0827 11:32:24.338439       1 scheduler.go:454] Total Schedule Algo cumulative time:1.938657016s for 912
I0827 11:32:24.340437       1 scheduler.go:451] ScheduleAlgoTime 1.871361ms Start:2018-08-27 11:32:24.33855986 +0000 UTC m=+30.207867100 End:2018-08-27 11:32:24.340431277 +0000 UTC m=+30.209738461
I0827 11:32:24.340462       1 scheduler.go:454] Total Schedule Algo cumulative time:1.940528377s for 913
I0827 11:32:24.342303       1 scheduler.go:451] ScheduleAlgoTime 1.708415ms Start:2018-08-27 11:32:24.340589486 +0000 UTC m=+30.209896728 End:2018-08-27 11:32:24.342297961 +0000 UTC m=+30.211605143
I0827 11:32:24.342329       1 scheduler.go:454] Total Schedule Algo cumulative time:1.942236792s for 914
I0827 11:32:24.343874       1 scheduler.go:451] ScheduleAlgoTime 1.42596ms Start:2018-08-27 11:32:24.342441598 +0000 UTC m=+30.211748810 End:2018-08-27 11:32:24.343867577 +0000 UTC m=+30.213174770
I0827 11:32:24.343902       1 scheduler.go:454] Total Schedule Algo cumulative time:1.943662752s for 915
I0827 11:32:24.345588       1 scheduler.go:451] ScheduleAlgoTime 1.513315ms Start:2018-08-27 11:32:24.344069195 +0000 UTC m=+30.213376394 End:2018-08-27 11:32:24.345582526 +0000 UTC m=+30.214889709
I0827 11:32:24.345611       1 scheduler.go:454] Total Schedule Algo cumulative time:1.945176067s for 916
I0827 11:32:24.347312       1 scheduler.go:451] ScheduleAlgoTime 1.507986ms Start:2018-08-27 11:32:24.345798387 +0000 UTC m=+30.215105594 End:2018-08-27 11:32:24.347306397 +0000 UTC m=+30.216613580
I0827 11:32:24.347336       1 scheduler.go:454] Total Schedule Algo cumulative time:1.946684053s for 917
I0827 11:32:24.349155       1 scheduler.go:451] ScheduleAlgoTime 1.585555ms Start:2018-08-27 11:32:24.347563005 +0000 UTC m=+30.216870243 End:2018-08-27 11:32:24.349148612 +0000 UTC m=+30.218455798
I0827 11:32:24.349182       1 scheduler.go:454] Total Schedule Algo cumulative time:1.948269608s for 918
I0827 11:32:24.351283       1 scheduler.go:451] ScheduleAlgoTime 2.012717ms Start:2018-08-27 11:32:24.349264946 +0000 UTC m=+30.218572192 End:2018-08-27 11:32:24.351277726 +0000 UTC m=+30.220584909
I0827 11:32:24.351317       1 scheduler.go:454] Total Schedule Algo cumulative time:1.950282325s for 919
I0827 11:32:24.352930       1 scheduler.go:451] ScheduleAlgoTime 1.498272ms Start:2018-08-27 11:32:24.351425148 +0000 UTC m=+30.220732330 End:2018-08-27 11:32:24.352923418 +0000 UTC m=+30.222230602
I0827 11:32:24.352955       1 scheduler.go:454] Total Schedule Algo cumulative time:1.951780597s for 920
I0827 11:32:24.354945       1 scheduler.go:451] ScheduleAlgoTime 1.700479ms Start:2018-08-27 11:32:24.353238346 +0000 UTC m=+30.222545595 End:2018-08-27 11:32:24.354938892 +0000 UTC m=+30.224246074
I0827 11:32:24.354968       1 scheduler.go:454] Total Schedule Algo cumulative time:1.953481076s for 921
I0827 11:32:24.356655       1 scheduler.go:451] ScheduleAlgoTime 1.549244ms Start:2018-08-27 11:32:24.355099842 +0000 UTC m=+30.224407094 End:2018-08-27 11:32:24.356649157 +0000 UTC m=+30.225956338
I0827 11:32:24.356690       1 scheduler.go:454] Total Schedule Algo cumulative time:1.95503032s for 922
I0827 11:32:24.358294       1 scheduler.go:451] ScheduleAlgoTime 1.477053ms Start:2018-08-27 11:32:24.356811414 +0000 UTC m=+30.226118671 End:2018-08-27 11:32:24.358288541 +0000 UTC m=+30.227595724
I0827 11:32:24.358320       1 scheduler.go:454] Total Schedule Algo cumulative time:1.956507373s for 923
I0827 11:32:24.359946       1 scheduler.go:451] ScheduleAlgoTime 1.492574ms Start:2018-08-27 11:32:24.358447857 +0000 UTC m=+30.227755100 End:2018-08-27 11:32:24.359940493 +0000 UTC m=+30.229247674
I0827 11:32:24.359968       1 scheduler.go:454] Total Schedule Algo cumulative time:1.957999947s for 924
I0827 11:32:24.361692       1 scheduler.go:451] ScheduleAlgoTime 1.568747ms Start:2018-08-27 11:32:24.360109756 +0000 UTC m=+30.229416999 End:2018-08-27 11:32:24.361678563 +0000 UTC m=+30.230985746
I0827 11:32:24.361713       1 scheduler.go:454] Total Schedule Algo cumulative time:1.959568694s for 925
I0827 11:32:24.363232       1 scheduler.go:451] ScheduleAlgoTime 1.38783ms Start:2018-08-27 11:32:24.361838038 +0000 UTC m=+30.231145239 End:2018-08-27 11:32:24.363225882 +0000 UTC m=+30.232533069
I0827 11:32:24.363257       1 scheduler.go:454] Total Schedule Algo cumulative time:1.960956524s for 926
I0827 11:32:24.367021       1 scheduler.go:451] ScheduleAlgoTime 3.497592ms Start:2018-08-27 11:32:24.363516163 +0000 UTC m=+30.232823385 End:2018-08-27 11:32:24.367013708 +0000 UTC m=+30.236320977
I0827 11:32:24.367084       1 scheduler.go:454] Total Schedule Algo cumulative time:1.964454116s for 927
I0827 11:32:24.371007       1 scheduler.go:451] ScheduleAlgoTime 3.671043ms Start:2018-08-27 11:32:24.367327868 +0000 UTC m=+30.236635089 End:2018-08-27 11:32:24.370998948 +0000 UTC m=+30.240306132
I0827 11:32:24.371040       1 scheduler.go:454] Total Schedule Algo cumulative time:1.968125159s for 928
I0827 11:32:24.373499       1 scheduler.go:451] ScheduleAlgoTime 2.282274ms Start:2018-08-27 11:32:24.371210045 +0000 UTC m=+30.240517325 End:2018-08-27 11:32:24.373492416 +0000 UTC m=+30.242799599
I0827 11:32:24.373528       1 scheduler.go:454] Total Schedule Algo cumulative time:1.970407433s for 929
I0827 11:32:24.375087       1 scheduler.go:451] ScheduleAlgoTime 1.426767ms Start:2018-08-27 11:32:24.373653109 +0000 UTC m=+30.242960342 End:2018-08-27 11:32:24.375079927 +0000 UTC m=+30.244387109
I0827 11:32:24.375119       1 scheduler.go:454] Total Schedule Algo cumulative time:1.9718342s for 930
I0827 11:32:24.377282       1 scheduler.go:451] ScheduleAlgoTime 2.008788ms Start:2018-08-27 11:32:24.375266593 +0000 UTC m=+30.244573841 End:2018-08-27 11:32:24.377275446 +0000 UTC m=+30.246582629
I0827 11:32:24.377309       1 scheduler.go:454] Total Schedule Algo cumulative time:1.973842988s for 931
I0827 11:32:24.379104       1 scheduler.go:451] ScheduleAlgoTime 1.666434ms Start:2018-08-27 11:32:24.377432164 +0000 UTC m=+30.246739378 End:2018-08-27 11:32:24.379098628 +0000 UTC m=+30.248405812
I0827 11:32:24.379138       1 scheduler.go:454] Total Schedule Algo cumulative time:1.975509422s for 932
I0827 11:32:24.380912       1 scheduler.go:451] ScheduleAlgoTime 1.632401ms Start:2018-08-27 11:32:24.379275116 +0000 UTC m=+30.248582329 End:2018-08-27 11:32:24.380907548 +0000 UTC m=+30.250214730
I0827 11:32:24.380950       1 scheduler.go:454] Total Schedule Algo cumulative time:1.977141823s for 933
I0827 11:32:24.382846       1 scheduler.go:451] ScheduleAlgoTime 1.69083ms Start:2018-08-27 11:32:24.381147596 +0000 UTC m=+30.250454814 End:2018-08-27 11:32:24.382838372 +0000 UTC m=+30.252145644
I0827 11:32:24.382873       1 scheduler.go:454] Total Schedule Algo cumulative time:1.978832653s for 934
I0827 11:32:24.384505       1 scheduler.go:451] ScheduleAlgoTime 1.496892ms Start:2018-08-27 11:32:24.383003936 +0000 UTC m=+30.252311199 End:2018-08-27 11:32:24.384500902 +0000 UTC m=+30.253808091
I0827 11:32:24.384530       1 scheduler.go:454] Total Schedule Algo cumulative time:1.980329545s for 935
I0827 11:32:24.386273       1 scheduler.go:451] ScheduleAlgoTime 1.604578ms Start:2018-08-27 11:32:24.38466165 +0000 UTC m=+30.253968864 End:2018-08-27 11:32:24.386266157 +0000 UTC m=+30.255573442
I0827 11:32:24.386301       1 scheduler.go:454] Total Schedule Algo cumulative time:1.981934123s for 936
I0827 11:32:24.388144       1 scheduler.go:451] ScheduleAlgoTime 1.688385ms Start:2018-08-27 11:32:24.386450139 +0000 UTC m=+30.255757341 End:2018-08-27 11:32:24.38813852 +0000 UTC m=+30.257445726
I0827 11:32:24.388168       1 scheduler.go:454] Total Schedule Algo cumulative time:1.983622508s for 937
I0827 11:32:24.390002       1 scheduler.go:451] ScheduleAlgoTime 1.683681ms Start:2018-08-27 11:32:24.388313234 +0000 UTC m=+30.257620474 End:2018-08-27 11:32:24.389996972 +0000 UTC m=+30.259304155
I0827 11:32:24.390025       1 scheduler.go:454] Total Schedule Algo cumulative time:1.985306189s for 938
I0827 11:32:24.391721       1 scheduler.go:451] ScheduleAlgoTime 1.505738ms Start:2018-08-27 11:32:24.390210085 +0000 UTC m=+30.259517347 End:2018-08-27 11:32:24.391715903 +0000 UTC m=+30.261023085
I0827 11:32:24.391773       1 scheduler.go:454] Total Schedule Algo cumulative time:1.986811927s for 939
I0827 11:32:24.393515       1 scheduler.go:451] ScheduleAlgoTime 1.608158ms Start:2018-08-27 11:32:24.391902153 +0000 UTC m=+30.261209419 End:2018-08-27 11:32:24.393510394 +0000 UTC m=+30.262817577
I0827 11:32:24.393539       1 scheduler.go:454] Total Schedule Algo cumulative time:1.988420085s for 940
I0827 11:32:24.395960       1 scheduler.go:451] ScheduleAlgoTime 2.284792ms Start:2018-08-27 11:32:24.393670369 +0000 UTC m=+30.262977588 End:2018-08-27 11:32:24.395955199 +0000 UTC m=+30.265262380
I0827 11:32:24.395984       1 scheduler.go:454] Total Schedule Algo cumulative time:1.990704877s for 941
I0827 11:32:24.397835       1 scheduler.go:451] ScheduleAlgoTime 1.693143ms Start:2018-08-27 11:32:24.396135436 +0000 UTC m=+30.265442668 End:2018-08-27 11:32:24.397828624 +0000 UTC m=+30.267135811
I0827 11:32:24.397865       1 scheduler.go:454] Total Schedule Algo cumulative time:1.99239802s for 942
I0827 11:32:24.399510       1 scheduler.go:451] ScheduleAlgoTime 1.499105ms Start:2018-08-27 11:32:24.398006061 +0000 UTC m=+30.267313295 End:2018-08-27 11:32:24.399505217 +0000 UTC m=+30.268812400
I0827 11:32:24.399534       1 scheduler.go:454] Total Schedule Algo cumulative time:1.993897125s for 943
I0827 11:32:24.401078       1 scheduler.go:451] ScheduleAlgoTime 1.413943ms Start:2018-08-27 11:32:24.399660084 +0000 UTC m=+30.268967341 End:2018-08-27 11:32:24.401074101 +0000 UTC m=+30.270381284
I0827 11:32:24.401099       1 scheduler.go:454] Total Schedule Algo cumulative time:1.995311068s for 944
I0827 11:32:24.402651       1 scheduler.go:451] ScheduleAlgoTime 1.386317ms Start:2018-08-27 11:32:24.401259516 +0000 UTC m=+30.270566743 End:2018-08-27 11:32:24.402645873 +0000 UTC m=+30.271953060
I0827 11:32:24.402689       1 scheduler.go:454] Total Schedule Algo cumulative time:1.996697385s for 945
I0827 11:32:24.404247       1 scheduler.go:451] ScheduleAlgoTime 1.460108ms Start:2018-08-27 11:32:24.402782748 +0000 UTC m=+30.272089932 End:2018-08-27 11:32:24.404242857 +0000 UTC m=+30.273550040
I0827 11:32:24.404273       1 scheduler.go:454] Total Schedule Algo cumulative time:1.998157493s for 946
I0827 11:32:24.405911       1 scheduler.go:451] ScheduleAlgoTime 1.488099ms Start:2018-08-27 11:32:24.404418199 +0000 UTC m=+30.273725401 End:2018-08-27 11:32:24.405906314 +0000 UTC m=+30.275213500
I0827 11:32:24.405995       1 scheduler.go:454] Total Schedule Algo cumulative time:1.999645592s for 947
I0827 11:32:24.407860       1 scheduler.go:451] ScheduleAlgoTime 1.747878ms Start:2018-08-27 11:32:24.40610746 +0000 UTC m=+30.275414675 End:2018-08-27 11:32:24.407855367 +0000 UTC m=+30.277162553
I0827 11:32:24.407883       1 scheduler.go:454] Total Schedule Algo cumulative time:2.00139347s for 948
I0827 11:32:24.409531       1 scheduler.go:451] ScheduleAlgoTime 1.509421ms Start:2018-08-27 11:32:24.408016025 +0000 UTC m=+30.277323278 End:2018-08-27 11:32:24.409525518 +0000 UTC m=+30.278832699
I0827 11:32:24.409552       1 scheduler.go:454] Total Schedule Algo cumulative time:2.002902891s for 949
I0827 11:32:24.411266       1 scheduler.go:451] ScheduleAlgoTime 1.598383ms Start:2018-08-27 11:32:24.409662934 +0000 UTC m=+30.278970146 End:2018-08-27 11:32:24.411261347 +0000 UTC m=+30.280568529
I0827 11:32:24.411287       1 scheduler.go:454] Total Schedule Algo cumulative time:2.004501274s for 950
I0827 11:32:24.412650       1 scheduler.go:451] ScheduleAlgoTime 1.275138ms Start:2018-08-27 11:32:24.411370624 +0000 UTC m=+30.280677807 End:2018-08-27 11:32:24.412645756 +0000 UTC m=+30.281952945
I0827 11:32:24.412671       1 scheduler.go:454] Total Schedule Algo cumulative time:2.005776412s for 951
I0827 11:32:24.414562       1 scheduler.go:451] ScheduleAlgoTime 1.750951ms Start:2018-08-27 11:32:24.412805613 +0000 UTC m=+30.282112812 End:2018-08-27 11:32:24.414556561 +0000 UTC m=+30.283863763
I0827 11:32:24.414584       1 scheduler.go:454] Total Schedule Algo cumulative time:2.007527363s for 952
I0827 11:32:24.416328       1 scheduler.go:451] ScheduleAlgoTime 1.594541ms Start:2018-08-27 11:32:24.414728504 +0000 UTC m=+30.284035753 End:2018-08-27 11:32:24.416323112 +0000 UTC m=+30.285630294
I0827 11:32:24.416349       1 scheduler.go:454] Total Schedule Algo cumulative time:2.009121904s for 953
I0827 11:32:24.418037       1 scheduler.go:451] ScheduleAlgoTime 1.578874ms Start:2018-08-27 11:32:24.416447761 +0000 UTC m=+30.285754994 End:2018-08-27 11:32:24.418026682 +0000 UTC m=+30.287333868
I0827 11:32:24.418057       1 scheduler.go:454] Total Schedule Algo cumulative time:2.010700778s for 954
I0827 11:32:24.419531       1 scheduler.go:451] ScheduleAlgoTime 1.351747ms Start:2018-08-27 11:32:24.418174534 +0000 UTC m=+30.287481763 End:2018-08-27 11:32:24.419526324 +0000 UTC m=+30.288833510
I0827 11:32:24.419555       1 scheduler.go:454] Total Schedule Algo cumulative time:2.012052525s for 955
I0827 11:32:24.421631       1 scheduler.go:451] ScheduleAlgoTime 1.977001ms Start:2018-08-27 11:32:24.419649294 +0000 UTC m=+30.288956490 End:2018-08-27 11:32:24.42162631 +0000 UTC m=+30.290933491
I0827 11:32:24.421654       1 scheduler.go:454] Total Schedule Algo cumulative time:2.014029526s for 956
I0827 11:32:24.423935       1 scheduler.go:451] ScheduleAlgoTime 2.163934ms Start:2018-08-27 11:32:24.421763344 +0000 UTC m=+30.291070525 End:2018-08-27 11:32:24.423927273 +0000 UTC m=+30.293234459
I0827 11:32:24.423965       1 scheduler.go:454] Total Schedule Algo cumulative time:2.01619346s for 957
I0827 11:32:24.425663       1 scheduler.go:451] ScheduleAlgoTime 1.513166ms Start:2018-08-27 11:32:24.424144811 +0000 UTC m=+30.293452053 End:2018-08-27 11:32:24.425658034 +0000 UTC m=+30.294965219
I0827 11:32:24.425701       1 scheduler.go:454] Total Schedule Algo cumulative time:2.017706626s for 958
I0827 11:32:24.427935       1 scheduler.go:451] ScheduleAlgoTime 1.967717ms Start:2018-08-27 11:32:24.425955663 +0000 UTC m=+30.295262939 End:2018-08-27 11:32:24.427923357 +0000 UTC m=+30.297230656
I0827 11:32:24.427966       1 scheduler.go:454] Total Schedule Algo cumulative time:2.019674343s for 959
I0827 11:32:24.429717       1 scheduler.go:451] ScheduleAlgoTime 1.597893ms Start:2018-08-27 11:32:24.428113422 +0000 UTC m=+30.297420658 End:2018-08-27 11:32:24.429711363 +0000 UTC m=+30.299018551
I0827 11:32:24.429750       1 scheduler.go:454] Total Schedule Algo cumulative time:2.021272236s for 960
I0827 11:32:24.431613       1 scheduler.go:451] ScheduleAlgoTime 1.667926ms Start:2018-08-27 11:32:24.429937324 +0000 UTC m=+30.299244581 End:2018-08-27 11:32:24.431605325 +0000 UTC m=+30.300912507
I0827 11:32:24.431657       1 scheduler.go:454] Total Schedule Algo cumulative time:2.022940162s for 961
I0827 11:32:24.433449       1 scheduler.go:451] ScheduleAlgoTime 1.699251ms Start:2018-08-27 11:32:24.431743954 +0000 UTC m=+30.301051185 End:2018-08-27 11:32:24.433443249 +0000 UTC m=+30.302750436
I0827 11:32:24.433471       1 scheduler.go:454] Total Schedule Algo cumulative time:2.024639413s for 962
I0827 11:32:24.435101       1 scheduler.go:451] ScheduleAlgoTime 1.461414ms Start:2018-08-27 11:32:24.433634921 +0000 UTC m=+30.302942160 End:2018-08-27 11:32:24.435096394 +0000 UTC m=+30.304403574
I0827 11:32:24.435126       1 scheduler.go:454] Total Schedule Algo cumulative time:2.026100827s for 963
I0827 11:32:24.436702       1 scheduler.go:451] ScheduleAlgoTime 1.441696ms Start:2018-08-27 11:32:24.435253812 +0000 UTC m=+30.304561049 End:2018-08-27 11:32:24.436695554 +0000 UTC m=+30.306002745
I0827 11:32:24.436733       1 scheduler.go:454] Total Schedule Algo cumulative time:2.027542523s for 964
I0827 11:32:24.438657       1 scheduler.go:451] ScheduleAlgoTime 1.759083ms Start:2018-08-27 11:32:24.436892086 +0000 UTC m=+30.306199296 End:2018-08-27 11:32:24.438651197 +0000 UTC m=+30.307958379
I0827 11:32:24.438690       1 scheduler.go:454] Total Schedule Algo cumulative time:2.029301606s for 965
I0827 11:32:24.440531       1 scheduler.go:451] ScheduleAlgoTime 1.718116ms Start:2018-08-27 11:32:24.438807357 +0000 UTC m=+30.308114619 End:2018-08-27 11:32:24.440525553 +0000 UTC m=+30.309832735
I0827 11:32:24.440555       1 scheduler.go:454] Total Schedule Algo cumulative time:2.031019722s for 966
I0827 11:32:24.442452       1 scheduler.go:451] ScheduleAlgoTime 1.702292ms Start:2018-08-27 11:32:24.440742437 +0000 UTC m=+30.310049713 End:2018-08-27 11:32:24.442444731 +0000 UTC m=+30.311752005
I0827 11:32:24.442480       1 scheduler.go:454] Total Schedule Algo cumulative time:2.032722014s for 967
I0827 11:32:24.444523       1 scheduler.go:451] ScheduleAlgoTime 1.685451ms Start:2018-08-27 11:32:24.442831834 +0000 UTC m=+30.312139061 End:2018-08-27 11:32:24.444517331 +0000 UTC m=+30.313824512
I0827 11:32:24.444545       1 scheduler.go:454] Total Schedule Algo cumulative time:2.034407465s for 968
I0827 11:32:24.446314       1 scheduler.go:451] ScheduleAlgoTime 1.586136ms Start:2018-08-27 11:32:24.444723012 +0000 UTC m=+30.314030217 End:2018-08-27 11:32:24.446309171 +0000 UTC m=+30.315616353
I0827 11:32:24.446336       1 scheduler.go:454] Total Schedule Algo cumulative time:2.035993601s for 969
I0827 11:32:24.448292       1 scheduler.go:451] ScheduleAlgoTime 1.847584ms Start:2018-08-27 11:32:24.446439778 +0000 UTC m=+30.315747008 End:2018-08-27 11:32:24.44828741 +0000 UTC m=+30.317594592
I0827 11:32:24.448314       1 scheduler.go:454] Total Schedule Algo cumulative time:2.037841185s for 970
I0827 11:32:24.454187       1 scheduler.go:451] ScheduleAlgoTime 5.758624ms Start:2018-08-27 11:32:24.44842037 +0000 UTC m=+30.317727613 End:2018-08-27 11:32:24.454179055 +0000 UTC m=+30.323486237
I0827 11:32:24.454230       1 scheduler.go:454] Total Schedule Algo cumulative time:2.043599809s for 971
I0827 11:32:24.456810       1 scheduler.go:451] ScheduleAlgoTime 2.4149ms Start:2018-08-27 11:32:24.454388923 +0000 UTC m=+30.323696182 End:2018-08-27 11:32:24.456803895 +0000 UTC m=+30.326111082
I0827 11:32:24.456841       1 scheduler.go:454] Total Schedule Algo cumulative time:2.046014709s for 972
I0827 11:32:24.458791       1 scheduler.go:451] ScheduleAlgoTime 1.814326ms Start:2018-08-27 11:32:24.456969105 +0000 UTC m=+30.326276346 End:2018-08-27 11:32:24.45878349 +0000 UTC m=+30.328090672
I0827 11:32:24.458822       1 scheduler.go:454] Total Schedule Algo cumulative time:2.047829035s for 973
I0827 11:32:24.460929       1 scheduler.go:451] ScheduleAlgoTime 1.913322ms Start:2018-08-27 11:32:24.459008728 +0000 UTC m=+30.328315994 End:2018-08-27 11:32:24.460922134 +0000 UTC m=+30.330229316
I0827 11:32:24.460965       1 scheduler.go:454] Total Schedule Algo cumulative time:2.049742357s for 974
I0827 11:32:24.462689       1 scheduler.go:451] ScheduleAlgoTime 1.557373ms Start:2018-08-27 11:32:24.461117991 +0000 UTC m=+30.330425188 End:2018-08-27 11:32:24.462675373 +0000 UTC m=+30.331982561
I0827 11:32:24.462715       1 scheduler.go:454] Total Schedule Algo cumulative time:2.05129973s for 975
I0827 11:32:24.464541       1 scheduler.go:451] ScheduleAlgoTime 1.631672ms Start:2018-08-27 11:32:24.46290358 +0000 UTC m=+30.332210816 End:2018-08-27 11:32:24.464535306 +0000 UTC m=+30.333842488
I0827 11:32:24.464566       1 scheduler.go:454] Total Schedule Algo cumulative time:2.052931402s for 976
I0827 11:32:24.466482       1 scheduler.go:451] ScheduleAlgoTime 1.732116ms Start:2018-08-27 11:32:24.464743075 +0000 UTC m=+30.334050361 End:2018-08-27 11:32:24.466475294 +0000 UTC m=+30.335782477
I0827 11:32:24.466514       1 scheduler.go:454] Total Schedule Algo cumulative time:2.054663518s for 977
I0827 11:32:24.468404       1 scheduler.go:451] ScheduleAlgoTime 1.764644ms Start:2018-08-27 11:32:24.466634809 +0000 UTC m=+30.335942034 End:2018-08-27 11:32:24.468399496 +0000 UTC m=+30.337706678
I0827 11:32:24.468430       1 scheduler.go:454] Total Schedule Algo cumulative time:2.056428162s for 978
I0827 11:32:24.470352       1 scheduler.go:451] ScheduleAlgoTime 1.746799ms Start:2018-08-27 11:32:24.468599188 +0000 UTC m=+30.337906415 End:2018-08-27 11:32:24.47034603 +0000 UTC m=+30.339653214
I0827 11:32:24.470379       1 scheduler.go:454] Total Schedule Algo cumulative time:2.058174961s for 979
I0827 11:32:24.472123       1 scheduler.go:451] ScheduleAlgoTime 1.622507ms Start:2018-08-27 11:32:24.470494954 +0000 UTC m=+30.339802175 End:2018-08-27 11:32:24.472117495 +0000 UTC m=+30.341424682
I0827 11:32:24.472148       1 scheduler.go:454] Total Schedule Algo cumulative time:2.059797468s for 980
I0827 11:32:24.473917       1 scheduler.go:451] ScheduleAlgoTime 1.596005ms Start:2018-08-27 11:32:24.472311826 +0000 UTC m=+30.341619090 End:2018-08-27 11:32:24.473907887 +0000 UTC m=+30.343215095
I0827 11:32:24.473952       1 scheduler.go:454] Total Schedule Algo cumulative time:2.061393473s for 981
I0827 11:32:24.475806       1 scheduler.go:451] ScheduleAlgoTime 1.672787ms Start:2018-08-27 11:32:24.474125014 +0000 UTC m=+30.343432268 End:2018-08-27 11:32:24.475797855 +0000 UTC m=+30.345105055
I0827 11:32:24.475839       1 scheduler.go:454] Total Schedule Algo cumulative time:2.06306626s for 982
I0827 11:32:24.477657       1 scheduler.go:451] ScheduleAlgoTime 1.643103ms Start:2018-08-27 11:32:24.476000516 +0000 UTC m=+30.345307763 End:2018-08-27 11:32:24.477643677 +0000 UTC m=+30.346950866
I0827 11:32:24.477715       1 scheduler.go:454] Total Schedule Algo cumulative time:2.064709363s for 983
I0827 11:32:24.479689       1 scheduler.go:451] ScheduleAlgoTime 1.829967ms Start:2018-08-27 11:32:24.477843191 +0000 UTC m=+30.347150467 End:2018-08-27 11:32:24.479673252 +0000 UTC m=+30.348980434
I0827 11:32:24.479715       1 scheduler.go:454] Total Schedule Algo cumulative time:2.06653933s for 984
I0827 11:32:24.481401       1 scheduler.go:451] ScheduleAlgoTime 1.552305ms Start:2018-08-27 11:32:24.479843664 +0000 UTC m=+30.349150906 End:2018-08-27 11:32:24.481396029 +0000 UTC m=+30.350703211
I0827 11:32:24.481424       1 scheduler.go:454] Total Schedule Algo cumulative time:2.068091635s for 985
I0827 11:32:24.483206       1 scheduler.go:451] ScheduleAlgoTime 1.706044ms Start:2018-08-27 11:32:24.4814922 +0000 UTC m=+30.350799415 End:2018-08-27 11:32:24.483198261 +0000 UTC m=+30.352505459
I0827 11:32:24.483235       1 scheduler.go:454] Total Schedule Algo cumulative time:2.069797679s for 986
I0827 11:32:24.484995       1 scheduler.go:451] ScheduleAlgoTime 1.621126ms Start:2018-08-27 11:32:24.483367156 +0000 UTC m=+30.352674386 End:2018-08-27 11:32:24.484988327 +0000 UTC m=+30.354295512
I0827 11:32:24.485031       1 scheduler.go:454] Total Schedule Algo cumulative time:2.071418805s for 987
I0827 11:32:24.486815       1 scheduler.go:451] ScheduleAlgoTime 1.666466ms Start:2018-08-27 11:32:24.485143268 +0000 UTC m=+30.354450472 End:2018-08-27 11:32:24.486809756 +0000 UTC m=+30.356116938
I0827 11:32:24.486841       1 scheduler.go:454] Total Schedule Algo cumulative time:2.073085271s for 988
I0827 11:32:24.488587       1 scheduler.go:451] ScheduleAlgoTime 1.526022ms Start:2018-08-27 11:32:24.487053423 +0000 UTC m=+30.356360608 End:2018-08-27 11:32:24.488579431 +0000 UTC m=+30.357886630
I0827 11:32:24.488624       1 scheduler.go:454] Total Schedule Algo cumulative time:2.074611293s for 989
I0827 11:32:24.490373       1 scheduler.go:451] ScheduleAlgoTime 1.670751ms Start:2018-08-27 11:32:24.488695871 +0000 UTC m=+30.358003070 End:2018-08-27 11:32:24.49036664 +0000 UTC m=+30.359673821
I0827 11:32:24.490403       1 scheduler.go:454] Total Schedule Algo cumulative time:2.076282044s for 990
I0827 11:32:24.492386       1 scheduler.go:451] ScheduleAlgoTime 1.842015ms Start:2018-08-27 11:32:24.490538171 +0000 UTC m=+30.359845412 End:2018-08-27 11:32:24.49238024 +0000 UTC m=+30.361687427
I0827 11:32:24.492413       1 scheduler.go:454] Total Schedule Algo cumulative time:2.078124059s for 991
I0827 11:32:24.494317       1 scheduler.go:451] ScheduleAlgoTime 1.753398ms Start:2018-08-27 11:32:24.492555993 +0000 UTC m=+30.361863212 End:2018-08-27 11:32:24.494309429 +0000 UTC m=+30.363616610
I0827 11:32:24.494344       1 scheduler.go:454] Total Schedule Algo cumulative time:2.079877457s for 992
I0827 11:32:24.496063       1 scheduler.go:451] ScheduleAlgoTime 1.521ms Start:2018-08-27 11:32:24.4945366 +0000 UTC m=+30.363843815 End:2018-08-27 11:32:24.496057633 +0000 UTC m=+30.365364815
I0827 11:32:24.496088       1 scheduler.go:454] Total Schedule Algo cumulative time:2.081398457s for 993
I0827 11:32:24.497867       1 scheduler.go:451] ScheduleAlgoTime 1.613913ms Start:2018-08-27 11:32:24.496245028 +0000 UTC m=+30.365552592 End:2018-08-27 11:32:24.497859322 +0000 UTC m=+30.367166505
I0827 11:32:24.497895       1 scheduler.go:454] Total Schedule Algo cumulative time:2.08301237s for 994
I0827 11:32:24.499995       1 scheduler.go:451] ScheduleAlgoTime 1.951915ms Start:2018-08-27 11:32:24.498037476 +0000 UTC m=+30.367344700 End:2018-08-27 11:32:24.499989434 +0000 UTC m=+30.369296615
I0827 11:32:24.500024       1 scheduler.go:454] Total Schedule Algo cumulative time:2.084964285s for 995
I0827 11:32:24.502439       1 scheduler.go:451] ScheduleAlgoTime 2.225402ms Start:2018-08-27 11:32:24.500206335 +0000 UTC m=+30.369513546 End:2018-08-27 11:32:24.502431763 +0000 UTC m=+30.371738948
I0827 11:32:24.502466       1 scheduler.go:454] Total Schedule Algo cumulative time:2.087189687s for 996
I0827 11:32:24.504417       1 scheduler.go:451] ScheduleAlgoTime 1.790108ms Start:2018-08-27 11:32:24.502619566 +0000 UTC m=+30.371926860 End:2018-08-27 11:32:24.504409786 +0000 UTC m=+30.373716968
I0827 11:32:24.504445       1 scheduler.go:454] Total Schedule Algo cumulative time:2.088979795s for 997
I0827 11:32:24.506852       1 scheduler.go:451] ScheduleAlgoTime 2.227706ms Start:2018-08-27 11:32:24.504618 +0000 UTC m=+30.373925210 End:2018-08-27 11:32:24.506845735 +0000 UTC m=+30.376152916
I0827 11:32:24.506881       1 scheduler.go:454] Total Schedule Algo cumulative time:2.091207501s for 998
I0827 11:32:24.508650       1 scheduler.go:451] ScheduleAlgoTime 1.586762ms Start:2018-08-27 11:32:24.507058019 +0000 UTC m=+30.376365275 End:2018-08-27 11:32:24.508644856 +0000 UTC m=+30.377952037
I0827 11:32:24.508673       1 scheduler.go:454] Total Schedule Algo cumulative time:2.092794263s for 999
I0827 11:32:24.510332       1 scheduler.go:451] ScheduleAlgoTime 1.557237ms Start:2018-08-27 11:32:24.508768788 +0000 UTC m=+30.378075990 End:2018-08-27 11:32:24.510326045 +0000 UTC m=+30.379633227
I0827 11:32:24.510357       1 scheduler.go:454] Total Schedule Algo cumulative time:2.0943515s for 1000
I0827 11:34:21.514332       1 scheduler.go:451] ScheduleAlgoTime 33.59952ms Start:2018-08-27 11:34:21.480721424 +0000 UTC m=+147.350028690 End:2018-08-27 11:34:21.514321026 +0000 UTC m=+147.383628210
I0827 11:34:21.514394       1 scheduler.go:454] Total Schedule Algo cumulative time:2.12795102s for 1001
I0827 11:34:21.565442       1 scheduler.go:451] ScheduleAlgoTime 50.09501ms Start:2018-08-27 11:34:21.515335799 +0000 UTC m=+147.384643044 End:2018-08-27 11:34:21.565430871 +0000 UTC m=+147.434738054
I0827 11:34:21.565486       1 scheduler.go:454] Total Schedule Algo cumulative time:2.17804603s for 1002
I0827 11:34:21.609135       1 scheduler.go:451] ScheduleAlgoTime 43.520024ms Start:2018-08-27 11:34:21.565604083 +0000 UTC m=+147.434911334 End:2018-08-27 11:34:21.609124172 +0000 UTC m=+147.478431358
I0827 11:34:21.609176       1 scheduler.go:454] Total Schedule Algo cumulative time:2.221566054s for 1003
I0827 11:34:21.657183       1 scheduler.go:451] ScheduleAlgoTime 47.819722ms Start:2018-08-27 11:34:21.609352508 +0000 UTC m=+147.478659753 End:2018-08-27 11:34:21.65717228 +0000 UTC m=+147.526479475
I0827 11:34:21.657224       1 scheduler.go:454] Total Schedule Algo cumulative time:2.269385776s for 1004
I0827 11:34:21.702193       1 scheduler.go:451] ScheduleAlgoTime 44.875243ms Start:2018-08-27 11:34:21.657307844 +0000 UTC m=+147.526615047 End:2018-08-27 11:34:21.702183104 +0000 UTC m=+147.571490290
I0827 11:34:21.702231       1 scheduler.go:454] Total Schedule Algo cumulative time:2.314261019s for 1005
I0827 11:34:21.743575       1 scheduler.go:451] ScheduleAlgoTime 39.825973ms Start:2018-08-27 11:34:21.703737244 +0000 UTC m=+147.573044493 End:2018-08-27 11:34:21.743563272 +0000 UTC m=+147.612870466
I0827 11:34:21.743683       1 scheduler.go:454] Total Schedule Algo cumulative time:2.354086992s for 1006
I0827 11:34:21.780480       1 scheduler.go:451] ScheduleAlgoTime 36.228508ms Start:2018-08-27 11:34:21.744243129 +0000 UTC m=+147.613550447 End:2018-08-27 11:34:21.780471772 +0000 UTC m=+147.649778955
I0827 11:34:21.780511       1 scheduler.go:454] Total Schedule Algo cumulative time:2.3903155s for 1007
I0827 11:34:21.812179       1 scheduler.go:451] ScheduleAlgoTime 31.497753ms Start:2018-08-27 11:34:21.78067219 +0000 UTC m=+147.649979400 End:2018-08-27 11:34:21.812169964 +0000 UTC m=+147.681477153
I0827 11:34:21.812233       1 scheduler.go:454] Total Schedule Algo cumulative time:2.421813253s for 1008
I0827 11:34:21.847684       1 scheduler.go:451] ScheduleAlgoTime 35.153698ms Start:2018-08-27 11:34:21.812521798 +0000 UTC m=+147.681829046 End:2018-08-27 11:34:21.847675562 +0000 UTC m=+147.716982744
I0827 11:34:21.847734       1 scheduler.go:454] Total Schedule Algo cumulative time:2.456966951s for 1009
I0827 11:34:21.881974       1 scheduler.go:451] ScheduleAlgoTime 34.098312ms Start:2018-08-27 11:34:21.847864228 +0000 UTC m=+147.717171489 End:2018-08-27 11:34:21.881962616 +0000 UTC m=+147.751269801
I0827 11:34:21.882026       1 scheduler.go:454] Total Schedule Algo cumulative time:2.491065263s for 1010
I0827 11:34:21.927133       1 scheduler.go:451] ScheduleAlgoTime 44.908183ms Start:2018-08-27 11:34:21.882216684 +0000 UTC m=+147.751523937 End:2018-08-27 11:34:21.927124938 +0000 UTC m=+147.796432120
I0827 11:34:21.927174       1 scheduler.go:454] Total Schedule Algo cumulative time:2.535973446s for 1011
I0827 11:34:21.969855       1 scheduler.go:451] ScheduleAlgoTime 42.502961ms Start:2018-08-27 11:34:21.927342988 +0000 UTC m=+147.796650237 End:2018-08-27 11:34:21.969846017 +0000 UTC m=+147.839153198
I0827 11:34:21.969907       1 scheduler.go:454] Total Schedule Algo cumulative time:2.578476407s for 1012
I0827 11:34:22.002944       1 scheduler.go:451] ScheduleAlgoTime 32.801002ms Start:2018-08-27 11:34:21.970133257 +0000 UTC m=+147.839440503 End:2018-08-27 11:34:22.002934322 +0000 UTC m=+147.872241505
I0827 11:34:22.003002       1 scheduler.go:454] Total Schedule Algo cumulative time:2.611277409s for 1013
I0827 11:34:22.037530       1 scheduler.go:451] ScheduleAlgoTime 34.287094ms Start:2018-08-27 11:34:22.003234637 +0000 UTC m=+147.872541853 End:2018-08-27 11:34:22.037521763 +0000 UTC m=+147.906828947
I0827 11:34:22.037593       1 scheduler.go:454] Total Schedule Algo cumulative time:2.645564503s for 1014
I0827 11:34:22.072706       1 scheduler.go:451] ScheduleAlgoTime 34.923434ms Start:2018-08-27 11:34:22.037760395 +0000 UTC m=+147.907067652 End:2018-08-27 11:34:22.0726839 +0000 UTC m=+147.941991086
I0827 11:34:22.072759       1 scheduler.go:454] Total Schedule Algo cumulative time:2.680487937s for 1015
I0827 11:34:22.108220       1 scheduler.go:451] ScheduleAlgoTime 35.250387ms Start:2018-08-27 11:34:22.072961006 +0000 UTC m=+147.942268286 End:2018-08-27 11:34:22.10821149 +0000 UTC m=+147.977518673
I0827 11:34:22.108266       1 scheduler.go:454] Total Schedule Algo cumulative time:2.715738324s for 1016
I0827 11:34:22.151056       1 scheduler.go:451] ScheduleAlgoTime 42.626635ms Start:2018-08-27 11:34:22.108421326 +0000 UTC m=+147.977728593 End:2018-08-27 11:34:22.151048042 +0000 UTC m=+148.020355228
I0827 11:34:22.151109       1 scheduler.go:454] Total Schedule Algo cumulative time:2.758364959s for 1017
I0827 11:34:22.185168       1 scheduler.go:451] ScheduleAlgoTime 33.884839ms Start:2018-08-27 11:34:22.151270913 +0000 UTC m=+148.020578185 End:2018-08-27 11:34:22.185155843 +0000 UTC m=+148.054463024
I0827 11:34:22.185218       1 scheduler.go:454] Total Schedule Algo cumulative time:2.792249798s for 1018
I0827 11:34:22.221549       1 scheduler.go:451] ScheduleAlgoTime 36.156906ms Start:2018-08-27 11:34:22.185380848 +0000 UTC m=+148.054688046 End:2018-08-27 11:34:22.22153777 +0000 UTC m=+148.090844952
I0827 11:34:22.221596       1 scheduler.go:454] Total Schedule Algo cumulative time:2.828406704s for 1019
I0827 11:34:22.258077       1 scheduler.go:451] ScheduleAlgoTime 36.306305ms Start:2018-08-27 11:34:22.221759004 +0000 UTC m=+148.091066243 End:2018-08-27 11:34:22.258065366 +0000 UTC m=+148.127372548
I0827 11:34:22.258138       1 scheduler.go:454] Total Schedule Algo cumulative time:2.864713009s for 1020
I0827 11:34:22.294330       1 scheduler.go:451] ScheduleAlgoTime 35.979382ms Start:2018-08-27 11:34:22.258339402 +0000 UTC m=+148.127646674 End:2018-08-27 11:34:22.29431885 +0000 UTC m=+148.163626056
I0827 11:34:22.294375       1 scheduler.go:454] Total Schedule Algo cumulative time:2.900692391s for 1021
I0827 11:34:22.330956       1 scheduler.go:451] ScheduleAlgoTime 36.411489ms Start:2018-08-27 11:34:22.294534315 +0000 UTC m=+148.163841559 End:2018-08-27 11:34:22.330945864 +0000 UTC m=+148.200253048
I0827 11:34:22.330994       1 scheduler.go:454] Total Schedule Algo cumulative time:2.93710388s for 1022
I0827 11:34:22.375153       1 scheduler.go:451] ScheduleAlgoTime 43.8375ms Start:2018-08-27 11:34:22.33130683 +0000 UTC m=+148.200614081 End:2018-08-27 11:34:22.375144396 +0000 UTC m=+148.244451581
I0827 11:34:22.375202       1 scheduler.go:454] Total Schedule Algo cumulative time:2.98094138s for 1023
I0827 11:34:22.412297       1 scheduler.go:451] ScheduleAlgoTime 36.913913ms Start:2018-08-27 11:34:22.375374806 +0000 UTC m=+148.244682028 End:2018-08-27 11:34:22.412288756 +0000 UTC m=+148.281595941
I0827 11:34:22.412340       1 scheduler.go:454] Total Schedule Algo cumulative time:3.017855293s for 1024
I0827 11:34:22.448204       1 scheduler.go:451] ScheduleAlgoTime 35.664196ms Start:2018-08-27 11:34:22.412529789 +0000 UTC m=+148.281837082 End:2018-08-27 11:34:22.448194095 +0000 UTC m=+148.317501278
I0827 11:34:22.448241       1 scheduler.go:454] Total Schedule Algo cumulative time:3.053519489s for 1025
I0827 11:34:22.482004       1 scheduler.go:451] ScheduleAlgoTime 33.527618ms Start:2018-08-27 11:34:22.448461995 +0000 UTC m=+148.317769257 End:2018-08-27 11:34:22.481989438 +0000 UTC m=+148.351296875
I0827 11:34:22.482062       1 scheduler.go:454] Total Schedule Algo cumulative time:3.087047107s for 1026
I0827 11:34:22.517269       1 scheduler.go:451] ScheduleAlgoTime 34.967073ms Start:2018-08-27 11:34:22.482291409 +0000 UTC m=+148.351598641 End:2018-08-27 11:34:22.517258533 +0000 UTC m=+148.386565714
I0827 11:34:22.517324       1 scheduler.go:454] Total Schedule Algo cumulative time:3.12201418s for 1027
I0827 11:34:22.556077       1 scheduler.go:451] ScheduleAlgoTime 38.539692ms Start:2018-08-27 11:34:22.51752518 +0000 UTC m=+148.386832432 End:2018-08-27 11:34:22.55606494 +0000 UTC m=+148.425372124
I0827 11:34:22.556122       1 scheduler.go:454] Total Schedule Algo cumulative time:3.160553872s for 1028
I0827 11:34:22.597523       1 scheduler.go:451] ScheduleAlgoTime 41.216677ms Start:2018-08-27 11:34:22.556295872 +0000 UTC m=+148.425603117 End:2018-08-27 11:34:22.597512611 +0000 UTC m=+148.466819794
I0827 11:34:22.597570       1 scheduler.go:454] Total Schedule Algo cumulative time:3.201770549s for 1029
I0827 11:34:22.631416       1 scheduler.go:451] ScheduleAlgoTime 33.681616ms Start:2018-08-27 11:34:22.59772263 +0000 UTC m=+148.467029857 End:2018-08-27 11:34:22.631404289 +0000 UTC m=+148.500711473
I0827 11:34:22.631470       1 scheduler.go:454] Total Schedule Algo cumulative time:3.235452165s for 1030
I0827 11:34:22.666108       1 scheduler.go:451] ScheduleAlgoTime 34.434084ms Start:2018-08-27 11:34:22.631665426 +0000 UTC m=+148.500972680 End:2018-08-27 11:34:22.666099575 +0000 UTC m=+148.535406764
I0827 11:34:22.666186       1 scheduler.go:454] Total Schedule Algo cumulative time:3.269886249s for 1031
I0827 11:34:22.700053       1 scheduler.go:451] ScheduleAlgoTime 33.686776ms Start:2018-08-27 11:34:22.666358605 +0000 UTC m=+148.535665824 End:2018-08-27 11:34:22.70004541 +0000 UTC m=+148.569352600
I0827 11:34:22.700084       1 scheduler.go:454] Total Schedule Algo cumulative time:3.303573025s for 1032
I0827 11:34:22.739112       1 scheduler.go:451] ScheduleAlgoTime 38.815468ms Start:2018-08-27 11:34:22.700287932 +0000 UTC m=+148.569595180 End:2018-08-27 11:34:22.739103465 +0000 UTC m=+148.608410648
I0827 11:34:22.739150       1 scheduler.go:454] Total Schedule Algo cumulative time:3.342388493s for 1033
I0827 11:34:22.780476       1 scheduler.go:451] ScheduleAlgoTime 41.161464ms Start:2018-08-27 11:34:22.739305611 +0000 UTC m=+148.608612826 End:2018-08-27 11:34:22.780467108 +0000 UTC m=+148.649774290
I0827 11:34:22.780518       1 scheduler.go:454] Total Schedule Algo cumulative time:3.383549957s for 1034
I0827 11:34:22.817407       1 scheduler.go:451] ScheduleAlgoTime 36.661755ms Start:2018-08-27 11:34:22.780736107 +0000 UTC m=+148.650043364 End:2018-08-27 11:34:22.817397935 +0000 UTC m=+148.686705119
I0827 11:34:22.817450       1 scheduler.go:454] Total Schedule Algo cumulative time:3.420211712s for 1035
I0827 11:34:22.853421       1 scheduler.go:451] ScheduleAlgoTime 35.811953ms Start:2018-08-27 11:34:22.817601967 +0000 UTC m=+148.686909188 End:2018-08-27 11:34:22.853413947 +0000 UTC m=+148.722721141
I0827 11:34:22.853459       1 scheduler.go:454] Total Schedule Algo cumulative time:3.456023665s for 1036
I0827 11:34:22.885989       1 scheduler.go:451] ScheduleAlgoTime 32.333742ms Start:2018-08-27 11:34:22.853645216 +0000 UTC m=+148.722952462 End:2018-08-27 11:34:22.885979022 +0000 UTC m=+148.755286204
I0827 11:34:22.886035       1 scheduler.go:454] Total Schedule Algo cumulative time:3.488357407s for 1037
I0827 11:34:22.921254       1 scheduler.go:451] ScheduleAlgoTime 34.994878ms Start:2018-08-27 11:34:22.886250783 +0000 UTC m=+148.755558028 End:2018-08-27 11:34:22.921245724 +0000 UTC m=+148.790552906
I0827 11:34:22.921290       1 scheduler.go:454] Total Schedule Algo cumulative time:3.523352285s for 1038
I0827 11:34:22.961885       1 scheduler.go:451] ScheduleAlgoTime 40.417266ms Start:2018-08-27 11:34:22.92145652 +0000 UTC m=+148.790763778 End:2018-08-27 11:34:22.961873854 +0000 UTC m=+148.831181044
I0827 11:34:22.961937       1 scheduler.go:454] Total Schedule Algo cumulative time:3.563769551s for 1039
I0827 11:34:22.996888       1 scheduler.go:451] ScheduleAlgoTime 34.740582ms Start:2018-08-27 11:34:22.96213537 +0000 UTC m=+148.831442642 End:2018-08-27 11:34:22.996876042 +0000 UTC m=+148.866183224
I0827 11:34:22.996948       1 scheduler.go:454] Total Schedule Algo cumulative time:3.598510133s for 1040
I0827 11:34:23.030199       1 scheduler.go:451] ScheduleAlgoTime 33.064196ms Start:2018-08-27 11:34:22.997122623 +0000 UTC m=+148.866429866 End:2018-08-27 11:34:23.030186816 +0000 UTC m=+148.899494062
I0827 11:34:23.030260       1 scheduler.go:454] Total Schedule Algo cumulative time:3.631574329s for 1041
I0827 11:34:23.064609       1 scheduler.go:451] ScheduleAlgoTime 34.18326ms Start:2018-08-27 11:34:23.030416174 +0000 UTC m=+148.899723415 End:2018-08-27 11:34:23.064599491 +0000 UTC m=+148.933906675
I0827 11:34:23.064653       1 scheduler.go:454] Total Schedule Algo cumulative time:3.665757589s for 1042
I0827 11:34:23.102879       1 scheduler.go:451] ScheduleAlgoTime 38.021838ms Start:2018-08-27 11:34:23.064847434 +0000 UTC m=+148.934154688 End:2018-08-27 11:34:23.102869343 +0000 UTC m=+148.972176526
I0827 11:34:23.102917       1 scheduler.go:454] Total Schedule Algo cumulative time:3.703779427s for 1043
I0827 11:34:23.139870       1 scheduler.go:451] ScheduleAlgoTime 36.778506ms Start:2018-08-27 11:34:23.103084273 +0000 UTC m=+148.972391514 End:2018-08-27 11:34:23.139862836 +0000 UTC m=+149.009170020
I0827 11:34:23.139905       1 scheduler.go:454] Total Schedule Algo cumulative time:3.740557933s for 1044
I0827 11:34:23.180377       1 scheduler.go:451] ScheduleAlgoTime 40.23987ms Start:2018-08-27 11:34:23.140128139 +0000 UTC m=+149.009435382 End:2018-08-27 11:34:23.18036807 +0000 UTC m=+149.049675252
I0827 11:34:23.180416       1 scheduler.go:454] Total Schedule Algo cumulative time:3.780797803s for 1045
I0827 11:34:23.213212       1 scheduler.go:451] ScheduleAlgoTime 32.648031ms Start:2018-08-27 11:34:23.180556107 +0000 UTC m=+149.049863353 End:2018-08-27 11:34:23.213204198 +0000 UTC m=+149.082511384
I0827 11:34:23.213254       1 scheduler.go:454] Total Schedule Algo cumulative time:3.813445834s for 1046
I0827 11:34:23.248665       1 scheduler.go:451] ScheduleAlgoTime 35.258631ms Start:2018-08-27 11:34:23.213398747 +0000 UTC m=+149.082706020 End:2018-08-27 11:34:23.248657467 +0000 UTC m=+149.117964651
I0827 11:34:23.248718       1 scheduler.go:454] Total Schedule Algo cumulative time:3.848704465s for 1047
I0827 11:34:23.288422       1 scheduler.go:451] ScheduleAlgoTime 39.577884ms Start:2018-08-27 11:34:23.248837098 +0000 UTC m=+149.118144367 End:2018-08-27 11:34:23.288415069 +0000 UTC m=+149.157722251
I0827 11:34:23.288459       1 scheduler.go:454] Total Schedule Algo cumulative time:3.888282349s for 1048
I0827 11:34:23.324034       1 scheduler.go:451] ScheduleAlgoTime 35.43097ms Start:2018-08-27 11:34:23.288594198 +0000 UTC m=+149.157901429 End:2018-08-27 11:34:23.324025216 +0000 UTC m=+149.193332399
I0827 11:34:23.324080       1 scheduler.go:454] Total Schedule Algo cumulative time:3.923713319s for 1049
I0827 11:34:23.363802       1 scheduler.go:451] ScheduleAlgoTime 39.568518ms Start:2018-08-27 11:34:23.324222361 +0000 UTC m=+149.193529622 End:2018-08-27 11:34:23.363790948 +0000 UTC m=+149.233098140
I0827 11:34:23.363857       1 scheduler.go:454] Total Schedule Algo cumulative time:3.963281837s for 1050
I0827 11:34:23.399034       1 scheduler.go:451] ScheduleAlgoTime 35.002464ms Start:2018-08-27 11:34:23.364021124 +0000 UTC m=+149.233328403 End:2018-08-27 11:34:23.399023684 +0000 UTC m=+149.268330867
I0827 11:34:23.399092       1 scheduler.go:454] Total Schedule Algo cumulative time:3.998284301s for 1051
I0827 11:34:23.437322       1 scheduler.go:451] ScheduleAlgoTime 38.008396ms Start:2018-08-27 11:34:23.399306003 +0000 UTC m=+149.268613275 End:2018-08-27 11:34:23.437314489 +0000 UTC m=+149.306621671
I0827 11:34:23.437359       1 scheduler.go:454] Total Schedule Algo cumulative time:4.036292697s for 1052
I0827 11:34:23.472446       1 scheduler.go:451] ScheduleAlgoTime 34.892473ms Start:2018-08-27 11:34:23.437541233 +0000 UTC m=+149.306848480 End:2018-08-27 11:34:23.472433677 +0000 UTC m=+149.341740953
I0827 11:34:23.472496       1 scheduler.go:454] Total Schedule Algo cumulative time:4.07118517s for 1053
I0827 11:34:23.509127       1 scheduler.go:451] ScheduleAlgoTime 36.470977ms Start:2018-08-27 11:34:23.47264482 +0000 UTC m=+149.341952083 End:2018-08-27 11:34:23.509115873 +0000 UTC m=+149.378423060
I0827 11:34:23.509191       1 scheduler.go:454] Total Schedule Algo cumulative time:4.107656147s for 1054
I0827 11:34:23.551061       1 scheduler.go:451] ScheduleAlgoTime 41.665089ms Start:2018-08-27 11:34:23.50938692 +0000 UTC m=+149.378694154 End:2018-08-27 11:34:23.551052061 +0000 UTC m=+149.420359243
I0827 11:34:23.551100       1 scheduler.go:454] Total Schedule Algo cumulative time:4.149321236s for 1055
I0827 11:34:23.585475       1 scheduler.go:451] ScheduleAlgoTime 34.222356ms Start:2018-08-27 11:34:23.551245735 +0000 UTC m=+149.420552983 End:2018-08-27 11:34:23.585468154 +0000 UTC m=+149.454775339
I0827 11:34:23.585515       1 scheduler.go:454] Total Schedule Algo cumulative time:4.183543592s for 1056
I0827 11:34:23.617980       1 scheduler.go:451] ScheduleAlgoTime 32.32722ms Start:2018-08-27 11:34:23.585638076 +0000 UTC m=+149.454945331 End:2018-08-27 11:34:23.617965369 +0000 UTC m=+149.487272551
I0827 11:34:23.618030       1 scheduler.go:454] Total Schedule Algo cumulative time:4.215870812s for 1057
I0827 11:34:23.654885       1 scheduler.go:451] ScheduleAlgoTime 36.621934ms Start:2018-08-27 11:34:23.618254997 +0000 UTC m=+149.487562255 End:2018-08-27 11:34:23.654877005 +0000 UTC m=+149.524184189
I0827 11:34:23.654921       1 scheduler.go:454] Total Schedule Algo cumulative time:4.252492746s for 1058
I0827 11:34:23.690404       1 scheduler.go:451] ScheduleAlgoTime 35.321038ms Start:2018-08-27 11:34:23.655074866 +0000 UTC m=+149.524382113 End:2018-08-27 11:34:23.690395967 +0000 UTC m=+149.559703151
I0827 11:34:23.690449       1 scheduler.go:454] Total Schedule Algo cumulative time:4.287813784s for 1059
I0827 11:34:23.734269       1 scheduler.go:451] ScheduleAlgoTime 43.667631ms Start:2018-08-27 11:34:23.690592311 +0000 UTC m=+149.559899587 End:2018-08-27 11:34:23.734260037 +0000 UTC m=+149.603567218
I0827 11:34:23.734311       1 scheduler.go:454] Total Schedule Algo cumulative time:4.331481415s for 1060
I0827 11:34:23.773506       1 scheduler.go:451] ScheduleAlgoTime 39.046207ms Start:2018-08-27 11:34:23.734449806 +0000 UTC m=+149.603757061 End:2018-08-27 11:34:23.773496076 +0000 UTC m=+149.642803268
I0827 11:34:23.773560       1 scheduler.go:454] Total Schedule Algo cumulative time:4.370527622s for 1061
I0827 11:34:23.809023       1 scheduler.go:451] ScheduleAlgoTime 35.252816ms Start:2018-08-27 11:34:23.773761401 +0000 UTC m=+149.643068653 End:2018-08-27 11:34:23.809014286 +0000 UTC m=+149.678321469
I0827 11:34:23.809113       1 scheduler.go:454] Total Schedule Algo cumulative time:4.405780438s for 1062
I0827 11:34:23.850615       1 scheduler.go:451] ScheduleAlgoTime 41.335613ms Start:2018-08-27 11:34:23.809270154 +0000 UTC m=+149.678577397 End:2018-08-27 11:34:23.850605827 +0000 UTC m=+149.719913010
I0827 11:34:23.850653       1 scheduler.go:454] Total Schedule Algo cumulative time:4.447116051s for 1063
I0827 11:34:23.889630       1 scheduler.go:451] ScheduleAlgoTime 38.860099ms Start:2018-08-27 11:34:23.850760001 +0000 UTC m=+149.720067271 End:2018-08-27 11:34:23.88962009 +0000 UTC m=+149.758927370
I0827 11:34:23.889682       1 scheduler.go:454] Total Schedule Algo cumulative time:4.48597615s for 1064
I0827 11:34:23.929228       1 scheduler.go:451] ScheduleAlgoTime 39.438737ms Start:2018-08-27 11:34:23.889778098 +0000 UTC m=+149.759085355 End:2018-08-27 11:34:23.92921691 +0000 UTC m=+149.798524092
I0827 11:34:23.929281       1 scheduler.go:454] Total Schedule Algo cumulative time:4.525414887s for 1065
I0827 11:34:23.967536       1 scheduler.go:451] ScheduleAlgoTime 38.09683ms Start:2018-08-27 11:34:23.92943172 +0000 UTC m=+149.798738976 End:2018-08-27 11:34:23.967528623 +0000 UTC m=+149.836835806
I0827 11:34:23.967571       1 scheduler.go:454] Total Schedule Algo cumulative time:4.563511717s for 1066
I0827 11:34:24.002041       1 scheduler.go:451] ScheduleAlgoTime 34.243752ms Start:2018-08-27 11:34:23.96778799 +0000 UTC m=+149.837095311 End:2018-08-27 11:34:24.002031881 +0000 UTC m=+149.871339063
I0827 11:34:24.002081       1 scheduler.go:454] Total Schedule Algo cumulative time:4.597755469s for 1067
I0827 11:34:24.038315       1 scheduler.go:451] ScheduleAlgoTime 36.070226ms Start:2018-08-27 11:34:24.002230237 +0000 UTC m=+149.871537451 End:2018-08-27 11:34:24.038300491 +0000 UTC m=+149.907607677
I0827 11:34:24.038358       1 scheduler.go:454] Total Schedule Algo cumulative time:4.633825695s for 1068
I0827 11:34:24.073620       1 scheduler.go:451] ScheduleAlgoTime 35.092954ms Start:2018-08-27 11:34:24.038515536 +0000 UTC m=+149.907822801 End:2018-08-27 11:34:24.073608575 +0000 UTC m=+149.942915755
I0827 11:34:24.073676       1 scheduler.go:454] Total Schedule Algo cumulative time:4.668918649s for 1069
I0827 11:34:24.107903       1 scheduler.go:451] ScheduleAlgoTime 34.028772ms Start:2018-08-27 11:34:24.073867111 +0000 UTC m=+149.943174380 End:2018-08-27 11:34:24.107895971 +0000 UTC m=+149.977203152
I0827 11:34:24.107950       1 scheduler.go:454] Total Schedule Algo cumulative time:4.702947421s for 1070
I0827 11:34:24.149369       1 scheduler.go:451] ScheduleAlgoTime 41.164256ms Start:2018-08-27 11:34:24.108196821 +0000 UTC m=+149.977504099 End:2018-08-27 11:34:24.149361174 +0000 UTC m=+150.018668355
I0827 11:34:24.149404       1 scheduler.go:454] Total Schedule Algo cumulative time:4.744111677s for 1071
I0827 11:34:24.188308       1 scheduler.go:451] ScheduleAlgoTime 38.727517ms Start:2018-08-27 11:34:24.149572139 +0000 UTC m=+150.018879406 End:2018-08-27 11:34:24.188299738 +0000 UTC m=+150.057606923
I0827 11:34:24.188348       1 scheduler.go:454] Total Schedule Algo cumulative time:4.782839194s for 1072
I0827 11:34:24.223427       1 scheduler.go:451] ScheduleAlgoTime 34.953406ms Start:2018-08-27 11:34:24.188465792 +0000 UTC m=+150.057773036 End:2018-08-27 11:34:24.223419259 +0000 UTC m=+150.092726442
I0827 11:34:24.223468       1 scheduler.go:454] Total Schedule Algo cumulative time:4.8177926s for 1073
I0827 11:34:24.258873       1 scheduler.go:451] ScheduleAlgoTime 35.251399ms Start:2018-08-27 11:34:24.223606179 +0000 UTC m=+150.092913415 End:2018-08-27 11:34:24.258857567 +0000 UTC m=+150.128164814
I0827 11:34:24.258920       1 scheduler.go:454] Total Schedule Algo cumulative time:4.853043999s for 1074
I0827 11:34:24.299590       1 scheduler.go:451] ScheduleAlgoTime 40.467516ms Start:2018-08-27 11:34:24.259113807 +0000 UTC m=+150.128421026 End:2018-08-27 11:34:24.29958136 +0000 UTC m=+150.168888542
I0827 11:34:24.299660       1 scheduler.go:454] Total Schedule Algo cumulative time:4.893511515s for 1075
I0827 11:34:24.345824       1 scheduler.go:451] ScheduleAlgoTime 46.00977ms Start:2018-08-27 11:34:24.299804244 +0000 UTC m=+150.169111499 End:2018-08-27 11:34:24.34581407 +0000 UTC m=+150.215121269
I0827 11:34:24.345866       1 scheduler.go:454] Total Schedule Algo cumulative time:4.939521285s for 1076
I0827 11:34:24.389228       1 scheduler.go:451] ScheduleAlgoTime 43.207639ms Start:2018-08-27 11:34:24.346009824 +0000 UTC m=+150.215317096 End:2018-08-27 11:34:24.389217548 +0000 UTC m=+150.258524735
I0827 11:34:24.389272       1 scheduler.go:454] Total Schedule Algo cumulative time:4.982728924s for 1077
I0827 11:34:24.424220       1 scheduler.go:451] ScheduleAlgoTime 34.77947ms Start:2018-08-27 11:34:24.389429304 +0000 UTC m=+150.258736562 End:2018-08-27 11:34:24.424208846 +0000 UTC m=+150.293516032
I0827 11:34:24.424268       1 scheduler.go:454] Total Schedule Algo cumulative time:5.017508394s for 1078
I0827 11:34:24.462850       1 scheduler.go:451] ScheduleAlgoTime 38.351015ms Start:2018-08-27 11:34:24.424487066 +0000 UTC m=+150.293794309 End:2018-08-27 11:34:24.462837756 +0000 UTC m=+150.332145324
I0827 11:34:24.462927       1 scheduler.go:454] Total Schedule Algo cumulative time:5.055859409s for 1079
I0827 11:34:24.500739       1 scheduler.go:451] ScheduleAlgoTime 37.628708ms Start:2018-08-27 11:34:24.463100697 +0000 UTC m=+150.332407926 End:2018-08-27 11:34:24.500729446 +0000 UTC m=+150.370036634
I0827 11:34:24.500778       1 scheduler.go:454] Total Schedule Algo cumulative time:5.093488117s for 1080
I0827 11:34:24.542519       1 scheduler.go:451] ScheduleAlgoTime 41.572831ms Start:2018-08-27 11:34:24.500934049 +0000 UTC m=+150.370241305 End:2018-08-27 11:34:24.54250695 +0000 UTC m=+150.411814136
I0827 11:34:24.542591       1 scheduler.go:454] Total Schedule Algo cumulative time:5.135060948s for 1081
I0827 11:34:24.580161       1 scheduler.go:451] ScheduleAlgoTime 37.385775ms Start:2018-08-27 11:34:24.542767894 +0000 UTC m=+150.412075162 End:2018-08-27 11:34:24.580153752 +0000 UTC m=+150.449460937
I0827 11:34:24.580202       1 scheduler.go:454] Total Schedule Algo cumulative time:5.172446723s for 1082
I0827 11:34:24.618560       1 scheduler.go:451] ScheduleAlgoTime 38.197973ms Start:2018-08-27 11:34:24.580352761 +0000 UTC m=+150.449659971 End:2018-08-27 11:34:24.618550759 +0000 UTC m=+150.487857944
I0827 11:34:24.618592       1 scheduler.go:454] Total Schedule Algo cumulative time:5.210644696s for 1083
I0827 11:34:24.655896       1 scheduler.go:451] ScheduleAlgoTime 37.074885ms Start:2018-08-27 11:34:24.618812482 +0000 UTC m=+150.488119774 End:2018-08-27 11:34:24.655887476 +0000 UTC m=+150.525194659
I0827 11:34:24.655941       1 scheduler.go:454] Total Schedule Algo cumulative time:5.247719581s for 1084
I0827 11:34:24.693455       1 scheduler.go:451] ScheduleAlgoTime 37.338717ms Start:2018-08-27 11:34:24.656108405 +0000 UTC m=+150.525415650 End:2018-08-27 11:34:24.693447183 +0000 UTC m=+150.562754367
I0827 11:34:24.693486       1 scheduler.go:454] Total Schedule Algo cumulative time:5.285058298s for 1085
I0827 11:34:24.729575       1 scheduler.go:451] ScheduleAlgoTime 35.886547ms Start:2018-08-27 11:34:24.693680639 +0000 UTC m=+150.562987888 End:2018-08-27 11:34:24.729567251 +0000 UTC m=+150.598874435
I0827 11:34:24.729624       1 scheduler.go:454] Total Schedule Algo cumulative time:5.320944845s for 1086
I0827 11:34:24.768498       1 scheduler.go:451] ScheduleAlgoTime 38.714112ms Start:2018-08-27 11:34:24.729775623 +0000 UTC m=+150.599082869 End:2018-08-27 11:34:24.768489791 +0000 UTC m=+150.637796981
I0827 11:34:24.768538       1 scheduler.go:454] Total Schedule Algo cumulative time:5.359658957s for 1087
I0827 11:34:24.806231       1 scheduler.go:451] ScheduleAlgoTime 37.51173ms Start:2018-08-27 11:34:24.768706472 +0000 UTC m=+150.638013677 End:2018-08-27 11:34:24.806218219 +0000 UTC m=+150.675525407
I0827 11:34:24.806286       1 scheduler.go:454] Total Schedule Algo cumulative time:5.397170687s for 1088
I0827 11:34:24.847977       1 scheduler.go:451] ScheduleAlgoTime 41.543429ms Start:2018-08-27 11:34:24.806423415 +0000 UTC m=+150.675730661 End:2018-08-27 11:34:24.847966907 +0000 UTC m=+150.717274090
I0827 11:34:24.848020       1 scheduler.go:454] Total Schedule Algo cumulative time:5.438714116s for 1089
I0827 11:34:24.886594       1 scheduler.go:451] ScheduleAlgoTime 38.415937ms Start:2018-08-27 11:34:24.848169255 +0000 UTC m=+150.717476478 End:2018-08-27 11:34:24.886585231 +0000 UTC m=+150.755892415
I0827 11:34:24.886629       1 scheduler.go:454] Total Schedule Algo cumulative time:5.477130053s for 1090
I0827 11:34:24.921155       1 scheduler.go:451] ScheduleAlgoTime 34.289666ms Start:2018-08-27 11:34:24.886856299 +0000 UTC m=+150.756163519 End:2018-08-27 11:34:24.921145998 +0000 UTC m=+150.790453185
I0827 11:34:24.921198       1 scheduler.go:454] Total Schedule Algo cumulative time:5.511419719s for 1091
I0827 11:34:24.967562       1 scheduler.go:451] ScheduleAlgoTime 46.187895ms Start:2018-08-27 11:34:24.921364846 +0000 UTC m=+150.790672095 End:2018-08-27 11:34:24.967552805 +0000 UTC m=+150.836859990
I0827 11:34:24.967605       1 scheduler.go:454] Total Schedule Algo cumulative time:5.557607614s for 1092
I0827 11:34:25.002639       1 scheduler.go:451] ScheduleAlgoTime 34.830906ms Start:2018-08-27 11:34:24.967798174 +0000 UTC m=+150.837105413 End:2018-08-27 11:34:25.002629134 +0000 UTC m=+150.871936319
I0827 11:34:25.002708       1 scheduler.go:454] Total Schedule Algo cumulative time:5.59243852s for 1093
I0827 11:34:25.037401       1 scheduler.go:451] ScheduleAlgoTime 34.493021ms Start:2018-08-27 11:34:25.002899233 +0000 UTC m=+150.872206525 End:2018-08-27 11:34:25.03739236 +0000 UTC m=+150.906699546
I0827 11:34:25.037459       1 scheduler.go:454] Total Schedule Algo cumulative time:5.626931541s for 1094
I0827 11:34:25.075070       1 scheduler.go:451] ScheduleAlgoTime 37.450584ms Start:2018-08-27 11:34:25.037607433 +0000 UTC m=+150.906914659 End:2018-08-27 11:34:25.075058008 +0000 UTC m=+150.944365243
I0827 11:34:25.075124       1 scheduler.go:454] Total Schedule Algo cumulative time:5.664382125s for 1095
I0827 11:34:25.113491       1 scheduler.go:451] ScheduleAlgoTime 38.191723ms Start:2018-08-27 11:34:25.075291589 +0000 UTC m=+150.944598830 End:2018-08-27 11:34:25.113483369 +0000 UTC m=+150.982790553
I0827 11:34:25.113528       1 scheduler.go:454] Total Schedule Algo cumulative time:5.702573848s for 1096
I0827 11:34:25.162441       1 scheduler.go:451] ScheduleAlgoTime 48.721982ms Start:2018-08-27 11:34:25.113710435 +0000 UTC m=+150.983017675 End:2018-08-27 11:34:25.162432474 +0000 UTC m=+151.031739657
I0827 11:34:25.162482       1 scheduler.go:454] Total Schedule Algo cumulative time:5.75129583s for 1097
I0827 11:34:25.201184       1 scheduler.go:451] ScheduleAlgoTime 38.516661ms Start:2018-08-27 11:34:25.162659349 +0000 UTC m=+151.031966586 End:2018-08-27 11:34:25.20117606 +0000 UTC m=+151.070483247
I0827 11:34:25.201225       1 scheduler.go:454] Total Schedule Algo cumulative time:5.789812491s for 1098
I0827 11:34:25.238934       1 scheduler.go:451] ScheduleAlgoTime 37.572469ms Start:2018-08-27 11:34:25.201354458 +0000 UTC m=+151.070661661 End:2018-08-27 11:34:25.238926943 +0000 UTC m=+151.108234130
I0827 11:34:25.238983       1 scheduler.go:454] Total Schedule Algo cumulative time:5.82738496s for 1099
I0827 11:34:25.275598       1 scheduler.go:451] ScheduleAlgoTime 36.424413ms Start:2018-08-27 11:34:25.239162314 +0000 UTC m=+151.108469561 End:2018-08-27 11:34:25.27558679 +0000 UTC m=+151.144893974
I0827 11:34:25.275676       1 scheduler.go:454] Total Schedule Algo cumulative time:5.863809373s for 1100
I0827 11:34:25.311100       1 scheduler.go:451] ScheduleAlgoTime 35.233148ms Start:2018-08-27 11:34:25.275856936 +0000 UTC m=+151.145164204 End:2018-08-27 11:34:25.311090072 +0000 UTC m=+151.180397352
I0827 11:34:25.311140       1 scheduler.go:454] Total Schedule Algo cumulative time:5.899042521s for 1101
I0827 11:34:25.352500       1 scheduler.go:451] ScheduleAlgoTime 41.154619ms Start:2018-08-27 11:34:25.311335366 +0000 UTC m=+151.180642634 End:2018-08-27 11:34:25.35249006 +0000 UTC m=+151.221797253
I0827 11:34:25.352549       1 scheduler.go:454] Total Schedule Algo cumulative time:5.94019714s for 1102
I0827 11:34:25.392141       1 scheduler.go:451] ScheduleAlgoTime 39.427898ms Start:2018-08-27 11:34:25.352705021 +0000 UTC m=+151.222012257 End:2018-08-27 11:34:25.392132971 +0000 UTC m=+151.261440155
I0827 11:34:25.392182       1 scheduler.go:454] Total Schedule Algo cumulative time:5.979625038s for 1103
I0827 11:34:25.427143       1 scheduler.go:451] ScheduleAlgoTime 34.786048ms Start:2018-08-27 11:34:25.392348944 +0000 UTC m=+151.261656206 End:2018-08-27 11:34:25.42713507 +0000 UTC m=+151.296442254
I0827 11:34:25.427193       1 scheduler.go:454] Total Schedule Algo cumulative time:6.014411086s for 1104
I0827 11:34:25.462238       1 scheduler.go:451] ScheduleAlgoTime 34.875353ms Start:2018-08-27 11:34:25.427351057 +0000 UTC m=+151.296658314 End:2018-08-27 11:34:25.462226485 +0000 UTC m=+151.331533667
I0827 11:34:25.462280       1 scheduler.go:454] Total Schedule Algo cumulative time:6.049286439s for 1105
I0827 11:34:25.498084       1 scheduler.go:451] ScheduleAlgoTime 35.655863ms Start:2018-08-27 11:34:25.462417475 +0000 UTC m=+151.331724736 End:2018-08-27 11:34:25.49807341 +0000 UTC m=+151.367380599
I0827 11:34:25.498127       1 scheduler.go:454] Total Schedule Algo cumulative time:6.084942302s for 1106
I0827 11:34:25.539206       1 scheduler.go:451] ScheduleAlgoTime 40.928193ms Start:2018-08-27 11:34:25.498269076 +0000 UTC m=+151.367576323 End:2018-08-27 11:34:25.539197332 +0000 UTC m=+151.408504516
I0827 11:34:25.539247       1 scheduler.go:454] Total Schedule Algo cumulative time:6.125870495s for 1107
I0827 11:34:25.580928       1 scheduler.go:451] ScheduleAlgoTime 41.515655ms Start:2018-08-27 11:34:25.539395564 +0000 UTC m=+151.408702833 End:2018-08-27 11:34:25.580911224 +0000 UTC m=+151.450218488
I0827 11:34:25.580971       1 scheduler.go:454] Total Schedule Algo cumulative time:6.16738615s for 1108
I0827 11:34:25.616057       1 scheduler.go:451] ScheduleAlgoTime 34.902675ms Start:2018-08-27 11:34:25.581146271 +0000 UTC m=+151.450453526 End:2018-08-27 11:34:25.616049018 +0000 UTC m=+151.485356201
I0827 11:34:25.616095       1 scheduler.go:454] Total Schedule Algo cumulative time:6.202288825s for 1109
I0827 11:34:25.652502       1 scheduler.go:451] ScheduleAlgoTime 36.183464ms Start:2018-08-27 11:34:25.616307551 +0000 UTC m=+151.485614771 End:2018-08-27 11:34:25.652491046 +0000 UTC m=+151.521798235
I0827 11:34:25.652553       1 scheduler.go:454] Total Schedule Algo cumulative time:6.238472289s for 1110
I0827 11:34:25.689022       1 scheduler.go:451] ScheduleAlgoTime 36.28419ms Start:2018-08-27 11:34:25.652728741 +0000 UTC m=+151.522036009 End:2018-08-27 11:34:25.689013015 +0000 UTC m=+151.558320199
I0827 11:34:25.689071       1 scheduler.go:454] Total Schedule Algo cumulative time:6.274756479s for 1111
I0827 11:34:25.727608       1 scheduler.go:451] ScheduleAlgoTime 38.401615ms Start:2018-08-27 11:34:25.689196762 +0000 UTC m=+151.558504002 End:2018-08-27 11:34:25.727598435 +0000 UTC m=+151.596905617
I0827 11:34:25.727675       1 scheduler.go:454] Total Schedule Algo cumulative time:6.313158094s for 1112
I0827 11:34:25.770316       1 scheduler.go:451] ScheduleAlgoTime 42.317107ms Start:2018-08-27 11:34:25.727989571 +0000 UTC m=+151.597296807 End:2018-08-27 11:34:25.770306731 +0000 UTC m=+151.639613914
I0827 11:34:25.770354       1 scheduler.go:454] Total Schedule Algo cumulative time:6.355475201s for 1113
I0827 11:34:25.810399       1 scheduler.go:451] ScheduleAlgoTime 39.900829ms Start:2018-08-27 11:34:25.770490337 +0000 UTC m=+151.639797593 End:2018-08-27 11:34:25.810391241 +0000 UTC m=+151.679698422
I0827 11:34:25.810444       1 scheduler.go:454] Total Schedule Algo cumulative time:6.39537603s for 1114
I0827 11:34:25.847601       1 scheduler.go:451] ScheduleAlgoTime 37.024295ms Start:2018-08-27 11:34:25.810563141 +0000 UTC m=+151.679870368 End:2018-08-27 11:34:25.847587208 +0000 UTC m=+151.716894663
I0827 11:34:25.847674       1 scheduler.go:454] Total Schedule Algo cumulative time:6.432400325s for 1115
I0827 11:34:25.882862       1 scheduler.go:451] ScheduleAlgoTime 35.006437ms Start:2018-08-27 11:34:25.847846402 +0000 UTC m=+151.717153656 End:2018-08-27 11:34:25.882852908 +0000 UTC m=+151.752160093
I0827 11:34:25.882894       1 scheduler.go:454] Total Schedule Algo cumulative time:6.467406762s for 1116
I0827 11:34:25.921818       1 scheduler.go:451] ScheduleAlgoTime 38.776253ms Start:2018-08-27 11:34:25.883032496 +0000 UTC m=+151.752339740 End:2018-08-27 11:34:25.921808808 +0000 UTC m=+151.791115993
I0827 11:34:25.921847       1 scheduler.go:454] Total Schedule Algo cumulative time:6.506183015s for 1117
I0827 11:34:25.966875       1 scheduler.go:451] ScheduleAlgoTime 44.866375ms Start:2018-08-27 11:34:25.921999881 +0000 UTC m=+151.791307081 End:2018-08-27 11:34:25.966866261 +0000 UTC m=+151.836173456
I0827 11:34:25.966918       1 scheduler.go:454] Total Schedule Algo cumulative time:6.55104939s for 1118
I0827 11:34:26.003926       1 scheduler.go:451] ScheduleAlgoTime 36.803702ms Start:2018-08-27 11:34:25.967110886 +0000 UTC m=+151.836418160 End:2018-08-27 11:34:26.003914679 +0000 UTC m=+151.873221862
I0827 11:34:26.003973       1 scheduler.go:454] Total Schedule Algo cumulative time:6.587853092s for 1119
I0827 11:34:26.043324       1 scheduler.go:451] ScheduleAlgoTime 39.169589ms Start:2018-08-27 11:34:26.00414687 +0000 UTC m=+151.873454146 End:2018-08-27 11:34:26.043316549 +0000 UTC m=+151.912623735
I0827 11:34:26.043364       1 scheduler.go:454] Total Schedule Algo cumulative time:6.627022681s for 1120
I0827 11:34:26.082346       1 scheduler.go:451] ScheduleAlgoTime 38.798431ms Start:2018-08-27 11:34:26.043538714 +0000 UTC m=+151.912846025 End:2018-08-27 11:34:26.082337275 +0000 UTC m=+151.951644456
I0827 11:34:26.082495       1 scheduler.go:454] Total Schedule Algo cumulative time:6.665821112s for 1121
I0827 11:34:26.119604       1 scheduler.go:451] ScheduleAlgoTime 36.958277ms Start:2018-08-27 11:34:26.082633777 +0000 UTC m=+151.951940983 End:2018-08-27 11:34:26.119592076 +0000 UTC m=+151.988899260
I0827 11:34:26.119678       1 scheduler.go:454] Total Schedule Algo cumulative time:6.702779389s for 1122
I0827 11:34:26.162121       1 scheduler.go:451] ScheduleAlgoTime 42.265084ms Start:2018-08-27 11:34:26.119846684 +0000 UTC m=+151.989153882 End:2018-08-27 11:34:26.162111768 +0000 UTC m=+152.031418966
I0827 11:34:26.162193       1 scheduler.go:454] Total Schedule Algo cumulative time:6.745044473s for 1123
I0827 11:34:26.208511       1 scheduler.go:451] ScheduleAlgoTime 43.7147ms Start:2018-08-27 11:34:26.164786502 +0000 UTC m=+152.034093731 End:2018-08-27 11:34:26.208501249 +0000 UTC m=+152.077808431
I0827 11:34:26.208549       1 scheduler.go:454] Total Schedule Algo cumulative time:6.788759173s for 1124
I0827 11:34:26.245656       1 scheduler.go:451] ScheduleAlgoTime 36.89855ms Start:2018-08-27 11:34:26.208746654 +0000 UTC m=+152.078053953 End:2018-08-27 11:34:26.245645322 +0000 UTC m=+152.114952503
I0827 11:34:26.245705       1 scheduler.go:454] Total Schedule Algo cumulative time:6.825657723s for 1125
I0827 11:34:26.283999       1 scheduler.go:451] ScheduleAlgoTime 38.142433ms Start:2018-08-27 11:34:26.245844312 +0000 UTC m=+152.115151579 End:2018-08-27 11:34:26.28398683 +0000 UTC m=+152.153294012
I0827 11:34:26.284055       1 scheduler.go:454] Total Schedule Algo cumulative time:6.863800156s for 1126
I0827 11:34:26.321810       1 scheduler.go:451] ScheduleAlgoTime 37.605597ms Start:2018-08-27 11:34:26.284195607 +0000 UTC m=+152.153502889 End:2018-08-27 11:34:26.321801303 +0000 UTC m=+152.191108486
I0827 11:34:26.321844       1 scheduler.go:454] Total Schedule Algo cumulative time:6.901405753s for 1127
I0827 11:34:26.360045       1 scheduler.go:451] ScheduleAlgoTime 38.05385ms Start:2018-08-27 11:34:26.321982472 +0000 UTC m=+152.191289745 End:2018-08-27 11:34:26.360036411 +0000 UTC m=+152.229343595
I0827 11:34:26.360095       1 scheduler.go:454] Total Schedule Algo cumulative time:6.939459603s for 1128
I0827 11:34:26.404707       1 scheduler.go:451] ScheduleAlgoTime 44.434837ms Start:2018-08-27 11:34:26.360263344 +0000 UTC m=+152.229570616 End:2018-08-27 11:34:26.40469827 +0000 UTC m=+152.274005453
I0827 11:34:26.404753       1 scheduler.go:454] Total Schedule Algo cumulative time:6.98389444s for 1129
I0827 11:34:26.440221       1 scheduler.go:451] ScheduleAlgoTime 35.243392ms Start:2018-08-27 11:34:26.404967045 +0000 UTC m=+152.274274314 End:2018-08-27 11:34:26.440210523 +0000 UTC m=+152.309517706
I0827 11:34:26.440294       1 scheduler.go:454] Total Schedule Algo cumulative time:7.019137832s for 1130
I0827 11:34:26.478266       1 scheduler.go:451] ScheduleAlgoTime 37.789235ms Start:2018-08-27 11:34:26.44046768 +0000 UTC m=+152.309774899 End:2018-08-27 11:34:26.478256948 +0000 UTC m=+152.347564134
I0827 11:34:26.478310       1 scheduler.go:454] Total Schedule Algo cumulative time:7.056927067s for 1131
I0827 11:34:26.514381       1 scheduler.go:451] ScheduleAlgoTime 35.882708ms Start:2018-08-27 11:34:26.478489716 +0000 UTC m=+152.347796958 End:2018-08-27 11:34:26.51437248 +0000 UTC m=+152.383679666
I0827 11:34:26.514416       1 scheduler.go:454] Total Schedule Algo cumulative time:7.092809775s for 1132
I0827 11:34:26.552006       1 scheduler.go:451] ScheduleAlgoTime 37.275952ms Start:2018-08-27 11:34:26.514722621 +0000 UTC m=+152.384029876 End:2018-08-27 11:34:26.551998647 +0000 UTC m=+152.421305828
I0827 11:34:26.552043       1 scheduler.go:454] Total Schedule Algo cumulative time:7.130085727s for 1133
I0827 11:34:26.595239       1 scheduler.go:451] ScheduleAlgoTime 43.063462ms Start:2018-08-27 11:34:26.552167148 +0000 UTC m=+152.421474413 End:2018-08-27 11:34:26.595230694 +0000 UTC m=+152.464537875
I0827 11:34:26.595290       1 scheduler.go:454] Total Schedule Algo cumulative time:7.173149189s for 1134
I0827 11:34:26.632704       1 scheduler.go:451] ScheduleAlgoTime 37.250812ms Start:2018-08-27 11:34:26.595433659 +0000 UTC m=+152.464740887 End:2018-08-27 11:34:26.632684491 +0000 UTC m=+152.501991699
I0827 11:34:26.632753       1 scheduler.go:454] Total Schedule Algo cumulative time:7.210400001s for 1135
I0827 11:34:26.668190       1 scheduler.go:451] ScheduleAlgoTime 35.220586ms Start:2018-08-27 11:34:26.632961524 +0000 UTC m=+152.502268775 End:2018-08-27 11:34:26.668182178 +0000 UTC m=+152.537489361
I0827 11:34:26.668235       1 scheduler.go:454] Total Schedule Algo cumulative time:7.245620587s for 1136
I0827 11:34:26.706190       1 scheduler.go:451] ScheduleAlgoTime 37.786947ms Start:2018-08-27 11:34:26.668395135 +0000 UTC m=+152.537702421 End:2018-08-27 11:34:26.706182186 +0000 UTC m=+152.575489368
I0827 11:34:26.706231       1 scheduler.go:454] Total Schedule Algo cumulative time:7.283407534s for 1137
I0827 11:34:26.742809       1 scheduler.go:451] ScheduleAlgoTime 36.448303ms Start:2018-08-27 11:34:26.706351003 +0000 UTC m=+152.575658322 End:2018-08-27 11:34:26.742799442 +0000 UTC m=+152.612106625
I0827 11:34:26.742849       1 scheduler.go:454] Total Schedule Algo cumulative time:7.319855837s for 1138
I0827 11:34:26.783614       1 scheduler.go:451] ScheduleAlgoTime 40.599826ms Start:2018-08-27 11:34:26.743000137 +0000 UTC m=+152.612307368 End:2018-08-27 11:34:26.783599997 +0000 UTC m=+152.652907194
I0827 11:34:26.783734       1 scheduler.go:454] Total Schedule Algo cumulative time:7.360455663s for 1139
I0827 11:34:26.825372       1 scheduler.go:451] ScheduleAlgoTime 39.233075ms Start:2018-08-27 11:34:26.786128091 +0000 UTC m=+152.655435337 End:2018-08-27 11:34:26.825361229 +0000 UTC m=+152.694668412
I0827 11:34:26.825414       1 scheduler.go:454] Total Schedule Algo cumulative time:7.399688738s for 1140
I0827 11:34:26.864523       1 scheduler.go:451] ScheduleAlgoTime 38.967142ms Start:2018-08-27 11:34:26.825545746 +0000 UTC m=+152.694852997 End:2018-08-27 11:34:26.864512954 +0000 UTC m=+152.733820139
I0827 11:34:26.864578       1 scheduler.go:454] Total Schedule Algo cumulative time:7.43865588s for 1141
I0827 11:34:26.901045       1 scheduler.go:451] ScheduleAlgoTime 36.303438ms Start:2018-08-27 11:34:26.864733283 +0000 UTC m=+152.734040526 End:2018-08-27 11:34:26.901036782 +0000 UTC m=+152.770343964
I0827 11:34:26.901083       1 scheduler.go:454] Total Schedule Algo cumulative time:7.474959318s for 1142
I0827 11:34:26.940798       1 scheduler.go:451] ScheduleAlgoTime 39.490419ms Start:2018-08-27 11:34:26.901259523 +0000 UTC m=+152.770566775 End:2018-08-27 11:34:26.940750006 +0000 UTC m=+152.810057194
I0827 11:34:26.940841       1 scheduler.go:454] Total Schedule Algo cumulative time:7.514449737s for 1143
I0827 11:34:26.976620       1 scheduler.go:451] ScheduleAlgoTime 35.647033ms Start:2018-08-27 11:34:26.940964949 +0000 UTC m=+152.810272209 End:2018-08-27 11:34:26.97661206 +0000 UTC m=+152.845919242
I0827 11:34:26.976659       1 scheduler.go:454] Total Schedule Algo cumulative time:7.55009677s for 1144
I0827 11:34:27.019422       1 scheduler.go:451] ScheduleAlgoTime 42.607075ms Start:2018-08-27 11:34:26.976801746 +0000 UTC m=+152.846108999 End:2018-08-27 11:34:27.019408892 +0000 UTC m=+152.888716074
I0827 11:34:27.019460       1 scheduler.go:454] Total Schedule Algo cumulative time:7.592703845s for 1145
I0827 11:34:27.057405       1 scheduler.go:451] ScheduleAlgoTime 37.80894ms Start:2018-08-27 11:34:27.019587819 +0000 UTC m=+152.888895082 End:2018-08-27 11:34:27.05739684 +0000 UTC m=+152.926704022
I0827 11:34:27.057450       1 scheduler.go:454] Total Schedule Algo cumulative time:7.630512785s for 1146
I0827 11:34:27.096778       1 scheduler.go:451] ScheduleAlgoTime 39.175717ms Start:2018-08-27 11:34:27.057591451 +0000 UTC m=+152.926898703 End:2018-08-27 11:34:27.096767234 +0000 UTC m=+152.966074420
I0827 11:34:27.096820       1 scheduler.go:454] Total Schedule Algo cumulative time:7.669688502s for 1147
I0827 11:34:27.134991       1 scheduler.go:451] ScheduleAlgoTime 37.97916ms Start:2018-08-27 11:34:27.096995915 +0000 UTC m=+152.966303161 End:2018-08-27 11:34:27.134975137 +0000 UTC m=+153.004282321
I0827 11:34:27.135037       1 scheduler.go:454] Total Schedule Algo cumulative time:7.707667662s for 1148
I0827 11:34:27.172245       1 scheduler.go:451] ScheduleAlgoTime 37.015397ms Start:2018-08-27 11:34:27.135221709 +0000 UTC m=+153.004528914 End:2018-08-27 11:34:27.172237128 +0000 UTC m=+153.041544311
I0827 11:34:27.172289       1 scheduler.go:454] Total Schedule Algo cumulative time:7.744683059s for 1149
I0827 11:34:27.218337       1 scheduler.go:451] ScheduleAlgoTime 45.882671ms Start:2018-08-27 11:34:27.172444169 +0000 UTC m=+153.041751425 End:2018-08-27 11:34:27.218326914 +0000 UTC m=+153.087634096
I0827 11:34:27.218384       1 scheduler.go:454] Total Schedule Algo cumulative time:7.79056573s for 1150
I0827 11:34:27.257141       1 scheduler.go:451] ScheduleAlgoTime 38.58779ms Start:2018-08-27 11:34:27.218542825 +0000 UTC m=+153.087850082 End:2018-08-27 11:34:27.257130687 +0000 UTC m=+153.126437872
I0827 11:34:27.257192       1 scheduler.go:454] Total Schedule Algo cumulative time:7.82915352s for 1151
I0827 11:34:27.296926       1 scheduler.go:451] ScheduleAlgoTime 39.544718ms Start:2018-08-27 11:34:27.257370846 +0000 UTC m=+153.126678077 End:2018-08-27 11:34:27.296915607 +0000 UTC m=+153.166222795
I0827 11:34:27.296979       1 scheduler.go:454] Total Schedule Algo cumulative time:7.868698238s for 1152
I0827 11:34:27.333393       1 scheduler.go:451] ScheduleAlgoTime 36.235998ms Start:2018-08-27 11:34:27.297149161 +0000 UTC m=+153.166456413 End:2018-08-27 11:34:27.333385228 +0000 UTC m=+153.202692411
I0827 11:34:27.333427       1 scheduler.go:454] Total Schedule Algo cumulative time:7.904934236s for 1153
I0827 11:34:27.370712       1 scheduler.go:451] ScheduleAlgoTime 37.137198ms Start:2018-08-27 11:34:27.333564396 +0000 UTC m=+153.202871660 End:2018-08-27 11:34:27.370701676 +0000 UTC m=+153.240008858
I0827 11:34:27.370760       1 scheduler.go:454] Total Schedule Algo cumulative time:7.942071434s for 1154
I0827 11:34:27.414793       1 scheduler.go:451] ScheduleAlgoTime 43.869939ms Start:2018-08-27 11:34:27.370910826 +0000 UTC m=+153.240218066 End:2018-08-27 11:34:27.414780823 +0000 UTC m=+153.284088005
I0827 11:34:27.414850       1 scheduler.go:454] Total Schedule Algo cumulative time:7.985941373s for 1155
I0827 11:34:27.450811       1 scheduler.go:451] ScheduleAlgoTime 35.806927ms Start:2018-08-27 11:34:27.414994932 +0000 UTC m=+153.284302198 End:2018-08-27 11:34:27.450801943 +0000 UTC m=+153.320109125
I0827 11:34:27.450881       1 scheduler.go:454] Total Schedule Algo cumulative time:8.0217483s for 1156
I0827 11:34:27.487327       1 scheduler.go:451] ScheduleAlgoTime 36.271896ms Start:2018-08-27 11:34:27.451046457 +0000 UTC m=+153.320353702 End:2018-08-27 11:34:27.487318415 +0000 UTC m=+153.356625598
I0827 11:34:27.487372       1 scheduler.go:454] Total Schedule Algo cumulative time:8.058020196s for 1157
I0827 11:34:27.524685       1 scheduler.go:451] ScheduleAlgoTime 37.177503ms Start:2018-08-27 11:34:27.487497873 +0000 UTC m=+153.356805128 End:2018-08-27 11:34:27.52467545 +0000 UTC m=+153.393982631
I0827 11:34:27.524744       1 scheduler.go:454] Total Schedule Algo cumulative time:8.095197699s for 1158
I0827 11:34:27.562487       1 scheduler.go:451] ScheduleAlgoTime 37.395571ms Start:2018-08-27 11:34:27.525081785 +0000 UTC m=+153.394389027 End:2018-08-27 11:34:27.562477411 +0000 UTC m=+153.431784598
I0827 11:34:27.562537       1 scheduler.go:454] Total Schedule Algo cumulative time:8.13259327s for 1159
I0827 11:34:27.601045       1 scheduler.go:451] ScheduleAlgoTime 38.318404ms Start:2018-08-27 11:34:27.562715361 +0000 UTC m=+153.432022588 End:2018-08-27 11:34:27.601033805 +0000 UTC m=+153.470340992
I0827 11:34:27.601095       1 scheduler.go:454] Total Schedule Algo cumulative time:8.170911674s for 1160
I0827 11:34:27.662189       1 scheduler.go:451] ScheduleAlgoTime 60.933006ms Start:2018-08-27 11:34:27.601247014 +0000 UTC m=+153.470554253 End:2018-08-27 11:34:27.662180072 +0000 UTC m=+153.531487259
I0827 11:34:27.662256       1 scheduler.go:454] Total Schedule Algo cumulative time:8.23184468s for 1161
I0827 11:34:27.698227       1 scheduler.go:451] ScheduleAlgoTime 35.807407ms Start:2018-08-27 11:34:27.662411056 +0000 UTC m=+153.531718315 End:2018-08-27 11:34:27.69821854 +0000 UTC m=+153.567525722
I0827 11:34:27.698260       1 scheduler.go:454] Total Schedule Algo cumulative time:8.267652087s for 1162
I0827 11:34:27.735068       1 scheduler.go:451] ScheduleAlgoTime 36.652826ms Start:2018-08-27 11:34:27.698405185 +0000 UTC m=+153.567712436 End:2018-08-27 11:34:27.735058078 +0000 UTC m=+153.604365262
I0827 11:34:27.735127       1 scheduler.go:454] Total Schedule Algo cumulative time:8.304304913s for 1163
I0827 11:34:27.778430       1 scheduler.go:451] ScheduleAlgoTime 43.141886ms Start:2018-08-27 11:34:27.735280245 +0000 UTC m=+153.604587490 End:2018-08-27 11:34:27.778422194 +0000 UTC m=+153.647729376
I0827 11:34:27.778473       1 scheduler.go:454] Total Schedule Algo cumulative time:8.347446799s for 1164
I0827 11:34:27.815815       1 scheduler.go:451] ScheduleAlgoTime 37.156622ms Start:2018-08-27 11:34:27.778649388 +0000 UTC m=+153.647956648 End:2018-08-27 11:34:27.815806088 +0000 UTC m=+153.685113270
I0827 11:34:27.815866       1 scheduler.go:454] Total Schedule Algo cumulative time:8.384603421s for 1165
I0827 11:34:27.859198       1 scheduler.go:451] ScheduleAlgoTime 43.196144ms Start:2018-08-27 11:34:27.815993171 +0000 UTC m=+153.685300406 End:2018-08-27 11:34:27.859189369 +0000 UTC m=+153.728496550
I0827 11:34:27.859238       1 scheduler.go:454] Total Schedule Algo cumulative time:8.427799565s for 1166
I0827 11:34:27.896410       1 scheduler.go:451] ScheduleAlgoTime 36.982224ms Start:2018-08-27 11:34:27.859419151 +0000 UTC m=+153.728726410 End:2018-08-27 11:34:27.89640145 +0000 UTC m=+153.765708634
I0827 11:34:27.896450       1 scheduler.go:454] Total Schedule Algo cumulative time:8.464781789s for 1167
I0827 11:34:27.935279       1 scheduler.go:451] ScheduleAlgoTime 38.674835ms Start:2018-08-27 11:34:27.896594956 +0000 UTC m=+153.765902210 End:2018-08-27 11:34:27.93526985 +0000 UTC m=+153.804577045
I0827 11:34:27.935340       1 scheduler.go:454] Total Schedule Algo cumulative time:8.503456624s for 1168
I0827 11:34:27.978052       1 scheduler.go:451] ScheduleAlgoTime 42.530006ms Start:2018-08-27 11:34:27.93551266 +0000 UTC m=+153.804819939 End:2018-08-27 11:34:27.978042763 +0000 UTC m=+153.847349945
I0827 11:34:27.978099       1 scheduler.go:454] Total Schedule Algo cumulative time:8.54598663s for 1169
I0827 11:34:28.016527       1 scheduler.go:451] ScheduleAlgoTime 38.275372ms Start:2018-08-27 11:34:27.978243042 +0000 UTC m=+153.847550297 End:2018-08-27 11:34:28.016518484 +0000 UTC m=+153.885825669
I0827 11:34:28.016563       1 scheduler.go:454] Total Schedule Algo cumulative time:8.584262002s for 1170
I0827 11:34:28.074127       1 scheduler.go:451] ScheduleAlgoTime 57.412502ms Start:2018-08-27 11:34:28.016705684 +0000 UTC m=+153.886012933 End:2018-08-27 11:34:28.074118253 +0000 UTC m=+153.943425435
I0827 11:34:28.074167       1 scheduler.go:454] Total Schedule Algo cumulative time:8.641674504s for 1171
I0827 11:34:28.116707       1 scheduler.go:451] ScheduleAlgoTime 41.83332ms Start:2018-08-27 11:34:28.074861677 +0000 UTC m=+153.944168906 End:2018-08-27 11:34:28.116695043 +0000 UTC m=+153.986002226
I0827 11:34:28.116764       1 scheduler.go:454] Total Schedule Algo cumulative time:8.683507824s for 1172
I0827 11:34:28.158588       1 scheduler.go:451] ScheduleAlgoTime 41.557211ms Start:2018-08-27 11:34:28.117020248 +0000 UTC m=+153.986327527 End:2018-08-27 11:34:28.158577555 +0000 UTC m=+154.027884738
I0827 11:34:28.158645       1 scheduler.go:454] Total Schedule Algo cumulative time:8.725065035s for 1173
I0827 11:34:28.199083       1 scheduler.go:451] ScheduleAlgoTime 40.158467ms Start:2018-08-27 11:34:28.158913498 +0000 UTC m=+154.028220754 End:2018-08-27 11:34:28.199072035 +0000 UTC m=+154.068379221
I0827 11:34:28.199144       1 scheduler.go:454] Total Schedule Algo cumulative time:8.765223502s for 1174
I0827 11:34:28.235916       1 scheduler.go:451] ScheduleAlgoTime 36.477943ms Start:2018-08-27 11:34:28.199428709 +0000 UTC m=+154.068735952 End:2018-08-27 11:34:28.235906712 +0000 UTC m=+154.105213895
I0827 11:34:28.235956       1 scheduler.go:454] Total Schedule Algo cumulative time:8.801701445s for 1175
I0827 11:34:28.274037       1 scheduler.go:451] ScheduleAlgoTime 37.851145ms Start:2018-08-27 11:34:28.236177769 +0000 UTC m=+154.105485033 End:2018-08-27 11:34:28.274028995 +0000 UTC m=+154.143336178
I0827 11:34:28.274078       1 scheduler.go:454] Total Schedule Algo cumulative time:8.83955259s for 1176
I0827 11:34:28.319762       1 scheduler.go:451] ScheduleAlgoTime 45.511425ms Start:2018-08-27 11:34:28.274225307 +0000 UTC m=+154.143532518 End:2018-08-27 11:34:28.319736741 +0000 UTC m=+154.189043943
I0827 11:34:28.319800       1 scheduler.go:454] Total Schedule Algo cumulative time:8.885064015s for 1177
I0827 11:34:28.357091       1 scheduler.go:451] ScheduleAlgoTime 36.967252ms Start:2018-08-27 11:34:28.320112809 +0000 UTC m=+154.189420077 End:2018-08-27 11:34:28.357079723 +0000 UTC m=+154.226387329
I0827 11:34:28.357152       1 scheduler.go:454] Total Schedule Algo cumulative time:8.922031267s for 1178
I0827 11:34:28.397147       1 scheduler.go:451] ScheduleAlgoTime 39.820511ms Start:2018-08-27 11:34:28.357316361 +0000 UTC m=+154.226623644 End:2018-08-27 11:34:28.397136971 +0000 UTC m=+154.266444155
I0827 11:34:28.397204       1 scheduler.go:454] Total Schedule Algo cumulative time:8.961851778s for 1179
I0827 11:34:28.438268       1 scheduler.go:451] ScheduleAlgoTime 40.886168ms Start:2018-08-27 11:34:28.39736528 +0000 UTC m=+154.266672512 End:2018-08-27 11:34:28.438251494 +0000 UTC m=+154.307558680
I0827 11:34:28.438316       1 scheduler.go:454] Total Schedule Algo cumulative time:9.002737946s for 1180
I0827 11:34:28.490763       1 scheduler.go:451] ScheduleAlgoTime 52.271223ms Start:2018-08-27 11:34:28.4384828 +0000 UTC m=+154.307790069 End:2018-08-27 11:34:28.490754108 +0000 UTC m=+154.360061292
I0827 11:34:28.490805       1 scheduler.go:454] Total Schedule Algo cumulative time:9.055009169s for 1181
I0827 11:34:28.536012       1 scheduler.go:451] ScheduleAlgoTime 45.051989ms Start:2018-08-27 11:34:28.490949439 +0000 UTC m=+154.360256638 End:2018-08-27 11:34:28.53600144 +0000 UTC m=+154.405308627
I0827 11:34:28.536064       1 scheduler.go:454] Total Schedule Algo cumulative time:9.100061158s for 1182
I0827 11:34:28.573143       1 scheduler.go:451] ScheduleAlgoTime 36.862024ms Start:2018-08-27 11:34:28.536271374 +0000 UTC m=+154.405578628 End:2018-08-27 11:34:28.573133469 +0000 UTC m=+154.442440652
I0827 11:34:28.573190       1 scheduler.go:454] Total Schedule Algo cumulative time:9.136923182s for 1183
I0827 11:34:28.612197       1 scheduler.go:451] ScheduleAlgoTime 38.829705ms Start:2018-08-27 11:34:28.573359497 +0000 UTC m=+154.442666769 End:2018-08-27 11:34:28.612189288 +0000 UTC m=+154.481496474
I0827 11:34:28.612237       1 scheduler.go:454] Total Schedule Algo cumulative time:9.175752887s for 1184
I0827 11:34:28.650142       1 scheduler.go:451] ScheduleAlgoTime 37.760575ms Start:2018-08-27 11:34:28.61237199 +0000 UTC m=+154.481679237 End:2018-08-27 11:34:28.650132631 +0000 UTC m=+154.519439812
I0827 11:34:28.650190       1 scheduler.go:454] Total Schedule Algo cumulative time:9.213513462s for 1185
I0827 11:34:28.688355       1 scheduler.go:451] ScheduleAlgoTime 37.99679ms Start:2018-08-27 11:34:28.650343564 +0000 UTC m=+154.519650813 End:2018-08-27 11:34:28.68834042 +0000 UTC m=+154.557647603
I0827 11:34:28.688396       1 scheduler.go:454] Total Schedule Algo cumulative time:9.251510252s for 1186
I0827 11:34:28.736176       1 scheduler.go:451] ScheduleAlgoTime 47.556004ms Start:2018-08-27 11:34:28.688611585 +0000 UTC m=+154.557918826 End:2018-08-27 11:34:28.736167649 +0000 UTC m=+154.605474830
I0827 11:34:28.736216       1 scheduler.go:454] Total Schedule Algo cumulative time:9.299066256s for 1187
I0827 11:34:28.774111       1 scheduler.go:451] ScheduleAlgoTime 37.739516ms Start:2018-08-27 11:34:28.736360341 +0000 UTC m=+154.605667577 End:2018-08-27 11:34:28.77409991 +0000 UTC m=+154.643407093
I0827 11:34:28.774153       1 scheduler.go:454] Total Schedule Algo cumulative time:9.336805772s for 1188
I0827 11:34:28.811665       1 scheduler.go:451] ScheduleAlgoTime 37.361885ms Start:2018-08-27 11:34:28.774294776 +0000 UTC m=+154.643602015 End:2018-08-27 11:34:28.811656711 +0000 UTC m=+154.680963900
I0827 11:34:28.811721       1 scheduler.go:454] Total Schedule Algo cumulative time:9.374167657s for 1189
I0827 11:34:28.850377       1 scheduler.go:451] ScheduleAlgoTime 38.482867ms Start:2018-08-27 11:34:28.811886571 +0000 UTC m=+154.681193787 End:2018-08-27 11:34:28.850369469 +0000 UTC m=+154.719676654
I0827 11:34:28.850414       1 scheduler.go:454] Total Schedule Algo cumulative time:9.412650524s for 1190
I0827 11:34:28.888032       1 scheduler.go:451] ScheduleAlgoTime 37.416159ms Start:2018-08-27 11:34:28.850605331 +0000 UTC m=+154.719912608 End:2018-08-27 11:34:28.88802158 +0000 UTC m=+154.757328767
I0827 11:34:28.888079       1 scheduler.go:454] Total Schedule Algo cumulative time:9.450066683s for 1191
I0827 11:34:28.925944       1 scheduler.go:451] ScheduleAlgoTime 37.685113ms Start:2018-08-27 11:34:28.888248404 +0000 UTC m=+154.757555675 End:2018-08-27 11:34:28.925933605 +0000 UTC m=+154.795240788
I0827 11:34:28.925987       1 scheduler.go:454] Total Schedule Algo cumulative time:9.487751796s for 1192
I0827 11:34:28.973065       1 scheduler.go:451] ScheduleAlgoTime 46.801604ms Start:2018-08-27 11:34:28.926252753 +0000 UTC m=+154.795560009 End:2018-08-27 11:34:28.973054432 +0000 UTC m=+154.842361613
I0827 11:34:28.973105       1 scheduler.go:454] Total Schedule Algo cumulative time:9.5345534s for 1193
I0827 11:34:29.009819       1 scheduler.go:451] ScheduleAlgoTime 36.582165ms Start:2018-08-27 11:34:28.973228626 +0000 UTC m=+154.842535879 End:2018-08-27 11:34:29.009810858 +0000 UTC m=+154.879118044
I0827 11:34:29.009869       1 scheduler.go:454] Total Schedule Algo cumulative time:9.571135565s for 1194
I0827 11:34:29.049708       1 scheduler.go:451] ScheduleAlgoTime 39.584387ms Start:2018-08-27 11:34:29.010100252 +0000 UTC m=+154.879407505 End:2018-08-27 11:34:29.04968471 +0000 UTC m=+154.918991892
I0827 11:34:29.049770       1 scheduler.go:454] Total Schedule Algo cumulative time:9.610719952s for 1195
I0827 11:34:29.086901       1 scheduler.go:451] ScheduleAlgoTime 36.96705ms Start:2018-08-27 11:34:29.049924133 +0000 UTC m=+154.919231376 End:2018-08-27 11:34:29.086891226 +0000 UTC m=+154.956198426
I0827 11:34:29.086948       1 scheduler.go:454] Total Schedule Algo cumulative time:9.647687002s for 1196
I0827 11:34:29.124310       1 scheduler.go:451] ScheduleAlgoTime 37.186281ms Start:2018-08-27 11:34:29.087115154 +0000 UTC m=+154.956422369 End:2018-08-27 11:34:29.124301469 +0000 UTC m=+154.993608650
I0827 11:34:29.124363       1 scheduler.go:454] Total Schedule Algo cumulative time:9.684873283s for 1197
I0827 11:34:29.167898       1 scheduler.go:451] ScheduleAlgoTime 43.375482ms Start:2018-08-27 11:34:29.124511936 +0000 UTC m=+154.993819186 End:2018-08-27 11:34:29.167887486 +0000 UTC m=+155.037194668
I0827 11:34:29.167944       1 scheduler.go:454] Total Schedule Algo cumulative time:9.728248765s for 1198
I0827 11:34:29.206212       1 scheduler.go:451] ScheduleAlgoTime 38.133932ms Start:2018-08-27 11:34:29.168070186 +0000 UTC m=+155.037377418 End:2018-08-27 11:34:29.206204162 +0000 UTC m=+155.075511350
I0827 11:34:29.206260       1 scheduler.go:454] Total Schedule Algo cumulative time:9.766382697s for 1199
I0827 11:34:29.244134       1 scheduler.go:451] ScheduleAlgoTime 37.737153ms Start:2018-08-27 11:34:29.206386126 +0000 UTC m=+155.075693404 End:2018-08-27 11:34:29.244123365 +0000 UTC m=+155.113430557
I0827 11:34:29.244180       1 scheduler.go:454] Total Schedule Algo cumulative time:9.80411985s for 1200
I0827 11:34:29.282138       1 scheduler.go:451] ScheduleAlgoTime 37.797479ms Start:2018-08-27 11:34:29.244330079 +0000 UTC m=+155.113637344 End:2018-08-27 11:34:29.28212764 +0000 UTC m=+155.151434823
I0827 11:34:29.282216       1 scheduler.go:454] Total Schedule Algo cumulative time:9.841917329s for 1201
I0827 11:34:29.319074       1 scheduler.go:451] ScheduleAlgoTime 36.725431ms Start:2018-08-27 11:34:29.282339745 +0000 UTC m=+155.151647008 End:2018-08-27 11:34:29.319065255 +0000 UTC m=+155.188372439
I0827 11:34:29.319124       1 scheduler.go:454] Total Schedule Algo cumulative time:9.87864276s for 1202
I0827 11:34:29.363084       1 scheduler.go:451] ScheduleAlgoTime 43.8131ms Start:2018-08-27 11:34:29.319261815 +0000 UTC m=+155.188569041 End:2018-08-27 11:34:29.363074958 +0000 UTC m=+155.232382141
I0827 11:34:29.363164       1 scheduler.go:454] Total Schedule Algo cumulative time:9.92245586s for 1203
I0827 11:34:29.400988       1 scheduler.go:451] ScheduleAlgoTime 37.617698ms Start:2018-08-27 11:34:29.363359566 +0000 UTC m=+155.232666779 End:2018-08-27 11:34:29.400977294 +0000 UTC m=+155.270284477
I0827 11:34:29.401049       1 scheduler.go:454] Total Schedule Algo cumulative time:9.960073558s for 1204
I0827 11:34:29.439572       1 scheduler.go:451] ScheduleAlgoTime 38.2538ms Start:2018-08-27 11:34:29.401309439 +0000 UTC m=+155.270616692 End:2018-08-27 11:34:29.439563309 +0000 UTC m=+155.308870492
I0827 11:34:29.439622       1 scheduler.go:454] Total Schedule Algo cumulative time:9.998327358s for 1205
I0827 11:34:29.477301       1 scheduler.go:451] ScheduleAlgoTime 37.492902ms Start:2018-08-27 11:34:29.439799461 +0000 UTC m=+155.309106720 End:2018-08-27 11:34:29.477292442 +0000 UTC m=+155.346599622
I0827 11:34:29.477340       1 scheduler.go:454] Total Schedule Algo cumulative time:10.03582026s for 1206
I0827 11:34:29.514598       1 scheduler.go:451] ScheduleAlgoTime 37.102657ms Start:2018-08-27 11:34:29.47748662 +0000 UTC m=+155.346793892 End:2018-08-27 11:34:29.514589367 +0000 UTC m=+155.383896549
I0827 11:34:29.514628       1 scheduler.go:454] Total Schedule Algo cumulative time:10.072922917s for 1207
I0827 11:34:29.554258       1 scheduler.go:451] ScheduleAlgoTime 39.446952ms Start:2018-08-27 11:34:29.514799587 +0000 UTC m=+155.384106821 End:2018-08-27 11:34:29.554246552 +0000 UTC m=+155.423553773
I0827 11:34:29.554311       1 scheduler.go:454] Total Schedule Algo cumulative time:10.112369869s for 1208
I0827 11:34:29.593336       1 scheduler.go:451] ScheduleAlgoTime 38.802458ms Start:2018-08-27 11:34:29.554522423 +0000 UTC m=+155.423829746 End:2018-08-27 11:34:29.593325018 +0000 UTC m=+155.462632204
I0827 11:34:29.593383       1 scheduler.go:454] Total Schedule Algo cumulative time:10.151172327s for 1209
I0827 11:34:29.633431       1 scheduler.go:451] ScheduleAlgoTime 39.90349ms Start:2018-08-27 11:34:29.593516459 +0000 UTC m=+155.462823693 End:2018-08-27 11:34:29.633419997 +0000 UTC m=+155.502727183
I0827 11:34:29.633480       1 scheduler.go:454] Total Schedule Algo cumulative time:10.191075817s for 1210
I0827 11:34:29.672929       1 scheduler.go:451] ScheduleAlgoTime 39.278586ms Start:2018-08-27 11:34:29.633639691 +0000 UTC m=+155.502946951 End:2018-08-27 11:34:29.672918349 +0000 UTC m=+155.542225537
I0827 11:34:29.672984       1 scheduler.go:454] Total Schedule Algo cumulative time:10.230354403s for 1211
I0827 11:34:29.716667       1 scheduler.go:451] ScheduleAlgoTime 43.534616ms Start:2018-08-27 11:34:29.673125405 +0000 UTC m=+155.542432657 End:2018-08-27 11:34:29.716660088 +0000 UTC m=+155.585967273
I0827 11:34:29.716716       1 scheduler.go:454] Total Schedule Algo cumulative time:10.273889019s for 1212
I0827 11:34:29.754109       1 scheduler.go:451] ScheduleAlgoTime 37.182892ms Start:2018-08-27 11:34:29.716915793 +0000 UTC m=+155.586223058 End:2018-08-27 11:34:29.754098767 +0000 UTC m=+155.623405950
I0827 11:34:29.754151       1 scheduler.go:454] Total Schedule Algo cumulative time:10.311071911s for 1213
I0827 11:34:29.798210       1 scheduler.go:451] ScheduleAlgoTime 43.825739ms Start:2018-08-27 11:34:29.75437218 +0000 UTC m=+155.623679450 End:2018-08-27 11:34:29.798198005 +0000 UTC m=+155.667505189
I0827 11:34:29.798257       1 scheduler.go:454] Total Schedule Algo cumulative time:10.35489765s for 1214
I0827 11:34:29.836701       1 scheduler.go:451] ScheduleAlgoTime 38.288829ms Start:2018-08-27 11:34:29.798387551 +0000 UTC m=+155.667694784 End:2018-08-27 11:34:29.836676296 +0000 UTC m=+155.705983613
I0827 11:34:29.836747       1 scheduler.go:454] Total Schedule Algo cumulative time:10.393186479s for 1215
I0827 11:34:29.877123       1 scheduler.go:451] ScheduleAlgoTime 40.218657ms Start:2018-08-27 11:34:29.836892588 +0000 UTC m=+155.706199840 End:2018-08-27 11:34:29.877111284 +0000 UTC m=+155.746418497
I0827 11:34:29.877185       1 scheduler.go:454] Total Schedule Algo cumulative time:10.433405136s for 1216
I0827 11:34:29.917145       1 scheduler.go:451] ScheduleAlgoTime 39.844882ms Start:2018-08-27 11:34:29.877290267 +0000 UTC m=+155.746597516 End:2018-08-27 11:34:29.917135123 +0000 UTC m=+155.786442398
I0827 11:34:29.917248       1 scheduler.go:454] Total Schedule Algo cumulative time:10.473250018s for 1217
I0827 11:34:29.954392       1 scheduler.go:451] ScheduleAlgoTime 37.04019ms Start:2018-08-27 11:34:29.917340564 +0000 UTC m=+155.786647794 End:2018-08-27 11:34:29.954380721 +0000 UTC m=+155.823687984
I0827 11:34:29.954431       1 scheduler.go:454] Total Schedule Algo cumulative time:10.510290208s for 1218
I0827 11:34:30.000015       1 scheduler.go:451] ScheduleAlgoTime 45.43886ms Start:2018-08-27 11:34:29.954563358 +0000 UTC m=+155.823870615 End:2018-08-27 11:34:30.000002264 +0000 UTC m=+155.869309475
I0827 11:34:30.000063       1 scheduler.go:454] Total Schedule Algo cumulative time:10.555729068s for 1219
I0827 11:34:30.037004       1 scheduler.go:451] ScheduleAlgoTime 36.741823ms Start:2018-08-27 11:34:30.000252077 +0000 UTC m=+155.869559359 End:2018-08-27 11:34:30.036994 +0000 UTC m=+155.906301182
I0827 11:34:30.037059       1 scheduler.go:454] Total Schedule Algo cumulative time:10.592470891s for 1220
I0827 11:34:30.075453       1 scheduler.go:451] ScheduleAlgoTime 38.236178ms Start:2018-08-27 11:34:30.037208839 +0000 UTC m=+155.906516041 End:2018-08-27 11:34:30.075445038 +0000 UTC m=+155.944752219
I0827 11:34:30.075490       1 scheduler.go:454] Total Schedule Algo cumulative time:10.630707069s for 1221
I0827 11:34:30.114521       1 scheduler.go:451] ScheduleAlgoTime 38.904066ms Start:2018-08-27 11:34:30.07560863 +0000 UTC m=+155.944915889 End:2018-08-27 11:34:30.114512773 +0000 UTC m=+155.983819955
I0827 11:34:30.114555       1 scheduler.go:454] Total Schedule Algo cumulative time:10.669611135s for 1222
I0827 11:34:30.153152       1 scheduler.go:451] ScheduleAlgoTime 38.417873ms Start:2018-08-27 11:34:30.114724886 +0000 UTC m=+155.984032160 End:2018-08-27 11:34:30.153142846 +0000 UTC m=+156.022450033
I0827 11:34:30.153193       1 scheduler.go:454] Total Schedule Algo cumulative time:10.708029008s for 1223
I0827 11:34:30.199767       1 scheduler.go:451] ScheduleAlgoTime 46.439095ms Start:2018-08-27 11:34:30.153319112 +0000 UTC m=+156.022626362 End:2018-08-27 11:34:30.199758276 +0000 UTC m=+156.069065457
I0827 11:34:30.199810       1 scheduler.go:454] Total Schedule Algo cumulative time:10.754468103s for 1224
I0827 11:34:30.237783       1 scheduler.go:451] ScheduleAlgoTime 37.849092ms Start:2018-08-27 11:34:30.199921687 +0000 UTC m=+156.069228955 End:2018-08-27 11:34:30.237770864 +0000 UTC m=+156.107078047
I0827 11:34:30.237844       1 scheduler.go:454] Total Schedule Algo cumulative time:10.792317195s for 1225
I0827 11:34:30.275773       1 scheduler.go:451] ScheduleAlgoTime 37.72884ms Start:2018-08-27 11:34:30.23803556 +0000 UTC m=+156.107342787 End:2018-08-27 11:34:30.275764442 +0000 UTC m=+156.145071627
I0827 11:34:30.275813       1 scheduler.go:454] Total Schedule Algo cumulative time:10.830046035s for 1226
I0827 11:34:30.313590       1 scheduler.go:451] ScheduleAlgoTime 37.609379ms Start:2018-08-27 11:34:30.275972629 +0000 UTC m=+156.145279870 End:2018-08-27 11:34:30.313582068 +0000 UTC m=+156.182889249
I0827 11:34:30.313641       1 scheduler.go:454] Total Schedule Algo cumulative time:10.867655414s for 1227
I0827 11:34:30.353236       1 scheduler.go:451] ScheduleAlgoTime 39.376425ms Start:2018-08-27 11:34:30.313848779 +0000 UTC m=+156.183156032 End:2018-08-27 11:34:30.35322527 +0000 UTC m=+156.222532457
I0827 11:34:30.353276       1 scheduler.go:454] Total Schedule Algo cumulative time:10.907031839s for 1228
I0827 11:34:30.398623       1 scheduler.go:451] ScheduleAlgoTime 45.223644ms Start:2018-08-27 11:34:30.353388383 +0000 UTC m=+156.222695615 End:2018-08-27 11:34:30.398612049 +0000 UTC m=+156.267919259
I0827 11:34:30.398671       1 scheduler.go:454] Total Schedule Algo cumulative time:10.952255483s for 1229
I0827 11:34:30.436977       1 scheduler.go:451] ScheduleAlgoTime 38.147818ms Start:2018-08-27 11:34:30.398820001 +0000 UTC m=+156.268127238 End:2018-08-27 11:34:30.436967875 +0000 UTC m=+156.306275056
I0827 11:34:30.437023       1 scheduler.go:454] Total Schedule Algo cumulative time:10.990403301s for 1230
I0827 11:34:30.475700       1 scheduler.go:451] ScheduleAlgoTime 38.528002ms Start:2018-08-27 11:34:30.437154387 +0000 UTC m=+156.306461591 End:2018-08-27 11:34:30.475682411 +0000 UTC m=+156.344989593
I0827 11:34:30.475744       1 scheduler.go:454] Total Schedule Algo cumulative time:11.028931303s for 1231
I0827 11:34:30.519168       1 scheduler.go:451] ScheduleAlgoTime 43.265327ms Start:2018-08-27 11:34:30.47589515 +0000 UTC m=+156.345202402 End:2018-08-27 11:34:30.519160544 +0000 UTC m=+156.388467729
I0827 11:34:30.519211       1 scheduler.go:454] Total Schedule Algo cumulative time:11.07219663s for 1232
I0827 11:34:30.563423       1 scheduler.go:451] ScheduleAlgoTime 44.038877ms Start:2018-08-27 11:34:30.519376121 +0000 UTC m=+156.388683354 End:2018-08-27 11:34:30.563415048 +0000 UTC m=+156.432722231
I0827 11:34:30.563461       1 scheduler.go:454] Total Schedule Algo cumulative time:11.116235507s for 1233
I0827 11:34:30.607285       1 scheduler.go:451] ScheduleAlgoTime 43.649151ms Start:2018-08-27 11:34:30.563626204 +0000 UTC m=+156.432933440 End:2018-08-27 11:34:30.607275405 +0000 UTC m=+156.476582591
I0827 11:34:30.607331       1 scheduler.go:454] Total Schedule Algo cumulative time:11.159884658s for 1234
I0827 11:34:30.646252       1 scheduler.go:451] ScheduleAlgoTime 38.784674ms Start:2018-08-27 11:34:30.607456419 +0000 UTC m=+156.476763646 End:2018-08-27 11:34:30.646241136 +0000 UTC m=+156.515548320
I0827 11:34:30.646310       1 scheduler.go:454] Total Schedule Algo cumulative time:11.198669332s for 1235
I0827 11:34:30.683271       1 scheduler.go:451] ScheduleAlgoTime 36.820152ms Start:2018-08-27 11:34:30.646441462 +0000 UTC m=+156.515748705 End:2018-08-27 11:34:30.68326167 +0000 UTC m=+156.552568857
I0827 11:34:30.683316       1 scheduler.go:454] Total Schedule Algo cumulative time:11.235489484s for 1236
I0827 11:34:30.723288       1 scheduler.go:451] ScheduleAlgoTime 39.822466ms Start:2018-08-27 11:34:30.683455245 +0000 UTC m=+156.552762501 End:2018-08-27 11:34:30.723277781 +0000 UTC m=+156.592584967
I0827 11:34:30.723333       1 scheduler.go:454] Total Schedule Algo cumulative time:11.27531195s for 1237
I0827 11:34:30.762365       1 scheduler.go:451] ScheduleAlgoTime 38.868268ms Start:2018-08-27 11:34:30.723488244 +0000 UTC m=+156.592795463 End:2018-08-27 11:34:30.762356549 +0000 UTC m=+156.631663731
I0827 11:34:30.762412       1 scheduler.go:454] Total Schedule Algo cumulative time:11.314180218s for 1238
I0827 11:34:30.812142       1 scheduler.go:451] ScheduleAlgoTime 49.602625ms Start:2018-08-27 11:34:30.762531117 +0000 UTC m=+156.631838392 End:2018-08-27 11:34:30.812133834 +0000 UTC m=+156.681441017
I0827 11:34:30.812178       1 scheduler.go:454] Total Schedule Algo cumulative time:11.363782843s for 1239
I0827 11:34:30.850351       1 scheduler.go:451] ScheduleAlgoTime 38.053739ms Start:2018-08-27 11:34:30.812289449 +0000 UTC m=+156.681596657 End:2018-08-27 11:34:30.85034321 +0000 UTC m=+156.719650396
I0827 11:34:30.850397       1 scheduler.go:454] Total Schedule Algo cumulative time:11.401836582s for 1240
I0827 11:34:30.889267       1 scheduler.go:451] ScheduleAlgoTime 38.67292ms Start:2018-08-27 11:34:30.850582207 +0000 UTC m=+156.719889493 End:2018-08-27 11:34:30.889255132 +0000 UTC m=+156.758562413
I0827 11:34:30.889329       1 scheduler.go:454] Total Schedule Algo cumulative time:11.440509502s for 1241
I0827 11:34:30.928730       1 scheduler.go:451] ScheduleAlgoTime 39.281542ms Start:2018-08-27 11:34:30.889440353 +0000 UTC m=+156.758747622 End:2018-08-27 11:34:30.928721982 +0000 UTC m=+156.798029164
I0827 11:34:30.928761       1 scheduler.go:454] Total Schedule Algo cumulative time:11.479791044s for 1242
I0827 11:34:30.967255       1 scheduler.go:451] ScheduleAlgoTime 38.255081ms Start:2018-08-27 11:34:30.928992033 +0000 UTC m=+156.798299278 End:2018-08-27 11:34:30.967247177 +0000 UTC m=+156.836554359
I0827 11:34:30.967287       1 scheduler.go:454] Total Schedule Algo cumulative time:11.518046125s for 1243
I0827 11:34:31.009880       1 scheduler.go:451] ScheduleAlgoTime 42.467222ms Start:2018-08-27 11:34:30.967400711 +0000 UTC m=+156.836707977 End:2018-08-27 11:34:31.009867983 +0000 UTC m=+156.879175199
I0827 11:34:31.009954       1 scheduler.go:454] Total Schedule Algo cumulative time:11.560513347s for 1244
I0827 11:34:31.053753       1 scheduler.go:451] ScheduleAlgoTime 41.609645ms Start:2018-08-27 11:34:31.0121347 +0000 UTC m=+156.881441907 End:2018-08-27 11:34:31.053744369 +0000 UTC m=+156.923051552
I0827 11:34:31.053797       1 scheduler.go:454] Total Schedule Algo cumulative time:11.602122992s for 1245
I0827 11:34:31.094907       1 scheduler.go:451] ScheduleAlgoTime 40.839067ms Start:2018-08-27 11:34:31.054056956 +0000 UTC m=+156.923364186 End:2018-08-27 11:34:31.094896071 +0000 UTC m=+156.964203253
I0827 11:34:31.094959       1 scheduler.go:454] Total Schedule Algo cumulative time:11.642962059s for 1246
I0827 11:34:31.137918       1 scheduler.go:451] ScheduleAlgoTime 42.743195ms Start:2018-08-27 11:34:31.095164022 +0000 UTC m=+156.964471219 End:2018-08-27 11:34:31.137907218 +0000 UTC m=+157.007214414
I0827 11:34:31.137962       1 scheduler.go:454] Total Schedule Algo cumulative time:11.685705254s for 1247
I0827 11:34:31.177400       1 scheduler.go:451] ScheduleAlgoTime 39.275521ms Start:2018-08-27 11:34:31.138115096 +0000 UTC m=+157.007422374 End:2018-08-27 11:34:31.17739071 +0000 UTC m=+157.046697895
I0827 11:34:31.177433       1 scheduler.go:454] Total Schedule Algo cumulative time:11.724980775s for 1248
I0827 11:34:31.215818       1 scheduler.go:451] ScheduleAlgoTime 38.238828ms Start:2018-08-27 11:34:31.177569531 +0000 UTC m=+157.046876781 End:2018-08-27 11:34:31.215808419 +0000 UTC m=+157.085115609
I0827 11:34:31.215869       1 scheduler.go:454] Total Schedule Algo cumulative time:11.763219603s for 1249
I0827 11:34:31.261535       1 scheduler.go:451] ScheduleAlgoTime 45.51221ms Start:2018-08-27 11:34:31.216013989 +0000 UTC m=+157.085321234 End:2018-08-27 11:34:31.261526261 +0000 UTC m=+157.130833444
I0827 11:34:31.261585       1 scheduler.go:454] Total Schedule Algo cumulative time:11.808731813s for 1250
I0827 11:34:31.302565       1 scheduler.go:451] ScheduleAlgoTime 40.808774ms Start:2018-08-27 11:34:31.261746559 +0000 UTC m=+157.131053802 End:2018-08-27 11:34:31.302555391 +0000 UTC m=+157.171862576
I0827 11:34:31.302658       1 scheduler.go:454] Total Schedule Algo cumulative time:11.849540587s for 1251
I0827 11:34:31.346185       1 scheduler.go:451] ScheduleAlgoTime 43.375409ms Start:2018-08-27 11:34:31.302798623 +0000 UTC m=+157.172105867 End:2018-08-27 11:34:31.34617409 +0000 UTC m=+157.215481276
I0827 11:34:31.346240       1 scheduler.go:454] Total Schedule Algo cumulative time:11.892915996s for 1252
I0827 11:34:31.386848       1 scheduler.go:451] ScheduleAlgoTime 40.449028ms Start:2018-08-27 11:34:31.346387743 +0000 UTC m=+157.215695002 End:2018-08-27 11:34:31.386836847 +0000 UTC m=+157.256144030
I0827 11:34:31.386896       1 scheduler.go:454] Total Schedule Algo cumulative time:11.933365024s for 1253
I0827 11:34:31.428935       1 scheduler.go:451] ScheduleAlgoTime 41.83025ms Start:2018-08-27 11:34:31.387097007 +0000 UTC m=+157.256404256 End:2018-08-27 11:34:31.428927324 +0000 UTC m=+157.298234506
I0827 11:34:31.428984       1 scheduler.go:454] Total Schedule Algo cumulative time:11.975195274s for 1254
I0827 11:34:31.476893       1 scheduler.go:451] ScheduleAlgoTime 47.760151ms Start:2018-08-27 11:34:31.429120323 +0000 UTC m=+157.298427584 End:2018-08-27 11:34:31.476880552 +0000 UTC m=+157.346187735
I0827 11:34:31.476983       1 scheduler.go:454] Total Schedule Algo cumulative time:12.022955425s for 1255
I0827 11:34:31.516606       1 scheduler.go:451] ScheduleAlgoTime 39.44249ms Start:2018-08-27 11:34:31.477155281 +0000 UTC m=+157.346462518 End:2018-08-27 11:34:31.516597826 +0000 UTC m=+157.385905008
I0827 11:34:31.516644       1 scheduler.go:454] Total Schedule Algo cumulative time:12.062397915s for 1256
I0827 11:34:31.556562       1 scheduler.go:451] ScheduleAlgoTime 39.754948ms Start:2018-08-27 11:34:31.516796384 +0000 UTC m=+157.386103644 End:2018-08-27 11:34:31.556551391 +0000 UTC m=+157.425858592
I0827 11:34:31.556613       1 scheduler.go:454] Total Schedule Algo cumulative time:12.102152863s for 1257
I0827 11:34:31.606328       1 scheduler.go:451] ScheduleAlgoTime 49.507408ms Start:2018-08-27 11:34:31.556811439 +0000 UTC m=+157.426118666 End:2018-08-27 11:34:31.606318893 +0000 UTC m=+157.475626074
I0827 11:34:31.606379       1 scheduler.go:454] Total Schedule Algo cumulative time:12.151660271s for 1258
I0827 11:34:31.649939       1 scheduler.go:451] ScheduleAlgoTime 43.286417ms Start:2018-08-27 11:34:31.606645194 +0000 UTC m=+157.475952484 End:2018-08-27 11:34:31.649931719 +0000 UTC m=+157.519238901
I0827 11:34:31.649977       1 scheduler.go:454] Total Schedule Algo cumulative time:12.194946688s for 1259
I0827 11:34:31.695244       1 scheduler.go:451] ScheduleAlgoTime 45.126091ms Start:2018-08-27 11:34:31.650105599 +0000 UTC m=+157.519412808 End:2018-08-27 11:34:31.695231716 +0000 UTC m=+157.564538899
I0827 11:34:31.695296       1 scheduler.go:454] Total Schedule Algo cumulative time:12.240072779s for 1260
I0827 11:34:31.737251       1 scheduler.go:451] ScheduleAlgoTime 41.757405ms Start:2018-08-27 11:34:31.695485812 +0000 UTC m=+157.564793079 End:2018-08-27 11:34:31.737243295 +0000 UTC m=+157.606550484
I0827 11:34:31.737297       1 scheduler.go:454] Total Schedule Algo cumulative time:12.281830184s for 1261
I0827 11:34:31.783521       1 scheduler.go:451] ScheduleAlgoTime 46.081964ms Start:2018-08-27 11:34:31.73742989 +0000 UTC m=+157.606737122 End:2018-08-27 11:34:31.783511904 +0000 UTC m=+157.652819086
I0827 11:34:31.783565       1 scheduler.go:454] Total Schedule Algo cumulative time:12.327912148s for 1262
