I1018 09:56:23.034652       1 flags.go:27] FLAG: --address=""
I1018 09:56:23.034926       1 flags.go:27] FLAG: --algorithm-provider=""
I1018 09:56:23.034935       1 flags.go:27] FLAG: --alsologtostderr="false"
I1018 09:56:23.034942       1 flags.go:27] FLAG: --config=""
I1018 09:56:23.034946       1 flags.go:27] FLAG: --contention-profiling="false"
I1018 09:56:23.034951       1 flags.go:27] FLAG: --failure-domains="kubernetes.io/hostname,failure-domain.beta.kubernetes.io/zone,failure-domain.beta.kubernetes.io/region"
I1018 09:56:23.034961       1 flags.go:27] FLAG: --feature-gates=""
I1018 09:56:23.034969       1 flags.go:27] FLAG: --hard-pod-affinity-symmetric-weight="1"
I1018 09:56:23.034975       1 flags.go:27] FLAG: --help="false"
I1018 09:56:23.034979       1 flags.go:27] FLAG: --kube-api-burst="100"
I1018 09:56:23.034983       1 flags.go:27] FLAG: --kube-api-content-type="application/vnd.kubernetes.protobuf"
I1018 09:56:23.034988       1 flags.go:27] FLAG: --kube-api-qps="50"
I1018 09:56:23.034995       1 flags.go:27] FLAG: --kubeconfig="/etc/srv/kubernetes/kube-scheduler/kubeconfig"
I1018 09:56:23.034999       1 flags.go:27] FLAG: --leader-elect="true"
I1018 09:56:23.035003       1 flags.go:27] FLAG: --leader-elect-lease-duration="15s"
I1018 09:56:23.035009       1 flags.go:27] FLAG: --leader-elect-renew-deadline="10s"
I1018 09:56:23.035013       1 flags.go:27] FLAG: --leader-elect-resource-lock="endpoints"
I1018 09:56:23.035017       1 flags.go:27] FLAG: --leader-elect-retry-period="2s"
I1018 09:56:23.035021       1 flags.go:27] FLAG: --lock-object-name="kube-scheduler"
I1018 09:56:23.035025       1 flags.go:27] FLAG: --lock-object-namespace="kube-system"
I1018 09:56:23.035028       1 flags.go:27] FLAG: --log-backtrace-at=":0"
I1018 09:56:23.035035       1 flags.go:27] FLAG: --log-dir=""
I1018 09:56:23.035039       1 flags.go:27] FLAG: --log-flush-frequency="5s"
I1018 09:56:23.035043       1 flags.go:27] FLAG: --logtostderr="true"
I1018 09:56:23.035047       1 flags.go:27] FLAG: --master=""
I1018 09:56:23.035050       1 flags.go:27] FLAG: --policy-config-file=""
I1018 09:56:23.035054       1 flags.go:27] FLAG: --policy-configmap=""
I1018 09:56:23.035057       1 flags.go:27] FLAG: --policy-configmap-namespace=""
I1018 09:56:23.035062       1 flags.go:27] FLAG: --port="10251"
I1018 09:56:23.035067       1 flags.go:27] FLAG: --profiling="false"
I1018 09:56:23.035071       1 flags.go:27] FLAG: --scheduler-name="default-scheduler"
I1018 09:56:23.035075       1 flags.go:27] FLAG: --stderrthreshold="2"
I1018 09:56:23.035079       1 flags.go:27] FLAG: --use-legacy-policy-config="false"
I1018 09:56:23.035083       1 flags.go:27] FLAG: --v="2"
I1018 09:56:23.035086       1 flags.go:27] FLAG: --version="false"
I1018 09:56:23.035093       1 flags.go:27] FLAG: --vmodule=""
W1018 09:56:23.035106       1 server.go:163] WARNING: all flags other than --config are deprecated. Please begin using a config file ASAP.
I1018 09:56:23.037888       1 server.go:555] Version: v1.10.4
I1018 09:56:23.038157       1 factory.go:922] Creating scheduler from algorithm provider 'DefaultProvider'
I1018 09:56:23.038167       1 factory.go:1022] Creating scheduler with fit predicates 'map[NoDiskConflict:{} GeneralPredicates:{} CheckNodeCondition:{} PodToleratesNodeTaints:{} CheckVolumeBinding:{} MaxGCEPDVolumeCount:{} MaxAzureDiskVolumeCount:{} MatchInterPodAffinity:{} CheckNodeDiskPressure:{} NoVolumeZoneConflict:{} MaxEBSVolumeCount:{} CheckNodeMemoryPressure:{}]' and priority functions 'map[TaintTolerationPriority:{} SelectorSpreadPriority:{} InterPodAffinityPriority:{} LeastRequestedPriority:{} BalancedResourceAllocation:{} NodePreferAvoidPodsPriority:{} NodeAffinityPriority:{}]'
I1018 09:56:23.038635       1 server.go:574] starting healthz server on 0.0.0.0:10251
I1018 09:56:23.940265       1 controller_utils.go:1019] Waiting for caches to sync for scheduler controller
I1018 09:56:24.040582       1 controller_utils.go:1026] Caches are synced for scheduler controller
I1018 09:56:24.040637       1 leaderelection.go:175] attempting to acquire leader lease  kube-system/kube-scheduler...
I1018 09:56:24.048208       1 leaderelection.go:184] successfully acquired lease kube-system/kube-scheduler
I1018 09:56:43.586078       1 scheduler.go:451] ScheduleAlgoTime 6.010323ms Start:2018-10-18 09:56:43.580056315 +0000 UTC m=+20.603540233 End:2018-10-18 09:56:43.586066753 +0000 UTC m=+20.609550556
I1018 09:56:43.586207       1 scheduler.go:454] Total Schedule Algo cumulative time:6.010323ms for 1
I1018 09:56:43.588858       1 scheduler.go:451] ScheduleAlgoTime 2.479502ms Start:2018-10-18 09:56:43.586367227 +0000 UTC m=+20.609851095 End:2018-10-18 09:56:43.588846791 +0000 UTC m=+20.612330597
I1018 09:56:43.588916       1 scheduler.go:454] Total Schedule Algo cumulative time:8.489825ms for 2
I1018 09:56:43.591276       1 scheduler.go:451] ScheduleAlgoTime 2.232601ms Start:2018-10-18 09:56:43.589033526 +0000 UTC m=+20.612517352 End:2018-10-18 09:56:43.591266125 +0000 UTC m=+20.614749953
I1018 09:56:43.591314       1 scheduler.go:454] Total Schedule Algo cumulative time:10.722426ms for 3
I1018 09:56:43.594597       1 scheduler.go:451] ScheduleAlgoTime 3.108403ms Start:2018-10-18 09:56:43.591480509 +0000 UTC m=+20.614964390 End:2018-10-18 09:56:43.594588964 +0000 UTC m=+20.618072793
I1018 09:56:43.594645       1 scheduler.go:454] Total Schedule Algo cumulative time:13.830829ms for 4
I1018 09:56:43.597421       1 scheduler.go:451] ScheduleAlgoTime 2.591095ms Start:2018-10-18 09:56:43.594818479 +0000 UTC m=+20.618302383 End:2018-10-18 09:56:43.597409669 +0000 UTC m=+20.620893478
I1018 09:56:43.597465       1 scheduler.go:454] Total Schedule Algo cumulative time:16.421924ms for 5
I1018 09:56:43.599744       1 scheduler.go:451] ScheduleAlgoTime 2.149817ms Start:2018-10-18 09:56:43.597581415 +0000 UTC m=+20.621065269 End:2018-10-18 09:56:43.599731085 +0000 UTC m=+20.623215086
I1018 09:56:43.599799       1 scheduler.go:454] Total Schedule Algo cumulative time:18.571741ms for 6
I1018 09:56:43.602466       1 scheduler.go:451] ScheduleAlgoTime 2.295493ms Start:2018-10-18 09:56:43.600161025 +0000 UTC m=+20.623644888 End:2018-10-18 09:56:43.602456577 +0000 UTC m=+20.625940381
I1018 09:56:43.602498       1 scheduler.go:454] Total Schedule Algo cumulative time:20.867234ms for 7
I1018 09:56:43.604672       1 scheduler.go:451] ScheduleAlgoTime 2.045364ms Start:2018-10-18 09:56:43.602608165 +0000 UTC m=+20.626092061 End:2018-10-18 09:56:43.604653622 +0000 UTC m=+20.628137425
I1018 09:56:43.604708       1 scheduler.go:454] Total Schedule Algo cumulative time:22.912598ms for 8
I1018 09:56:43.606967       1 scheduler.go:451] ScheduleAlgoTime 2.045987ms Start:2018-10-18 09:56:43.604914569 +0000 UTC m=+20.628398450 End:2018-10-18 09:56:43.606960633 +0000 UTC m=+20.630444437
I1018 09:56:43.607075       1 scheduler.go:454] Total Schedule Algo cumulative time:24.958585ms for 9
I1018 09:56:43.609539       1 scheduler.go:451] ScheduleAlgoTime 2.041688ms Start:2018-10-18 09:56:43.607488573 +0000 UTC m=+20.630972377 End:2018-10-18 09:56:43.609530263 +0000 UTC m=+20.633014065
I1018 09:56:43.609577       1 scheduler.go:454] Total Schedule Algo cumulative time:27.000273ms for 10
I1018 09:56:43.611870       1 scheduler.go:451] ScheduleAlgoTime 2.125288ms Start:2018-10-18 09:56:43.609736522 +0000 UTC m=+20.633220426 End:2018-10-18 09:56:43.611861912 +0000 UTC m=+20.635345714
I1018 09:56:43.611907       1 scheduler.go:454] Total Schedule Algo cumulative time:29.125561ms for 11
I1018 09:56:43.618706       1 scheduler.go:451] ScheduleAlgoTime 5.238792ms Start:2018-10-18 09:56:43.612068883 +0000 UTC m=+20.635552790 End:2018-10-18 09:56:43.617307779 +0000 UTC m=+20.640791582
I1018 09:56:43.618766       1 scheduler.go:454] Total Schedule Algo cumulative time:34.364353ms for 12
I1018 09:56:43.621529       1 scheduler.go:451] ScheduleAlgoTime 2.652655ms Start:2018-10-18 09:56:43.618865387 +0000 UTC m=+20.642349208 End:2018-10-18 09:56:43.621518058 +0000 UTC m=+20.645001863
I1018 09:56:43.621568       1 scheduler.go:454] Total Schedule Algo cumulative time:37.017008ms for 13
I1018 09:56:43.628982       1 scheduler.go:451] ScheduleAlgoTime 6.221944ms Start:2018-10-18 09:56:43.622748384 +0000 UTC m=+20.646232208 End:2018-10-18 09:56:43.628970336 +0000 UTC m=+20.652454152
I1018 09:56:43.629044       1 scheduler.go:454] Total Schedule Algo cumulative time:43.238952ms for 14
I1018 09:56:43.632232       1 scheduler.go:451] ScheduleAlgoTime 2.298788ms Start:2018-10-18 09:56:43.629920673 +0000 UTC m=+20.653404580 End:2018-10-18 09:56:43.632219541 +0000 UTC m=+20.655703368
I1018 09:56:43.632275       1 scheduler.go:454] Total Schedule Algo cumulative time:45.53774ms for 15
I1018 09:56:43.635846       1 scheduler.go:451] ScheduleAlgoTime 3.450161ms Start:2018-10-18 09:56:43.632385468 +0000 UTC m=+20.655869367 End:2018-10-18 09:56:43.635835722 +0000 UTC m=+20.659319528
I1018 09:56:43.635879       1 scheduler.go:454] Total Schedule Algo cumulative time:48.987901ms for 16
I1018 09:56:43.638884       1 scheduler.go:451] ScheduleAlgoTime 2.799095ms Start:2018-10-18 09:56:43.636075373 +0000 UTC m=+20.659559287 End:2018-10-18 09:56:43.638874553 +0000 UTC m=+20.662358382
I1018 09:56:43.638920       1 scheduler.go:454] Total Schedule Algo cumulative time:51.786996ms for 17
I1018 09:56:43.641887       1 scheduler.go:451] ScheduleAlgoTime 2.317339ms Start:2018-10-18 09:56:43.639561746 +0000 UTC m=+20.663045645 End:2018-10-18 09:56:43.641879178 +0000 UTC m=+20.665362984
I1018 09:56:43.641920       1 scheduler.go:454] Total Schedule Algo cumulative time:54.104335ms for 18
I1018 09:56:43.645931       1 scheduler.go:451] ScheduleAlgoTime 3.425979ms Start:2018-10-18 09:56:43.642496935 +0000 UTC m=+20.665980830 End:2018-10-18 09:56:43.645923 +0000 UTC m=+20.669406809
I1018 09:56:43.645962       1 scheduler.go:454] Total Schedule Algo cumulative time:57.530314ms for 19
I1018 09:56:43.649219       1 scheduler.go:451] ScheduleAlgoTime 2.861065ms Start:2018-10-18 09:56:43.646345318 +0000 UTC m=+20.669829238 End:2018-10-18 09:56:43.649206279 +0000 UTC m=+20.672690303
I1018 09:56:43.649260       1 scheduler.go:454] Total Schedule Algo cumulative time:60.391379ms for 20
I1018 09:56:43.662331       1 scheduler.go:451] ScheduleAlgoTime 12.805496ms Start:2018-10-18 09:56:43.649509521 +0000 UTC m=+20.672993334 End:2018-10-18 09:56:43.662314813 +0000 UTC m=+20.685798830
I1018 09:56:43.662394       1 scheduler.go:454] Total Schedule Algo cumulative time:73.196875ms for 21
I1018 09:56:43.665376       1 scheduler.go:451] ScheduleAlgoTime 2.820556ms Start:2018-10-18 09:56:43.662546453 +0000 UTC m=+20.686030345 End:2018-10-18 09:56:43.665367097 +0000 UTC m=+20.688850901
I1018 09:56:43.665416       1 scheduler.go:454] Total Schedule Algo cumulative time:76.017431ms for 22
I1018 09:56:43.668917       1 scheduler.go:451] ScheduleAlgoTime 3.378666ms Start:2018-10-18 09:56:43.665531344 +0000 UTC m=+20.689015181 End:2018-10-18 09:56:43.668910045 +0000 UTC m=+20.692393847
I1018 09:56:43.668947       1 scheduler.go:454] Total Schedule Algo cumulative time:79.396097ms for 23
I1018 09:56:43.671313       1 scheduler.go:451] ScheduleAlgoTime 2.243727ms Start:2018-10-18 09:56:43.669061323 +0000 UTC m=+20.692545130 End:2018-10-18 09:56:43.671305054 +0000 UTC m=+20.694788857
I1018 09:56:43.671352       1 scheduler.go:454] Total Schedule Algo cumulative time:81.639824ms for 24
I1018 09:56:43.674094       1 scheduler.go:451] ScheduleAlgoTime 2.624916ms Start:2018-10-18 09:56:43.671459433 +0000 UTC m=+20.694943266 End:2018-10-18 09:56:43.674084379 +0000 UTC m=+20.697568182
I1018 09:56:43.674127       1 scheduler.go:454] Total Schedule Algo cumulative time:84.26474ms for 25
I1018 09:56:43.676280       1 scheduler.go:451] ScheduleAlgoTime 1.965058ms Start:2018-10-18 09:56:43.674306105 +0000 UTC m=+20.697790032 End:2018-10-18 09:56:43.676271284 +0000 UTC m=+20.699755090
I1018 09:56:43.676308       1 scheduler.go:454] Total Schedule Algo cumulative time:86.229798ms for 26
I1018 09:56:43.680194       1 scheduler.go:451] ScheduleAlgoTime 3.145563ms Start:2018-10-18 09:56:43.677035816 +0000 UTC m=+20.700519717 End:2018-10-18 09:56:43.680181423 +0000 UTC m=+20.703665280
I1018 09:56:43.680238       1 scheduler.go:454] Total Schedule Algo cumulative time:89.375361ms for 27
I1018 09:56:43.682212       1 scheduler.go:451] ScheduleAlgoTime 1.776564ms Start:2018-10-18 09:56:43.680428482 +0000 UTC m=+20.703912376 End:2018-10-18 09:56:43.682205136 +0000 UTC m=+20.705688940
I1018 09:56:43.682247       1 scheduler.go:454] Total Schedule Algo cumulative time:91.151925ms for 28
I1018 09:56:43.684529       1 scheduler.go:451] ScheduleAlgoTime 1.929693ms Start:2018-10-18 09:56:43.6825898 +0000 UTC m=+20.706073638 End:2018-10-18 09:56:43.684519526 +0000 UTC m=+20.708003331
I1018 09:56:43.684560       1 scheduler.go:454] Total Schedule Algo cumulative time:93.081618ms for 29
I1018 09:56:43.686763       1 scheduler.go:451] ScheduleAlgoTime 2.017642ms Start:2018-10-18 09:56:43.684736202 +0000 UTC m=+20.708220077 End:2018-10-18 09:56:43.686753914 +0000 UTC m=+20.710237719
I1018 09:56:43.686793       1 scheduler.go:454] Total Schedule Algo cumulative time:95.09926ms for 30
I1018 09:56:43.688877       1 scheduler.go:451] ScheduleAlgoTime 1.953558ms Start:2018-10-18 09:56:43.686915198 +0000 UTC m=+20.710399043 End:2018-10-18 09:56:43.688868799 +0000 UTC m=+20.712352601
I1018 09:56:43.688913       1 scheduler.go:454] Total Schedule Algo cumulative time:97.052818ms for 31
I1018 09:56:43.692265       1 scheduler.go:451] ScheduleAlgoTime 3.178576ms Start:2018-10-18 09:56:43.689074105 +0000 UTC m=+20.712558021 End:2018-10-18 09:56:43.692252696 +0000 UTC m=+20.715736597
I1018 09:56:43.692326       1 scheduler.go:454] Total Schedule Algo cumulative time:100.231394ms for 32
I1018 09:56:43.695242       1 scheduler.go:451] ScheduleAlgoTime 2.792437ms Start:2018-10-18 09:56:43.692440949 +0000 UTC m=+20.715924845 End:2018-10-18 09:56:43.695233479 +0000 UTC m=+20.718717282
I1018 09:56:43.695274       1 scheduler.go:454] Total Schedule Algo cumulative time:103.023831ms for 33
I1018 09:56:43.698206       1 scheduler.go:451] ScheduleAlgoTime 2.591057ms Start:2018-10-18 09:56:43.695607912 +0000 UTC m=+20.719091784 End:2018-10-18 09:56:43.698199026 +0000 UTC m=+20.721682841
I1018 09:56:43.698241       1 scheduler.go:454] Total Schedule Algo cumulative time:105.614888ms for 34
I1018 09:56:43.700855       1 scheduler.go:451] ScheduleAlgoTime 2.374662ms Start:2018-10-18 09:56:43.698468685 +0000 UTC m=+20.721952489 End:2018-10-18 09:56:43.70084334 +0000 UTC m=+20.724327151
I1018 09:56:43.700889       1 scheduler.go:454] Total Schedule Algo cumulative time:107.98955ms for 35
I1018 09:56:43.708360       1 scheduler.go:451] ScheduleAlgoTime 4.007151ms Start:2018-10-18 09:56:43.704344961 +0000 UTC m=+20.727828765 End:2018-10-18 09:56:43.708352111 +0000 UTC m=+20.731835916
I1018 09:56:43.708391       1 scheduler.go:454] Total Schedule Algo cumulative time:111.996701ms for 36
I1018 09:56:43.715529       1 scheduler.go:451] ScheduleAlgoTime 6.998925ms Start:2018-10-18 09:56:43.708516684 +0000 UTC m=+20.732000539 End:2018-10-18 09:56:43.715515658 +0000 UTC m=+20.738999464
I1018 09:56:43.715579       1 scheduler.go:454] Total Schedule Algo cumulative time:118.995626ms for 37
I1018 09:56:43.718308       1 scheduler.go:451] ScheduleAlgoTime 2.604592ms Start:2018-10-18 09:56:43.715692564 +0000 UTC m=+20.739176435 End:2018-10-18 09:56:43.718297221 +0000 UTC m=+20.741781027
I1018 09:56:43.718354       1 scheduler.go:454] Total Schedule Algo cumulative time:121.600218ms for 38
I1018 09:56:43.722690       1 scheduler.go:451] ScheduleAlgoTime 3.914575ms Start:2018-10-18 09:56:43.718763269 +0000 UTC m=+20.742247162 End:2018-10-18 09:56:43.722677927 +0000 UTC m=+20.746161737
I1018 09:56:43.722732       1 scheduler.go:454] Total Schedule Algo cumulative time:125.514793ms for 39
I1018 09:56:43.725044       1 scheduler.go:451] ScheduleAlgoTime 1.992185ms Start:2018-10-18 09:56:43.723040484 +0000 UTC m=+20.746524384 End:2018-10-18 09:56:43.725032736 +0000 UTC m=+20.748516569
I1018 09:56:43.725094       1 scheduler.go:454] Total Schedule Algo cumulative time:127.506978ms for 40
I1018 09:56:43.730275       1 scheduler.go:451] ScheduleAlgoTime 4.002832ms Start:2018-10-18 09:56:43.726257631 +0000 UTC m=+20.749741464 End:2018-10-18 09:56:43.730260401 +0000 UTC m=+20.753744296
I1018 09:56:43.730331       1 scheduler.go:454] Total Schedule Algo cumulative time:131.50981ms for 41
I1018 09:56:43.732542       1 scheduler.go:451] ScheduleAlgoTime 2.079535ms Start:2018-10-18 09:56:43.730453645 +0000 UTC m=+20.753937485 End:2018-10-18 09:56:43.732533213 +0000 UTC m=+20.756017020
I1018 09:56:43.732582       1 scheduler.go:454] Total Schedule Algo cumulative time:133.589345ms for 42
I1018 09:56:43.734503       1 scheduler.go:451] ScheduleAlgoTime 1.762866ms Start:2018-10-18 09:56:43.732730741 +0000 UTC m=+20.756214610 End:2018-10-18 09:56:43.734493662 +0000 UTC m=+20.757977476
I1018 09:56:43.734536       1 scheduler.go:454] Total Schedule Algo cumulative time:135.352211ms for 43
I1018 09:56:43.737956       1 scheduler.go:451] ScheduleAlgoTime 3.158592ms Start:2018-10-18 09:56:43.734789572 +0000 UTC m=+20.758273479 End:2018-10-18 09:56:43.737948267 +0000 UTC m=+20.761432071
I1018 09:56:43.737996       1 scheduler.go:454] Total Schedule Algo cumulative time:138.510803ms for 44
I1018 09:56:43.741232       1 scheduler.go:451] ScheduleAlgoTime 2.091679ms Start:2018-10-18 09:56:43.739131942 +0000 UTC m=+20.762615778 End:2018-10-18 09:56:43.741223649 +0000 UTC m=+20.764707457
I1018 09:56:43.741269       1 scheduler.go:454] Total Schedule Algo cumulative time:140.602482ms for 45
I1018 09:56:43.744076       1 scheduler.go:451] ScheduleAlgoTime 2.680145ms Start:2018-10-18 09:56:43.741384756 +0000 UTC m=+20.764868574 End:2018-10-18 09:56:43.744064829 +0000 UTC m=+20.767548719
I1018 09:56:43.744114       1 scheduler.go:454] Total Schedule Algo cumulative time:143.282627ms for 46
I1018 09:56:43.746912       1 scheduler.go:451] ScheduleAlgoTime 2.685879ms Start:2018-10-18 09:56:43.744214678 +0000 UTC m=+20.767698514 End:2018-10-18 09:56:43.746900579 +0000 UTC m=+20.770384393
I1018 09:56:43.746966       1 scheduler.go:454] Total Schedule Algo cumulative time:145.968506ms for 47
I1018 09:56:43.749287       1 scheduler.go:451] ScheduleAlgoTime 2.040069ms Start:2018-10-18 09:56:43.747236293 +0000 UTC m=+20.770720160 End:2018-10-18 09:56:43.749276417 +0000 UTC m=+20.772760229
I1018 09:56:43.749318       1 scheduler.go:454] Total Schedule Algo cumulative time:148.008575ms for 48
I1018 09:56:43.754890       1 scheduler.go:451] ScheduleAlgoTime 3.703061ms Start:2018-10-18 09:56:43.751174784 +0000 UTC m=+20.774658664 End:2018-10-18 09:56:43.754877914 +0000 UTC m=+20.778361725
I1018 09:56:43.754926       1 scheduler.go:454] Total Schedule Algo cumulative time:151.711636ms for 49
I1018 09:56:43.757261       1 scheduler.go:451] ScheduleAlgoTime 2.218877ms Start:2018-10-18 09:56:43.755028797 +0000 UTC m=+20.778512692 End:2018-10-18 09:56:43.757247742 +0000 UTC m=+20.780731569
I1018 09:56:43.757302       1 scheduler.go:454] Total Schedule Algo cumulative time:153.930513ms for 50
I1018 09:56:43.759578       1 scheduler.go:451] ScheduleAlgoTime 2.108018ms Start:2018-10-18 09:56:43.757457383 +0000 UTC m=+20.780941245 End:2018-10-18 09:56:43.75956537 +0000 UTC m=+20.783049263
I1018 09:56:43.759619       1 scheduler.go:454] Total Schedule Algo cumulative time:156.038531ms for 51
I1018 09:56:43.764659       1 scheduler.go:451] ScheduleAlgoTime 4.899708ms Start:2018-10-18 09:56:43.759746536 +0000 UTC m=+20.783230430 End:2018-10-18 09:56:43.764646247 +0000 UTC m=+20.788130138
I1018 09:56:43.764711       1 scheduler.go:454] Total Schedule Algo cumulative time:160.938239ms for 52
I1018 09:56:43.767724       1 scheduler.go:451] ScheduleAlgoTime 2.88272ms Start:2018-10-18 09:56:43.764816418 +0000 UTC m=+20.788312550 End:2018-10-18 09:56:43.76771146 +0000 UTC m=+20.791195270
I1018 09:56:43.767777       1 scheduler.go:454] Total Schedule Algo cumulative time:163.820959ms for 53
I1018 09:56:43.780326       1 scheduler.go:451] ScheduleAlgoTime 12.267848ms Start:2018-10-18 09:56:43.767985072 +0000 UTC m=+20.791469021 End:2018-10-18 09:56:43.780253062 +0000 UTC m=+20.803736869
I1018 09:56:43.780379       1 scheduler.go:454] Total Schedule Algo cumulative time:176.088807ms for 54
I1018 09:56:43.785153       1 scheduler.go:451] ScheduleAlgoTime 4.038312ms Start:2018-10-18 09:56:43.781100879 +0000 UTC m=+20.804584776 End:2018-10-18 09:56:43.785139206 +0000 UTC m=+20.808623088
I1018 09:56:43.785206       1 scheduler.go:454] Total Schedule Algo cumulative time:180.127119ms for 55
I1018 09:56:43.788044       1 scheduler.go:451] ScheduleAlgoTime 2.682613ms Start:2018-10-18 09:56:43.785352367 +0000 UTC m=+20.808836248 End:2018-10-18 09:56:43.788035058 +0000 UTC m=+20.811518861
I1018 09:56:43.788076       1 scheduler.go:454] Total Schedule Algo cumulative time:182.809732ms for 56
I1018 09:56:43.790359       1 scheduler.go:451] ScheduleAlgoTime 2.148386ms Start:2018-10-18 09:56:43.788202153 +0000 UTC m=+20.811686058 End:2018-10-18 09:56:43.790350639 +0000 UTC m=+20.813834444
I1018 09:56:43.790392       1 scheduler.go:454] Total Schedule Algo cumulative time:184.958118ms for 57
I1018 09:56:43.792632       1 scheduler.go:451] ScheduleAlgoTime 1.996202ms Start:2018-10-18 09:56:43.790628144 +0000 UTC m=+20.814111989 End:2018-10-18 09:56:43.792624387 +0000 UTC m=+20.816108191
I1018 09:56:43.792680       1 scheduler.go:454] Total Schedule Algo cumulative time:186.95432ms for 58
I1018 09:56:43.795616       1 scheduler.go:451] ScheduleAlgoTime 2.682708ms Start:2018-10-18 09:56:43.792925243 +0000 UTC m=+20.816409140 End:2018-10-18 09:56:43.795608045 +0000 UTC m=+20.819091848
I1018 09:56:43.795643       1 scheduler.go:454] Total Schedule Algo cumulative time:189.637028ms for 59
I1018 09:56:43.798209       1 scheduler.go:451] ScheduleAlgoTime 2.425073ms Start:2018-10-18 09:56:43.795778078 +0000 UTC m=+20.819261990 End:2018-10-18 09:56:43.79820326 +0000 UTC m=+20.821687063
I1018 09:56:43.798247       1 scheduler.go:454] Total Schedule Algo cumulative time:192.062101ms for 60
I1018 09:56:43.800246       1 scheduler.go:451] ScheduleAlgoTime 1.862987ms Start:2018-10-18 09:56:43.798371421 +0000 UTC m=+20.821855277 End:2018-10-18 09:56:43.800234459 +0000 UTC m=+20.823718264
I1018 09:56:43.800296       1 scheduler.go:454] Total Schedule Algo cumulative time:193.925088ms for 61
I1018 09:56:43.802555       1 scheduler.go:451] ScheduleAlgoTime 2.13737ms Start:2018-10-18 09:56:43.800409355 +0000 UTC m=+20.823893190 End:2018-10-18 09:56:43.802546756 +0000 UTC m=+20.826030560
I1018 09:56:43.802583       1 scheduler.go:454] Total Schedule Algo cumulative time:196.062458ms for 62
I1018 09:56:43.805094       1 scheduler.go:451] ScheduleAlgoTime 2.342225ms Start:2018-10-18 09:56:43.802741398 +0000 UTC m=+20.826225287 End:2018-10-18 09:56:43.805083683 +0000 UTC m=+20.828567512
I1018 09:56:43.805153       1 scheduler.go:454] Total Schedule Algo cumulative time:198.404683ms for 63
I1018 09:56:43.807702       1 scheduler.go:451] ScheduleAlgoTime 2.395566ms Start:2018-10-18 09:56:43.805296689 +0000 UTC m=+20.828780572 End:2018-10-18 09:56:43.807692297 +0000 UTC m=+20.831176138
I1018 09:56:43.807747       1 scheduler.go:454] Total Schedule Algo cumulative time:200.800249ms for 64
I1018 09:56:43.810910       1 scheduler.go:451] ScheduleAlgoTime 3.038614ms Start:2018-10-18 09:56:43.807859081 +0000 UTC m=+20.831342944 End:2018-10-18 09:56:43.810897733 +0000 UTC m=+20.834381558
I1018 09:56:43.810956       1 scheduler.go:454] Total Schedule Algo cumulative time:203.838863ms for 65
I1018 09:56:43.813226       1 scheduler.go:451] ScheduleAlgoTime 2.082529ms Start:2018-10-18 09:56:43.81113285 +0000 UTC m=+20.834616723 End:2018-10-18 09:56:43.813215367 +0000 UTC m=+20.836699252
I1018 09:56:43.813270       1 scheduler.go:454] Total Schedule Algo cumulative time:205.921392ms for 66
I1018 09:56:43.815635       1 scheduler.go:451] ScheduleAlgoTime 2.189459ms Start:2018-10-18 09:56:43.813435897 +0000 UTC m=+20.836919824 End:2018-10-18 09:56:43.815625479 +0000 UTC m=+20.839109283
I1018 09:56:43.815681       1 scheduler.go:454] Total Schedule Algo cumulative time:208.110851ms for 67
I1018 09:56:43.818055       1 scheduler.go:451] ScheduleAlgoTime 2.199902ms Start:2018-10-18 09:56:43.815848122 +0000 UTC m=+20.839332024 End:2018-10-18 09:56:43.818048122 +0000 UTC m=+20.841531926
I1018 09:56:43.818095       1 scheduler.go:454] Total Schedule Algo cumulative time:210.310753ms for 68
I1018 09:56:43.820557       1 scheduler.go:451] ScheduleAlgoTime 2.266622ms Start:2018-10-18 09:56:43.818283478 +0000 UTC m=+20.841767388 End:2018-10-18 09:56:43.8205502 +0000 UTC m=+20.844034010
I1018 09:56:43.820585       1 scheduler.go:454] Total Schedule Algo cumulative time:212.577375ms for 69
I1018 09:56:43.822426       1 scheduler.go:451] ScheduleAlgoTime 1.686298ms Start:2018-10-18 09:56:43.820731465 +0000 UTC m=+20.844215359 End:2018-10-18 09:56:43.822417853 +0000 UTC m=+20.845901657
I1018 09:56:43.822455       1 scheduler.go:454] Total Schedule Algo cumulative time:214.263673ms for 70
I1018 09:56:43.824544       1 scheduler.go:451] ScheduleAlgoTime 1.917117ms Start:2018-10-18 09:56:43.822605597 +0000 UTC m=+20.846089479 End:2018-10-18 09:56:43.824522771 +0000 UTC m=+20.848006596
I1018 09:56:43.824583       1 scheduler.go:454] Total Schedule Algo cumulative time:216.18079ms for 71
I1018 09:56:43.827037       1 scheduler.go:451] ScheduleAlgoTime 2.241484ms Start:2018-10-18 09:56:43.824787883 +0000 UTC m=+20.848271773 End:2018-10-18 09:56:43.827029427 +0000 UTC m=+20.850513257
I1018 09:56:43.827066       1 scheduler.go:454] Total Schedule Algo cumulative time:218.422274ms for 72
I1018 09:56:43.829399       1 scheduler.go:451] ScheduleAlgoTime 2.154617ms Start:2018-10-18 09:56:43.827234706 +0000 UTC m=+20.850718597 End:2018-10-18 09:56:43.829389351 +0000 UTC m=+20.852873214
I1018 09:56:43.829427       1 scheduler.go:454] Total Schedule Algo cumulative time:220.576891ms for 73
I1018 09:56:43.832115       1 scheduler.go:451] ScheduleAlgoTime 2.408123ms Start:2018-10-18 09:56:43.829695493 +0000 UTC m=+20.853179369 End:2018-10-18 09:56:43.832103642 +0000 UTC m=+20.855587492
I1018 09:56:43.832155       1 scheduler.go:454] Total Schedule Algo cumulative time:222.985014ms for 74
I1018 09:56:43.834833       1 scheduler.go:451] ScheduleAlgoTime 2.404852ms Start:2018-10-18 09:56:43.832420493 +0000 UTC m=+20.855904380 End:2018-10-18 09:56:43.834825425 +0000 UTC m=+20.858309232
I1018 09:56:43.834863       1 scheduler.go:454] Total Schedule Algo cumulative time:225.389866ms for 75
I1018 09:56:43.836777       1 scheduler.go:451] ScheduleAlgoTime 1.763078ms Start:2018-10-18 09:56:43.835005317 +0000 UTC m=+20.858489210 End:2018-10-18 09:56:43.836768484 +0000 UTC m=+20.860252288
I1018 09:56:43.836805       1 scheduler.go:454] Total Schedule Algo cumulative time:227.152944ms for 76
I1018 09:56:43.838945       1 scheduler.go:451] ScheduleAlgoTime 1.997282ms Start:2018-10-18 09:56:43.836938353 +0000 UTC m=+20.860422277 End:2018-10-18 09:56:43.838935756 +0000 UTC m=+20.862419559
I1018 09:56:43.838974       1 scheduler.go:454] Total Schedule Algo cumulative time:229.150226ms for 77
I1018 09:56:43.841472       1 scheduler.go:451] ScheduleAlgoTime 2.250852ms Start:2018-10-18 09:56:43.83921264 +0000 UTC m=+20.862696499 End:2018-10-18 09:56:43.841463546 +0000 UTC m=+20.864947351
I1018 09:56:43.841507       1 scheduler.go:454] Total Schedule Algo cumulative time:231.401078ms for 78
I1018 09:56:43.847292       1 scheduler.go:451] ScheduleAlgoTime 5.630585ms Start:2018-10-18 09:56:43.841651461 +0000 UTC m=+20.865135322 End:2018-10-18 09:56:43.847282105 +0000 UTC m=+20.870765907
I1018 09:56:43.847332       1 scheduler.go:454] Total Schedule Algo cumulative time:237.031663ms for 79
I1018 09:56:43.849597       1 scheduler.go:451] ScheduleAlgoTime 2.135848ms Start:2018-10-18 09:56:43.84745494 +0000 UTC m=+20.870938841 End:2018-10-18 09:56:43.849590885 +0000 UTC m=+20.873074689
I1018 09:56:43.849622       1 scheduler.go:454] Total Schedule Algo cumulative time:239.167511ms for 80
I1018 09:56:43.852406       1 scheduler.go:451] ScheduleAlgoTime 2.509934ms Start:2018-10-18 09:56:43.849888391 +0000 UTC m=+20.873372251 End:2018-10-18 09:56:43.852398383 +0000 UTC m=+20.875882185
I1018 09:56:43.852442       1 scheduler.go:454] Total Schedule Algo cumulative time:241.677445ms for 81
I1018 09:56:43.854615       1 scheduler.go:451] ScheduleAlgoTime 2.020464ms Start:2018-10-18 09:56:43.852584295 +0000 UTC m=+20.876068169 End:2018-10-18 09:56:43.854604825 +0000 UTC m=+20.878088633
I1018 09:56:43.854659       1 scheduler.go:454] Total Schedule Algo cumulative time:243.697909ms for 82
I1018 09:56:43.856559       1 scheduler.go:451] ScheduleAlgoTime 1.740862ms Start:2018-10-18 09:56:43.854810672 +0000 UTC m=+20.878294475 End:2018-10-18 09:56:43.85655153 +0000 UTC m=+20.880035337
I1018 09:56:43.856598       1 scheduler.go:454] Total Schedule Algo cumulative time:245.438771ms for 83
I1018 09:56:43.859017       1 scheduler.go:451] ScheduleAlgoTime 2.086428ms Start:2018-10-18 09:56:43.856919373 +0000 UTC m=+20.880403219 End:2018-10-18 09:56:43.859005734 +0000 UTC m=+20.882489647
I1018 09:56:43.859060       1 scheduler.go:454] Total Schedule Algo cumulative time:247.525199ms for 84
I1018 09:56:43.861525       1 scheduler.go:451] ScheduleAlgoTime 2.021408ms Start:2018-10-18 09:56:43.85948842 +0000 UTC m=+20.882972318 End:2018-10-18 09:56:43.861509915 +0000 UTC m=+20.884993726
I1018 09:56:43.861572       1 scheduler.go:454] Total Schedule Algo cumulative time:249.546607ms for 85
I1018 09:56:43.863631       1 scheduler.go:451] ScheduleAlgoTime 1.897343ms Start:2018-10-18 09:56:43.861727371 +0000 UTC m=+20.885211207 End:2018-10-18 09:56:43.863624739 +0000 UTC m=+20.887108550
I1018 09:56:43.863659       1 scheduler.go:454] Total Schedule Algo cumulative time:251.44395ms for 86
I1018 09:56:43.865941       1 scheduler.go:451] ScheduleAlgoTime 2.084655ms Start:2018-10-18 09:56:43.863847109 +0000 UTC m=+20.887331023 End:2018-10-18 09:56:43.865931874 +0000 UTC m=+20.889415678
I1018 09:56:43.865976       1 scheduler.go:454] Total Schedule Algo cumulative time:253.528605ms for 87
I1018 09:56:43.868031       1 scheduler.go:451] ScheduleAlgoTime 1.876724ms Start:2018-10-18 09:56:43.866146184 +0000 UTC m=+20.889630091 End:2018-10-18 09:56:43.868023008 +0000 UTC m=+20.891506815
I1018 09:56:43.868060       1 scheduler.go:454] Total Schedule Algo cumulative time:255.405329ms for 88
I1018 09:56:43.870637       1 scheduler.go:451] ScheduleAlgoTime 2.40084ms Start:2018-10-18 09:56:43.868225358 +0000 UTC m=+20.891709214 End:2018-10-18 09:56:43.870626227 +0000 UTC m=+20.894110054
I1018 09:56:43.870688       1 scheduler.go:454] Total Schedule Algo cumulative time:257.806169ms for 89
I1018 09:56:43.872965       1 scheduler.go:451] ScheduleAlgoTime 2.100389ms Start:2018-10-18 09:56:43.870858023 +0000 UTC m=+20.894341947 End:2018-10-18 09:56:43.872958533 +0000 UTC m=+20.896442336
I1018 09:56:43.872994       1 scheduler.go:454] Total Schedule Algo cumulative time:259.906558ms for 90
I1018 09:56:43.874839       1 scheduler.go:451] ScheduleAlgoTime 1.666993ms Start:2018-10-18 09:56:43.873163349 +0000 UTC m=+20.896647230 End:2018-10-18 09:56:43.874830419 +0000 UTC m=+20.898314223
I1018 09:56:43.874866       1 scheduler.go:454] Total Schedule Algo cumulative time:261.573551ms for 91
I1018 09:56:43.876701       1 scheduler.go:451] ScheduleAlgoTime 1.665022ms Start:2018-10-18 09:56:43.875028541 +0000 UTC m=+20.898512411 End:2018-10-18 09:56:43.876693629 +0000 UTC m=+20.900177433
I1018 09:56:43.876731       1 scheduler.go:454] Total Schedule Algo cumulative time:263.238573ms for 92
I1018 09:56:43.878585       1 scheduler.go:451] ScheduleAlgoTime 1.679077ms Start:2018-10-18 09:56:43.876897508 +0000 UTC m=+20.900381415 End:2018-10-18 09:56:43.878576688 +0000 UTC m=+20.902060492
I1018 09:56:43.878613       1 scheduler.go:454] Total Schedule Algo cumulative time:264.91765ms for 93
I1018 09:56:43.881660       1 scheduler.go:451] ScheduleAlgoTime 2.729607ms Start:2018-10-18 09:56:43.878921975 +0000 UTC m=+20.902405866 End:2018-10-18 09:56:43.881651669 +0000 UTC m=+20.905135473
I1018 09:56:43.881697       1 scheduler.go:454] Total Schedule Algo cumulative time:267.647257ms for 94
I1018 09:56:43.883606       1 scheduler.go:451] ScheduleAlgoTime 1.688264ms Start:2018-10-18 09:56:43.881907632 +0000 UTC m=+20.905391519 End:2018-10-18 09:56:43.883595951 +0000 UTC m=+20.907079783
I1018 09:56:43.883633       1 scheduler.go:454] Total Schedule Algo cumulative time:269.335521ms for 95
I1018 09:56:43.885618       1 scheduler.go:451] ScheduleAlgoTime 1.79236ms Start:2018-10-18 09:56:43.88381778 +0000 UTC m=+20.907301661 End:2018-10-18 09:56:43.885610217 +0000 UTC m=+20.909094021
I1018 09:56:43.885656       1 scheduler.go:454] Total Schedule Algo cumulative time:271.127881ms for 96
I1018 09:56:43.888345       1 scheduler.go:451] ScheduleAlgoTime 2.51614ms Start:2018-10-18 09:56:43.885821141 +0000 UTC m=+20.909305020 End:2018-10-18 09:56:43.888337356 +0000 UTC m=+20.911821160
I1018 09:56:43.888381       1 scheduler.go:454] Total Schedule Algo cumulative time:273.644021ms for 97
I1018 09:56:43.890192       1 scheduler.go:451] ScheduleAlgoTime 1.555294ms Start:2018-10-18 09:56:43.888626909 +0000 UTC m=+20.912110789 End:2018-10-18 09:56:43.890182276 +0000 UTC m=+20.913666083
I1018 09:56:43.890258       1 scheduler.go:454] Total Schedule Algo cumulative time:275.199315ms for 98
I1018 09:56:43.892303       1 scheduler.go:451] ScheduleAlgoTime 1.832408ms Start:2018-10-18 09:56:43.890464027 +0000 UTC m=+20.913947891 End:2018-10-18 09:56:43.892296496 +0000 UTC m=+20.915780299
I1018 09:56:43.892331       1 scheduler.go:454] Total Schedule Algo cumulative time:277.031723ms for 99
I1018 09:56:43.894789       1 scheduler.go:451] ScheduleAlgoTime 2.345987ms Start:2018-10-18 09:56:43.892436065 +0000 UTC m=+20.915919938 End:2018-10-18 09:56:43.894782121 +0000 UTC m=+20.918265925
I1018 09:56:43.894816       1 scheduler.go:454] Total Schedule Algo cumulative time:279.37771ms for 100
I1018 09:56:43.896826       1 scheduler.go:451] ScheduleAlgoTime 1.91606ms Start:2018-10-18 09:56:43.894901022 +0000 UTC m=+20.918384909 End:2018-10-18 09:56:43.896817051 +0000 UTC m=+20.920300969
I1018 09:56:43.896865       1 scheduler.go:454] Total Schedule Algo cumulative time:281.29377ms for 101
I1018 09:56:43.898606       1 scheduler.go:451] ScheduleAlgoTime 1.631576ms Start:2018-10-18 09:56:43.896957337 +0000 UTC m=+20.920441204 End:2018-10-18 09:56:43.898588976 +0000 UTC m=+20.922072780
I1018 09:56:43.898685       1 scheduler.go:454] Total Schedule Algo cumulative time:282.925346ms for 102
I1018 09:56:43.900816       1 scheduler.go:451] ScheduleAlgoTime 1.914943ms Start:2018-10-18 09:56:43.898893986 +0000 UTC m=+20.922377902 End:2018-10-18 09:56:43.900809038 +0000 UTC m=+20.924292845
I1018 09:56:43.900843       1 scheduler.go:454] Total Schedule Algo cumulative time:284.840289ms for 103
I1018 09:56:43.902943       1 scheduler.go:451] ScheduleAlgoTime 1.875718ms Start:2018-10-18 09:56:43.901057679 +0000 UTC m=+20.924541573 End:2018-10-18 09:56:43.902933481 +0000 UTC m=+20.926417291
I1018 09:56:43.902974       1 scheduler.go:454] Total Schedule Algo cumulative time:286.716007ms for 104
I1018 09:56:43.906881       1 scheduler.go:451] ScheduleAlgoTime 3.825028ms Start:2018-10-18 09:56:43.903045812 +0000 UTC m=+20.926529646 End:2018-10-18 09:56:43.906870871 +0000 UTC m=+20.930354674
I1018 09:56:43.906922       1 scheduler.go:454] Total Schedule Algo cumulative time:290.541035ms for 105
I1018 09:56:43.911519       1 scheduler.go:451] ScheduleAlgoTime 3.934187ms Start:2018-10-18 09:56:43.907575324 +0000 UTC m=+20.931059224 End:2018-10-18 09:56:43.911509602 +0000 UTC m=+20.934993411
I1018 09:56:43.911557       1 scheduler.go:454] Total Schedule Algo cumulative time:294.475222ms for 106
I1018 09:56:43.914076       1 scheduler.go:451] ScheduleAlgoTime 2.26302ms Start:2018-10-18 09:56:43.911800851 +0000 UTC m=+20.935284757 End:2018-10-18 09:56:43.914063913 +0000 UTC m=+20.937547777
I1018 09:56:43.914123       1 scheduler.go:454] Total Schedule Algo cumulative time:296.738242ms for 107
I1018 09:56:43.916019       1 scheduler.go:451] ScheduleAlgoTime 1.757572ms Start:2018-10-18 09:56:43.91425266 +0000 UTC m=+20.937736516 End:2018-10-18 09:56:43.916010286 +0000 UTC m=+20.939494088
I1018 09:56:43.916047       1 scheduler.go:454] Total Schedule Algo cumulative time:298.495814ms for 108
I1018 09:56:43.919171       1 scheduler.go:451] ScheduleAlgoTime 2.918877ms Start:2018-10-18 09:56:43.916244178 +0000 UTC m=+20.939728048 End:2018-10-18 09:56:43.919163114 +0000 UTC m=+20.942646925
I1018 09:56:43.919216       1 scheduler.go:454] Total Schedule Algo cumulative time:301.414691ms for 109
I1018 09:56:43.922460       1 scheduler.go:451] ScheduleAlgoTime 3.10529ms Start:2018-10-18 09:56:43.919346604 +0000 UTC m=+20.942830447 End:2018-10-18 09:56:43.922451935 +0000 UTC m=+20.945935737
I1018 09:56:43.922512       1 scheduler.go:454] Total Schedule Algo cumulative time:304.519981ms for 110
I1018 09:56:43.930645       1 scheduler.go:451] ScheduleAlgoTime 4.807316ms Start:2018-10-18 09:56:43.925827952 +0000 UTC m=+20.949311859 End:2018-10-18 09:56:43.93063537 +0000 UTC m=+20.954119175
I1018 09:56:43.930685       1 scheduler.go:454] Total Schedule Algo cumulative time:309.327297ms for 111
I1018 09:56:43.934161       1 scheduler.go:451] ScheduleAlgoTime 3.393867ms Start:2018-10-18 09:56:43.930751997 +0000 UTC m=+20.954235799 End:2018-10-18 09:56:43.934145757 +0000 UTC m=+20.957629666
I1018 09:56:43.934211       1 scheduler.go:454] Total Schedule Algo cumulative time:312.721164ms for 112
I1018 09:56:43.941742       1 scheduler.go:451] ScheduleAlgoTime 3.164815ms Start:2018-10-18 09:56:43.938566099 +0000 UTC m=+20.962049950 End:2018-10-18 09:56:43.941730957 +0000 UTC m=+20.965214765
I1018 09:56:43.941794       1 scheduler.go:454] Total Schedule Algo cumulative time:315.885979ms for 113
I1018 09:56:43.945871       1 scheduler.go:451] ScheduleAlgoTime 3.924306ms Start:2018-10-18 09:56:43.941927221 +0000 UTC m=+20.965411073 End:2018-10-18 09:56:43.945851573 +0000 UTC m=+20.969335379
I1018 09:56:43.945907       1 scheduler.go:454] Total Schedule Algo cumulative time:319.810285ms for 114
I1018 09:56:43.952390       1 scheduler.go:451] ScheduleAlgoTime 6.378963ms Start:2018-10-18 09:56:43.945998153 +0000 UTC m=+20.969481959 End:2018-10-18 09:56:43.952377114 +0000 UTC m=+20.975860922
I1018 09:56:43.952454       1 scheduler.go:454] Total Schedule Algo cumulative time:326.189248ms for 115
I1018 09:56:43.955134       1 scheduler.go:451] ScheduleAlgoTime 2.540214ms Start:2018-10-18 09:56:43.952582467 +0000 UTC m=+20.976066280 End:2018-10-18 09:56:43.955122642 +0000 UTC m=+20.978606494
I1018 09:56:43.955172       1 scheduler.go:454] Total Schedule Algo cumulative time:328.729462ms for 116
I1018 09:56:43.958819       1 scheduler.go:451] ScheduleAlgoTime 3.436583ms Start:2018-10-18 09:56:43.955372134 +0000 UTC m=+20.978856004 End:2018-10-18 09:56:43.958808694 +0000 UTC m=+20.982292587
I1018 09:56:43.958857       1 scheduler.go:454] Total Schedule Algo cumulative time:332.166045ms for 117
I1018 09:56:43.961749       1 scheduler.go:451] ScheduleAlgoTime 2.707267ms Start:2018-10-18 09:56:43.959032218 +0000 UTC m=+20.982516118 End:2018-10-18 09:56:43.961739575 +0000 UTC m=+20.985223385
I1018 09:56:43.961781       1 scheduler.go:454] Total Schedule Algo cumulative time:334.873312ms for 118
I1018 09:56:43.964145       1 scheduler.go:451] ScheduleAlgoTime 2.206299ms Start:2018-10-18 09:56:43.961932818 +0000 UTC m=+20.985416722 End:2018-10-18 09:56:43.964139216 +0000 UTC m=+20.987623021
I1018 09:56:43.964185       1 scheduler.go:454] Total Schedule Algo cumulative time:337.079611ms for 119
I1018 09:56:43.966165       1 scheduler.go:451] ScheduleAlgoTime 1.800209ms Start:2018-10-18 09:56:43.964357407 +0000 UTC m=+20.987841293 End:2018-10-18 09:56:43.966157699 +0000 UTC m=+20.989641502
I1018 09:56:43.966197       1 scheduler.go:454] Total Schedule Algo cumulative time:338.87982ms for 120
I1018 09:56:43.968312       1 scheduler.go:451] ScheduleAlgoTime 1.982307ms Start:2018-10-18 09:56:43.966320819 +0000 UTC m=+20.989804682 End:2018-10-18 09:56:43.968303185 +0000 UTC m=+20.991786989
I1018 09:56:43.968345       1 scheduler.go:454] Total Schedule Algo cumulative time:340.862127ms for 121
I1018 09:56:43.970746       1 scheduler.go:451] ScheduleAlgoTime 2.126683ms Start:2018-10-18 09:56:43.96860991 +0000 UTC m=+20.992093714 End:2018-10-18 09:56:43.970736473 +0000 UTC m=+20.994220397
I1018 09:56:43.970776       1 scheduler.go:454] Total Schedule Algo cumulative time:342.98881ms for 122
I1018 09:56:43.972897       1 scheduler.go:451] ScheduleAlgoTime 1.936879ms Start:2018-10-18 09:56:43.970952462 +0000 UTC m=+20.994436332 End:2018-10-18 09:56:43.972889404 +0000 UTC m=+20.996373211
I1018 09:56:43.972925       1 scheduler.go:454] Total Schedule Algo cumulative time:344.925689ms for 123
I1018 09:56:43.975049       1 scheduler.go:451] ScheduleAlgoTime 1.995545ms Start:2018-10-18 09:56:43.973045843 +0000 UTC m=+20.996529734 End:2018-10-18 09:56:43.975041472 +0000 UTC m=+20.998525279
I1018 09:56:43.975077       1 scheduler.go:454] Total Schedule Algo cumulative time:346.921234ms for 124
I1018 09:56:43.977100       1 scheduler.go:451] ScheduleAlgoTime 1.833345ms Start:2018-10-18 09:56:43.975257019 +0000 UTC m=+20.998740856 End:2018-10-18 09:56:43.977090399 +0000 UTC m=+21.000574201
I1018 09:56:43.977129       1 scheduler.go:454] Total Schedule Algo cumulative time:348.754579ms for 125
I1018 09:56:43.979159       1 scheduler.go:451] ScheduleAlgoTime 1.881757ms Start:2018-10-18 09:56:43.977269956 +0000 UTC m=+21.000753834 End:2018-10-18 09:56:43.979151787 +0000 UTC m=+21.002635591
I1018 09:56:43.979201       1 scheduler.go:454] Total Schedule Algo cumulative time:350.636336ms for 126
I1018 09:56:43.981492       1 scheduler.go:451] ScheduleAlgoTime 2.100095ms Start:2018-10-18 09:56:43.979381501 +0000 UTC m=+21.002865348 End:2018-10-18 09:56:43.981481565 +0000 UTC m=+21.004965443
I1018 09:56:43.981529       1 scheduler.go:454] Total Schedule Algo cumulative time:352.736431ms for 127
I1018 09:56:43.983712       1 scheduler.go:451] ScheduleAlgoTime 2.012316ms Start:2018-10-18 09:56:43.981691633 +0000 UTC m=+21.005175506 End:2018-10-18 09:56:43.983704018 +0000 UTC m=+21.007187822
I1018 09:56:43.983740       1 scheduler.go:454] Total Schedule Algo cumulative time:354.748747ms for 128
I1018 09:56:43.985982       1 scheduler.go:451] ScheduleAlgoTime 2.108655ms Start:2018-10-18 09:56:43.983864015 +0000 UTC m=+21.007347896 End:2018-10-18 09:56:43.985972745 +0000 UTC m=+21.009456551
I1018 09:56:43.986016       1 scheduler.go:454] Total Schedule Algo cumulative time:356.857402ms for 129
I1018 09:56:43.988235       1 scheduler.go:451] ScheduleAlgoTime 2.097531ms Start:2018-10-18 09:56:43.986130561 +0000 UTC m=+21.009614483 End:2018-10-18 09:56:43.988228206 +0000 UTC m=+21.011712014
I1018 09:56:43.988272       1 scheduler.go:454] Total Schedule Algo cumulative time:358.954933ms for 130
I1018 09:56:43.990220       1 scheduler.go:451] ScheduleAlgoTime 1.779262ms Start:2018-10-18 09:56:43.988434252 +0000 UTC m=+21.011918119 End:2018-10-18 09:56:43.990213578 +0000 UTC m=+21.013697381
I1018 09:56:43.990252       1 scheduler.go:454] Total Schedule Algo cumulative time:360.734195ms for 131
I1018 09:56:43.993174       1 scheduler.go:451] ScheduleAlgoTime 2.765366ms Start:2018-10-18 09:56:43.990399926 +0000 UTC m=+21.013883813 End:2018-10-18 09:56:43.993165377 +0000 UTC m=+21.016649179
I1018 09:56:43.993204       1 scheduler.go:454] Total Schedule Algo cumulative time:363.499561ms for 132
I1018 09:56:43.995826       1 scheduler.go:451] ScheduleAlgoTime 2.459632ms Start:2018-10-18 09:56:43.993358666 +0000 UTC m=+21.016842512 End:2018-10-18 09:56:43.995818337 +0000 UTC m=+21.019302144
I1018 09:56:43.995870       1 scheduler.go:454] Total Schedule Algo cumulative time:365.959193ms for 133
I1018 09:56:43.998292       1 scheduler.go:451] ScheduleAlgoTime 2.224428ms Start:2018-10-18 09:56:43.99605791 +0000 UTC m=+21.019541785 End:2018-10-18 09:56:43.998282404 +0000 UTC m=+21.021766213
I1018 09:56:43.998320       1 scheduler.go:454] Total Schedule Algo cumulative time:368.183621ms for 134
I1018 09:56:44.004547       1 scheduler.go:451] ScheduleAlgoTime 6.044366ms Start:2018-10-18 09:56:43.998490387 +0000 UTC m=+21.021974282 End:2018-10-18 09:56:44.004534845 +0000 UTC m=+21.028018648
I1018 09:56:44.004594       1 scheduler.go:454] Total Schedule Algo cumulative time:374.227987ms for 135
I1018 09:56:44.006583       1 scheduler.go:451] ScheduleAlgoTime 1.833104ms Start:2018-10-18 09:56:44.004738592 +0000 UTC m=+21.028222477 End:2018-10-18 09:56:44.006571704 +0000 UTC m=+21.030055581
I1018 09:56:44.006647       1 scheduler.go:454] Total Schedule Algo cumulative time:376.061091ms for 136
I1018 09:56:44.008477       1 scheduler.go:451] ScheduleAlgoTime 1.724074ms Start:2018-10-18 09:56:44.006746128 +0000 UTC m=+21.030229950 End:2018-10-18 09:56:44.008470215 +0000 UTC m=+21.031954024
I1018 09:56:44.008513       1 scheduler.go:454] Total Schedule Algo cumulative time:377.785165ms for 137
I1018 09:56:44.010613       1 scheduler.go:451] ScheduleAlgoTime 1.948983ms Start:2018-10-18 09:56:44.008656234 +0000 UTC m=+21.032140114 End:2018-10-18 09:56:44.010605284 +0000 UTC m=+21.034089097
I1018 09:56:44.010649       1 scheduler.go:454] Total Schedule Algo cumulative time:379.734148ms for 138
I1018 09:56:44.012721       1 scheduler.go:451] ScheduleAlgoTime 1.83422ms Start:2018-10-18 09:56:44.010880524 +0000 UTC m=+21.034364411 End:2018-10-18 09:56:44.012714828 +0000 UTC m=+21.036198631
I1018 09:56:44.012793       1 scheduler.go:454] Total Schedule Algo cumulative time:381.568368ms for 139
I1018 09:56:44.015336       1 scheduler.go:451] ScheduleAlgoTime 2.411656ms Start:2018-10-18 09:56:44.012913979 +0000 UTC m=+21.036397884 End:2018-10-18 09:56:44.015325721 +0000 UTC m=+21.038809540
I1018 09:56:44.015395       1 scheduler.go:454] Total Schedule Algo cumulative time:383.980024ms for 140
I1018 09:56:44.018016       1 scheduler.go:451] ScheduleAlgoTime 2.470345ms Start:2018-10-18 09:56:44.015535955 +0000 UTC m=+21.039019858 End:2018-10-18 09:56:44.018006399 +0000 UTC m=+21.041490203
I1018 09:56:44.018059       1 scheduler.go:454] Total Schedule Algo cumulative time:386.450369ms for 141
I1018 09:56:44.020141       1 scheduler.go:451] ScheduleAlgoTime 1.949623ms Start:2018-10-18 09:56:44.018182911 +0000 UTC m=+21.041666754 End:2018-10-18 09:56:44.020132572 +0000 UTC m=+21.043616377
I1018 09:56:44.020175       1 scheduler.go:454] Total Schedule Algo cumulative time:388.399992ms for 142
I1018 09:56:44.022110       1 scheduler.go:451] ScheduleAlgoTime 1.789234ms Start:2018-10-18 09:56:44.020314622 +0000 UTC m=+21.043798510 End:2018-10-18 09:56:44.022103937 +0000 UTC m=+21.045587744
I1018 09:56:44.022138       1 scheduler.go:454] Total Schedule Algo cumulative time:390.189226ms for 143
I1018 09:56:44.025372       1 scheduler.go:451] ScheduleAlgoTime 2.889097ms Start:2018-10-18 09:56:44.022474564 +0000 UTC m=+21.045958452 End:2018-10-18 09:56:44.025363746 +0000 UTC m=+21.048847549
I1018 09:56:44.025403       1 scheduler.go:454] Total Schedule Algo cumulative time:393.078323ms for 144
I1018 09:56:44.027377       1 scheduler.go:451] ScheduleAlgoTime 1.807537ms Start:2018-10-18 09:56:44.025561863 +0000 UTC m=+21.049045706 End:2018-10-18 09:56:44.027369427 +0000 UTC m=+21.050853243
I1018 09:56:44.027405       1 scheduler.go:454] Total Schedule Algo cumulative time:394.88586ms for 145
I1018 09:56:44.029281       1 scheduler.go:451] ScheduleAlgoTime 1.703146ms Start:2018-10-18 09:56:44.027567421 +0000 UTC m=+21.051051310 End:2018-10-18 09:56:44.029270556 +0000 UTC m=+21.052754456
I1018 09:56:44.029321       1 scheduler.go:454] Total Schedule Algo cumulative time:396.589006ms for 146
I1018 09:56:44.031253       1 scheduler.go:451] ScheduleAlgoTime 1.76389ms Start:2018-10-18 09:56:44.029475114 +0000 UTC m=+21.052959015 End:2018-10-18 09:56:44.031239097 +0000 UTC m=+21.054722905
I1018 09:56:44.031280       1 scheduler.go:454] Total Schedule Algo cumulative time:398.352896ms for 147
I1018 09:56:44.033335       1 scheduler.go:451] ScheduleAlgoTime 1.920243ms Start:2018-10-18 09:56:44.031407282 +0000 UTC m=+21.054891178 End:2018-10-18 09:56:44.033327615 +0000 UTC m=+21.056811421
I1018 09:56:44.033372       1 scheduler.go:454] Total Schedule Algo cumulative time:400.273139ms for 148
I1018 09:56:44.035327       1 scheduler.go:451] ScheduleAlgoTime 1.859922ms Start:2018-10-18 09:56:44.033459146 +0000 UTC m=+21.056943005 End:2018-10-18 09:56:44.035319118 +0000 UTC m=+21.058802927
I1018 09:56:44.035365       1 scheduler.go:454] Total Schedule Algo cumulative time:402.133061ms for 149
I1018 09:56:44.037275       1 scheduler.go:451] ScheduleAlgoTime 1.740786ms Start:2018-10-18 09:56:44.035524225 +0000 UTC m=+21.059008117 End:2018-10-18 09:56:44.037265059 +0000 UTC m=+21.060748903
I1018 09:56:44.037312       1 scheduler.go:454] Total Schedule Algo cumulative time:403.873847ms for 150
I1018 09:56:44.039472       1 scheduler.go:451] ScheduleAlgoTime 2.035938ms Start:2018-10-18 09:56:44.037428624 +0000 UTC m=+21.060912479 End:2018-10-18 09:56:44.039464613 +0000 UTC m=+21.062948417
I1018 09:56:44.039512       1 scheduler.go:454] Total Schedule Algo cumulative time:405.909785ms for 151
I1018 09:56:44.041480       1 scheduler.go:451] ScheduleAlgoTime 1.725031ms Start:2018-10-18 09:56:44.039747037 +0000 UTC m=+21.063230942 End:2018-10-18 09:56:44.04147217 +0000 UTC m=+21.064955973
I1018 09:56:44.041507       1 scheduler.go:454] Total Schedule Algo cumulative time:407.634816ms for 152
I1018 09:56:44.043596       1 scheduler.go:451] ScheduleAlgoTime 1.944001ms Start:2018-10-18 09:56:44.04164055 +0000 UTC m=+21.065124383 End:2018-10-18 09:56:44.043584431 +0000 UTC m=+21.067068384
I1018 09:56:44.043633       1 scheduler.go:454] Total Schedule Algo cumulative time:409.578817ms for 153
I1018 09:56:44.046150       1 scheduler.go:451] ScheduleAlgoTime 2.288663ms Start:2018-10-18 09:56:44.04385326 +0000 UTC m=+21.067337131 End:2018-10-18 09:56:44.046141986 +0000 UTC m=+21.069625794
I1018 09:56:44.046177       1 scheduler.go:454] Total Schedule Algo cumulative time:411.86748ms for 154
I1018 09:56:44.048140       1 scheduler.go:451] ScheduleAlgoTime 1.808532ms Start:2018-10-18 09:56:44.04632381 +0000 UTC m=+21.069807712 End:2018-10-18 09:56:44.048132441 +0000 UTC m=+21.071616244
I1018 09:56:44.048168       1 scheduler.go:454] Total Schedule Algo cumulative time:413.676012ms for 155
I1018 09:56:44.050082       1 scheduler.go:451] ScheduleAlgoTime 1.730324ms Start:2018-10-18 09:56:44.048343114 +0000 UTC m=+21.071827001 End:2018-10-18 09:56:44.050073518 +0000 UTC m=+21.073557325
I1018 09:56:44.050158       1 scheduler.go:454] Total Schedule Algo cumulative time:415.406336ms for 156
I1018 09:56:44.051994       1 scheduler.go:451] ScheduleAlgoTime 1.695956ms Start:2018-10-18 09:56:44.050290244 +0000 UTC m=+21.073774119 End:2018-10-18 09:56:44.051986266 +0000 UTC m=+21.075470075
I1018 09:56:44.052024       1 scheduler.go:454] Total Schedule Algo cumulative time:417.102292ms for 157
I1018 09:56:44.053993       1 scheduler.go:451] ScheduleAlgoTime 1.730487ms Start:2018-10-18 09:56:44.052251819 +0000 UTC m=+21.075735705 End:2018-10-18 09:56:44.053982363 +0000 UTC m=+21.077466192
I1018 09:56:44.054039       1 scheduler.go:454] Total Schedule Algo cumulative time:418.832779ms for 158
I1018 09:56:44.056487       1 scheduler.go:451] ScheduleAlgoTime 2.242159ms Start:2018-10-18 09:56:44.054236723 +0000 UTC m=+21.077720598 End:2018-10-18 09:56:44.056478954 +0000 UTC m=+21.079962757
I1018 09:56:44.056514       1 scheduler.go:454] Total Schedule Algo cumulative time:421.074938ms for 159
I1018 09:56:44.058388       1 scheduler.go:451] ScheduleAlgoTime 1.738245ms Start:2018-10-18 09:56:44.056639553 +0000 UTC m=+21.080123433 End:2018-10-18 09:56:44.058377823 +0000 UTC m=+21.081861678
I1018 09:56:44.058426       1 scheduler.go:454] Total Schedule Algo cumulative time:422.813183ms for 160
I1018 09:56:44.060352       1 scheduler.go:451] ScheduleAlgoTime 1.743385ms Start:2018-10-18 09:56:44.058600152 +0000 UTC m=+21.082084053 End:2018-10-18 09:56:44.060343632 +0000 UTC m=+21.083827438
I1018 09:56:44.060378       1 scheduler.go:454] Total Schedule Algo cumulative time:424.556568ms for 161
I1018 09:56:44.062347       1 scheduler.go:451] ScheduleAlgoTime 1.804097ms Start:2018-10-18 09:56:44.060533825 +0000 UTC m=+21.084017723 End:2018-10-18 09:56:44.062338017 +0000 UTC m=+21.085821820
I1018 09:56:44.062377       1 scheduler.go:454] Total Schedule Algo cumulative time:426.360665ms for 162
I1018 09:56:44.064334       1 scheduler.go:451] ScheduleAlgoTime 1.804964ms Start:2018-10-18 09:56:44.062523973 +0000 UTC m=+21.086007833 End:2018-10-18 09:56:44.064328992 +0000 UTC m=+21.087812797
I1018 09:56:44.064371       1 scheduler.go:454] Total Schedule Algo cumulative time:428.165629ms for 163
I1018 09:56:44.066404       1 scheduler.go:451] ScheduleAlgoTime 1.818279ms Start:2018-10-18 09:56:44.064578068 +0000 UTC m=+21.088061939 End:2018-10-18 09:56:44.066396415 +0000 UTC m=+21.089880218
I1018 09:56:44.066441       1 scheduler.go:454] Total Schedule Algo cumulative time:429.983908ms for 164
I1018 09:56:44.068506       1 scheduler.go:451] ScheduleAlgoTime 1.945939ms Start:2018-10-18 09:56:44.066552301 +0000 UTC m=+21.090036261 End:2018-10-18 09:56:44.068498397 +0000 UTC m=+21.091982200
I1018 09:56:44.068535       1 scheduler.go:454] Total Schedule Algo cumulative time:431.929847ms for 165
I1018 09:56:44.070294       1 scheduler.go:451] ScheduleAlgoTime 1.609498ms Start:2018-10-18 09:56:44.068676601 +0000 UTC m=+21.092160463 End:2018-10-18 09:56:44.070286155 +0000 UTC m=+21.093769961
I1018 09:56:44.070322       1 scheduler.go:454] Total Schedule Algo cumulative time:433.539345ms for 166
I1018 09:56:44.073164       1 scheduler.go:451] ScheduleAlgoTime 2.570937ms Start:2018-10-18 09:56:44.070584745 +0000 UTC m=+21.094068658 End:2018-10-18 09:56:44.073155779 +0000 UTC m=+21.096639595
I1018 09:56:44.073194       1 scheduler.go:454] Total Schedule Algo cumulative time:436.110282ms for 167
I1018 09:56:44.079638       1 scheduler.go:451] ScheduleAlgoTime 6.243502ms Start:2018-10-18 09:56:44.073381981 +0000 UTC m=+21.096865837 End:2018-10-18 09:56:44.079625536 +0000 UTC m=+21.103109339
I1018 09:56:44.079690       1 scheduler.go:454] Total Schedule Algo cumulative time:442.353784ms for 168
I1018 09:56:44.081636       1 scheduler.go:451] ScheduleAlgoTime 1.801744ms Start:2018-10-18 09:56:44.079826846 +0000 UTC m=+21.103310687 End:2018-10-18 09:56:44.081628626 +0000 UTC m=+21.105112431
I1018 09:56:44.081684       1 scheduler.go:454] Total Schedule Algo cumulative time:444.155528ms for 169
I1018 09:56:44.083869       1 scheduler.go:451] ScheduleAlgoTime 2.027273ms Start:2018-10-18 09:56:44.081834179 +0000 UTC m=+21.105318061 End:2018-10-18 09:56:44.08386153 +0000 UTC m=+21.107345334
I1018 09:56:44.083906       1 scheduler.go:454] Total Schedule Algo cumulative time:446.182801ms for 170
I1018 09:56:44.085816       1 scheduler.go:451] ScheduleAlgoTime 1.724833ms Start:2018-10-18 09:56:44.084082363 +0000 UTC m=+21.107566255 End:2018-10-18 09:56:44.085807273 +0000 UTC m=+21.109291088
I1018 09:56:44.085929       1 scheduler.go:454] Total Schedule Algo cumulative time:447.907634ms for 171
I1018 09:56:44.088374       1 scheduler.go:451] ScheduleAlgoTime 2.278586ms Start:2018-10-18 09:56:44.086086033 +0000 UTC m=+21.109569963 End:2018-10-18 09:56:44.088364745 +0000 UTC m=+21.111848549
I1018 09:56:44.088415       1 scheduler.go:454] Total Schedule Algo cumulative time:450.18622ms for 172
I1018 09:56:44.091023       1 scheduler.go:451] ScheduleAlgoTime 2.445928ms Start:2018-10-18 09:56:44.088569509 +0000 UTC m=+21.112053408 End:2018-10-18 09:56:44.091015533 +0000 UTC m=+21.114499336
I1018 09:56:44.091052       1 scheduler.go:454] Total Schedule Algo cumulative time:452.632148ms for 173
I1018 09:56:44.092964       1 scheduler.go:451] ScheduleAlgoTime 1.741096ms Start:2018-10-18 09:56:44.091215618 +0000 UTC m=+21.114699528 End:2018-10-18 09:56:44.092956822 +0000 UTC m=+21.116440624
I1018 09:56:44.092991       1 scheduler.go:454] Total Schedule Algo cumulative time:454.373244ms for 174
I1018 09:56:44.095040       1 scheduler.go:451] ScheduleAlgoTime 1.933376ms Start:2018-10-18 09:56:44.093099926 +0000 UTC m=+21.116583813 End:2018-10-18 09:56:44.095033382 +0000 UTC m=+21.118517189
I1018 09:56:44.095072       1 scheduler.go:454] Total Schedule Algo cumulative time:456.30662ms for 175
I1018 09:56:44.097238       1 scheduler.go:451] ScheduleAlgoTime 1.954988ms Start:2018-10-18 09:56:44.095275629 +0000 UTC m=+21.118759522 End:2018-10-18 09:56:44.097230703 +0000 UTC m=+21.120714510
I1018 09:56:44.097264       1 scheduler.go:454] Total Schedule Algo cumulative time:458.261608ms for 176
I1018 09:56:44.099529       1 scheduler.go:451] ScheduleAlgoTime 2.062755ms Start:2018-10-18 09:56:44.097453804 +0000 UTC m=+21.120937700 End:2018-10-18 09:56:44.099516653 +0000 UTC m=+21.123000455
I1018 09:56:44.099567       1 scheduler.go:454] Total Schedule Algo cumulative time:460.324363ms for 177
I1018 09:56:44.101596       1 scheduler.go:451] ScheduleAlgoTime 1.844136ms Start:2018-10-18 09:56:44.09974186 +0000 UTC m=+21.123225761 End:2018-10-18 09:56:44.101586089 +0000 UTC m=+21.125069897
I1018 09:56:44.101630       1 scheduler.go:454] Total Schedule Algo cumulative time:462.168499ms for 178
I1018 09:56:44.103541       1 scheduler.go:451] ScheduleAlgoTime 1.76347ms Start:2018-10-18 09:56:44.101768176 +0000 UTC m=+21.125252101 End:2018-10-18 09:56:44.103531767 +0000 UTC m=+21.127015571
I1018 09:56:44.103587       1 scheduler.go:454] Total Schedule Algo cumulative time:463.931969ms for 179
I1018 09:56:44.105443       1 scheduler.go:451] ScheduleAlgoTime 1.704863ms Start:2018-10-18 09:56:44.103731404 +0000 UTC m=+21.127215305 End:2018-10-18 09:56:44.105436361 +0000 UTC m=+21.128920168
I1018 09:56:44.105481       1 scheduler.go:454] Total Schedule Algo cumulative time:465.636832ms for 180
I1018 09:56:44.107428       1 scheduler.go:451] ScheduleAlgoTime 1.72989ms Start:2018-10-18 09:56:44.105689163 +0000 UTC m=+21.129173059 End:2018-10-18 09:56:44.107419126 +0000 UTC m=+21.130902949
I1018 09:56:44.107454       1 scheduler.go:454] Total Schedule Algo cumulative time:467.366722ms for 181
I1018 09:56:44.109491       1 scheduler.go:451] ScheduleAlgoTime 1.883912ms Start:2018-10-18 09:56:44.107599891 +0000 UTC m=+21.131083795 End:2018-10-18 09:56:44.1094839 +0000 UTC m=+21.132967707
I1018 09:56:44.109517       1 scheduler.go:454] Total Schedule Algo cumulative time:469.250634ms for 182
I1018 09:56:44.111530       1 scheduler.go:451] ScheduleAlgoTime 1.786658ms Start:2018-10-18 09:56:44.109734064 +0000 UTC m=+21.133217973 End:2018-10-18 09:56:44.111520828 +0000 UTC m=+21.135004631
I1018 09:56:44.111566       1 scheduler.go:454] Total Schedule Algo cumulative time:471.037292ms for 183
I1018 09:56:44.113620       1 scheduler.go:451] ScheduleAlgoTime 1.898621ms Start:2018-10-18 09:56:44.111714331 +0000 UTC m=+21.135198217 End:2018-10-18 09:56:44.113613031 +0000 UTC m=+21.137096838
I1018 09:56:44.113692       1 scheduler.go:454] Total Schedule Algo cumulative time:472.935913ms for 184
I1018 09:56:44.115680       1 scheduler.go:451] ScheduleAlgoTime 1.836236ms Start:2018-10-18 09:56:44.113823452 +0000 UTC m=+21.137307297 End:2018-10-18 09:56:44.115659701 +0000 UTC m=+21.139143533
I1018 09:56:44.115715       1 scheduler.go:454] Total Schedule Algo cumulative time:474.772149ms for 185
I1018 09:56:44.117987       1 scheduler.go:451] ScheduleAlgoTime 1.981333ms Start:2018-10-18 09:56:44.11599577 +0000 UTC m=+21.139479588 End:2018-10-18 09:56:44.117977109 +0000 UTC m=+21.141460921
I1018 09:56:44.118023       1 scheduler.go:454] Total Schedule Algo cumulative time:476.753482ms for 186
I1018 09:56:44.120468       1 scheduler.go:451] ScheduleAlgoTime 2.280097ms Start:2018-10-18 09:56:44.118178889 +0000 UTC m=+21.141662802 End:2018-10-18 09:56:44.120459095 +0000 UTC m=+21.143942899
I1018 09:56:44.120497       1 scheduler.go:454] Total Schedule Algo cumulative time:479.033579ms for 187
I1018 09:56:44.122369       1 scheduler.go:451] ScheduleAlgoTime 1.724702ms Start:2018-10-18 09:56:44.120637445 +0000 UTC m=+21.144121333 End:2018-10-18 09:56:44.122362233 +0000 UTC m=+21.145846035
I1018 09:56:44.122400       1 scheduler.go:454] Total Schedule Algo cumulative time:480.758281ms for 188
I1018 09:56:44.124486       1 scheduler.go:451] ScheduleAlgoTime 1.94206ms Start:2018-10-18 09:56:44.122536789 +0000 UTC m=+21.146020702 End:2018-10-18 09:56:44.124478955 +0000 UTC m=+21.147962762
I1018 09:56:44.124512       1 scheduler.go:454] Total Schedule Algo cumulative time:482.700341ms for 189
I1018 09:56:44.126733       1 scheduler.go:451] ScheduleAlgoTime 2.048703ms Start:2018-10-18 09:56:44.124671878 +0000 UTC m=+21.148155754 End:2018-10-18 09:56:44.126720622 +0000 UTC m=+21.150204457
I1018 09:56:44.126783       1 scheduler.go:454] Total Schedule Algo cumulative time:484.749044ms for 190
I1018 09:56:44.128975       1 scheduler.go:451] ScheduleAlgoTime 2.001506ms Start:2018-10-18 09:56:44.126967839 +0000 UTC m=+21.150451711 End:2018-10-18 09:56:44.128969414 +0000 UTC m=+21.152453217
I1018 09:56:44.129003       1 scheduler.go:454] Total Schedule Algo cumulative time:486.75055ms for 191
I1018 09:56:44.131769       1 scheduler.go:451] ScheduleAlgoTime 2.58595ms Start:2018-10-18 09:56:44.129176203 +0000 UTC m=+21.152660148 End:2018-10-18 09:56:44.131762296 +0000 UTC m=+21.155246098
I1018 09:56:44.131807       1 scheduler.go:454] Total Schedule Algo cumulative time:489.3365ms for 192
I1018 09:56:44.133578       1 scheduler.go:451] ScheduleAlgoTime 1.651071ms Start:2018-10-18 09:56:44.131920452 +0000 UTC m=+21.155404334 End:2018-10-18 09:56:44.133571598 +0000 UTC m=+21.157055405
I1018 09:56:44.133600       1 scheduler.go:454] Total Schedule Algo cumulative time:490.987571ms for 193
I1018 09:56:44.135528       1 scheduler.go:451] ScheduleAlgoTime 1.79158ms Start:2018-10-18 09:56:44.133728126 +0000 UTC m=+21.157211957 End:2018-10-18 09:56:44.135519725 +0000 UTC m=+21.159003537
I1018 09:56:44.135560       1 scheduler.go:454] Total Schedule Algo cumulative time:492.779151ms for 194
I1018 09:56:44.137537       1 scheduler.go:451] ScheduleAlgoTime 1.840009ms Start:2018-10-18 09:56:44.135688417 +0000 UTC m=+21.159172273 End:2018-10-18 09:56:44.137528374 +0000 UTC m=+21.161012282
I1018 09:56:44.137566       1 scheduler.go:454] Total Schedule Algo cumulative time:494.61916ms for 195
I1018 09:56:44.139632       1 scheduler.go:451] ScheduleAlgoTime 1.900397ms Start:2018-10-18 09:56:44.137725887 +0000 UTC m=+21.161209775 End:2018-10-18 09:56:44.139626365 +0000 UTC m=+21.163110172
I1018 09:56:44.139657       1 scheduler.go:454] Total Schedule Algo cumulative time:496.519557ms for 196
I1018 09:56:44.141817       1 scheduler.go:451] ScheduleAlgoTime 1.946921ms Start:2018-10-18 09:56:44.13986116 +0000 UTC m=+21.163345038 End:2018-10-18 09:56:44.141808155 +0000 UTC m=+21.165291959
I1018 09:56:44.141845       1 scheduler.go:454] Total Schedule Algo cumulative time:498.466478ms for 197
I1018 09:56:44.143585       1 scheduler.go:451] ScheduleAlgoTime 1.577078ms Start:2018-10-18 09:56:44.141999131 +0000 UTC m=+21.165483027 End:2018-10-18 09:56:44.143576301 +0000 UTC m=+21.167060105
I1018 09:56:44.143624       1 scheduler.go:454] Total Schedule Algo cumulative time:500.043556ms for 198
I1018 09:56:44.145439       1 scheduler.go:451] ScheduleAlgoTime 1.633749ms Start:2018-10-18 09:56:44.143798856 +0000 UTC m=+21.167282739 End:2018-10-18 09:56:44.145432686 +0000 UTC m=+21.168916488
I1018 09:56:44.145462       1 scheduler.go:454] Total Schedule Algo cumulative time:501.677305ms for 199
I1018 09:56:44.147457       1 scheduler.go:451] ScheduleAlgoTime 1.751864ms Start:2018-10-18 09:56:44.145697343 +0000 UTC m=+21.169181239 End:2018-10-18 09:56:44.147449251 +0000 UTC m=+21.170933103
I1018 09:56:44.147487       1 scheduler.go:454] Total Schedule Algo cumulative time:503.429169ms for 200
I1018 09:56:44.149561       1 scheduler.go:451] ScheduleAlgoTime 1.948844ms Start:2018-10-18 09:56:44.147604666 +0000 UTC m=+21.171088551 End:2018-10-18 09:56:44.149553591 +0000 UTC m=+21.173037395
I1018 09:56:44.149615       1 scheduler.go:454] Total Schedule Algo cumulative time:505.378013ms for 201
I1018 09:56:44.154495       1 scheduler.go:451] ScheduleAlgoTime 4.692399ms Start:2018-10-18 09:56:44.149794131 +0000 UTC m=+21.173278007 End:2018-10-18 09:56:44.154486602 +0000 UTC m=+21.177970406
I1018 09:56:44.154577       1 scheduler.go:454] Total Schedule Algo cumulative time:510.070412ms for 202
I1018 09:56:44.158246       1 scheduler.go:451] ScheduleAlgoTime 3.416113ms Start:2018-10-18 09:56:44.154823668 +0000 UTC m=+21.178307531 End:2018-10-18 09:56:44.158239839 +0000 UTC m=+21.181723644
I1018 09:56:44.158280       1 scheduler.go:454] Total Schedule Algo cumulative time:513.486525ms for 203
I1018 09:56:44.160204       1 scheduler.go:451] ScheduleAlgoTime 1.800831ms Start:2018-10-18 09:56:44.158395355 +0000 UTC m=+21.181879216 End:2018-10-18 09:56:44.160196242 +0000 UTC m=+21.183680047
I1018 09:56:44.160234       1 scheduler.go:454] Total Schedule Algo cumulative time:515.287356ms for 204
I1018 09:56:44.162153       1 scheduler.go:451] ScheduleAlgoTime 1.785185ms Start:2018-10-18 09:56:44.16035989 +0000 UTC m=+21.183843802 End:2018-10-18 09:56:44.162145183 +0000 UTC m=+21.185628987
I1018 09:56:44.162189       1 scheduler.go:454] Total Schedule Algo cumulative time:517.072541ms for 205
I1018 09:56:44.164080       1 scheduler.go:451] ScheduleAlgoTime 1.745439ms Start:2018-10-18 09:56:44.16232913 +0000 UTC m=+21.185813007 End:2018-10-18 09:56:44.164074643 +0000 UTC m=+21.187558446
I1018 09:56:44.164103       1 scheduler.go:454] Total Schedule Algo cumulative time:518.81798ms for 206
I1018 09:56:44.166383       1 scheduler.go:451] ScheduleAlgoTime 2.066867ms Start:2018-10-18 09:56:44.164307198 +0000 UTC m=+21.187791069 End:2018-10-18 09:56:44.166374133 +0000 UTC m=+21.189857936
I1018 09:56:44.166421       1 scheduler.go:454] Total Schedule Algo cumulative time:520.884847ms for 207
I1018 09:56:44.168184       1 scheduler.go:451] ScheduleAlgoTime 1.639054ms Start:2018-10-18 09:56:44.166538996 +0000 UTC m=+21.190022855 End:2018-10-18 09:56:44.168178106 +0000 UTC m=+21.191661909
I1018 09:56:44.168214       1 scheduler.go:454] Total Schedule Algo cumulative time:522.523901ms for 208
I1018 09:56:44.169991       1 scheduler.go:451] ScheduleAlgoTime 1.595316ms Start:2018-10-18 09:56:44.168387948 +0000 UTC m=+21.191871751 End:2018-10-18 09:56:44.169983265 +0000 UTC m=+21.193467067
I1018 09:56:44.170025       1 scheduler.go:454] Total Schedule Algo cumulative time:524.119217ms for 209
I1018 09:56:44.172413       1 scheduler.go:451] ScheduleAlgoTime 2.165333ms Start:2018-10-18 09:56:44.170241221 +0000 UTC m=+21.193725109 End:2018-10-18 09:56:44.172406638 +0000 UTC m=+21.195890442
I1018 09:56:44.172448       1 scheduler.go:454] Total Schedule Algo cumulative time:526.28455ms for 210
I1018 09:56:44.174475       1 scheduler.go:451] ScheduleAlgoTime 1.867684ms Start:2018-10-18 09:56:44.172600198 +0000 UTC m=+21.196084075 End:2018-10-18 09:56:44.174467955 +0000 UTC m=+21.197951759
I1018 09:56:44.174507       1 scheduler.go:454] Total Schedule Algo cumulative time:528.152234ms for 211
I1018 09:56:44.176525       1 scheduler.go:451] ScheduleAlgoTime 1.866722ms Start:2018-10-18 09:56:44.174651 +0000 UTC m=+21.198134914 End:2018-10-18 09:56:44.176517831 +0000 UTC m=+21.200001636
I1018 09:56:44.176565       1 scheduler.go:454] Total Schedule Algo cumulative time:530.018956ms for 212
I1018 09:56:44.178612       1 scheduler.go:451] ScheduleAlgoTime 1.881665ms Start:2018-10-18 09:56:44.176724422 +0000 UTC m=+21.200208324 End:2018-10-18 09:56:44.178606186 +0000 UTC m=+21.202089989
I1018 09:56:44.178640       1 scheduler.go:454] Total Schedule Algo cumulative time:531.900621ms for 213
I1018 09:56:44.180400       1 scheduler.go:451] ScheduleAlgoTime 1.594699ms Start:2018-10-18 09:56:44.178797182 +0000 UTC m=+21.202281070 End:2018-10-18 09:56:44.180391965 +0000 UTC m=+21.203875769
I1018 09:56:44.180434       1 scheduler.go:454] Total Schedule Algo cumulative time:533.49532ms for 214
I1018 09:56:44.182288       1 scheduler.go:451] ScheduleAlgoTime 1.713656ms Start:2018-10-18 09:56:44.180567457 +0000 UTC m=+21.204051260 End:2018-10-18 09:56:44.182281077 +0000 UTC m=+21.205764916
I1018 09:56:44.182314       1 scheduler.go:454] Total Schedule Algo cumulative time:535.208976ms for 215
I1018 09:56:44.184193       1 scheduler.go:451] ScheduleAlgoTime 1.790005ms Start:2018-10-18 09:56:44.182397025 +0000 UTC m=+21.205880910 End:2018-10-18 09:56:44.184187113 +0000 UTC m=+21.207670915
I1018 09:56:44.184221       1 scheduler.go:454] Total Schedule Algo cumulative time:536.998981ms for 216
I1018 09:56:44.186062       1 scheduler.go:451] ScheduleAlgoTime 1.690865ms Start:2018-10-18 09:56:44.18436327 +0000 UTC m=+21.207847174 End:2018-10-18 09:56:44.186054237 +0000 UTC m=+21.209538039
I1018 09:56:44.186103       1 scheduler.go:454] Total Schedule Algo cumulative time:538.689846ms for 217
I1018 09:56:44.188239       1 scheduler.go:451] ScheduleAlgoTime 1.982907ms Start:2018-10-18 09:56:44.186246948 +0000 UTC m=+21.209730885 End:2018-10-18 09:56:44.188229876 +0000 UTC m=+21.211713792
I1018 09:56:44.188270       1 scheduler.go:454] Total Schedule Algo cumulative time:540.672753ms for 218
I1018 09:56:44.190825       1 scheduler.go:451] ScheduleAlgoTime 1.914791ms Start:2018-10-18 09:56:44.188902685 +0000 UTC m=+21.212386619 End:2018-10-18 09:56:44.190817607 +0000 UTC m=+21.214301410
I1018 09:56:44.190853       1 scheduler.go:454] Total Schedule Algo cumulative time:542.587544ms for 219
I1018 09:56:44.192783       1 scheduler.go:451] ScheduleAlgoTime 1.820364ms Start:2018-10-18 09:56:44.190956494 +0000 UTC m=+21.214440304 End:2018-10-18 09:56:44.192776865 +0000 UTC m=+21.216260668
I1018 09:56:44.192829       1 scheduler.go:454] Total Schedule Algo cumulative time:544.407908ms for 220
I1018 09:56:44.194962       1 scheduler.go:451] ScheduleAlgoTime 1.983835ms Start:2018-10-18 09:56:44.19296861 +0000 UTC m=+21.216452476 End:2018-10-18 09:56:44.194952439 +0000 UTC m=+21.218436311
I1018 09:56:44.194991       1 scheduler.go:454] Total Schedule Algo cumulative time:546.391743ms for 221
I1018 09:56:44.197010       1 scheduler.go:451] ScheduleAlgoTime 1.820095ms Start:2018-10-18 09:56:44.195184427 +0000 UTC m=+21.218668303 End:2018-10-18 09:56:44.197004595 +0000 UTC m=+21.220488398
I1018 09:56:44.197036       1 scheduler.go:454] Total Schedule Algo cumulative time:548.211838ms for 222
I1018 09:56:44.198980       1 scheduler.go:451] ScheduleAlgoTime 1.798841ms Start:2018-10-18 09:56:44.197172358 +0000 UTC m=+21.220656253 End:2018-10-18 09:56:44.198971286 +0000 UTC m=+21.222455094
I1018 09:56:44.199019       1 scheduler.go:454] Total Schedule Algo cumulative time:550.010679ms for 223
I1018 09:56:44.201061       1 scheduler.go:451] ScheduleAlgoTime 1.937963ms Start:2018-10-18 09:56:44.19911291 +0000 UTC m=+21.222596778 End:2018-10-18 09:56:44.201050928 +0000 UTC m=+21.224534741
I1018 09:56:44.201098       1 scheduler.go:454] Total Schedule Algo cumulative time:551.948642ms for 224
I1018 09:56:44.203053       1 scheduler.go:451] ScheduleAlgoTime 1.790758ms Start:2018-10-18 09:56:44.201255903 +0000 UTC m=+21.224739813 End:2018-10-18 09:56:44.203046763 +0000 UTC m=+21.226530571
I1018 09:56:44.203080       1 scheduler.go:454] Total Schedule Algo cumulative time:553.7394ms for 225
I1018 09:56:44.205019       1 scheduler.go:451] ScheduleAlgoTime 1.811639ms Start:2018-10-18 09:56:44.203197077 +0000 UTC m=+21.226680953 End:2018-10-18 09:56:44.205008604 +0000 UTC m=+21.228492592
I1018 09:56:44.205054       1 scheduler.go:454] Total Schedule Algo cumulative time:555.551039ms for 226
I1018 09:56:44.206924       1 scheduler.go:451] ScheduleAlgoTime 1.727422ms Start:2018-10-18 09:56:44.205188779 +0000 UTC m=+21.228672678 End:2018-10-18 09:56:44.206916295 +0000 UTC m=+21.230400100
I1018 09:56:44.206957       1 scheduler.go:454] Total Schedule Algo cumulative time:557.278461ms for 227
I1018 09:56:44.209063       1 scheduler.go:451] ScheduleAlgoTime 1.880177ms Start:2018-10-18 09:56:44.207174435 +0000 UTC m=+21.230658323 End:2018-10-18 09:56:44.209054684 +0000 UTC m=+21.232538500
I1018 09:56:44.209090       1 scheduler.go:454] Total Schedule Algo cumulative time:559.158638ms for 228
I1018 09:56:44.211073       1 scheduler.go:451] ScheduleAlgoTime 1.890552ms Start:2018-10-18 09:56:44.209174662 +0000 UTC m=+21.232658554 End:2018-10-18 09:56:44.211065207 +0000 UTC m=+21.234549106
I1018 09:56:44.211105       1 scheduler.go:454] Total Schedule Algo cumulative time:561.04919ms for 229
I1018 09:56:44.213238       1 scheduler.go:451] ScheduleAlgoTime 1.964429ms Start:2018-10-18 09:56:44.211260286 +0000 UTC m=+21.234744154 End:2018-10-18 09:56:44.213224735 +0000 UTC m=+21.236708583
I1018 09:56:44.213274       1 scheduler.go:454] Total Schedule Algo cumulative time:563.013619ms for 230
I1018 09:56:44.215275       1 scheduler.go:451] ScheduleAlgoTime 1.825793ms Start:2018-10-18 09:56:44.213440664 +0000 UTC m=+21.236924551 End:2018-10-18 09:56:44.21526654 +0000 UTC m=+21.238750344
I1018 09:56:44.215319       1 scheduler.go:454] Total Schedule Algo cumulative time:564.839412ms for 231
I1018 09:56:44.217175       1 scheduler.go:451] ScheduleAlgoTime 1.718659ms Start:2018-10-18 09:56:44.215449137 +0000 UTC m=+21.238933021 End:2018-10-18 09:56:44.217167876 +0000 UTC m=+21.240651680
I1018 09:56:44.217201       1 scheduler.go:454] Total Schedule Algo cumulative time:566.558071ms for 232
I1018 09:56:44.219183       1 scheduler.go:451] ScheduleAlgoTime 1.833296ms Start:2018-10-18 09:56:44.217340676 +0000 UTC m=+21.240824544 End:2018-10-18 09:56:44.219174028 +0000 UTC m=+21.242657840
I1018 09:56:44.219222       1 scheduler.go:454] Total Schedule Algo cumulative time:568.391367ms for 233
I1018 09:56:44.220994       1 scheduler.go:451] ScheduleAlgoTime 1.657595ms Start:2018-10-18 09:56:44.219326913 +0000 UTC m=+21.242810803 End:2018-10-18 09:56:44.22098449 +0000 UTC m=+21.244468398
I1018 09:56:44.221026       1 scheduler.go:454] Total Schedule Algo cumulative time:570.048962ms for 234
I1018 09:56:44.222923       1 scheduler.go:451] ScheduleAlgoTime 1.760101ms Start:2018-10-18 09:56:44.221155937 +0000 UTC m=+21.244639848 End:2018-10-18 09:56:44.222916146 +0000 UTC m=+21.246399949
I1018 09:56:44.222951       1 scheduler.go:454] Total Schedule Algo cumulative time:571.809063ms for 235
I1018 09:56:44.224783       1 scheduler.go:451] ScheduleAlgoTime 1.715008ms Start:2018-10-18 09:56:44.223061372 +0000 UTC m=+21.246545254 End:2018-10-18 09:56:44.224776458 +0000 UTC m=+21.248260262
I1018 09:56:44.224811       1 scheduler.go:454] Total Schedule Algo cumulative time:573.524071ms for 236
I1018 09:56:44.226953       1 scheduler.go:451] ScheduleAlgoTime 1.984438ms Start:2018-10-18 09:56:44.224963324 +0000 UTC m=+21.248447257 End:2018-10-18 09:56:44.226947892 +0000 UTC m=+21.250431695
I1018 09:56:44.226978       1 scheduler.go:454] Total Schedule Algo cumulative time:575.508509ms for 237
I1018 09:56:44.228991       1 scheduler.go:451] ScheduleAlgoTime 1.833972ms Start:2018-10-18 09:56:44.227150951 +0000 UTC m=+21.250634825 End:2018-10-18 09:56:44.228984989 +0000 UTC m=+21.252468797
I1018 09:56:44.229015       1 scheduler.go:454] Total Schedule Algo cumulative time:577.342481ms for 238
I1018 09:56:44.231218       1 scheduler.go:451] ScheduleAlgoTime 2.006039ms Start:2018-10-18 09:56:44.229203198 +0000 UTC m=+21.252687001 End:2018-10-18 09:56:44.231209129 +0000 UTC m=+21.254693040
I1018 09:56:44.231249       1 scheduler.go:454] Total Schedule Algo cumulative time:579.34852ms for 239
I1018 09:56:44.233435       1 scheduler.go:451] ScheduleAlgoTime 2.03078ms Start:2018-10-18 09:56:44.231398487 +0000 UTC m=+21.254882388 End:2018-10-18 09:56:44.233429365 +0000 UTC m=+21.256913168
I1018 09:56:44.233461       1 scheduler.go:454] Total Schedule Algo cumulative time:581.3793ms for 240
I1018 09:56:44.237612       1 scheduler.go:451] ScheduleAlgoTime 3.860817ms Start:2018-10-18 09:56:44.233743045 +0000 UTC m=+21.257226989 End:2018-10-18 09:56:44.237604 +0000 UTC m=+21.261087806
I1018 09:56:44.237658       1 scheduler.go:454] Total Schedule Algo cumulative time:585.240117ms for 241
I1018 09:56:44.240730       1 scheduler.go:451] ScheduleAlgoTime 2.898273ms Start:2018-10-18 09:56:44.237823307 +0000 UTC m=+21.261307125 End:2018-10-18 09:56:44.240721595 +0000 UTC m=+21.264205398
I1018 09:56:44.240761       1 scheduler.go:454] Total Schedule Algo cumulative time:588.13839ms for 242
I1018 09:56:44.242973       1 scheduler.go:451] ScheduleAlgoTime 2.014101ms Start:2018-10-18 09:56:44.240947573 +0000 UTC m=+21.264431474 End:2018-10-18 09:56:44.242961762 +0000 UTC m=+21.266445575
I1018 09:56:44.243021       1 scheduler.go:454] Total Schedule Algo cumulative time:590.152491ms for 243
I1018 09:56:44.244902       1 scheduler.go:451] ScheduleAlgoTime 1.667732ms Start:2018-10-18 09:56:44.243227425 +0000 UTC m=+21.266711314 End:2018-10-18 09:56:44.244895245 +0000 UTC m=+21.268379046
I1018 09:56:44.244945       1 scheduler.go:454] Total Schedule Algo cumulative time:591.820223ms for 244
I1018 09:56:44.247049       1 scheduler.go:451] ScheduleAlgoTime 1.925852ms Start:2018-10-18 09:56:44.245109357 +0000 UTC m=+21.268593270 End:2018-10-18 09:56:44.247035224 +0000 UTC m=+21.270519122
I1018 09:56:44.247100       1 scheduler.go:454] Total Schedule Algo cumulative time:593.746075ms for 245
I1018 09:56:44.249297       1 scheduler.go:451] ScheduleAlgoTime 2.040792ms Start:2018-10-18 09:56:44.247249185 +0000 UTC m=+21.270733097 End:2018-10-18 09:56:44.249290084 +0000 UTC m=+21.272773889
I1018 09:56:44.249336       1 scheduler.go:454] Total Schedule Algo cumulative time:595.786867ms for 246
I1018 09:56:44.251285       1 scheduler.go:451] ScheduleAlgoTime 1.829584ms Start:2018-10-18 09:56:44.249448207 +0000 UTC m=+21.272932030 End:2018-10-18 09:56:44.25127781 +0000 UTC m=+21.274761614
I1018 09:56:44.251320       1 scheduler.go:454] Total Schedule Algo cumulative time:597.616451ms for 247
I1018 09:56:44.253684       1 scheduler.go:451] ScheduleAlgoTime 2.216952ms Start:2018-10-18 09:56:44.251438416 +0000 UTC m=+21.274922325 End:2018-10-18 09:56:44.253655473 +0000 UTC m=+21.277139277
I1018 09:56:44.253740       1 scheduler.go:454] Total Schedule Algo cumulative time:599.833403ms for 248
I1018 09:56:44.255915       1 scheduler.go:451] ScheduleAlgoTime 1.948358ms Start:2018-10-18 09:56:44.25395752 +0000 UTC m=+21.277441367 End:2018-10-18 09:56:44.255905905 +0000 UTC m=+21.279389725
I1018 09:56:44.255946       1 scheduler.go:454] Total Schedule Algo cumulative time:601.781761ms for 249
I1018 09:56:44.258176       1 scheduler.go:451] ScheduleAlgoTime 2.02874ms Start:2018-10-18 09:56:44.256138959 +0000 UTC m=+21.279622844 End:2018-10-18 09:56:44.25816778 +0000 UTC m=+21.281651584
I1018 09:56:44.258206       1 scheduler.go:454] Total Schedule Algo cumulative time:603.810501ms for 250
I1018 09:56:44.259999       1 scheduler.go:451] ScheduleAlgoTime 1.639772ms Start:2018-10-18 09:56:44.258353314 +0000 UTC m=+21.281837132 End:2018-10-18 09:56:44.259993099 +0000 UTC m=+21.283476904
I1018 09:56:44.260036       1 scheduler.go:454] Total Schedule Algo cumulative time:605.450273ms for 251
I1018 09:56:44.262215       1 scheduler.go:451] ScheduleAlgoTime 2.015275ms Start:2018-10-18 09:56:44.260190594 +0000 UTC m=+21.283674475 End:2018-10-18 09:56:44.262205945 +0000 UTC m=+21.285689750
I1018 09:56:44.262246       1 scheduler.go:454] Total Schedule Algo cumulative time:607.465548ms for 252
I1018 09:56:44.264129       1 scheduler.go:451] ScheduleAlgoTime 1.740675ms Start:2018-10-18 09:56:44.262381395 +0000 UTC m=+21.285865284 End:2018-10-18 09:56:44.264122153 +0000 UTC m=+21.287605959
I1018 09:56:44.264158       1 scheduler.go:454] Total Schedule Algo cumulative time:609.206223ms for 253
I1018 09:56:44.266123       1 scheduler.go:451] ScheduleAlgoTime 1.825411ms Start:2018-10-18 09:56:44.264291353 +0000 UTC m=+21.287775208 End:2018-10-18 09:56:44.26611681 +0000 UTC m=+21.289600619
I1018 09:56:44.266148       1 scheduler.go:454] Total Schedule Algo cumulative time:611.031634ms for 254
I1018 09:56:44.268270       1 scheduler.go:451] ScheduleAlgoTime 1.948456ms Start:2018-10-18 09:56:44.266313772 +0000 UTC m=+21.289797674 End:2018-10-18 09:56:44.268262283 +0000 UTC m=+21.291746130
I1018 09:56:44.268298       1 scheduler.go:454] Total Schedule Algo cumulative time:612.98009ms for 255
I1018 09:56:44.270550       1 scheduler.go:451] ScheduleAlgoTime 2.081501ms Start:2018-10-18 09:56:44.268460639 +0000 UTC m=+21.291944501 End:2018-10-18 09:56:44.270542196 +0000 UTC m=+21.294026002
I1018 09:56:44.270581       1 scheduler.go:454] Total Schedule Algo cumulative time:615.061591ms for 256
I1018 09:56:44.272606       1 scheduler.go:451] ScheduleAlgoTime 1.894088ms Start:2018-10-18 09:56:44.270703715 +0000 UTC m=+21.294187625 End:2018-10-18 09:56:44.27259791 +0000 UTC m=+21.296081713
I1018 09:56:44.272639       1 scheduler.go:454] Total Schedule Algo cumulative time:616.955679ms for 257
I1018 09:56:44.274577       1 scheduler.go:451] ScheduleAlgoTime 1.776533ms Start:2018-10-18 09:56:44.272793571 +0000 UTC m=+21.296277459 End:2018-10-18 09:56:44.274570187 +0000 UTC m=+21.298053992
I1018 09:56:44.274622       1 scheduler.go:454] Total Schedule Algo cumulative time:618.732212ms for 258
I1018 09:56:44.276737       1 scheduler.go:451] ScheduleAlgoTime 1.915861ms Start:2018-10-18 09:56:44.27481471 +0000 UTC m=+21.298298607 End:2018-10-18 09:56:44.276730664 +0000 UTC m=+21.300214468
I1018 09:56:44.276796       1 scheduler.go:454] Total Schedule Algo cumulative time:620.648073ms for 259
I1018 09:56:44.279028       1 scheduler.go:451] ScheduleAlgoTime 2.026374ms Start:2018-10-18 09:56:44.276992409 +0000 UTC m=+21.300476228 End:2018-10-18 09:56:44.279018788 +0000 UTC m=+21.302502602
I1018 09:56:44.279064       1 scheduler.go:454] Total Schedule Algo cumulative time:622.674447ms for 260
I1018 09:56:44.281443       1 scheduler.go:451] ScheduleAlgoTime 2.226017ms Start:2018-10-18 09:56:44.279207326 +0000 UTC m=+21.302691223 End:2018-10-18 09:56:44.28143329 +0000 UTC m=+21.304917240
I1018 09:56:44.281479       1 scheduler.go:454] Total Schedule Algo cumulative time:624.900464ms for 261
I1018 09:56:44.283543       1 scheduler.go:451] ScheduleAlgoTime 1.939613ms Start:2018-10-18 09:56:44.281596904 +0000 UTC m=+21.305080780 End:2018-10-18 09:56:44.283536586 +0000 UTC m=+21.307020393
I1018 09:56:44.283571       1 scheduler.go:454] Total Schedule Algo cumulative time:626.840077ms for 262
I1018 09:56:44.285811       1 scheduler.go:451] ScheduleAlgoTime 2.029499ms Start:2018-10-18 09:56:44.283728023 +0000 UTC m=+21.307211916 End:2018-10-18 09:56:44.285757553 +0000 UTC m=+21.309241415
I1018 09:56:44.285836       1 scheduler.go:454] Total Schedule Algo cumulative time:628.869576ms for 263
I1018 09:56:44.287984       1 scheduler.go:451] ScheduleAlgoTime 1.964931ms Start:2018-10-18 09:56:44.286009448 +0000 UTC m=+21.309493392 End:2018-10-18 09:56:44.287974485 +0000 UTC m=+21.311458323
I1018 09:56:44.288007       1 scheduler.go:454] Total Schedule Algo cumulative time:630.834507ms for 264
I1018 09:56:44.289833       1 scheduler.go:451] ScheduleAlgoTime 1.667447ms Start:2018-10-18 09:56:44.288159213 +0000 UTC m=+21.311643105 End:2018-10-18 09:56:44.289826748 +0000 UTC m=+21.313310552
I1018 09:56:44.289864       1 scheduler.go:454] Total Schedule Algo cumulative time:632.501954ms for 265
I1018 09:56:44.292131       1 scheduler.go:451] ScheduleAlgoTime 2.091622ms Start:2018-10-18 09:56:44.290032871 +0000 UTC m=+21.313516768 End:2018-10-18 09:56:44.292124582 +0000 UTC m=+21.315608390
I1018 09:56:44.292156       1 scheduler.go:454] Total Schedule Algo cumulative time:634.593576ms for 266
I1018 09:56:44.294085       1 scheduler.go:451] ScheduleAlgoTime 1.803819ms Start:2018-10-18 09:56:44.292257874 +0000 UTC m=+21.315741774 End:2018-10-18 09:56:44.294061788 +0000 UTC m=+21.317545593
I1018 09:56:44.294111       1 scheduler.go:454] Total Schedule Algo cumulative time:636.397395ms for 267
I1018 09:56:44.295942       1 scheduler.go:451] ScheduleAlgoTime 1.711969ms Start:2018-10-18 09:56:44.294221893 +0000 UTC m=+21.317705768 End:2018-10-18 09:56:44.295933932 +0000 UTC m=+21.319417737
I1018 09:56:44.295971       1 scheduler.go:454] Total Schedule Algo cumulative time:638.109364ms for 268
I1018 09:56:44.298091       1 scheduler.go:451] ScheduleAlgoTime 1.906092ms Start:2018-10-18 09:56:44.296177734 +0000 UTC m=+21.319661621 End:2018-10-18 09:56:44.298083908 +0000 UTC m=+21.321567713
I1018 09:56:44.298117       1 scheduler.go:454] Total Schedule Algo cumulative time:640.015456ms for 269
I1018 09:56:44.300192       1 scheduler.go:451] ScheduleAlgoTime 1.952988ms Start:2018-10-18 09:56:44.298229467 +0000 UTC m=+21.321713333 End:2018-10-18 09:56:44.300182506 +0000 UTC m=+21.323666321
I1018 09:56:44.300222       1 scheduler.go:454] Total Schedule Algo cumulative time:641.968444ms for 270
I1018 09:56:44.302151       1 scheduler.go:451] ScheduleAlgoTime 1.798699ms Start:2018-10-18 09:56:44.300345712 +0000 UTC m=+21.323829615 End:2018-10-18 09:56:44.302144508 +0000 UTC m=+21.325628314
I1018 09:56:44.302176       1 scheduler.go:454] Total Schedule Algo cumulative time:643.767143ms for 271
I1018 09:56:44.304170       1 scheduler.go:451] ScheduleAlgoTime 1.83214ms Start:2018-10-18 09:56:44.302330145 +0000 UTC m=+21.325814012 End:2018-10-18 09:56:44.304162349 +0000 UTC m=+21.327646152
I1018 09:56:44.304206       1 scheduler.go:454] Total Schedule Algo cumulative time:645.599283ms for 272
I1018 09:56:44.306674       1 scheduler.go:451] ScheduleAlgoTime 2.300483ms Start:2018-10-18 09:56:44.304358316 +0000 UTC m=+21.327842194 End:2018-10-18 09:56:44.306658874 +0000 UTC m=+21.330142677
I1018 09:56:44.306705       1 scheduler.go:454] Total Schedule Algo cumulative time:647.899766ms for 273
I1018 09:56:44.308807       1 scheduler.go:451] ScheduleAlgoTime 1.920637ms Start:2018-10-18 09:56:44.306875157 +0000 UTC m=+21.330359014 End:2018-10-18 09:56:44.308795834 +0000 UTC m=+21.332279651
I1018 09:56:44.308851       1 scheduler.go:454] Total Schedule Algo cumulative time:649.820403ms for 274
I1018 09:56:44.310719       1 scheduler.go:451] ScheduleAlgoTime 1.75042ms Start:2018-10-18 09:56:44.308959429 +0000 UTC m=+21.332443310 End:2018-10-18 09:56:44.310709918 +0000 UTC m=+21.334193730
I1018 09:56:44.310753       1 scheduler.go:454] Total Schedule Algo cumulative time:651.570823ms for 275
I1018 09:56:44.312762       1 scheduler.go:451] ScheduleAlgoTime 1.755763ms Start:2018-10-18 09:56:44.310993368 +0000 UTC m=+21.334481973 End:2018-10-18 09:56:44.312753934 +0000 UTC m=+21.336237736
I1018 09:56:44.312839       1 scheduler.go:454] Total Schedule Algo cumulative time:653.326586ms for 276
I1018 09:56:44.314847       1 scheduler.go:451] ScheduleAlgoTime 1.902437ms Start:2018-10-18 09:56:44.312937202 +0000 UTC m=+21.336421092 End:2018-10-18 09:56:44.314839723 +0000 UTC m=+21.338323529
I1018 09:56:44.314875       1 scheduler.go:454] Total Schedule Algo cumulative time:655.229023ms for 277
I1018 09:56:44.317269       1 scheduler.go:451] ScheduleAlgoTime 2.275861ms Start:2018-10-18 09:56:44.314985707 +0000 UTC m=+21.338469634 End:2018-10-18 09:56:44.317261693 +0000 UTC m=+21.340745495
I1018 09:56:44.317298       1 scheduler.go:454] Total Schedule Algo cumulative time:657.504884ms for 278
I1018 09:56:44.319347       1 scheduler.go:451] ScheduleAlgoTime 1.916736ms Start:2018-10-18 09:56:44.317422884 +0000 UTC m=+21.340906778 End:2018-10-18 09:56:44.319339705 +0000 UTC m=+21.342823514
I1018 09:56:44.319374       1 scheduler.go:454] Total Schedule Algo cumulative time:659.42162ms for 279
I1018 09:56:44.322901       1 scheduler.go:451] ScheduleAlgoTime 3.308253ms Start:2018-10-18 09:56:44.319583067 +0000 UTC m=+21.343066960 End:2018-10-18 09:56:44.3228914 +0000 UTC m=+21.346375213
I1018 09:56:44.322946       1 scheduler.go:454] Total Schedule Algo cumulative time:662.729873ms for 280
I1018 09:56:44.326878       1 scheduler.go:451] ScheduleAlgoTime 3.710058ms Start:2018-10-18 09:56:44.323156216 +0000 UTC m=+21.346640117 End:2018-10-18 09:56:44.326866366 +0000 UTC m=+21.350350175
I1018 09:56:44.326917       1 scheduler.go:454] Total Schedule Algo cumulative time:666.439931ms for 281
I1018 09:56:44.329116       1 scheduler.go:451] ScheduleAlgoTime 2.052552ms Start:2018-10-18 09:56:44.327052759 +0000 UTC m=+21.350536614 End:2018-10-18 09:56:44.329105341 +0000 UTC m=+21.352589166
I1018 09:56:44.329157       1 scheduler.go:454] Total Schedule Algo cumulative time:668.492483ms for 282
I1018 09:56:44.331479       1 scheduler.go:451] ScheduleAlgoTime 2.099392ms Start:2018-10-18 09:56:44.329371794 +0000 UTC m=+21.352855706 End:2018-10-18 09:56:44.331471295 +0000 UTC m=+21.354955098
I1018 09:56:44.331508       1 scheduler.go:454] Total Schedule Algo cumulative time:670.591875ms for 283
I1018 09:56:44.333330       1 scheduler.go:451] ScheduleAlgoTime 1.688099ms Start:2018-10-18 09:56:44.33163533 +0000 UTC m=+21.355119160 End:2018-10-18 09:56:44.333323452 +0000 UTC m=+21.356807259
I1018 09:56:44.333356       1 scheduler.go:454] Total Schedule Algo cumulative time:672.279974ms for 284
I1018 09:56:44.335570       1 scheduler.go:451] ScheduleAlgoTime 2.093201ms Start:2018-10-18 09:56:44.333467246 +0000 UTC m=+21.356951186 End:2018-10-18 09:56:44.335560543 +0000 UTC m=+21.359044387
I1018 09:56:44.335616       1 scheduler.go:454] Total Schedule Algo cumulative time:674.373175ms for 285
I1018 09:56:44.337598       1 scheduler.go:451] ScheduleAlgoTime 1.822365ms Start:2018-10-18 09:56:44.335768281 +0000 UTC m=+21.359252183 End:2018-10-18 09:56:44.337590715 +0000 UTC m=+21.361074548
I1018 09:56:44.337641       1 scheduler.go:454] Total Schedule Algo cumulative time:676.19554ms for 286
I1018 09:56:44.339530       1 scheduler.go:451] ScheduleAlgoTime 1.67814ms Start:2018-10-18 09:56:44.337845063 +0000 UTC m=+21.361328957 End:2018-10-18 09:56:44.33952326 +0000 UTC m=+21.363007097
I1018 09:56:44.339556       1 scheduler.go:454] Total Schedule Algo cumulative time:677.87368ms for 287
I1018 09:56:44.341415       1 scheduler.go:451] ScheduleAlgoTime 1.767163ms Start:2018-10-18 09:56:44.339641716 +0000 UTC m=+21.363125577 End:2018-10-18 09:56:44.341408932 +0000 UTC m=+21.364892740
I1018 09:56:44.341448       1 scheduler.go:454] Total Schedule Algo cumulative time:679.640843ms for 288
I1018 09:56:44.343221       1 scheduler.go:451] ScheduleAlgoTime 1.644835ms Start:2018-10-18 09:56:44.341566387 +0000 UTC m=+21.365050313 End:2018-10-18 09:56:44.343211345 +0000 UTC m=+21.366695148
I1018 09:56:44.343257       1 scheduler.go:454] Total Schedule Algo cumulative time:681.285678ms for 289
I1018 09:56:44.345437       1 scheduler.go:451] ScheduleAlgoTime 2.053187ms Start:2018-10-18 09:56:44.34337615 +0000 UTC m=+21.366860067 End:2018-10-18 09:56:44.345429448 +0000 UTC m=+21.368913254
I1018 09:56:44.345468       1 scheduler.go:454] Total Schedule Algo cumulative time:683.338865ms for 290
I1018 09:56:44.347608       1 scheduler.go:451] ScheduleAlgoTime 1.954941ms Start:2018-10-18 09:56:44.34564603 +0000 UTC m=+21.369129911 End:2018-10-18 09:56:44.347601049 +0000 UTC m=+21.371084852
I1018 09:56:44.347636       1 scheduler.go:454] Total Schedule Algo cumulative time:685.293806ms for 291
I1018 09:56:44.349885       1 scheduler.go:451] ScheduleAlgoTime 2.102539ms Start:2018-10-18 09:56:44.347772848 +0000 UTC m=+21.371256726 End:2018-10-18 09:56:44.34987546 +0000 UTC m=+21.373359265
I1018 09:56:44.349914       1 scheduler.go:454] Total Schedule Algo cumulative time:687.396345ms for 292
I1018 09:56:44.352108       1 scheduler.go:451] ScheduleAlgoTime 2.027827ms Start:2018-10-18 09:56:44.350073291 +0000 UTC m=+21.373557097 End:2018-10-18 09:56:44.352101122 +0000 UTC m=+21.375584924
I1018 09:56:44.352143       1 scheduler.go:454] Total Schedule Algo cumulative time:689.424172ms for 293
I1018 09:56:44.354325       1 scheduler.go:451] ScheduleAlgoTime 2.037712ms Start:2018-10-18 09:56:44.352275277 +0000 UTC m=+21.375759079 End:2018-10-18 09:56:44.354312985 +0000 UTC m=+21.377796791
I1018 09:56:44.354368       1 scheduler.go:454] Total Schedule Algo cumulative time:691.461884ms for 294
I1018 09:56:44.356221       1 scheduler.go:451] ScheduleAlgoTime 1.706398ms Start:2018-10-18 09:56:44.354505933 +0000 UTC m=+21.377989832 End:2018-10-18 09:56:44.356212419 +0000 UTC m=+21.379696230
I1018 09:56:44.356254       1 scheduler.go:454] Total Schedule Algo cumulative time:693.168282ms for 295
I1018 09:56:44.358563       1 scheduler.go:451] ScheduleAlgoTime 2.0914ms Start:2018-10-18 09:56:44.356462053 +0000 UTC m=+21.379945946 End:2018-10-18 09:56:44.358553532 +0000 UTC m=+21.382037346
I1018 09:56:44.358607       1 scheduler.go:454] Total Schedule Algo cumulative time:695.259682ms for 296
I1018 09:56:44.360729       1 scheduler.go:451] ScheduleAlgoTime 1.973732ms Start:2018-10-18 09:56:44.358744816 +0000 UTC m=+21.382228744 End:2018-10-18 09:56:44.360718638 +0000 UTC m=+21.384202476
I1018 09:56:44.360785       1 scheduler.go:454] Total Schedule Algo cumulative time:697.233414ms for 297
I1018 09:56:44.362996       1 scheduler.go:451] ScheduleAlgoTime 2.013363ms Start:2018-10-18 09:56:44.360974643 +0000 UTC m=+21.384458562 End:2018-10-18 09:56:44.362988118 +0000 UTC m=+21.386471925
I1018 09:56:44.363023       1 scheduler.go:454] Total Schedule Algo cumulative time:699.246777ms for 298
I1018 09:56:44.369434       1 scheduler.go:451] ScheduleAlgoTime 2.600359ms Start:2018-10-18 09:56:44.366824546 +0000 UTC m=+21.390308483 End:2018-10-18 09:56:44.369425039 +0000 UTC m=+21.392908842
I1018 09:56:44.369472       1 scheduler.go:454] Total Schedule Algo cumulative time:701.847136ms for 299
I1018 09:56:44.371776       1 scheduler.go:451] ScheduleAlgoTime 2.131271ms Start:2018-10-18 09:56:44.369632717 +0000 UTC m=+21.393116647 End:2018-10-18 09:56:44.371763967 +0000 UTC m=+21.395247918
I1018 09:56:44.371821       1 scheduler.go:454] Total Schedule Algo cumulative time:703.978407ms for 300
I1018 09:56:44.374379       1 scheduler.go:451] ScheduleAlgoTime 2.232858ms Start:2018-10-18 09:56:44.372137941 +0000 UTC m=+21.395621834 End:2018-10-18 09:56:44.374370883 +0000 UTC m=+21.397854692
I1018 09:56:44.374416       1 scheduler.go:454] Total Schedule Algo cumulative time:706.211265ms for 301
I1018 09:56:44.376453       1 scheduler.go:451] ScheduleAlgoTime 1.90797ms Start:2018-10-18 09:56:44.374537927 +0000 UTC m=+21.398021827 End:2018-10-18 09:56:44.376445994 +0000 UTC m=+21.399929797
I1018 09:56:44.376481       1 scheduler.go:454] Total Schedule Algo cumulative time:708.119235ms for 302
I1018 09:56:44.378756       1 scheduler.go:451] ScheduleAlgoTime 2.098042ms Start:2018-10-18 09:56:44.376648433 +0000 UTC m=+21.400132331 End:2018-10-18 09:56:44.378746568 +0000 UTC m=+21.402230373
I1018 09:56:44.378785       1 scheduler.go:454] Total Schedule Algo cumulative time:710.217277ms for 303
I1018 09:56:44.380854       1 scheduler.go:451] ScheduleAlgoTime 1.922641ms Start:2018-10-18 09:56:44.378920459 +0000 UTC m=+21.402404375 End:2018-10-18 09:56:44.380843102 +0000 UTC m=+21.404327016
I1018 09:56:44.380908       1 scheduler.go:454] Total Schedule Algo cumulative time:712.139918ms for 304
I1018 09:56:44.382939       1 scheduler.go:451] ScheduleAlgoTime 1.848015ms Start:2018-10-18 09:56:44.381082466 +0000 UTC m=+21.404566375 End:2018-10-18 09:56:44.382930584 +0000 UTC m=+21.406414390
I1018 09:56:44.382968       1 scheduler.go:454] Total Schedule Algo cumulative time:713.987933ms for 305
I1018 09:56:44.384857       1 scheduler.go:451] ScheduleAlgoTime 1.759881ms Start:2018-10-18 09:56:44.383090787 +0000 UTC m=+21.406574689 End:2018-10-18 09:56:44.384850768 +0000 UTC m=+21.408334570
I1018 09:56:44.384882       1 scheduler.go:454] Total Schedule Algo cumulative time:715.747814ms for 306
I1018 09:56:44.387030       1 scheduler.go:451] ScheduleAlgoTime 1.961694ms Start:2018-10-18 09:56:44.385062372 +0000 UTC m=+21.408546293 End:2018-10-18 09:56:44.38702418 +0000 UTC m=+21.410507987
I1018 09:56:44.387066       1 scheduler.go:454] Total Schedule Algo cumulative time:717.709508ms for 307
I1018 09:56:44.388927       1 scheduler.go:451] ScheduleAlgoTime 1.734568ms Start:2018-10-18 09:56:44.387183601 +0000 UTC m=+21.410667408 End:2018-10-18 09:56:44.38891806 +0000 UTC m=+21.412401976
I1018 09:56:44.388976       1 scheduler.go:454] Total Schedule Algo cumulative time:719.444076ms for 308
I1018 09:56:44.390927       1 scheduler.go:451] ScheduleAlgoTime 1.77531ms Start:2018-10-18 09:56:44.389145141 +0000 UTC m=+21.412629022 End:2018-10-18 09:56:44.390920529 +0000 UTC m=+21.414404332
I1018 09:56:44.390956       1 scheduler.go:454] Total Schedule Algo cumulative time:721.219386ms for 309
I1018 09:56:44.393240       1 scheduler.go:451] ScheduleAlgoTime 2.118134ms Start:2018-10-18 09:56:44.391114361 +0000 UTC m=+21.414598261 End:2018-10-18 09:56:44.393232594 +0000 UTC m=+21.416716395
I1018 09:56:44.393272       1 scheduler.go:454] Total Schedule Algo cumulative time:723.33752ms for 310
I1018 09:56:44.395363       1 scheduler.go:451] ScheduleAlgoTime 1.931779ms Start:2018-10-18 09:56:44.393422508 +0000 UTC m=+21.416906310 End:2018-10-18 09:56:44.395354286 +0000 UTC m=+21.418838089
I1018 09:56:44.395423       1 scheduler.go:454] Total Schedule Algo cumulative time:725.269299ms for 311
I1018 09:56:44.397545       1 scheduler.go:451] ScheduleAlgoTime 1.923048ms Start:2018-10-18 09:56:44.395613486 +0000 UTC m=+21.419097409 End:2018-10-18 09:56:44.397536653 +0000 UTC m=+21.421020457
I1018 09:56:44.397605       1 scheduler.go:454] Total Schedule Algo cumulative time:727.192347ms for 312
I1018 09:56:44.399591       1 scheduler.go:451] ScheduleAlgoTime 1.764859ms Start:2018-10-18 09:56:44.397819625 +0000 UTC m=+21.421303516 End:2018-10-18 09:56:44.399584572 +0000 UTC m=+21.423068375
I1018 09:56:44.399617       1 scheduler.go:454] Total Schedule Algo cumulative time:728.957206ms for 313
I1018 09:56:44.401564       1 scheduler.go:451] ScheduleAlgoTime 1.598472ms Start:2018-10-18 09:56:44.399959368 +0000 UTC m=+21.423443240 End:2018-10-18 09:56:44.401557909 +0000 UTC m=+21.425041712
I1018 09:56:44.401602       1 scheduler.go:454] Total Schedule Algo cumulative time:730.555678ms for 314
I1018 09:56:44.403597       1 scheduler.go:451] ScheduleAlgoTime 1.774725ms Start:2018-10-18 09:56:44.401812914 +0000 UTC m=+21.425296805 End:2018-10-18 09:56:44.403587615 +0000 UTC m=+21.427071530
I1018 09:56:44.403650       1 scheduler.go:454] Total Schedule Algo cumulative time:732.330403ms for 315
I1018 09:56:44.405753       1 scheduler.go:451] ScheduleAlgoTime 1.860226ms Start:2018-10-18 09:56:44.40388577 +0000 UTC m=+21.427369676 End:2018-10-18 09:56:44.405746099 +0000 UTC m=+21.429229902
I1018 09:56:44.405783       1 scheduler.go:454] Total Schedule Algo cumulative time:734.190629ms for 316
I1018 09:56:44.407913       1 scheduler.go:451] ScheduleAlgoTime 1.926824ms Start:2018-10-18 09:56:44.405967674 +0000 UTC m=+21.429451556 End:2018-10-18 09:56:44.407894572 +0000 UTC m=+21.431378380
I1018 09:56:44.407962       1 scheduler.go:454] Total Schedule Algo cumulative time:736.117453ms for 317
I1018 09:56:44.410455       1 scheduler.go:451] ScheduleAlgoTime 2.274719ms Start:2018-10-18 09:56:44.408169684 +0000 UTC m=+21.431653567 End:2018-10-18 09:56:44.41044445 +0000 UTC m=+21.433928286
I1018 09:56:44.410491       1 scheduler.go:454] Total Schedule Algo cumulative time:738.392172ms for 318
I1018 09:56:44.413058       1 scheduler.go:451] ScheduleAlgoTime 2.415676ms Start:2018-10-18 09:56:44.410634208 +0000 UTC m=+21.434118059 End:2018-10-18 09:56:44.41304993 +0000 UTC m=+21.436533735
I1018 09:56:44.413086       1 scheduler.go:454] Total Schedule Algo cumulative time:740.807848ms for 319
I1018 09:56:44.415557       1 scheduler.go:451] ScheduleAlgoTime 2.269206ms Start:2018-10-18 09:56:44.413278487 +0000 UTC m=+21.436762390 End:2018-10-18 09:56:44.415547792 +0000 UTC m=+21.439031596
I1018 09:56:44.415588       1 scheduler.go:454] Total Schedule Algo cumulative time:743.077054ms for 320
I1018 09:56:44.418165       1 scheduler.go:451] ScheduleAlgoTime 2.441428ms Start:2018-10-18 09:56:44.415716924 +0000 UTC m=+21.439200848 End:2018-10-18 09:56:44.418158473 +0000 UTC m=+21.441642276
I1018 09:56:44.418199       1 scheduler.go:454] Total Schedule Algo cumulative time:745.518482ms for 321
I1018 09:56:44.422732       1 scheduler.go:451] ScheduleAlgoTime 4.400825ms Start:2018-10-18 09:56:44.418315138 +0000 UTC m=+21.441799009 End:2018-10-18 09:56:44.422716029 +0000 UTC m=+21.446199834
I1018 09:56:44.422804       1 scheduler.go:454] Total Schedule Algo cumulative time:749.919307ms for 322
I1018 09:56:44.427003       1 scheduler.go:451] ScheduleAlgoTime 3.255773ms Start:2018-10-18 09:56:44.423734595 +0000 UTC m=+21.447218468 End:2018-10-18 09:56:44.426990437 +0000 UTC m=+21.450474241
I1018 09:56:44.427047       1 scheduler.go:454] Total Schedule Algo cumulative time:753.17508ms for 323
I1018 09:56:44.429281       1 scheduler.go:451] ScheduleAlgoTime 1.995699ms Start:2018-10-18 09:56:44.427277659 +0000 UTC m=+21.450761536 End:2018-10-18 09:56:44.429273434 +0000 UTC m=+21.452757235
I1018 09:56:44.429316       1 scheduler.go:454] Total Schedule Algo cumulative time:755.170779ms for 324
I1018 09:56:44.431428       1 scheduler.go:451] ScheduleAlgoTime 1.942332ms Start:2018-10-18 09:56:44.42947894 +0000 UTC m=+21.452962790 End:2018-10-18 09:56:44.43142132 +0000 UTC m=+21.454905122
I1018 09:56:44.431466       1 scheduler.go:454] Total Schedule Algo cumulative time:757.113111ms for 325
I1018 09:56:44.434179       1 scheduler.go:451] ScheduleAlgoTime 2.522692ms Start:2018-10-18 09:56:44.431651061 +0000 UTC m=+21.455134951 End:2018-10-18 09:56:44.43417384 +0000 UTC m=+21.457657643
I1018 09:56:44.434205       1 scheduler.go:454] Total Schedule Algo cumulative time:759.635803ms for 326
I1018 09:56:44.436322       1 scheduler.go:451] ScheduleAlgoTime 1.985271ms Start:2018-10-18 09:56:44.434330432 +0000 UTC m=+21.457814327 End:2018-10-18 09:56:44.436315795 +0000 UTC m=+21.459799598
I1018 09:56:44.436346       1 scheduler.go:454] Total Schedule Algo cumulative time:761.621074ms for 327
I1018 09:56:44.438226       1 scheduler.go:451] ScheduleAlgoTime 1.756934ms Start:2018-10-18 09:56:44.43645925 +0000 UTC m=+21.459943155 End:2018-10-18 09:56:44.438216279 +0000 UTC m=+21.461700089
I1018 09:56:44.438251       1 scheduler.go:454] Total Schedule Algo cumulative time:763.378008ms for 328
I1018 09:56:44.440252       1 scheduler.go:451] ScheduleAlgoTime 1.786677ms Start:2018-10-18 09:56:44.438457293 +0000 UTC m=+21.461941183 End:2018-10-18 09:56:44.440244052 +0000 UTC m=+21.463727860
I1018 09:56:44.440291       1 scheduler.go:454] Total Schedule Algo cumulative time:765.164685ms for 329
I1018 09:56:44.442366       1 scheduler.go:451] ScheduleAlgoTime 1.962935ms Start:2018-10-18 09:56:44.440393917 +0000 UTC m=+21.463877754 End:2018-10-18 09:56:44.442356795 +0000 UTC m=+21.465840689
I1018 09:56:44.442399       1 scheduler.go:454] Total Schedule Algo cumulative time:767.12762ms for 330
I1018 09:56:44.444502       1 scheduler.go:451] ScheduleAlgoTime 1.846514ms Start:2018-10-18 09:56:44.442647355 +0000 UTC m=+21.466131192 End:2018-10-18 09:56:44.444493898 +0000 UTC m=+21.467977706
I1018 09:56:44.444530       1 scheduler.go:454] Total Schedule Algo cumulative time:768.974134ms for 331
I1018 09:56:44.446631       1 scheduler.go:451] ScheduleAlgoTime 1.927244ms Start:2018-10-18 09:56:44.444695247 +0000 UTC m=+21.468179109 End:2018-10-18 09:56:44.446622545 +0000 UTC m=+21.470106353
I1018 09:56:44.446687       1 scheduler.go:454] Total Schedule Algo cumulative time:770.901378ms for 332
I1018 09:56:44.449792       1 scheduler.go:451] ScheduleAlgoTime 2.887627ms Start:2018-10-18 09:56:44.446894997 +0000 UTC m=+21.470378846 End:2018-10-18 09:56:44.449782671 +0000 UTC m=+21.473266473
I1018 09:56:44.449838       1 scheduler.go:454] Total Schedule Algo cumulative time:773.789005ms for 333
I1018 09:56:44.452384       1 scheduler.go:451] ScheduleAlgoTime 2.191429ms Start:2018-10-18 09:56:44.45018319 +0000 UTC m=+21.473667091 End:2018-10-18 09:56:44.452374624 +0000 UTC m=+21.475858520
I1018 09:56:44.452452       1 scheduler.go:454] Total Schedule Algo cumulative time:775.980434ms for 334
I1018 09:56:44.454867       1 scheduler.go:451] ScheduleAlgoTime 2.268202ms Start:2018-10-18 09:56:44.452590778 +0000 UTC m=+21.476074680 End:2018-10-18 09:56:44.454859078 +0000 UTC m=+21.478342882
I1018 09:56:44.454899       1 scheduler.go:454] Total Schedule Algo cumulative time:778.248636ms for 335
I1018 09:56:44.456948       1 scheduler.go:451] ScheduleAlgoTime 1.894928ms Start:2018-10-18 09:56:44.455044743 +0000 UTC m=+21.478528657 End:2018-10-18 09:56:44.456939779 +0000 UTC m=+21.480423585
I1018 09:56:44.456977       1 scheduler.go:454] Total Schedule Algo cumulative time:780.143564ms for 336
I1018 09:56:44.458896       1 scheduler.go:451] ScheduleAlgoTime 1.779533ms Start:2018-10-18 09:56:44.457107266 +0000 UTC m=+21.480591166 End:2018-10-18 09:56:44.458886892 +0000 UTC m=+21.482370699
I1018 09:56:44.458935       1 scheduler.go:454] Total Schedule Algo cumulative time:781.923097ms for 337
I1018 09:56:44.462067       1 scheduler.go:451] ScheduleAlgoTime 2.850507ms Start:2018-10-18 09:56:44.459210002 +0000 UTC m=+21.482693897 End:2018-10-18 09:56:44.462060599 +0000 UTC m=+21.485544404
I1018 09:56:44.462104       1 scheduler.go:454] Total Schedule Algo cumulative time:784.773604ms for 338
I1018 09:56:44.464431       1 scheduler.go:451] ScheduleAlgoTime 2.027481ms Start:2018-10-18 09:56:44.462396406 +0000 UTC m=+21.485880296 End:2018-10-18 09:56:44.464423975 +0000 UTC m=+21.487907777
I1018 09:56:44.464470       1 scheduler.go:454] Total Schedule Algo cumulative time:786.801085ms for 339
I1018 09:56:44.466608       1 scheduler.go:451] ScheduleAlgoTime 1.899504ms Start:2018-10-18 09:56:44.46470022 +0000 UTC m=+21.488184120 End:2018-10-18 09:56:44.466599813 +0000 UTC m=+21.490083624
I1018 09:56:44.466651       1 scheduler.go:454] Total Schedule Algo cumulative time:788.700589ms for 340
I1018 09:56:44.468709       1 scheduler.go:451] ScheduleAlgoTime 1.873442ms Start:2018-10-18 09:56:44.466827293 +0000 UTC m=+21.490311122 End:2018-10-18 09:56:44.468700756 +0000 UTC m=+21.492184564
I1018 09:56:44.468736       1 scheduler.go:454] Total Schedule Algo cumulative time:790.574031ms for 341
I1018 09:56:44.471106       1 scheduler.go:451] ScheduleAlgoTime 2.086118ms Start:2018-10-18 09:56:44.469009836 +0000 UTC m=+21.492493731 End:2018-10-18 09:56:44.471096024 +0000 UTC m=+21.494579849
I1018 09:56:44.471142       1 scheduler.go:454] Total Schedule Algo cumulative time:792.660149ms for 342
I1018 09:56:44.473356       1 scheduler.go:451] ScheduleAlgoTime 2.045586ms Start:2018-10-18 09:56:44.47130237 +0000 UTC m=+21.494786244 End:2018-10-18 09:56:44.473348028 +0000 UTC m=+21.496831830
I1018 09:56:44.473392       1 scheduler.go:454] Total Schedule Algo cumulative time:794.705735ms for 343
I1018 09:56:44.475445       1 scheduler.go:451] ScheduleAlgoTime 1.925722ms Start:2018-10-18 09:56:44.473510887 +0000 UTC m=+21.496994793 End:2018-10-18 09:56:44.475436711 +0000 UTC m=+21.498920515
I1018 09:56:44.475474       1 scheduler.go:454] Total Schedule Algo cumulative time:796.631457ms for 344
I1018 09:56:44.478168       1 scheduler.go:451] ScheduleAlgoTime 2.5253ms Start:2018-10-18 09:56:44.475632265 +0000 UTC m=+21.499116158 End:2018-10-18 09:56:44.478157606 +0000 UTC m=+21.501641458
I1018 09:56:44.478205       1 scheduler.go:454] Total Schedule Algo cumulative time:799.156757ms for 345
I1018 09:56:44.480087       1 scheduler.go:451] ScheduleAlgoTime 1.799614ms Start:2018-10-18 09:56:44.478279758 +0000 UTC m=+21.501763642 End:2018-10-18 09:56:44.480079449 +0000 UTC m=+21.503563256
I1018 09:56:44.480115       1 scheduler.go:454] Total Schedule Algo cumulative time:800.956371ms for 346
I1018 09:56:44.482103       1 scheduler.go:451] ScheduleAlgoTime 1.838756ms Start:2018-10-18 09:56:44.480257744 +0000 UTC m=+21.503741650 End:2018-10-18 09:56:44.482096598 +0000 UTC m=+21.505580406
I1018 09:56:44.482130       1 scheduler.go:454] Total Schedule Algo cumulative time:802.795127ms for 347
I1018 09:56:44.484170       1 scheduler.go:451] ScheduleAlgoTime 1.888766ms Start:2018-10-18 09:56:44.482270154 +0000 UTC m=+21.505754048 End:2018-10-18 09:56:44.484158887 +0000 UTC m=+21.507642814
I1018 09:56:44.484216       1 scheduler.go:454] Total Schedule Algo cumulative time:804.683893ms for 348
I1018 09:56:44.486106       1 scheduler.go:451] ScheduleAlgoTime 1.684142ms Start:2018-10-18 09:56:44.484413931 +0000 UTC m=+21.507897822 End:2018-10-18 09:56:44.486098159 +0000 UTC m=+21.509581964
I1018 09:56:44.486134       1 scheduler.go:454] Total Schedule Algo cumulative time:806.368035ms for 349
I1018 09:56:44.488054       1 scheduler.go:451] ScheduleAlgoTime 1.717684ms Start:2018-10-18 09:56:44.486328128 +0000 UTC m=+21.509811932 End:2018-10-18 09:56:44.488045811 +0000 UTC m=+21.511529616
I1018 09:56:44.488083       1 scheduler.go:454] Total Schedule Algo cumulative time:808.085719ms for 350
I1018 09:56:44.490144       1 scheduler.go:451] ScheduleAlgoTime 1.874704ms Start:2018-10-18 09:56:44.488261747 +0000 UTC m=+21.511745616 End:2018-10-18 09:56:44.490136513 +0000 UTC m=+21.513620320
I1018 09:56:44.490172       1 scheduler.go:454] Total Schedule Algo cumulative time:809.960423ms for 351
I1018 09:56:44.492179       1 scheduler.go:451] ScheduleAlgoTime 1.809373ms Start:2018-10-18 09:56:44.49036319 +0000 UTC m=+21.513847082 End:2018-10-18 09:56:44.492172646 +0000 UTC m=+21.515656455
I1018 09:56:44.492209       1 scheduler.go:454] Total Schedule Algo cumulative time:811.769796ms for 352
I1018 09:56:44.494326       1 scheduler.go:451] ScheduleAlgoTime 1.856953ms Start:2018-10-18 09:56:44.49246142 +0000 UTC m=+21.515945307 End:2018-10-18 09:56:44.494318453 +0000 UTC m=+21.517802260
I1018 09:56:44.494355       1 scheduler.go:454] Total Schedule Algo cumulative time:813.626749ms for 353
I1018 09:56:44.496335       1 scheduler.go:451] ScheduleAlgoTime 1.809452ms Start:2018-10-18 09:56:44.494516818 +0000 UTC m=+21.518000704 End:2018-10-18 09:56:44.496326346 +0000 UTC m=+21.519810156
I1018 09:56:44.496368       1 scheduler.go:454] Total Schedule Algo cumulative time:815.436201ms for 354
I1018 09:56:44.498735       1 scheduler.go:451] ScheduleAlgoTime 2.139728ms Start:2018-10-18 09:56:44.496587391 +0000 UTC m=+21.520071293 End:2018-10-18 09:56:44.49872718 +0000 UTC m=+21.522211021
I1018 09:56:44.498767       1 scheduler.go:454] Total Schedule Algo cumulative time:817.575929ms for 355
I1018 09:56:44.500730       1 scheduler.go:451] ScheduleAlgoTime 1.755756ms Start:2018-10-18 09:56:44.498967778 +0000 UTC m=+21.522451660 End:2018-10-18 09:56:44.500723611 +0000 UTC m=+21.524207416
I1018 09:56:44.500760       1 scheduler.go:454] Total Schedule Algo cumulative time:819.331685ms for 356
I1018 09:56:44.502613       1 scheduler.go:451] ScheduleAlgoTime 1.57987ms Start:2018-10-18 09:56:44.501027104 +0000 UTC m=+21.524511014 End:2018-10-18 09:56:44.502607081 +0000 UTC m=+21.526090884
I1018 09:56:44.502641       1 scheduler.go:454] Total Schedule Algo cumulative time:820.911555ms for 357
I1018 09:56:44.504709       1 scheduler.go:451] ScheduleAlgoTime 1.904579ms Start:2018-10-18 09:56:44.502797728 +0000 UTC m=+21.526281545 End:2018-10-18 09:56:44.504702317 +0000 UTC m=+21.528186124
I1018 09:56:44.504750       1 scheduler.go:454] Total Schedule Algo cumulative time:822.816134ms for 358
I1018 09:56:44.506951       1 scheduler.go:451] ScheduleAlgoTime 2.035886ms Start:2018-10-18 09:56:44.504908709 +0000 UTC m=+21.528392613 End:2018-10-18 09:56:44.506944689 +0000 UTC m=+21.530428499
I1018 09:56:44.506980       1 scheduler.go:454] Total Schedule Algo cumulative time:824.85202ms for 359
I1018 09:56:44.509863       1 scheduler.go:451] ScheduleAlgoTime 2.724478ms Start:2018-10-18 09:56:44.507126268 +0000 UTC m=+21.530610076 End:2018-10-18 09:56:44.509850741 +0000 UTC m=+21.533334554
I1018 09:56:44.509905       1 scheduler.go:454] Total Schedule Algo cumulative time:827.576498ms for 360
I1018 09:56:44.511798       1 scheduler.go:451] ScheduleAlgoTime 1.628818ms Start:2018-10-18 09:56:44.510161973 +0000 UTC m=+21.533645862 End:2018-10-18 09:56:44.511790876 +0000 UTC m=+21.535274680
I1018 09:56:44.511825       1 scheduler.go:454] Total Schedule Algo cumulative time:829.205316ms for 361
I1018 09:56:44.514035       1 scheduler.go:451] ScheduleAlgoTime 1.959288ms Start:2018-10-18 09:56:44.512070164 +0000 UTC m=+21.535554039 End:2018-10-18 09:56:44.514029523 +0000 UTC m=+21.537513327
I1018 09:56:44.514060       1 scheduler.go:454] Total Schedule Algo cumulative time:831.164604ms for 362
I1018 09:56:44.516013       1 scheduler.go:451] ScheduleAlgoTime 1.768656ms Start:2018-10-18 09:56:44.51423825 +0000 UTC m=+21.537722164 End:2018-10-18 09:56:44.516007013 +0000 UTC m=+21.539490820
I1018 09:56:44.516042       1 scheduler.go:454] Total Schedule Algo cumulative time:832.93326ms for 363
I1018 09:56:44.517891       1 scheduler.go:451] ScheduleAlgoTime 1.621232ms Start:2018-10-18 09:56:44.516264332 +0000 UTC m=+21.539748230 End:2018-10-18 09:56:44.517885654 +0000 UTC m=+21.541369462
I1018 09:56:44.517914       1 scheduler.go:454] Total Schedule Algo cumulative time:834.554492ms for 364
I1018 09:56:44.525245       1 scheduler.go:451] ScheduleAlgoTime 6.973308ms Start:2018-10-18 09:56:44.518254551 +0000 UTC m=+21.541738443 End:2018-10-18 09:56:44.525227908 +0000 UTC m=+21.548711751
I1018 09:56:44.525304       1 scheduler.go:454] Total Schedule Algo cumulative time:841.5278ms for 365
I1018 09:56:44.527826       1 scheduler.go:451] ScheduleAlgoTime 2.313184ms Start:2018-10-18 09:56:44.525501536 +0000 UTC m=+21.548985430 End:2018-10-18 09:56:44.527814807 +0000 UTC m=+21.551298614
I1018 09:56:44.527880       1 scheduler.go:454] Total Schedule Algo cumulative time:843.840984ms for 366
I1018 09:56:44.530032       1 scheduler.go:451] ScheduleAlgoTime 1.931413ms Start:2018-10-18 09:56:44.528092709 +0000 UTC m=+21.551576596 End:2018-10-18 09:56:44.5300241 +0000 UTC m=+21.553508009
I1018 09:56:44.530122       1 scheduler.go:454] Total Schedule Algo cumulative time:845.772397ms for 367
I1018 09:56:44.532319       1 scheduler.go:451] ScheduleAlgoTime 2.016492ms Start:2018-10-18 09:56:44.530295277 +0000 UTC m=+21.553779173 End:2018-10-18 09:56:44.532311857 +0000 UTC m=+21.555795665
I1018 09:56:44.532356       1 scheduler.go:454] Total Schedule Algo cumulative time:847.788889ms for 368
I1018 09:56:44.534722       1 scheduler.go:451] ScheduleAlgoTime 2.177189ms Start:2018-10-18 09:56:44.532537127 +0000 UTC m=+21.556020982 End:2018-10-18 09:56:44.534714367 +0000 UTC m=+21.558198171
I1018 09:56:44.534760       1 scheduler.go:454] Total Schedule Algo cumulative time:849.966078ms for 369
I1018 09:56:44.537068       1 scheduler.go:451] ScheduleAlgoTime 2.025446ms Start:2018-10-18 09:56:44.535034419 +0000 UTC m=+21.558518322 End:2018-10-18 09:56:44.537059966 +0000 UTC m=+21.560543768
I1018 09:56:44.537109       1 scheduler.go:454] Total Schedule Algo cumulative time:851.991524ms for 370
I1018 09:56:44.539515       1 scheduler.go:451] ScheduleAlgoTime 2.225503ms Start:2018-10-18 09:56:44.537280845 +0000 UTC m=+21.560764764 End:2018-10-18 09:56:44.539506465 +0000 UTC m=+21.562990267
I1018 09:56:44.539546       1 scheduler.go:454] Total Schedule Algo cumulative time:854.217027ms for 371
I1018 09:56:44.542165       1 scheduler.go:451] ScheduleAlgoTime 2.322485ms Start:2018-10-18 09:56:44.539833835 +0000 UTC m=+21.563317703 End:2018-10-18 09:56:44.542156383 +0000 UTC m=+21.565640188
I1018 09:56:44.542199       1 scheduler.go:454] Total Schedule Algo cumulative time:856.539512ms for 372
I1018 09:56:44.544977       1 scheduler.go:451] ScheduleAlgoTime 2.558535ms Start:2018-10-18 09:56:44.54240831 +0000 UTC m=+21.565892162 End:2018-10-18 09:56:44.544966861 +0000 UTC m=+21.568450697
I1018 09:56:44.545023       1 scheduler.go:454] Total Schedule Algo cumulative time:859.098047ms for 373
I1018 09:56:44.547449       1 scheduler.go:451] ScheduleAlgoTime 2.148446ms Start:2018-10-18 09:56:44.545292661 +0000 UTC m=+21.568776548 End:2018-10-18 09:56:44.547441189 +0000 UTC m=+21.570924994
I1018 09:56:44.547481       1 scheduler.go:454] Total Schedule Algo cumulative time:861.246493ms for 374
I1018 09:56:44.549823       1 scheduler.go:451] ScheduleAlgoTime 1.946993ms Start:2018-10-18 09:56:44.547865377 +0000 UTC m=+21.571349251 End:2018-10-18 09:56:44.549812436 +0000 UTC m=+21.573296244
I1018 09:56:44.549866       1 scheduler.go:454] Total Schedule Algo cumulative time:863.193486ms for 375
I1018 09:56:44.552017       1 scheduler.go:451] ScheduleAlgoTime 1.926347ms Start:2018-10-18 09:56:44.550082152 +0000 UTC m=+21.573566037 End:2018-10-18 09:56:44.552008579 +0000 UTC m=+21.575492384
I1018 09:56:44.552096       1 scheduler.go:454] Total Schedule Algo cumulative time:865.119833ms for 376
I1018 09:56:44.554530       1 scheduler.go:451] ScheduleAlgoTime 2.220898ms Start:2018-10-18 09:56:44.552298375 +0000 UTC m=+21.575782263 End:2018-10-18 09:56:44.554519143 +0000 UTC m=+21.578003161
I1018 09:56:44.554584       1 scheduler.go:454] Total Schedule Algo cumulative time:867.340731ms for 377
I1018 09:56:44.556533       1 scheduler.go:451] ScheduleAlgoTime 1.770939ms Start:2018-10-18 09:56:44.554755736 +0000 UTC m=+21.578239670 End:2018-10-18 09:56:44.556526804 +0000 UTC m=+21.580010609
I1018 09:56:44.556559       1 scheduler.go:454] Total Schedule Algo cumulative time:869.11167ms for 378
I1018 09:56:44.558709       1 scheduler.go:451] ScheduleAlgoTime 1.955013ms Start:2018-10-18 09:56:44.556745587 +0000 UTC m=+21.580229461 End:2018-10-18 09:56:44.558700669 +0000 UTC m=+21.582184474
I1018 09:56:44.558743       1 scheduler.go:454] Total Schedule Algo cumulative time:871.066683ms for 379
I1018 09:56:44.560798       1 scheduler.go:451] ScheduleAlgoTime 1.86807ms Start:2018-10-18 09:56:44.558920996 +0000 UTC m=+21.582404866 End:2018-10-18 09:56:44.560789133 +0000 UTC m=+21.584272936
I1018 09:56:44.561065       1 scheduler.go:454] Total Schedule Algo cumulative time:872.934753ms for 380
I1018 09:56:44.563314       1 scheduler.go:451] ScheduleAlgoTime 1.937853ms Start:2018-10-18 09:56:44.561366739 +0000 UTC m=+21.584850654 End:2018-10-18 09:56:44.563304702 +0000 UTC m=+21.586788507
I1018 09:56:44.563347       1 scheduler.go:454] Total Schedule Algo cumulative time:874.872606ms for 381
I1018 09:56:44.565876       1 scheduler.go:451] ScheduleAlgoTime 2.264834ms Start:2018-10-18 09:56:44.563602022 +0000 UTC m=+21.587085860 End:2018-10-18 09:56:44.565866889 +0000 UTC m=+21.589350694
I1018 09:56:44.565907       1 scheduler.go:454] Total Schedule Algo cumulative time:877.13744ms for 382
I1018 09:56:44.568433       1 scheduler.go:451] ScheduleAlgoTime 2.372699ms Start:2018-10-18 09:56:44.566052957 +0000 UTC m=+21.589536762 End:2018-10-18 09:56:44.568425656 +0000 UTC m=+21.591909461
I1018 09:56:44.568463       1 scheduler.go:454] Total Schedule Algo cumulative time:879.510139ms for 383
I1018 09:56:44.570871       1 scheduler.go:451] ScheduleAlgoTime 2.2538ms Start:2018-10-18 09:56:44.568606814 +0000 UTC m=+21.592090683 End:2018-10-18 09:56:44.570860519 +0000 UTC m=+21.594344483
I1018 09:56:44.570909       1 scheduler.go:454] Total Schedule Algo cumulative time:881.763939ms for 384
I1018 09:56:44.573413       1 scheduler.go:451] ScheduleAlgoTime 2.219095ms Start:2018-10-18 09:56:44.571183451 +0000 UTC m=+21.594667308 End:2018-10-18 09:56:44.573402494 +0000 UTC m=+21.596886403
I1018 09:56:44.573456       1 scheduler.go:454] Total Schedule Algo cumulative time:883.983034ms for 385
I1018 09:56:44.575640       1 scheduler.go:451] ScheduleAlgoTime 1.947444ms Start:2018-10-18 09:56:44.573684277 +0000 UTC m=+21.597168121 End:2018-10-18 09:56:44.575631762 +0000 UTC m=+21.599115565
I1018 09:56:44.575686       1 scheduler.go:454] Total Schedule Algo cumulative time:885.930478ms for 386
I1018 09:56:44.578043       1 scheduler.go:451] ScheduleAlgoTime 2.178939ms Start:2018-10-18 09:56:44.575856774 +0000 UTC m=+21.599340594 End:2018-10-18 09:56:44.578035726 +0000 UTC m=+21.601519533
I1018 09:56:44.578074       1 scheduler.go:454] Total Schedule Algo cumulative time:888.109417ms for 387
I1018 09:56:44.580145       1 scheduler.go:451] ScheduleAlgoTime 1.92263ms Start:2018-10-18 09:56:44.578214657 +0000 UTC m=+21.601698576 End:2018-10-18 09:56:44.580137403 +0000 UTC m=+21.603621206
I1018 09:56:44.580175       1 scheduler.go:454] Total Schedule Algo cumulative time:890.032047ms for 388
I1018 09:56:44.582789       1 scheduler.go:451] ScheduleAlgoTime 2.39348ms Start:2018-10-18 09:56:44.580386693 +0000 UTC m=+21.603870575 End:2018-10-18 09:56:44.582780251 +0000 UTC m=+21.606264055
I1018 09:56:44.582824       1 scheduler.go:454] Total Schedule Algo cumulative time:892.425527ms for 389
I1018 09:56:44.584831       1 scheduler.go:451] ScheduleAlgoTime 1.825888ms Start:2018-10-18 09:56:44.582996871 +0000 UTC m=+21.606480798 End:2018-10-18 09:56:44.584822883 +0000 UTC m=+21.608306686
I1018 09:56:44.584861       1 scheduler.go:454] Total Schedule Algo cumulative time:894.251415ms for 390
I1018 09:56:44.587036       1 scheduler.go:451] ScheduleAlgoTime 1.95004ms Start:2018-10-18 09:56:44.585077185 +0000 UTC m=+21.608561077 End:2018-10-18 09:56:44.587027311 +0000 UTC m=+21.610511117
I1018 09:56:44.587064       1 scheduler.go:454] Total Schedule Algo cumulative time:896.201455ms for 391
I1018 09:56:44.589085       1 scheduler.go:451] ScheduleAlgoTime 1.891682ms Start:2018-10-18 09:56:44.587185964 +0000 UTC m=+21.610669876 End:2018-10-18 09:56:44.589077755 +0000 UTC m=+21.612561558
I1018 09:56:44.589113       1 scheduler.go:454] Total Schedule Algo cumulative time:898.093137ms for 392
I1018 09:56:44.591367       1 scheduler.go:451] ScheduleAlgoTime 2.128019ms Start:2018-10-18 09:56:44.589232147 +0000 UTC m=+21.612716019 End:2018-10-18 09:56:44.591360234 +0000 UTC m=+21.614844038
I1018 09:56:44.591417       1 scheduler.go:454] Total Schedule Algo cumulative time:900.221156ms for 393
I1018 09:56:44.593521       1 scheduler.go:451] ScheduleAlgoTime 1.941101ms Start:2018-10-18 09:56:44.59157222 +0000 UTC m=+21.615056166 End:2018-10-18 09:56:44.593513462 +0000 UTC m=+21.616997267
I1018 09:56:44.593553       1 scheduler.go:454] Total Schedule Algo cumulative time:902.162257ms for 394
I1018 09:56:44.595789       1 scheduler.go:451] ScheduleAlgoTime 2.055238ms Start:2018-10-18 09:56:44.593727619 +0000 UTC m=+21.617211546 End:2018-10-18 09:56:44.595782981 +0000 UTC m=+21.619266784
I1018 09:56:44.595817       1 scheduler.go:454] Total Schedule Algo cumulative time:904.217495ms for 395
I1018 09:56:44.597733       1 scheduler.go:451] ScheduleAlgoTime 1.763758ms Start:2018-10-18 09:56:44.595962467 +0000 UTC m=+21.619446377 End:2018-10-18 09:56:44.597726333 +0000 UTC m=+21.621210135
I1018 09:56:44.597759       1 scheduler.go:454] Total Schedule Algo cumulative time:905.981253ms for 396
I1018 09:56:44.599984       1 scheduler.go:451] ScheduleAlgoTime 2.048026ms Start:2018-10-18 09:56:44.597926977 +0000 UTC m=+21.621410866 End:2018-10-18 09:56:44.599975089 +0000 UTC m=+21.623458892
I1018 09:56:44.600015       1 scheduler.go:454] Total Schedule Algo cumulative time:908.029279ms for 397
I1018 09:56:44.602237       1 scheduler.go:451] ScheduleAlgoTime 2.008287ms Start:2018-10-18 09:56:44.600209348 +0000 UTC m=+21.623693255 End:2018-10-18 09:56:44.602217712 +0000 UTC m=+21.625701542
I1018 09:56:44.602279       1 scheduler.go:454] Total Schedule Algo cumulative time:910.037566ms for 398
I1018 09:56:44.604602       1 scheduler.go:451] ScheduleAlgoTime 2.048487ms Start:2018-10-18 09:56:44.602542348 +0000 UTC m=+21.626026153 End:2018-10-18 09:56:44.604590824 +0000 UTC m=+21.628074640
I1018 09:56:44.604641       1 scheduler.go:454] Total Schedule Algo cumulative time:912.086053ms for 399
I1018 09:56:44.607371       1 scheduler.go:451] ScheduleAlgoTime 2.466861ms Start:2018-10-18 09:56:44.604897267 +0000 UTC m=+21.628381106 End:2018-10-18 09:56:44.607364163 +0000 UTC m=+21.630847967
I1018 09:56:44.607398       1 scheduler.go:454] Total Schedule Algo cumulative time:914.552914ms for 400
I1018 09:56:44.609660       1 scheduler.go:451] ScheduleAlgoTime 1.898476ms Start:2018-10-18 09:56:44.607751751 +0000 UTC m=+21.631235576 End:2018-10-18 09:56:44.609650247 +0000 UTC m=+21.633134052
I1018 09:56:44.609744       1 scheduler.go:454] Total Schedule Algo cumulative time:916.45139ms for 401
I1018 09:56:44.612244       1 scheduler.go:451] ScheduleAlgoTime 2.207522ms Start:2018-10-18 09:56:44.610024453 +0000 UTC m=+21.633508318 End:2018-10-18 09:56:44.612231957 +0000 UTC m=+21.635715840
I1018 09:56:44.612282       1 scheduler.go:454] Total Schedule Algo cumulative time:918.658912ms for 402
I1018 09:56:44.614550       1 scheduler.go:451] ScheduleAlgoTime 1.915301ms Start:2018-10-18 09:56:44.612625992 +0000 UTC m=+21.636109876 End:2018-10-18 09:56:44.61454137 +0000 UTC m=+21.638025177
I1018 09:56:44.614580       1 scheduler.go:454] Total Schedule Algo cumulative time:920.574213ms for 403
I1018 09:56:44.617169       1 scheduler.go:451] ScheduleAlgoTime 2.365173ms Start:2018-10-18 09:56:44.614794693 +0000 UTC m=+21.638278573 End:2018-10-18 09:56:44.617159938 +0000 UTC m=+21.640643746
I1018 09:56:44.617202       1 scheduler.go:454] Total Schedule Algo cumulative time:922.939386ms for 404
I1018 09:56:44.618920       1 scheduler.go:451] ScheduleAlgoTime 1.567498ms Start:2018-10-18 09:56:44.617346131 +0000 UTC m=+21.640830025 End:2018-10-18 09:56:44.618913715 +0000 UTC m=+21.642397523
I1018 09:56:44.618947       1 scheduler.go:454] Total Schedule Algo cumulative time:924.506884ms for 405
I1018 09:56:44.620934       1 scheduler.go:451] ScheduleAlgoTime 1.792596ms Start:2018-10-18 09:56:44.619132573 +0000 UTC m=+21.642616525 End:2018-10-18 09:56:44.620925314 +0000 UTC m=+21.644409121
I1018 09:56:44.620967       1 scheduler.go:454] Total Schedule Algo cumulative time:926.29948ms for 406
I1018 09:56:44.623499       1 scheduler.go:451] ScheduleAlgoTime 2.211909ms Start:2018-10-18 09:56:44.621278805 +0000 UTC m=+21.644762686 End:2018-10-18 09:56:44.623490794 +0000 UTC m=+21.646974595
I1018 09:56:44.623538       1 scheduler.go:454] Total Schedule Algo cumulative time:928.511389ms for 407
I1018 09:56:44.626031       1 scheduler.go:451] ScheduleAlgoTime 2.293217ms Start:2018-10-18 09:56:44.62372878 +0000 UTC m=+21.647212689 End:2018-10-18 09:56:44.626022104 +0000 UTC m=+21.649505906
I1018 09:56:44.626065       1 scheduler.go:454] Total Schedule Algo cumulative time:930.804606ms for 408
I1018 09:56:44.628470       1 scheduler.go:451] ScheduleAlgoTime 2.137348ms Start:2018-10-18 09:56:44.626324019 +0000 UTC m=+21.649807869 End:2018-10-18 09:56:44.62846141 +0000 UTC m=+21.651945217
I1018 09:56:44.628498       1 scheduler.go:454] Total Schedule Algo cumulative time:932.941954ms for 409
I1018 09:56:44.631417       1 scheduler.go:451] ScheduleAlgoTime 2.632634ms Start:2018-10-18 09:56:44.628771903 +0000 UTC m=+21.652255822 End:2018-10-18 09:56:44.631404653 +0000 UTC m=+21.654888456
I1018 09:56:44.631458       1 scheduler.go:454] Total Schedule Algo cumulative time:935.574588ms for 410
I1018 09:56:44.638736       1 scheduler.go:451] ScheduleAlgoTime 7.012756ms Start:2018-10-18 09:56:44.631712151 +0000 UTC m=+21.655196072 End:2018-10-18 09:56:44.638725019 +0000 UTC m=+21.662208828
I1018 09:56:44.638780       1 scheduler.go:454] Total Schedule Algo cumulative time:942.587344ms for 411
I1018 09:56:44.641365       1 scheduler.go:451] ScheduleAlgoTime 2.29984ms Start:2018-10-18 09:56:44.639056205 +0000 UTC m=+21.662540099 End:2018-10-18 09:56:44.641356137 +0000 UTC m=+21.664839939
I1018 09:56:44.641401       1 scheduler.go:454] Total Schedule Algo cumulative time:944.887184ms for 412
I1018 09:56:44.643877       1 scheduler.go:451] ScheduleAlgoTime 2.255828ms Start:2018-10-18 09:56:44.641610073 +0000 UTC m=+21.665094003 End:2018-10-18 09:56:44.643866012 +0000 UTC m=+21.667349831
I1018 09:56:44.643986       1 scheduler.go:454] Total Schedule Algo cumulative time:947.143012ms for 413
I1018 09:56:44.646290       1 scheduler.go:451] ScheduleAlgoTime 2.035027ms Start:2018-10-18 09:56:44.644245838 +0000 UTC m=+21.667729731 End:2018-10-18 09:56:44.646280953 +0000 UTC m=+21.669764758
I1018 09:56:44.646331       1 scheduler.go:454] Total Schedule Algo cumulative time:949.178039ms for 414
I1018 09:56:44.648418       1 scheduler.go:451] ScheduleAlgoTime 1.914014ms Start:2018-10-18 09:56:44.646498367 +0000 UTC m=+21.669982180 End:2018-10-18 09:56:44.648412388 +0000 UTC m=+21.671896194
I1018 09:56:44.648460       1 scheduler.go:454] Total Schedule Algo cumulative time:951.092053ms for 415
I1018 09:56:44.650811       1 scheduler.go:451] ScheduleAlgoTime 2.169007ms Start:2018-10-18 09:56:44.648634119 +0000 UTC m=+21.672118002 End:2018-10-18 09:56:44.650803205 +0000 UTC m=+21.674287009
I1018 09:56:44.650840       1 scheduler.go:454] Total Schedule Algo cumulative time:953.26106ms for 416
I1018 09:56:44.653306       1 scheduler.go:451] ScheduleAlgoTime 2.290645ms Start:2018-10-18 09:56:44.651009122 +0000 UTC m=+21.674493044 End:2018-10-18 09:56:44.653299885 +0000 UTC m=+21.676783689
I1018 09:56:44.653355       1 scheduler.go:454] Total Schedule Algo cumulative time:955.551705ms for 417
I1018 09:56:44.655542       1 scheduler.go:451] ScheduleAlgoTime 1.903844ms Start:2018-10-18 09:56:44.653629807 +0000 UTC m=+21.677113688 End:2018-10-18 09:56:44.655533715 +0000 UTC m=+21.679017532
I1018 09:56:44.655575       1 scheduler.go:454] Total Schedule Algo cumulative time:957.455549ms for 418
I1018 09:56:44.657893       1 scheduler.go:451] ScheduleAlgoTime 2.05852ms Start:2018-10-18 09:56:44.655825853 +0000 UTC m=+21.679309793 End:2018-10-18 09:56:44.657884472 +0000 UTC m=+21.681368313
I1018 09:56:44.657929       1 scheduler.go:454] Total Schedule Algo cumulative time:959.514069ms for 419
I1018 09:56:44.660179       1 scheduler.go:451] ScheduleAlgoTime 1.949554ms Start:2018-10-18 09:56:44.658221636 +0000 UTC m=+21.681705531 End:2018-10-18 09:56:44.660171277 +0000 UTC m=+21.683655085
I1018 09:56:44.660224       1 scheduler.go:454] Total Schedule Algo cumulative time:961.463623ms for 420
I1018 09:56:44.662412       1 scheduler.go:451] ScheduleAlgoTime 1.94445ms Start:2018-10-18 09:56:44.660458446 +0000 UTC m=+21.683942326 End:2018-10-18 09:56:44.66240294 +0000 UTC m=+21.685886776
I1018 09:56:44.662447       1 scheduler.go:454] Total Schedule Algo cumulative time:963.408073ms for 421
I1018 09:56:44.664724       1 scheduler.go:451] ScheduleAlgoTime 2.064091ms Start:2018-10-18 09:56:44.662651245 +0000 UTC m=+21.686135133 End:2018-10-18 09:56:44.664715415 +0000 UTC m=+21.688199224
I1018 09:56:44.664754       1 scheduler.go:454] Total Schedule Algo cumulative time:965.472164ms for 422
I1018 09:56:44.666941       1 scheduler.go:451] ScheduleAlgoTime 1.968835ms Start:2018-10-18 09:56:44.66496496 +0000 UTC m=+21.688448856 End:2018-10-18 09:56:44.666933889 +0000 UTC m=+21.690417691
I1018 09:56:44.666970       1 scheduler.go:454] Total Schedule Algo cumulative time:967.440999ms for 423
I1018 09:56:44.669152       1 scheduler.go:451] ScheduleAlgoTime 1.961195ms Start:2018-10-18 09:56:44.66718326 +0000 UTC m=+21.690667154 End:2018-10-18 09:56:44.669144541 +0000 UTC m=+21.692628349
I1018 09:56:44.669203       1 scheduler.go:454] Total Schedule Algo cumulative time:969.402194ms for 424
I1018 09:56:44.671287       1 scheduler.go:451] ScheduleAlgoTime 1.910846ms Start:2018-10-18 09:56:44.669368918 +0000 UTC m=+21.692852757 End:2018-10-18 09:56:44.671279795 +0000 UTC m=+21.694763603
I1018 09:56:44.671325       1 scheduler.go:454] Total Schedule Algo cumulative time:971.31304ms for 425
I1018 09:56:44.673558       1 scheduler.go:451] ScheduleAlgoTime 2.097419ms Start:2018-10-18 09:56:44.671448726 +0000 UTC m=+21.694932532 End:2018-10-18 09:56:44.673546147 +0000 UTC m=+21.697029951
I1018 09:56:44.673586       1 scheduler.go:454] Total Schedule Algo cumulative time:973.410459ms for 426
I1018 09:56:44.676032       1 scheduler.go:451] ScheduleAlgoTime 2.145951ms Start:2018-10-18 09:56:44.673875599 +0000 UTC m=+21.697359484 End:2018-10-18 09:56:44.676021598 +0000 UTC m=+21.699505435
I1018 09:56:44.676067       1 scheduler.go:454] Total Schedule Algo cumulative time:975.55641ms for 427
I1018 09:56:44.678399       1 scheduler.go:451] ScheduleAlgoTime 2.040326ms Start:2018-10-18 09:56:44.676351539 +0000 UTC m=+21.699835483 End:2018-10-18 09:56:44.678392007 +0000 UTC m=+21.701875809
I1018 09:56:44.678428       1 scheduler.go:454] Total Schedule Algo cumulative time:977.596736ms for 428
I1018 09:56:44.681158       1 scheduler.go:451] ScheduleAlgoTime 2.443242ms Start:2018-10-18 09:56:44.678706923 +0000 UTC m=+21.702190796 End:2018-10-18 09:56:44.681150232 +0000 UTC m=+21.704634038
I1018 09:56:44.681196       1 scheduler.go:454] Total Schedule Algo cumulative time:980.039978ms for 429
I1018 09:56:44.683360       1 scheduler.go:451] ScheduleAlgoTime 2.028752ms Start:2018-10-18 09:56:44.681326059 +0000 UTC m=+21.704809862 End:2018-10-18 09:56:44.68335481 +0000 UTC m=+21.706838614
I1018 09:56:44.683384       1 scheduler.go:454] Total Schedule Algo cumulative time:982.06873ms for 430
I1018 09:56:44.685470       1 scheduler.go:451] ScheduleAlgoTime 1.896808ms Start:2018-10-18 09:56:44.683566726 +0000 UTC m=+21.707050631 End:2018-10-18 09:56:44.685463624 +0000 UTC m=+21.708947439
I1018 09:56:44.685499       1 scheduler.go:454] Total Schedule Algo cumulative time:983.965538ms for 431
I1018 09:56:44.687400       1 scheduler.go:451] ScheduleAlgoTime 1.662013ms Start:2018-10-18 09:56:44.685730321 +0000 UTC m=+21.709214231 End:2018-10-18 09:56:44.687392426 +0000 UTC m=+21.710876244
I1018 09:56:44.687433       1 scheduler.go:454] Total Schedule Algo cumulative time:985.627551ms for 432
I1018 09:56:44.689417       1 scheduler.go:451] ScheduleAlgoTime 1.767611ms Start:2018-10-18 09:56:44.68764197 +0000 UTC m=+21.711125864 End:2018-10-18 09:56:44.689409672 +0000 UTC m=+21.712893475
I1018 09:56:44.689443       1 scheduler.go:454] Total Schedule Algo cumulative time:987.395162ms for 433
I1018 09:56:44.691784       1 scheduler.go:451] ScheduleAlgoTime 2.227532ms Start:2018-10-18 09:56:44.689547584 +0000 UTC m=+21.713031397 End:2018-10-18 09:56:44.691775125 +0000 UTC m=+21.715258929
I1018 09:56:44.691829       1 scheduler.go:454] Total Schedule Algo cumulative time:989.622694ms for 434
I1018 09:56:44.694111       1 scheduler.go:451] ScheduleAlgoTime 2.028522ms Start:2018-10-18 09:56:44.692075047 +0000 UTC m=+21.715558960 End:2018-10-18 09:56:44.694103675 +0000 UTC m=+21.717587482
I1018 09:56:44.694138       1 scheduler.go:454] Total Schedule Algo cumulative time:991.651216ms for 435
I1018 09:56:44.697000       1 scheduler.go:451] ScheduleAlgoTime 2.180884ms Start:2018-10-18 09:56:44.694813204 +0000 UTC m=+21.718297053 End:2018-10-18 09:56:44.696994131 +0000 UTC m=+21.720477937
I1018 09:56:44.697069       1 scheduler.go:454] Total Schedule Algo cumulative time:993.8321ms for 436
I1018 09:56:44.699501       1 scheduler.go:451] ScheduleAlgoTime 2.082442ms Start:2018-10-18 09:56:44.697409758 +0000 UTC m=+21.720893645 End:2018-10-18 09:56:44.699492278 +0000 UTC m=+21.722976087
I1018 09:56:44.699535       1 scheduler.go:454] Total Schedule Algo cumulative time:995.914542ms for 437
I1018 09:56:44.701847       1 scheduler.go:451] ScheduleAlgoTime 2.047102ms Start:2018-10-18 09:56:44.699788825 +0000 UTC m=+21.723272707 End:2018-10-18 09:56:44.701835985 +0000 UTC m=+21.725319809
I1018 09:56:44.701889       1 scheduler.go:454] Total Schedule Algo cumulative time:997.961644ms for 438
I1018 09:56:44.703925       1 scheduler.go:451] ScheduleAlgoTime 1.826933ms Start:2018-10-18 09:56:44.702091896 +0000 UTC m=+21.725575777 End:2018-10-18 09:56:44.703918902 +0000 UTC m=+21.727402710
I1018 09:56:44.703951       1 scheduler.go:454] Total Schedule Algo cumulative time:999.788577ms for 439
I1018 09:56:44.706277       1 scheduler.go:451] ScheduleAlgoTime 2.030394ms Start:2018-10-18 09:56:44.704235142 +0000 UTC m=+21.727719032 End:2018-10-18 09:56:44.706265495 +0000 UTC m=+21.729749426
I1018 09:56:44.706319       1 scheduler.go:454] Total Schedule Algo cumulative time:1.001818971s for 440
I1018 09:56:44.708290       1 scheduler.go:451] ScheduleAlgoTime 1.834971ms Start:2018-10-18 09:56:44.706448628 +0000 UTC m=+21.729932529 End:2018-10-18 09:56:44.708283696 +0000 UTC m=+21.731767500
I1018 09:56:44.708321       1 scheduler.go:454] Total Schedule Algo cumulative time:1.003653942s for 441
I1018 09:56:44.710259       1 scheduler.go:451] ScheduleAlgoTime 1.782294ms Start:2018-10-18 09:56:44.708468776 +0000 UTC m=+21.731952657 End:2018-10-18 09:56:44.710251142 +0000 UTC m=+21.733734951
I1018 09:56:44.710288       1 scheduler.go:454] Total Schedule Algo cumulative time:1.005436236s for 442
I1018 09:56:44.712602       1 scheduler.go:451] ScheduleAlgoTime 2.070831ms Start:2018-10-18 09:56:44.710524639 +0000 UTC m=+21.734008536 End:2018-10-18 09:56:44.712595564 +0000 UTC m=+21.736079367
I1018 09:56:44.712629       1 scheduler.go:454] Total Schedule Algo cumulative time:1.007507067s for 443
I1018 09:56:44.715706       1 scheduler.go:451] ScheduleAlgoTime 2.790086ms Start:2018-10-18 09:56:44.712907105 +0000 UTC m=+21.736390982 End:2018-10-18 09:56:44.715697263 +0000 UTC m=+21.739181068
I1018 09:56:44.715736       1 scheduler.go:454] Total Schedule Algo cumulative time:1.010297153s for 444
I1018 09:56:44.718385       1 scheduler.go:451] ScheduleAlgoTime 2.430613ms Start:2018-10-18 09:56:44.715946588 +0000 UTC m=+21.739430481 End:2018-10-18 09:56:44.71837729 +0000 UTC m=+21.741861094
I1018 09:56:44.718418       1 scheduler.go:454] Total Schedule Algo cumulative time:1.012727766s for 445
I1018 09:56:44.720483       1 scheduler.go:451] ScheduleAlgoTime 1.879627ms Start:2018-10-18 09:56:44.718594063 +0000 UTC m=+21.742077956 End:2018-10-18 09:56:44.720473774 +0000 UTC m=+21.743957583
I1018 09:56:44.720517       1 scheduler.go:454] Total Schedule Algo cumulative time:1.014607393s for 446
I1018 09:56:44.722539       1 scheduler.go:451] ScheduleAlgoTime 1.781905ms Start:2018-10-18 09:56:44.720748351 +0000 UTC m=+21.744232226 End:2018-10-18 09:56:44.722530329 +0000 UTC m=+21.746014131
I1018 09:56:44.722602       1 scheduler.go:454] Total Schedule Algo cumulative time:1.016389298s for 447
I1018 09:56:44.724889       1 scheduler.go:451] ScheduleAlgoTime 1.936561ms Start:2018-10-18 09:56:44.722944452 +0000 UTC m=+21.746428353 End:2018-10-18 09:56:44.724881111 +0000 UTC m=+21.748364914
I1018 09:56:44.724937       1 scheduler.go:454] Total Schedule Algo cumulative time:1.018325859s for 448
I1018 09:56:44.726800       1 scheduler.go:451] ScheduleAlgoTime 1.716921ms Start:2018-10-18 09:56:44.725076751 +0000 UTC m=+21.748560554 End:2018-10-18 09:56:44.726793671 +0000 UTC m=+21.750277475
I1018 09:56:44.726828       1 scheduler.go:454] Total Schedule Algo cumulative time:1.02004278s for 449
I1018 09:56:44.729033       1 scheduler.go:451] ScheduleAlgoTime 1.978537ms Start:2018-10-18 09:56:44.727048131 +0000 UTC m=+21.750532007 End:2018-10-18 09:56:44.729026738 +0000 UTC m=+21.752510544
I1018 09:56:44.729214       1 scheduler.go:454] Total Schedule Algo cumulative time:1.022021317s for 450
I1018 09:56:44.731707       1 scheduler.go:451] ScheduleAlgoTime 2.213344ms Start:2018-10-18 09:56:44.729482176 +0000 UTC m=+21.752966099 End:2018-10-18 09:56:44.731695555 +0000 UTC m=+21.755179443
I1018 09:56:44.731748       1 scheduler.go:454] Total Schedule Algo cumulative time:1.024234661s for 451
I1018 09:56:44.734430       1 scheduler.go:451] ScheduleAlgoTime 2.390851ms Start:2018-10-18 09:56:44.732030393 +0000 UTC m=+21.755514286 End:2018-10-18 09:56:44.734421335 +0000 UTC m=+21.757905137
I1018 09:56:44.734475       1 scheduler.go:454] Total Schedule Algo cumulative time:1.026625512s for 452
I1018 09:56:44.737243       1 scheduler.go:451] ScheduleAlgoTime 2.393195ms Start:2018-10-18 09:56:44.734833444 +0000 UTC m=+21.758324224 End:2018-10-18 09:56:44.737233612 +0000 UTC m=+21.760717419
I1018 09:56:44.737306       1 scheduler.go:454] Total Schedule Algo cumulative time:1.029018707s for 453
I1018 09:56:44.739654       1 scheduler.go:451] ScheduleAlgoTime 2.121453ms Start:2018-10-18 09:56:44.737516677 +0000 UTC m=+21.761000577 End:2018-10-18 09:56:44.739638203 +0000 UTC m=+21.763122030
I1018 09:56:44.739721       1 scheduler.go:454] Total Schedule Algo cumulative time:1.03114016s for 454
I1018 09:56:44.742305       1 scheduler.go:451] ScheduleAlgoTime 2.241708ms Start:2018-10-18 09:56:44.740050729 +0000 UTC m=+21.763534576 End:2018-10-18 09:56:44.74229246 +0000 UTC m=+21.765776284
I1018 09:56:44.742347       1 scheduler.go:454] Total Schedule Algo cumulative time:1.033381868s for 455
I1018 09:56:44.744910       1 scheduler.go:451] ScheduleAlgoTime 2.301626ms Start:2018-10-18 09:56:44.742597562 +0000 UTC m=+21.766081472 End:2018-10-18 09:56:44.744899295 +0000 UTC m=+21.768383098
I1018 09:56:44.744941       1 scheduler.go:454] Total Schedule Algo cumulative time:1.035683494s for 456
I1018 09:56:44.747298       1 scheduler.go:451] ScheduleAlgoTime 2.09551ms Start:2018-10-18 09:56:44.745193869 +0000 UTC m=+21.768677711 End:2018-10-18 09:56:44.747289416 +0000 UTC m=+21.770773221
I1018 09:56:44.747331       1 scheduler.go:454] Total Schedule Algo cumulative time:1.037779004s for 457
I1018 09:56:44.749488       1 scheduler.go:451] ScheduleAlgoTime 1.848193ms Start:2018-10-18 09:56:44.747629684 +0000 UTC m=+21.771113560 End:2018-10-18 09:56:44.749477942 +0000 UTC m=+21.772961753
I1018 09:56:44.749523       1 scheduler.go:454] Total Schedule Algo cumulative time:1.039627197s for 458
I1018 09:56:44.757576       1 scheduler.go:451] ScheduleAlgoTime 7.660317ms Start:2018-10-18 09:56:44.749905684 +0000 UTC m=+21.773389614 End:2018-10-18 09:56:44.757566108 +0000 UTC m=+21.781049931
I1018 09:56:44.757614       1 scheduler.go:454] Total Schedule Algo cumulative time:1.047287514s for 459
I1018 09:56:44.760013       1 scheduler.go:451] ScheduleAlgoTime 2.227761ms Start:2018-10-18 09:56:44.757774119 +0000 UTC m=+21.781257927 End:2018-10-18 09:56:44.760001884 +0000 UTC m=+21.783485688
I1018 09:56:44.760059       1 scheduler.go:454] Total Schedule Algo cumulative time:1.049515275s for 460
I1018 09:56:44.762610       1 scheduler.go:451] ScheduleAlgoTime 2.302809ms Start:2018-10-18 09:56:44.760288299 +0000 UTC m=+21.783772225 End:2018-10-18 09:56:44.762591209 +0000 UTC m=+21.786075034
I1018 09:56:44.762713       1 scheduler.go:454] Total Schedule Algo cumulative time:1.051818084s for 461
I1018 09:56:44.764821       1 scheduler.go:451] ScheduleAlgoTime 1.885187ms Start:2018-10-18 09:56:44.762928812 +0000 UTC m=+21.786412735 End:2018-10-18 09:56:44.764814117 +0000 UTC m=+21.788297922
I1018 09:56:44.764864       1 scheduler.go:454] Total Schedule Algo cumulative time:1.053703271s for 462
I1018 09:56:44.767253       1 scheduler.go:451] ScheduleAlgoTime 2.175529ms Start:2018-10-18 09:56:44.765068015 +0000 UTC m=+21.788551926 End:2018-10-18 09:56:44.767243637 +0000 UTC m=+21.790727455
I1018 09:56:44.767285       1 scheduler.go:454] Total Schedule Algo cumulative time:1.0558788s for 463
I1018 09:56:44.769856       1 scheduler.go:451] ScheduleAlgoTime 2.436886ms Start:2018-10-18 09:56:44.767412457 +0000 UTC m=+21.790896364 End:2018-10-18 09:56:44.769849445 +0000 UTC m=+21.793333250
I1018 09:56:44.769889       1 scheduler.go:454] Total Schedule Algo cumulative time:1.058315686s for 464
I1018 09:56:44.772297       1 scheduler.go:451] ScheduleAlgoTime 2.185496ms Start:2018-10-18 09:56:44.77010029 +0000 UTC m=+21.793584223 End:2018-10-18 09:56:44.772285917 +0000 UTC m=+21.795769719
I1018 09:56:44.772345       1 scheduler.go:454] Total Schedule Algo cumulative time:1.060501182s for 465
I1018 09:56:44.774895       1 scheduler.go:451] ScheduleAlgoTime 2.352436ms Start:2018-10-18 09:56:44.772534773 +0000 UTC m=+21.796018665 End:2018-10-18 09:56:44.774887293 +0000 UTC m=+21.798371101
I1018 09:56:44.774926       1 scheduler.go:454] Total Schedule Algo cumulative time:1.062853618s for 466
I1018 09:56:44.777473       1 scheduler.go:451] ScheduleAlgoTime 2.26594ms Start:2018-10-18 09:56:44.775197173 +0000 UTC m=+21.798681097 End:2018-10-18 09:56:44.777463221 +0000 UTC m=+21.800947037
I1018 09:56:44.777514       1 scheduler.go:454] Total Schedule Algo cumulative time:1.065119558s for 467
I1018 09:56:44.780011       1 scheduler.go:451] ScheduleAlgoTime 2.347075ms Start:2018-10-18 09:56:44.77765479 +0000 UTC m=+21.801138694 End:2018-10-18 09:56:44.780001965 +0000 UTC m=+21.803485769
I1018 09:56:44.780046       1 scheduler.go:454] Total Schedule Algo cumulative time:1.067466633s for 468
I1018 09:56:44.782290       1 scheduler.go:451] ScheduleAlgoTime 1.942626ms Start:2018-10-18 09:56:44.780339811 +0000 UTC m=+21.803823727 End:2018-10-18 09:56:44.782282549 +0000 UTC m=+21.805766353
I1018 09:56:44.782327       1 scheduler.go:454] Total Schedule Algo cumulative time:1.069409259s for 469
I1018 09:56:44.784634       1 scheduler.go:451] ScheduleAlgoTime 2.026927ms Start:2018-10-18 09:56:44.782598686 +0000 UTC m=+21.806082581 End:2018-10-18 09:56:44.784625705 +0000 UTC m=+21.808109508
I1018 09:56:44.784708       1 scheduler.go:454] Total Schedule Algo cumulative time:1.071436186s for 470
I1018 09:56:44.787973       1 scheduler.go:451] ScheduleAlgoTime 2.864138ms Start:2018-10-18 09:56:44.785099367 +0000 UTC m=+21.808583247 End:2018-10-18 09:56:44.787963581 +0000 UTC m=+21.811447385
I1018 09:56:44.788004       1 scheduler.go:454] Total Schedule Algo cumulative time:1.074300324s for 471
I1018 09:56:44.791157       1 scheduler.go:451] ScheduleAlgoTime 2.510541ms Start:2018-10-18 09:56:44.788637307 +0000 UTC m=+21.812121187 End:2018-10-18 09:56:44.791147925 +0000 UTC m=+21.814631728
I1018 09:56:44.791190       1 scheduler.go:454] Total Schedule Algo cumulative time:1.076810865s for 472
I1018 09:56:44.793623       1 scheduler.go:451] ScheduleAlgoTime 2.159592ms Start:2018-10-18 09:56:44.791455869 +0000 UTC m=+21.814939745 End:2018-10-18 09:56:44.793615532 +0000 UTC m=+21.817099337
I1018 09:56:44.793651       1 scheduler.go:454] Total Schedule Algo cumulative time:1.078970457s for 473
I1018 09:56:44.795873       1 scheduler.go:451] ScheduleAlgoTime 1.94337ms Start:2018-10-18 09:56:44.793920658 +0000 UTC m=+21.817404490 End:2018-10-18 09:56:44.795864057 +0000 UTC m=+21.819347860
I1018 09:56:44.795912       1 scheduler.go:454] Total Schedule Algo cumulative time:1.080913827s for 474
I1018 09:56:44.798849       1 scheduler.go:451] ScheduleAlgoTime 2.598758ms Start:2018-10-18 09:56:44.796241606 +0000 UTC m=+21.819725504 End:2018-10-18 09:56:44.79884046 +0000 UTC m=+21.822324262
I1018 09:56:44.798879       1 scheduler.go:454] Total Schedule Algo cumulative time:1.083512585s for 475
I1018 09:56:44.801976       1 scheduler.go:451] ScheduleAlgoTime 2.932839ms Start:2018-10-18 09:56:44.799033179 +0000 UTC m=+21.822516983 End:2018-10-18 09:56:44.801966005 +0000 UTC m=+21.825449822
I1018 09:56:44.802011       1 scheduler.go:454] Total Schedule Algo cumulative time:1.086445424s for 476
I1018 09:56:44.804584       1 scheduler.go:451] ScheduleAlgoTime 2.35619ms Start:2018-10-18 09:56:44.802219559 +0000 UTC m=+21.825703457 End:2018-10-18 09:56:44.804575838 +0000 UTC m=+21.828059647
I1018 09:56:44.804615       1 scheduler.go:454] Total Schedule Algo cumulative time:1.088801614s for 477
I1018 09:56:44.807180       1 scheduler.go:451] ScheduleAlgoTime 2.309371ms Start:2018-10-18 09:56:44.804861575 +0000 UTC m=+21.828345473 End:2018-10-18 09:56:44.807171039 +0000 UTC m=+21.830654844
I1018 09:56:44.807214       1 scheduler.go:454] Total Schedule Algo cumulative time:1.091110985s for 478
I1018 09:56:44.809617       1 scheduler.go:451] ScheduleAlgoTime 2.156744ms Start:2018-10-18 09:56:44.807450193 +0000 UTC m=+21.830934034 End:2018-10-18 09:56:44.809606869 +0000 UTC m=+21.833090778
I1018 09:56:44.809656       1 scheduler.go:454] Total Schedule Algo cumulative time:1.093267729s for 479
I1018 09:56:44.812504       1 scheduler.go:451] ScheduleAlgoTime 2.553699ms Start:2018-10-18 09:56:44.809939623 +0000 UTC m=+21.833423530 End:2018-10-18 09:56:44.812493421 +0000 UTC m=+21.835977229
I1018 09:56:44.812552       1 scheduler.go:454] Total Schedule Algo cumulative time:1.095821428s for 480
I1018 09:56:44.815000       1 scheduler.go:451] ScheduleAlgoTime 2.134035ms Start:2018-10-18 09:56:44.812856883 +0000 UTC m=+21.836340798 End:2018-10-18 09:56:44.814991025 +0000 UTC m=+21.838474833
I1018 09:56:44.815034       1 scheduler.go:454] Total Schedule Algo cumulative time:1.097955463s for 481
I1018 09:56:44.817523       1 scheduler.go:451] ScheduleAlgoTime 2.19486ms Start:2018-10-18 09:56:44.815319465 +0000 UTC m=+21.838803342 End:2018-10-18 09:56:44.817514395 +0000 UTC m=+21.840998202
I1018 09:56:44.817555       1 scheduler.go:454] Total Schedule Algo cumulative time:1.100150323s for 482
I1018 09:56:44.820451       1 scheduler.go:451] ScheduleAlgoTime 2.459804ms Start:2018-10-18 09:56:44.817977762 +0000 UTC m=+21.841461631 End:2018-10-18 09:56:44.820437502 +0000 UTC m=+21.843921435
I1018 09:56:44.820490       1 scheduler.go:454] Total Schedule Algo cumulative time:1.102610127s for 483
I1018 09:56:44.822954       1 scheduler.go:451] ScheduleAlgoTime 2.147195ms Start:2018-10-18 09:56:44.820798334 +0000 UTC m=+21.844282227 End:2018-10-18 09:56:44.822945614 +0000 UTC m=+21.846429422
I1018 09:56:44.822997       1 scheduler.go:454] Total Schedule Algo cumulative time:1.104757322s for 484
I1018 09:56:44.825807       1 scheduler.go:451] ScheduleAlgoTime 2.611135ms Start:2018-10-18 09:56:44.823186287 +0000 UTC m=+21.846670176 End:2018-10-18 09:56:44.825797508 +0000 UTC m=+21.849281311
I1018 09:56:44.825840       1 scheduler.go:454] Total Schedule Algo cumulative time:1.107368457s for 485
I1018 09:56:44.828066       1 scheduler.go:451] ScheduleAlgoTime 1.923199ms Start:2018-10-18 09:56:44.826136353 +0000 UTC m=+21.849620256 End:2018-10-18 09:56:44.828059652 +0000 UTC m=+21.851543455
I1018 09:56:44.828094       1 scheduler.go:454] Total Schedule Algo cumulative time:1.109291656s for 486
I1018 09:56:44.830243       1 scheduler.go:451] ScheduleAlgoTime 1.94631ms Start:2018-10-18 09:56:44.828289629 +0000 UTC m=+21.851773502 End:2018-10-18 09:56:44.830236009 +0000 UTC m=+21.853719812
I1018 09:56:44.830270       1 scheduler.go:454] Total Schedule Algo cumulative time:1.111237966s for 487
I1018 09:56:44.832426       1 scheduler.go:451] ScheduleAlgoTime 1.93722ms Start:2018-10-18 09:56:44.830478149 +0000 UTC m=+21.853962026 End:2018-10-18 09:56:44.832415358 +0000 UTC m=+21.855899246
I1018 09:56:44.832474       1 scheduler.go:454] Total Schedule Algo cumulative time:1.113175186s for 488
I1018 09:56:44.835212       1 scheduler.go:451] ScheduleAlgoTime 2.638088ms Start:2018-10-18 09:56:44.832564444 +0000 UTC m=+21.856048260 End:2018-10-18 09:56:44.835202544 +0000 UTC m=+21.858686348
I1018 09:56:44.835246       1 scheduler.go:454] Total Schedule Algo cumulative time:1.115813274s for 489
I1018 09:56:44.837240       1 scheduler.go:451] ScheduleAlgoTime 1.829843ms Start:2018-10-18 09:56:44.835402476 +0000 UTC m=+21.858886385 End:2018-10-18 09:56:44.837232425 +0000 UTC m=+21.860716228
I1018 09:56:44.837268       1 scheduler.go:454] Total Schedule Algo cumulative time:1.117643117s for 490
I1018 09:56:44.839413       1 scheduler.go:451] ScheduleAlgoTime 2.007803ms Start:2018-10-18 09:56:44.837397964 +0000 UTC m=+21.860881831 End:2018-10-18 09:56:44.839405824 +0000 UTC m=+21.862889634
I1018 09:56:44.839444       1 scheduler.go:454] Total Schedule Algo cumulative time:1.11965092s for 491
I1018 09:56:44.841447       1 scheduler.go:451] ScheduleAlgoTime 1.92023ms Start:2018-10-18 09:56:44.839513168 +0000 UTC m=+21.862997004 End:2018-10-18 09:56:44.841433422 +0000 UTC m=+21.864917234
I1018 09:56:44.841489       1 scheduler.go:454] Total Schedule Algo cumulative time:1.12157115s for 492
I1018 09:56:44.843582       1 scheduler.go:451] ScheduleAlgoTime 1.859094ms Start:2018-10-18 09:56:44.841716141 +0000 UTC m=+21.865199946 End:2018-10-18 09:56:44.843575232 +0000 UTC m=+21.867059040
I1018 09:56:44.843625       1 scheduler.go:454] Total Schedule Algo cumulative time:1.123430244s for 493
I1018 09:56:44.845905       1 scheduler.go:451] ScheduleAlgoTime 2.025069ms Start:2018-10-18 09:56:44.843870241 +0000 UTC m=+21.867354116 End:2018-10-18 09:56:44.845895323 +0000 UTC m=+21.869379185
I1018 09:56:44.845942       1 scheduler.go:454] Total Schedule Algo cumulative time:1.125455313s for 494
I1018 09:56:44.848209       1 scheduler.go:451] ScheduleAlgoTime 1.9362ms Start:2018-10-18 09:56:44.846266033 +0000 UTC m=+21.869749861 End:2018-10-18 09:56:44.848202258 +0000 UTC m=+21.871686061
I1018 09:56:44.848237       1 scheduler.go:454] Total Schedule Algo cumulative time:1.127391513s for 495
I1018 09:56:44.850799       1 scheduler.go:451] ScheduleAlgoTime 2.258975ms Start:2018-10-18 09:56:44.848530428 +0000 UTC m=+21.872014233 End:2018-10-18 09:56:44.850789371 +0000 UTC m=+21.874273208
I1018 09:56:44.850832       1 scheduler.go:454] Total Schedule Algo cumulative time:1.129650488s for 496
I1018 09:56:44.852902       1 scheduler.go:451] ScheduleAlgoTime 1.924255ms Start:2018-10-18 09:56:44.850969028 +0000 UTC m=+21.874452906 End:2018-10-18 09:56:44.852893355 +0000 UTC m=+21.876377161
I1018 09:56:44.852933       1 scheduler.go:454] Total Schedule Algo cumulative time:1.131574743s for 497
I1018 09:56:44.854995       1 scheduler.go:451] ScheduleAlgoTime 1.817496ms Start:2018-10-18 09:56:44.853168377 +0000 UTC m=+21.876652315 End:2018-10-18 09:56:44.854986003 +0000 UTC m=+21.878469811
I1018 09:56:44.855025       1 scheduler.go:454] Total Schedule Algo cumulative time:1.133392239s for 498
I1018 09:56:44.857088       1 scheduler.go:451] ScheduleAlgoTime 1.80498ms Start:2018-10-18 09:56:44.855274139 +0000 UTC m=+21.878758002 End:2018-10-18 09:56:44.857079178 +0000 UTC m=+21.880562982
I1018 09:56:44.857119       1 scheduler.go:454] Total Schedule Algo cumulative time:1.135197219s for 499
I1018 09:56:44.859401       1 scheduler.go:451] ScheduleAlgoTime 1.931848ms Start:2018-10-18 09:56:44.857460161 +0000 UTC m=+21.880944028 End:2018-10-18 09:56:44.859392066 +0000 UTC m=+21.882875876
I1018 09:56:44.859430       1 scheduler.go:454] Total Schedule Algo cumulative time:1.137129067s for 500
I1018 09:56:44.861839       1 scheduler.go:451] ScheduleAlgoTime 2.144382ms Start:2018-10-18 09:56:44.85968659 +0000 UTC m=+21.883170493 End:2018-10-18 09:56:44.861831067 +0000 UTC m=+21.885314875
I1018 09:56:44.861868       1 scheduler.go:454] Total Schedule Algo cumulative time:1.139273449s for 501
I1018 09:56:44.864078       1 scheduler.go:451] ScheduleAlgoTime 1.865625ms Start:2018-10-18 09:56:44.862203501 +0000 UTC m=+21.885687374 End:2018-10-18 09:56:44.864069195 +0000 UTC m=+21.887552999
I1018 09:56:44.864116       1 scheduler.go:454] Total Schedule Algo cumulative time:1.141139074s for 502
I1018 09:56:44.866523       1 scheduler.go:451] ScheduleAlgoTime 2.188226ms Start:2018-10-18 09:56:44.864326594 +0000 UTC m=+21.887810481 End:2018-10-18 09:56:44.8665149 +0000 UTC m=+21.889998707
I1018 09:56:44.866554       1 scheduler.go:454] Total Schedule Algo cumulative time:1.1433273s for 503
I1018 09:56:44.868876       1 scheduler.go:451] ScheduleAlgoTime 2.217082ms Start:2018-10-18 09:56:44.866652833 +0000 UTC m=+21.890136708 End:2018-10-18 09:56:44.868869972 +0000 UTC m=+21.892353790
I1018 09:56:44.868908       1 scheduler.go:454] Total Schedule Algo cumulative time:1.145544382s for 504
I1018 09:56:44.871526       1 scheduler.go:451] ScheduleAlgoTime 2.351948ms Start:2018-10-18 09:56:44.869167532 +0000 UTC m=+21.892651426 End:2018-10-18 09:56:44.871519567 +0000 UTC m=+21.895003374
I1018 09:56:44.871555       1 scheduler.go:454] Total Schedule Algo cumulative time:1.14789633s for 505
I1018 09:56:44.874403       1 scheduler.go:451] ScheduleAlgoTime 2.379949ms Start:2018-10-18 09:56:44.872015978 +0000 UTC m=+21.895499864 End:2018-10-18 09:56:44.87439601 +0000 UTC m=+21.897879813
I1018 09:56:44.874431       1 scheduler.go:454] Total Schedule Algo cumulative time:1.150276279s for 506
I1018 09:56:44.878882       1 scheduler.go:451] ScheduleAlgoTime 4.291289ms Start:2018-10-18 09:56:44.874572499 +0000 UTC m=+21.898056310 End:2018-10-18 09:56:44.878863796 +0000 UTC m=+21.902347599
I1018 09:56:44.878980       1 scheduler.go:454] Total Schedule Algo cumulative time:1.154567568s for 507
I1018 09:56:44.884454       1 scheduler.go:451] ScheduleAlgoTime 5.153206ms Start:2018-10-18 09:56:44.879289209 +0000 UTC m=+21.902773012 End:2018-10-18 09:56:44.884442417 +0000 UTC m=+21.907926218
I1018 09:56:44.884496       1 scheduler.go:454] Total Schedule Algo cumulative time:1.159720774s for 508
I1018 09:56:44.887166       1 scheduler.go:451] ScheduleAlgoTime 2.137694ms Start:2018-10-18 09:56:44.885019157 +0000 UTC m=+21.908503041 End:2018-10-18 09:56:44.887156931 +0000 UTC m=+21.910640735
I1018 09:56:44.887197       1 scheduler.go:454] Total Schedule Algo cumulative time:1.161858468s for 509
I1018 09:56:44.889245       1 scheduler.go:451] ScheduleAlgoTime 1.81995ms Start:2018-10-18 09:56:44.887417457 +0000 UTC m=+21.910901349 End:2018-10-18 09:56:44.889237495 +0000 UTC m=+21.912721299
I1018 09:56:44.889287       1 scheduler.go:454] Total Schedule Algo cumulative time:1.163678418s for 510
I1018 09:56:44.891753       1 scheduler.go:451] ScheduleAlgoTime 2.279184ms Start:2018-10-18 09:56:44.889466137 +0000 UTC m=+21.912950012 End:2018-10-18 09:56:44.891745393 +0000 UTC m=+21.915229196
I1018 09:56:44.891783       1 scheduler.go:454] Total Schedule Algo cumulative time:1.165957602s for 511
I1018 09:56:44.894743       1 scheduler.go:451] ScheduleAlgoTime 2.742083ms Start:2018-10-18 09:56:44.891992897 +0000 UTC m=+21.915476791 End:2018-10-18 09:56:44.894735066 +0000 UTC m=+21.918218874
I1018 09:56:44.894772       1 scheduler.go:454] Total Schedule Algo cumulative time:1.168699685s for 512
I1018 09:56:44.897442       1 scheduler.go:451] ScheduleAlgoTime 2.548123ms Start:2018-10-18 09:56:44.894886768 +0000 UTC m=+21.918370572 End:2018-10-18 09:56:44.897434885 +0000 UTC m=+21.920918695
I1018 09:56:44.897472       1 scheduler.go:454] Total Schedule Algo cumulative time:1.171247808s for 513
I1018 09:56:44.899485       1 scheduler.go:451] ScheduleAlgoTime 1.867627ms Start:2018-10-18 09:56:44.897607877 +0000 UTC m=+21.921091761 End:2018-10-18 09:56:44.899475585 +0000 UTC m=+21.922959388
I1018 09:56:44.899516       1 scheduler.go:454] Total Schedule Algo cumulative time:1.173115435s for 514
I1018 09:56:44.902001       1 scheduler.go:451] ScheduleAlgoTime 2.199565ms Start:2018-10-18 09:56:44.899794219 +0000 UTC m=+21.923278099 End:2018-10-18 09:56:44.901993862 +0000 UTC m=+21.925477664
I1018 09:56:44.902045       1 scheduler.go:454] Total Schedule Algo cumulative time:1.175315s for 515
I1018 09:56:44.904217       1 scheduler.go:451] ScheduleAlgoTime 1.896366ms Start:2018-10-18 09:56:44.902313389 +0000 UTC m=+21.925797220 End:2018-10-18 09:56:44.904209782 +0000 UTC m=+21.927693586
I1018 09:56:44.904283       1 scheduler.go:454] Total Schedule Algo cumulative time:1.177211366s for 516
I1018 09:56:44.906659       1 scheduler.go:451] ScheduleAlgoTime 2.104418ms Start:2018-10-18 09:56:44.904544373 +0000 UTC m=+21.928028260 End:2018-10-18 09:56:44.906648803 +0000 UTC m=+21.930132678
I1018 09:56:44.906744       1 scheduler.go:454] Total Schedule Algo cumulative time:1.179315784s for 517
I1018 09:56:44.909442       1 scheduler.go:451] ScheduleAlgoTime 2.495979ms Start:2018-10-18 09:56:44.906939177 +0000 UTC m=+21.930423062 End:2018-10-18 09:56:44.909435235 +0000 UTC m=+21.932919041
I1018 09:56:44.909469       1 scheduler.go:454] Total Schedule Algo cumulative time:1.181811763s for 518
I1018 09:56:44.912737       1 scheduler.go:451] ScheduleAlgoTime 3.096041ms Start:2018-10-18 09:56:44.909631356 +0000 UTC m=+21.933115263 End:2018-10-18 09:56:44.912727499 +0000 UTC m=+21.936211304
I1018 09:56:44.912772       1 scheduler.go:454] Total Schedule Algo cumulative time:1.184907804s for 519
I1018 09:56:44.914982       1 scheduler.go:451] ScheduleAlgoTime 1.872321ms Start:2018-10-18 09:56:44.913102541 +0000 UTC m=+21.936586446 End:2018-10-18 09:56:44.914974962 +0000 UTC m=+21.938458767
I1018 09:56:44.915016       1 scheduler.go:454] Total Schedule Algo cumulative time:1.186780125s for 520
I1018 09:56:44.917317       1 scheduler.go:451] ScheduleAlgoTime 2.026834ms Start:2018-10-18 09:56:44.915280874 +0000 UTC m=+21.938764767 End:2018-10-18 09:56:44.917307775 +0000 UTC m=+21.940791601
I1018 09:56:44.917356       1 scheduler.go:454] Total Schedule Algo cumulative time:1.188806959s for 521
I1018 09:56:44.919767       1 scheduler.go:451] ScheduleAlgoTime 2.175865ms Start:2018-10-18 09:56:44.917582645 +0000 UTC m=+21.941066501 End:2018-10-18 09:56:44.919758562 +0000 UTC m=+21.943242366
I1018 09:56:44.919801       1 scheduler.go:454] Total Schedule Algo cumulative time:1.190982824s for 522
I1018 09:56:44.921852       1 scheduler.go:451] ScheduleAlgoTime 1.837787ms Start:2018-10-18 09:56:44.920005759 +0000 UTC m=+21.943489630 End:2018-10-18 09:56:44.921843613 +0000 UTC m=+21.945327417
I1018 09:56:44.921893       1 scheduler.go:454] Total Schedule Algo cumulative time:1.192820611s for 523
I1018 09:56:44.923920       1 scheduler.go:451] ScheduleAlgoTime 1.818492ms Start:2018-10-18 09:56:44.922093961 +0000 UTC m=+21.945577845 End:2018-10-18 09:56:44.923912533 +0000 UTC m=+21.947396337
I1018 09:56:44.923955       1 scheduler.go:454] Total Schedule Algo cumulative time:1.194639103s for 524
I1018 09:56:44.926250       1 scheduler.go:451] ScheduleAlgoTime 2.056553ms Start:2018-10-18 09:56:44.924185634 +0000 UTC m=+21.947669505 End:2018-10-18 09:56:44.926242234 +0000 UTC m=+21.949726058
I1018 09:56:44.926280       1 scheduler.go:454] Total Schedule Algo cumulative time:1.196695656s for 525
I1018 09:56:44.929088       1 scheduler.go:451] ScheduleAlgoTime 2.549095ms Start:2018-10-18 09:56:44.926520803 +0000 UTC m=+21.950004683 End:2018-10-18 09:56:44.929069975 +0000 UTC m=+21.952553778
I1018 09:56:44.929120       1 scheduler.go:454] Total Schedule Algo cumulative time:1.199244751s for 526
I1018 09:56:44.931590       1 scheduler.go:451] ScheduleAlgoTime 2.298836ms Start:2018-10-18 09:56:44.929281181 +0000 UTC m=+21.952765067 End:2018-10-18 09:56:44.931580097 +0000 UTC m=+21.955063903
I1018 09:56:44.931622       1 scheduler.go:454] Total Schedule Algo cumulative time:1.201543587s for 527
I1018 09:56:44.934306       1 scheduler.go:451] ScheduleAlgoTime 2.368656ms Start:2018-10-18 09:56:44.931928233 +0000 UTC m=+21.955412116 End:2018-10-18 09:56:44.934296867 +0000 UTC m=+21.957780772
I1018 09:56:44.934338       1 scheduler.go:454] Total Schedule Algo cumulative time:1.203912243s for 528
I1018 09:56:44.937272       1 scheduler.go:451] ScheduleAlgoTime 2.339703ms Start:2018-10-18 09:56:44.934922707 +0000 UTC m=+21.958406590 End:2018-10-18 09:56:44.937262486 +0000 UTC m=+21.960746293
I1018 09:56:44.937305       1 scheduler.go:454] Total Schedule Algo cumulative time:1.206251946s for 529
I1018 09:56:44.940241       1 scheduler.go:451] ScheduleAlgoTime 2.257518ms Start:2018-10-18 09:56:44.937974476 +0000 UTC m=+21.961458371 End:2018-10-18 09:56:44.940232082 +0000 UTC m=+21.963715889
I1018 09:56:44.940274       1 scheduler.go:454] Total Schedule Algo cumulative time:1.208509464s for 530
I1018 09:56:44.942576       1 scheduler.go:451] ScheduleAlgoTime 2.037932ms Start:2018-10-18 09:56:44.940529643 +0000 UTC m=+21.964013541 End:2018-10-18 09:56:44.942567666 +0000 UTC m=+21.966051473
I1018 09:56:44.942610       1 scheduler.go:454] Total Schedule Algo cumulative time:1.210547396s for 531
I1018 09:56:44.945113       1 scheduler.go:451] ScheduleAlgoTime 2.168711ms Start:2018-10-18 09:56:44.942936408 +0000 UTC m=+21.966420309 End:2018-10-18 09:56:44.945105166 +0000 UTC m=+21.968589020
I1018 09:56:44.945145       1 scheduler.go:454] Total Schedule Algo cumulative time:1.212716107s for 532
I1018 09:56:44.947647       1 scheduler.go:451] ScheduleAlgoTime 2.138446ms Start:2018-10-18 09:56:44.94549417 +0000 UTC m=+21.968978090 End:2018-10-18 09:56:44.947632718 +0000 UTC m=+21.971116536
I1018 09:56:44.947714       1 scheduler.go:454] Total Schedule Algo cumulative time:1.214854553s for 533
I1018 09:56:44.950350       1 scheduler.go:451] ScheduleAlgoTime 2.33622ms Start:2018-10-18 09:56:44.948003132 +0000 UTC m=+21.971487008 End:2018-10-18 09:56:44.950339368 +0000 UTC m=+21.973823228
I1018 09:56:44.950400       1 scheduler.go:454] Total Schedule Algo cumulative time:1.217190773s for 534
I1018 09:56:44.953013       1 scheduler.go:451] ScheduleAlgoTime 2.407204ms Start:2018-10-18 09:56:44.95059314 +0000 UTC m=+21.974077030 End:2018-10-18 09:56:44.953000308 +0000 UTC m=+21.976484234
I1018 09:56:44.953051       1 scheduler.go:454] Total Schedule Algo cumulative time:1.219597977s for 535
I1018 09:56:44.955330       1 scheduler.go:451] ScheduleAlgoTime 2.1026ms Start:2018-10-18 09:56:44.953216258 +0000 UTC m=+21.976700096 End:2018-10-18 09:56:44.955318893 +0000 UTC m=+21.978802696
I1018 09:56:44.955430       1 scheduler.go:454] Total Schedule Algo cumulative time:1.221700577s for 536
I1018 09:56:44.958264       1 scheduler.go:451] ScheduleAlgoTime 2.543577ms Start:2018-10-18 09:56:44.955711166 +0000 UTC m=+21.979195049 End:2018-10-18 09:56:44.958254819 +0000 UTC m=+21.981738626
I1018 09:56:44.958300       1 scheduler.go:454] Total Schedule Algo cumulative time:1.224244154s for 537
I1018 09:56:44.960638       1 scheduler.go:451] ScheduleAlgoTime 2.193753ms Start:2018-10-18 09:56:44.958435742 +0000 UTC m=+21.981919602 End:2018-10-18 09:56:44.960629551 +0000 UTC m=+21.984113355
I1018 09:56:44.960728       1 scheduler.go:454] Total Schedule Algo cumulative time:1.226437907s for 538
I1018 09:56:44.963146       1 scheduler.go:451] ScheduleAlgoTime 2.23206ms Start:2018-10-18 09:56:44.960899426 +0000 UTC m=+21.984383298 End:2018-10-18 09:56:44.96313151 +0000 UTC m=+21.986615358
I1018 09:56:44.963187       1 scheduler.go:454] Total Schedule Algo cumulative time:1.228669967s for 539
I1018 09:56:44.965856       1 scheduler.go:451] ScheduleAlgoTime 2.430834ms Start:2018-10-18 09:56:44.963415129 +0000 UTC m=+21.986899034 End:2018-10-18 09:56:44.96584606 +0000 UTC m=+21.989329868
I1018 09:56:44.965890       1 scheduler.go:454] Total Schedule Algo cumulative time:1.231100801s for 540
I1018 09:56:44.968702       1 scheduler.go:451] ScheduleAlgoTime 2.610086ms Start:2018-10-18 09:56:44.966082238 +0000 UTC m=+21.989566169 End:2018-10-18 09:56:44.968692451 +0000 UTC m=+21.992176255
I1018 09:56:44.968738       1 scheduler.go:454] Total Schedule Algo cumulative time:1.233710887s for 541
I1018 09:56:44.971500       1 scheduler.go:451] ScheduleAlgoTime 2.440314ms Start:2018-10-18 09:56:44.969049244 +0000 UTC m=+21.992533134 End:2018-10-18 09:56:44.971489596 +0000 UTC m=+21.994973448
I1018 09:56:44.971549       1 scheduler.go:454] Total Schedule Algo cumulative time:1.236151201s for 542
I1018 09:56:44.974764       1 scheduler.go:451] ScheduleAlgoTime 3.049492ms Start:2018-10-18 09:56:44.971702605 +0000 UTC m=+21.995186498 End:2018-10-18 09:56:44.974752094 +0000 UTC m=+21.998235990
I1018 09:56:44.974808       1 scheduler.go:454] Total Schedule Algo cumulative time:1.239200693s for 543
I1018 09:56:44.977760       1 scheduler.go:451] ScheduleAlgoTime 2.698755ms Start:2018-10-18 09:56:44.975050304 +0000 UTC m=+21.998534227 End:2018-10-18 09:56:44.977749173 +0000 UTC m=+22.001232982
I1018 09:56:44.977842       1 scheduler.go:454] Total Schedule Algo cumulative time:1.241899448s for 544
I1018 09:56:44.980511       1 scheduler.go:451] ScheduleAlgoTime 2.219126ms Start:2018-10-18 09:56:44.978279487 +0000 UTC m=+22.001763379 End:2018-10-18 09:56:44.980498664 +0000 UTC m=+22.003982505
I1018 09:56:44.980552       1 scheduler.go:454] Total Schedule Algo cumulative time:1.244118574s for 545
I1018 09:56:44.983002       1 scheduler.go:451] ScheduleAlgoTime 2.030233ms Start:2018-10-18 09:56:44.980962758 +0000 UTC m=+22.004446620 End:2018-10-18 09:56:44.98299305 +0000 UTC m=+22.006476853
I1018 09:56:44.983038       1 scheduler.go:454] Total Schedule Algo cumulative time:1.246148807s for 546
I1018 09:56:44.985381       1 scheduler.go:451] ScheduleAlgoTime 1.988834ms Start:2018-10-18 09:56:44.983383831 +0000 UTC m=+22.006867765 End:2018-10-18 09:56:44.985372794 +0000 UTC m=+22.008856599
I1018 09:56:44.985412       1 scheduler.go:454] Total Schedule Algo cumulative time:1.248137641s for 547
I1018 09:56:44.987796       1 scheduler.go:451] ScheduleAlgoTime 2.169339ms Start:2018-10-18 09:56:44.985619783 +0000 UTC m=+22.009103600 End:2018-10-18 09:56:44.987789123 +0000 UTC m=+22.011272939
I1018 09:56:44.987825       1 scheduler.go:454] Total Schedule Algo cumulative time:1.25030698s for 548
I1018 09:56:44.990204       1 scheduler.go:451] ScheduleAlgoTime 2.186315ms Start:2018-10-18 09:56:44.988008615 +0000 UTC m=+22.011492518 End:2018-10-18 09:56:44.990195028 +0000 UTC m=+22.013678833
I1018 09:56:44.990237       1 scheduler.go:454] Total Schedule Algo cumulative time:1.252493295s for 549
I1018 09:56:44.992506       1 scheduler.go:451] ScheduleAlgoTime 2.018533ms Start:2018-10-18 09:56:44.990479268 +0000 UTC m=+22.013963156 End:2018-10-18 09:56:44.992497885 +0000 UTC m=+22.015981689
I1018 09:56:44.992540       1 scheduler.go:454] Total Schedule Algo cumulative time:1.254511828s for 550
I1018 09:56:44.994964       1 scheduler.go:451] ScheduleAlgoTime 2.13806ms Start:2018-10-18 09:56:44.992818572 +0000 UTC m=+22.016302446 End:2018-10-18 09:56:44.994956705 +0000 UTC m=+22.018440506
I1018 09:56:44.994992       1 scheduler.go:454] Total Schedule Algo cumulative time:1.256649888s for 551
I1018 09:56:44.997188       1 scheduler.go:451] ScheduleAlgoTime 1.886112ms Start:2018-10-18 09:56:44.995294033 +0000 UTC m=+22.018777938 End:2018-10-18 09:56:44.997180242 +0000 UTC m=+22.020664050
I1018 09:56:44.997216       1 scheduler.go:454] Total Schedule Algo cumulative time:1.258536s for 552
I1018 09:56:44.999405       1 scheduler.go:451] ScheduleAlgoTime 1.945798ms Start:2018-10-18 09:56:44.997453214 +0000 UTC m=+22.020937134 End:2018-10-18 09:56:44.999399124 +0000 UTC m=+22.022882932
I1018 09:56:44.999433       1 scheduler.go:454] Total Schedule Algo cumulative time:1.260481798s for 553
I1018 09:56:45.001834       1 scheduler.go:451] ScheduleAlgoTime 2.223665ms Start:2018-10-18 09:56:44.999596903 +0000 UTC m=+22.023080830 End:2018-10-18 09:56:45.001820671 +0000 UTC m=+22.025304495
I1018 09:56:45.001965       1 scheduler.go:454] Total Schedule Algo cumulative time:1.262705463s for 554
I1018 09:56:45.004252       1 scheduler.go:451] ScheduleAlgoTime 2.055524ms Start:2018-10-18 09:56:45.002188985 +0000 UTC m=+22.025672869 End:2018-10-18 09:56:45.004244592 +0000 UTC m=+22.027728393
I1018 09:56:45.004280       1 scheduler.go:454] Total Schedule Algo cumulative time:1.264760987s for 555
I1018 09:56:45.007005       1 scheduler.go:451] ScheduleAlgoTime 2.465765ms Start:2018-10-18 09:56:45.004528886 +0000 UTC m=+22.028012803 End:2018-10-18 09:56:45.006994763 +0000 UTC m=+22.030478568
I1018 09:56:45.007043       1 scheduler.go:454] Total Schedule Algo cumulative time:1.267226752s for 556
I1018 09:56:45.009833       1 scheduler.go:451] ScheduleAlgoTime 2.524555ms Start:2018-10-18 09:56:45.007298633 +0000 UTC m=+22.030782514 End:2018-10-18 09:56:45.009823266 +0000 UTC m=+22.033307069
I1018 09:56:45.009865       1 scheduler.go:454] Total Schedule Algo cumulative time:1.269751307s for 557
I1018 09:56:45.012500       1 scheduler.go:451] ScheduleAlgoTime 2.376779ms Start:2018-10-18 09:56:45.010113771 +0000 UTC m=+22.033597662 End:2018-10-18 09:56:45.01249063 +0000 UTC m=+22.035974441
I1018 09:56:45.012529       1 scheduler.go:454] Total Schedule Algo cumulative time:1.272128086s for 558
I1018 09:56:45.015324       1 scheduler.go:451] ScheduleAlgoTime 2.402582ms Start:2018-10-18 09:56:45.012911751 +0000 UTC m=+22.036395652 End:2018-10-18 09:56:45.015314432 +0000 UTC m=+22.038798234
I1018 09:56:45.015361       1 scheduler.go:454] Total Schedule Algo cumulative time:1.274530668s for 559
I1018 09:56:45.018626       1 scheduler.go:451] ScheduleAlgoTime 2.920619ms Start:2018-10-18 09:56:45.01569543 +0000 UTC m=+22.039179333 End:2018-10-18 09:56:45.018616148 +0000 UTC m=+22.042099952
I1018 09:56:45.018657       1 scheduler.go:454] Total Schedule Algo cumulative time:1.277451287s for 560
I1018 09:56:45.026309       1 scheduler.go:451] ScheduleAlgoTime 6.126223ms Start:2018-10-18 09:56:45.020067417 +0000 UTC m=+22.043551257 End:2018-10-18 09:56:45.026193538 +0000 UTC m=+22.049677480
I1018 09:56:45.026358       1 scheduler.go:454] Total Schedule Algo cumulative time:1.28357751s for 561
I1018 09:56:45.029039       1 scheduler.go:451] ScheduleAlgoTime 2.441634ms Start:2018-10-18 09:56:45.026588491 +0000 UTC m=+22.050072379 End:2018-10-18 09:56:45.029030207 +0000 UTC m=+22.052514013
I1018 09:56:45.029156       1 scheduler.go:454] Total Schedule Algo cumulative time:1.286019144s for 562
I1018 09:56:45.031341       1 scheduler.go:451] ScheduleAlgoTime 2.090507ms Start:2018-10-18 09:56:45.029236233 +0000 UTC m=+22.052720072 End:2018-10-18 09:56:45.031326772 +0000 UTC m=+22.054810579
I1018 09:56:45.031378       1 scheduler.go:454] Total Schedule Algo cumulative time:1.288109651s for 563
I1018 09:56:45.034071       1 scheduler.go:451] ScheduleAlgoTime 2.558265ms Start:2018-10-18 09:56:45.03150286 +0000 UTC m=+22.054986671 End:2018-10-18 09:56:45.034061132 +0000 UTC m=+22.057544936
I1018 09:56:45.034103       1 scheduler.go:454] Total Schedule Algo cumulative time:1.290667916s for 564
I1018 09:56:45.036650       1 scheduler.go:451] ScheduleAlgoTime 2.05186ms Start:2018-10-18 09:56:45.034588557 +0000 UTC m=+22.058072479 End:2018-10-18 09:56:45.036640536 +0000 UTC m=+22.060124339
I1018 09:56:45.036730       1 scheduler.go:454] Total Schedule Algo cumulative time:1.292719776s for 565
I1018 09:56:45.039059       1 scheduler.go:451] ScheduleAlgoTime 2.105396ms Start:2018-10-18 09:56:45.036943826 +0000 UTC m=+22.060427715 End:2018-10-18 09:56:45.039049302 +0000 UTC m=+22.062533111
I1018 09:56:45.039099       1 scheduler.go:454] Total Schedule Algo cumulative time:1.294825172s for 566
I1018 09:56:45.041619       1 scheduler.go:451] ScheduleAlgoTime 2.379132ms Start:2018-10-18 09:56:45.039231039 +0000 UTC m=+22.062714954 End:2018-10-18 09:56:45.041610285 +0000 UTC m=+22.065094086
I1018 09:56:45.041696       1 scheduler.go:454] Total Schedule Algo cumulative time:1.297204304s for 567
I1018 09:56:45.044239       1 scheduler.go:451] ScheduleAlgoTime 2.192775ms Start:2018-10-18 09:56:45.042039271 +0000 UTC m=+22.065523114 End:2018-10-18 09:56:45.044232085 +0000 UTC m=+22.067715889
I1018 09:56:45.044280       1 scheduler.go:454] Total Schedule Algo cumulative time:1.299397079s for 568
I1018 09:56:45.046698       1 scheduler.go:451] ScheduleAlgoTime 2.172768ms Start:2018-10-18 09:56:45.044478845 +0000 UTC m=+22.067962751 End:2018-10-18 09:56:45.046651712 +0000 UTC m=+22.070135519
I1018 09:56:45.046753       1 scheduler.go:454] Total Schedule Algo cumulative time:1.301569847s for 569
I1018 09:56:45.049178       1 scheduler.go:451] ScheduleAlgoTime 2.1264ms Start:2018-10-18 09:56:45.047044213 +0000 UTC m=+22.070528101 End:2018-10-18 09:56:45.049170693 +0000 UTC m=+22.072654501
I1018 09:56:45.049208       1 scheduler.go:454] Total Schedule Algo cumulative time:1.303696247s for 570
I1018 09:56:45.051650       1 scheduler.go:451] ScheduleAlgoTime 2.219059ms Start:2018-10-18 09:56:45.049413891 +0000 UTC m=+22.072897811 End:2018-10-18 09:56:45.051633063 +0000 UTC m=+22.075116870
I1018 09:56:45.051799       1 scheduler.go:454] Total Schedule Algo cumulative time:1.305915306s for 571
I1018 09:56:45.054507       1 scheduler.go:451] ScheduleAlgoTime 2.447748ms Start:2018-10-18 09:56:45.052051314 +0000 UTC m=+22.075535183 End:2018-10-18 09:56:45.054499128 +0000 UTC m=+22.077982931
I1018 09:56:45.054539       1 scheduler.go:454] Total Schedule Algo cumulative time:1.308363054s for 572
I1018 09:56:45.057835       1 scheduler.go:451] ScheduleAlgoTime 3.07761ms Start:2018-10-18 09:56:45.05474625 +0000 UTC m=+22.078230165 End:2018-10-18 09:56:45.057823824 +0000 UTC m=+22.081307775
I1018 09:56:45.057885       1 scheduler.go:454] Total Schedule Algo cumulative time:1.311440664s for 573
I1018 09:56:45.060381       1 scheduler.go:451] ScheduleAlgoTime 2.177075ms Start:2018-10-18 09:56:45.058195443 +0000 UTC m=+22.081679275 End:2018-10-18 09:56:45.060372547 +0000 UTC m=+22.083856350
I1018 09:56:45.060412       1 scheduler.go:454] Total Schedule Algo cumulative time:1.313617739s for 574
I1018 09:56:45.063079       1 scheduler.go:451] ScheduleAlgoTime 2.177574ms Start:2018-10-18 09:56:45.06088773 +0000 UTC m=+22.084371630 End:2018-10-18 09:56:45.063065398 +0000 UTC m=+22.086549204
I1018 09:56:45.063115       1 scheduler.go:454] Total Schedule Algo cumulative time:1.315795313s for 575
I1018 09:56:45.066034       1 scheduler.go:451] ScheduleAlgoTime 2.671177ms Start:2018-10-18 09:56:45.063351405 +0000 UTC m=+22.086835300 End:2018-10-18 09:56:45.066022666 +0000 UTC m=+22.089506477
I1018 09:56:45.066079       1 scheduler.go:454] Total Schedule Algo cumulative time:1.31846649s for 576
I1018 09:56:45.068557       1 scheduler.go:451] ScheduleAlgoTime 2.152309ms Start:2018-10-18 09:56:45.066398165 +0000 UTC m=+22.089882045 End:2018-10-18 09:56:45.068550527 +0000 UTC m=+22.092034354
I1018 09:56:45.068592       1 scheduler.go:454] Total Schedule Algo cumulative time:1.320618799s for 577
I1018 09:56:45.071007       1 scheduler.go:451] ScheduleAlgoTime 2.269409ms Start:2018-10-18 09:56:45.068727806 +0000 UTC m=+22.092211653 End:2018-10-18 09:56:45.070997251 +0000 UTC m=+22.094481062
I1018 09:56:45.071045       1 scheduler.go:454] Total Schedule Algo cumulative time:1.322888208s for 578
I1018 09:56:45.073899       1 scheduler.go:451] ScheduleAlgoTime 2.551965ms Start:2018-10-18 09:56:45.071333615 +0000 UTC m=+22.094817532 End:2018-10-18 09:56:45.073885582 +0000 UTC m=+22.097369497
I1018 09:56:45.073946       1 scheduler.go:454] Total Schedule Algo cumulative time:1.325440173s for 579
I1018 09:56:45.076250       1 scheduler.go:451] ScheduleAlgoTime 2.033716ms Start:2018-10-18 09:56:45.074208153 +0000 UTC m=+22.097692038 End:2018-10-18 09:56:45.07624195 +0000 UTC m=+22.099725754
I1018 09:56:45.076284       1 scheduler.go:454] Total Schedule Algo cumulative time:1.327473889s for 580
I1018 09:56:45.079049       1 scheduler.go:451] ScheduleAlgoTime 2.16581ms Start:2018-10-18 09:56:45.076872843 +0000 UTC m=+22.100356721 End:2018-10-18 09:56:45.079038727 +0000 UTC m=+22.102522531
I1018 09:56:45.079085       1 scheduler.go:454] Total Schedule Algo cumulative time:1.329639699s for 581
I1018 09:56:45.081544       1 scheduler.go:451] ScheduleAlgoTime 2.259573ms Start:2018-10-18 09:56:45.079276182 +0000 UTC m=+22.102760079 End:2018-10-18 09:56:45.081535845 +0000 UTC m=+22.105019652
I1018 09:56:45.081576       1 scheduler.go:454] Total Schedule Algo cumulative time:1.331899272s for 582
I1018 09:56:45.083655       1 scheduler.go:451] ScheduleAlgoTime 1.891307ms Start:2018-10-18 09:56:45.081755979 +0000 UTC m=+22.105239906 End:2018-10-18 09:56:45.083647409 +0000 UTC m=+22.107131213
I1018 09:56:45.083734       1 scheduler.go:454] Total Schedule Algo cumulative time:1.333790579s for 583
I1018 09:56:45.086064       1 scheduler.go:451] ScheduleAlgoTime 2.175457ms Start:2018-10-18 09:56:45.083875771 +0000 UTC m=+22.107359575 End:2018-10-18 09:56:45.086051181 +0000 UTC m=+22.109535032
I1018 09:56:45.086097       1 scheduler.go:454] Total Schedule Algo cumulative time:1.335966036s for 584
I1018 09:56:45.088369       1 scheduler.go:451] ScheduleAlgoTime 1.979459ms Start:2018-10-18 09:56:45.086384198 +0000 UTC m=+22.109868072 End:2018-10-18 09:56:45.088363728 +0000 UTC m=+22.111847531
I1018 09:56:45.088399       1 scheduler.go:454] Total Schedule Algo cumulative time:1.337945495s for 585
I1018 09:56:45.090513       1 scheduler.go:451] ScheduleAlgoTime 1.898296ms Start:2018-10-18 09:56:45.088607381 +0000 UTC m=+22.112091268 End:2018-10-18 09:56:45.090505762 +0000 UTC m=+22.113989564
I1018 09:56:45.090542       1 scheduler.go:454] Total Schedule Algo cumulative time:1.339843791s for 586
I1018 09:56:45.092622       1 scheduler.go:451] ScheduleAlgoTime 1.847916ms Start:2018-10-18 09:56:45.090767498 +0000 UTC m=+22.114251386 End:2018-10-18 09:56:45.0926155 +0000 UTC m=+22.116099302
I1018 09:56:45.092652       1 scheduler.go:454] Total Schedule Algo cumulative time:1.341691707s for 587
I1018 09:56:45.094989       1 scheduler.go:451] ScheduleAlgoTime 2.210085ms Start:2018-10-18 09:56:45.092765356 +0000 UTC m=+22.116249161 End:2018-10-18 09:56:45.094975396 +0000 UTC m=+22.118459246
I1018 09:56:45.095027       1 scheduler.go:454] Total Schedule Algo cumulative time:1.343901792s for 588
I1018 09:56:45.097570       1 scheduler.go:451] ScheduleAlgoTime 2.132967ms Start:2018-10-18 09:56:45.095431084 +0000 UTC m=+22.118914949 End:2018-10-18 09:56:45.097564111 +0000 UTC m=+22.121047916
I1018 09:56:45.097640       1 scheduler.go:454] Total Schedule Algo cumulative time:1.346034759s for 589
I1018 09:56:45.099838       1 scheduler.go:451] ScheduleAlgoTime 1.87876ms Start:2018-10-18 09:56:45.09795039 +0000 UTC m=+22.121434285 End:2018-10-18 09:56:45.099829238 +0000 UTC m=+22.123313045
I1018 09:56:45.099920       1 scheduler.go:454] Total Schedule Algo cumulative time:1.347913519s for 590
I1018 09:56:45.102126       1 scheduler.go:451] ScheduleAlgoTime 1.988859ms Start:2018-10-18 09:56:45.100127743 +0000 UTC m=+22.123611612 End:2018-10-18 09:56:45.102116661 +0000 UTC m=+22.125600471
I1018 09:56:45.102157       1 scheduler.go:454] Total Schedule Algo cumulative time:1.349902378s for 591
I1018 09:56:45.104745       1 scheduler.go:451] ScheduleAlgoTime 2.205025ms Start:2018-10-18 09:56:45.102528179 +0000 UTC m=+22.126012059 End:2018-10-18 09:56:45.104733152 +0000 UTC m=+22.128217084
I1018 09:56:45.104789       1 scheduler.go:454] Total Schedule Algo cumulative time:1.352107403s for 592
I1018 09:56:45.107708       1 scheduler.go:451] ScheduleAlgoTime 2.624488ms Start:2018-10-18 09:56:45.105075539 +0000 UTC m=+22.128559424 End:2018-10-18 09:56:45.10770011 +0000 UTC m=+22.131183912
I1018 09:56:45.107739       1 scheduler.go:454] Total Schedule Algo cumulative time:1.354731891s for 593
I1018 09:56:45.109984       1 scheduler.go:451] ScheduleAlgoTime 2.107305ms Start:2018-10-18 09:56:45.107869453 +0000 UTC m=+22.131353350 End:2018-10-18 09:56:45.109976847 +0000 UTC m=+22.133460655
I1018 09:56:45.110013       1 scheduler.go:454] Total Schedule Algo cumulative time:1.356839196s for 594
I1018 09:56:45.112874       1 scheduler.go:451] ScheduleAlgoTime 2.632594ms Start:2018-10-18 09:56:45.110233254 +0000 UTC m=+22.133717158 End:2018-10-18 09:56:45.112865943 +0000 UTC m=+22.136349752
I1018 09:56:45.112904       1 scheduler.go:454] Total Schedule Algo cumulative time:1.35947179s for 595
I1018 09:56:45.115375       1 scheduler.go:451] ScheduleAlgoTime 2.2716ms Start:2018-10-18 09:56:45.113094023 +0000 UTC m=+22.136577859 End:2018-10-18 09:56:45.11536563 +0000 UTC m=+22.138849459
I1018 09:56:45.115425       1 scheduler.go:454] Total Schedule Algo cumulative time:1.36174339s for 596
I1018 09:56:45.118541       1 scheduler.go:451] ScheduleAlgoTime 2.798765ms Start:2018-10-18 09:56:45.115732544 +0000 UTC m=+22.139216387 End:2018-10-18 09:56:45.118531345 +0000 UTC m=+22.142015152
I1018 09:56:45.118574       1 scheduler.go:454] Total Schedule Algo cumulative time:1.364542155s for 597
I1018 09:56:45.121069       1 scheduler.go:451] ScheduleAlgoTime 2.170426ms Start:2018-10-18 09:56:45.118893354 +0000 UTC m=+22.142377228 End:2018-10-18 09:56:45.121063852 +0000 UTC m=+22.144547654
I1018 09:56:45.121097       1 scheduler.go:454] Total Schedule Algo cumulative time:1.366712581s for 598
I1018 09:56:45.123298       1 scheduler.go:451] ScheduleAlgoTime 2.067298ms Start:2018-10-18 09:56:45.121221261 +0000 UTC m=+22.144705066 End:2018-10-18 09:56:45.123288561 +0000 UTC m=+22.146772364
I1018 09:56:45.123328       1 scheduler.go:454] Total Schedule Algo cumulative time:1.368779879s for 599
I1018 09:56:45.125414       1 scheduler.go:451] ScheduleAlgoTime 1.803244ms Start:2018-10-18 09:56:45.12360447 +0000 UTC m=+22.147088350 End:2018-10-18 09:56:45.125407791 +0000 UTC m=+22.148891594
I1018 09:56:45.125446       1 scheduler.go:454] Total Schedule Algo cumulative time:1.370583123s for 600
I1018 09:56:45.127551       1 scheduler.go:451] ScheduleAlgoTime 1.903219ms Start:2018-10-18 09:56:45.12564007 +0000 UTC m=+22.149123952 End:2018-10-18 09:56:45.127543368 +0000 UTC m=+22.151027171
I1018 09:56:45.127582       1 scheduler.go:454] Total Schedule Algo cumulative time:1.372486342s for 601
I1018 09:56:45.130132       1 scheduler.go:451] ScheduleAlgoTime 2.3222ms Start:2018-10-18 09:56:45.12780336 +0000 UTC m=+22.151287259 End:2018-10-18 09:56:45.130125655 +0000 UTC m=+22.153609459
I1018 09:56:45.130160       1 scheduler.go:454] Total Schedule Algo cumulative time:1.374808542s for 602
I1018 09:56:45.132163       1 scheduler.go:451] ScheduleAlgoTime 1.860565ms Start:2018-10-18 09:56:45.130297388 +0000 UTC m=+22.153781281 End:2018-10-18 09:56:45.132158044 +0000 UTC m=+22.155641846
I1018 09:56:45.132189       1 scheduler.go:454] Total Schedule Algo cumulative time:1.376669107s for 603
I1018 09:56:45.134416       1 scheduler.go:451] ScheduleAlgoTime 2.014504ms Start:2018-10-18 09:56:45.132391418 +0000 UTC m=+22.155875286 End:2018-10-18 09:56:45.134405987 +0000 UTC m=+22.157889790
I1018 09:56:45.134449       1 scheduler.go:454] Total Schedule Algo cumulative time:1.378683611s for 604
I1018 09:56:45.136891       1 scheduler.go:451] ScheduleAlgoTime 2.030525ms Start:2018-10-18 09:56:45.134852976 +0000 UTC m=+22.158336839 End:2018-10-18 09:56:45.136883558 +0000 UTC m=+22.160367364
I1018 09:56:45.136919       1 scheduler.go:454] Total Schedule Algo cumulative time:1.380714136s for 605
I1018 09:56:45.139448       1 scheduler.go:451] ScheduleAlgoTime 2.063484ms Start:2018-10-18 09:56:45.137374138 +0000 UTC m=+22.160858050 End:2018-10-18 09:56:45.139437728 +0000 UTC m=+22.162921534
I1018 09:56:45.139482       1 scheduler.go:454] Total Schedule Algo cumulative time:1.38277762s for 606
I1018 09:56:45.141697       1 scheduler.go:451] ScheduleAlgoTime 1.973962ms Start:2018-10-18 09:56:45.139681979 +0000 UTC m=+22.163165848 End:2018-10-18 09:56:45.141656003 +0000 UTC m=+22.165139810
I1018 09:56:45.141761       1 scheduler.go:454] Total Schedule Algo cumulative time:1.384751582s for 607
I1018 09:56:45.144277       1 scheduler.go:451] ScheduleAlgoTime 2.33508ms Start:2018-10-18 09:56:45.141933905 +0000 UTC m=+22.165417782 End:2018-10-18 09:56:45.144269058 +0000 UTC m=+22.167752862
I1018 09:56:45.144306       1 scheduler.go:454] Total Schedule Algo cumulative time:1.387086662s for 608
I1018 09:56:45.146506       1 scheduler.go:451] ScheduleAlgoTime 2.020638ms Start:2018-10-18 09:56:45.14447754 +0000 UTC m=+22.167961345 End:2018-10-18 09:56:45.146498179 +0000 UTC m=+22.169981983
I1018 09:56:45.146538       1 scheduler.go:454] Total Schedule Algo cumulative time:1.3891073s for 609
I1018 09:56:45.149224       1 scheduler.go:451] ScheduleAlgoTime 2.389379ms Start:2018-10-18 09:56:45.146825245 +0000 UTC m=+22.170309154 End:2018-10-18 09:56:45.149214713 +0000 UTC m=+22.172698533
I1018 09:56:45.149269       1 scheduler.go:454] Total Schedule Algo cumulative time:1.391496679s for 610
I1018 09:56:45.151471       1 scheduler.go:451] ScheduleAlgoTime 1.981399ms Start:2018-10-18 09:56:45.149481008 +0000 UTC m=+22.172964876 End:2018-10-18 09:56:45.151462467 +0000 UTC m=+22.174946275
I1018 09:56:45.151502       1 scheduler.go:454] Total Schedule Algo cumulative time:1.393478078s for 611
I1018 09:56:45.154034       1 scheduler.go:451] ScheduleAlgoTime 2.297478ms Start:2018-10-18 09:56:45.151726326 +0000 UTC m=+22.175210202 End:2018-10-18 09:56:45.154023843 +0000 UTC m=+22.177507680
I1018 09:56:45.154094       1 scheduler.go:454] Total Schedule Algo cumulative time:1.395775556s for 612
I1018 09:56:45.156325       1 scheduler.go:451] ScheduleAlgoTime 2.100727ms Start:2018-10-18 09:56:45.154214783 +0000 UTC m=+22.177698677 End:2018-10-18 09:56:45.156315601 +0000 UTC m=+22.179799404
I1018 09:56:45.156369       1 scheduler.go:454] Total Schedule Algo cumulative time:1.397876283s for 613
I1018 09:56:45.158971       1 scheduler.go:451] ScheduleAlgoTime 2.459536ms Start:2018-10-18 09:56:45.156501944 +0000 UTC m=+22.179985748 End:2018-10-18 09:56:45.158961479 +0000 UTC m=+22.182445284
I1018 09:56:45.159010       1 scheduler.go:454] Total Schedule Algo cumulative time:1.400335819s for 614
I1018 09:56:45.161735       1 scheduler.go:451] ScheduleAlgoTime 2.566614ms Start:2018-10-18 09:56:45.159159693 +0000 UTC m=+22.182643512 End:2018-10-18 09:56:45.161726287 +0000 UTC m=+22.185210126
I1018 09:56:45.161768       1 scheduler.go:454] Total Schedule Algo cumulative time:1.402902433s for 615
I1018 09:56:45.167754       1 scheduler.go:451] ScheduleAlgoTime 5.813582ms Start:2018-10-18 09:56:45.161928003 +0000 UTC m=+22.185411889 End:2018-10-18 09:56:45.16774164 +0000 UTC m=+22.191225471
I1018 09:56:45.167810       1 scheduler.go:454] Total Schedule Algo cumulative time:1.408716015s for 616
I1018 09:56:45.173046       1 scheduler.go:451] ScheduleAlgoTime 4.553401ms Start:2018-10-18 09:56:45.168484106 +0000 UTC m=+22.191968007 End:2018-10-18 09:56:45.173037603 +0000 UTC m=+22.196521408
I1018 09:56:45.173079       1 scheduler.go:454] Total Schedule Algo cumulative time:1.413269416s for 617
I1018 09:56:45.175558       1 scheduler.go:451] ScheduleAlgoTime 2.17444ms Start:2018-10-18 09:56:45.173373113 +0000 UTC m=+22.196856993 End:2018-10-18 09:56:45.175547622 +0000 UTC m=+22.199031433
I1018 09:56:45.175599       1 scheduler.go:454] Total Schedule Algo cumulative time:1.415443856s for 618
I1018 09:56:45.177843       1 scheduler.go:451] ScheduleAlgoTime 2.095068ms Start:2018-10-18 09:56:45.175738569 +0000 UTC m=+22.199222465 End:2018-10-18 09:56:45.177833724 +0000 UTC m=+22.201317533
I1018 09:56:45.177881       1 scheduler.go:454] Total Schedule Algo cumulative time:1.417538924s for 619
I1018 09:56:45.180731       1 scheduler.go:451] ScheduleAlgoTime 2.501825ms Start:2018-10-18 09:56:45.178220004 +0000 UTC m=+22.201703911 End:2018-10-18 09:56:45.180721929 +0000 UTC m=+22.204205736
I1018 09:56:45.180776       1 scheduler.go:454] Total Schedule Algo cumulative time:1.420040749s for 620
I1018 09:56:45.183488       1 scheduler.go:451] ScheduleAlgoTime 2.400798ms Start:2018-10-18 09:56:45.181075865 +0000 UTC m=+22.204559747 End:2018-10-18 09:56:45.183476514 +0000 UTC m=+22.206960545
I1018 09:56:45.183530       1 scheduler.go:454] Total Schedule Algo cumulative time:1.422441547s for 621
I1018 09:56:45.186052       1 scheduler.go:451] ScheduleAlgoTime 2.279242ms Start:2018-10-18 09:56:45.183762406 +0000 UTC m=+22.207246321 End:2018-10-18 09:56:45.186041635 +0000 UTC m=+22.209525563
I1018 09:56:45.186098       1 scheduler.go:454] Total Schedule Algo cumulative time:1.424720789s for 622
I1018 09:56:45.188642       1 scheduler.go:451] ScheduleAlgoTime 2.358015ms Start:2018-10-18 09:56:45.186273842 +0000 UTC m=+22.209757736 End:2018-10-18 09:56:45.188631927 +0000 UTC m=+22.212115751
I1018 09:56:45.188753       1 scheduler.go:454] Total Schedule Algo cumulative time:1.427078804s for 623
I1018 09:56:45.191178       1 scheduler.go:451] ScheduleAlgoTime 2.157894ms Start:2018-10-18 09:56:45.189010424 +0000 UTC m=+22.212494320 End:2018-10-18 09:56:45.191168409 +0000 UTC m=+22.214652214
I1018 09:56:45.191214       1 scheduler.go:454] Total Schedule Algo cumulative time:1.429236698s for 624
I1018 09:56:45.193876       1 scheduler.go:451] ScheduleAlgoTime 2.446947ms Start:2018-10-18 09:56:45.191415296 +0000 UTC m=+22.214899183 End:2018-10-18 09:56:45.193862311 +0000 UTC m=+22.217346130
I1018 09:56:45.193920       1 scheduler.go:454] Total Schedule Algo cumulative time:1.431683645s for 625
I1018 09:56:45.196116       1 scheduler.go:451] ScheduleAlgoTime 1.9811ms Start:2018-10-18 09:56:45.194125812 +0000 UTC m=+22.217609718 End:2018-10-18 09:56:45.196107016 +0000 UTC m=+22.219590818
I1018 09:56:45.196156       1 scheduler.go:454] Total Schedule Algo cumulative time:1.433664745s for 626
I1018 09:56:45.198991       1 scheduler.go:451] ScheduleAlgoTime 2.617305ms Start:2018-10-18 09:56:45.196363643 +0000 UTC m=+22.219847547 End:2018-10-18 09:56:45.198981048 +0000 UTC m=+22.222464852
I1018 09:56:45.199038       1 scheduler.go:454] Total Schedule Algo cumulative time:1.43628205s for 627
I1018 09:56:45.201499       1 scheduler.go:451] ScheduleAlgoTime 2.14987ms Start:2018-10-18 09:56:45.199340639 +0000 UTC m=+22.222824550 End:2018-10-18 09:56:45.201490612 +0000 UTC m=+22.224974420
I1018 09:56:45.201530       1 scheduler.go:454] Total Schedule Algo cumulative time:1.43843192s for 628
I1018 09:56:45.203964       1 scheduler.go:451] ScheduleAlgoTime 2.187936ms Start:2018-10-18 09:56:45.201764064 +0000 UTC m=+22.225247916 End:2018-10-18 09:56:45.203951936 +0000 UTC m=+22.227435852
I1018 09:56:45.204004       1 scheduler.go:454] Total Schedule Algo cumulative time:1.440619856s for 629
I1018 09:56:45.206167       1 scheduler.go:451] ScheduleAlgoTime 1.986521ms Start:2018-10-18 09:56:45.204168693 +0000 UTC m=+22.227652581 End:2018-10-18 09:56:45.206155298 +0000 UTC m=+22.229639102
I1018 09:56:45.206198       1 scheduler.go:454] Total Schedule Algo cumulative time:1.442606377s for 630
I1018 09:56:45.208801       1 scheduler.go:451] ScheduleAlgoTime 2.280034ms Start:2018-10-18 09:56:45.20651367 +0000 UTC m=+22.229997568 End:2018-10-18 09:56:45.2087938 +0000 UTC m=+22.232277602
I1018 09:56:45.208836       1 scheduler.go:454] Total Schedule Algo cumulative time:1.444886411s for 631
I1018 09:56:45.211948       1 scheduler.go:451] ScheduleAlgoTime 2.914353ms Start:2018-10-18 09:56:45.209025484 +0000 UTC m=+22.232509401 End:2018-10-18 09:56:45.211939945 +0000 UTC m=+22.235423754
I1018 09:56:45.211991       1 scheduler.go:454] Total Schedule Algo cumulative time:1.447800764s for 632
I1018 09:56:45.214140       1 scheduler.go:451] ScheduleAlgoTime 1.971301ms Start:2018-10-18 09:56:45.212163001 +0000 UTC m=+22.235646875 End:2018-10-18 09:56:45.21413437 +0000 UTC m=+22.237618176
I1018 09:56:45.214169       1 scheduler.go:454] Total Schedule Algo cumulative time:1.449772065s for 633
I1018 09:56:45.217040       1 scheduler.go:451] ScheduleAlgoTime 2.622084ms Start:2018-10-18 09:56:45.214409225 +0000 UTC m=+22.237893112 End:2018-10-18 09:56:45.217031393 +0000 UTC m=+22.240515196
I1018 09:56:45.217075       1 scheduler.go:454] Total Schedule Algo cumulative time:1.452394149s for 634
I1018 09:56:45.219293       1 scheduler.go:451] ScheduleAlgoTime 2.004763ms Start:2018-10-18 09:56:45.217279881 +0000 UTC m=+22.240763775 End:2018-10-18 09:56:45.219284736 +0000 UTC m=+22.242768538
I1018 09:56:45.219330       1 scheduler.go:454] Total Schedule Algo cumulative time:1.454398912s for 635
I1018 09:56:45.221618       1 scheduler.go:451] ScheduleAlgoTime 2.082063ms Start:2018-10-18 09:56:45.219528364 +0000 UTC m=+22.243012258 End:2018-10-18 09:56:45.221610517 +0000 UTC m=+22.245094321
I1018 09:56:45.221644       1 scheduler.go:454] Total Schedule Algo cumulative time:1.456480975s for 636
I1018 09:56:45.224108       1 scheduler.go:451] ScheduleAlgoTime 2.281485ms Start:2018-10-18 09:56:45.221815849 +0000 UTC m=+22.245299709 End:2018-10-18 09:56:45.22409737 +0000 UTC m=+22.247581194
I1018 09:56:45.224170       1 scheduler.go:454] Total Schedule Algo cumulative time:1.45876246s for 637
I1018 09:56:45.226809       1 scheduler.go:451] ScheduleAlgoTime 2.345974ms Start:2018-10-18 09:56:45.224454062 +0000 UTC m=+22.247937939 End:2018-10-18 09:56:45.226800104 +0000 UTC m=+22.250283913
I1018 09:56:45.226844       1 scheduler.go:454] Total Schedule Algo cumulative time:1.461108434s for 638
I1018 09:56:45.229511       1 scheduler.go:451] ScheduleAlgoTime 2.21983ms Start:2018-10-18 09:56:45.227282216 +0000 UTC m=+22.250766029 End:2018-10-18 09:56:45.229502027 +0000 UTC m=+22.252985859
I1018 09:56:45.229540       1 scheduler.go:454] Total Schedule Algo cumulative time:1.463328264s for 639
I1018 09:56:45.231649       1 scheduler.go:451] ScheduleAlgoTime 1.853435ms Start:2018-10-18 09:56:45.229787513 +0000 UTC m=+22.253271393 End:2018-10-18 09:56:45.231640983 +0000 UTC m=+22.255124828
I1018 09:56:45.231724       1 scheduler.go:454] Total Schedule Algo cumulative time:1.465181699s for 640
I1018 09:56:45.233856       1 scheduler.go:451] ScheduleAlgoTime 1.984635ms Start:2018-10-18 09:56:45.231861456 +0000 UTC m=+22.255345321 End:2018-10-18 09:56:45.233846132 +0000 UTC m=+22.257329956
I1018 09:56:45.233894       1 scheduler.go:454] Total Schedule Algo cumulative time:1.467166334s for 641
I1018 09:56:45.235920       1 scheduler.go:451] ScheduleAlgoTime 1.872655ms Start:2018-10-18 09:56:45.234037135 +0000 UTC m=+22.257521023 End:2018-10-18 09:56:45.235909871 +0000 UTC m=+22.259393678
I1018 09:56:45.235950       1 scheduler.go:454] Total Schedule Algo cumulative time:1.469038989s for 642
I1018 09:56:45.238020       1 scheduler.go:451] ScheduleAlgoTime 1.784256ms Start:2018-10-18 09:56:45.236229207 +0000 UTC m=+22.259713063 End:2018-10-18 09:56:45.238013516 +0000 UTC m=+22.261497319
I1018 09:56:45.238049       1 scheduler.go:454] Total Schedule Algo cumulative time:1.470823245s for 643
I1018 09:56:45.240125       1 scheduler.go:451] ScheduleAlgoTime 1.871645ms Start:2018-10-18 09:56:45.238244879 +0000 UTC m=+22.261728769 End:2018-10-18 09:56:45.240116586 +0000 UTC m=+22.263600414
I1018 09:56:45.240161       1 scheduler.go:454] Total Schedule Algo cumulative time:1.47269489s for 644
I1018 09:56:45.242254       1 scheduler.go:451] ScheduleAlgoTime 1.872724ms Start:2018-10-18 09:56:45.240371965 +0000 UTC m=+22.263855857 End:2018-10-18 09:56:45.242244778 +0000 UTC m=+22.265728581
I1018 09:56:45.242286       1 scheduler.go:454] Total Schedule Algo cumulative time:1.474567614s for 645
I1018 09:56:45.244503       1 scheduler.go:451] ScheduleAlgoTime 1.928336ms Start:2018-10-18 09:56:45.242564825 +0000 UTC m=+22.266048719 End:2018-10-18 09:56:45.244493213 +0000 UTC m=+22.267977055
I1018 09:56:45.244541       1 scheduler.go:454] Total Schedule Algo cumulative time:1.47649595s for 646
I1018 09:56:45.246648       1 scheduler.go:451] ScheduleAlgoTime 1.944161ms Start:2018-10-18 09:56:45.244663224 +0000 UTC m=+22.268176385 End:2018-10-18 09:56:45.246636711 +0000 UTC m=+22.270120546
I1018 09:56:45.246711       1 scheduler.go:454] Total Schedule Algo cumulative time:1.478440111s for 647
I1018 09:56:45.249005       1 scheduler.go:451] ScheduleAlgoTime 2.044741ms Start:2018-10-18 09:56:45.246947469 +0000 UTC m=+22.270431339 End:2018-10-18 09:56:45.248992252 +0000 UTC m=+22.272476080
I1018 09:56:45.249038       1 scheduler.go:454] Total Schedule Algo cumulative time:1.480484852s for 648
I1018 09:56:45.251347       1 scheduler.go:451] ScheduleAlgoTime 2.058054ms Start:2018-10-18 09:56:45.24928159 +0000 UTC m=+22.272765436 End:2018-10-18 09:56:45.251339686 +0000 UTC m=+22.274823490
I1018 09:56:45.251377       1 scheduler.go:454] Total Schedule Algo cumulative time:1.482542906s for 649
I1018 09:56:45.253859       1 scheduler.go:451] ScheduleAlgoTime 2.223629ms Start:2018-10-18 09:56:45.251626151 +0000 UTC m=+22.275110052 End:2018-10-18 09:56:45.253849876 +0000 UTC m=+22.277333681
I1018 09:56:45.253892       1 scheduler.go:454] Total Schedule Algo cumulative time:1.484766535s for 650
I1018 09:56:45.256242       1 scheduler.go:451] ScheduleAlgoTime 2.183642ms Start:2018-10-18 09:56:45.254050488 +0000 UTC m=+22.277534375 End:2018-10-18 09:56:45.256234212 +0000 UTC m=+22.279718017
I1018 09:56:45.256275       1 scheduler.go:454] Total Schedule Algo cumulative time:1.486950177s for 651
I1018 09:56:45.258386       1 scheduler.go:451] ScheduleAlgoTime 1.841614ms Start:2018-10-18 09:56:45.256536134 +0000 UTC m=+22.280020028 End:2018-10-18 09:56:45.258377834 +0000 UTC m=+22.281861642
I1018 09:56:45.258418       1 scheduler.go:454] Total Schedule Algo cumulative time:1.488791791s for 652
I1018 09:56:45.260746       1 scheduler.go:451] ScheduleAlgoTime 2.154276ms Start:2018-10-18 09:56:45.258583885 +0000 UTC m=+22.282067761 End:2018-10-18 09:56:45.26073823 +0000 UTC m=+22.284222037
I1018 09:56:45.260775       1 scheduler.go:454] Total Schedule Algo cumulative time:1.490946067s for 653
I1018 09:56:45.263029       1 scheduler.go:451] ScheduleAlgoTime 2.071817ms Start:2018-10-18 09:56:45.260947621 +0000 UTC m=+22.284431425 End:2018-10-18 09:56:45.263019424 +0000 UTC m=+22.286503242
I1018 09:56:45.263068       1 scheduler.go:454] Total Schedule Algo cumulative time:1.493017884s for 654
I1018 09:56:45.265876       1 scheduler.go:451] ScheduleAlgoTime 2.567334ms Start:2018-10-18 09:56:45.263298417 +0000 UTC m=+22.286782308 End:2018-10-18 09:56:45.265865832 +0000 UTC m=+22.289349642
I1018 09:56:45.265916       1 scheduler.go:454] Total Schedule Algo cumulative time:1.495585218s for 655
I1018 09:56:45.268099       1 scheduler.go:451] ScheduleAlgoTime 2.067062ms Start:2018-10-18 09:56:45.2660218 +0000 UTC m=+22.289505715 End:2018-10-18 09:56:45.268088907 +0000 UTC m=+22.291572777
I1018 09:56:45.268138       1 scheduler.go:454] Total Schedule Algo cumulative time:1.49765228s for 656
I1018 09:56:45.270932       1 scheduler.go:451] ScheduleAlgoTime 2.641359ms Start:2018-10-18 09:56:45.268281815 +0000 UTC m=+22.291765743 End:2018-10-18 09:56:45.270923297 +0000 UTC m=+22.294407102
I1018 09:56:45.270974       1 scheduler.go:454] Total Schedule Algo cumulative time:1.500293639s for 657
I1018 09:56:45.273098       1 scheduler.go:451] ScheduleAlgoTime 1.970678ms Start:2018-10-18 09:56:45.271122041 +0000 UTC m=+22.294605846 End:2018-10-18 09:56:45.273092721 +0000 UTC m=+22.296576524
I1018 09:56:45.273127       1 scheduler.go:454] Total Schedule Algo cumulative time:1.502264317s for 658
I1018 09:56:45.275337       1 scheduler.go:451] ScheduleAlgoTime 1.971831ms Start:2018-10-18 09:56:45.273357524 +0000 UTC m=+22.296841412 End:2018-10-18 09:56:45.275329437 +0000 UTC m=+22.298813243
I1018 09:56:45.275367       1 scheduler.go:454] Total Schedule Algo cumulative time:1.504236148s for 659
I1018 09:56:45.277947       1 scheduler.go:451] ScheduleAlgoTime 2.179702ms Start:2018-10-18 09:56:45.275759695 +0000 UTC m=+22.299243606 End:2018-10-18 09:56:45.277939505 +0000 UTC m=+22.301423308
I1018 09:56:45.277976       1 scheduler.go:454] Total Schedule Algo cumulative time:1.50641585s for 660
I1018 09:56:45.280262       1 scheduler.go:451] ScheduleAlgoTime 1.976948ms Start:2018-10-18 09:56:45.278275158 +0000 UTC m=+22.301759063 End:2018-10-18 09:56:45.280252207 +0000 UTC m=+22.303736011
I1018 09:56:45.280290       1 scheduler.go:454] Total Schedule Algo cumulative time:1.508392798s for 661
I1018 09:56:45.282458       1 scheduler.go:451] ScheduleAlgoTime 1.966689ms Start:2018-10-18 09:56:45.280482772 +0000 UTC m=+22.303966666 End:2018-10-18 09:56:45.282449552 +0000 UTC m=+22.305933355
I1018 09:56:45.282491       1 scheduler.go:454] Total Schedule Algo cumulative time:1.510359487s for 662
I1018 09:56:45.284774       1 scheduler.go:451] ScheduleAlgoTime 1.894976ms Start:2018-10-18 09:56:45.282871866 +0000 UTC m=+22.306355717 End:2018-10-18 09:56:45.28476689 +0000 UTC m=+22.308250693
I1018 09:56:45.284803       1 scheduler.go:454] Total Schedule Algo cumulative time:1.512254463s for 663
I1018 09:56:45.287496       1 scheduler.go:451] ScheduleAlgoTime 2.40781ms Start:2018-10-18 09:56:45.285078013 +0000 UTC m=+22.308561908 End:2018-10-18 09:56:45.287485898 +0000 UTC m=+22.310969718
I1018 09:56:45.287545       1 scheduler.go:454] Total Schedule Algo cumulative time:1.514662273s for 664
I1018 09:56:45.290431       1 scheduler.go:451] ScheduleAlgoTime 2.621948ms Start:2018-10-18 09:56:45.287799951 +0000 UTC m=+22.311283836 End:2018-10-18 09:56:45.290421977 +0000 UTC m=+22.313905784
I1018 09:56:45.290464       1 scheduler.go:454] Total Schedule Algo cumulative time:1.517284221s for 665
I1018 09:56:45.293054       1 scheduler.go:451] ScheduleAlgoTime 2.447074ms Start:2018-10-18 09:56:45.290596022 +0000 UTC m=+22.314079828 End:2018-10-18 09:56:45.293043091 +0000 UTC m=+22.316526902
I1018 09:56:45.293109       1 scheduler.go:454] Total Schedule Algo cumulative time:1.519731295s for 666
I1018 09:56:45.295141       1 scheduler.go:451] ScheduleAlgoTime 1.923059ms Start:2018-10-18 09:56:45.293211044 +0000 UTC m=+22.316694887 End:2018-10-18 09:56:45.295134143 +0000 UTC m=+22.318617946
I1018 09:56:45.295172       1 scheduler.go:454] Total Schedule Algo cumulative time:1.521654354s for 667
I1018 09:56:45.297811       1 scheduler.go:451] ScheduleAlgoTime 2.401161ms Start:2018-10-18 09:56:45.295401108 +0000 UTC m=+22.318885014 End:2018-10-18 09:56:45.297802372 +0000 UTC m=+22.321286175
I1018 09:56:45.297842       1 scheduler.go:454] Total Schedule Algo cumulative time:1.524055515s for 668
I1018 09:56:45.300759       1 scheduler.go:451] ScheduleAlgoTime 2.697955ms Start:2018-10-18 09:56:45.298051147 +0000 UTC m=+22.321535048 End:2018-10-18 09:56:45.300749188 +0000 UTC m=+22.324233003
I1018 09:56:45.300794       1 scheduler.go:454] Total Schedule Algo cumulative time:1.52675347s for 669
I1018 09:56:45.303240       1 scheduler.go:451] ScheduleAlgoTime 2.227083ms Start:2018-10-18 09:56:45.301004546 +0000 UTC m=+22.324488437 End:2018-10-18 09:56:45.303231703 +0000 UTC m=+22.326715520
I1018 09:56:45.303361       1 scheduler.go:454] Total Schedule Algo cumulative time:1.528980553s for 670
I1018 09:56:45.306165       1 scheduler.go:451] ScheduleAlgoTime 2.450717ms Start:2018-10-18 09:56:45.303702664 +0000 UTC m=+22.327186557 End:2018-10-18 09:56:45.306153448 +0000 UTC m=+22.329637274
I1018 09:56:45.306205       1 scheduler.go:454] Total Schedule Algo cumulative time:1.53143127s for 671
I1018 09:56:45.309524       1 scheduler.go:451] ScheduleAlgoTime 2.874143ms Start:2018-10-18 09:56:45.306640431 +0000 UTC m=+22.330124269 End:2018-10-18 09:56:45.309514609 +0000 UTC m=+22.332998412
I1018 09:56:45.309554       1 scheduler.go:454] Total Schedule Algo cumulative time:1.534305413s for 672
I1018 09:56:45.318567       1 scheduler.go:451] ScheduleAlgoTime 8.742691ms Start:2018-10-18 09:56:45.309809548 +0000 UTC m=+22.333293455 End:2018-10-18 09:56:45.318552342 +0000 UTC m=+22.342036146
I1018 09:56:45.319489       1 scheduler.go:454] Total Schedule Algo cumulative time:1.543048104s for 673
I1018 09:56:45.322229       1 scheduler.go:451] ScheduleAlgoTime 2.58305ms Start:2018-10-18 09:56:45.319635969 +0000 UTC m=+22.343119907 End:2018-10-18 09:56:45.32221915 +0000 UTC m=+22.345702957
I1018 09:56:45.322278       1 scheduler.go:454] Total Schedule Algo cumulative time:1.545631154s for 674
I1018 09:56:45.324656       1 scheduler.go:451] ScheduleAlgoTime 2.193788ms Start:2018-10-18 09:56:45.322453174 +0000 UTC m=+22.345937058 End:2018-10-18 09:56:45.324647043 +0000 UTC m=+22.348130846
I1018 09:56:45.324778       1 scheduler.go:454] Total Schedule Algo cumulative time:1.547824942s for 675
I1018 09:56:45.327261       1 scheduler.go:451] ScheduleAlgoTime 2.219059ms Start:2018-10-18 09:56:45.325033493 +0000 UTC m=+22.348517358 End:2018-10-18 09:56:45.327252615 +0000 UTC m=+22.350736417
I1018 09:56:45.327321       1 scheduler.go:454] Total Schedule Algo cumulative time:1.550044001s for 676
I1018 09:56:45.330188       1 scheduler.go:451] ScheduleAlgoTime 2.28444ms Start:2018-10-18 09:56:45.327895295 +0000 UTC m=+22.351379215 End:2018-10-18 09:56:45.330179852 +0000 UTC m=+22.353663655
I1018 09:56:45.330240       1 scheduler.go:454] Total Schedule Algo cumulative time:1.552328441s for 677
I1018 09:56:45.332294       1 scheduler.go:451] ScheduleAlgoTime 1.845049ms Start:2018-10-18 09:56:45.330437896 +0000 UTC m=+22.353921804 End:2018-10-18 09:56:45.332283032 +0000 UTC m=+22.355766853
I1018 09:56:45.332331       1 scheduler.go:454] Total Schedule Algo cumulative time:1.55417349s for 678
I1018 09:56:45.334788       1 scheduler.go:451] ScheduleAlgoTime 2.128962ms Start:2018-10-18 09:56:45.332645 +0000 UTC m=+22.356128895 End:2018-10-18 09:56:45.334773959 +0000 UTC m=+22.358257857
I1018 09:56:45.334835       1 scheduler.go:454] Total Schedule Algo cumulative time:1.556302452s for 679
I1018 09:56:45.337211       1 scheduler.go:451] ScheduleAlgoTime 2.136842ms Start:2018-10-18 09:56:45.335065131 +0000 UTC m=+22.358549038 End:2018-10-18 09:56:45.337202072 +0000 UTC m=+22.360685880
I1018 09:56:45.337262       1 scheduler.go:454] Total Schedule Algo cumulative time:1.558439294s for 680
I1018 09:56:45.339846       1 scheduler.go:451] ScheduleAlgoTime 2.341007ms Start:2018-10-18 09:56:45.337493862 +0000 UTC m=+22.360977756 End:2018-10-18 09:56:45.339834915 +0000 UTC m=+22.363318763
I1018 09:56:45.339907       1 scheduler.go:454] Total Schedule Algo cumulative time:1.560780301s for 681
I1018 09:56:45.342272       1 scheduler.go:451] ScheduleAlgoTime 2.145496ms Start:2018-10-18 09:56:45.34011707 +0000 UTC m=+22.363600904 End:2018-10-18 09:56:45.342262595 +0000 UTC m=+22.365746400
I1018 09:56:45.342312       1 scheduler.go:454] Total Schedule Algo cumulative time:1.562925797s for 682
I1018 09:56:45.345383       1 scheduler.go:451] ScheduleAlgoTime 2.863355ms Start:2018-10-18 09:56:45.342508851 +0000 UTC m=+22.365992758 End:2018-10-18 09:56:45.345372291 +0000 UTC m=+22.368856113
I1018 09:56:45.345422       1 scheduler.go:454] Total Schedule Algo cumulative time:1.565789152s for 683
I1018 09:56:45.347769       1 scheduler.go:451] ScheduleAlgoTime 2.120477ms Start:2018-10-18 09:56:45.345635192 +0000 UTC m=+22.369119089 End:2018-10-18 09:56:45.347755759 +0000 UTC m=+22.371239566
I1018 09:56:45.347798       1 scheduler.go:454] Total Schedule Algo cumulative time:1.567909629s for 684
I1018 09:56:45.349900       1 scheduler.go:451] ScheduleAlgoTime 2.022863ms Start:2018-10-18 09:56:45.347868022 +0000 UTC m=+22.371351915 End:2018-10-18 09:56:45.34989097 +0000 UTC m=+22.373374778
I1018 09:56:45.349936       1 scheduler.go:454] Total Schedule Algo cumulative time:1.569932492s for 685
I1018 09:56:45.353041       1 scheduler.go:451] ScheduleAlgoTime 2.844898ms Start:2018-10-18 09:56:45.350187747 +0000 UTC m=+22.373671641 End:2018-10-18 09:56:45.353032736 +0000 UTC m=+22.376516539
I1018 09:56:45.353071       1 scheduler.go:454] Total Schedule Algo cumulative time:1.57277739s for 686
I1018 09:56:45.355630       1 scheduler.go:451] ScheduleAlgoTime 2.330053ms Start:2018-10-18 09:56:45.353291465 +0000 UTC m=+22.376775360 End:2018-10-18 09:56:45.355621611 +0000 UTC m=+22.379105413
I1018 09:56:45.355659       1 scheduler.go:454] Total Schedule Algo cumulative time:1.575107443s for 687
I1018 09:56:45.358099       1 scheduler.go:451] ScheduleAlgoTime 2.109248ms Start:2018-10-18 09:56:45.355981048 +0000 UTC m=+22.379464956 End:2018-10-18 09:56:45.358090312 +0000 UTC m=+22.381574204
I1018 09:56:45.358134       1 scheduler.go:454] Total Schedule Algo cumulative time:1.577216691s for 688
I1018 09:56:45.360496       1 scheduler.go:451] ScheduleAlgoTime 2.07696ms Start:2018-10-18 09:56:45.358408363 +0000 UTC m=+22.381892270 End:2018-10-18 09:56:45.360485399 +0000 UTC m=+22.383969230
I1018 09:56:45.360544       1 scheduler.go:454] Total Schedule Algo cumulative time:1.579293651s for 689
I1018 09:56:45.363217       1 scheduler.go:451] ScheduleAlgoTime 2.349291ms Start:2018-10-18 09:56:45.360860764 +0000 UTC m=+22.384344660 End:2018-10-18 09:56:45.363210147 +0000 UTC m=+22.386693951
I1018 09:56:45.363247       1 scheduler.go:454] Total Schedule Algo cumulative time:1.581642942s for 690
I1018 09:56:45.365770       1 scheduler.go:451] ScheduleAlgoTime 2.308658ms Start:2018-10-18 09:56:45.363448396 +0000 UTC m=+22.386932317 End:2018-10-18 09:56:45.365757048 +0000 UTC m=+22.389240975
I1018 09:56:45.365821       1 scheduler.go:454] Total Schedule Algo cumulative time:1.5839516s for 691
I1018 09:56:45.369016       1 scheduler.go:451] ScheduleAlgoTime 3.024661ms Start:2018-10-18 09:56:45.365976661 +0000 UTC m=+22.389460526 End:2018-10-18 09:56:45.369001339 +0000 UTC m=+22.392485187
I1018 09:56:45.369057       1 scheduler.go:454] Total Schedule Algo cumulative time:1.586976261s for 692
I1018 09:56:45.371957       1 scheduler.go:451] ScheduleAlgoTime 2.542484ms Start:2018-10-18 09:56:45.369406758 +0000 UTC m=+22.392890676 End:2018-10-18 09:56:45.371949356 +0000 UTC m=+22.395433160
I1018 09:56:45.371996       1 scheduler.go:454] Total Schedule Algo cumulative time:1.589518745s for 693
I1018 09:56:45.374527       1 scheduler.go:451] ScheduleAlgoTime 2.16771ms Start:2018-10-18 09:56:45.372348656 +0000 UTC m=+22.395832556 End:2018-10-18 09:56:45.374516451 +0000 UTC m=+22.398000266
I1018 09:56:45.374578       1 scheduler.go:454] Total Schedule Algo cumulative time:1.591686455s for 694
I1018 09:56:45.377208       1 scheduler.go:451] ScheduleAlgoTime 2.151801ms Start:2018-10-18 09:56:45.375045637 +0000 UTC m=+22.398529513 End:2018-10-18 09:56:45.377197512 +0000 UTC m=+22.400681314
I1018 09:56:45.377264       1 scheduler.go:454] Total Schedule Algo cumulative time:1.593838256s for 695
I1018 09:56:45.379984       1 scheduler.go:451] ScheduleAlgoTime 2.443256ms Start:2018-10-18 09:56:45.377528674 +0000 UTC m=+22.401012600 End:2018-10-18 09:56:45.379972039 +0000 UTC m=+22.403455856
I1018 09:56:45.380023       1 scheduler.go:454] Total Schedule Algo cumulative time:1.596281512s for 696
I1018 09:56:45.382335       1 scheduler.go:451] ScheduleAlgoTime 2.064323ms Start:2018-10-18 09:56:45.380263471 +0000 UTC m=+22.403747346 End:2018-10-18 09:56:45.382327864 +0000 UTC m=+22.405811669
I1018 09:56:45.382372       1 scheduler.go:454] Total Schedule Algo cumulative time:1.598345835s for 697
I1018 09:56:45.384600       1 scheduler.go:451] ScheduleAlgoTime 2.076144ms Start:2018-10-18 09:56:45.382512992 +0000 UTC m=+22.405996882 End:2018-10-18 09:56:45.384589203 +0000 UTC m=+22.408073026
I1018 09:56:45.384635       1 scheduler.go:454] Total Schedule Algo cumulative time:1.600421979s for 698
I1018 09:56:45.387095       1 scheduler.go:451] ScheduleAlgoTime 2.13566ms Start:2018-10-18 09:56:45.384949636 +0000 UTC m=+22.408433517 End:2018-10-18 09:56:45.387085309 +0000 UTC m=+22.410569177
I1018 09:56:45.387134       1 scheduler.go:454] Total Schedule Algo cumulative time:1.602557639s for 699
I1018 09:56:45.389816       1 scheduler.go:451] ScheduleAlgoTime 2.481337ms Start:2018-10-18 09:56:45.387326108 +0000 UTC m=+22.410810027 End:2018-10-18 09:56:45.389807557 +0000 UTC m=+22.413291364
I1018 09:56:45.389846       1 scheduler.go:454] Total Schedule Algo cumulative time:1.605038976s for 700
I1018 09:56:45.392440       1 scheduler.go:451] ScheduleAlgoTime 2.393039ms Start:2018-10-18 09:56:45.390037191 +0000 UTC m=+22.413521122 End:2018-10-18 09:56:45.392430357 +0000 UTC m=+22.415914161
I1018 09:56:45.392476       1 scheduler.go:454] Total Schedule Algo cumulative time:1.607432015s for 701
I1018 09:56:45.395520       1 scheduler.go:451] ScheduleAlgoTime 2.338348ms Start:2018-10-18 09:56:45.393171549 +0000 UTC m=+22.416655437 End:2018-10-18 09:56:45.395509926 +0000 UTC m=+22.418993785
I1018 09:56:45.395561       1 scheduler.go:454] Total Schedule Algo cumulative time:1.609770363s for 702
I1018 09:56:45.398019       1 scheduler.go:451] ScheduleAlgoTime 2.182127ms Start:2018-10-18 09:56:45.395826243 +0000 UTC m=+22.419310132 End:2018-10-18 09:56:45.398008451 +0000 UTC m=+22.421492259
I1018 09:56:45.398052       1 scheduler.go:454] Total Schedule Algo cumulative time:1.61195249s for 703
I1018 09:56:45.400626       1 scheduler.go:451] ScheduleAlgoTime 2.376536ms Start:2018-10-18 09:56:45.3982412 +0000 UTC m=+22.421725103 End:2018-10-18 09:56:45.400617829 +0000 UTC m=+22.424101639
I1018 09:56:45.400658       1 scheduler.go:454] Total Schedule Algo cumulative time:1.614329026s for 704
I1018 09:56:45.403036       1 scheduler.go:451] ScheduleAlgoTime 2.053437ms Start:2018-10-18 09:56:45.400971223 +0000 UTC m=+22.424455131 End:2018-10-18 09:56:45.403024608 +0000 UTC m=+22.426508568
I1018 09:56:45.403078       1 scheduler.go:454] Total Schedule Algo cumulative time:1.616382463s for 705
I1018 09:56:45.405724       1 scheduler.go:451] ScheduleAlgoTime 2.425311ms Start:2018-10-18 09:56:45.40323279 +0000 UTC m=+22.426716609 End:2018-10-18 09:56:45.405658058 +0000 UTC m=+22.429141920
I1018 09:56:45.405768       1 scheduler.go:454] Total Schedule Algo cumulative time:1.618807774s for 706
I1018 09:56:45.407967       1 scheduler.go:451] ScheduleAlgoTime 2.086334ms Start:2018-10-18 09:56:45.405872072 +0000 UTC m=+22.429355982 End:2018-10-18 09:56:45.407958513 +0000 UTC m=+22.431442316
I1018 09:56:45.408000       1 scheduler.go:454] Total Schedule Algo cumulative time:1.620894108s for 707
I1018 09:56:45.410515       1 scheduler.go:451] ScheduleAlgoTime 2.311105ms Start:2018-10-18 09:56:45.408194843 +0000 UTC m=+22.431678762 End:2018-10-18 09:56:45.410506053 +0000 UTC m=+22.433989867
I1018 09:56:45.410547       1 scheduler.go:454] Total Schedule Algo cumulative time:1.623205213s for 708
I1018 09:56:45.413060       1 scheduler.go:451] ScheduleAlgoTime 2.284975ms Start:2018-10-18 09:56:45.410697292 +0000 UTC m=+22.434181187 End:2018-10-18 09:56:45.412982339 +0000 UTC m=+22.436466162
I1018 09:56:45.413097       1 scheduler.go:454] Total Schedule Algo cumulative time:1.625490188s for 709
I1018 09:56:45.415708       1 scheduler.go:451] ScheduleAlgoTime 2.391984ms Start:2018-10-18 09:56:45.41330474 +0000 UTC m=+22.436788668 End:2018-10-18 09:56:45.415696809 +0000 UTC m=+22.439180652
I1018 09:56:45.415749       1 scheduler.go:454] Total Schedule Algo cumulative time:1.627882172s for 710
I1018 09:56:45.417959       1 scheduler.go:451] ScheduleAlgoTime 1.968047ms Start:2018-10-18 09:56:45.415979031 +0000 UTC m=+22.439462930 End:2018-10-18 09:56:45.417946941 +0000 UTC m=+22.441430977
I1018 09:56:45.418007       1 scheduler.go:454] Total Schedule Algo cumulative time:1.629850219s for 711
I1018 09:56:45.420498       1 scheduler.go:451] ScheduleAlgoTime 2.273298ms Start:2018-10-18 09:56:45.418215297 +0000 UTC m=+22.441699210 End:2018-10-18 09:56:45.420488706 +0000 UTC m=+22.443972508
I1018 09:56:45.420530       1 scheduler.go:454] Total Schedule Algo cumulative time:1.632123517s for 712
I1018 09:56:45.423124       1 scheduler.go:451] ScheduleAlgoTime 2.337683ms Start:2018-10-18 09:56:45.420775113 +0000 UTC m=+22.444259017 End:2018-10-18 09:56:45.423112897 +0000 UTC m=+22.446596700
I1018 09:56:45.423157       1 scheduler.go:454] Total Schedule Algo cumulative time:1.6344612s for 713
I1018 09:56:45.425916       1 scheduler.go:451] ScheduleAlgoTime 2.524637ms Start:2018-10-18 09:56:45.423382142 +0000 UTC m=+22.446866051 End:2018-10-18 09:56:45.425906884 +0000 UTC m=+22.449390688
I1018 09:56:45.425951       1 scheduler.go:454] Total Schedule Algo cumulative time:1.636985837s for 714
I1018 09:56:45.428229       1 scheduler.go:451] ScheduleAlgoTime 1.979519ms Start:2018-10-18 09:56:45.42623857 +0000 UTC m=+22.449722490 End:2018-10-18 09:56:45.428218206 +0000 UTC m=+22.451702009
I1018 09:56:45.428260       1 scheduler.go:454] Total Schedule Algo cumulative time:1.638965356s for 715
I1018 09:56:45.430661       1 scheduler.go:451] ScheduleAlgoTime 2.047187ms Start:2018-10-18 09:56:45.428602422 +0000 UTC m=+22.452086303 End:2018-10-18 09:56:45.430649685 +0000 UTC m=+22.454133490
I1018 09:56:45.430725       1 scheduler.go:454] Total Schedule Algo cumulative time:1.641012543s for 716
I1018 09:56:45.433194       1 scheduler.go:451] ScheduleAlgoTime 2.242076ms Start:2018-10-18 09:56:45.430938688 +0000 UTC m=+22.454422566 End:2018-10-18 09:56:45.433180733 +0000 UTC m=+22.456664642
I1018 09:56:45.433233       1 scheduler.go:454] Total Schedule Algo cumulative time:1.643254619s for 717
I1018 09:56:45.435855       1 scheduler.go:451] ScheduleAlgoTime 2.386327ms Start:2018-10-18 09:56:45.43345989 +0000 UTC m=+22.456943735 End:2018-10-18 09:56:45.43584626 +0000 UTC m=+22.459330062
I1018 09:56:45.435899       1 scheduler.go:454] Total Schedule Algo cumulative time:1.645640946s for 718
I1018 09:56:45.438112       1 scheduler.go:451] ScheduleAlgoTime 1.956607ms Start:2018-10-18 09:56:45.43614723 +0000 UTC m=+22.459631131 End:2018-10-18 09:56:45.438103928 +0000 UTC m=+22.461587738
I1018 09:56:45.438150       1 scheduler.go:454] Total Schedule Algo cumulative time:1.647597553s for 719
I1018 09:56:45.440462       1 scheduler.go:451] ScheduleAlgoTime 2.059697ms Start:2018-10-18 09:56:45.438392883 +0000 UTC m=+22.461876760 End:2018-10-18 09:56:45.440452654 +0000 UTC m=+22.463936457
I1018 09:56:45.440513       1 scheduler.go:454] Total Schedule Algo cumulative time:1.64965725s for 720
I1018 09:56:45.442949       1 scheduler.go:451] ScheduleAlgoTime 2.180712ms Start:2018-10-18 09:56:45.440759306 +0000 UTC m=+22.464243206 End:2018-10-18 09:56:45.442940114 +0000 UTC m=+22.466423918
I1018 09:56:45.442979       1 scheduler.go:454] Total Schedule Algo cumulative time:1.651837962s for 721
I1018 09:56:45.445573       1 scheduler.go:451] ScheduleAlgoTime 2.44454ms Start:2018-10-18 09:56:45.443115788 +0000 UTC m=+22.466599664 End:2018-10-18 09:56:45.445560386 +0000 UTC m=+22.469044204
I1018 09:56:45.445611       1 scheduler.go:454] Total Schedule Algo cumulative time:1.654282502s for 722
I1018 09:56:45.448155       1 scheduler.go:451] ScheduleAlgoTime 2.246179ms Start:2018-10-18 09:56:45.445899733 +0000 UTC m=+22.469383595 End:2018-10-18 09:56:45.448145968 +0000 UTC m=+22.471629774
I1018 09:56:45.448188       1 scheduler.go:454] Total Schedule Algo cumulative time:1.656528681s for 723
I1018 09:56:45.450985       1 scheduler.go:451] ScheduleAlgoTime 2.55138ms Start:2018-10-18 09:56:45.44842314 +0000 UTC m=+22.471906982 End:2018-10-18 09:56:45.450974554 +0000 UTC m=+22.474458362
I1018 09:56:45.451043       1 scheduler.go:454] Total Schedule Algo cumulative time:1.659080061s for 724
I1018 09:56:45.453414       1 scheduler.go:451] ScheduleAlgoTime 2.111436ms Start:2018-10-18 09:56:45.451294294 +0000 UTC m=+22.474778185 End:2018-10-18 09:56:45.453405816 +0000 UTC m=+22.476889621
I1018 09:56:45.453443       1 scheduler.go:454] Total Schedule Algo cumulative time:1.661191497s for 725
I1018 09:56:45.456119       1 scheduler.go:451] ScheduleAlgoTime 2.475305ms Start:2018-10-18 09:56:45.453632172 +0000 UTC m=+22.477116106 End:2018-10-18 09:56:45.456107501 +0000 UTC m=+22.479591411
I1018 09:56:45.456168       1 scheduler.go:454] Total Schedule Algo cumulative time:1.663666802s for 726
I1018 09:56:45.458591       1 scheduler.go:451] ScheduleAlgoTime 2.172019ms Start:2018-10-18 09:56:45.456408667 +0000 UTC m=+22.479892542 End:2018-10-18 09:56:45.458580735 +0000 UTC m=+22.482064561
I1018 09:56:45.458626       1 scheduler.go:454] Total Schedule Algo cumulative time:1.665838821s for 727
I1018 09:56:45.461326       1 scheduler.go:451] ScheduleAlgoTime 2.353586ms Start:2018-10-18 09:56:45.458964206 +0000 UTC m=+22.482448083 End:2018-10-18 09:56:45.46131786 +0000 UTC m=+22.484801669
I1018 09:56:45.461360       1 scheduler.go:454] Total Schedule Algo cumulative time:1.668192407s for 728
I1018 09:56:45.464177       1 scheduler.go:451] ScheduleAlgoTime 2.343884ms Start:2018-10-18 09:56:45.461808147 +0000 UTC m=+22.485292051 End:2018-10-18 09:56:45.464152081 +0000 UTC m=+22.487635935
I1018 09:56:45.464215       1 scheduler.go:454] Total Schedule Algo cumulative time:1.670536291s for 729
I1018 09:56:45.467104       1 scheduler.go:451] ScheduleAlgoTime 2.564692ms Start:2018-10-18 09:56:45.46452992 +0000 UTC m=+22.488013838 End:2018-10-18 09:56:45.467094727 +0000 UTC m=+22.490578530
I1018 09:56:45.467135       1 scheduler.go:454] Total Schedule Algo cumulative time:1.673100983s for 730
I1018 09:56:45.470128       1 scheduler.go:451] ScheduleAlgoTime 2.839687ms Start:2018-10-18 09:56:45.467279431 +0000 UTC m=+22.490763234 End:2018-10-18 09:56:45.470119116 +0000 UTC m=+22.493602921
I1018 09:56:45.470158       1 scheduler.go:454] Total Schedule Algo cumulative time:1.67594067s for 731
I1018 09:56:45.474351       1 scheduler.go:451] ScheduleAlgoTime 3.99806ms Start:2018-10-18 09:56:45.470344639 +0000 UTC m=+22.493828514 End:2018-10-18 09:56:45.474342765 +0000 UTC m=+22.497826574
I1018 09:56:45.474388       1 scheduler.go:454] Total Schedule Algo cumulative time:1.67993873s for 732
I1018 09:56:45.482047       1 scheduler.go:451] ScheduleAlgoTime 7.188541ms Start:2018-10-18 09:56:45.474845433 +0000 UTC m=+22.498329338 End:2018-10-18 09:56:45.482033966 +0000 UTC m=+22.505517879
I1018 09:56:45.482132       1 scheduler.go:454] Total Schedule Algo cumulative time:1.687127271s for 733
I1018 09:56:45.486454       1 scheduler.go:451] ScheduleAlgoTime 2.632385ms Start:2018-10-18 09:56:45.48381264 +0000 UTC m=+22.507296535 End:2018-10-18 09:56:45.486445114 +0000 UTC m=+22.509928920
I1018 09:56:45.486495       1 scheduler.go:454] Total Schedule Algo cumulative time:1.689759656s for 734
I1018 09:56:45.488863       1 scheduler.go:451] ScheduleAlgoTime 2.196865ms Start:2018-10-18 09:56:45.486654666 +0000 UTC m=+22.510138591 End:2018-10-18 09:56:45.488851561 +0000 UTC m=+22.512335456
I1018 09:56:45.488908       1 scheduler.go:454] Total Schedule Algo cumulative time:1.691956521s for 735
I1018 09:56:45.491549       1 scheduler.go:451] ScheduleAlgoTime 2.26693ms Start:2018-10-18 09:56:45.489274797 +0000 UTC m=+22.512758692 End:2018-10-18 09:56:45.491541814 +0000 UTC m=+22.515025622
I1018 09:56:45.491581       1 scheduler.go:454] Total Schedule Algo cumulative time:1.694223451s for 736
I1018 09:56:45.494075       1 scheduler.go:451] ScheduleAlgoTime 2.18901ms Start:2018-10-18 09:56:45.491875523 +0000 UTC m=+22.515359425 End:2018-10-18 09:56:45.494064628 +0000 UTC m=+22.517548435
I1018 09:56:45.494108       1 scheduler.go:454] Total Schedule Algo cumulative time:1.696412461s for 737
I1018 09:56:45.496401       1 scheduler.go:451] ScheduleAlgoTime 2.104492ms Start:2018-10-18 09:56:45.494288762 +0000 UTC m=+22.517772668 End:2018-10-18 09:56:45.496393352 +0000 UTC m=+22.519877160
I1018 09:56:45.496433       1 scheduler.go:454] Total Schedule Algo cumulative time:1.698516953s for 738
I1018 09:56:45.498762       1 scheduler.go:451] ScheduleAlgoTime 2.104187ms Start:2018-10-18 09:56:45.496647755 +0000 UTC m=+22.520131651 End:2018-10-18 09:56:45.498752035 +0000 UTC m=+22.522235838
I1018 09:56:45.498798       1 scheduler.go:454] Total Schedule Algo cumulative time:1.70062114s for 739
I1018 09:56:45.501198       1 scheduler.go:451] ScheduleAlgoTime 2.184605ms Start:2018-10-18 09:56:45.499003005 +0000 UTC m=+22.522486881 End:2018-10-18 09:56:45.501187663 +0000 UTC m=+22.524671486
I1018 09:56:45.501233       1 scheduler.go:454] Total Schedule Algo cumulative time:1.702805745s for 740
I1018 09:56:45.503644       1 scheduler.go:451] ScheduleAlgoTime 2.231342ms Start:2018-10-18 09:56:45.501401798 +0000 UTC m=+22.524885669 End:2018-10-18 09:56:45.50363311 +0000 UTC m=+22.527117011
I1018 09:56:45.503708       1 scheduler.go:454] Total Schedule Algo cumulative time:1.705037087s for 741
I1018 09:56:45.506063       1 scheduler.go:451] ScheduleAlgoTime 2.162835ms Start:2018-10-18 09:56:45.503891961 +0000 UTC m=+22.527375764 End:2018-10-18 09:56:45.506054795 +0000 UTC m=+22.529538599
I1018 09:56:45.506095       1 scheduler.go:454] Total Schedule Algo cumulative time:1.707199922s for 742
I1018 09:56:45.509449       1 scheduler.go:451] ScheduleAlgoTime 3.008965ms Start:2018-10-18 09:56:45.506430053 +0000 UTC m=+22.529913889 End:2018-10-18 09:56:45.509439051 +0000 UTC m=+22.532922854
I1018 09:56:45.509490       1 scheduler.go:454] Total Schedule Algo cumulative time:1.710208887s for 743
I1018 09:56:45.513126       1 scheduler.go:451] ScheduleAlgoTime 3.374572ms Start:2018-10-18 09:56:45.509739846 +0000 UTC m=+22.533223728 End:2018-10-18 09:56:45.513114332 +0000 UTC m=+22.536598300
I1018 09:56:45.513177       1 scheduler.go:454] Total Schedule Algo cumulative time:1.713583459s for 744
I1018 09:56:45.515494       1 scheduler.go:451] ScheduleAlgoTime 2.147922ms Start:2018-10-18 09:56:45.513335106 +0000 UTC m=+22.536818978 End:2018-10-18 09:56:45.51548309 +0000 UTC m=+22.538966900
I1018 09:56:45.515548       1 scheduler.go:454] Total Schedule Algo cumulative time:1.715731381s for 745
I1018 09:56:45.517908       1 scheduler.go:451] ScheduleAlgoTime 2.239597ms Start:2018-10-18 09:56:45.515657747 +0000 UTC m=+22.539141637 End:2018-10-18 09:56:45.517897316 +0000 UTC m=+22.541381234
I1018 09:56:45.517937       1 scheduler.go:454] Total Schedule Algo cumulative time:1.717970978s for 746
I1018 09:56:45.520346       1 scheduler.go:451] ScheduleAlgoTime 2.104193ms Start:2018-10-18 09:56:45.518234248 +0000 UTC m=+22.541718212 End:2018-10-18 09:56:45.520338599 +0000 UTC m=+22.543822405
I1018 09:56:45.520375       1 scheduler.go:454] Total Schedule Algo cumulative time:1.720075171s for 747
I1018 09:56:45.522814       1 scheduler.go:451] ScheduleAlgoTime 2.224278ms Start:2018-10-18 09:56:45.520581826 +0000 UTC m=+22.544065634 End:2018-10-18 09:56:45.522806108 +0000 UTC m=+22.546289912
I1018 09:56:45.522842       1 scheduler.go:454] Total Schedule Algo cumulative time:1.722299449s for 748
I1018 09:56:45.525159       1 scheduler.go:451] ScheduleAlgoTime 2.118993ms Start:2018-10-18 09:56:45.523030042 +0000 UTC m=+22.546513925 End:2018-10-18 09:56:45.525149112 +0000 UTC m=+22.548632918
I1018 09:56:45.525191       1 scheduler.go:454] Total Schedule Algo cumulative time:1.724418442s for 749
I1018 09:56:45.527796       1 scheduler.go:451] ScheduleAlgoTime 2.345709ms Start:2018-10-18 09:56:45.525441192 +0000 UTC m=+22.548925096 End:2018-10-18 09:56:45.527787003 +0000 UTC m=+22.551270805
I1018 09:56:45.527828       1 scheduler.go:454] Total Schedule Algo cumulative time:1.726764151s for 750
I1018 09:56:45.530311       1 scheduler.go:451] ScheduleAlgoTime 2.175319ms Start:2018-10-18 09:56:45.528123458 +0000 UTC m=+22.551607335 End:2018-10-18 09:56:45.530298847 +0000 UTC m=+22.553782654
I1018 09:56:45.530341       1 scheduler.go:454] Total Schedule Algo cumulative time:1.72893947s for 751
I1018 09:56:45.532603       1 scheduler.go:451] ScheduleAlgoTime 2.123692ms Start:2018-10-18 09:56:45.530469553 +0000 UTC m=+22.553953370 End:2018-10-18 09:56:45.532593254 +0000 UTC m=+22.556077062
I1018 09:56:45.532635       1 scheduler.go:454] Total Schedule Algo cumulative time:1.731063162s for 752
I1018 09:56:45.534932       1 scheduler.go:451] ScheduleAlgoTime 2.002945ms Start:2018-10-18 09:56:45.532918998 +0000 UTC m=+22.556402893 End:2018-10-18 09:56:45.534922008 +0000 UTC m=+22.558405838
I1018 09:56:45.534978       1 scheduler.go:454] Total Schedule Algo cumulative time:1.733066107s for 753
I1018 09:56:45.537330       1 scheduler.go:451] ScheduleAlgoTime 2.057385ms Start:2018-10-18 09:56:45.535265483 +0000 UTC m=+22.558749376 End:2018-10-18 09:56:45.537322953 +0000 UTC m=+22.560806761
I1018 09:56:45.537359       1 scheduler.go:454] Total Schedule Algo cumulative time:1.735123492s for 754
I1018 09:56:45.539720       1 scheduler.go:451] ScheduleAlgoTime 2.163591ms Start:2018-10-18 09:56:45.53754681 +0000 UTC m=+22.561030727 End:2018-10-18 09:56:45.539710514 +0000 UTC m=+22.563194318
I1018 09:56:45.539752       1 scheduler.go:454] Total Schedule Algo cumulative time:1.737287083s for 755
I1018 09:56:45.541859       1 scheduler.go:451] ScheduleAlgoTime 1.892369ms Start:2018-10-18 09:56:45.539959486 +0000 UTC m=+22.563443340 End:2018-10-18 09:56:45.541851906 +0000 UTC m=+22.565335709
I1018 09:56:45.541887       1 scheduler.go:454] Total Schedule Algo cumulative time:1.739179452s for 756
I1018 09:56:45.544535       1 scheduler.go:451] ScheduleAlgoTime 2.321101ms Start:2018-10-18 09:56:45.542205307 +0000 UTC m=+22.565689204 End:2018-10-18 09:56:45.544526492 +0000 UTC m=+22.568010305
I1018 09:56:45.544573       1 scheduler.go:454] Total Schedule Algo cumulative time:1.741500553s for 757
I1018 09:56:45.547711       1 scheduler.go:451] ScheduleAlgoTime 2.92673ms Start:2018-10-18 09:56:45.544729187 +0000 UTC m=+22.568213005 End:2018-10-18 09:56:45.547655923 +0000 UTC m=+22.571139735
I1018 09:56:45.547754       1 scheduler.go:454] Total Schedule Algo cumulative time:1.744427283s for 758
I1018 09:56:45.550913       1 scheduler.go:451] ScheduleAlgoTime 3.056108ms Start:2018-10-18 09:56:45.547849946 +0000 UTC m=+22.571333776 End:2018-10-18 09:56:45.550906079 +0000 UTC m=+22.574389884
I1018 09:56:45.550962       1 scheduler.go:454] Total Schedule Algo cumulative time:1.747483391s for 759
I1018 09:56:45.554906       1 scheduler.go:451] ScheduleAlgoTime 3.667272ms Start:2018-10-18 09:56:45.551231631 +0000 UTC m=+22.574715454 End:2018-10-18 09:56:45.554898924 +0000 UTC m=+22.578382726
I1018 09:56:45.554938       1 scheduler.go:454] Total Schedule Algo cumulative time:1.751150663s for 760
I1018 09:56:45.560810       1 scheduler.go:451] ScheduleAlgoTime 4.078728ms Start:2018-10-18 09:56:45.556723904 +0000 UTC m=+22.580207788 End:2018-10-18 09:56:45.560802713 +0000 UTC m=+22.584286516
I1018 09:56:45.560849       1 scheduler.go:454] Total Schedule Algo cumulative time:1.755229391s for 761
I1018 09:56:45.564796       1 scheduler.go:451] ScheduleAlgoTime 3.654988ms Start:2018-10-18 09:56:45.561132763 +0000 UTC m=+22.584616641 End:2018-10-18 09:56:45.564787825 +0000 UTC m=+22.588271629
I1018 09:56:45.564828       1 scheduler.go:454] Total Schedule Algo cumulative time:1.758884379s for 762
I1018 09:56:45.571494       1 scheduler.go:451] ScheduleAlgoTime 4.533328ms Start:2018-10-18 09:56:45.566948518 +0000 UTC m=+22.590432341 End:2018-10-18 09:56:45.571481862 +0000 UTC m=+22.594965669
I1018 09:56:45.571542       1 scheduler.go:454] Total Schedule Algo cumulative time:1.763417707s for 763
I1018 09:56:45.575235       1 scheduler.go:451] ScheduleAlgoTime 2.984886ms Start:2018-10-18 09:56:45.572241513 +0000 UTC m=+22.595725415 End:2018-10-18 09:56:45.575226498 +0000 UTC m=+22.598710301
I1018 09:56:45.575276       1 scheduler.go:454] Total Schedule Algo cumulative time:1.766402593s for 764
I1018 09:56:45.581832       1 scheduler.go:451] ScheduleAlgoTime 3.528844ms Start:2018-10-18 09:56:45.578294237 +0000 UTC m=+22.601778132 End:2018-10-18 09:56:45.581823174 +0000 UTC m=+22.605306976
I1018 09:56:45.581876       1 scheduler.go:454] Total Schedule Algo cumulative time:1.769931437s for 765
I1018 09:56:45.588459       1 scheduler.go:451] ScheduleAlgoTime 2.524111ms Start:2018-10-18 09:56:45.585925783 +0000 UTC m=+22.609409673 End:2018-10-18 09:56:45.58844998 +0000 UTC m=+22.611933784
I1018 09:56:45.588492       1 scheduler.go:454] Total Schedule Algo cumulative time:1.772455548s for 766
I1018 09:56:45.591431       1 scheduler.go:451] ScheduleAlgoTime 2.694651ms Start:2018-10-18 09:56:45.588725878 +0000 UTC m=+22.612209762 End:2018-10-18 09:56:45.591420609 +0000 UTC m=+22.614904413
I1018 09:56:45.591470       1 scheduler.go:454] Total Schedule Algo cumulative time:1.775150199s for 767
I1018 09:56:45.593878       1 scheduler.go:451] ScheduleAlgoTime 2.163226ms Start:2018-10-18 09:56:45.591706261 +0000 UTC m=+22.615190159 End:2018-10-18 09:56:45.593869583 +0000 UTC m=+22.617353385
I1018 09:56:45.593910       1 scheduler.go:454] Total Schedule Algo cumulative time:1.777313425s for 768
I1018 09:56:45.596306       1 scheduler.go:451] ScheduleAlgoTime 2.08834ms Start:2018-10-18 09:56:45.594208708 +0000 UTC m=+22.617692586 End:2018-10-18 09:56:45.596297079 +0000 UTC m=+22.619780926
I1018 09:56:45.596335       1 scheduler.go:454] Total Schedule Algo cumulative time:1.779401765s for 769
I1018 09:56:45.598292       1 scheduler.go:451] ScheduleAlgoTime 1.798058ms Start:2018-10-18 09:56:45.596487696 +0000 UTC m=+22.619971576 End:2018-10-18 09:56:45.598285827 +0000 UTC m=+22.621769634
I1018 09:56:45.598320       1 scheduler.go:454] Total Schedule Algo cumulative time:1.781199823s for 770
I1018 09:56:45.600401       1 scheduler.go:451] ScheduleAlgoTime 1.857181ms Start:2018-10-18 09:56:45.598537793 +0000 UTC m=+22.622021649 End:2018-10-18 09:56:45.60039502 +0000 UTC m=+22.623878830
I1018 09:56:45.600431       1 scheduler.go:454] Total Schedule Algo cumulative time:1.783057004s for 771
I1018 09:56:45.603223       1 scheduler.go:451] ScheduleAlgoTime 2.562313ms Start:2018-10-18 09:56:45.600646725 +0000 UTC m=+22.624130653 End:2018-10-18 09:56:45.603208708 +0000 UTC m=+22.626692966
I1018 09:56:45.603321       1 scheduler.go:454] Total Schedule Algo cumulative time:1.785619317s for 772
I1018 09:56:45.605842       1 scheduler.go:451] ScheduleAlgoTime 2.265736ms Start:2018-10-18 09:56:45.603567448 +0000 UTC m=+22.627051342 End:2018-10-18 09:56:45.60583327 +0000 UTC m=+22.629317078
I1018 09:56:45.605894       1 scheduler.go:454] Total Schedule Algo cumulative time:1.787885053s for 773
I1018 09:56:45.608285       1 scheduler.go:451] ScheduleAlgoTime 2.09148ms Start:2018-10-18 09:56:45.606185049 +0000 UTC m=+22.629668943 End:2018-10-18 09:56:45.608276618 +0000 UTC m=+22.631760423
I1018 09:56:45.608315       1 scheduler.go:454] Total Schedule Algo cumulative time:1.789976533s for 774
I1018 09:56:45.610899       1 scheduler.go:451] ScheduleAlgoTime 2.366005ms Start:2018-10-18 09:56:45.608521739 +0000 UTC m=+22.632005582 End:2018-10-18 09:56:45.610887781 +0000 UTC m=+22.634371587
I1018 09:56:45.610938       1 scheduler.go:454] Total Schedule Algo cumulative time:1.792342538s for 775
I1018 09:56:45.613048       1 scheduler.go:451] ScheduleAlgoTime 1.848526ms Start:2018-10-18 09:56:45.611192801 +0000 UTC m=+22.634676701 End:2018-10-18 09:56:45.61304142 +0000 UTC m=+22.636525227
I1018 09:56:45.613077       1 scheduler.go:454] Total Schedule Algo cumulative time:1.794191064s for 776
I1018 09:56:45.615386       1 scheduler.go:451] ScheduleAlgoTime 2.116904ms Start:2018-10-18 09:56:45.613260451 +0000 UTC m=+22.636744327 End:2018-10-18 09:56:45.615377429 +0000 UTC m=+22.638861231
I1018 09:56:45.615416       1 scheduler.go:454] Total Schedule Algo cumulative time:1.796307968s for 777
I1018 09:56:45.617374       1 scheduler.go:451] ScheduleAlgoTime 1.803786ms Start:2018-10-18 09:56:45.615563486 +0000 UTC m=+22.639047304 End:2018-10-18 09:56:45.617367284 +0000 UTC m=+22.640851090
I1018 09:56:45.617398       1 scheduler.go:454] Total Schedule Algo cumulative time:1.798111754s for 778
I1018 09:56:45.619901       1 scheduler.go:451] ScheduleAlgoTime 2.235054ms Start:2018-10-18 09:56:45.617654478 +0000 UTC m=+22.641138375 End:2018-10-18 09:56:45.619889611 +0000 UTC m=+22.643373429
I1018 09:56:45.619947       1 scheduler.go:454] Total Schedule Algo cumulative time:1.800346808s for 779
I1018 09:56:45.622265       1 scheduler.go:451] ScheduleAlgoTime 2.11498ms Start:2018-10-18 09:56:45.620140854 +0000 UTC m=+22.643624735 End:2018-10-18 09:56:45.622255911 +0000 UTC m=+22.645739715
I1018 09:56:45.622304       1 scheduler.go:454] Total Schedule Algo cumulative time:1.802461788s for 780
I1018 09:56:45.624483       1 scheduler.go:451] ScheduleAlgoTime 1.928488ms Start:2018-10-18 09:56:45.622547839 +0000 UTC m=+22.646031714 End:2018-10-18 09:56:45.624476398 +0000 UTC m=+22.647960202
I1018 09:56:45.624518       1 scheduler.go:454] Total Schedule Algo cumulative time:1.804390276s for 781
I1018 09:56:45.626867       1 scheduler.go:451] ScheduleAlgoTime 2.120662ms Start:2018-10-18 09:56:45.624739392 +0000 UTC m=+22.648223274 End:2018-10-18 09:56:45.62686013 +0000 UTC m=+22.650343936
I1018 09:56:45.626895       1 scheduler.go:454] Total Schedule Algo cumulative time:1.806510938s for 782
I1018 09:56:45.629099       1 scheduler.go:451] ScheduleAlgoTime 1.994278ms Start:2018-10-18 09:56:45.627094883 +0000 UTC m=+22.650578792 End:2018-10-18 09:56:45.629089263 +0000 UTC m=+22.652573070
I1018 09:56:45.629130       1 scheduler.go:454] Total Schedule Algo cumulative time:1.808505216s for 783
I1018 09:56:45.631386       1 scheduler.go:451] ScheduleAlgoTime 2.105258ms Start:2018-10-18 09:56:45.629269756 +0000 UTC m=+22.652753593 End:2018-10-18 09:56:45.631375036 +0000 UTC m=+22.654858851
I1018 09:56:45.631426       1 scheduler.go:454] Total Schedule Algo cumulative time:1.810610474s for 784
I1018 09:56:45.634151       1 scheduler.go:451] ScheduleAlgoTime 2.454916ms Start:2018-10-18 09:56:45.631684972 +0000 UTC m=+22.655168870 End:2018-10-18 09:56:45.634139836 +0000 UTC m=+22.657623786
I1018 09:56:45.634188       1 scheduler.go:454] Total Schedule Algo cumulative time:1.81306539s for 785
I1018 09:56:45.636343       1 scheduler.go:451] ScheduleAlgoTime 1.837624ms Start:2018-10-18 09:56:45.634498706 +0000 UTC m=+22.657982588 End:2018-10-18 09:56:45.636336407 +0000 UTC m=+22.659820212
I1018 09:56:45.636384       1 scheduler.go:454] Total Schedule Algo cumulative time:1.814903014s for 786
I1018 09:56:45.638848       1 scheduler.go:451] ScheduleAlgoTime 2.053252ms Start:2018-10-18 09:56:45.636785253 +0000 UTC m=+22.660269133 End:2018-10-18 09:56:45.638838553 +0000 UTC m=+22.662322385
I1018 09:56:45.638882       1 scheduler.go:454] Total Schedule Algo cumulative time:1.816956266s for 787
I1018 09:56:45.641049       1 scheduler.go:451] ScheduleAlgoTime 1.942249ms Start:2018-10-18 09:56:45.639099654 +0000 UTC m=+22.662583596 End:2018-10-18 09:56:45.641042038 +0000 UTC m=+22.664525845
I1018 09:56:45.641075       1 scheduler.go:454] Total Schedule Algo cumulative time:1.818898515s for 788
I1018 09:56:45.643485       1 scheduler.go:451] ScheduleAlgoTime 2.17234ms Start:2018-10-18 09:56:45.641304328 +0000 UTC m=+22.664788214 End:2018-10-18 09:56:45.643476736 +0000 UTC m=+22.666960554
I1018 09:56:45.643542       1 scheduler.go:454] Total Schedule Algo cumulative time:1.821070855s for 789
I1018 09:56:45.646237       1 scheduler.go:451] ScheduleAlgoTime 2.427357ms Start:2018-10-18 09:56:45.643802824 +0000 UTC m=+22.667286729 End:2018-10-18 09:56:45.646230281 +0000 UTC m=+22.669714086
I1018 09:56:45.646264       1 scheduler.go:454] Total Schedule Algo cumulative time:1.823498212s for 790
I1018 09:56:45.648877       1 scheduler.go:451] ScheduleAlgoTime 2.344683ms Start:2018-10-18 09:56:45.646522867 +0000 UTC m=+22.670006754 End:2018-10-18 09:56:45.648867628 +0000 UTC m=+22.672351437
I1018 09:56:45.648912       1 scheduler.go:454] Total Schedule Algo cumulative time:1.825842895s for 791
I1018 09:56:45.651112       1 scheduler.go:451] ScheduleAlgoTime 1.986721ms Start:2018-10-18 09:56:45.649119452 +0000 UTC m=+22.672603376 End:2018-10-18 09:56:45.651106293 +0000 UTC m=+22.674590097
I1018 09:56:45.651142       1 scheduler.go:454] Total Schedule Algo cumulative time:1.827829616s for 792
I1018 09:56:45.653956       1 scheduler.go:451] ScheduleAlgoTime 2.566586ms Start:2018-10-18 09:56:45.651382102 +0000 UTC m=+22.674865988 End:2018-10-18 09:56:45.653948767 +0000 UTC m=+22.677432574
I1018 09:56:45.653982       1 scheduler.go:454] Total Schedule Algo cumulative time:1.830396202s for 793
I1018 09:56:45.656327       1 scheduler.go:451] ScheduleAlgoTime 2.120797ms Start:2018-10-18 09:56:45.65419666 +0000 UTC m=+22.677680483 End:2018-10-18 09:56:45.656317474 +0000 UTC m=+22.679801280
I1018 09:56:45.656355       1 scheduler.go:454] Total Schedule Algo cumulative time:1.832516999s for 794
I1018 09:56:45.658852       1 scheduler.go:451] ScheduleAlgoTime 2.291535ms Start:2018-10-18 09:56:45.656549997 +0000 UTC m=+22.680033892 End:2018-10-18 09:56:45.658841517 +0000 UTC m=+22.682325427
I1018 09:56:45.658895       1 scheduler.go:454] Total Schedule Algo cumulative time:1.834808534s for 795
I1018 09:56:45.664298       1 scheduler.go:451] ScheduleAlgoTime 5.156688ms Start:2018-10-18 09:56:45.659132313 +0000 UTC m=+22.682616222 End:2018-10-18 09:56:45.664289106 +0000 UTC m=+22.687772910
I1018 09:56:45.664350       1 scheduler.go:454] Total Schedule Algo cumulative time:1.839965222s for 796
I1018 09:56:45.674348       1 scheduler.go:451] ScheduleAlgoTime 9.353479ms Start:2018-10-18 09:56:45.664981707 +0000 UTC m=+22.688465597 End:2018-10-18 09:56:45.67433527 +0000 UTC m=+22.697819076
I1018 09:56:45.674400       1 scheduler.go:454] Total Schedule Algo cumulative time:1.849318701s for 797
I1018 09:56:45.677135       1 scheduler.go:451] ScheduleAlgoTime 2.536467ms Start:2018-10-18 09:56:45.674586602 +0000 UTC m=+22.698070462 End:2018-10-18 09:56:45.677122857 +0000 UTC m=+22.700606929
I1018 09:56:45.677184       1 scheduler.go:454] Total Schedule Algo cumulative time:1.851855168s for 798
I1018 09:56:45.679781       1 scheduler.go:451] ScheduleAlgoTime 2.269172ms Start:2018-10-18 09:56:45.677504149 +0000 UTC m=+22.700988076 End:2018-10-18 09:56:45.679773444 +0000 UTC m=+22.703257248
I1018 09:56:45.679815       1 scheduler.go:454] Total Schedule Algo cumulative time:1.85412434s for 799
I1018 09:56:45.683214       1 scheduler.go:451] ScheduleAlgoTime 3.121454ms Start:2018-10-18 09:56:45.680083537 +0000 UTC m=+22.703567437 End:2018-10-18 09:56:45.683205088 +0000 UTC m=+22.706688891
I1018 09:56:45.683254       1 scheduler.go:454] Total Schedule Algo cumulative time:1.857245794s for 800
I1018 09:56:45.685625       1 scheduler.go:451] ScheduleAlgoTime 2.167754ms Start:2018-10-18 09:56:45.68344798 +0000 UTC m=+22.706931877 End:2018-10-18 09:56:45.685615822 +0000 UTC m=+22.709099631
I1018 09:56:45.685658       1 scheduler.go:454] Total Schedule Algo cumulative time:1.859413548s for 801
I1018 09:56:45.688469       1 scheduler.go:451] ScheduleAlgoTime 2.595139ms Start:2018-10-18 09:56:45.685864299 +0000 UTC m=+22.709348104 End:2018-10-18 09:56:45.688459434 +0000 UTC m=+22.711943243
I1018 09:56:45.688504       1 scheduler.go:454] Total Schedule Algo cumulative time:1.862008687s for 802
I1018 09:56:45.691145       1 scheduler.go:451] ScheduleAlgoTime 2.416019ms Start:2018-10-18 09:56:45.68872055 +0000 UTC m=+22.712204461 End:2018-10-18 09:56:45.69113667 +0000 UTC m=+22.714620480
I1018 09:56:45.691188       1 scheduler.go:454] Total Schedule Algo cumulative time:1.864424706s for 803
I1018 09:56:45.693636       1 scheduler.go:451] ScheduleAlgoTime 2.191419ms Start:2018-10-18 09:56:45.691435851 +0000 UTC m=+22.714919783 End:2018-10-18 09:56:45.693627397 +0000 UTC m=+22.717111202
I1018 09:56:45.693752       1 scheduler.go:454] Total Schedule Algo cumulative time:1.866616125s for 804
I1018 09:56:45.695990       1 scheduler.go:451] ScheduleAlgoTime 2.043809ms Start:2018-10-18 09:56:45.693931751 +0000 UTC m=+22.717415638 End:2018-10-18 09:56:45.695975437 +0000 UTC m=+22.719459447
I1018 09:56:45.696031       1 scheduler.go:454] Total Schedule Algo cumulative time:1.868659934s for 805
I1018 09:56:45.698467       1 scheduler.go:451] ScheduleAlgoTime 2.173317ms Start:2018-10-18 09:56:45.696286437 +0000 UTC m=+22.719770286 End:2018-10-18 09:56:45.698459796 +0000 UTC m=+22.721943603
I1018 09:56:45.698497       1 scheduler.go:454] Total Schedule Algo cumulative time:1.870833251s for 806
I1018 09:56:45.700445       1 scheduler.go:451] ScheduleAlgoTime 1.747655ms Start:2018-10-18 09:56:45.698690282 +0000 UTC m=+22.722174172 End:2018-10-18 09:56:45.700438019 +0000 UTC m=+22.723921827
I1018 09:56:45.700474       1 scheduler.go:454] Total Schedule Algo cumulative time:1.872580906s for 807
I1018 09:56:45.702377       1 scheduler.go:451] ScheduleAlgoTime 1.677202ms Start:2018-10-18 09:56:45.700690188 +0000 UTC m=+22.724174055 End:2018-10-18 09:56:45.70236744 +0000 UTC m=+22.725851257
I1018 09:56:45.702412       1 scheduler.go:454] Total Schedule Algo cumulative time:1.874258108s for 808
I1018 09:56:45.704743       1 scheduler.go:451] ScheduleAlgoTime 2.124971ms Start:2018-10-18 09:56:45.702610037 +0000 UTC m=+22.726093928 End:2018-10-18 09:56:45.704735082 +0000 UTC m=+22.728218899
I1018 09:56:45.704769       1 scheduler.go:454] Total Schedule Algo cumulative time:1.876383079s for 809
I1018 09:56:45.707719       1 scheduler.go:451] ScheduleAlgoTime 2.618115ms Start:2018-10-18 09:56:45.70508959 +0000 UTC m=+22.728573508 End:2018-10-18 09:56:45.70770782 +0000 UTC m=+22.731191623
I1018 09:56:45.707751       1 scheduler.go:454] Total Schedule Algo cumulative time:1.879001194s for 810
I1018 09:56:45.710112       1 scheduler.go:451] ScheduleAlgoTime 2.114479ms Start:2018-10-18 09:56:45.707988338 +0000 UTC m=+22.731472201 End:2018-10-18 09:56:45.710102848 +0000 UTC m=+22.733586680
I1018 09:56:45.710143       1 scheduler.go:454] Total Schedule Algo cumulative time:1.881115673s for 811
I1018 09:56:45.712657       1 scheduler.go:451] ScheduleAlgoTime 2.194824ms Start:2018-10-18 09:56:45.710452565 +0000 UTC m=+22.733936446 End:2018-10-18 09:56:45.712647465 +0000 UTC m=+22.736131270
I1018 09:56:45.712728       1 scheduler.go:454] Total Schedule Algo cumulative time:1.883310497s for 812
I1018 09:56:45.715311       1 scheduler.go:451] ScheduleAlgoTime 2.257685ms Start:2018-10-18 09:56:45.713044666 +0000 UTC m=+22.736528553 End:2018-10-18 09:56:45.715302435 +0000 UTC m=+22.738786238
I1018 09:56:45.715351       1 scheduler.go:454] Total Schedule Algo cumulative time:1.885568182s for 813
I1018 09:56:45.717533       1 scheduler.go:451] ScheduleAlgoTime 1.870151ms Start:2018-10-18 09:56:45.715655108 +0000 UTC m=+22.739138983 End:2018-10-18 09:56:45.717525304 +0000 UTC m=+22.741009134
I1018 09:56:45.717561       1 scheduler.go:454] Total Schedule Algo cumulative time:1.887438333s for 814
I1018 09:56:45.720045       1 scheduler.go:451] ScheduleAlgoTime 2.280706ms Start:2018-10-18 09:56:45.717754922 +0000 UTC m=+22.741238786 End:2018-10-18 09:56:45.720035535 +0000 UTC m=+22.743519492
I1018 09:56:45.720090       1 scheduler.go:454] Total Schedule Algo cumulative time:1.889719039s for 815
I1018 09:56:45.722698       1 scheduler.go:451] ScheduleAlgoTime 2.320623ms Start:2018-10-18 09:56:45.720339354 +0000 UTC m=+22.743823266 End:2018-10-18 09:56:45.722660086 +0000 UTC m=+22.746143889
I1018 09:56:45.722730       1 scheduler.go:454] Total Schedule Algo cumulative time:1.892039662s for 816
I1018 09:56:45.725201       1 scheduler.go:451] ScheduleAlgoTime 2.1625ms Start:2018-10-18 09:56:45.723029612 +0000 UTC m=+22.746513496 End:2018-10-18 09:56:45.725192191 +0000 UTC m=+22.748675996
I1018 09:56:45.725235       1 scheduler.go:454] Total Schedule Algo cumulative time:1.894202162s for 817
I1018 09:56:45.727961       1 scheduler.go:451] ScheduleAlgoTime 2.468719ms Start:2018-10-18 09:56:45.725484454 +0000 UTC m=+22.748968359 End:2018-10-18 09:56:45.727953276 +0000 UTC m=+22.751437078
I1018 09:56:45.727993       1 scheduler.go:454] Total Schedule Algo cumulative time:1.896670881s for 818
I1018 09:56:45.730213       1 scheduler.go:451] ScheduleAlgoTime 1.811159ms Start:2018-10-18 09:56:45.728394334 +0000 UTC m=+22.751878225 End:2018-10-18 09:56:45.730205579 +0000 UTC m=+22.753689384
I1018 09:56:45.730253       1 scheduler.go:454] Total Schedule Algo cumulative time:1.89848204s for 819
I1018 09:56:45.733334       1 scheduler.go:451] ScheduleAlgoTime 2.817738ms Start:2018-10-18 09:56:45.730507002 +0000 UTC m=+22.753990896 End:2018-10-18 09:56:45.733324826 +0000 UTC m=+22.756808634
I1018 09:56:45.733367       1 scheduler.go:454] Total Schedule Algo cumulative time:1.901299778s for 820
I1018 09:56:45.735761       1 scheduler.go:451] ScheduleAlgoTime 2.177482ms Start:2018-10-18 09:56:45.733573174 +0000 UTC m=+22.757057062 End:2018-10-18 09:56:45.73575073 +0000 UTC m=+22.759234544
I1018 09:56:45.735803       1 scheduler.go:454] Total Schedule Algo cumulative time:1.90347726s for 821
I1018 09:56:45.738165       1 scheduler.go:451] ScheduleAlgoTime 1.987459ms Start:2018-10-18 09:56:45.736170242 +0000 UTC m=+22.759654153 End:2018-10-18 09:56:45.738157807 +0000 UTC m=+22.761641612
I1018 09:56:45.738194       1 scheduler.go:454] Total Schedule Algo cumulative time:1.905464719s for 822
I1018 09:56:45.740385       1 scheduler.go:451] ScheduleAlgoTime 1.929559ms Start:2018-10-18 09:56:45.738445015 +0000 UTC m=+22.761928916 End:2018-10-18 09:56:45.740374667 +0000 UTC m=+22.763858475
I1018 09:56:45.740439       1 scheduler.go:454] Total Schedule Algo cumulative time:1.907394278s for 823
I1018 09:56:45.742602       1 scheduler.go:451] ScheduleAlgoTime 2.010135ms Start:2018-10-18 09:56:45.740584726 +0000 UTC m=+22.764068646 End:2018-10-18 09:56:45.742594975 +0000 UTC m=+22.766078781
I1018 09:56:45.742634       1 scheduler.go:454] Total Schedule Algo cumulative time:1.909404413s for 824
I1018 09:56:45.745257       1 scheduler.go:451] ScheduleAlgoTime 2.303079ms Start:2018-10-18 09:56:45.742944465 +0000 UTC m=+22.766428347 End:2018-10-18 09:56:45.745247606 +0000 UTC m=+22.768731426
I1018 09:56:45.745289       1 scheduler.go:454] Total Schedule Algo cumulative time:1.911707492s for 825
I1018 09:56:45.748132       1 scheduler.go:451] ScheduleAlgoTime 2.533808ms Start:2018-10-18 09:56:45.745586197 +0000 UTC m=+22.769070111 End:2018-10-18 09:56:45.748120079 +0000 UTC m=+22.771603919
I1018 09:56:45.748172       1 scheduler.go:454] Total Schedule Algo cumulative time:1.9142413s for 826
I1018 09:56:45.750771       1 scheduler.go:451] ScheduleAlgoTime 2.294821ms Start:2018-10-18 09:56:45.748468384 +0000 UTC m=+22.771952287 End:2018-10-18 09:56:45.750763305 +0000 UTC m=+22.774247108
I1018 09:56:45.750800       1 scheduler.go:454] Total Schedule Algo cumulative time:1.916536121s for 827
I1018 09:56:45.753080       1 scheduler.go:451] ScheduleAlgoTime 2.11146ms Start:2018-10-18 09:56:45.750959729 +0000 UTC m=+22.774443533 End:2018-10-18 09:56:45.753071185 +0000 UTC m=+22.776554993
I1018 09:56:45.753113       1 scheduler.go:454] Total Schedule Algo cumulative time:1.918647581s for 828
I1018 09:56:45.755629       1 scheduler.go:451] ScheduleAlgoTime 2.322836ms Start:2018-10-18 09:56:45.753297319 +0000 UTC m=+22.776781144 End:2018-10-18 09:56:45.755620176 +0000 UTC m=+22.779103980
I1018 09:56:45.755705       1 scheduler.go:454] Total Schedule Algo cumulative time:1.920970417s for 829
I1018 09:56:45.757987       1 scheduler.go:451] ScheduleAlgoTime 2.044314ms Start:2018-10-18 09:56:45.755935704 +0000 UTC m=+22.779419607 End:2018-10-18 09:56:45.757980118 +0000 UTC m=+22.781463921
I1018 09:56:45.758017       1 scheduler.go:454] Total Schedule Algo cumulative time:1.923014731s for 830
I1018 09:56:45.760204       1 scheduler.go:451] ScheduleAlgoTime 1.938109ms Start:2018-10-18 09:56:45.758257276 +0000 UTC m=+22.781741171 End:2018-10-18 09:56:45.760195477 +0000 UTC m=+22.783679280
I1018 09:56:45.760237       1 scheduler.go:454] Total Schedule Algo cumulative time:1.92495284s for 831
I1018 09:56:45.762508       1 scheduler.go:451] ScheduleAlgoTime 1.981127ms Start:2018-10-18 09:56:45.760520439 +0000 UTC m=+22.784004339 End:2018-10-18 09:56:45.76250166 +0000 UTC m=+22.785985466
I1018 09:56:45.762539       1 scheduler.go:454] Total Schedule Algo cumulative time:1.926933967s for 832
I1018 09:56:45.764980       1 scheduler.go:451] ScheduleAlgoTime 2.188627ms Start:2018-10-18 09:56:45.762782591 +0000 UTC m=+22.786266490 End:2018-10-18 09:56:45.764971305 +0000 UTC m=+22.788455117
I1018 09:56:45.765014       1 scheduler.go:454] Total Schedule Algo cumulative time:1.929122594s for 833
I1018 09:56:45.767759       1 scheduler.go:451] ScheduleAlgoTime 2.481306ms Start:2018-10-18 09:56:45.765270071 +0000 UTC m=+22.788753961 End:2018-10-18 09:56:45.767751428 +0000 UTC m=+22.791235267
I1018 09:56:45.767799       1 scheduler.go:454] Total Schedule Algo cumulative time:1.9316039s for 834
I1018 09:56:45.770447       1 scheduler.go:451] ScheduleAlgoTime 2.124768ms Start:2018-10-18 09:56:45.768314898 +0000 UTC m=+22.791798787 End:2018-10-18 09:56:45.77043975 +0000 UTC m=+22.793923555
I1018 09:56:45.770475       1 scheduler.go:454] Total Schedule Algo cumulative time:1.933728668s for 835
I1018 09:56:45.773466       1 scheduler.go:451] ScheduleAlgoTime 2.663094ms Start:2018-10-18 09:56:45.770795339 +0000 UTC m=+22.794279227 End:2018-10-18 09:56:45.773458516 +0000 UTC m=+22.796942321
I1018 09:56:45.773493       1 scheduler.go:454] Total Schedule Algo cumulative time:1.936391762s for 836
I1018 09:56:45.776241       1 scheduler.go:451] ScheduleAlgoTime 2.619313ms Start:2018-10-18 09:56:45.773611499 +0000 UTC m=+22.797095416 End:2018-10-18 09:56:45.776230926 +0000 UTC m=+22.799714729
I1018 09:56:45.776272       1 scheduler.go:454] Total Schedule Algo cumulative time:1.939011075s for 837
I1018 09:56:45.779021       1 scheduler.go:451] ScheduleAlgoTime 2.529607ms Start:2018-10-18 09:56:45.776479399 +0000 UTC m=+22.799963269 End:2018-10-18 09:56:45.779008969 +0000 UTC m=+22.802492876
I1018 09:56:45.779064       1 scheduler.go:454] Total Schedule Algo cumulative time:1.941540682s for 838
I1018 09:56:45.782257       1 scheduler.go:451] ScheduleAlgoTime 2.910243ms Start:2018-10-18 09:56:45.779336611 +0000 UTC m=+22.802820538 End:2018-10-18 09:56:45.782246976 +0000 UTC m=+22.805730781
I1018 09:56:45.782293       1 scheduler.go:454] Total Schedule Algo cumulative time:1.944450925s for 839
I1018 09:56:45.785024       1 scheduler.go:451] ScheduleAlgoTime 2.449967ms Start:2018-10-18 09:56:45.782561954 +0000 UTC m=+22.806045866 End:2018-10-18 09:56:45.785011979 +0000 UTC m=+22.808495833
I1018 09:56:45.785074       1 scheduler.go:454] Total Schedule Algo cumulative time:1.946900892s for 840
I1018 09:56:45.787801       1 scheduler.go:451] ScheduleAlgoTime 2.376256ms Start:2018-10-18 09:56:45.785414007 +0000 UTC m=+22.808897914 End:2018-10-18 09:56:45.787790344 +0000 UTC m=+22.811274170
I1018 09:56:45.787846       1 scheduler.go:454] Total Schedule Algo cumulative time:1.949277148s for 841
I1018 09:56:45.790112       1 scheduler.go:451] ScheduleAlgoTime 1.991714ms Start:2018-10-18 09:56:45.788111885 +0000 UTC m=+22.811595787 End:2018-10-18 09:56:45.790103696 +0000 UTC m=+22.813587501
I1018 09:56:45.790151       1 scheduler.go:454] Total Schedule Algo cumulative time:1.951268862s for 842
I1018 09:56:45.792828       1 scheduler.go:451] ScheduleAlgoTime 2.33893ms Start:2018-10-18 09:56:45.790478574 +0000 UTC m=+22.813962488 End:2018-10-18 09:56:45.792817588 +0000 UTC m=+22.816301418
I1018 09:56:45.792866       1 scheduler.go:454] Total Schedule Algo cumulative time:1.953607792s for 843
I1018 09:56:45.795465       1 scheduler.go:451] ScheduleAlgoTime 2.321701ms Start:2018-10-18 09:56:45.793133536 +0000 UTC m=+22.816617420 End:2018-10-18 09:56:45.795455312 +0000 UTC m=+22.818939121
I1018 09:56:45.795502       1 scheduler.go:454] Total Schedule Algo cumulative time:1.955929493s for 844
I1018 09:56:45.797839       1 scheduler.go:451] ScheduleAlgoTime 1.906759ms Start:2018-10-18 09:56:45.79592389 +0000 UTC m=+22.819407779 End:2018-10-18 09:56:45.797830731 +0000 UTC m=+22.821314538
I1018 09:56:45.797868       1 scheduler.go:454] Total Schedule Algo cumulative time:1.957836252s for 845
I1018 09:56:45.800125       1 scheduler.go:451] ScheduleAlgoTime 2.01355ms Start:2018-10-18 09:56:45.798105184 +0000 UTC m=+22.821589077 End:2018-10-18 09:56:45.800118824 +0000 UTC m=+22.823602627
I1018 09:56:45.800214       1 scheduler.go:454] Total Schedule Algo cumulative time:1.959849802s for 846
I1018 09:56:45.802346       1 scheduler.go:451] ScheduleAlgoTime 1.921727ms Start:2018-10-18 09:56:45.800415072 +0000 UTC m=+22.823898946 End:2018-10-18 09:56:45.802336866 +0000 UTC m=+22.825820673
I1018 09:56:45.802381       1 scheduler.go:454] Total Schedule Algo cumulative time:1.961771529s for 847
I1018 09:56:45.804472       1 scheduler.go:451] ScheduleAlgoTime 1.975648ms Start:2018-10-18 09:56:45.802485321 +0000 UTC m=+22.825969215 End:2018-10-18 09:56:45.8044608 +0000 UTC m=+22.827944863
I1018 09:56:45.804512       1 scheduler.go:454] Total Schedule Algo cumulative time:1.963747177s for 848
I1018 09:56:45.807053       1 scheduler.go:451] ScheduleAlgoTime 2.315889ms Start:2018-10-18 09:56:45.804729469 +0000 UTC m=+22.828213367 End:2018-10-18 09:56:45.807045453 +0000 UTC m=+22.830529256
I1018 09:56:45.807093       1 scheduler.go:454] Total Schedule Algo cumulative time:1.966063066s for 849
I1018 09:56:45.809647       1 scheduler.go:451] ScheduleAlgoTime 2.214213ms Start:2018-10-18 09:56:45.80742429 +0000 UTC m=+22.830908211 End:2018-10-18 09:56:45.80963862 +0000 UTC m=+22.833122424
I1018 09:56:45.809727       1 scheduler.go:454] Total Schedule Algo cumulative time:1.968277279s for 850
I1018 09:56:45.811945       1 scheduler.go:451] ScheduleAlgoTime 1.983713ms Start:2018-10-18 09:56:45.80995448 +0000 UTC m=+22.833438337 End:2018-10-18 09:56:45.811938244 +0000 UTC m=+22.835422050
I1018 09:56:45.811973       1 scheduler.go:454] Total Schedule Algo cumulative time:1.970260992s for 851
I1018 09:56:45.814485       1 scheduler.go:451] ScheduleAlgoTime 2.08622ms Start:2018-10-18 09:56:45.812388478 +0000 UTC m=+22.835872343 End:2018-10-18 09:56:45.814474749 +0000 UTC m=+22.837958563
I1018 09:56:45.814522       1 scheduler.go:454] Total Schedule Algo cumulative time:1.972347212s for 852
I1018 09:56:45.817367       1 scheduler.go:451] ScheduleAlgoTime 2.594575ms Start:2018-10-18 09:56:45.814762545 +0000 UTC m=+22.838246443 End:2018-10-18 09:56:45.8173572 +0000 UTC m=+22.840841018
I1018 09:56:45.817400       1 scheduler.go:454] Total Schedule Algo cumulative time:1.974941787s for 853
I1018 09:56:45.820038       1 scheduler.go:451] ScheduleAlgoTime 2.339211ms Start:2018-10-18 09:56:45.817689802 +0000 UTC m=+22.841173714 End:2018-10-18 09:56:45.820029123 +0000 UTC m=+22.843512925
I1018 09:56:45.820070       1 scheduler.go:454] Total Schedule Algo cumulative time:1.977280998s for 854
I1018 09:56:45.822411       1 scheduler.go:451] ScheduleAlgoTime 2.104704ms Start:2018-10-18 09:56:45.820296973 +0000 UTC m=+22.843780892 End:2018-10-18 09:56:45.82240179 +0000 UTC m=+22.845885596
I1018 09:56:45.822448       1 scheduler.go:454] Total Schedule Algo cumulative time:1.979385702s for 855
I1018 09:56:45.825096       1 scheduler.go:451] ScheduleAlgoTime 2.381402ms Start:2018-10-18 09:56:45.822704065 +0000 UTC m=+22.846187962 End:2018-10-18 09:56:45.825085553 +0000 UTC m=+22.848569364
I1018 09:56:45.825127       1 scheduler.go:454] Total Schedule Algo cumulative time:1.981767104s for 856
I1018 09:56:45.827624       1 scheduler.go:451] ScheduleAlgoTime 2.343892ms Start:2018-10-18 09:56:45.825271153 +0000 UTC m=+22.848754988 End:2018-10-18 09:56:45.827615055 +0000 UTC m=+22.851098880
I1018 09:56:45.827733       1 scheduler.go:454] Total Schedule Algo cumulative time:1.984110996s for 857
I1018 09:56:45.830533       1 scheduler.go:451] ScheduleAlgoTime 2.553176ms Start:2018-10-18 09:56:45.82796622 +0000 UTC m=+22.851450107 End:2018-10-18 09:56:45.830519479 +0000 UTC m=+22.854003283
I1018 09:56:45.830715       1 scheduler.go:454] Total Schedule Algo cumulative time:1.986664172s for 858
I1018 09:56:45.833362       1 scheduler.go:451] ScheduleAlgoTime 2.34623ms Start:2018-10-18 09:56:45.831007148 +0000 UTC m=+22.854491033 End:2018-10-18 09:56:45.833353459 +0000 UTC m=+22.856837263
I1018 09:56:45.833388       1 scheduler.go:454] Total Schedule Algo cumulative time:1.989010402s for 859
I1018 09:56:45.835854       1 scheduler.go:451] ScheduleAlgoTime 2.187537ms Start:2018-10-18 09:56:45.833654464 +0000 UTC m=+22.857138281 End:2018-10-18 09:56:45.835841933 +0000 UTC m=+22.859325818
I1018 09:56:45.835900       1 scheduler.go:454] Total Schedule Algo cumulative time:1.991197939s for 860
I1018 09:56:45.841842       1 scheduler.go:451] ScheduleAlgoTime 5.72686ms Start:2018-10-18 09:56:45.836105603 +0000 UTC m=+22.859589504 End:2018-10-18 09:56:45.84183256 +0000 UTC m=+22.865316364
I1018 09:56:45.841933       1 scheduler.go:454] Total Schedule Algo cumulative time:1.996924799s for 861
I1018 09:56:45.847302       1 scheduler.go:451] ScheduleAlgoTime 3.50786ms Start:2018-10-18 09:56:45.843785105 +0000 UTC m=+22.867268937 End:2018-10-18 09:56:45.847292992 +0000 UTC m=+22.870776797
I1018 09:56:45.847343       1 scheduler.go:454] Total Schedule Algo cumulative time:2.000432659s for 862
I1018 09:56:45.850579       1 scheduler.go:451] ScheduleAlgoTime 3.070709ms Start:2018-10-18 09:56:45.847497682 +0000 UTC m=+22.870981545 End:2018-10-18 09:56:45.850568446 +0000 UTC m=+22.874052254
I1018 09:56:45.850616       1 scheduler.go:454] Total Schedule Algo cumulative time:2.003503368s for 863
I1018 09:56:45.853762       1 scheduler.go:451] ScheduleAlgoTime 2.710882ms Start:2018-10-18 09:56:45.851036231 +0000 UTC m=+22.874520128 End:2018-10-18 09:56:45.853747187 +0000 UTC m=+22.877231010
I1018 09:56:45.853822       1 scheduler.go:454] Total Schedule Algo cumulative time:2.00621425s for 864
I1018 09:56:45.856706       1 scheduler.go:451] ScheduleAlgoTime 2.546519ms Start:2018-10-18 09:56:45.854116525 +0000 UTC m=+22.877600406 End:2018-10-18 09:56:45.85666312 +0000 UTC m=+22.880146925
I1018 09:56:45.856741       1 scheduler.go:454] Total Schedule Algo cumulative time:2.008760769s for 865
I1018 09:56:45.859397       1 scheduler.go:451] ScheduleAlgoTime 2.441403ms Start:2018-10-18 09:56:45.856946395 +0000 UTC m=+22.880430277 End:2018-10-18 09:56:45.859387876 +0000 UTC m=+22.882871680
I1018 09:56:45.859436       1 scheduler.go:454] Total Schedule Algo cumulative time:2.011202172s for 866
I1018 09:56:45.861742       1 scheduler.go:451] ScheduleAlgoTime 2.072594ms Start:2018-10-18 09:56:45.859662514 +0000 UTC m=+22.883146429 End:2018-10-18 09:56:45.861735213 +0000 UTC m=+22.885219023
I1018 09:56:45.861787       1 scheduler.go:454] Total Schedule Algo cumulative time:2.013274766s for 867
I1018 09:56:45.864007       1 scheduler.go:451] ScheduleAlgoTime 1.981295ms Start:2018-10-18 09:56:45.862017704 +0000 UTC m=+22.885501557 End:2018-10-18 09:56:45.863999049 +0000 UTC m=+22.887482852
I1018 09:56:45.864038       1 scheduler.go:454] Total Schedule Algo cumulative time:2.015256061s for 868
I1018 09:56:45.866654       1 scheduler.go:451] ScheduleAlgoTime 2.435856ms Start:2018-10-18 09:56:45.864209947 +0000 UTC m=+22.887693841 End:2018-10-18 09:56:45.866645887 +0000 UTC m=+22.890129697
I1018 09:56:45.866722       1 scheduler.go:454] Total Schedule Algo cumulative time:2.017691917s for 869
I1018 09:56:45.869638       1 scheduler.go:451] ScheduleAlgoTime 2.654534ms Start:2018-10-18 09:56:45.866973264 +0000 UTC m=+22.890457158 End:2018-10-18 09:56:45.869627889 +0000 UTC m=+22.893111692
I1018 09:56:45.869750       1 scheduler.go:454] Total Schedule Algo cumulative time:2.020346451s for 870
I1018 09:56:45.871961       1 scheduler.go:451] ScheduleAlgoTime 1.964032ms Start:2018-10-18 09:56:45.869988961 +0000 UTC m=+22.893472875 End:2018-10-18 09:56:45.871953102 +0000 UTC m=+22.895436907
I1018 09:56:45.872044       1 scheduler.go:454] Total Schedule Algo cumulative time:2.022310483s for 871
I1018 09:56:45.875332       1 scheduler.go:451] ScheduleAlgoTime 2.998741ms Start:2018-10-18 09:56:45.872325542 +0000 UTC m=+22.895809467 End:2018-10-18 09:56:45.875324402 +0000 UTC m=+22.898808208
I1018 09:56:45.875364       1 scheduler.go:454] Total Schedule Algo cumulative time:2.025309224s for 872
I1018 09:56:45.877591       1 scheduler.go:451] ScheduleAlgoTime 2.04108ms Start:2018-10-18 09:56:45.875539916 +0000 UTC m=+22.899023811 End:2018-10-18 09:56:45.877581084 +0000 UTC m=+22.901064891
I1018 09:56:45.877624       1 scheduler.go:454] Total Schedule Algo cumulative time:2.027350304s for 873
I1018 09:56:45.880052       1 scheduler.go:451] ScheduleAlgoTime 2.093133ms Start:2018-10-18 09:56:45.877875279 +0000 UTC m=+22.901359161 End:2018-10-18 09:56:45.879968382 +0000 UTC m=+22.903452294
I1018 09:56:45.880093       1 scheduler.go:454] Total Schedule Algo cumulative time:2.029443437s for 874
I1018 09:56:45.882615       1 scheduler.go:451] ScheduleAlgoTime 2.308715ms Start:2018-10-18 09:56:45.880295384 +0000 UTC m=+22.903779279 End:2018-10-18 09:56:45.882604187 +0000 UTC m=+22.906087994
I1018 09:56:45.882654       1 scheduler.go:454] Total Schedule Algo cumulative time:2.031752152s for 875
I1018 09:56:45.884841       1 scheduler.go:451] ScheduleAlgoTime 1.962835ms Start:2018-10-18 09:56:45.882870325 +0000 UTC m=+22.906354165 End:2018-10-18 09:56:45.884833197 +0000 UTC m=+22.908317000
I1018 09:56:45.884871       1 scheduler.go:454] Total Schedule Algo cumulative time:2.033714987s for 876
I1018 09:56:45.887189       1 scheduler.go:451] ScheduleAlgoTime 2.075393ms Start:2018-10-18 09:56:45.885102196 +0000 UTC m=+22.908586079 End:2018-10-18 09:56:45.887177591 +0000 UTC m=+22.910661472
I1018 09:56:45.887244       1 scheduler.go:454] Total Schedule Algo cumulative time:2.03579038s for 877
I1018 09:56:45.889511       1 scheduler.go:451] ScheduleAlgoTime 1.994349ms Start:2018-10-18 09:56:45.887507818 +0000 UTC m=+22.910991696 End:2018-10-18 09:56:45.889502239 +0000 UTC m=+22.912986045
I1018 09:56:45.889543       1 scheduler.go:454] Total Schedule Algo cumulative time:2.037784729s for 878
I1018 09:56:45.891841       1 scheduler.go:451] ScheduleAlgoTime 2.09809ms Start:2018-10-18 09:56:45.889736298 +0000 UTC m=+22.913220118 End:2018-10-18 09:56:45.891834399 +0000 UTC m=+22.915318208
I1018 09:56:45.891885       1 scheduler.go:454] Total Schedule Algo cumulative time:2.039882819s for 879
I1018 09:56:45.894251       1 scheduler.go:451] ScheduleAlgoTime 2.142383ms Start:2018-10-18 09:56:45.89209806 +0000 UTC m=+22.915581945 End:2018-10-18 09:56:45.894240525 +0000 UTC m=+22.917724328
I1018 09:56:45.894292       1 scheduler.go:454] Total Schedule Algo cumulative time:2.042025202s for 880
I1018 09:56:45.896435       1 scheduler.go:451] ScheduleAlgoTime 1.997979ms Start:2018-10-18 09:56:45.8944301 +0000 UTC m=+22.917913981 End:2018-10-18 09:56:45.896428151 +0000 UTC m=+22.919911960
I1018 09:56:45.896468       1 scheduler.go:454] Total Schedule Algo cumulative time:2.044023181s for 881
I1018 09:56:45.898567       1 scheduler.go:451] ScheduleAlgoTime 1.852732ms Start:2018-10-18 09:56:45.896708292 +0000 UTC m=+22.920192187 End:2018-10-18 09:56:45.898561114 +0000 UTC m=+22.922044919
I1018 09:56:45.898596       1 scheduler.go:454] Total Schedule Algo cumulative time:2.045875913s for 882
I1018 09:56:45.900870       1 scheduler.go:451] ScheduleAlgoTime 2.07067ms Start:2018-10-18 09:56:45.898791051 +0000 UTC m=+22.922274960 End:2018-10-18 09:56:45.900861825 +0000 UTC m=+22.924345630
I1018 09:56:45.900897       1 scheduler.go:454] Total Schedule Algo cumulative time:2.047946583s for 883
I1018 09:56:45.903092       1 scheduler.go:451] ScheduleAlgoTime 2.001064ms Start:2018-10-18 09:56:45.901081558 +0000 UTC m=+22.924565366 End:2018-10-18 09:56:45.903082622 +0000 UTC m=+22.926566430
I1018 09:56:45.903126       1 scheduler.go:454] Total Schedule Algo cumulative time:2.049947647s for 884
I1018 09:56:45.905772       1 scheduler.go:451] ScheduleAlgoTime 2.17137ms Start:2018-10-18 09:56:45.903592415 +0000 UTC m=+22.927076296 End:2018-10-18 09:56:45.905763861 +0000 UTC m=+22.929247666
I1018 09:56:45.905808       1 scheduler.go:454] Total Schedule Algo cumulative time:2.052119017s for 885
I1018 09:56:45.907893       1 scheduler.go:451] ScheduleAlgoTime 1.899739ms Start:2018-10-18 09:56:45.905985007 +0000 UTC m=+22.929468894 End:2018-10-18 09:56:45.907884825 +0000 UTC m=+22.931368633
I1018 09:56:45.907925       1 scheduler.go:454] Total Schedule Algo cumulative time:2.054018756s for 886
I1018 09:56:45.910195       1 scheduler.go:451] ScheduleAlgoTime 2.061974ms Start:2018-10-18 09:56:45.908118995 +0000 UTC m=+22.931602888 End:2018-10-18 09:56:45.910181061 +0000 UTC m=+22.933664862
I1018 09:56:45.910227       1 scheduler.go:454] Total Schedule Algo cumulative time:2.05608073s for 887
I1018 09:56:45.913149       1 scheduler.go:451] ScheduleAlgoTime 2.26477ms Start:2018-10-18 09:56:45.91087467 +0000 UTC m=+22.934358553 End:2018-10-18 09:56:45.913139396 +0000 UTC m=+22.936623323
I1018 09:56:45.913189       1 scheduler.go:454] Total Schedule Algo cumulative time:2.0583455s for 888
I1018 09:56:45.915626       1 scheduler.go:451] ScheduleAlgoTime 2.235774ms Start:2018-10-18 09:56:45.913383594 +0000 UTC m=+22.936867483 End:2018-10-18 09:56:45.915619449 +0000 UTC m=+22.939103257
I1018 09:56:45.915658       1 scheduler.go:454] Total Schedule Algo cumulative time:2.060581274s for 889
I1018 09:56:45.918123       1 scheduler.go:451] ScheduleAlgoTime 2.0596ms Start:2018-10-18 09:56:45.916052602 +0000 UTC m=+22.939536502 End:2018-10-18 09:56:45.918112194 +0000 UTC m=+22.941596102
I1018 09:56:45.918166       1 scheduler.go:454] Total Schedule Algo cumulative time:2.062640874s for 890
I1018 09:56:45.920309       1 scheduler.go:451] ScheduleAlgoTime 1.950181ms Start:2018-10-18 09:56:45.918350455 +0000 UTC m=+22.941834258 End:2018-10-18 09:56:45.920300634 +0000 UTC m=+22.943784439
I1018 09:56:45.920339       1 scheduler.go:454] Total Schedule Algo cumulative time:2.064591055s for 891
I1018 09:56:45.922958       1 scheduler.go:451] ScheduleAlgoTime 2.420927ms Start:2018-10-18 09:56:45.920527758 +0000 UTC m=+22.944011688 End:2018-10-18 09:56:45.922948807 +0000 UTC m=+22.946432615
I1018 09:56:45.922993       1 scheduler.go:454] Total Schedule Algo cumulative time:2.067011982s for 892
I1018 09:56:45.925536       1 scheduler.go:451] ScheduleAlgoTime 2.324254ms Start:2018-10-18 09:56:45.923203121 +0000 UTC m=+22.946686980 End:2018-10-18 09:56:45.925527431 +0000 UTC m=+22.949011234
I1018 09:56:45.925567       1 scheduler.go:454] Total Schedule Algo cumulative time:2.069336236s for 893
I1018 09:56:45.928225       1 scheduler.go:451] ScheduleAlgoTime 2.482473ms Start:2018-10-18 09:56:45.925733526 +0000 UTC m=+22.949217417 End:2018-10-18 09:56:45.928216087 +0000 UTC m=+22.951699890
I1018 09:56:45.928276       1 scheduler.go:454] Total Schedule Algo cumulative time:2.071818709s for 894
I1018 09:56:45.931392       1 scheduler.go:451] ScheduleAlgoTime 2.79228ms Start:2018-10-18 09:56:45.928587834 +0000 UTC m=+22.952071771 End:2018-10-18 09:56:45.931380241 +0000 UTC m=+22.954864051
I1018 09:56:45.931435       1 scheduler.go:454] Total Schedule Algo cumulative time:2.074610989s for 895
I1018 09:56:45.934443       1 scheduler.go:451] ScheduleAlgoTime 2.470418ms Start:2018-10-18 09:56:45.931962861 +0000 UTC m=+22.955446783 End:2018-10-18 09:56:45.934433396 +0000 UTC m=+22.957917201
I1018 09:56:45.934477       1 scheduler.go:454] Total Schedule Algo cumulative time:2.077081407s for 896
I1018 09:56:45.936745       1 scheduler.go:451] ScheduleAlgoTime 2.129635ms Start:2018-10-18 09:56:45.934606584 +0000 UTC m=+22.958090520 End:2018-10-18 09:56:45.936736348 +0000 UTC m=+22.960220155
I1018 09:56:45.936775       1 scheduler.go:454] Total Schedule Algo cumulative time:2.079211042s for 897
I1018 09:56:45.939293       1 scheduler.go:451] ScheduleAlgoTime 2.324293ms Start:2018-10-18 09:56:45.936959551 +0000 UTC m=+22.960443419 End:2018-10-18 09:56:45.939283831 +0000 UTC m=+22.962767712
I1018 09:56:45.939329       1 scheduler.go:454] Total Schedule Algo cumulative time:2.081535335s for 898
I1018 09:56:45.942124       1 scheduler.go:451] ScheduleAlgoTime 2.585092ms Start:2018-10-18 09:56:45.939530783 +0000 UTC m=+22.963014728 End:2018-10-18 09:56:45.942116016 +0000 UTC m=+22.965599820
I1018 09:56:45.942154       1 scheduler.go:454] Total Schedule Algo cumulative time:2.084120427s for 899
I1018 09:56:45.944484       1 scheduler.go:451] ScheduleAlgoTime 2.129061ms Start:2018-10-18 09:56:45.942346885 +0000 UTC m=+22.965830775 End:2018-10-18 09:56:45.944476033 +0000 UTC m=+22.967959836
I1018 09:56:45.944510       1 scheduler.go:454] Total Schedule Algo cumulative time:2.086249488s for 900
I1018 09:56:45.946942       1 scheduler.go:451] ScheduleAlgoTime 2.161405ms Start:2018-10-18 09:56:45.944767302 +0000 UTC m=+22.968251209 End:2018-10-18 09:56:45.946928753 +0000 UTC m=+22.970412614
I1018 09:56:45.946987       1 scheduler.go:454] Total Schedule Algo cumulative time:2.088410893s for 901
I1018 09:56:45.949445       1 scheduler.go:451] ScheduleAlgoTime 2.15782ms Start:2018-10-18 09:56:45.947279622 +0000 UTC m=+22.970763489 End:2018-10-18 09:56:45.949437507 +0000 UTC m=+22.972921309
I1018 09:56:45.949474       1 scheduler.go:454] Total Schedule Algo cumulative time:2.090568713s for 902
I1018 09:56:45.951805       1 scheduler.go:451] ScheduleAlgoTime 2.068735ms Start:2018-10-18 09:56:45.949727458 +0000 UTC m=+22.973211372 End:2018-10-18 09:56:45.951796303 +0000 UTC m=+22.975280107
I1018 09:56:45.951839       1 scheduler.go:454] Total Schedule Algo cumulative time:2.092637448s for 903
I1018 09:56:45.954338       1 scheduler.go:451] ScheduleAlgoTime 2.300609ms Start:2018-10-18 09:56:45.952028409 +0000 UTC m=+22.975512317 End:2018-10-18 09:56:45.954329123 +0000 UTC m=+22.977812926
I1018 09:56:45.954371       1 scheduler.go:454] Total Schedule Algo cumulative time:2.094938057s for 904
I1018 09:56:45.956660       1 scheduler.go:451] ScheduleAlgoTime 2.149482ms Start:2018-10-18 09:56:45.954501117 +0000 UTC m=+22.977985016 End:2018-10-18 09:56:45.956650689 +0000 UTC m=+22.980134498
I1018 09:56:45.956718       1 scheduler.go:454] Total Schedule Algo cumulative time:2.097087539s for 905
I1018 09:56:45.959110       1 scheduler.go:451] ScheduleAlgoTime 2.142387ms Start:2018-10-18 09:56:45.956957589 +0000 UTC m=+22.980441486 End:2018-10-18 09:56:45.959100069 +0000 UTC m=+22.982583873
I1018 09:56:45.959149       1 scheduler.go:454] Total Schedule Algo cumulative time:2.099229926s for 906
I1018 09:56:45.961641       1 scheduler.go:451] ScheduleAlgoTime 2.106287ms Start:2018-10-18 09:56:45.959525262 +0000 UTC m=+22.983009150 End:2018-10-18 09:56:45.961631631 +0000 UTC m=+22.985115437
I1018 09:56:45.961721       1 scheduler.go:454] Total Schedule Algo cumulative time:2.101336213s for 907
I1018 09:56:45.964290       1 scheduler.go:451] ScheduleAlgoTime 2.331603ms Start:2018-10-18 09:56:45.961947317 +0000 UTC m=+22.985431204 End:2018-10-18 09:56:45.964278889 +0000 UTC m=+22.987762807
I1018 09:56:45.964325       1 scheduler.go:454] Total Schedule Algo cumulative time:2.103667816s for 908
I1018 09:56:45.966877       1 scheduler.go:451] ScheduleAlgoTime 2.154351ms Start:2018-10-18 09:56:45.964714271 +0000 UTC m=+22.988198181 End:2018-10-18 09:56:45.966868701 +0000 UTC m=+22.990352532
I1018 09:56:45.966909       1 scheduler.go:454] Total Schedule Algo cumulative time:2.105822167s for 909
I1018 09:56:45.970266       1 scheduler.go:451] ScheduleAlgoTime 3.023423ms Start:2018-10-18 09:56:45.96723255 +0000 UTC m=+22.990716402 End:2018-10-18 09:56:45.970256023 +0000 UTC m=+22.993739825
I1018 09:56:45.970303       1 scheduler.go:454] Total Schedule Algo cumulative time:2.10884559s for 910
I1018 09:56:45.972661       1 scheduler.go:451] ScheduleAlgoTime 2.099557ms Start:2018-10-18 09:56:45.970551261 +0000 UTC m=+22.994035168 End:2018-10-18 09:56:45.972650921 +0000 UTC m=+22.996134725
I1018 09:56:45.972713       1 scheduler.go:454] Total Schedule Algo cumulative time:2.110945147s for 911
I1018 09:56:45.975513       1 scheduler.go:451] ScheduleAlgoTime 2.59961ms Start:2018-10-18 09:56:45.972901533 +0000 UTC m=+22.996385420 End:2018-10-18 09:56:45.975501126 +0000 UTC m=+22.998985030
I1018 09:56:45.975549       1 scheduler.go:454] Total Schedule Algo cumulative time:2.113544757s for 912
I1018 09:56:45.977952       1 scheduler.go:451] ScheduleAlgoTime 2.240215ms Start:2018-10-18 09:56:45.975702709 +0000 UTC m=+22.999186616 End:2018-10-18 09:56:45.977943028 +0000 UTC m=+23.001426831
I1018 09:56:45.977981       1 scheduler.go:454] Total Schedule Algo cumulative time:2.115784972s for 913
I1018 09:56:45.981326       1 scheduler.go:451] ScheduleAlgoTime 3.060317ms Start:2018-10-18 09:56:45.978256732 +0000 UTC m=+23.001740610 End:2018-10-18 09:56:45.981317117 +0000 UTC m=+23.004800927
I1018 09:56:45.981372       1 scheduler.go:454] Total Schedule Algo cumulative time:2.118845289s for 914
I1018 09:56:45.983820       1 scheduler.go:451] ScheduleAlgoTime 2.185638ms Start:2018-10-18 09:56:45.981624963 +0000 UTC m=+23.005108848 End:2018-10-18 09:56:45.983810655 +0000 UTC m=+23.007294486
I1018 09:56:45.983856       1 scheduler.go:454] Total Schedule Algo cumulative time:2.121030927s for 915
I1018 09:56:45.986444       1 scheduler.go:451] ScheduleAlgoTime 2.352098ms Start:2018-10-18 09:56:45.984080937 +0000 UTC m=+23.007564825 End:2018-10-18 09:56:45.986433114 +0000 UTC m=+23.009916923
I1018 09:56:45.986479       1 scheduler.go:454] Total Schedule Algo cumulative time:2.123383025s for 916
I1018 09:56:45.988650       1 scheduler.go:451] ScheduleAlgoTime 1.945764ms Start:2018-10-18 09:56:45.986696854 +0000 UTC m=+23.010180739 End:2018-10-18 09:56:45.9886427 +0000 UTC m=+23.012126503
I1018 09:56:45.988716       1 scheduler.go:454] Total Schedule Algo cumulative time:2.125328789s for 917
I1018 09:56:45.991093       1 scheduler.go:451] ScheduleAlgoTime 2.008614ms Start:2018-10-18 09:56:45.989076367 +0000 UTC m=+23.012560259 End:2018-10-18 09:56:45.991085069 +0000 UTC m=+23.014568873
I1018 09:56:45.991124       1 scheduler.go:454] Total Schedule Algo cumulative time:2.127337403s for 918
I1018 09:56:45.993092       1 scheduler.go:451] ScheduleAlgoTime 1.829006ms Start:2018-10-18 09:56:45.991254006 +0000 UTC m=+23.014737809 End:2018-10-18 09:56:45.993082891 +0000 UTC m=+23.016566815
I1018 09:56:45.993126       1 scheduler.go:454] Total Schedule Algo cumulative time:2.129166409s for 919
I1018 09:56:45.996093       1 scheduler.go:451] ScheduleAlgoTime 2.654878ms Start:2018-10-18 09:56:45.993429558 +0000 UTC m=+23.016913485 End:2018-10-18 09:56:45.996084552 +0000 UTC m=+23.019568363
I1018 09:56:45.996122       1 scheduler.go:454] Total Schedule Algo cumulative time:2.131821287s for 920
I1018 09:56:45.998763       1 scheduler.go:451] ScheduleAlgoTime 2.340374ms Start:2018-10-18 09:56:45.996413355 +0000 UTC m=+23.019897252 End:2018-10-18 09:56:45.998753817 +0000 UTC m=+23.022237626
I1018 09:56:45.998816       1 scheduler.go:454] Total Schedule Algo cumulative time:2.134161661s for 921
I1018 09:56:46.001169       1 scheduler.go:451] ScheduleAlgoTime 2.053866ms Start:2018-10-18 09:56:45.999106595 +0000 UTC m=+23.022590507 End:2018-10-18 09:56:46.001160568 +0000 UTC m=+23.024644373
I1018 09:56:46.001200       1 scheduler.go:454] Total Schedule Algo cumulative time:2.136215527s for 922
I1018 09:56:46.003792       1 scheduler.go:451] ScheduleAlgoTime 2.234376ms Start:2018-10-18 09:56:46.001548886 +0000 UTC m=+23.025032760 End:2018-10-18 09:56:46.003783332 +0000 UTC m=+23.027267136
I1018 09:56:46.003827       1 scheduler.go:454] Total Schedule Algo cumulative time:2.138449903s for 923
I1018 09:56:46.006962       1 scheduler.go:451] ScheduleAlgoTime 2.714912ms Start:2018-10-18 09:56:46.004236789 +0000 UTC m=+23.027720694 End:2018-10-18 09:56:46.006951788 +0000 UTC m=+23.030435606
I1018 09:56:46.007006       1 scheduler.go:454] Total Schedule Algo cumulative time:2.141164815s for 924
I1018 09:56:46.010082       1 scheduler.go:451] ScheduleAlgoTime 2.845675ms Start:2018-10-18 09:56:46.00722941 +0000 UTC m=+23.030713321 End:2018-10-18 09:56:46.010075193 +0000 UTC m=+23.033558996
I1018 09:56:46.010123       1 scheduler.go:454] Total Schedule Algo cumulative time:2.14401049s for 925
I1018 09:56:46.013628       1 scheduler.go:451] ScheduleAlgoTime 3.069611ms Start:2018-10-18 09:56:46.010548788 +0000 UTC m=+23.034032697 End:2018-10-18 09:56:46.013618349 +0000 UTC m=+23.037102308
I1018 09:56:46.013740       1 scheduler.go:454] Total Schedule Algo cumulative time:2.147080101s for 926
I1018 09:56:46.017122       1 scheduler.go:451] ScheduleAlgoTime 2.98798ms Start:2018-10-18 09:56:46.014122504 +0000 UTC m=+23.037606385 End:2018-10-18 09:56:46.017110563 +0000 UTC m=+23.040594365
I1018 09:56:46.017152       1 scheduler.go:454] Total Schedule Algo cumulative time:2.150068081s for 927
I1018 09:56:46.023098       1 scheduler.go:451] ScheduleAlgoTime 5.783354ms Start:2018-10-18 09:56:46.017301414 +0000 UTC m=+23.040785309 End:2018-10-18 09:56:46.023084856 +0000 UTC m=+23.046568663
I1018 09:56:46.023162       1 scheduler.go:454] Total Schedule Algo cumulative time:2.155851435s for 928
I1018 09:56:46.031451       1 scheduler.go:451] ScheduleAlgoTime 7.718186ms Start:2018-10-18 09:56:46.023723236 +0000 UTC m=+23.047207039 End:2018-10-18 09:56:46.03144142 +0000 UTC m=+23.054925225
I1018 09:56:46.031487       1 scheduler.go:454] Total Schedule Algo cumulative time:2.163569621s for 929
I1018 09:56:46.034214       1 scheduler.go:451] ScheduleAlgoTime 2.554148ms Start:2018-10-18 09:56:46.031652557 +0000 UTC m=+23.055136442 End:2018-10-18 09:56:46.034206785 +0000 UTC m=+23.057690590
I1018 09:56:46.034243       1 scheduler.go:454] Total Schedule Algo cumulative time:2.166123769s for 930
I1018 09:56:46.037020       1 scheduler.go:451] ScheduleAlgoTime 2.622511ms Start:2018-10-18 09:56:46.034389328 +0000 UTC m=+23.057873168 End:2018-10-18 09:56:46.037011874 +0000 UTC m=+23.060495679
I1018 09:56:46.037057       1 scheduler.go:454] Total Schedule Algo cumulative time:2.16874628s for 931
I1018 09:56:46.039895       1 scheduler.go:451] ScheduleAlgoTime 2.636419ms Start:2018-10-18 09:56:46.03724918 +0000 UTC m=+23.060733099 End:2018-10-18 09:56:46.039885712 +0000 UTC m=+23.063369518
I1018 09:56:46.039929       1 scheduler.go:454] Total Schedule Algo cumulative time:2.171382699s for 932
I1018 09:56:46.042452       1 scheduler.go:451] ScheduleAlgoTime 2.353507ms Start:2018-10-18 09:56:46.04008935 +0000 UTC m=+23.063573177 End:2018-10-18 09:56:46.042442879 +0000 UTC m=+23.065926684
I1018 09:56:46.042498       1 scheduler.go:454] Total Schedule Algo cumulative time:2.173736206s for 933
I1018 09:56:46.045344       1 scheduler.go:451] ScheduleAlgoTime 2.620776ms Start:2018-10-18 09:56:46.042716098 +0000 UTC m=+23.066199973 End:2018-10-18 09:56:46.045336946 +0000 UTC m=+23.068820749
I1018 09:56:46.045375       1 scheduler.go:454] Total Schedule Algo cumulative time:2.176356982s for 934
I1018 09:56:46.047745       1 scheduler.go:451] ScheduleAlgoTime 2.0913ms Start:2018-10-18 09:56:46.045641894 +0000 UTC m=+23.069125769 End:2018-10-18 09:56:46.04773315 +0000 UTC m=+23.071217069
I1018 09:56:46.047809       1 scheduler.go:454] Total Schedule Algo cumulative time:2.178448282s for 935
I1018 09:56:46.050575       1 scheduler.go:451] ScheduleAlgoTime 2.438089ms Start:2018-10-18 09:56:46.048128297 +0000 UTC m=+23.071612165 End:2018-10-18 09:56:46.050566444 +0000 UTC m=+23.074050254
I1018 09:56:46.050610       1 scheduler.go:454] Total Schedule Algo cumulative time:2.180886371s for 936
I1018 09:56:46.053147       1 scheduler.go:451] ScheduleAlgoTime 2.235717ms Start:2018-10-18 09:56:46.050902818 +0000 UTC m=+23.074386691 End:2018-10-18 09:56:46.053138604 +0000 UTC m=+23.076622408
I1018 09:56:46.053176       1 scheduler.go:454] Total Schedule Algo cumulative time:2.183122088s for 937
I1018 09:56:46.055503       1 scheduler.go:451] ScheduleAlgoTime 2.133261ms Start:2018-10-18 09:56:46.053362463 +0000 UTC m=+23.076846370 End:2018-10-18 09:56:46.05549583 +0000 UTC m=+23.078979631
I1018 09:56:46.055542       1 scheduler.go:454] Total Schedule Algo cumulative time:2.185255349s for 938
I1018 09:56:46.058404       1 scheduler.go:451] ScheduleAlgoTime 2.611179ms Start:2018-10-18 09:56:46.055779129 +0000 UTC m=+23.079263006 End:2018-10-18 09:56:46.058390265 +0000 UTC m=+23.081874185
I1018 09:56:46.058463       1 scheduler.go:454] Total Schedule Algo cumulative time:2.187866528s for 939
I1018 09:56:46.060831       1 scheduler.go:451] ScheduleAlgoTime 2.125604ms Start:2018-10-18 09:56:46.058696802 +0000 UTC m=+23.082180682 End:2018-10-18 09:56:46.060822483 +0000 UTC m=+23.084306286
I1018 09:56:46.060868       1 scheduler.go:454] Total Schedule Algo cumulative time:2.189992132s for 940
I1018 09:56:46.063689       1 scheduler.go:451] ScheduleAlgoTime 2.57322ms Start:2018-10-18 09:56:46.061082883 +0000 UTC m=+23.084566785 End:2018-10-18 09:56:46.063656201 +0000 UTC m=+23.087140005
I1018 09:56:46.063723       1 scheduler.go:454] Total Schedule Algo cumulative time:2.192565352s for 941
I1018 09:56:46.066252       1 scheduler.go:451] ScheduleAlgoTime 2.289328ms Start:2018-10-18 09:56:46.063955084 +0000 UTC m=+23.087438969 End:2018-10-18 09:56:46.066244494 +0000 UTC m=+23.089728297
I1018 09:56:46.066282       1 scheduler.go:454] Total Schedule Algo cumulative time:2.19485468s for 942
I1018 09:56:46.068697       1 scheduler.go:451] ScheduleAlgoTime 2.21562ms Start:2018-10-18 09:56:46.066445246 +0000 UTC m=+23.089929051 End:2018-10-18 09:56:46.068660856 +0000 UTC m=+23.092144671
I1018 09:56:46.068726       1 scheduler.go:454] Total Schedule Algo cumulative time:2.1970703s for 943
I1018 09:56:46.071159       1 scheduler.go:451] ScheduleAlgoTime 2.275264ms Start:2018-10-18 09:56:46.068869691 +0000 UTC m=+23.092353529 End:2018-10-18 09:56:46.071144942 +0000 UTC m=+23.094628793
I1018 09:56:46.071262       1 scheduler.go:454] Total Schedule Algo cumulative time:2.199345564s for 944
I1018 09:56:46.073729       1 scheduler.go:451] ScheduleAlgoTime 2.199911ms Start:2018-10-18 09:56:46.071498275 +0000 UTC m=+23.094982141 End:2018-10-18 09:56:46.07369825 +0000 UTC m=+23.097182052
I1018 09:56:46.073760       1 scheduler.go:454] Total Schedule Algo cumulative time:2.201545475s for 945
I1018 09:56:46.076864       1 scheduler.go:451] ScheduleAlgoTime 2.869016ms Start:2018-10-18 09:56:46.073987146 +0000 UTC m=+23.097471036 End:2018-10-18 09:56:46.076856249 +0000 UTC m=+23.100340052
I1018 09:56:46.076896       1 scheduler.go:454] Total Schedule Algo cumulative time:2.204414491s for 946
I1018 09:56:46.079927       1 scheduler.go:451] ScheduleAlgoTime 2.79077ms Start:2018-10-18 09:56:46.077123023 +0000 UTC m=+23.100606935 End:2018-10-18 09:56:46.079913769 +0000 UTC m=+23.103397705
I1018 09:56:46.079973       1 scheduler.go:454] Total Schedule Algo cumulative time:2.207205261s for 947
I1018 09:56:46.083060       1 scheduler.go:451] ScheduleAlgoTime 2.745954ms Start:2018-10-18 09:56:46.080305505 +0000 UTC m=+23.103789392 End:2018-10-18 09:56:46.083051537 +0000 UTC m=+23.106535346
I1018 09:56:46.083102       1 scheduler.go:454] Total Schedule Algo cumulative time:2.209951215s for 948
I1018 09:56:46.085653       1 scheduler.go:451] ScheduleAlgoTime 2.291958ms Start:2018-10-18 09:56:46.083352071 +0000 UTC m=+23.106835954 End:2018-10-18 09:56:46.085644109 +0000 UTC m=+23.109127912
I1018 09:56:46.085745       1 scheduler.go:454] Total Schedule Algo cumulative time:2.212243173s for 949
I1018 09:56:46.088182       1 scheduler.go:451] ScheduleAlgoTime 2.033995ms Start:2018-10-18 09:56:46.086140185 +0000 UTC m=+23.109624052 End:2018-10-18 09:56:46.088174241 +0000 UTC m=+23.111658047
I1018 09:56:46.088212       1 scheduler.go:454] Total Schedule Algo cumulative time:2.214277168s for 950
I1018 09:56:46.090439       1 scheduler.go:451] ScheduleAlgoTime 1.981835ms Start:2018-10-18 09:56:46.088451017 +0000 UTC m=+23.111934918 End:2018-10-18 09:56:46.090432946 +0000 UTC m=+23.113916753
I1018 09:56:46.090467       1 scheduler.go:454] Total Schedule Algo cumulative time:2.216259003s for 951
I1018 09:56:46.093872       1 scheduler.go:451] ScheduleAlgoTime 3.158124ms Start:2018-10-18 09:56:46.090706413 +0000 UTC m=+23.114190299 End:2018-10-18 09:56:46.09386462 +0000 UTC m=+23.117348423
I1018 09:56:46.093911       1 scheduler.go:454] Total Schedule Algo cumulative time:2.219417127s for 952
I1018 09:56:46.096730       1 scheduler.go:451] ScheduleAlgoTime 2.465149ms Start:2018-10-18 09:56:46.094255256 +0000 UTC m=+23.117739133 End:2018-10-18 09:56:46.096720477 +0000 UTC m=+23.120204282
I1018 09:56:46.096765       1 scheduler.go:454] Total Schedule Algo cumulative time:2.221882276s for 953
I1018 09:56:46.099409       1 scheduler.go:451] ScheduleAlgoTime 2.356488ms Start:2018-10-18 09:56:46.097043215 +0000 UTC m=+23.120527112 End:2018-10-18 09:56:46.099399796 +0000 UTC m=+23.122883600
I1018 09:56:46.099467       1 scheduler.go:454] Total Schedule Algo cumulative time:2.224238764s for 954
I1018 09:56:46.102219       1 scheduler.go:451] ScheduleAlgoTime 2.425785ms Start:2018-10-18 09:56:46.09978473 +0000 UTC m=+23.123268596 End:2018-10-18 09:56:46.102210575 +0000 UTC m=+23.125694381
I1018 09:56:46.102257       1 scheduler.go:454] Total Schedule Algo cumulative time:2.226664549s for 955
I1018 09:56:46.105116       1 scheduler.go:451] ScheduleAlgoTime 2.522519ms Start:2018-10-18 09:56:46.102584728 +0000 UTC m=+23.126068607 End:2018-10-18 09:56:46.105107319 +0000 UTC m=+23.128591126
I1018 09:56:46.105146       1 scheduler.go:454] Total Schedule Algo cumulative time:2.229187068s for 956
I1018 09:56:46.107604       1 scheduler.go:451] ScheduleAlgoTime 2.158792ms Start:2018-10-18 09:56:46.105435596 +0000 UTC m=+23.128919481 End:2018-10-18 09:56:46.10759447 +0000 UTC m=+23.131078273
I1018 09:56:46.107637       1 scheduler.go:454] Total Schedule Algo cumulative time:2.23134586s for 957
I1018 09:56:46.110087       1 scheduler.go:451] ScheduleAlgoTime 2.123518ms Start:2018-10-18 09:56:46.107951798 +0000 UTC m=+23.131435698 End:2018-10-18 09:56:46.110075252 +0000 UTC m=+23.133559216
I1018 09:56:46.110131       1 scheduler.go:454] Total Schedule Algo cumulative time:2.233469378s for 958
I1018 09:56:46.112807       1 scheduler.go:451] ScheduleAlgoTime 2.450965ms Start:2018-10-18 09:56:46.110348509 +0000 UTC m=+23.133832398 End:2018-10-18 09:56:46.112799558 +0000 UTC m=+23.136283363
I1018 09:56:46.112836       1 scheduler.go:454] Total Schedule Algo cumulative time:2.235920343s for 959
I1018 09:56:46.115750       1 scheduler.go:451] ScheduleAlgoTime 2.540304ms Start:2018-10-18 09:56:46.113201538 +0000 UTC m=+23.136685412 End:2018-10-18 09:56:46.115741908 +0000 UTC m=+23.139225716
I1018 09:56:46.115789       1 scheduler.go:454] Total Schedule Algo cumulative time:2.238460647s for 960
I1018 09:56:46.118216       1 scheduler.go:451] ScheduleAlgoTime 2.280728ms Start:2018-10-18 09:56:46.115925765 +0000 UTC m=+23.139409570 End:2018-10-18 09:56:46.118206496 +0000 UTC m=+23.141690298
I1018 09:56:46.118249       1 scheduler.go:454] Total Schedule Algo cumulative time:2.240741375s for 961
I1018 09:56:46.120454       1 scheduler.go:451] ScheduleAlgoTime 1.928586ms Start:2018-10-18 09:56:46.118517489 +0000 UTC m=+23.142001377 End:2018-10-18 09:56:46.120446158 +0000 UTC m=+23.143929963
I1018 09:56:46.120502       1 scheduler.go:454] Total Schedule Algo cumulative time:2.242669961s for 962
I1018 09:56:46.122736       1 scheduler.go:451] ScheduleAlgoTime 2.067117ms Start:2018-10-18 09:56:46.12066005 +0000 UTC m=+23.144143920 End:2018-10-18 09:56:46.122727235 +0000 UTC m=+23.146211037
I1018 09:56:46.122770       1 scheduler.go:454] Total Schedule Algo cumulative time:2.244737078s for 963
I1018 09:56:46.125519       1 scheduler.go:451] ScheduleAlgoTime 2.554005ms Start:2018-10-18 09:56:46.122952904 +0000 UTC m=+23.146436786 End:2018-10-18 09:56:46.12550698 +0000 UTC m=+23.148990791
I1018 09:56:46.125558       1 scheduler.go:454] Total Schedule Algo cumulative time:2.247291083s for 964
I1018 09:56:46.127990       1 scheduler.go:451] ScheduleAlgoTime 2.137103ms Start:2018-10-18 09:56:46.125841979 +0000 UTC m=+23.149325912 End:2018-10-18 09:56:46.127979205 +0000 UTC m=+23.151463015
I1018 09:56:46.128031       1 scheduler.go:454] Total Schedule Algo cumulative time:2.249428186s for 965
I1018 09:56:46.130474       1 scheduler.go:451] ScheduleAlgoTime 2.301697ms Start:2018-10-18 09:56:46.128162997 +0000 UTC m=+23.151646819 End:2018-10-18 09:56:46.130464714 +0000 UTC m=+23.153948516
I1018 09:56:46.130517       1 scheduler.go:454] Total Schedule Algo cumulative time:2.251729883s for 966
I1018 09:56:46.133580       1 scheduler.go:451] ScheduleAlgoTime 2.683454ms Start:2018-10-18 09:56:46.130886517 +0000 UTC m=+23.154370407 End:2018-10-18 09:56:46.133570058 +0000 UTC m=+23.157053861
I1018 09:56:46.133626       1 scheduler.go:454] Total Schedule Algo cumulative time:2.254413337s for 967
I1018 09:56:46.136452       1 scheduler.go:451] ScheduleAlgoTime 2.233414ms Start:2018-10-18 09:56:46.134204518 +0000 UTC m=+23.157688402 End:2018-10-18 09:56:46.136437996 +0000 UTC m=+23.159921816
I1018 09:56:46.136501       1 scheduler.go:454] Total Schedule Algo cumulative time:2.256646751s for 968
I1018 09:56:46.139125       1 scheduler.go:451] ScheduleAlgoTime 2.300276ms Start:2018-10-18 09:56:46.13681364 +0000 UTC m=+23.160297536 End:2018-10-18 09:56:46.139114002 +0000 UTC m=+23.162597812
I1018 09:56:46.139174       1 scheduler.go:454] Total Schedule Algo cumulative time:2.258947027s for 969
I1018 09:56:46.141634       1 scheduler.go:451] ScheduleAlgoTime 2.22609ms Start:2018-10-18 09:56:46.139399498 +0000 UTC m=+23.162883338 End:2018-10-18 09:56:46.141625626 +0000 UTC m=+23.165109428
I1018 09:56:46.141739       1 scheduler.go:454] Total Schedule Algo cumulative time:2.261173117s for 970
I1018 09:56:46.143965       1 scheduler.go:451] ScheduleAlgoTime 2.005031ms Start:2018-10-18 09:56:46.141953767 +0000 UTC m=+23.165437656 End:2018-10-18 09:56:46.143958883 +0000 UTC m=+23.167442687
I1018 09:56:46.143998       1 scheduler.go:454] Total Schedule Algo cumulative time:2.263178148s for 971
I1018 09:56:46.147239       1 scheduler.go:451] ScheduleAlgoTime 2.994717ms Start:2018-10-18 09:56:46.144235058 +0000 UTC m=+23.167718966 End:2018-10-18 09:56:46.147229856 +0000 UTC m=+23.170713683
I1018 09:56:46.147279       1 scheduler.go:454] Total Schedule Algo cumulative time:2.266172865s for 972
I1018 09:56:46.150267       1 scheduler.go:451] ScheduleAlgoTime 2.636669ms Start:2018-10-18 09:56:46.147614223 +0000 UTC m=+23.171098119 End:2018-10-18 09:56:46.150250983 +0000 UTC m=+23.173734788
I1018 09:56:46.150300       1 scheduler.go:454] Total Schedule Algo cumulative time:2.268809534s for 973
I1018 09:56:46.153081       1 scheduler.go:451] ScheduleAlgoTime 2.421021ms Start:2018-10-18 09:56:46.15065093 +0000 UTC m=+23.174134844 End:2018-10-18 09:56:46.153072058 +0000 UTC m=+23.176555865
I1018 09:56:46.153122       1 scheduler.go:454] Total Schedule Algo cumulative time:2.271230555s for 974
I1018 09:56:46.155876       1 scheduler.go:451] ScheduleAlgoTime 2.49377ms Start:2018-10-18 09:56:46.153374783 +0000 UTC m=+23.176858712 End:2018-10-18 09:56:46.155868675 +0000 UTC m=+23.179352482
I1018 09:56:46.155909       1 scheduler.go:454] Total Schedule Algo cumulative time:2.273724325s for 975
I1018 09:56:46.158851       1 scheduler.go:451] ScheduleAlgoTime 2.423864ms Start:2018-10-18 09:56:46.156417301 +0000 UTC m=+23.179901189 End:2018-10-18 09:56:46.158841249 +0000 UTC m=+23.182325053
I1018 09:56:46.158888       1 scheduler.go:454] Total Schedule Algo cumulative time:2.276148189s for 976
I1018 09:56:46.161498       1 scheduler.go:451] ScheduleAlgoTime 2.355372ms Start:2018-10-18 09:56:46.159133075 +0000 UTC m=+23.182616962 End:2018-10-18 09:56:46.161488531 +0000 UTC m=+23.184972334
I1018 09:56:46.161530       1 scheduler.go:454] Total Schedule Algo cumulative time:2.278503561s for 977
I1018 09:56:46.164148       1 scheduler.go:451] ScheduleAlgoTime 2.283249ms Start:2018-10-18 09:56:46.161855724 +0000 UTC m=+23.185339614 End:2018-10-18 09:56:46.164139053 +0000 UTC m=+23.187622863
I1018 09:56:46.164182       1 scheduler.go:454] Total Schedule Algo cumulative time:2.28078681s for 978
I1018 09:56:46.166752       1 scheduler.go:451] ScheduleAlgoTime 2.391274ms Start:2018-10-18 09:56:46.164353022 +0000 UTC m=+23.187836960 End:2018-10-18 09:56:46.16674441 +0000 UTC m=+23.190228234
I1018 09:56:46.166785       1 scheduler.go:454] Total Schedule Algo cumulative time:2.283178084s for 979
I1018 09:56:46.169584       1 scheduler.go:451] ScheduleAlgoTime 2.527298ms Start:2018-10-18 09:56:46.167047382 +0000 UTC m=+23.190531263 End:2018-10-18 09:56:46.169574754 +0000 UTC m=+23.193058561
I1018 09:56:46.169616       1 scheduler.go:454] Total Schedule Algo cumulative time:2.285705382s for 980
I1018 09:56:46.172074       1 scheduler.go:451] ScheduleAlgoTime 1.990814ms Start:2018-10-18 09:56:46.170071976 +0000 UTC m=+23.193555877 End:2018-10-18 09:56:46.172062845 +0000 UTC m=+23.195546691
I1018 09:56:46.172115       1 scheduler.go:454] Total Schedule Algo cumulative time:2.287696196s for 981
I1018 09:56:46.174630       1 scheduler.go:451] ScheduleAlgoTime 2.333375ms Start:2018-10-18 09:56:46.172287463 +0000 UTC m=+23.195771344 End:2018-10-18 09:56:46.174620915 +0000 UTC m=+23.198104719
I1018 09:56:46.174691       1 scheduler.go:454] Total Schedule Algo cumulative time:2.290029571s for 982
I1018 09:56:46.176922       1 scheduler.go:451] ScheduleAlgoTime 2.020568ms Start:2018-10-18 09:56:46.174893531 +0000 UTC m=+23.198377440 End:2018-10-18 09:56:46.176914206 +0000 UTC m=+23.200398008
I1018 09:56:46.176951       1 scheduler.go:454] Total Schedule Algo cumulative time:2.292050139s for 983
I1018 09:56:46.179261       1 scheduler.go:451] ScheduleAlgoTime 2.079262ms Start:2018-10-18 09:56:46.177173269 +0000 UTC m=+23.200657182 End:2018-10-18 09:56:46.179252641 +0000 UTC m=+23.202736444
I1018 09:56:46.179292       1 scheduler.go:454] Total Schedule Algo cumulative time:2.294129401s for 984
I1018 09:56:46.181598       1 scheduler.go:451] ScheduleAlgoTime 2.093781ms Start:2018-10-18 09:56:46.179457828 +0000 UTC m=+23.202941755 End:2018-10-18 09:56:46.181551734 +0000 UTC m=+23.205035536
I1018 09:56:46.181627       1 scheduler.go:454] Total Schedule Algo cumulative time:2.296223182s for 985
I1018 09:56:46.183855       1 scheduler.go:451] ScheduleAlgoTime 1.913419ms Start:2018-10-18 09:56:46.181931974 +0000 UTC m=+23.205415880 End:2018-10-18 09:56:46.183845491 +0000 UTC m=+23.207329299
I1018 09:56:46.183888       1 scheduler.go:454] Total Schedule Algo cumulative time:2.298136601s for 986
I1018 09:56:46.186144       1 scheduler.go:451] ScheduleAlgoTime 2.090612ms Start:2018-10-18 09:56:46.184046194 +0000 UTC m=+23.207530054 End:2018-10-18 09:56:46.186136864 +0000 UTC m=+23.209620666
I1018 09:56:46.186182       1 scheduler.go:454] Total Schedule Algo cumulative time:2.300227213s for 987
I1018 09:56:46.189204       1 scheduler.go:451] ScheduleAlgoTime 2.731888ms Start:2018-10-18 09:56:46.186462362 +0000 UTC m=+23.209946239 End:2018-10-18 09:56:46.189194318 +0000 UTC m=+23.212678127
I1018 09:56:46.189233       1 scheduler.go:454] Total Schedule Algo cumulative time:2.302959101s for 988
I1018 09:56:46.191261       1 scheduler.go:451] ScheduleAlgoTime 1.842508ms Start:2018-10-18 09:56:46.189409477 +0000 UTC m=+23.212893297 End:2018-10-18 09:56:46.191251999 +0000 UTC m=+23.214735805
I1018 09:56:46.191300       1 scheduler.go:454] Total Schedule Algo cumulative time:2.304801609s for 989
I1018 09:56:46.193501       1 scheduler.go:451] ScheduleAlgoTime 1.962151ms Start:2018-10-18 09:56:46.191529769 +0000 UTC m=+23.215013680 End:2018-10-18 09:56:46.193492024 +0000 UTC m=+23.216975831
I1018 09:56:46.193536       1 scheduler.go:454] Total Schedule Algo cumulative time:2.30676376s for 990
I1018 09:56:46.195997       1 scheduler.go:451] ScheduleAlgoTime 2.131968ms Start:2018-10-18 09:56:46.193856044 +0000 UTC m=+23.217339912 End:2018-10-18 09:56:46.195988078 +0000 UTC m=+23.219471880
I1018 09:56:46.196079       1 scheduler.go:454] Total Schedule Algo cumulative time:2.308895728s for 991
I1018 09:56:46.198181       1 scheduler.go:451] ScheduleAlgoTime 2.026675ms Start:2018-10-18 09:56:46.196147654 +0000 UTC m=+23.219631505 End:2018-10-18 09:56:46.198174376 +0000 UTC m=+23.221658180
I1018 09:56:46.198210       1 scheduler.go:454] Total Schedule Algo cumulative time:2.310922403s for 992
I1018 09:56:46.200408       1 scheduler.go:451] ScheduleAlgoTime 2.042283ms Start:2018-10-18 09:56:46.198358508 +0000 UTC m=+23.221842398 End:2018-10-18 09:56:46.200400878 +0000 UTC m=+23.223884681
I1018 09:56:46.200434       1 scheduler.go:454] Total Schedule Algo cumulative time:2.312964686s for 993
I1018 09:56:46.202775       1 scheduler.go:451] ScheduleAlgoTime 2.067712ms Start:2018-10-18 09:56:46.200698465 +0000 UTC m=+23.224182354 End:2018-10-18 09:56:46.202766232 +0000 UTC m=+23.226250066
I1018 09:56:46.202814       1 scheduler.go:454] Total Schedule Algo cumulative time:2.315032398s for 994
I1018 09:56:46.206146       1 scheduler.go:451] ScheduleAlgoTime 2.961366ms Start:2018-10-18 09:56:46.203172351 +0000 UTC m=+23.226656188 End:2018-10-18 09:56:46.206133595 +0000 UTC m=+23.229617554
I1018 09:56:46.206189       1 scheduler.go:454] Total Schedule Algo cumulative time:2.317993764s for 995
I1018 09:56:46.208715       1 scheduler.go:451] ScheduleAlgoTime 2.359513ms Start:2018-10-18 09:56:46.20634768 +0000 UTC m=+23.229831488 End:2018-10-18 09:56:46.208707194 +0000 UTC m=+23.232191001
I1018 09:56:46.208743       1 scheduler.go:454] Total Schedule Algo cumulative time:2.320353277s for 996
I1018 09:56:46.212191       1 scheduler.go:451] ScheduleAlgoTime 3.235881ms Start:2018-10-18 09:56:46.208944997 +0000 UTC m=+23.232428906 End:2018-10-18 09:56:46.21218098 +0000 UTC m=+23.235664787
I1018 09:56:46.212233       1 scheduler.go:454] Total Schedule Algo cumulative time:2.323589158s for 997
I1018 09:56:46.214600       1 scheduler.go:451] ScheduleAlgoTime 2.127548ms Start:2018-10-18 09:56:46.212464821 +0000 UTC m=+23.235948755 End:2018-10-18 09:56:46.214592497 +0000 UTC m=+23.238076303
I1018 09:56:46.214633       1 scheduler.go:454] Total Schedule Algo cumulative time:2.325716706s for 998
I1018 09:56:46.217476       1 scheduler.go:451] ScheduleAlgoTime 2.559113ms Start:2018-10-18 09:56:46.214905163 +0000 UTC m=+23.238389003 End:2018-10-18 09:56:46.217464159 +0000 UTC m=+23.240948116
I1018 09:56:46.217519       1 scheduler.go:454] Total Schedule Algo cumulative time:2.328275819s for 999
I1018 09:56:46.221350       1 scheduler.go:451] ScheduleAlgoTime 3.415917ms Start:2018-10-18 09:56:46.217885858 +0000 UTC m=+23.241369765 End:2018-10-18 09:56:46.221301498 +0000 UTC m=+23.244785682
I1018 09:56:46.221816       1 scheduler.go:454] Total Schedule Algo cumulative time:2.331691736s for 1000
I1018 09:56:46.228528       1 scheduler.go:451] ScheduleAlgoTime 6.412958ms Start:2018-10-18 09:56:46.222103458 +0000 UTC m=+23.245587285 End:2018-10-18 09:56:46.228516433 +0000 UTC m=+23.252000243
I1018 09:56:46.228767       1 scheduler.go:454] Total Schedule Algo cumulative time:2.338104694s for 1001
I1018 09:56:46.232927       1 scheduler.go:451] ScheduleAlgoTime 3.910049ms Start:2018-10-18 09:56:46.229005526 +0000 UTC m=+23.252489374 End:2018-10-18 09:56:46.23291562 +0000 UTC m=+23.256399423
I1018 09:56:46.232969       1 scheduler.go:454] Total Schedule Algo cumulative time:2.342014743s for 1002
I1018 09:56:46.235609       1 scheduler.go:451] ScheduleAlgoTime 2.372564ms Start:2018-10-18 09:56:46.233229535 +0000 UTC m=+23.256713437 End:2018-10-18 09:56:46.235602197 +0000 UTC m=+23.259086001
I1018 09:56:46.235646       1 scheduler.go:454] Total Schedule Algo cumulative time:2.344387307s for 1003
I1018 09:56:46.238563       1 scheduler.go:451] ScheduleAlgoTime 2.633183ms Start:2018-10-18 09:56:46.235921341 +0000 UTC m=+23.259405228 End:2018-10-18 09:56:46.238554595 +0000 UTC m=+23.262038411
I1018 09:56:46.238599       1 scheduler.go:454] Total Schedule Algo cumulative time:2.34702049s for 1004
I1018 09:56:46.241182       1 scheduler.go:451] ScheduleAlgoTime 2.260216ms Start:2018-10-18 09:56:46.238915002 +0000 UTC m=+23.262398927 End:2018-10-18 09:56:46.24117534 +0000 UTC m=+23.264659143
I1018 09:56:46.241217       1 scheduler.go:454] Total Schedule Algo cumulative time:2.349280706s for 1005
I1018 09:56:46.243391       1 scheduler.go:451] ScheduleAlgoTime 1.990697ms Start:2018-10-18 09:56:46.241391342 +0000 UTC m=+23.264875232 End:2018-10-18 09:56:46.243382127 +0000 UTC m=+23.266865929
I1018 09:56:46.243424       1 scheduler.go:454] Total Schedule Algo cumulative time:2.351271403s for 1006
I1018 09:56:46.245602       1 scheduler.go:451] ScheduleAlgoTime 1.976046ms Start:2018-10-18 09:56:46.243619659 +0000 UTC m=+23.267103559 End:2018-10-18 09:56:46.245595799 +0000 UTC m=+23.269079605
I1018 09:56:46.245632       1 scheduler.go:454] Total Schedule Algo cumulative time:2.353247449s for 1007
I1018 09:56:46.248077       1 scheduler.go:451] ScheduleAlgoTime 2.197332ms Start:2018-10-18 09:56:46.245872152 +0000 UTC m=+23.269356007 End:2018-10-18 09:56:46.248069535 +0000 UTC m=+23.271553339
I1018 09:56:46.248176       1 scheduler.go:454] Total Schedule Algo cumulative time:2.355444781s for 1008
I1018 09:56:46.250586       1 scheduler.go:451] ScheduleAlgoTime 2.24365ms Start:2018-10-18 09:56:46.248334821 +0000 UTC m=+23.271818723 End:2018-10-18 09:56:46.25057857 +0000 UTC m=+23.274062373
I1018 09:56:46.250616       1 scheduler.go:454] Total Schedule Algo cumulative time:2.357688431s for 1009
I1018 09:56:46.252993       1 scheduler.go:451] ScheduleAlgoTime 2.165486ms Start:2018-10-18 09:56:46.250818901 +0000 UTC m=+23.274302705 End:2018-10-18 09:56:46.252984387 +0000 UTC m=+23.276468191
I1018 09:56:46.253024       1 scheduler.go:454] Total Schedule Algo cumulative time:2.359853917s for 1010
I1018 09:56:46.255750       1 scheduler.go:451] ScheduleAlgoTime 2.547709ms Start:2018-10-18 09:56:46.25319111 +0000 UTC m=+23.276674976 End:2018-10-18 09:56:46.255738844 +0000 UTC m=+23.279222685
I1018 09:56:46.255796       1 scheduler.go:454] Total Schedule Algo cumulative time:2.362401626s for 1011
I1018 09:56:46.258314       1 scheduler.go:451] ScheduleAlgoTime 2.275188ms Start:2018-10-18 09:56:46.256029194 +0000 UTC m=+23.279513041 End:2018-10-18 09:56:46.258304424 +0000 UTC m=+23.281788229
I1018 09:56:46.258353       1 scheduler.go:454] Total Schedule Algo cumulative time:2.364676814s for 1012
I1018 09:56:46.260906       1 scheduler.go:451] ScheduleAlgoTime 2.318037ms Start:2018-10-18 09:56:46.258579682 +0000 UTC m=+23.282063603 End:2018-10-18 09:56:46.260897837 +0000 UTC m=+23.284381640
I1018 09:56:46.260942       1 scheduler.go:454] Total Schedule Algo cumulative time:2.366994851s for 1013
I1018 09:56:46.263446       1 scheduler.go:451] ScheduleAlgoTime 2.187505ms Start:2018-10-18 09:56:46.261247655 +0000 UTC m=+23.284731571 End:2018-10-18 09:56:46.263435268 +0000 UTC m=+23.286919076
I1018 09:56:46.263485       1 scheduler.go:454] Total Schedule Algo cumulative time:2.369182356s for 1014
I1018 09:56:46.265654       1 scheduler.go:451] ScheduleAlgoTime 2.034149ms Start:2018-10-18 09:56:46.263612851 +0000 UTC m=+23.287096741 End:2018-10-18 09:56:46.265647086 +0000 UTC m=+23.289130890
I1018 09:56:46.265756       1 scheduler.go:454] Total Schedule Algo cumulative time:2.371216505s for 1015
I1018 09:56:46.268069       1 scheduler.go:451] ScheduleAlgoTime 2.12414ms Start:2018-10-18 09:56:46.265938586 +0000 UTC m=+23.289422389 End:2018-10-18 09:56:46.268062723 +0000 UTC m=+23.291546529
I1018 09:56:46.268118       1 scheduler.go:454] Total Schedule Algo cumulative time:2.373340645s for 1016
I1018 09:56:46.270384       1 scheduler.go:451] ScheduleAlgoTime 2.084326ms Start:2018-10-18 09:56:46.268291677 +0000 UTC m=+23.291775593 End:2018-10-18 09:56:46.270376112 +0000 UTC m=+23.293859919
I1018 09:56:46.270416       1 scheduler.go:454] Total Schedule Algo cumulative time:2.375424971s for 1017
I1018 09:56:46.272517       1 scheduler.go:451] ScheduleAlgoTime 1.849242ms Start:2018-10-18 09:56:46.27065864 +0000 UTC m=+23.294142510 End:2018-10-18 09:56:46.272507918 +0000 UTC m=+23.295991752
I1018 09:56:46.272551       1 scheduler.go:454] Total Schedule Algo cumulative time:2.377274213s for 1018
I1018 09:56:46.274975       1 scheduler.go:451] ScheduleAlgoTime 2.109253ms Start:2018-10-18 09:56:46.272859506 +0000 UTC m=+23.296343399 End:2018-10-18 09:56:46.274968848 +0000 UTC m=+23.298452652
I1018 09:56:46.275003       1 scheduler.go:454] Total Schedule Algo cumulative time:2.379383466s for 1019
I1018 09:56:46.277390       1 scheduler.go:451] ScheduleAlgoTime 2.173833ms Start:2018-10-18 09:56:46.275206613 +0000 UTC m=+23.298690506 End:2018-10-18 09:56:46.27738042 +0000 UTC m=+23.300864339
I1018 09:56:46.277426       1 scheduler.go:454] Total Schedule Algo cumulative time:2.381557299s for 1020
I1018 09:56:46.279971       1 scheduler.go:451] ScheduleAlgoTime 1.962543ms Start:2018-10-18 09:56:46.277999945 +0000 UTC m=+23.301483810 End:2018-10-18 09:56:46.279962542 +0000 UTC m=+23.303446353
I1018 09:56:46.280024       1 scheduler.go:454] Total Schedule Algo cumulative time:2.383519842s for 1021
I1018 09:56:46.282321       1 scheduler.go:451] ScheduleAlgoTime 2.064222ms Start:2018-10-18 09:56:46.280248769 +0000 UTC m=+23.303732645 End:2018-10-18 09:56:46.282313064 +0000 UTC m=+23.305796867
I1018 09:56:46.282351       1 scheduler.go:454] Total Schedule Algo cumulative time:2.385584064s for 1022
I1018 09:56:46.284971       1 scheduler.go:451] ScheduleAlgoTime 2.37142ms Start:2018-10-18 09:56:46.282591724 +0000 UTC m=+23.306075622 End:2018-10-18 09:56:46.284963239 +0000 UTC m=+23.308447042
I1018 09:56:46.285001       1 scheduler.go:454] Total Schedule Algo cumulative time:2.387955484s for 1023
I1018 09:56:46.287213       1 scheduler.go:451] ScheduleAlgoTime 2.027427ms Start:2018-10-18 09:56:46.285176782 +0000 UTC m=+23.308660669 End:2018-10-18 09:56:46.287204292 +0000 UTC m=+23.310688096
I1018 09:56:46.287245       1 scheduler.go:454] Total Schedule Algo cumulative time:2.389982911s for 1024
I1018 09:56:46.289297       1 scheduler.go:451] ScheduleAlgoTime 1.954514ms Start:2018-10-18 09:56:46.287334619 +0000 UTC m=+23.310818422 End:2018-10-18 09:56:46.289289126 +0000 UTC m=+23.312772936
I1018 09:56:46.289327       1 scheduler.go:454] Total Schedule Algo cumulative time:2.391937425s for 1025
I1018 09:56:46.291631       1 scheduler.go:451] ScheduleAlgoTime 2.048514ms Start:2018-10-18 09:56:46.289574683 +0000 UTC m=+23.313058559 End:2018-10-18 09:56:46.291623269 +0000 UTC m=+23.315107073
I1018 09:56:46.291699       1 scheduler.go:454] Total Schedule Algo cumulative time:2.393985939s for 1026
I1018 09:56:46.294172       1 scheduler.go:451] ScheduleAlgoTime 2.295952ms Start:2018-10-18 09:56:46.291866858 +0000 UTC m=+23.315350745 End:2018-10-18 09:56:46.294162893 +0000 UTC m=+23.317646697
I1018 09:56:46.294201       1 scheduler.go:454] Total Schedule Algo cumulative time:2.396281891s for 1027
I1018 09:56:46.296939       1 scheduler.go:451] ScheduleAlgoTime 2.413547ms Start:2018-10-18 09:56:46.294517015 +0000 UTC m=+23.318000936 End:2018-10-18 09:56:46.296930681 +0000 UTC m=+23.320414483
I1018 09:56:46.296971       1 scheduler.go:454] Total Schedule Algo cumulative time:2.398695438s for 1028
I1018 09:56:46.299416       1 scheduler.go:451] ScheduleAlgoTime 2.174963ms Start:2018-10-18 09:56:46.297232256 +0000 UTC m=+23.320716131 End:2018-10-18 09:56:46.299407285 +0000 UTC m=+23.322891094
I1018 09:56:46.299446       1 scheduler.go:454] Total Schedule Algo cumulative time:2.400870401s for 1029
I1018 09:56:46.301735       1 scheduler.go:451] ScheduleAlgoTime 2.012002ms Start:2018-10-18 09:56:46.299645909 +0000 UTC m=+23.323129813 End:2018-10-18 09:56:46.301658013 +0000 UTC m=+23.325141815
I1018 09:56:46.301769       1 scheduler.go:454] Total Schedule Algo cumulative time:2.402882403s for 1030
I1018 09:56:46.303938       1 scheduler.go:451] ScheduleAlgoTime 2.027059ms Start:2018-10-18 09:56:46.301903472 +0000 UTC m=+23.325387274 End:2018-10-18 09:56:46.303930528 +0000 UTC m=+23.327414333
I1018 09:56:46.303967       1 scheduler.go:454] Total Schedule Algo cumulative time:2.404909462s for 1031
I1018 09:56:46.306306       1 scheduler.go:451] ScheduleAlgoTime 1.985399ms Start:2018-10-18 09:56:46.304312682 +0000 UTC m=+23.327796570 End:2018-10-18 09:56:46.306298165 +0000 UTC m=+23.329781969
I1018 09:56:46.306340       1 scheduler.go:454] Total Schedule Algo cumulative time:2.406894861s for 1032
I1018 09:56:46.309188       1 scheduler.go:451] ScheduleAlgoTime 2.543948ms Start:2018-10-18 09:56:46.306634222 +0000 UTC m=+23.330118085 End:2018-10-18 09:56:46.30917823 +0000 UTC m=+23.332662033
I1018 09:56:46.309217       1 scheduler.go:454] Total Schedule Algo cumulative time:2.409438809s for 1033
I1018 09:56:46.311786       1 scheduler.go:451] ScheduleAlgoTime 2.218785ms Start:2018-10-18 09:56:46.309559061 +0000 UTC m=+23.333042963 End:2018-10-18 09:56:46.311777945 +0000 UTC m=+23.335261748
I1018 09:56:46.311817       1 scheduler.go:454] Total Schedule Algo cumulative time:2.411657594s for 1034
I1018 09:56:46.314831       1 scheduler.go:451] ScheduleAlgoTime 2.26522ms Start:2018-10-18 09:56:46.312558115 +0000 UTC m=+23.336042008 End:2018-10-18 09:56:46.314823424 +0000 UTC m=+23.338307228
I1018 09:56:46.314864       1 scheduler.go:454] Total Schedule Algo cumulative time:2.413922814s for 1035
I1018 09:56:46.317041       1 scheduler.go:451] ScheduleAlgoTime 1.990779ms Start:2018-10-18 09:56:46.315041859 +0000 UTC m=+23.338525745 End:2018-10-18 09:56:46.31703272 +0000 UTC m=+23.340516524
I1018 09:56:46.317072       1 scheduler.go:454] Total Schedule Algo cumulative time:2.415913593s for 1036
I1018 09:56:46.319410       1 scheduler.go:451] ScheduleAlgoTime 2.053096ms Start:2018-10-18 09:56:46.317349972 +0000 UTC m=+23.340833855 End:2018-10-18 09:56:46.319403148 +0000 UTC m=+23.342886951
I1018 09:56:46.319439       1 scheduler.go:454] Total Schedule Algo cumulative time:2.417966689s for 1037
I1018 09:56:46.322519       1 scheduler.go:451] ScheduleAlgoTime 2.938044ms Start:2018-10-18 09:56:46.319572252 +0000 UTC m=+23.343056155 End:2018-10-18 09:56:46.322510394 +0000 UTC m=+23.345994199
I1018 09:56:46.322552       1 scheduler.go:454] Total Schedule Algo cumulative time:2.420904733s for 1038
I1018 09:56:46.324854       1 scheduler.go:451] ScheduleAlgoTime 2.128237ms Start:2018-10-18 09:56:46.322712783 +0000 UTC m=+23.346196672 End:2018-10-18 09:56:46.324841105 +0000 UTC m=+23.348324909
I1018 09:56:46.324886       1 scheduler.go:454] Total Schedule Algo cumulative time:2.42303297s for 1039
I1018 09:56:46.327360       1 scheduler.go:451] ScheduleAlgoTime 2.270326ms Start:2018-10-18 09:56:46.325080646 +0000 UTC m=+23.348564555 End:2018-10-18 09:56:46.327351055 +0000 UTC m=+23.350834881
I1018 09:56:46.327394       1 scheduler.go:454] Total Schedule Algo cumulative time:2.425303296s for 1040
I1018 09:56:46.329772       1 scheduler.go:451] ScheduleAlgoTime 2.016827ms Start:2018-10-18 09:56:46.327745641 +0000 UTC m=+23.351229542 End:2018-10-18 09:56:46.329762552 +0000 UTC m=+23.353246369
I1018 09:56:46.329803       1 scheduler.go:454] Total Schedule Algo cumulative time:2.427320123s for 1041
I1018 09:56:46.332144       1 scheduler.go:451] ScheduleAlgoTime 2.118093ms Start:2018-10-18 09:56:46.330016425 +0000 UTC m=+23.353500312 End:2018-10-18 09:56:46.332134601 +0000 UTC m=+23.355618405
I1018 09:56:46.332225       1 scheduler.go:454] Total Schedule Algo cumulative time:2.429438216s for 1042
I1018 09:56:46.335449       1 scheduler.go:451] ScheduleAlgoTime 2.984528ms Start:2018-10-18 09:56:46.332452542 +0000 UTC m=+23.355936449 End:2018-10-18 09:56:46.33543707 +0000 UTC m=+23.358920977
I1018 09:56:46.335505       1 scheduler.go:454] Total Schedule Algo cumulative time:2.432422744s for 1043
I1018 09:56:46.338498       1 scheduler.go:451] ScheduleAlgoTime 2.645432ms Start:2018-10-18 09:56:46.335843846 +0000 UTC m=+23.359327707 End:2018-10-18 09:56:46.338489334 +0000 UTC m=+23.361973139
I1018 09:56:46.338531       1 scheduler.go:454] Total Schedule Algo cumulative time:2.435068176s for 1044
I1018 09:56:46.340984       1 scheduler.go:451] ScheduleAlgoTime 1.932061ms Start:2018-10-18 09:56:46.339043485 +0000 UTC m=+23.362527359 End:2018-10-18 09:56:46.340975608 +0000 UTC m=+23.364459420
I1018 09:56:46.341014       1 scheduler.go:454] Total Schedule Algo cumulative time:2.437000237s for 1045
I1018 09:56:46.343286       1 scheduler.go:451] ScheduleAlgoTime 2.047868ms Start:2018-10-18 09:56:46.341227815 +0000 UTC m=+23.364711708 End:2018-10-18 09:56:46.343275749 +0000 UTC m=+23.366759576
I1018 09:56:46.343318       1 scheduler.go:454] Total Schedule Algo cumulative time:2.439048105s for 1046
I1018 09:56:46.345919       1 scheduler.go:451] ScheduleAlgoTime 2.445759ms Start:2018-10-18 09:56:46.343464835 +0000 UTC m=+23.366948695 End:2018-10-18 09:56:46.345910649 +0000 UTC m=+23.369394454
I1018 09:56:46.345950       1 scheduler.go:454] Total Schedule Algo cumulative time:2.441493864s for 1047
I1018 09:56:46.348630       1 scheduler.go:451] ScheduleAlgoTime 2.454461ms Start:2018-10-18 09:56:46.346165911 +0000 UTC m=+23.369649825 End:2018-10-18 09:56:46.348620468 +0000 UTC m=+23.372104286
I1018 09:56:46.348716       1 scheduler.go:454] Total Schedule Algo cumulative time:2.443948325s for 1048
I1018 09:56:46.351751       1 scheduler.go:451] ScheduleAlgoTime 2.701824ms Start:2018-10-18 09:56:46.34903556 +0000 UTC m=+23.372519385 End:2018-10-18 09:56:46.351737305 +0000 UTC m=+23.375221209
I1018 09:56:46.351874       1 scheduler.go:454] Total Schedule Algo cumulative time:2.446650149s for 1049
I1018 09:56:46.355065       1 scheduler.go:451] ScheduleAlgoTime 2.889668ms Start:2018-10-18 09:56:46.352162914 +0000 UTC m=+23.375646809 End:2018-10-18 09:56:46.355052556 +0000 UTC m=+23.378536477
I1018 09:56:46.355107       1 scheduler.go:454] Total Schedule Algo cumulative time:2.449539817s for 1050
I1018 09:56:46.357842       1 scheduler.go:451] ScheduleAlgoTime 2.453301ms Start:2018-10-18 09:56:46.35537926 +0000 UTC m=+23.378863152 End:2018-10-18 09:56:46.357832644 +0000 UTC m=+23.381316453
I1018 09:56:46.357876       1 scheduler.go:454] Total Schedule Algo cumulative time:2.451993118s for 1051
I1018 09:56:46.360580       1 scheduler.go:451] ScheduleAlgoTime 2.357361ms Start:2018-10-18 09:56:46.358212529 +0000 UTC m=+23.381696420 End:2018-10-18 09:56:46.360569976 +0000 UTC m=+23.384053781
I1018 09:56:46.360610       1 scheduler.go:454] Total Schedule Algo cumulative time:2.454350479s for 1052
I1018 09:56:46.363171       1 scheduler.go:451] ScheduleAlgoTime 2.194802ms Start:2018-10-18 09:56:46.360968856 +0000 UTC m=+23.384452786 End:2018-10-18 09:56:46.363163784 +0000 UTC m=+23.386647588
I1018 09:56:46.363205       1 scheduler.go:454] Total Schedule Algo cumulative time:2.456545281s for 1053
I1018 09:56:46.365607       1 scheduler.go:451] ScheduleAlgoTime 2.135925ms Start:2018-10-18 09:56:46.3634622 +0000 UTC m=+23.386946109 End:2018-10-18 09:56:46.365598224 +0000 UTC m=+23.389082034
I1018 09:56:46.365641       1 scheduler.go:454] Total Schedule Algo cumulative time:2.458681206s for 1054
I1018 09:56:46.367997       1 scheduler.go:451] ScheduleAlgoTime 2.098737ms Start:2018-10-18 09:56:46.365887893 +0000 UTC m=+23.389371697 End:2018-10-18 09:56:46.36798663 +0000 UTC m=+23.391470434
I1018 09:56:46.368032       1 scheduler.go:454] Total Schedule Algo cumulative time:2.460779943s for 1055
I1018 09:56:46.370882       1 scheduler.go:451] ScheduleAlgoTime 2.515088ms Start:2018-10-18 09:56:46.368356516 +0000 UTC m=+23.391840437 End:2018-10-18 09:56:46.370871707 +0000 UTC m=+23.394355525
I1018 09:56:46.370926       1 scheduler.go:454] Total Schedule Algo cumulative time:2.463295031s for 1056
I1018 09:56:46.374067       1 scheduler.go:451] ScheduleAlgoTime 2.773814ms Start:2018-10-18 09:56:46.371282383 +0000 UTC m=+23.394766315 End:2018-10-18 09:56:46.374056326 +0000 UTC m=+23.397540129
I1018 09:56:46.374101       1 scheduler.go:454] Total Schedule Algo cumulative time:2.466068845s for 1057
I1018 09:56:46.376961       1 scheduler.go:451] ScheduleAlgoTime 2.449153ms Start:2018-10-18 09:56:46.37450293 +0000 UTC m=+23.397986829 End:2018-10-18 09:56:46.376952175 +0000 UTC m=+23.400435982
I1018 09:56:46.376994       1 scheduler.go:454] Total Schedule Algo cumulative time:2.468517998s for 1058
I1018 09:56:46.379840       1 scheduler.go:451] ScheduleAlgoTime 2.558476ms Start:2018-10-18 09:56:46.377272878 +0000 UTC m=+23.400756758 End:2018-10-18 09:56:46.379831425 +0000 UTC m=+23.403315234
I1018 09:56:46.379877       1 scheduler.go:454] Total Schedule Algo cumulative time:2.471076474s for 1059
I1018 09:56:46.382436       1 scheduler.go:451] ScheduleAlgoTime 2.28211ms Start:2018-10-18 09:56:46.380143919 +0000 UTC m=+23.403627818 End:2018-10-18 09:56:46.38242612 +0000 UTC m=+23.405909928
I1018 09:56:46.382473       1 scheduler.go:454] Total Schedule Algo cumulative time:2.473358584s for 1060
I1018 09:56:46.384751       1 scheduler.go:451] ScheduleAlgoTime 1.967702ms Start:2018-10-18 09:56:46.382774329 +0000 UTC m=+23.406258231 End:2018-10-18 09:56:46.38474213 +0000 UTC m=+23.408225933
I1018 09:56:46.384780       1 scheduler.go:454] Total Schedule Algo cumulative time:2.475326286s for 1061
I1018 09:56:46.387807       1 scheduler.go:451] ScheduleAlgoTime 2.531537ms Start:2018-10-18 09:56:46.38526326 +0000 UTC m=+23.408747146 End:2018-10-18 09:56:46.387794858 +0000 UTC m=+23.411278683
I1018 09:56:46.387851       1 scheduler.go:454] Total Schedule Algo cumulative time:2.477857823s for 1062
I1018 09:56:46.390150       1 scheduler.go:451] ScheduleAlgoTime 2.072534ms Start:2018-10-18 09:56:46.388067545 +0000 UTC m=+23.411551426 End:2018-10-18 09:56:46.390140157 +0000 UTC m=+23.413623960
I1018 09:56:46.390186       1 scheduler.go:454] Total Schedule Algo cumulative time:2.479930357s for 1063
I1018 09:56:46.393115       1 scheduler.go:451] ScheduleAlgoTime 2.635279ms Start:2018-10-18 09:56:46.390470463 +0000 UTC m=+23.413954303 End:2018-10-18 09:56:46.393105774 +0000 UTC m=+23.416589582
I1018 09:56:46.393150       1 scheduler.go:454] Total Schedule Algo cumulative time:2.482565636s for 1064
I1018 09:56:46.396409       1 scheduler.go:451] ScheduleAlgoTime 3.082267ms Start:2018-10-18 09:56:46.393317461 +0000 UTC m=+23.416801286 End:2018-10-18 09:56:46.396399746 +0000 UTC m=+23.419883553
I1018 09:56:46.396439       1 scheduler.go:454] Total Schedule Algo cumulative time:2.485647903s for 1065
I1018 09:56:46.398981       1 scheduler.go:451] ScheduleAlgoTime 2.410672ms Start:2018-10-18 09:56:46.396558506 +0000 UTC m=+23.420042379 End:2018-10-18 09:56:46.39896914 +0000 UTC m=+23.422453051
I1018 09:56:46.399032       1 scheduler.go:454] Total Schedule Algo cumulative time:2.488058575s for 1066
I1018 09:56:46.401755       1 scheduler.go:451] ScheduleAlgoTime 2.276409ms Start:2018-10-18 09:56:46.399466083 +0000 UTC m=+23.422950013 End:2018-10-18 09:56:46.40174255 +0000 UTC m=+23.425226422
I1018 09:56:46.401807       1 scheduler.go:454] Total Schedule Algo cumulative time:2.490334984s for 1067
I1018 09:56:46.404611       1 scheduler.go:451] ScheduleAlgoTime 2.264643ms Start:2018-10-18 09:56:46.402335643 +0000 UTC m=+23.425819551 End:2018-10-18 09:56:46.404600391 +0000 UTC m=+23.428084194
I1018 09:56:46.404654       1 scheduler.go:454] Total Schedule Algo cumulative time:2.492599627s for 1068
I1018 09:56:46.407167       1 scheduler.go:451] ScheduleAlgoTime 2.268604ms Start:2018-10-18 09:56:46.404889101 +0000 UTC m=+23.428372988 End:2018-10-18 09:56:46.407157782 +0000 UTC m=+23.430641592
I1018 09:56:46.407197       1 scheduler.go:454] Total Schedule Algo cumulative time:2.494868231s for 1069
I1018 09:56:46.409505       1 scheduler.go:451] ScheduleAlgoTime 2.018655ms Start:2018-10-18 09:56:46.407476251 +0000 UTC m=+23.430960107 End:2018-10-18 09:56:46.409494958 +0000 UTC m=+23.432978762
I1018 09:56:46.409557       1 scheduler.go:454] Total Schedule Algo cumulative time:2.496886886s for 1070
I1018 09:56:46.412241       1 scheduler.go:451] ScheduleAlgoTime 2.419947ms Start:2018-10-18 09:56:46.409811694 +0000 UTC m=+23.433295602 End:2018-10-18 09:56:46.412231746 +0000 UTC m=+23.435715549
I1018 09:56:46.412272       1 scheduler.go:454] Total Schedule Algo cumulative time:2.499306833s for 1071
I1018 09:56:46.415598       1 scheduler.go:451] ScheduleAlgoTime 3.033605ms Start:2018-10-18 09:56:46.412557547 +0000 UTC m=+23.436041441 End:2018-10-18 09:56:46.415591239 +0000 UTC m=+23.439075046
I1018 09:56:46.415646       1 scheduler.go:454] Total Schedule Algo cumulative time:2.502340438s for 1072
I1018 09:56:46.418263       1 scheduler.go:451] ScheduleAlgoTime 2.316781ms Start:2018-10-18 09:56:46.415936547 +0000 UTC m=+23.439420442 End:2018-10-18 09:56:46.418253419 +0000 UTC m=+23.441737223
I1018 09:56:46.418295       1 scheduler.go:454] Total Schedule Algo cumulative time:2.504657219s for 1073
I1018 09:56:46.421454       1 scheduler.go:451] ScheduleAlgoTime 2.69203ms Start:2018-10-18 09:56:46.418745094 +0000 UTC m=+23.442228979 End:2018-10-18 09:56:46.421437206 +0000 UTC m=+23.444921009
I1018 09:56:46.421491       1 scheduler.go:454] Total Schedule Algo cumulative time:2.507349249s for 1074
I1018 09:56:46.424400       1 scheduler.go:451] ScheduleAlgoTime 2.403719ms Start:2018-10-18 09:56:46.421986535 +0000 UTC m=+23.445470443 End:2018-10-18 09:56:46.424390312 +0000 UTC m=+23.447874162
I1018 09:56:46.424443       1 scheduler.go:454] Total Schedule Algo cumulative time:2.509752968s for 1075
I1018 09:56:46.427563       1 scheduler.go:451] ScheduleAlgoTime 2.837871ms Start:2018-10-18 09:56:46.424717505 +0000 UTC m=+23.448201429 End:2018-10-18 09:56:46.427555493 +0000 UTC m=+23.451039300
I1018 09:56:46.427600       1 scheduler.go:454] Total Schedule Algo cumulative time:2.512590839s for 1076
I1018 09:56:46.431138       1 scheduler.go:451] ScheduleAlgoTime 3.055636ms Start:2018-10-18 09:56:46.428073101 +0000 UTC m=+23.451557042 End:2018-10-18 09:56:46.431128872 +0000 UTC m=+23.454612678
I1018 09:56:46.431170       1 scheduler.go:454] Total Schedule Algo cumulative time:2.515646475s for 1077
I1018 09:56:46.440604       1 scheduler.go:451] ScheduleAlgoTime 8.809643ms Start:2018-10-18 09:56:46.431780955 +0000 UTC m=+23.455264894 End:2018-10-18 09:56:46.440590336 +0000 UTC m=+23.464074537
I1018 09:56:46.440738       1 scheduler.go:454] Total Schedule Algo cumulative time:2.524456118s for 1078
I1018 09:56:46.446511       1 scheduler.go:451] ScheduleAlgoTime 5.194916ms Start:2018-10-18 09:56:46.44130554 +0000 UTC m=+23.464789357 End:2018-10-18 09:56:46.446500464 +0000 UTC m=+23.469984273
I1018 09:56:46.446558       1 scheduler.go:454] Total Schedule Algo cumulative time:2.529651034s for 1079
I1018 09:56:46.449264       1 scheduler.go:451] ScheduleAlgoTime 2.523855ms Start:2018-10-18 09:56:46.446732687 +0000 UTC m=+23.470216600 End:2018-10-18 09:56:46.449256652 +0000 UTC m=+23.472740455
I1018 09:56:46.449310       1 scheduler.go:454] Total Schedule Algo cumulative time:2.532174889s for 1080
I1018 09:56:46.452065       1 scheduler.go:451] ScheduleAlgoTime 2.392339ms Start:2018-10-18 09:56:46.449660114 +0000 UTC m=+23.473144001 End:2018-10-18 09:56:46.452052443 +0000 UTC m=+23.475536340
I1018 09:56:46.452122       1 scheduler.go:454] Total Schedule Algo cumulative time:2.534567228s for 1081
I1018 09:56:46.455048       1 scheduler.go:451] ScheduleAlgoTime 2.658359ms Start:2018-10-18 09:56:46.452381029 +0000 UTC m=+23.475864870 End:2018-10-18 09:56:46.455039423 +0000 UTC m=+23.478523229
I1018 09:56:46.455084       1 scheduler.go:454] Total Schedule Algo cumulative time:2.537225587s for 1082
I1018 09:56:46.458183       1 scheduler.go:451] ScheduleAlgoTime 2.895433ms Start:2018-10-18 09:56:46.455278597 +0000 UTC m=+23.478762487 End:2018-10-18 09:56:46.458174116 +0000 UTC m=+23.481657920
I1018 09:56:46.458224       1 scheduler.go:454] Total Schedule Algo cumulative time:2.54012102s for 1083
I1018 09:56:46.460551       1 scheduler.go:451] ScheduleAlgoTime 2.150549ms Start:2018-10-18 09:56:46.458392693 +0000 UTC m=+23.481876548 End:2018-10-18 09:56:46.460543294 +0000 UTC m=+23.484027097
I1018 09:56:46.460584       1 scheduler.go:454] Total Schedule Algo cumulative time:2.542271569s for 1084
I1018 09:56:46.463756       1 scheduler.go:451] ScheduleAlgoTime 2.749934ms Start:2018-10-18 09:56:46.460996924 +0000 UTC m=+23.484480825 End:2018-10-18 09:56:46.463746957 +0000 UTC m=+23.487230759
I1018 09:56:46.463792       1 scheduler.go:454] Total Schedule Algo cumulative time:2.545021503s for 1085
I1018 09:56:46.466180       1 scheduler.go:451] ScheduleAlgoTime 2.180526ms Start:2018-10-18 09:56:46.463991573 +0000 UTC m=+23.487475420 End:2018-10-18 09:56:46.466172139 +0000 UTC m=+23.489655946
I1018 09:56:46.466221       1 scheduler.go:454] Total Schedule Algo cumulative time:2.547202029s for 1086
I1018 09:56:46.468958       1 scheduler.go:451] ScheduleAlgoTime 2.329077ms Start:2018-10-18 09:56:46.466618815 +0000 UTC m=+23.490102736 End:2018-10-18 09:56:46.468948004 +0000 UTC m=+23.492431813
I1018 09:56:46.469005       1 scheduler.go:454] Total Schedule Algo cumulative time:2.549531106s for 1087
I1018 09:56:46.471740       1 scheduler.go:451] ScheduleAlgoTime 2.456511ms Start:2018-10-18 09:56:46.469273743 +0000 UTC m=+23.492757646 End:2018-10-18 09:56:46.471730353 +0000 UTC m=+23.495214157
I1018 09:56:46.471779       1 scheduler.go:454] Total Schedule Algo cumulative time:2.551987617s for 1088
I1018 09:56:46.474316       1 scheduler.go:451] ScheduleAlgoTime 2.34599ms Start:2018-10-18 09:56:46.471960819 +0000 UTC m=+23.495444685 End:2018-10-18 09:56:46.47430687 +0000 UTC m=+23.497790675
I1018 09:56:46.474348       1 scheduler.go:454] Total Schedule Algo cumulative time:2.554333607s for 1089
I1018 09:56:46.476602       1 scheduler.go:451] ScheduleAlgoTime 1.984867ms Start:2018-10-18 09:56:46.474610856 +0000 UTC m=+23.498094764 End:2018-10-18 09:56:46.476595828 +0000 UTC m=+23.500079631
I1018 09:56:46.476646       1 scheduler.go:454] Total Schedule Algo cumulative time:2.556318474s for 1090
I1018 09:56:46.478950       1 scheduler.go:451] ScheduleAlgoTime 1.972167ms Start:2018-10-18 09:56:46.476967374 +0000 UTC m=+23.500451298 End:2018-10-18 09:56:46.478939657 +0000 UTC m=+23.502423465
I1018 09:56:46.478981       1 scheduler.go:454] Total Schedule Algo cumulative time:2.558290641s for 1091
I1018 09:56:46.480960       1 scheduler.go:451] ScheduleAlgoTime 1.755143ms Start:2018-10-18 09:56:46.479197861 +0000 UTC m=+23.502681753 End:2018-10-18 09:56:46.480953092 +0000 UTC m=+23.504436896
I1018 09:56:46.480995       1 scheduler.go:454] Total Schedule Algo cumulative time:2.560045784s for 1092
I1018 09:56:46.483234       1 scheduler.go:451] ScheduleAlgoTime 1.964661ms Start:2018-10-18 09:56:46.481262511 +0000 UTC m=+23.504746405 End:2018-10-18 09:56:46.483227264 +0000 UTC m=+23.506711066
I1018 09:56:46.483261       1 scheduler.go:454] Total Schedule Algo cumulative time:2.562010445s for 1093
I1018 09:56:46.486078       1 scheduler.go:451] ScheduleAlgoTime 2.572061ms Start:2018-10-18 09:56:46.48349541 +0000 UTC m=+23.506979344 End:2018-10-18 09:56:46.486067563 +0000 UTC m=+23.509551405
I1018 09:56:46.486120       1 scheduler.go:454] Total Schedule Algo cumulative time:2.564582506s for 1094
I1018 09:56:46.488646       1 scheduler.go:451] ScheduleAlgoTime 2.192032ms Start:2018-10-18 09:56:46.486437011 +0000 UTC m=+23.509920906 End:2018-10-18 09:56:46.488629121 +0000 UTC m=+23.512112938
I1018 09:56:46.488717       1 scheduler.go:454] Total Schedule Algo cumulative time:2.566774538s for 1095
I1018 09:56:46.491418       1 scheduler.go:451] ScheduleAlgoTime 2.493542ms Start:2018-10-18 09:56:46.488913244 +0000 UTC m=+23.512397094 End:2018-10-18 09:56:46.491406829 +0000 UTC m=+23.514890636
I1018 09:56:46.491455       1 scheduler.go:454] Total Schedule Algo cumulative time:2.56926808s for 1096
I1018 09:56:46.494123       1 scheduler.go:451] ScheduleAlgoTime 2.309486ms Start:2018-10-18 09:56:46.491803401 +0000 UTC m=+23.515287300 End:2018-10-18 09:56:46.494112983 +0000 UTC m=+23.517596786
I1018 09:56:46.494253       1 scheduler.go:454] Total Schedule Algo cumulative time:2.571577566s for 1097
I1018 09:56:46.496741       1 scheduler.go:451] ScheduleAlgoTime 2.173199ms Start:2018-10-18 09:56:46.494554544 +0000 UTC m=+23.518038404 End:2018-10-18 09:56:46.496727774 +0000 UTC m=+23.520211603
I1018 09:56:46.496789       1 scheduler.go:454] Total Schedule Algo cumulative time:2.573750765s for 1098
I1018 09:56:46.499980       1 scheduler.go:451] ScheduleAlgoTime 2.977222ms Start:2018-10-18 09:56:46.496993519 +0000 UTC m=+23.520477414 End:2018-10-18 09:56:46.499970834 +0000 UTC m=+23.523454636
I1018 09:56:46.500018       1 scheduler.go:454] Total Schedule Algo cumulative time:2.576727987s for 1099
I1018 09:56:46.502376       1 scheduler.go:451] ScheduleAlgoTime 2.201646ms Start:2018-10-18 09:56:46.500166025 +0000 UTC m=+23.523649946 End:2018-10-18 09:56:46.502367782 +0000 UTC m=+23.525851592
I1018 09:56:46.502410       1 scheduler.go:454] Total Schedule Algo cumulative time:2.578929633s for 1100
I1018 09:56:46.505442       1 scheduler.go:451] ScheduleAlgoTime 2.789483ms Start:2018-10-18 09:56:46.502642969 +0000 UTC m=+23.526126865 End:2018-10-18 09:56:46.505432545 +0000 UTC m=+23.528916348
I1018 09:56:46.505472       1 scheduler.go:454] Total Schedule Algo cumulative time:2.581719116s for 1101
I1018 09:56:46.508363       1 scheduler.go:451] ScheduleAlgoTime 2.657917ms Start:2018-10-18 09:56:46.505695616 +0000 UTC m=+23.529179539 End:2018-10-18 09:56:46.508353653 +0000 UTC m=+23.531837456
I1018 09:56:46.508397       1 scheduler.go:454] Total Schedule Algo cumulative time:2.584377033s for 1102
I1018 09:56:46.511247       1 scheduler.go:451] ScheduleAlgoTime 2.483166ms Start:2018-10-18 09:56:46.508754667 +0000 UTC m=+23.532238544 End:2018-10-18 09:56:46.511237905 +0000 UTC m=+23.534721710
I1018 09:56:46.511277       1 scheduler.go:454] Total Schedule Algo cumulative time:2.586860199s for 1103
I1018 09:56:46.513770       1 scheduler.go:451] ScheduleAlgoTime 2.233094ms Start:2018-10-18 09:56:46.511526819 +0000 UTC m=+23.535010707 End:2018-10-18 09:56:46.51376 +0000 UTC m=+23.537243801
I1018 09:56:46.513802       1 scheduler.go:454] Total Schedule Algo cumulative time:2.589093293s for 1104
I1018 09:56:46.516386       1 scheduler.go:451] ScheduleAlgoTime 2.27501ms Start:2018-10-18 09:56:46.514102393 +0000 UTC m=+23.537586289 End:2018-10-18 09:56:46.516377494 +0000 UTC m=+23.539861299
I1018 09:56:46.516417       1 scheduler.go:454] Total Schedule Algo cumulative time:2.591368303s for 1105
I1018 09:56:46.519507       1 scheduler.go:451] ScheduleAlgoTime 2.335542ms Start:2018-10-18 09:56:46.517161533 +0000 UTC m=+23.540645414 End:2018-10-18 09:56:46.519497153 +0000 UTC m=+23.542980956
I1018 09:56:46.519543       1 scheduler.go:454] Total Schedule Algo cumulative time:2.593703845s for 1106
I1018 09:56:46.523352       1 scheduler.go:451] ScheduleAlgoTime 3.571049ms Start:2018-10-18 09:56:46.519770849 +0000 UTC m=+23.543254751 End:2018-10-18 09:56:46.523341996 +0000 UTC m=+23.546825800
I1018 09:56:46.523388       1 scheduler.go:454] Total Schedule Algo cumulative time:2.597274894s for 1107
I1018 09:56:46.526087       1 scheduler.go:451] ScheduleAlgoTime 2.454264ms Start:2018-10-18 09:56:46.523601326 +0000 UTC m=+23.547085235 End:2018-10-18 09:56:46.526055696 +0000 UTC m=+23.549539499
I1018 09:56:46.526120       1 scheduler.go:454] Total Schedule Algo cumulative time:2.599729158s for 1108
I1018 09:56:46.528624       1 scheduler.go:451] ScheduleAlgoTime 2.152143ms Start:2018-10-18 09:56:46.526461844 +0000 UTC m=+23.549945747 End:2018-10-18 09:56:46.528614087 +0000 UTC m=+23.552097890
I1018 09:56:46.528655       1 scheduler.go:454] Total Schedule Algo cumulative time:2.601881301s for 1109
I1018 09:56:46.531608       1 scheduler.go:451] ScheduleAlgoTime 2.620926ms Start:2018-10-18 09:56:46.528977148 +0000 UTC m=+23.552461015 End:2018-10-18 09:56:46.53159814 +0000 UTC m=+23.555081941
I1018 09:56:46.531659       1 scheduler.go:454] Total Schedule Algo cumulative time:2.604502227s for 1110
I1018 09:56:46.534208       1 scheduler.go:451] ScheduleAlgoTime 2.413563ms Start:2018-10-18 09:56:46.531783244 +0000 UTC m=+23.555267071 End:2018-10-18 09:56:46.534196813 +0000 UTC m=+23.557680634
I1018 09:56:46.534248       1 scheduler.go:454] Total Schedule Algo cumulative time:2.60691579s for 1111
I1018 09:56:46.537022       1 scheduler.go:451] ScheduleAlgoTime 2.505401ms Start:2018-10-18 09:56:46.534504984 +0000 UTC m=+23.557988885 End:2018-10-18 09:56:46.537010478 +0000 UTC m=+23.560494286
I1018 09:56:46.537057       1 scheduler.go:454] Total Schedule Algo cumulative time:2.609421191s for 1112
I1018 09:56:46.539967       1 scheduler.go:451] ScheduleAlgoTime 2.574853ms Start:2018-10-18 09:56:46.537383336 +0000 UTC m=+23.560867242 End:2018-10-18 09:56:46.539958291 +0000 UTC m=+23.563442095
I1018 09:56:46.539998       1 scheduler.go:454] Total Schedule Algo cumulative time:2.611996044s for 1113
I1018 09:56:46.542196       1 scheduler.go:451] ScheduleAlgoTime 2.030984ms Start:2018-10-18 09:56:46.540156369 +0000 UTC m=+23.563640262 End:2018-10-18 09:56:46.542187443 +0000 UTC m=+23.565671246
I1018 09:56:46.542225       1 scheduler.go:454] Total Schedule Algo cumulative time:2.614027028s for 1114
I1018 09:56:46.544426       1 scheduler.go:451] ScheduleAlgoTime 2.034828ms Start:2018-10-18 09:56:46.54238127 +0000 UTC m=+23.565865185 End:2018-10-18 09:56:46.54441619 +0000 UTC m=+23.567900013
I1018 09:56:46.544459       1 scheduler.go:454] Total Schedule Algo cumulative time:2.616061856s for 1115
I1018 09:56:46.547012       1 scheduler.go:451] ScheduleAlgoTime 2.320242ms Start:2018-10-18 09:56:46.54468373 +0000 UTC m=+23.568167687 End:2018-10-18 09:56:46.547004104 +0000 UTC m=+23.570487929
I1018 09:56:46.547043       1 scheduler.go:454] Total Schedule Algo cumulative time:2.618382098s for 1116
I1018 09:56:46.549509       1 scheduler.go:451] ScheduleAlgoTime 2.05784ms Start:2018-10-18 09:56:46.547439018 +0000 UTC m=+23.570922902 End:2018-10-18 09:56:46.549496877 +0000 UTC m=+23.572980742
I1018 09:56:46.549561       1 scheduler.go:454] Total Schedule Algo cumulative time:2.620439938s for 1117
I1018 09:56:46.552267       1 scheduler.go:451] ScheduleAlgoTime 2.456165ms Start:2018-10-18 09:56:46.549801777 +0000 UTC m=+23.573285695 End:2018-10-18 09:56:46.552258057 +0000 UTC m=+23.575741860
I1018 09:56:46.552300       1 scheduler.go:454] Total Schedule Algo cumulative time:2.622896103s for 1118
I1018 09:56:46.555154       1 scheduler.go:451] ScheduleAlgoTime 2.549713ms Start:2018-10-18 09:56:46.552596118 +0000 UTC m=+23.576080022 End:2018-10-18 09:56:46.555145933 +0000 UTC m=+23.578629735
I1018 09:56:46.555186       1 scheduler.go:454] Total Schedule Algo cumulative time:2.625445816s for 1119
I1018 09:56:46.557482       1 scheduler.go:451] ScheduleAlgoTime 2.08927ms Start:2018-10-18 09:56:46.555381004 +0000 UTC m=+23.578864845 End:2018-10-18 09:56:46.557470313 +0000 UTC m=+23.580954115
I1018 09:56:46.557524       1 scheduler.go:454] Total Schedule Algo cumulative time:2.627535086s for 1120
I1018 09:56:46.559928       1 scheduler.go:451] ScheduleAlgoTime 2.058759ms Start:2018-10-18 09:56:46.557860073 +0000 UTC m=+23.581343963 End:2018-10-18 09:56:46.559918919 +0000 UTC m=+23.583402722
I1018 09:56:46.559961       1 scheduler.go:454] Total Schedule Algo cumulative time:2.629593845s for 1121
I1018 09:56:46.562926       1 scheduler.go:451] ScheduleAlgoTime 2.533622ms Start:2018-10-18 09:56:46.560381124 +0000 UTC m=+23.583865011 End:2018-10-18 09:56:46.562914785 +0000 UTC m=+23.586398633
I1018 09:56:46.562965       1 scheduler.go:454] Total Schedule Algo cumulative time:2.632127467s for 1122
I1018 09:56:46.565503       1 scheduler.go:451] ScheduleAlgoTime 2.19811ms Start:2018-10-18 09:56:46.563293588 +0000 UTC m=+23.586777483 End:2018-10-18 09:56:46.565491726 +0000 UTC m=+23.588975593
I1018 09:56:46.565541       1 scheduler.go:454] Total Schedule Algo cumulative time:2.634325577s for 1123
I1018 09:56:46.567976       1 scheduler.go:451] ScheduleAlgoTime 2.133063ms Start:2018-10-18 09:56:46.565830489 +0000 UTC m=+23.589314413 End:2018-10-18 09:56:46.567963579 +0000 UTC m=+23.591447476
I1018 09:56:46.568033       1 scheduler.go:454] Total Schedule Algo cumulative time:2.63645864s for 1124
I1018 09:56:46.570467       1 scheduler.go:451] ScheduleAlgoTime 2.163638ms Start:2018-10-18 09:56:46.568294555 +0000 UTC m=+23.591778474 End:2018-10-18 09:56:46.570458304 +0000 UTC m=+23.593942112
I1018 09:56:46.570496       1 scheduler.go:454] Total Schedule Algo cumulative time:2.638622278s for 1125
I1018 09:56:46.572811       1 scheduler.go:451] ScheduleAlgoTime 2.173472ms Start:2018-10-18 09:56:46.570630854 +0000 UTC m=+23.594114659 End:2018-10-18 09:56:46.572804325 +0000 UTC m=+23.596288131
I1018 09:56:46.572910       1 scheduler.go:454] Total Schedule Algo cumulative time:2.64079575s for 1126
I1018 09:56:46.575896       1 scheduler.go:451] ScheduleAlgoTime 2.807545ms Start:2018-10-18 09:56:46.573079166 +0000 UTC m=+23.596563111 End:2018-10-18 09:56:46.575886851 +0000 UTC m=+23.599370656
I1018 09:56:46.575932       1 scheduler.go:454] Total Schedule Algo cumulative time:2.643603295s for 1127
I1018 09:56:46.578333       1 scheduler.go:451] ScheduleAlgoTime 2.123289ms Start:2018-10-18 09:56:46.576201879 +0000 UTC m=+23.599685685 End:2018-10-18 09:56:46.578325169 +0000 UTC m=+23.601808974
I1018 09:56:46.578366       1 scheduler.go:454] Total Schedule Algo cumulative time:2.645726584s for 1128
I1018 09:56:46.581092       1 scheduler.go:451] ScheduleAlgoTime 2.494191ms Start:2018-10-18 09:56:46.578587223 +0000 UTC m=+23.602071096 End:2018-10-18 09:56:46.581081484 +0000 UTC m=+23.604565287
I1018 09:56:46.581127       1 scheduler.go:454] Total Schedule Algo cumulative time:2.648220775s for 1129
I1018 09:56:46.583817       1 scheduler.go:451] ScheduleAlgoTime 2.438511ms Start:2018-10-18 09:56:46.581370616 +0000 UTC m=+23.604854485 End:2018-10-18 09:56:46.583809192 +0000 UTC m=+23.607292996
I1018 09:56:46.583850       1 scheduler.go:454] Total Schedule Algo cumulative time:2.650659286s for 1130
I1018 09:56:46.586767       1 scheduler.go:451] ScheduleAlgoTime 2.706239ms Start:2018-10-18 09:56:46.584052323 +0000 UTC m=+23.607536187 End:2018-10-18 09:56:46.586758609 +0000 UTC m=+23.610242426
I1018 09:56:46.586804       1 scheduler.go:454] Total Schedule Algo cumulative time:2.653365525s for 1131
I1018 09:56:46.589211       1 scheduler.go:451] ScheduleAlgoTime 2.209118ms Start:2018-10-18 09:56:46.586992432 +0000 UTC m=+23.610476296 End:2018-10-18 09:56:46.589201607 +0000 UTC m=+23.612685414
I1018 09:56:46.589245       1 scheduler.go:454] Total Schedule Algo cumulative time:2.655574643s for 1132
I1018 09:56:46.591852       1 scheduler.go:451] ScheduleAlgoTime 2.497489ms Start:2018-10-18 09:56:46.58934308 +0000 UTC m=+23.612826884 End:2018-10-18 09:56:46.591840549 +0000 UTC m=+23.615324373
I1018 09:56:46.591893       1 scheduler.go:454] Total Schedule Algo cumulative time:2.658072132s for 1133
I1018 09:56:46.594405       1 scheduler.go:451] ScheduleAlgoTime 2.260258ms Start:2018-10-18 09:56:46.592135458 +0000 UTC m=+23.615619391 End:2018-10-18 09:56:46.594395749 +0000 UTC m=+23.617879649
I1018 09:56:46.594442       1 scheduler.go:454] Total Schedule Algo cumulative time:2.66033239s for 1134
I1018 09:56:46.597514       1 scheduler.go:451] ScheduleAlgoTime 2.817183ms Start:2018-10-18 09:56:46.594686787 +0000 UTC m=+23.618170694 End:2018-10-18 09:56:46.597504073 +0000 UTC m=+23.620987877
I1018 09:56:46.597546       1 scheduler.go:454] Total Schedule Algo cumulative time:2.663149573s for 1135
I1018 09:56:46.600400       1 scheduler.go:451] ScheduleAlgoTime 2.473624ms Start:2018-10-18 09:56:46.597911456 +0000 UTC m=+23.621395343 End:2018-10-18 09:56:46.600385118 +0000 UTC m=+23.623868967
I1018 09:56:46.600442       1 scheduler.go:454] Total Schedule Algo cumulative time:2.665623197s for 1136
I1018 09:56:46.602709       1 scheduler.go:451] ScheduleAlgoTime 1.997256ms Start:2018-10-18 09:56:46.600702238 +0000 UTC m=+23.624186101 End:2018-10-18 09:56:46.602699554 +0000 UTC m=+23.626183357
I1018 09:56:46.602804       1 scheduler.go:454] Total Schedule Algo cumulative time:2.667620453s for 1137
I1018 09:56:46.605091       1 scheduler.go:451] ScheduleAlgoTime 2.0894ms Start:2018-10-18 09:56:46.602993882 +0000 UTC m=+23.626477764 End:2018-10-18 09:56:46.605083362 +0000 UTC m=+23.628567164
I1018 09:56:46.605120       1 scheduler.go:454] Total Schedule Algo cumulative time:2.669709853s for 1138
I1018 09:56:46.607298       1 scheduler.go:451] ScheduleAlgoTime 1.979635ms Start:2018-10-18 09:56:46.605310905 +0000 UTC m=+23.628794800 End:2018-10-18 09:56:46.60729063 +0000 UTC m=+23.630774435
I1018 09:56:46.607328       1 scheduler.go:454] Total Schedule Algo cumulative time:2.671689488s for 1139
I1018 09:56:46.609560       1 scheduler.go:451] ScheduleAlgoTime 2.113025ms Start:2018-10-18 09:56:46.607436628 +0000 UTC m=+23.630920541 End:2018-10-18 09:56:46.609549753 +0000 UTC m=+23.633033566
I1018 09:56:46.609600       1 scheduler.go:454] Total Schedule Algo cumulative time:2.673802513s for 1140
I1018 09:56:46.612149       1 scheduler.go:451] ScheduleAlgoTime 2.314038ms Start:2018-10-18 09:56:46.60982584 +0000 UTC m=+23.633309752 End:2018-10-18 09:56:46.612139986 +0000 UTC m=+23.635623790
I1018 09:56:46.612180       1 scheduler.go:454] Total Schedule Algo cumulative time:2.676116551s for 1141
I1018 09:56:46.614290       1 scheduler.go:451] ScheduleAlgoTime 1.946711ms Start:2018-10-18 09:56:46.612335155 +0000 UTC m=+23.635818971 End:2018-10-18 09:56:46.614281878 +0000 UTC m=+23.637765682
I1018 09:56:46.614321       1 scheduler.go:454] Total Schedule Algo cumulative time:2.678063262s for 1142
I1018 09:56:46.616540       1 scheduler.go:451] ScheduleAlgoTime 1.955077ms Start:2018-10-18 09:56:46.614577383 +0000 UTC m=+23.638061272 End:2018-10-18 09:56:46.616532545 +0000 UTC m=+23.640016349
I1018 09:56:46.616569       1 scheduler.go:454] Total Schedule Algo cumulative time:2.680018339s for 1143
I1018 09:56:46.618876       1 scheduler.go:451] ScheduleAlgoTime 1.977835ms Start:2018-10-18 09:56:46.616891857 +0000 UTC m=+23.640375661 End:2018-10-18 09:56:46.618869694 +0000 UTC m=+23.642353496
I1018 09:56:46.618913       1 scheduler.go:454] Total Schedule Algo cumulative time:2.681996174s for 1144
I1018 09:56:46.621221       1 scheduler.go:451] ScheduleAlgoTime 2.111907ms Start:2018-10-18 09:56:46.619100217 +0000 UTC m=+23.642584107 End:2018-10-18 09:56:46.621212211 +0000 UTC m=+23.644696014
I1018 09:56:46.621258       1 scheduler.go:454] Total Schedule Algo cumulative time:2.684108081s for 1145
I1018 09:56:46.623819       1 scheduler.go:451] ScheduleAlgoTime 2.306841ms Start:2018-10-18 09:56:46.621504632 +0000 UTC m=+23.644988513 End:2018-10-18 09:56:46.623811549 +0000 UTC m=+23.647295354
I1018 09:56:46.623847       1 scheduler.go:454] Total Schedule Algo cumulative time:2.686414922s for 1146
I1018 09:56:46.626212       1 scheduler.go:451] ScheduleAlgoTime 2.220841ms Start:2018-10-18 09:56:46.623983241 +0000 UTC m=+23.647467044 End:2018-10-18 09:56:46.626204081 +0000 UTC m=+23.649687885
I1018 09:56:46.626244       1 scheduler.go:454] Total Schedule Algo cumulative time:2.688635763s for 1147
I1018 09:56:46.628735       1 scheduler.go:451] ScheduleAlgoTime 2.261196ms Start:2018-10-18 09:56:46.62646566 +0000 UTC m=+23.649949545 End:2018-10-18 09:56:46.628726902 +0000 UTC m=+23.652210741
I1018 09:56:46.628763       1 scheduler.go:454] Total Schedule Algo cumulative time:2.690896959s for 1148
I1018 09:56:46.631635       1 scheduler.go:451] ScheduleAlgoTime 2.58317ms Start:2018-10-18 09:56:46.629041881 +0000 UTC m=+23.652525770 End:2018-10-18 09:56:46.631625132 +0000 UTC m=+23.655108940
I1018 09:56:46.631698       1 scheduler.go:454] Total Schedule Algo cumulative time:2.693480129s for 1149
I1018 09:56:46.634077       1 scheduler.go:451] ScheduleAlgoTime 2.059633ms Start:2018-10-18 09:56:46.632009427 +0000 UTC m=+23.655493316 End:2018-10-18 09:56:46.634069145 +0000 UTC m=+23.657552949
I1018 09:56:46.634116       1 scheduler.go:454] Total Schedule Algo cumulative time:2.695539762s for 1150
I1018 09:56:46.636612       1 scheduler.go:451] ScheduleAlgoTime 2.31839ms Start:2018-10-18 09:56:46.634284493 +0000 UTC m=+23.657768380 End:2018-10-18 09:56:46.636602964 +0000 UTC m=+23.660086770
I1018 09:56:46.636661       1 scheduler.go:454] Total Schedule Algo cumulative time:2.697858152s for 1151
I1018 09:56:46.639127       1 scheduler.go:451] ScheduleAlgoTime 2.231695ms Start:2018-10-18 09:56:46.636888042 +0000 UTC m=+23.660371948 End:2018-10-18 09:56:46.639119828 +0000 UTC m=+23.662603643
I1018 09:56:46.639157       1 scheduler.go:454] Total Schedule Algo cumulative time:2.700089847s for 1152
I1018 09:56:46.641547       1 scheduler.go:451] ScheduleAlgoTime 2.154295ms Start:2018-10-18 09:56:46.639384403 +0000 UTC m=+23.662868298 End:2018-10-18 09:56:46.64153879 +0000 UTC m=+23.665022593
I1018 09:56:46.641578       1 scheduler.go:454] Total Schedule Algo cumulative time:2.702244142s for 1153
I1018 09:56:46.644174       1 scheduler.go:451] ScheduleAlgoTime 2.325394ms Start:2018-10-18 09:56:46.641839934 +0000 UTC m=+23.665323867 End:2018-10-18 09:56:46.644165458 +0000 UTC m=+23.667649261
I1018 09:56:46.644205       1 scheduler.go:454] Total Schedule Algo cumulative time:2.704569536s for 1154
I1018 09:56:46.646594       1 scheduler.go:451] ScheduleAlgoTime 2.260093ms Start:2018-10-18 09:56:46.644327912 +0000 UTC m=+23.667811810 End:2018-10-18 09:56:46.6465881 +0000 UTC m=+23.670071903
I1018 09:56:46.646624       1 scheduler.go:454] Total Schedule Algo cumulative time:2.706829629s for 1155
I1018 09:56:46.649277       1 scheduler.go:451] ScheduleAlgoTime 2.3848ms Start:2018-10-18 09:56:46.646885605 +0000 UTC m=+23.670369509 End:2018-10-18 09:56:46.649270504 +0000 UTC m=+23.672754309
I1018 09:56:46.649302       1 scheduler.go:454] Total Schedule Algo cumulative time:2.709214429s for 1156
I1018 09:56:46.652108       1 scheduler.go:451] ScheduleAlgoTime 2.270728ms Start:2018-10-18 09:56:46.649827226 +0000 UTC m=+23.673311131 End:2018-10-18 09:56:46.65209805 +0000 UTC m=+23.675581859
I1018 09:56:46.652139       1 scheduler.go:454] Total Schedule Algo cumulative time:2.711485157s for 1157
I1018 09:56:46.654839       1 scheduler.go:451] ScheduleAlgoTime 2.486208ms Start:2018-10-18 09:56:46.652342095 +0000 UTC m=+23.675825974 End:2018-10-18 09:56:46.654828372 +0000 UTC m=+23.678312182
I1018 09:56:46.654872       1 scheduler.go:454] Total Schedule Algo cumulative time:2.713971365s for 1158
I1018 09:56:46.658652       1 scheduler.go:451] ScheduleAlgoTime 3.366409ms Start:2018-10-18 09:56:46.65527572 +0000 UTC m=+23.678759586 End:2018-10-18 09:56:46.658642191 +0000 UTC m=+23.682125995
I1018 09:56:46.658710       1 scheduler.go:454] Total Schedule Algo cumulative time:2.717337774s for 1159
I1018 09:56:46.666216       1 scheduler.go:451] ScheduleAlgoTime 7.254324ms Start:2018-10-18 09:56:46.658948711 +0000 UTC m=+23.682432678 End:2018-10-18 09:56:46.666203199 +0000 UTC m=+23.689687002
I1018 09:56:46.666263       1 scheduler.go:454] Total Schedule Algo cumulative time:2.724592098s for 1160
I1018 09:56:46.671543       1 scheduler.go:451] ScheduleAlgoTime 3.794366ms Start:2018-10-18 09:56:46.667738142 +0000 UTC m=+23.691221945 End:2018-10-18 09:56:46.671532494 +0000 UTC m=+23.695016311
I1018 09:56:46.671584       1 scheduler.go:454] Total Schedule Algo cumulative time:2.728386464s for 1161
I1018 09:56:46.675404       1 scheduler.go:451] ScheduleAlgoTime 3.604004ms Start:2018-10-18 09:56:46.671790383 +0000 UTC m=+23.695274313 End:2018-10-18 09:56:46.67539451 +0000 UTC m=+23.698878317
I1018 09:56:46.675447       1 scheduler.go:454] Total Schedule Algo cumulative time:2.731990468s for 1162
I1018 09:56:46.678416       1 scheduler.go:451] ScheduleAlgoTime 2.467795ms Start:2018-10-18 09:56:46.675937308 +0000 UTC m=+23.699421207 End:2018-10-18 09:56:46.678405192 +0000 UTC m=+23.701889002
I1018 09:56:46.678463       1 scheduler.go:454] Total Schedule Algo cumulative time:2.734458263s for 1163
I1018 09:56:46.681373       1 scheduler.go:451] ScheduleAlgoTime 2.487072ms Start:2018-10-18 09:56:46.678876693 +0000 UTC m=+23.702360582 End:2018-10-18 09:56:46.68136385 +0000 UTC m=+23.704847654
I1018 09:56:46.681421       1 scheduler.go:454] Total Schedule Algo cumulative time:2.736945335s for 1164
I1018 09:56:46.684015       1 scheduler.go:451] ScheduleAlgoTime 2.322464ms Start:2018-10-18 09:56:46.68168251 +0000 UTC m=+23.705166416 End:2018-10-18 09:56:46.684005071 +0000 UTC m=+23.707488880
I1018 09:56:46.684048       1 scheduler.go:454] Total Schedule Algo cumulative time:2.739267799s for 1165
I1018 09:56:46.686995       1 scheduler.go:451] ScheduleAlgoTime 2.668506ms Start:2018-10-18 09:56:46.68431733 +0000 UTC m=+23.707801237 End:2018-10-18 09:56:46.686985941 +0000 UTC m=+23.710469743
I1018 09:56:46.687035       1 scheduler.go:454] Total Schedule Algo cumulative time:2.741936305s for 1166
I1018 09:56:46.689518       1 scheduler.go:451] ScheduleAlgoTime 2.271138ms Start:2018-10-18 09:56:46.687238586 +0000 UTC m=+23.710722487 End:2018-10-18 09:56:46.689509821 +0000 UTC m=+23.712993625
I1018 09:56:46.689550       1 scheduler.go:454] Total Schedule Algo cumulative time:2.744207443s for 1167
I1018 09:56:46.692168       1 scheduler.go:451] ScheduleAlgoTime 2.360656ms Start:2018-10-18 09:56:46.689797099 +0000 UTC m=+23.713281000 End:2018-10-18 09:56:46.692157818 +0000 UTC m=+23.715641656
I1018 09:56:46.692200       1 scheduler.go:454] Total Schedule Algo cumulative time:2.746568099s for 1168
I1018 09:56:46.694454       1 scheduler.go:451] ScheduleAlgoTime 2.092654ms Start:2018-10-18 09:56:46.692353427 +0000 UTC m=+23.715837334 End:2018-10-18 09:56:46.694446186 +0000 UTC m=+23.717929988
I1018 09:56:46.694493       1 scheduler.go:454] Total Schedule Algo cumulative time:2.748660753s for 1169
I1018 09:56:46.696730       1 scheduler.go:451] ScheduleAlgoTime 1.952512ms Start:2018-10-18 09:56:46.694767894 +0000 UTC m=+23.718251787 End:2018-10-18 09:56:46.696720496 +0000 UTC m=+23.720204299
I1018 09:56:46.696764       1 scheduler.go:454] Total Schedule Algo cumulative time:2.750613265s for 1170
I1018 09:56:46.699204       1 scheduler.go:451] ScheduleAlgoTime 2.149354ms Start:2018-10-18 09:56:46.697046458 +0000 UTC m=+23.720530393 End:2018-10-18 09:56:46.699195943 +0000 UTC m=+23.722679747
I1018 09:56:46.699238       1 scheduler.go:454] Total Schedule Algo cumulative time:2.752762619s for 1171
I1018 09:56:46.701787       1 scheduler.go:451] ScheduleAlgoTime 2.341965ms Start:2018-10-18 09:56:46.699430462 +0000 UTC m=+23.722914378 End:2018-10-18 09:56:46.701772518 +0000 UTC m=+23.725256343
I1018 09:56:46.701829       1 scheduler.go:454] Total Schedule Algo cumulative time:2.755104584s for 1172
I1018 09:56:46.704392       1 scheduler.go:451] ScheduleAlgoTime 2.258138ms Start:2018-10-18 09:56:46.702125557 +0000 UTC m=+23.725609444 End:2018-10-18 09:56:46.704383779 +0000 UTC m=+23.727867582
I1018 09:56:46.704435       1 scheduler.go:454] Total Schedule Algo cumulative time:2.757362722s for 1173
I1018 09:56:46.707159       1 scheduler.go:451] ScheduleAlgoTime 2.453688ms Start:2018-10-18 09:56:46.704694643 +0000 UTC m=+23.728178534 End:2018-10-18 09:56:46.707148412 +0000 UTC m=+23.730632222
I1018 09:56:46.707200       1 scheduler.go:454] Total Schedule Algo cumulative time:2.75981641s for 1174
I1018 09:56:46.709507       1 scheduler.go:451] ScheduleAlgoTime 2.048953ms Start:2018-10-18 09:56:46.707450248 +0000 UTC m=+23.730934128 End:2018-10-18 09:56:46.709499278 +0000 UTC m=+23.732983081
I1018 09:56:46.709539       1 scheduler.go:454] Total Schedule Algo cumulative time:2.761865363s for 1175
I1018 09:56:46.712119       1 scheduler.go:451] ScheduleAlgoTime 2.353726ms Start:2018-10-18 09:56:46.70975665 +0000 UTC m=+23.733240526 End:2018-10-18 09:56:46.712110441 +0000 UTC m=+23.735594252
I1018 09:56:46.712154       1 scheduler.go:454] Total Schedule Algo cumulative time:2.764219089s for 1176
I1018 09:56:46.714283       1 scheduler.go:451] ScheduleAlgoTime 1.927591ms Start:2018-10-18 09:56:46.712347702 +0000 UTC m=+23.735831583 End:2018-10-18 09:56:46.714275371 +0000 UTC m=+23.737759174
I1018 09:56:46.714315       1 scheduler.go:454] Total Schedule Algo cumulative time:2.76614668s for 1177
I1018 09:56:46.716480       1 scheduler.go:451] ScheduleAlgoTime 1.999831ms Start:2018-10-18 09:56:46.714472885 +0000 UTC m=+23.737956766 End:2018-10-18 09:56:46.716472795 +0000 UTC m=+23.739956597
I1018 09:56:46.716520       1 scheduler.go:454] Total Schedule Algo cumulative time:2.768146511s for 1178
I1018 09:56:46.718660       1 scheduler.go:451] ScheduleAlgoTime 1.949056ms Start:2018-10-18 09:56:46.716702681 +0000 UTC m=+23.740186609 End:2018-10-18 09:56:46.71865186 +0000 UTC m=+23.742135665
I1018 09:56:46.718720       1 scheduler.go:454] Total Schedule Algo cumulative time:2.770095567s for 1179
I1018 09:56:46.720927       1 scheduler.go:451] ScheduleAlgoTime 2.033984ms Start:2018-10-18 09:56:46.718885663 +0000 UTC m=+23.742369545 End:2018-10-18 09:56:46.720919727 +0000 UTC m=+23.744403529
I1018 09:56:46.720958       1 scheduler.go:454] Total Schedule Algo cumulative time:2.772129551s for 1180
I1018 09:56:46.723302       1 scheduler.go:451] ScheduleAlgoTime 2.100066ms Start:2018-10-18 09:56:46.721190902 +0000 UTC m=+23.744674805 End:2018-10-18 09:56:46.723291056 +0000 UTC m=+23.746774871
I1018 09:56:46.723344       1 scheduler.go:454] Total Schedule Algo cumulative time:2.774229617s for 1181
I1018 09:56:46.725818       1 scheduler.go:451] ScheduleAlgoTime 2.314333ms Start:2018-10-18 09:56:46.723496057 +0000 UTC m=+23.746979869 End:2018-10-18 09:56:46.725810366 +0000 UTC m=+23.749294202
I1018 09:56:46.725850       1 scheduler.go:454] Total Schedule Algo cumulative time:2.77654395s for 1182
I1018 09:56:46.728094       1 scheduler.go:451] ScheduleAlgoTime 1.991098ms Start:2018-10-18 09:56:46.726093481 +0000 UTC m=+23.749577378 End:2018-10-18 09:56:46.72808466 +0000 UTC m=+23.751568476
I1018 09:56:46.728127       1 scheduler.go:454] Total Schedule Algo cumulative time:2.778535048s for 1183
I1018 09:56:46.730790       1 scheduler.go:451] ScheduleAlgoTime 2.297376ms Start:2018-10-18 09:56:46.728484848 +0000 UTC m=+23.751968756 End:2018-10-18 09:56:46.730782328 +0000 UTC m=+23.754266132
I1018 09:56:46.730821       1 scheduler.go:454] Total Schedule Algo cumulative time:2.780832424s for 1184
I1018 09:56:46.733082       1 scheduler.go:451] ScheduleAlgoTime 2.038618ms Start:2018-10-18 09:56:46.731035927 +0000 UTC m=+23.754519823 End:2018-10-18 09:56:46.733074638 +0000 UTC m=+23.756558441
I1018 09:56:46.733114       1 scheduler.go:454] Total Schedule Algo cumulative time:2.782871042s for 1185
I1018 09:56:46.735861       1 scheduler.go:451] ScheduleAlgoTime 2.540647ms Start:2018-10-18 09:56:46.733310674 +0000 UTC m=+23.756794544 End:2018-10-18 09:56:46.735851388 +0000 UTC m=+23.759335191
I1018 09:56:46.735899       1 scheduler.go:454] Total Schedule Algo cumulative time:2.785411689s for 1186
I1018 09:56:46.738549       1 scheduler.go:451] ScheduleAlgoTime 2.423397ms Start:2018-10-18 09:56:46.736118849 +0000 UTC m=+23.759602745 End:2018-10-18 09:56:46.738542337 +0000 UTC m=+23.762026142
I1018 09:56:46.738585       1 scheduler.go:454] Total Schedule Algo cumulative time:2.787835086s for 1187
I1018 09:56:46.740638       1 scheduler.go:451] ScheduleAlgoTime 1.819228ms Start:2018-10-18 09:56:46.7388107 +0000 UTC m=+23.762294513 End:2018-10-18 09:56:46.740629938 +0000 UTC m=+23.764113741
I1018 09:56:46.740697       1 scheduler.go:454] Total Schedule Algo cumulative time:2.789654314s for 1188
I1018 09:56:46.743300       1 scheduler.go:451] ScheduleAlgoTime 2.412597ms Start:2018-10-18 09:56:46.740880194 +0000 UTC m=+23.764364075 End:2018-10-18 09:56:46.743292864 +0000 UTC m=+23.766776672
I1018 09:56:46.743333       1 scheduler.go:454] Total Schedule Algo cumulative time:2.792066911s for 1189
I1018 09:56:46.745391       1 scheduler.go:451] ScheduleAlgoTime 1.866796ms Start:2018-10-18 09:56:46.743514965 +0000 UTC m=+23.766998880 End:2018-10-18 09:56:46.745381862 +0000 UTC m=+23.768865676
I1018 09:56:46.745429       1 scheduler.go:454] Total Schedule Algo cumulative time:2.793933707s for 1190
I1018 09:56:46.747921       1 scheduler.go:451] ScheduleAlgoTime 2.172539ms Start:2018-10-18 09:56:46.745740754 +0000 UTC m=+23.769224646 End:2018-10-18 09:56:46.747913284 +0000 UTC m=+23.771397185
I1018 09:56:46.747966       1 scheduler.go:454] Total Schedule Algo cumulative time:2.796106246s for 1191
I1018 09:56:46.750472       1 scheduler.go:451] ScheduleAlgoTime 2.289339ms Start:2018-10-18 09:56:46.748174588 +0000 UTC m=+23.771658542 End:2018-10-18 09:56:46.750464074 +0000 UTC m=+23.773947881
I1018 09:56:46.750510       1 scheduler.go:454] Total Schedule Algo cumulative time:2.798395585s for 1192
I1018 09:56:46.753503       1 scheduler.go:451] ScheduleAlgoTime 2.595186ms Start:2018-10-18 09:56:46.750897267 +0000 UTC m=+23.774381181 End:2018-10-18 09:56:46.753492562 +0000 UTC m=+23.776976367
I1018 09:56:46.753537       1 scheduler.go:454] Total Schedule Algo cumulative time:2.800990771s for 1193
I1018 09:56:46.755912       1 scheduler.go:451] ScheduleAlgoTime 2.136916ms Start:2018-10-18 09:56:46.753765708 +0000 UTC m=+23.777249579 End:2018-10-18 09:56:46.755902596 +0000 UTC m=+23.779386495
I1018 09:56:46.755949       1 scheduler.go:454] Total Schedule Algo cumulative time:2.803127687s for 1194
I1018 09:56:46.758489       1 scheduler.go:451] ScheduleAlgoTime 2.301826ms Start:2018-10-18 09:56:46.756175681 +0000 UTC m=+23.779659585 End:2018-10-18 09:56:46.758477501 +0000 UTC m=+23.781961411
I1018 09:56:46.758530       1 scheduler.go:454] Total Schedule Algo cumulative time:2.805429513s for 1195
I1018 09:56:46.761250       1 scheduler.go:451] ScheduleAlgoTime 2.438618ms Start:2018-10-18 09:56:46.758803023 +0000 UTC m=+23.782286917 End:2018-10-18 09:56:46.761241728 +0000 UTC m=+23.784725535
I1018 09:56:46.761278       1 scheduler.go:454] Total Schedule Algo cumulative time:2.807868131s for 1196
I1018 09:56:46.763689       1 scheduler.go:451] ScheduleAlgoTime 2.170438ms Start:2018-10-18 09:56:46.761488876 +0000 UTC m=+23.784972751 End:2018-10-18 09:56:46.763659367 +0000 UTC m=+23.787143189
I1018 09:56:46.763722       1 scheduler.go:454] Total Schedule Algo cumulative time:2.810038569s for 1197
I1018 09:56:46.766045       1 scheduler.go:451] ScheduleAlgoTime 2.228817ms Start:2018-10-18 09:56:46.763809044 +0000 UTC m=+23.787292930 End:2018-10-18 09:56:46.766037942 +0000 UTC m=+23.789521747
I1018 09:56:46.766075       1 scheduler.go:454] Total Schedule Algo cumulative time:2.812267386s for 1198
I1018 09:56:46.768271       1 scheduler.go:451] ScheduleAlgoTime 1.964439ms Start:2018-10-18 09:56:46.766267837 +0000 UTC m=+23.789751738 End:2018-10-18 09:56:46.768232371 +0000 UTC m=+23.791716177
I1018 09:56:46.768298       1 scheduler.go:454] Total Schedule Algo cumulative time:2.814231825s for 1199
I1018 09:56:46.770626       1 scheduler.go:451] ScheduleAlgoTime 2.040362ms Start:2018-10-18 09:56:46.768579041 +0000 UTC m=+23.792062975 End:2018-10-18 09:56:46.770619535 +0000 UTC m=+23.794103337
I1018 09:56:46.770699       1 scheduler.go:454] Total Schedule Algo cumulative time:2.816272187s for 1200
I1018 09:56:46.773542       1 scheduler.go:451] ScheduleAlgoTime 2.565888ms Start:2018-10-18 09:56:46.77096874 +0000 UTC m=+23.794452660 End:2018-10-18 09:56:46.773534742 +0000 UTC m=+23.797018548
I1018 09:56:46.773569       1 scheduler.go:454] Total Schedule Algo cumulative time:2.818838075s for 1201
I1018 09:56:46.775746       1 scheduler.go:451] ScheduleAlgoTime 1.991168ms Start:2018-10-18 09:56:46.773742038 +0000 UTC m=+23.797225950 End:2018-10-18 09:56:46.775733286 +0000 UTC m=+23.799217118
I1018 09:56:46.775787       1 scheduler.go:454] Total Schedule Algo cumulative time:2.820829243s for 1202
I1018 09:56:46.778189       1 scheduler.go:451] ScheduleAlgoTime 2.183639ms Start:2018-10-18 09:56:46.775996695 +0000 UTC m=+23.799480616 End:2018-10-18 09:56:46.778180451 +0000 UTC m=+23.801664255
I1018 09:56:46.778223       1 scheduler.go:454] Total Schedule Algo cumulative time:2.823012882s for 1203
I1018 09:56:46.780549       1 scheduler.go:451] ScheduleAlgoTime 2.11682ms Start:2018-10-18 09:56:46.778424787 +0000 UTC m=+23.801908685 End:2018-10-18 09:56:46.7805417 +0000 UTC m=+23.804025505
I1018 09:56:46.780578       1 scheduler.go:454] Total Schedule Algo cumulative time:2.825129702s for 1204
I1018 09:56:46.782735       1 scheduler.go:451] ScheduleAlgoTime 1.939679ms Start:2018-10-18 09:56:46.780783979 +0000 UTC m=+23.804267878 End:2018-10-18 09:56:46.78272375 +0000 UTC m=+23.806207557
I1018 09:56:46.782797       1 scheduler.go:454] Total Schedule Algo cumulative time:2.827069381s for 1205
I1018 09:56:46.785140       1 scheduler.go:451] ScheduleAlgoTime 2.114232ms Start:2018-10-18 09:56:46.783015343 +0000 UTC m=+23.806499211 End:2018-10-18 09:56:46.785129536 +0000 UTC m=+23.808613443
I1018 09:56:46.785183       1 scheduler.go:454] Total Schedule Algo cumulative time:2.829183613s for 1206
I1018 09:56:46.787767       1 scheduler.go:451] ScheduleAlgoTime 2.40629ms Start:2018-10-18 09:56:46.785348736 +0000 UTC m=+23.808832546 End:2018-10-18 09:56:46.787755018 +0000 UTC m=+23.811238836
I1018 09:56:46.787805       1 scheduler.go:454] Total Schedule Algo cumulative time:2.831589903s for 1207
I1018 09:56:46.790254       1 scheduler.go:451] ScheduleAlgoTime 2.270493ms Start:2018-10-18 09:56:46.787975711 +0000 UTC m=+23.811459608 End:2018-10-18 09:56:46.790246297 +0000 UTC m=+23.813730101
I1018 09:56:46.790958       1 scheduler.go:454] Total Schedule Algo cumulative time:2.833860396s for 1208
I1018 09:56:46.793583       1 scheduler.go:451] ScheduleAlgoTime 2.295026ms Start:2018-10-18 09:56:46.791280921 +0000 UTC m=+23.814764829 End:2018-10-18 09:56:46.793576052 +0000 UTC m=+23.817059855
I1018 09:56:46.793611       1 scheduler.go:454] Total Schedule Algo cumulative time:2.836155422s for 1209
I1018 09:56:46.796594       1 scheduler.go:451] ScheduleAlgoTime 2.737736ms Start:2018-10-18 09:56:46.793848245 +0000 UTC m=+23.817332092 End:2018-10-18 09:56:46.796586021 +0000 UTC m=+23.820069828
I1018 09:56:46.796626       1 scheduler.go:454] Total Schedule Algo cumulative time:2.838893158s for 1210
I1018 09:56:46.799542       1 scheduler.go:451] ScheduleAlgoTime 2.580416ms Start:2018-10-18 09:56:46.796953943 +0000 UTC m=+23.820437833 End:2018-10-18 09:56:46.799534447 +0000 UTC m=+23.823018249
I1018 09:56:46.799573       1 scheduler.go:454] Total Schedule Algo cumulative time:2.841473574s for 1211
I1018 09:56:46.802187       1 scheduler.go:451] ScheduleAlgoTime 2.393733ms Start:2018-10-18 09:56:46.799782597 +0000 UTC m=+23.823266401 End:2018-10-18 09:56:46.802176325 +0000 UTC m=+23.825660134
I1018 09:56:46.802232       1 scheduler.go:454] Total Schedule Algo cumulative time:2.843867307s for 1212
I1018 09:56:46.804845       1 scheduler.go:451] ScheduleAlgoTime 2.228623ms Start:2018-10-18 09:56:46.802608587 +0000 UTC m=+23.826092467 End:2018-10-18 09:56:46.804837283 +0000 UTC m=+23.828321090
I1018 09:56:46.804882       1 scheduler.go:454] Total Schedule Algo cumulative time:2.84609593s for 1213
I1018 09:56:46.807273       1 scheduler.go:451] ScheduleAlgoTime 2.048527ms Start:2018-10-18 09:56:46.805216386 +0000 UTC m=+23.828700269 End:2018-10-18 09:56:46.807264992 +0000 UTC m=+23.830748796
I1018 09:56:46.807313       1 scheduler.go:454] Total Schedule Algo cumulative time:2.848144457s for 1214
I1018 09:56:46.810238       1 scheduler.go:451] ScheduleAlgoTime 2.333273ms Start:2018-10-18 09:56:46.807894138 +0000 UTC m=+23.831378056 End:2018-10-18 09:56:46.810227507 +0000 UTC m=+23.833711329
I1018 09:56:46.810278       1 scheduler.go:454] Total Schedule Algo cumulative time:2.85047773s for 1215
I1018 09:56:46.813181       1 scheduler.go:451] ScheduleAlgoTime 2.569579ms Start:2018-10-18 09:56:46.810600379 +0000 UTC m=+23.834084311 End:2018-10-18 09:56:46.81317008 +0000 UTC m=+23.836653890
I1018 09:56:46.813220       1 scheduler.go:454] Total Schedule Algo cumulative time:2.853047309s for 1216
I1018 09:56:46.815759       1 scheduler.go:451] ScheduleAlgoTime 2.35511ms Start:2018-10-18 09:56:46.813394021 +0000 UTC m=+23.836877857 End:2018-10-18 09:56:46.81574916 +0000 UTC m=+23.839232967
I1018 09:56:46.815799       1 scheduler.go:454] Total Schedule Algo cumulative time:2.855402419s for 1217
I1018 09:56:46.818429       1 scheduler.go:451] ScheduleAlgoTime 2.419396ms Start:2018-10-18 09:56:46.816002775 +0000 UTC m=+23.839486657 End:2018-10-18 09:56:46.818422246 +0000 UTC m=+23.841906053
I1018 09:56:46.818471       1 scheduler.go:454] Total Schedule Algo cumulative time:2.857821815s for 1218
I1018 09:56:46.821042       1 scheduler.go:451] ScheduleAlgoTime 2.290406ms Start:2018-10-18 09:56:46.818738989 +0000 UTC m=+23.842222813 End:2018-10-18 09:56:46.821029382 +0000 UTC m=+23.844513219
I1018 09:56:46.821083       1 scheduler.go:454] Total Schedule Algo cumulative time:2.860112221s for 1219
I1018 09:56:46.823994       1 scheduler.go:451] ScheduleAlgoTime 2.675752ms Start:2018-10-18 09:56:46.821308197 +0000 UTC m=+23.844792077 End:2018-10-18 09:56:46.823984025 +0000 UTC m=+23.847467829
I1018 09:56:46.824035       1 scheduler.go:454] Total Schedule Algo cumulative time:2.862787973s for 1220
I1018 09:56:46.826487       1 scheduler.go:451] ScheduleAlgoTime 2.221349ms Start:2018-10-18 09:56:46.824257248 +0000 UTC m=+23.847741185 End:2018-10-18 09:56:46.826478727 +0000 UTC m=+23.849962534
I1018 09:56:46.826519       1 scheduler.go:454] Total Schedule Algo cumulative time:2.865009322s for 1221
I1018 09:56:46.829410       1 scheduler.go:451] ScheduleAlgoTime 2.641472ms Start:2018-10-18 09:56:46.826757411 +0000 UTC m=+23.850241280 End:2018-10-18 09:56:46.829398931 +0000 UTC m=+23.852882752
I1018 09:56:46.829448       1 scheduler.go:454] Total Schedule Algo cumulative time:2.867650794s for 1222
I1018 09:56:46.831913       1 scheduler.go:451] ScheduleAlgoTime 2.307653ms Start:2018-10-18 09:56:46.829595774 +0000 UTC m=+23.853079655 End:2018-10-18 09:56:46.831903506 +0000 UTC m=+23.855387308
I1018 09:56:46.831946       1 scheduler.go:454] Total Schedule Algo cumulative time:2.869958447s for 1223
I1018 09:56:46.834412       1 scheduler.go:451] ScheduleAlgoTime 2.20809ms Start:2018-10-18 09:56:46.832192924 +0000 UTC m=+23.855676851 End:2018-10-18 09:56:46.834401065 +0000 UTC m=+23.857884941
I1018 09:56:46.834453       1 scheduler.go:454] Total Schedule Algo cumulative time:2.872166537s for 1224
I1018 09:56:46.836902       1 scheduler.go:451] ScheduleAlgoTime 2.147617ms Start:2018-10-18 09:56:46.834742774 +0000 UTC m=+23.858226689 End:2018-10-18 09:56:46.836890482 +0000 UTC m=+23.860374306
I1018 09:56:46.836939       1 scheduler.go:454] Total Schedule Algo cumulative time:2.874314154s for 1225
I1018 09:56:46.839445       1 scheduler.go:451] ScheduleAlgoTime 2.313453ms Start:2018-10-18 09:56:46.837125679 +0000 UTC m=+23.860609569 End:2018-10-18 09:56:46.839439218 +0000 UTC m=+23.862923022
I1018 09:56:46.839473       1 scheduler.go:454] Total Schedule Algo cumulative time:2.876627607s for 1226
I1018 09:56:46.842281       1 scheduler.go:451] ScheduleAlgoTime 2.475966ms Start:2018-10-18 09:56:46.839795515 +0000 UTC m=+23.863279336 End:2018-10-18 09:56:46.8422715 +0000 UTC m=+23.865755302
I1018 09:56:46.842313       1 scheduler.go:454] Total Schedule Algo cumulative time:2.879103573s for 1227
I1018 09:56:46.844945       1 scheduler.go:451] ScheduleAlgoTime 2.361521ms Start:2018-10-18 09:56:46.842574486 +0000 UTC m=+23.866058328 End:2018-10-18 09:56:46.844936012 +0000 UTC m=+23.868419849
I1018 09:56:46.844980       1 scheduler.go:454] Total Schedule Algo cumulative time:2.881465094s for 1228
I1018 09:56:46.847558       1 scheduler.go:451] ScheduleAlgoTime 2.280092ms Start:2018-10-18 09:56:46.845268286 +0000 UTC m=+23.868752176 End:2018-10-18 09:56:46.84754846 +0000 UTC m=+23.871032268
I1018 09:56:46.847589       1 scheduler.go:454] Total Schedule Algo cumulative time:2.883745186s for 1229
I1018 09:56:46.850212       1 scheduler.go:451] ScheduleAlgoTime 2.340004ms Start:2018-10-18 09:56:46.847862738 +0000 UTC m=+23.871346615 End:2018-10-18 09:56:46.850202811 +0000 UTC m=+23.873686619
I1018 09:56:46.850243       1 scheduler.go:454] Total Schedule Algo cumulative time:2.88608519s for 1230
I1018 09:56:46.852662       1 scheduler.go:451] ScheduleAlgoTime 2.166062ms Start:2018-10-18 09:56:46.850487272 +0000 UTC m=+23.873971218 End:2018-10-18 09:56:46.852653473 +0000 UTC m=+23.876137280
I1018 09:56:46.852729       1 scheduler.go:454] Total Schedule Algo cumulative time:2.888251252s for 1231
I1018 09:56:46.855555       1 scheduler.go:451] ScheduleAlgoTime 2.622911ms Start:2018-10-18 09:56:46.852922964 +0000 UTC m=+23.876406868 End:2018-10-18 09:56:46.855545977 +0000 UTC m=+23.879029779
I1018 09:56:46.855599       1 scheduler.go:454] Total Schedule Algo cumulative time:2.890874163s for 1232
I1018 09:56:46.857927       1 scheduler.go:451] ScheduleAlgoTime 2.134719ms Start:2018-10-18 09:56:46.855784587 +0000 UTC m=+23.879268474 End:2018-10-18 09:56:46.857919389 +0000 UTC m=+23.881403193
I1018 09:56:46.857959       1 scheduler.go:454] Total Schedule Algo cumulative time:2.893008882s for 1233
I1018 09:56:46.860294       1 scheduler.go:451] ScheduleAlgoTime 1.992589ms Start:2018-10-18 09:56:46.858291536 +0000 UTC m=+23.881775377 End:2018-10-18 09:56:46.860284164 +0000 UTC m=+23.883767966
I1018 09:56:46.860332       1 scheduler.go:454] Total Schedule Algo cumulative time:2.895001471s for 1234
I1018 09:56:46.862579       1 scheduler.go:451] ScheduleAlgoTime 2.032112ms Start:2018-10-18 09:56:46.860536447 +0000 UTC m=+23.884020334 End:2018-10-18 09:56:46.862568638 +0000 UTC m=+23.886052446
I1018 09:56:46.862622       1 scheduler.go:454] Total Schedule Algo cumulative time:2.897033583s for 1235
I1018 09:56:46.865201       1 scheduler.go:451] ScheduleAlgoTime 2.427964ms Start:2018-10-18 09:56:46.862764573 +0000 UTC m=+23.886248399 End:2018-10-18 09:56:46.865192559 +0000 UTC m=+23.888676363
I1018 09:56:46.865232       1 scheduler.go:454] Total Schedule Algo cumulative time:2.899461547s for 1236
I1018 09:56:46.867933       1 scheduler.go:451] ScheduleAlgoTime 2.346294ms Start:2018-10-18 09:56:46.86557568 +0000 UTC m=+23.889059608 End:2018-10-18 09:56:46.867922088 +0000 UTC m=+23.891405902
I1018 09:56:46.867972       1 scheduler.go:454] Total Schedule Algo cumulative time:2.901807841s for 1237
I1018 09:56:46.870482       1 scheduler.go:451] ScheduleAlgoTime 2.287046ms Start:2018-10-18 09:56:46.868186269 +0000 UTC m=+23.891670083 End:2018-10-18 09:56:46.870473326 +0000 UTC m=+23.893957129
I1018 09:56:46.870519       1 scheduler.go:454] Total Schedule Algo cumulative time:2.904094887s for 1238
I1018 09:56:46.873250       1 scheduler.go:451] ScheduleAlgoTime 2.500602ms Start:2018-10-18 09:56:46.870738879 +0000 UTC m=+23.894222683 End:2018-10-18 09:56:46.873239355 +0000 UTC m=+23.896723285
I1018 09:56:46.873287       1 scheduler.go:454] Total Schedule Algo cumulative time:2.906595489s for 1239
I1018 09:56:46.875482       1 scheduler.go:451] ScheduleAlgoTime 2.091401ms Start:2018-10-18 09:56:46.873381105 +0000 UTC m=+23.896864918 End:2018-10-18 09:56:46.875472499 +0000 UTC m=+23.898956319
I1018 09:56:46.875521       1 scheduler.go:454] Total Schedule Algo cumulative time:2.90868689s for 1240
I1018 09:56:46.878160       1 scheduler.go:451] ScheduleAlgoTime 2.419695ms Start:2018-10-18 09:56:46.875731346 +0000 UTC m=+23.899215221 End:2018-10-18 09:56:46.878151108 +0000 UTC m=+23.901634916
I1018 09:56:46.878195       1 scheduler.go:454] Total Schedule Algo cumulative time:2.911106585s for 1241
I1018 09:56:46.880422       1 scheduler.go:451] ScheduleAlgoTime 2.025788ms Start:2018-10-18 09:56:46.878387763 +0000 UTC m=+23.901871640 End:2018-10-18 09:56:46.880413624 +0000 UTC m=+23.903897428
I1018 09:56:46.880451       1 scheduler.go:454] Total Schedule Algo cumulative time:2.913132373s for 1242
I1018 09:56:46.883234       1 scheduler.go:451] ScheduleAlgoTime 2.309904ms Start:2018-10-18 09:56:46.88091635 +0000 UTC m=+23.904400232 End:2018-10-18 09:56:46.883226313 +0000 UTC m=+23.906710136
I1018 09:56:46.883264       1 scheduler.go:454] Total Schedule Algo cumulative time:2.915442277s for 1243
I1018 09:56:46.901593       1 scheduler.go:451] ScheduleAlgoTime 18.226732ms Start:2018-10-18 09:56:46.883355182 +0000 UTC m=+23.906838985 End:2018-10-18 09:56:46.901581914 +0000 UTC m=+23.925065717
I1018 09:56:46.901644       1 scheduler.go:454] Total Schedule Algo cumulative time:2.933669009s for 1244
I1018 09:56:46.904393       1 scheduler.go:451] ScheduleAlgoTime 2.5304ms Start:2018-10-18 09:56:46.901848405 +0000 UTC m=+23.925332304 End:2018-10-18 09:56:46.90437889 +0000 UTC m=+23.927862704
I1018 09:56:46.904451       1 scheduler.go:454] Total Schedule Algo cumulative time:2.936199409s for 1245
I1018 09:56:46.908219       1 scheduler.go:451] ScheduleAlgoTime 3.493211ms Start:2018-10-18 09:56:46.904711979 +0000 UTC m=+23.928195933 End:2018-10-18 09:56:46.908205233 +0000 UTC m=+23.931689144
I1018 09:56:46.908278       1 scheduler.go:454] Total Schedule Algo cumulative time:2.93969262s for 1246
I1018 09:56:46.910787       1 scheduler.go:451] ScheduleAlgoTime 2.219014ms Start:2018-10-18 09:56:46.908555673 +0000 UTC m=+23.932039600 End:2018-10-18 09:56:46.910774762 +0000 UTC m=+23.934258614
I1018 09:56:46.910832       1 scheduler.go:454] Total Schedule Algo cumulative time:2.941911634s for 1247
I1018 09:56:46.913614       1 scheduler.go:451] ScheduleAlgoTime 2.656514ms Start:2018-10-18 09:56:46.910949477 +0000 UTC m=+23.934433339 End:2018-10-18 09:56:46.913606049 +0000 UTC m=+23.937089853
I1018 09:56:46.913645       1 scheduler.go:454] Total Schedule Algo cumulative time:2.944568148s for 1248
I1018 09:56:46.915965       1 scheduler.go:451] ScheduleAlgoTime 2.09558ms Start:2018-10-18 09:56:46.913857768 +0000 UTC m=+23.937341574 End:2018-10-18 09:56:46.915953044 +0000 UTC m=+23.939437154
I1018 09:56:46.916006       1 scheduler.go:454] Total Schedule Algo cumulative time:2.946663728s for 1249
I1018 09:56:46.918753       1 scheduler.go:451] ScheduleAlgoTime 2.54039ms Start:2018-10-18 09:56:46.916203541 +0000 UTC m=+23.939687429 End:2018-10-18 09:56:46.918744013 +0000 UTC m=+23.942227819
I1018 09:56:46.918786       1 scheduler.go:454] Total Schedule Algo cumulative time:2.949204118s for 1250
I1018 09:56:46.921322       1 scheduler.go:451] ScheduleAlgoTime 2.262603ms Start:2018-10-18 09:56:46.919053825 +0000 UTC m=+23.942537695 End:2018-10-18 09:56:46.921316496 +0000 UTC m=+23.944800298
I1018 09:56:46.921351       1 scheduler.go:454] Total Schedule Algo cumulative time:2.951466721s for 1251
I1018 09:56:46.923730       1 scheduler.go:451] ScheduleAlgoTime 1.915649ms Start:2018-10-18 09:56:46.921807507 +0000 UTC m=+23.945291382 End:2018-10-18 09:56:46.923723184 +0000 UTC m=+23.947207031
I1018 09:56:46.923762       1 scheduler.go:454] Total Schedule Algo cumulative time:2.95338237s for 1252
I1018 09:56:46.926542       1 scheduler.go:451] ScheduleAlgoTime 2.47153ms Start:2018-10-18 09:56:46.924063365 +0000 UTC m=+23.947547233 End:2018-10-18 09:56:46.926534955 +0000 UTC m=+23.950018763
I1018 09:56:46.926571       1 scheduler.go:454] Total Schedule Algo cumulative time:2.9558539s for 1253
I1018 09:56:46.929134       1 scheduler.go:451] ScheduleAlgoTime 2.425157ms Start:2018-10-18 09:56:46.926701317 +0000 UTC m=+23.950185243 End:2018-10-18 09:56:46.92912656 +0000 UTC m=+23.952610400
I1018 09:56:46.929165       1 scheduler.go:454] Total Schedule Algo cumulative time:2.958279057s for 1254
I1018 09:56:46.931236       1 scheduler.go:451] ScheduleAlgoTime 1.932641ms Start:2018-10-18 09:56:46.929296695 +0000 UTC m=+23.952780498 End:2018-10-18 09:56:46.931229335 +0000 UTC m=+23.954713139
I1018 09:56:46.931274       1 scheduler.go:454] Total Schedule Algo cumulative time:2.960211698s for 1255
I1018 09:56:46.934934       1 scheduler.go:451] ScheduleAlgoTime 3.439766ms Start:2018-10-18 09:56:46.931484238 +0000 UTC m=+23.954968075 End:2018-10-18 09:56:46.934924037 +0000 UTC m=+23.958407841
I1018 09:56:46.934972       1 scheduler.go:454] Total Schedule Algo cumulative time:2.963651464s for 1256
I1018 09:56:46.937265       1 scheduler.go:451] ScheduleAlgoTime 2.096553ms Start:2018-10-18 09:56:46.935157721 +0000 UTC m=+23.958641613 End:2018-10-18 09:56:46.937253955 +0000 UTC m=+23.960738166
I1018 09:56:46.937310       1 scheduler.go:454] Total Schedule Algo cumulative time:2.965748017s for 1257
I1018 09:56:46.940292       1 scheduler.go:451] ScheduleAlgoTime 2.711237ms Start:2018-10-18 09:56:46.937566247 +0000 UTC m=+23.961050134 End:2018-10-18 09:56:46.940277533 +0000 UTC m=+23.963761371
I1018 09:56:46.940340       1 scheduler.go:454] Total Schedule Algo cumulative time:2.968459254s for 1258
I1018 09:56:46.942968       1 scheduler.go:451] ScheduleAlgoTime 2.26313ms Start:2018-10-18 09:56:46.940694699 +0000 UTC m=+23.964178580 End:2018-10-18 09:56:46.942957906 +0000 UTC m=+23.966441710
I1018 09:56:46.943014       1 scheduler.go:454] Total Schedule Algo cumulative time:2.970722384s for 1259
I1018 09:56:46.945635       1 scheduler.go:451] ScheduleAlgoTime 2.348874ms Start:2018-10-18 09:56:46.943274938 +0000 UTC m=+23.966758842 End:2018-10-18 09:56:46.945623885 +0000 UTC m=+23.969107716
I1018 09:56:46.945735       1 scheduler.go:454] Total Schedule Algo cumulative time:2.973071258s for 1260
I1018 09:56:46.948184       1 scheduler.go:451] ScheduleAlgoTime 2.143492ms Start:2018-10-18 09:56:46.946030626 +0000 UTC m=+23.969514520 End:2018-10-18 09:56:46.948174201 +0000 UTC m=+23.971658012
I1018 09:56:46.948246       1 scheduler.go:454] Total Schedule Algo cumulative time:2.97521475s for 1261
I1018 09:56:46.950540       1 scheduler.go:451] ScheduleAlgoTime 2.052911ms Start:2018-10-18 09:56:46.948478906 +0000 UTC m=+23.971962795 End:2018-10-18 09:56:46.950531902 +0000 UTC m=+23.974015706
I1018 09:56:46.950573       1 scheduler.go:454] Total Schedule Algo cumulative time:2.977267661s for 1262
I1018 09:56:46.952657       1 scheduler.go:451] ScheduleAlgoTime 1.855259ms Start:2018-10-18 09:56:46.950793789 +0000 UTC m=+23.974277702 End:2018-10-18 09:56:46.952649158 +0000 UTC m=+23.976132961
I1018 09:56:46.952732       1 scheduler.go:454] Total Schedule Algo cumulative time:2.97912292s for 1263
I1018 09:56:46.955225       1 scheduler.go:451] ScheduleAlgoTime 2.269055ms Start:2018-10-18 09:56:46.952947089 +0000 UTC m=+23.976430977 End:2018-10-18 09:56:46.95521623 +0000 UTC m=+23.978700032
I1018 09:56:46.955271       1 scheduler.go:454] Total Schedule Algo cumulative time:2.981391975s for 1264
I1018 09:56:46.957477       1 scheduler.go:451] ScheduleAlgoTime 2.042776ms Start:2018-10-18 09:56:46.955421541 +0000 UTC m=+23.978905343 End:2018-10-18 09:56:46.957464311 +0000 UTC m=+23.980948119
I1018 09:56:46.957529       1 scheduler.go:454] Total Schedule Algo cumulative time:2.983434751s for 1265
I1018 09:56:46.960215       1 scheduler.go:451] ScheduleAlgoTime 2.479213ms Start:2018-10-18 09:56:46.957726237 +0000 UTC m=+23.981210147 End:2018-10-18 09:56:46.960205553 +0000 UTC m=+23.983689360
I1018 09:56:46.960250       1 scheduler.go:454] Total Schedule Algo cumulative time:2.985913964s for 1266
I1018 09:56:46.962359       1 scheduler.go:451] ScheduleAlgoTime 1.862885ms Start:2018-10-18 09:56:46.960485061 +0000 UTC m=+23.983968955 End:2018-10-18 09:56:46.962348001 +0000 UTC m=+23.985831840
I1018 09:56:46.962401       1 scheduler.go:454] Total Schedule Algo cumulative time:2.987776849s for 1267
I1018 09:56:46.964931       1 scheduler.go:451] ScheduleAlgoTime 2.372357ms Start:2018-10-18 09:56:46.962548694 +0000 UTC m=+23.986032519 End:2018-10-18 09:56:46.964921068 +0000 UTC m=+23.988404876
I1018 09:56:46.964961       1 scheduler.go:454] Total Schedule Algo cumulative time:2.990149206s for 1268
I1018 09:56:46.967231       1 scheduler.go:451] ScheduleAlgoTime 2.072851ms Start:2018-10-18 09:56:46.965150807 +0000 UTC m=+23.988634709 End:2018-10-18 09:56:46.967223756 +0000 UTC m=+23.990707560
I1018 09:56:46.967263       1 scheduler.go:454] Total Schedule Algo cumulative time:2.992222057s for 1269
I1018 09:56:46.969491       1 scheduler.go:451] ScheduleAlgoTime 2.091719ms Start:2018-10-18 09:56:46.967390767 +0000 UTC m=+23.990874605 End:2018-10-18 09:56:46.969482519 +0000 UTC m=+23.992966324
I1018 09:56:46.969520       1 scheduler.go:454] Total Schedule Algo cumulative time:2.994313776s for 1270
I1018 09:56:46.971943       1 scheduler.go:451] ScheduleAlgoTime 2.184992ms Start:2018-10-18 09:56:46.969748707 +0000 UTC m=+23.993232562 End:2018-10-18 09:56:46.97193375 +0000 UTC m=+23.995417554
I1018 09:56:46.971973       1 scheduler.go:454] Total Schedule Algo cumulative time:2.996498768s for 1271
I1018 09:56:46.974477       1 scheduler.go:451] ScheduleAlgoTime 2.269631ms Start:2018-10-18 09:56:46.972199633 +0000 UTC m=+23.995683529 End:2018-10-18 09:56:46.974469352 +0000 UTC m=+23.997953160
I1018 09:56:46.974534       1 scheduler.go:454] Total Schedule Algo cumulative time:2.998768399s for 1272
I1018 09:56:46.977378       1 scheduler.go:451] ScheduleAlgoTime 2.498529ms Start:2018-10-18 09:56:46.974866446 +0000 UTC m=+23.998350375 End:2018-10-18 09:56:46.977364998 +0000 UTC m=+24.000848904
I1018 09:56:46.977422       1 scheduler.go:454] Total Schedule Algo cumulative time:3.001266928s for 1273
I1018 09:56:46.980102       1 scheduler.go:451] ScheduleAlgoTime 2.464528ms Start:2018-10-18 09:56:46.977626957 +0000 UTC m=+24.001110846 End:2018-10-18 09:56:46.980091562 +0000 UTC m=+24.003575374
I1018 09:56:46.980141       1 scheduler.go:454] Total Schedule Algo cumulative time:3.003731456s for 1274
I1018 09:56:46.982702       1 scheduler.go:451] ScheduleAlgoTime 2.24208ms Start:2018-10-18 09:56:46.980417466 +0000 UTC m=+24.003901371 End:2018-10-18 09:56:46.982659648 +0000 UTC m=+24.006143451
I1018 09:56:46.982733       1 scheduler.go:454] Total Schedule Algo cumulative time:3.005973536s for 1275
I1018 09:56:46.985136       1 scheduler.go:451] ScheduleAlgoTime 1.995834ms Start:2018-10-18 09:56:46.983125573 +0000 UTC m=+24.006609505 End:2018-10-18 09:56:46.985121537 +0000 UTC m=+24.008605339
I1018 09:56:46.985166       1 scheduler.go:454] Total Schedule Algo cumulative time:3.00796937s for 1276
I1018 09:56:46.987598       1 scheduler.go:451] ScheduleAlgoTime 2.285688ms Start:2018-10-18 09:56:46.985300954 +0000 UTC m=+24.008784758 End:2018-10-18 09:56:46.98758653 +0000 UTC m=+24.011070446
I1018 09:56:46.987646       1 scheduler.go:454] Total Schedule Algo cumulative time:3.010255058s for 1277
I1018 09:56:46.990084       1 scheduler.go:451] ScheduleAlgoTime 2.194722ms Start:2018-10-18 09:56:46.987877716 +0000 UTC m=+24.011361629 End:2018-10-18 09:56:46.990072456 +0000 UTC m=+24.013556351
I1018 09:56:46.990123       1 scheduler.go:454] Total Schedule Algo cumulative time:3.01244978s for 1278
I1018 09:56:46.992836       1 scheduler.go:451] ScheduleAlgoTime 2.384844ms Start:2018-10-18 09:56:46.990440679 +0000 UTC m=+24.013924566 End:2018-10-18 09:56:46.992825232 +0000 UTC m=+24.016309410
I1018 09:56:46.992873       1 scheduler.go:454] Total Schedule Algo cumulative time:3.014834624s for 1279
I1018 09:56:46.995949       1 scheduler.go:451] ScheduleAlgoTime 2.86038ms Start:2018-10-18 09:56:46.99307969 +0000 UTC m=+24.016563555 End:2018-10-18 09:56:46.995940132 +0000 UTC m=+24.019423935
I1018 09:56:46.995988       1 scheduler.go:454] Total Schedule Algo cumulative time:3.017695004s for 1280
I1018 09:56:46.998339       1 scheduler.go:451] ScheduleAlgoTime 2.068035ms Start:2018-10-18 09:56:46.996262884 +0000 UTC m=+24.019746741 End:2018-10-18 09:56:46.998330971 +0000 UTC m=+24.021814776
I1018 09:56:46.998369       1 scheduler.go:454] Total Schedule Algo cumulative time:3.019763039s for 1281
I1018 09:56:47.000624       1 scheduler.go:451] ScheduleAlgoTime 2.06432ms Start:2018-10-18 09:56:46.998549791 +0000 UTC m=+24.022033685 End:2018-10-18 09:56:47.000614086 +0000 UTC m=+24.024098005
I1018 09:56:47.000662       1 scheduler.go:454] Total Schedule Algo cumulative time:3.021827359s for 1282
I1018 09:56:47.003923       1 scheduler.go:451] ScheduleAlgoTime 2.902063ms Start:2018-10-18 09:56:47.001011101 +0000 UTC m=+24.024495008 End:2018-10-18 09:56:47.003913211 +0000 UTC m=+24.027397071
I1018 09:56:47.003956       1 scheduler.go:454] Total Schedule Algo cumulative time:3.024729422s for 1283
I1018 09:56:47.006248       1 scheduler.go:451] ScheduleAlgoTime 2.01594ms Start:2018-10-18 09:56:47.004222518 +0000 UTC m=+24.027706409 End:2018-10-18 09:56:47.00623854 +0000 UTC m=+24.029722349
I1018 09:56:47.006284       1 scheduler.go:454] Total Schedule Algo cumulative time:3.026745362s for 1284
I1018 09:56:47.008799       1 scheduler.go:451] ScheduleAlgoTime 2.321126ms Start:2018-10-18 09:56:47.00646815 +0000 UTC m=+24.029952077 End:2018-10-18 09:56:47.008789399 +0000 UTC m=+24.032273203
I1018 09:56:47.008840       1 scheduler.go:454] Total Schedule Algo cumulative time:3.029066488s for 1285
I1018 09:56:47.011099       1 scheduler.go:451] ScheduleAlgoTime 1.997389ms Start:2018-10-18 09:56:47.009092714 +0000 UTC m=+24.032576603 End:2018-10-18 09:56:47.011090191 +0000 UTC m=+24.034573992
I1018 09:56:47.011151       1 scheduler.go:454] Total Schedule Algo cumulative time:3.031063877s for 1286
I1018 09:56:47.013550       1 scheduler.go:451] ScheduleAlgoTime 2.175832ms Start:2018-10-18 09:56:47.011363478 +0000 UTC m=+24.034847372 End:2018-10-18 09:56:47.013539291 +0000 UTC m=+24.037023204
I1018 09:56:47.013588       1 scheduler.go:454] Total Schedule Algo cumulative time:3.033239709s for 1287
I1018 09:56:47.016236       1 scheduler.go:451] ScheduleAlgoTime 2.432423ms Start:2018-10-18 09:56:47.01379487 +0000 UTC m=+24.037278766 End:2018-10-18 09:56:47.016227387 +0000 UTC m=+24.039711189
I1018 09:56:47.016275       1 scheduler.go:454] Total Schedule Algo cumulative time:3.035672132s for 1288
I1018 09:56:47.018558       1 scheduler.go:451] ScheduleAlgoTime 2.08266ms Start:2018-10-18 09:56:47.016466907 +0000 UTC m=+24.039950796 End:2018-10-18 09:56:47.018549652 +0000 UTC m=+24.042033456
I1018 09:56:47.018588       1 scheduler.go:454] Total Schedule Algo cumulative time:3.037754792s for 1289
I1018 09:56:47.021397       1 scheduler.go:451] ScheduleAlgoTime 2.541173ms Start:2018-10-18 09:56:47.018846324 +0000 UTC m=+24.042330221 End:2018-10-18 09:56:47.021387569 +0000 UTC m=+24.044871394
I1018 09:56:47.021425       1 scheduler.go:454] Total Schedule Algo cumulative time:3.040295965s for 1290
I1018 09:56:47.024123       1 scheduler.go:451] ScheduleAlgoTime 2.559215ms Start:2018-10-18 09:56:47.021555048 +0000 UTC m=+24.045038935 End:2018-10-18 09:56:47.024114346 +0000 UTC m=+24.047598150
I1018 09:56:47.024153       1 scheduler.go:454] Total Schedule Algo cumulative time:3.04285518s for 1291
I1018 09:56:47.026490       1 scheduler.go:451] ScheduleAlgoTime 2.165569ms Start:2018-10-18 09:56:47.024316788 +0000 UTC m=+24.047800715 End:2018-10-18 09:56:47.026482477 +0000 UTC m=+24.049966284
I1018 09:56:47.026523       1 scheduler.go:454] Total Schedule Algo cumulative time:3.045020749s for 1292
I1018 09:56:47.028617       1 scheduler.go:451] ScheduleAlgoTime 1.890234ms Start:2018-10-18 09:56:47.026718417 +0000 UTC m=+24.050202297 End:2018-10-18 09:56:47.028608726 +0000 UTC m=+24.052092531
I1018 09:56:47.028646       1 scheduler.go:454] Total Schedule Algo cumulative time:3.046910983s for 1293
I1018 09:56:47.030845       1 scheduler.go:451] ScheduleAlgoTime 1.93428ms Start:2018-10-18 09:56:47.028901899 +0000 UTC m=+24.052385755 End:2018-10-18 09:56:47.030836227 +0000 UTC m=+24.054320035
I1018 09:56:47.030878       1 scheduler.go:454] Total Schedule Algo cumulative time:3.048845263s for 1294
I1018 09:56:47.033399       1 scheduler.go:451] ScheduleAlgoTime 2.380264ms Start:2018-10-18 09:56:47.031010924 +0000 UTC m=+24.054494835 End:2018-10-18 09:56:47.033391276 +0000 UTC m=+24.056875099
I1018 09:56:47.033428       1 scheduler.go:454] Total Schedule Algo cumulative time:3.051225527s for 1295
I1018 09:56:47.035775       1 scheduler.go:451] ScheduleAlgoTime 2.027223ms Start:2018-10-18 09:56:47.033740297 +0000 UTC m=+24.057224198 End:2018-10-18 09:56:47.035767616 +0000 UTC m=+24.059251421
I1018 09:56:47.035805       1 scheduler.go:454] Total Schedule Algo cumulative time:3.05325275s for 1296
I1018 09:56:47.038172       1 scheduler.go:451] ScheduleAlgoTime 2.036331ms Start:2018-10-18 09:56:47.036128748 +0000 UTC m=+24.059612629 End:2018-10-18 09:56:47.038165156 +0000 UTC m=+24.061648960
I1018 09:56:47.038199       1 scheduler.go:454] Total Schedule Algo cumulative time:3.055289081s for 1297
I1018 09:56:47.040635       1 scheduler.go:451] ScheduleAlgoTime 2.172158ms Start:2018-10-18 09:56:47.038454254 +0000 UTC m=+24.061938147 End:2018-10-18 09:56:47.040626499 +0000 UTC m=+24.064110305
I1018 09:56:47.040710       1 scheduler.go:454] Total Schedule Algo cumulative time:3.057461239s for 1298
I1018 09:56:47.043512       1 scheduler.go:451] ScheduleAlgoTime 2.298858ms Start:2018-10-18 09:56:47.041204113 +0000 UTC m=+24.064688005 End:2018-10-18 09:56:47.043503059 +0000 UTC m=+24.066986863
I1018 09:56:47.043588       1 scheduler.go:454] Total Schedule Algo cumulative time:3.059760097s for 1299
I1018 09:56:47.046768       1 scheduler.go:451] ScheduleAlgoTime 2.161643ms Start:2018-10-18 09:56:47.044592241 +0000 UTC m=+24.068076044 End:2018-10-18 09:56:47.046753885 +0000 UTC m=+24.070237687
I1018 09:56:47.046803       1 scheduler.go:454] Total Schedule Algo cumulative time:3.06192174s for 1300
I1018 09:56:47.049290       1 scheduler.go:451] ScheduleAlgoTime 2.214122ms Start:2018-10-18 09:56:47.047069386 +0000 UTC m=+24.070553301 End:2018-10-18 09:56:47.049283615 +0000 UTC m=+24.072767423
I1018 09:56:47.049328       1 scheduler.go:454] Total Schedule Algo cumulative time:3.064135862s for 1301
I1018 09:56:47.051966       1 scheduler.go:451] ScheduleAlgoTime 2.145169ms Start:2018-10-18 09:56:47.049810227 +0000 UTC m=+24.073294114 End:2018-10-18 09:56:47.051955445 +0000 UTC m=+24.075439283
I1018 09:56:47.052004       1 scheduler.go:454] Total Schedule Algo cumulative time:3.066281031s for 1302
I1018 09:56:47.054836       1 scheduler.go:451] ScheduleAlgoTime 2.679506ms Start:2018-10-18 09:56:47.052148207 +0000 UTC m=+24.075632074 End:2018-10-18 09:56:47.054827776 +0000 UTC m=+24.078311580
I1018 09:56:47.054873       1 scheduler.go:454] Total Schedule Algo cumulative time:3.068960537s for 1303
I1018 09:56:47.056989       1 scheduler.go:451] ScheduleAlgoTime 1.923963ms Start:2018-10-18 09:56:47.055058436 +0000 UTC m=+24.078542346 End:2018-10-18 09:56:47.056982506 +0000 UTC m=+24.080466309
I1018 09:56:47.057016       1 scheduler.go:454] Total Schedule Algo cumulative time:3.0708845s for 1304
I1018 09:56:47.059794       1 scheduler.go:451] ScheduleAlgoTime 2.482633ms Start:2018-10-18 09:56:47.057303742 +0000 UTC m=+24.080787593 End:2018-10-18 09:56:47.059786424 +0000 UTC m=+24.083270226
I1018 09:56:47.059827       1 scheduler.go:454] Total Schedule Algo cumulative time:3.073367133s for 1305
I1018 09:56:47.061955       1 scheduler.go:451] ScheduleAlgoTime 1.891667ms Start:2018-10-18 09:56:47.060054288 +0000 UTC m=+24.083538176 End:2018-10-18 09:56:47.061946041 +0000 UTC m=+24.085429843
I1018 09:56:47.062001       1 scheduler.go:454] Total Schedule Algo cumulative time:3.0752588s for 1306
I1018 09:56:47.064315       1 scheduler.go:451] ScheduleAlgoTime 2.041352ms Start:2018-10-18 09:56:47.062265158 +0000 UTC m=+24.085749015 End:2018-10-18 09:56:47.064306556 +0000 UTC m=+24.087790367
I1018 09:56:47.064344       1 scheduler.go:454] Total Schedule Algo cumulative time:3.077300152s for 1307
