I0831 12:50:37.380307       1 flags.go:27] FLAG: --address=""
I0831 12:50:37.380435       1 flags.go:27] FLAG: --algorithm-provider=""
I0831 12:50:37.380444       1 flags.go:27] FLAG: --alsologtostderr="false"
I0831 12:50:37.380450       1 flags.go:27] FLAG: --config=""
I0831 12:50:37.380454       1 flags.go:27] FLAG: --contention-profiling="false"
I0831 12:50:37.380459       1 flags.go:27] FLAG: --failure-domains="kubernetes.io/hostname,failure-domain.beta.kubernetes.io/zone,failure-domain.beta.kubernetes.io/region"
I0831 12:50:37.380467       1 flags.go:27] FLAG: --feature-gates=""
I0831 12:50:37.380474       1 flags.go:27] FLAG: --hard-pod-affinity-symmetric-weight="1"
I0831 12:50:37.380480       1 flags.go:27] FLAG: --help="false"
I0831 12:50:37.380484       1 flags.go:27] FLAG: --kube-api-burst="100"
I0831 12:50:37.380488       1 flags.go:27] FLAG: --kube-api-content-type="application/vnd.kubernetes.protobuf"
I0831 12:50:37.380492       1 flags.go:27] FLAG: --kube-api-qps="50"
I0831 12:50:37.380498       1 flags.go:27] FLAG: --kubeconfig="/etc/srv/kubernetes/kube-scheduler/kubeconfig"
I0831 12:50:37.380502       1 flags.go:27] FLAG: --leader-elect="true"
I0831 12:50:37.380506       1 flags.go:27] FLAG: --leader-elect-lease-duration="15s"
I0831 12:50:37.380511       1 flags.go:27] FLAG: --leader-elect-renew-deadline="10s"
I0831 12:50:37.380515       1 flags.go:27] FLAG: --leader-elect-resource-lock="endpoints"
I0831 12:50:37.380519       1 flags.go:27] FLAG: --leader-elect-retry-period="2s"
I0831 12:50:37.380523       1 flags.go:27] FLAG: --lock-object-name="kube-scheduler"
I0831 12:50:37.380526       1 flags.go:27] FLAG: --lock-object-namespace="kube-system"
I0831 12:50:37.380530       1 flags.go:27] FLAG: --log-backtrace-at=":0"
I0831 12:50:37.380536       1 flags.go:27] FLAG: --log-dir=""
I0831 12:50:37.380540       1 flags.go:27] FLAG: --log-flush-frequency="5s"
I0831 12:50:37.380544       1 flags.go:27] FLAG: --logtostderr="true"
I0831 12:50:37.380547       1 flags.go:27] FLAG: --master=""
I0831 12:50:37.380551       1 flags.go:27] FLAG: --policy-config-file=""
I0831 12:50:37.380554       1 flags.go:27] FLAG: --policy-configmap=""
I0831 12:50:37.380558       1 flags.go:27] FLAG: --policy-configmap-namespace=""
I0831 12:50:37.380562       1 flags.go:27] FLAG: --port="10251"
I0831 12:50:37.380566       1 flags.go:27] FLAG: --profiling="false"
I0831 12:50:37.380569       1 flags.go:27] FLAG: --scheduler-name="default-scheduler"
I0831 12:50:37.380573       1 flags.go:27] FLAG: --stderrthreshold="2"
I0831 12:50:37.380577       1 flags.go:27] FLAG: --use-legacy-policy-config="false"
I0831 12:50:37.380580       1 flags.go:27] FLAG: --v="2"
I0831 12:50:37.380584       1 flags.go:27] FLAG: --version="false"
I0831 12:50:37.380590       1 flags.go:27] FLAG: --vmodule=""
W0831 12:50:37.380601       1 server.go:163] WARNING: all flags other than --config are deprecated. Please begin using a config file ASAP.
I0831 12:50:37.383066       1 server.go:555] Version: v1.10.4
I0831 12:50:37.383276       1 factory.go:922] Creating scheduler from algorithm provider 'DefaultProvider'
I0831 12:50:37.383284       1 factory.go:1022] Creating scheduler with fit predicates 'map[MatchInterPodAffinity:{} CheckNodeMemoryPressure:{} NoVolumeZoneConflict:{} MaxEBSVolumeCount:{} MaxAzureDiskVolumeCount:{} CheckNodeDiskPressure:{} CheckNodeCondition:{} PodToleratesNodeTaints:{} CheckVolumeBinding:{} MaxGCEPDVolumeCount:{} NoDiskConflict:{} GeneralPredicates:{}]' and priority functions 'map[BalancedResourceAllocation:{} NodePreferAvoidPodsPriority:{} NodeAffinityPriority:{} TaintTolerationPriority:{} SelectorSpreadPriority:{} InterPodAffinityPriority:{} LeastRequestedPriority:{}]'
I0831 12:50:37.383597       1 server.go:574] starting healthz server on 0.0.0.0:10251
I0831 12:50:38.285137       1 controller_utils.go:1019] Waiting for caches to sync for scheduler controller
I0831 12:50:38.385325       1 controller_utils.go:1026] Caches are synced for scheduler controller
I0831 12:50:38.385372       1 leaderelection.go:175] attempting to acquire leader lease  kube-system/kube-scheduler...
I0831 12:50:38.389957       1 leaderelection.go:184] successfully acquired lease kube-system/kube-scheduler
I0831 12:53:16.804119       1 scheduler.go:451] ScheduleAlgoTime 1.464241ms Start:2018-08-31 12:53:16.802631467 +0000 UTC m=+159.473253656 End:2018-08-31 12:53:16.804095748 +0000 UTC m=+159.474717897
I0831 12:53:16.804255       1 scheduler.go:454] Total Schedule Algo cumulative time:1.464241ms for 1
I0831 12:53:16.981225       1 scheduler.go:451] ScheduleAlgoTime 2.15499ms Start:2018-08-31 12:53:16.979054629 +0000 UTC m=+159.649676812 End:2018-08-31 12:53:16.981209672 +0000 UTC m=+159.651831802
I0831 12:53:16.981292       1 scheduler.go:454] Total Schedule Algo cumulative time:3.619231ms for 2
I0831 12:53:16.988780       1 scheduler.go:451] ScheduleAlgoTime 5.947936ms Start:2018-08-31 12:53:16.982817443 +0000 UTC m=+159.653439652 End:2018-08-31 12:53:16.98876547 +0000 UTC m=+159.659387588
I0831 12:53:17.055856       1 scheduler.go:454] Total Schedule Algo cumulative time:9.567167ms for 3
I0831 12:53:17.060311       1 scheduler.go:451] ScheduleAlgoTime 1.216669ms Start:2018-08-31 12:53:17.059076607 +0000 UTC m=+159.729698823 End:2018-08-31 12:53:17.060293359 +0000 UTC m=+159.730915492
I0831 12:53:17.060375       1 scheduler.go:454] Total Schedule Algo cumulative time:10.783836ms for 4
I0831 12:53:17.066637       1 scheduler.go:451] ScheduleAlgoTime 1.26601ms Start:2018-08-31 12:53:17.065355222 +0000 UTC m=+159.735977367 End:2018-08-31 12:53:17.066621259 +0000 UTC m=+159.737243377
I0831 12:53:17.066706       1 scheduler.go:454] Total Schedule Algo cumulative time:12.049846ms for 5
I0831 12:53:17.069015       1 scheduler.go:451] ScheduleAlgoTime 1.947056ms Start:2018-08-31 12:53:17.067054044 +0000 UTC m=+159.737676176 End:2018-08-31 12:53:17.069001113 +0000 UTC m=+159.739623232
I0831 12:53:17.069062       1 scheduler.go:454] Total Schedule Algo cumulative time:13.996902ms for 6
I0831 12:53:17.070725       1 scheduler.go:451] ScheduleAlgoTime 860.368µs Start:2018-08-31 12:53:17.06985341 +0000 UTC m=+159.740475568 End:2018-08-31 12:53:17.07071381 +0000 UTC m=+159.741335936
I0831 12:53:17.070786       1 scheduler.go:454] Total Schedule Algo cumulative time:14.85727ms for 7
I0831 12:53:17.075393       1 scheduler.go:451] ScheduleAlgoTime 940.653µs Start:2018-08-31 12:53:17.074441117 +0000 UTC m=+159.745063285 End:2018-08-31 12:53:17.075381807 +0000 UTC m=+159.746003938
I0831 12:53:17.201048       1 scheduler.go:454] Total Schedule Algo cumulative time:15.797923ms for 8
I0831 12:53:17.223731       1 scheduler.go:451] ScheduleAlgoTime 2.157699ms Start:2018-08-31 12:53:17.221556186 +0000 UTC m=+159.892178367 End:2018-08-31 12:53:17.223713935 +0000 UTC m=+159.894336066
I0831 12:53:17.248704       1 scheduler.go:454] Total Schedule Algo cumulative time:17.955622ms for 9
I0831 12:53:17.250103       1 scheduler.go:451] ScheduleAlgoTime 1.192621ms Start:2018-08-31 12:53:17.24890246 +0000 UTC m=+159.919524613 End:2018-08-31 12:53:17.250095115 +0000 UTC m=+159.920717234
I0831 12:53:17.250152       1 scheduler.go:454] Total Schedule Algo cumulative time:19.148243ms for 10
I0831 12:53:17.251306       1 scheduler.go:451] ScheduleAlgoTime 1.05157ms Start:2018-08-31 12:53:17.250248045 +0000 UTC m=+159.920870191 End:2018-08-31 12:53:17.251299642 +0000 UTC m=+159.921921761
I0831 12:53:17.251347       1 scheduler.go:454] Total Schedule Algo cumulative time:20.199813ms for 11
I0831 12:53:17.262420       1 scheduler.go:451] ScheduleAlgoTime 1.046632ms Start:2018-08-31 12:53:17.261364886 +0000 UTC m=+159.931987096 End:2018-08-31 12:53:17.262411609 +0000 UTC m=+159.933033728
I0831 12:53:17.262476       1 scheduler.go:454] Total Schedule Algo cumulative time:21.246445ms for 12
I0831 12:53:17.263266       1 scheduler.go:451] ScheduleAlgoTime 702.852µs Start:2018-08-31 12:53:17.262553934 +0000 UTC m=+159.933176078 End:2018-08-31 12:53:17.263256808 +0000 UTC m=+159.933878930
I0831 12:53:17.263327       1 scheduler.go:454] Total Schedule Algo cumulative time:21.949297ms for 13
I0831 12:53:17.264419       1 scheduler.go:451] ScheduleAlgoTime 786.67µs Start:2018-08-31 12:53:17.263625317 +0000 UTC m=+159.934247467 End:2018-08-31 12:53:17.264412012 +0000 UTC m=+159.935034137
I0831 12:53:17.264503       1 scheduler.go:454] Total Schedule Algo cumulative time:22.735967ms for 14
I0831 12:53:17.295598       1 scheduler.go:451] ScheduleAlgoTime 1.170888ms Start:2018-08-31 12:53:17.294403977 +0000 UTC m=+159.965026146 End:2018-08-31 12:53:17.295574915 +0000 UTC m=+159.966197034
I0831 12:53:17.295647       1 scheduler.go:454] Total Schedule Algo cumulative time:23.906855ms for 15
I0831 12:53:17.551800       1 scheduler.go:451] ScheduleAlgoTime 1.453555ms Start:2018-08-31 12:53:17.55033808 +0000 UTC m=+160.220960251 End:2018-08-31 12:53:17.551791684 +0000 UTC m=+160.222413806
I0831 12:53:17.551852       1 scheduler.go:454] Total Schedule Algo cumulative time:25.36041ms for 16
I0831 12:53:17.781513       1 scheduler.go:451] ScheduleAlgoTime 1.064842ms Start:2018-08-31 12:53:17.780439997 +0000 UTC m=+160.451062165 End:2018-08-31 12:53:17.781504884 +0000 UTC m=+160.452127007
I0831 12:53:18.046479       1 scheduler.go:454] Total Schedule Algo cumulative time:26.425252ms for 17
I0831 12:53:18.047869       1 scheduler.go:451] ScheduleAlgoTime 1.086646ms Start:2018-08-31 12:53:18.046774634 +0000 UTC m=+160.717396809 End:2018-08-31 12:53:18.047861329 +0000 UTC m=+160.718483455
I0831 12:53:18.047936       1 scheduler.go:454] Total Schedule Algo cumulative time:27.511898ms for 18
I0831 12:53:18.048813       1 scheduler.go:451] ScheduleAlgoTime 760.304µs Start:2018-08-31 12:53:18.048042335 +0000 UTC m=+160.718664481 End:2018-08-31 12:53:18.048802664 +0000 UTC m=+160.719424785
I0831 12:53:18.048855       1 scheduler.go:454] Total Schedule Algo cumulative time:28.272202ms for 19
I0831 12:53:18.094089       1 scheduler.go:451] ScheduleAlgoTime 1.623906ms Start:2018-08-31 12:53:18.092450213 +0000 UTC m=+160.763072392 End:2018-08-31 12:53:18.09407418 +0000 UTC m=+160.764696298
I0831 12:53:18.094147       1 scheduler.go:454] Total Schedule Algo cumulative time:29.896108ms for 20
I0831 12:53:19.070467       1 scheduler.go:451] ScheduleAlgoTime 1.26633ms Start:2018-08-31 12:53:19.06919376 +0000 UTC m=+161.739815923 End:2018-08-31 12:53:19.070460131 +0000 UTC m=+161.741082253
I0831 12:53:19.070513       1 scheduler.go:454] Total Schedule Algo cumulative time:31.162438ms for 21
I0831 12:53:19.080682       1 scheduler.go:451] ScheduleAlgoTime 8.421342ms Start:2018-08-31 12:53:19.072248073 +0000 UTC m=+161.742870241 End:2018-08-31 12:53:19.080669464 +0000 UTC m=+161.751291583
I0831 12:53:19.080746       1 scheduler.go:454] Total Schedule Algo cumulative time:39.58378ms for 22
I0831 12:53:19.083150       1 scheduler.go:451] ScheduleAlgoTime 2.177268ms Start:2018-08-31 12:53:19.080967642 +0000 UTC m=+161.751589790 End:2018-08-31 12:53:19.08314494 +0000 UTC m=+161.753767058
I0831 12:53:19.083200       1 scheduler.go:454] Total Schedule Algo cumulative time:41.761048ms for 23
I0831 12:53:19.084335       1 scheduler.go:451] ScheduleAlgoTime 1.049421ms Start:2018-08-31 12:53:19.08327857 +0000 UTC m=+161.753900702 End:2018-08-31 12:53:19.084327965 +0000 UTC m=+161.754950123
I0831 12:53:19.084379       1 scheduler.go:454] Total Schedule Algo cumulative time:42.810469ms for 24
I0831 12:53:19.085398       1 scheduler.go:451] ScheduleAlgoTime 901.974µs Start:2018-08-31 12:53:19.084489362 +0000 UTC m=+161.755111508 End:2018-08-31 12:53:19.085391355 +0000 UTC m=+161.756013482
I0831 12:53:19.085466       1 scheduler.go:454] Total Schedule Algo cumulative time:43.712443ms for 25
I0831 12:53:19.086648       1 scheduler.go:451] ScheduleAlgoTime 1.050055ms Start:2018-08-31 12:53:19.085590879 +0000 UTC m=+161.756213041 End:2018-08-31 12:53:19.086640975 +0000 UTC m=+161.757263096
I0831 12:53:19.086686       1 scheduler.go:454] Total Schedule Algo cumulative time:44.762498ms for 26
I0831 12:53:19.381210       1 scheduler.go:451] ScheduleAlgoTime 1.39903ms Start:2018-08-31 12:53:19.379804018 +0000 UTC m=+162.050426173 End:2018-08-31 12:53:19.381203084 +0000 UTC m=+162.051825203
I0831 12:53:19.381272       1 scheduler.go:454] Total Schedule Algo cumulative time:46.161528ms for 27
I0831 12:53:19.736989       1 scheduler.go:451] ScheduleAlgoTime 1.354355ms Start:2018-08-31 12:53:19.735623974 +0000 UTC m=+162.406246269 End:2018-08-31 12:53:19.736978506 +0000 UTC m=+162.407600624
I0831 12:53:19.996815       1 scheduler.go:454] Total Schedule Algo cumulative time:47.515883ms for 28
I0831 12:53:19.997986       1 scheduler.go:451] ScheduleAlgoTime 976.685µs Start:2018-08-31 12:53:19.99700259 +0000 UTC m=+162.667624736 End:2018-08-31 12:53:19.997979298 +0000 UTC m=+162.668601421
I0831 12:53:19.998037       1 scheduler.go:454] Total Schedule Algo cumulative time:48.492568ms for 29
I0831 12:53:19.999129       1 scheduler.go:451] ScheduleAlgoTime 986.582µs Start:2018-08-31 12:53:19.99813341 +0000 UTC m=+162.668755595 End:2018-08-31 12:53:19.999120058 +0000 UTC m=+162.669742177
I0831 12:53:19.999182       1 scheduler.go:454] Total Schedule Algo cumulative time:49.47915ms for 30
I0831 12:53:20.000197       1 scheduler.go:451] ScheduleAlgoTime 936.14µs Start:2018-08-31 12:53:19.999255001 +0000 UTC m=+162.669877189 End:2018-08-31 12:53:20.000191209 +0000 UTC m=+162.670813329
I0831 12:53:20.000249       1 scheduler.go:454] Total Schedule Algo cumulative time:50.41529ms for 31
I0831 12:53:20.001111       1 scheduler.go:451] ScheduleAlgoTime 777.626µs Start:2018-08-31 12:53:20.00032751 +0000 UTC m=+162.670949685 End:2018-08-31 12:53:20.001105192 +0000 UTC m=+162.671727311
I0831 12:53:20.001169       1 scheduler.go:454] Total Schedule Algo cumulative time:51.192916ms for 32
I0831 12:53:20.001931       1 scheduler.go:451] ScheduleAlgoTime 679.271µs Start:2018-08-31 12:53:20.001246688 +0000 UTC m=+162.671868860 End:2018-08-31 12:53:20.001926009 +0000 UTC m=+162.672548131
I0831 12:53:20.001972       1 scheduler.go:454] Total Schedule Algo cumulative time:51.872187ms for 33
I0831 12:53:20.002843       1 scheduler.go:451] ScheduleAlgoTime 617.51µs Start:2018-08-31 12:53:20.002204721 +0000 UTC m=+162.672826903 End:2018-08-31 12:53:20.00282229 +0000 UTC m=+162.673444413
I0831 12:53:20.002894       1 scheduler.go:454] Total Schedule Algo cumulative time:52.489697ms for 34
I0831 12:53:20.004155       1 scheduler.go:451] ScheduleAlgoTime 1.120314ms Start:2018-08-31 12:53:20.003027721 +0000 UTC m=+162.673649886 End:2018-08-31 12:53:20.00414807 +0000 UTC m=+162.674770200
I0831 12:53:20.004194       1 scheduler.go:454] Total Schedule Algo cumulative time:53.610011ms for 35
I0831 12:53:20.005867       1 scheduler.go:451] ScheduleAlgoTime 1.094501ms Start:2018-08-31 12:53:20.004768209 +0000 UTC m=+162.675390356 End:2018-08-31 12:53:20.005862739 +0000 UTC m=+162.676484857
I0831 12:53:20.005903       1 scheduler.go:454] Total Schedule Algo cumulative time:54.704512ms for 36
I0831 12:53:20.007054       1 scheduler.go:451] ScheduleAlgoTime 941.038µs Start:2018-08-31 12:53:20.006108484 +0000 UTC m=+162.676730638 End:2018-08-31 12:53:20.007049553 +0000 UTC m=+162.677671676
I0831 12:53:20.007083       1 scheduler.go:454] Total Schedule Algo cumulative time:55.64555ms for 37
I0831 12:53:20.008148       1 scheduler.go:451] ScheduleAlgoTime 985.806µs Start:2018-08-31 12:53:20.007157258 +0000 UTC m=+162.677779405 End:2018-08-31 12:53:20.008143089 +0000 UTC m=+162.678765211
I0831 12:53:20.008184       1 scheduler.go:454] Total Schedule Algo cumulative time:56.631356ms for 38
I0831 12:53:20.009343       1 scheduler.go:451] ScheduleAlgoTime 947.608µs Start:2018-08-31 12:53:20.008385549 +0000 UTC m=+162.679007700 End:2018-08-31 12:53:20.009333178 +0000 UTC m=+162.679955308
I0831 12:53:20.009391       1 scheduler.go:454] Total Schedule Algo cumulative time:57.578964ms for 39
I0831 12:53:20.010551       1 scheduler.go:451] ScheduleAlgoTime 917.098µs Start:2018-08-31 12:53:20.009629256 +0000 UTC m=+162.680251415 End:2018-08-31 12:53:20.010546393 +0000 UTC m=+162.681168513
I0831 12:53:20.010612       1 scheduler.go:454] Total Schedule Algo cumulative time:58.496062ms for 40
I0831 12:53:20.060947       1 scheduler.go:451] ScheduleAlgoTime 1.089005ms Start:2018-08-31 12:53:20.059847186 +0000 UTC m=+162.730469371 End:2018-08-31 12:53:20.060936257 +0000 UTC m=+162.731558376
I0831 12:53:20.061144       1 scheduler.go:454] Total Schedule Algo cumulative time:59.585067ms for 41
I0831 12:53:20.062703       1 scheduler.go:451] ScheduleAlgoTime 1.410315ms Start:2018-08-31 12:53:20.061282447 +0000 UTC m=+162.731904599 End:2018-08-31 12:53:20.062692781 +0000 UTC m=+162.733314914
I0831 12:53:20.062754       1 scheduler.go:454] Total Schedule Algo cumulative time:60.995382ms for 42
I0831 12:53:20.066497       1 scheduler.go:451] ScheduleAlgoTime 773.197µs Start:2018-08-31 12:53:20.065715148 +0000 UTC m=+162.736337307 End:2018-08-31 12:53:20.066488374 +0000 UTC m=+162.737110504
I0831 12:53:20.066540       1 scheduler.go:454] Total Schedule Algo cumulative time:61.768579ms for 43
I0831 12:53:20.078364       1 scheduler.go:451] ScheduleAlgoTime 1.903599ms Start:2018-08-31 12:53:20.07644764 +0000 UTC m=+162.747069810 End:2018-08-31 12:53:20.07835128 +0000 UTC m=+162.748973409
I0831 12:53:20.903208       1 scheduler.go:454] Total Schedule Algo cumulative time:63.672178ms for 44
I0831 12:53:21.203656       1 scheduler.go:451] ScheduleAlgoTime 10.905552ms Start:2018-08-31 12:53:21.192734944 +0000 UTC m=+163.863357187 End:2018-08-31 12:53:21.203640612 +0000 UTC m=+163.874262739
I0831 12:53:21.203730       1 scheduler.go:454] Total Schedule Algo cumulative time:74.57773ms for 45
I0831 12:53:21.205634       1 scheduler.go:451] ScheduleAlgoTime 1.710186ms Start:2018-08-31 12:53:21.203914064 +0000 UTC m=+163.874536236 End:2018-08-31 12:53:21.205624302 +0000 UTC m=+163.876246422
I0831 12:53:21.205688       1 scheduler.go:454] Total Schedule Algo cumulative time:76.287916ms for 46
I0831 12:53:21.208150       1 scheduler.go:451] ScheduleAlgoTime 941.905µs Start:2018-08-31 12:53:21.20719789 +0000 UTC m=+163.877820071 End:2018-08-31 12:53:21.208139855 +0000 UTC m=+163.878761976
I0831 12:53:21.208195       1 scheduler.go:454] Total Schedule Algo cumulative time:77.229821ms for 47
I0831 12:53:21.209113       1 scheduler.go:451] ScheduleAlgoTime 730.104µs Start:2018-08-31 12:53:21.208375691 +0000 UTC m=+163.878997832 End:2018-08-31 12:53:21.209105805 +0000 UTC m=+163.879727936
I0831 12:53:21.209156       1 scheduler.go:454] Total Schedule Algo cumulative time:77.959925ms for 48
I0831 12:53:21.210949       1 scheduler.go:451] ScheduleAlgoTime 945.788µs Start:2018-08-31 12:53:21.20999554 +0000 UTC m=+163.880617709 End:2018-08-31 12:53:21.210941358 +0000 UTC m=+163.881563497
I0831 12:53:21.210989       1 scheduler.go:454] Total Schedule Algo cumulative time:78.905713ms for 49
I0831 12:53:21.211887       1 scheduler.go:451] ScheduleAlgoTime 674.117µs Start:2018-08-31 12:53:21.211207711 +0000 UTC m=+163.881829848 End:2018-08-31 12:53:21.211881846 +0000 UTC m=+163.882503965
I0831 12:53:21.211927       1 scheduler.go:454] Total Schedule Algo cumulative time:79.57983ms for 50
I0831 12:53:21.213196       1 scheduler.go:451] ScheduleAlgoTime 1.048298ms Start:2018-08-31 12:53:21.212141578 +0000 UTC m=+163.882763737 End:2018-08-31 12:53:21.213189907 +0000 UTC m=+163.883812035
I0831 12:53:21.213232       1 scheduler.go:454] Total Schedule Algo cumulative time:80.628128ms for 51
I0831 12:53:21.214139       1 scheduler.go:451] ScheduleAlgoTime 817.638µs Start:2018-08-31 12:53:21.213315424 +0000 UTC m=+163.883937580 End:2018-08-31 12:53:21.214133089 +0000 UTC m=+163.884755218
I0831 12:53:21.214172       1 scheduler.go:454] Total Schedule Algo cumulative time:81.445766ms for 52
I0831 12:53:21.285841       1 scheduler.go:451] ScheduleAlgoTime 1.034028ms Start:2018-08-31 12:53:21.28479184 +0000 UTC m=+163.955414023 End:2018-08-31 12:53:21.28582593 +0000 UTC m=+163.956448051
I0831 12:53:21.285888       1 scheduler.go:454] Total Schedule Algo cumulative time:82.479794ms for 53
I0831 12:53:21.320269       1 scheduler.go:451] ScheduleAlgoTime 1.31985ms Start:2018-08-31 12:53:21.318937897 +0000 UTC m=+163.989560106 End:2018-08-31 12:53:21.320257826 +0000 UTC m=+163.990879956
I0831 12:53:21.320315       1 scheduler.go:454] Total Schedule Algo cumulative time:83.799644ms for 54
I0831 12:53:21.321653       1 scheduler.go:451] ScheduleAlgoTime 1.024267ms Start:2018-08-31 12:53:21.320620418 +0000 UTC m=+163.991242585 End:2018-08-31 12:53:21.321644723 +0000 UTC m=+163.992266852
I0831 12:53:21.321691       1 scheduler.go:454] Total Schedule Algo cumulative time:84.823911ms for 55
I0831 12:53:21.323323       1 scheduler.go:451] ScheduleAlgoTime 1.52741ms Start:2018-08-31 12:53:21.321787992 +0000 UTC m=+163.992410152 End:2018-08-31 12:53:21.32331543 +0000 UTC m=+163.993937562
I0831 12:53:21.323372       1 scheduler.go:454] Total Schedule Algo cumulative time:86.351321ms for 56
I0831 12:53:21.324841       1 scheduler.go:451] ScheduleAlgoTime 1.031975ms Start:2018-08-31 12:53:21.323802359 +0000 UTC m=+163.994424508 End:2018-08-31 12:53:21.32483434 +0000 UTC m=+163.995456483
I0831 12:53:21.324880       1 scheduler.go:454] Total Schedule Algo cumulative time:87.383296ms for 57
I0831 12:53:22.151029       1 scheduler.go:451] ScheduleAlgoTime 1.246784ms Start:2018-08-31 12:53:22.14974043 +0000 UTC m=+164.820362599 End:2018-08-31 12:53:22.150987254 +0000 UTC m=+164.821609383
I0831 12:53:22.151084       1 scheduler.go:454] Total Schedule Algo cumulative time:88.63008ms for 58
I0831 12:53:22.202352       1 scheduler.go:451] ScheduleAlgoTime 929.199µs Start:2018-08-31 12:53:22.201411885 +0000 UTC m=+164.872034125 End:2018-08-31 12:53:22.202341197 +0000 UTC m=+164.872963324
I0831 12:53:22.202395       1 scheduler.go:454] Total Schedule Algo cumulative time:89.559279ms for 59
I0831 12:53:22.204640       1 scheduler.go:451] ScheduleAlgoTime 1.549834ms Start:2018-08-31 12:53:22.203080231 +0000 UTC m=+164.873702421 End:2018-08-31 12:53:22.204630126 +0000 UTC m=+164.875252255
I0831 12:53:22.204685       1 scheduler.go:454] Total Schedule Algo cumulative time:91.109113ms for 60
I0831 12:53:22.209951       1 scheduler.go:451] ScheduleAlgoTime 1.100401ms Start:2018-08-31 12:53:22.208842264 +0000 UTC m=+164.879464450 End:2018-08-31 12:53:22.209942723 +0000 UTC m=+164.880564851
I0831 12:53:22.209994       1 scheduler.go:454] Total Schedule Algo cumulative time:92.209514ms for 61
I0831 12:53:22.220325       1 scheduler.go:451] ScheduleAlgoTime 1.177052ms Start:2018-08-31 12:53:22.21913763 +0000 UTC m=+164.889759886 End:2018-08-31 12:53:22.220314816 +0000 UTC m=+164.890936938
I0831 12:53:22.220373       1 scheduler.go:454] Total Schedule Algo cumulative time:93.386566ms for 62
I0831 12:53:22.224722       1 scheduler.go:451] ScheduleAlgoTime 976.297µs Start:2018-08-31 12:53:22.223737908 +0000 UTC m=+164.894360083 End:2018-08-31 12:53:22.224714258 +0000 UTC m=+164.895336380
I0831 12:53:22.224766       1 scheduler.go:454] Total Schedule Algo cumulative time:94.362863ms for 63
I0831 12:53:22.225800       1 scheduler.go:451] ScheduleAlgoTime 934.239µs Start:2018-08-31 12:53:22.224858522 +0000 UTC m=+164.895480675 End:2018-08-31 12:53:22.225792783 +0000 UTC m=+164.896414914
I0831 12:53:22.225839       1 scheduler.go:454] Total Schedule Algo cumulative time:95.297102ms for 64
I0831 12:53:22.226819       1 scheduler.go:451] ScheduleAlgoTime 848.916µs Start:2018-08-31 12:53:22.225963806 +0000 UTC m=+164.896585986 End:2018-08-31 12:53:22.226812781 +0000 UTC m=+164.897434902
I0831 12:53:22.226848       1 scheduler.go:454] Total Schedule Algo cumulative time:96.146018ms for 65
I0831 12:53:22.228040       1 scheduler.go:451] ScheduleAlgoTime 1.100948ms Start:2018-08-31 12:53:22.226933487 +0000 UTC m=+164.897555653 End:2018-08-31 12:53:22.228034475 +0000 UTC m=+164.898656601
I0831 12:53:22.228076       1 scheduler.go:454] Total Schedule Algo cumulative time:97.246966ms for 66
I0831 12:53:22.242543       1 scheduler.go:451] ScheduleAlgoTime 1.446418ms Start:2018-08-31 12:53:22.241088897 +0000 UTC m=+164.911711113 End:2018-08-31 12:53:22.242535412 +0000 UTC m=+164.913157531
I0831 12:53:22.242609       1 scheduler.go:454] Total Schedule Algo cumulative time:98.693384ms for 67
I0831 12:53:22.243995       1 scheduler.go:451] ScheduleAlgoTime 861.044µs Start:2018-08-31 12:53:22.243127505 +0000 UTC m=+164.913749704 End:2018-08-31 12:53:22.243988624 +0000 UTC m=+164.914610748
I0831 12:53:22.244049       1 scheduler.go:454] Total Schedule Algo cumulative time:99.554428ms for 68
I0831 12:53:22.246519       1 scheduler.go:451] ScheduleAlgoTime 935.285µs Start:2018-08-31 12:53:22.245576343 +0000 UTC m=+164.916198504 End:2018-08-31 12:53:22.246511663 +0000 UTC m=+164.917133789
I0831 12:53:22.246552       1 scheduler.go:454] Total Schedule Algo cumulative time:100.489713ms for 69
I0831 12:53:22.247652       1 scheduler.go:451] ScheduleAlgoTime 753.355µs Start:2018-08-31 12:53:22.246893019 +0000 UTC m=+164.917515153 End:2018-08-31 12:53:22.247646379 +0000 UTC m=+164.918268508
I0831 12:53:22.247687       1 scheduler.go:454] Total Schedule Algo cumulative time:101.243068ms for 70
I0831 12:53:22.248803       1 scheduler.go:451] ScheduleAlgoTime 1.031235ms Start:2018-08-31 12:53:22.247766105 +0000 UTC m=+164.918388259 End:2018-08-31 12:53:22.248797374 +0000 UTC m=+164.919419494
I0831 12:53:22.248832       1 scheduler.go:454] Total Schedule Algo cumulative time:102.274303ms for 71
I0831 12:53:22.251539       1 scheduler.go:451] ScheduleAlgoTime 2.59948ms Start:2018-08-31 12:53:22.248932669 +0000 UTC m=+164.919554876 End:2018-08-31 12:53:22.251532228 +0000 UTC m=+164.922154356
I0831 12:53:22.434972       1 scheduler.go:454] Total Schedule Algo cumulative time:104.873783ms for 72
I0831 12:53:22.435793       1 scheduler.go:451] ScheduleAlgoTime 668.742µs Start:2018-08-31 12:53:22.435119945 +0000 UTC m=+165.105742107 End:2018-08-31 12:53:22.435788727 +0000 UTC m=+165.106410849
I0831 12:53:22.435829       1 scheduler.go:454] Total Schedule Algo cumulative time:105.542525ms for 73
I0831 12:53:22.877470       1 scheduler.go:451] ScheduleAlgoTime 1.709603ms Start:2018-08-31 12:53:22.875743895 +0000 UTC m=+165.546366093 End:2018-08-31 12:53:22.877453565 +0000 UTC m=+165.548075696
I0831 12:53:22.877517       1 scheduler.go:454] Total Schedule Algo cumulative time:107.252128ms for 74
I0831 12:53:22.878859       1 scheduler.go:451] ScheduleAlgoTime 1.025061ms Start:2018-08-31 12:53:22.877825863 +0000 UTC m=+165.548448034 End:2018-08-31 12:53:22.878850956 +0000 UTC m=+165.549473095
I0831 12:53:22.878894       1 scheduler.go:454] Total Schedule Algo cumulative time:108.277189ms for 75
I0831 12:53:22.880096       1 scheduler.go:451] ScheduleAlgoTime 1.007096ms Start:2018-08-31 12:53:22.879083135 +0000 UTC m=+165.549705310 End:2018-08-31 12:53:22.880090276 +0000 UTC m=+165.550712406
I0831 12:53:22.880126       1 scheduler.go:454] Total Schedule Algo cumulative time:109.284285ms for 76
I0831 12:53:22.880971       1 scheduler.go:451] ScheduleAlgoTime 759.698µs Start:2018-08-31 12:53:22.880205874 +0000 UTC m=+165.550828036 End:2018-08-31 12:53:22.880965611 +0000 UTC m=+165.551587734
I0831 12:53:22.880995       1 scheduler.go:454] Total Schedule Algo cumulative time:110.043983ms for 77
I0831 12:53:22.881776       1 scheduler.go:451] ScheduleAlgoTime 712.917µs Start:2018-08-31 12:53:22.881057813 +0000 UTC m=+165.551679973 End:2018-08-31 12:53:22.881770761 +0000 UTC m=+165.552392890
I0831 12:53:22.881849       1 scheduler.go:454] Total Schedule Algo cumulative time:110.7569ms for 78
I0831 12:53:22.887579       1 scheduler.go:451] ScheduleAlgoTime 1.485367ms Start:2018-08-31 12:53:22.886086328 +0000 UTC m=+165.556708488 End:2018-08-31 12:53:22.887571724 +0000 UTC m=+165.558193855
I0831 12:53:22.887612       1 scheduler.go:454] Total Schedule Algo cumulative time:112.242267ms for 79
I0831 12:53:22.888608       1 scheduler.go:451] ScheduleAlgoTime 901.515µs Start:2018-08-31 12:53:22.887699346 +0000 UTC m=+165.558321521 End:2018-08-31 12:53:22.888600903 +0000 UTC m=+165.559223036
I0831 12:53:22.888632       1 scheduler.go:454] Total Schedule Algo cumulative time:113.143782ms for 80
I0831 12:53:22.889421       1 scheduler.go:451] ScheduleAlgoTime 706.763µs Start:2018-08-31 12:53:22.888708797 +0000 UTC m=+165.559330962 End:2018-08-31 12:53:22.889415604 +0000 UTC m=+165.560037725
I0831 12:53:22.889468       1 scheduler.go:454] Total Schedule Algo cumulative time:113.850545ms for 81
I0831 12:53:22.890394       1 scheduler.go:451] ScheduleAlgoTime 788.744µs Start:2018-08-31 12:53:22.889599585 +0000 UTC m=+165.560221749 End:2018-08-31 12:53:22.890388361 +0000 UTC m=+165.561010493
I0831 12:53:22.890448       1 scheduler.go:454] Total Schedule Algo cumulative time:114.639289ms for 82
I0831 12:53:22.923080       1 scheduler.go:451] ScheduleAlgoTime 906.207µs Start:2018-08-31 12:53:22.922162532 +0000 UTC m=+165.592784719 End:2018-08-31 12:53:22.923068781 +0000 UTC m=+165.593690926
I0831 12:53:22.988011       1 scheduler.go:454] Total Schedule Algo cumulative time:115.545496ms for 83
I0831 12:53:22.988988       1 scheduler.go:451] ScheduleAlgoTime 848.213µs Start:2018-08-31 12:53:22.988132889 +0000 UTC m=+165.658755041 End:2018-08-31 12:53:22.988981126 +0000 UTC m=+165.659603254
I0831 12:53:22.989025       1 scheduler.go:454] Total Schedule Algo cumulative time:116.393709ms for 84
I0831 12:53:22.989865       1 scheduler.go:451] ScheduleAlgoTime 756.37µs Start:2018-08-31 12:53:22.989102747 +0000 UTC m=+165.659724907 End:2018-08-31 12:53:22.989859144 +0000 UTC m=+165.660481277
I0831 12:53:22.989899       1 scheduler.go:454] Total Schedule Algo cumulative time:117.150079ms for 85
I0831 12:53:22.990676       1 scheduler.go:451] ScheduleAlgoTime 714.266µs Start:2018-08-31 12:53:22.989955869 +0000 UTC m=+165.660578019 End:2018-08-31 12:53:22.990670148 +0000 UTC m=+165.661292285
I0831 12:53:22.990722       1 scheduler.go:454] Total Schedule Algo cumulative time:117.864345ms for 86
I0831 12:53:22.991574       1 scheduler.go:451] ScheduleAlgoTime 782.657µs Start:2018-08-31 12:53:22.990785172 +0000 UTC m=+165.661407328 End:2018-08-31 12:53:22.991567857 +0000 UTC m=+165.662189985
I0831 12:53:22.991605       1 scheduler.go:454] Total Schedule Algo cumulative time:118.647002ms for 87
I0831 12:53:22.992304       1 scheduler.go:451] ScheduleAlgoTime 635.694µs Start:2018-08-31 12:53:22.991662771 +0000 UTC m=+165.662284923 End:2018-08-31 12:53:22.992298487 +0000 UTC m=+165.662920617
I0831 12:53:22.992339       1 scheduler.go:454] Total Schedule Algo cumulative time:119.282696ms for 88
I0831 12:53:22.993143       1 scheduler.go:451] ScheduleAlgoTime 731.298µs Start:2018-08-31 12:53:22.99240518 +0000 UTC m=+165.663027332 End:2018-08-31 12:53:22.993136492 +0000 UTC m=+165.663758630
I0831 12:53:22.993177       1 scheduler.go:454] Total Schedule Algo cumulative time:120.013994ms for 89
I0831 12:53:22.993969       1 scheduler.go:451] ScheduleAlgoTime 716.286µs Start:2018-08-31 12:53:22.993246218 +0000 UTC m=+165.663868368 End:2018-08-31 12:53:22.993962509 +0000 UTC m=+165.664584654
I0831 12:53:22.994022       1 scheduler.go:454] Total Schedule Algo cumulative time:120.73028ms for 90
I0831 12:53:23.000403       1 scheduler.go:451] ScheduleAlgoTime 1.339322ms Start:2018-08-31 12:53:22.999052478 +0000 UTC m=+165.669674629 End:2018-08-31 12:53:23.000391822 +0000 UTC m=+165.671013951
I0831 12:53:23.000457       1 scheduler.go:454] Total Schedule Algo cumulative time:122.069602ms for 91
I0831 12:53:23.001814       1 scheduler.go:451] ScheduleAlgoTime 1.111112ms Start:2018-08-31 12:53:23.000695138 +0000 UTC m=+165.671317321 End:2018-08-31 12:53:23.001806303 +0000 UTC m=+165.672428433
I0831 12:53:23.001859       1 scheduler.go:454] Total Schedule Algo cumulative time:123.180714ms for 92
I0831 12:53:23.188451       1 scheduler.go:451] ScheduleAlgoTime 1.611407ms Start:2018-08-31 12:53:23.186827769 +0000 UTC m=+165.857449939 End:2018-08-31 12:53:23.188439219 +0000 UTC m=+165.859061346
I0831 12:53:23.188501       1 scheduler.go:454] Total Schedule Algo cumulative time:124.792121ms for 93
I0831 12:53:23.189599       1 scheduler.go:451] ScheduleAlgoTime 826.984µs Start:2018-08-31 12:53:23.18876617 +0000 UTC m=+165.859388312 End:2018-08-31 12:53:23.189593172 +0000 UTC m=+165.860215296
I0831 12:53:23.189630       1 scheduler.go:454] Total Schedule Algo cumulative time:125.619105ms for 94
I0831 12:53:23.190324       1 scheduler.go:451] ScheduleAlgoTime 608.781µs Start:2018-08-31 12:53:23.189709488 +0000 UTC m=+165.860331631 End:2018-08-31 12:53:23.190318289 +0000 UTC m=+165.860940412
I0831 12:53:23.190358       1 scheduler.go:454] Total Schedule Algo cumulative time:126.227886ms for 95
I0831 12:53:23.191257       1 scheduler.go:451] ScheduleAlgoTime 802.831µs Start:2018-08-31 12:53:23.190446176 +0000 UTC m=+165.861068349 End:2018-08-31 12:53:23.191249058 +0000 UTC m=+165.861871180
I0831 12:53:23.191308       1 scheduler.go:454] Total Schedule Algo cumulative time:127.030717ms for 96
I0831 12:53:23.206482       1 scheduler.go:451] ScheduleAlgoTime 909.379µs Start:2018-08-31 12:53:23.205564395 +0000 UTC m=+165.876186558 End:2018-08-31 12:53:23.206473817 +0000 UTC m=+165.877095937
I0831 12:53:23.375639       1 scheduler.go:454] Total Schedule Algo cumulative time:127.940096ms for 97
I0831 12:53:23.376953       1 scheduler.go:451] ScheduleAlgoTime 1.040677ms Start:2018-08-31 12:53:23.375906169 +0000 UTC m=+166.046528292 End:2018-08-31 12:53:23.376946849 +0000 UTC m=+166.047568969
I0831 12:53:23.376989       1 scheduler.go:454] Total Schedule Algo cumulative time:128.980773ms for 98
I0831 12:53:23.378403       1 scheduler.go:451] ScheduleAlgoTime 1.1948ms Start:2018-08-31 12:53:23.377201074 +0000 UTC m=+166.047823233 End:2018-08-31 12:53:23.378395905 +0000 UTC m=+166.049018033
I0831 12:53:23.378453       1 scheduler.go:454] Total Schedule Algo cumulative time:130.175573ms for 99
I0831 12:53:23.379576       1 scheduler.go:451] ScheduleAlgoTime 1.041917ms Start:2018-08-31 12:53:23.378526933 +0000 UTC m=+166.049149081 End:2018-08-31 12:53:23.379568875 +0000 UTC m=+166.050190998
I0831 12:53:23.379619       1 scheduler.go:454] Total Schedule Algo cumulative time:131.21749ms for 100
I0831 12:53:23.380477       1 scheduler.go:451] ScheduleAlgoTime 778.309µs Start:2018-08-31 12:53:23.379692688 +0000 UTC m=+166.050314885 End:2018-08-31 12:53:23.380471064 +0000 UTC m=+166.051093194
I0831 12:53:23.380533       1 scheduler.go:454] Total Schedule Algo cumulative time:131.995799ms for 101
I0831 12:53:23.381728       1 scheduler.go:451] ScheduleAlgoTime 976.414µs Start:2018-08-31 12:53:23.380745601 +0000 UTC m=+166.051367756 End:2018-08-31 12:53:23.381722042 +0000 UTC m=+166.052344170
I0831 12:53:23.381758       1 scheduler.go:454] Total Schedule Algo cumulative time:132.972213ms for 102
I0831 12:53:23.382649       1 scheduler.go:451] ScheduleAlgoTime 768.257µs Start:2018-08-31 12:53:23.381873973 +0000 UTC m=+166.052496142 End:2018-08-31 12:53:23.382642246 +0000 UTC m=+166.053264399
I0831 12:53:23.382696       1 scheduler.go:454] Total Schedule Algo cumulative time:133.74047ms for 103
I0831 12:53:23.383893       1 scheduler.go:451] ScheduleAlgoTime 1.114632ms Start:2018-08-31 12:53:23.382771427 +0000 UTC m=+166.053393588 End:2018-08-31 12:53:23.383886095 +0000 UTC m=+166.054508220
I0831 12:53:23.383928       1 scheduler.go:454] Total Schedule Algo cumulative time:134.855102ms for 104
I0831 12:53:23.384785       1 scheduler.go:451] ScheduleAlgoTime 784.415µs Start:2018-08-31 12:53:23.383993505 +0000 UTC m=+166.054615665 End:2018-08-31 12:53:23.384777944 +0000 UTC m=+166.055400080
I0831 12:53:23.384813       1 scheduler.go:454] Total Schedule Algo cumulative time:135.639517ms for 105
I0831 12:53:23.385897       1 scheduler.go:451] ScheduleAlgoTime 936.676µs Start:2018-08-31 12:53:23.384954974 +0000 UTC m=+166.055577136 End:2018-08-31 12:53:23.385891683 +0000 UTC m=+166.056513812
I0831 12:53:23.385927       1 scheduler.go:454] Total Schedule Algo cumulative time:136.576193ms for 106
I0831 12:53:23.390661       1 scheduler.go:451] ScheduleAlgoTime 783.817µs Start:2018-08-31 12:53:23.389870398 +0000 UTC m=+166.060492585 End:2018-08-31 12:53:23.390654274 +0000 UTC m=+166.061276402
I0831 12:53:23.390706       1 scheduler.go:454] Total Schedule Algo cumulative time:137.36001ms for 107
I0831 12:53:23.437592       1 scheduler.go:451] ScheduleAlgoTime 1.367437ms Start:2018-08-31 12:53:23.436214564 +0000 UTC m=+166.106836727 End:2018-08-31 12:53:23.437582038 +0000 UTC m=+166.108204164
I0831 12:53:23.437639       1 scheduler.go:454] Total Schedule Algo cumulative time:138.727447ms for 108
I0831 12:53:23.440673       1 scheduler.go:451] ScheduleAlgoTime 1.202477ms Start:2018-08-31 12:53:23.43946396 +0000 UTC m=+166.110086138 End:2018-08-31 12:53:23.440666492 +0000 UTC m=+166.111288615
I0831 12:53:23.440710       1 scheduler.go:454] Total Schedule Algo cumulative time:139.929924ms for 109
I0831 12:53:23.450034       1 scheduler.go:451] ScheduleAlgoTime 1.531462ms Start:2018-08-31 12:53:23.448493685 +0000 UTC m=+166.119115867 End:2018-08-31 12:53:23.450025209 +0000 UTC m=+166.120647329
I0831 12:53:23.450071       1 scheduler.go:454] Total Schedule Algo cumulative time:141.461386ms for 110
I0831 12:53:23.452241       1 scheduler.go:451] ScheduleAlgoTime 1.505951ms Start:2018-08-31 12:53:23.450725967 +0000 UTC m=+166.121348139 End:2018-08-31 12:53:23.452231971 +0000 UTC m=+166.122854090
I0831 12:53:23.452285       1 scheduler.go:454] Total Schedule Algo cumulative time:142.967337ms for 111
I0831 12:53:23.453418       1 scheduler.go:451] ScheduleAlgoTime 1.048159ms Start:2018-08-31 12:53:23.452363421 +0000 UTC m=+166.122985582 End:2018-08-31 12:53:23.453411615 +0000 UTC m=+166.124033741
I0831 12:53:23.453462       1 scheduler.go:454] Total Schedule Algo cumulative time:144.015496ms for 112
I0831 12:53:23.454719       1 scheduler.go:451] ScheduleAlgoTime 1.171183ms Start:2018-08-31 12:53:23.453542343 +0000 UTC m=+166.124164501 End:2018-08-31 12:53:23.45471356 +0000 UTC m=+166.125335684
I0831 12:53:23.493570       1 scheduler.go:454] Total Schedule Algo cumulative time:145.186679ms for 113
I0831 12:53:23.494864       1 scheduler.go:451] ScheduleAlgoTime 1.158001ms Start:2018-08-31 12:53:23.493699195 +0000 UTC m=+166.164321376 End:2018-08-31 12:53:23.494857251 +0000 UTC m=+166.165479377
I0831 12:53:23.494899       1 scheduler.go:454] Total Schedule Algo cumulative time:146.34468ms for 114
I0831 12:53:23.495911       1 scheduler.go:451] ScheduleAlgoTime 936.785µs Start:2018-08-31 12:53:23.494968502 +0000 UTC m=+166.165590676 End:2018-08-31 12:53:23.495905327 +0000 UTC m=+166.166527461
I0831 12:53:23.495938       1 scheduler.go:454] Total Schedule Algo cumulative time:147.281465ms for 115
I0831 12:53:23.496641       1 scheduler.go:451] ScheduleAlgoTime 618.442µs Start:2018-08-31 12:53:23.496017519 +0000 UTC m=+166.166639674 End:2018-08-31 12:53:23.496635987 +0000 UTC m=+166.167258116
I0831 12:53:23.496665       1 scheduler.go:454] Total Schedule Algo cumulative time:147.899907ms for 116
I0831 12:53:23.497847       1 scheduler.go:451] ScheduleAlgoTime 834.218µs Start:2018-08-31 12:53:23.497006888 +0000 UTC m=+166.167629060 End:2018-08-31 12:53:23.497841151 +0000 UTC m=+166.168463278
I0831 12:53:23.497872       1 scheduler.go:454] Total Schedule Algo cumulative time:148.734125ms for 117
I0831 12:53:23.498702       1 scheduler.go:451] ScheduleAlgoTime 763.91µs Start:2018-08-31 12:53:23.497931431 +0000 UTC m=+166.168553601 End:2018-08-31 12:53:23.498695375 +0000 UTC m=+166.169317511
I0831 12:53:23.498728       1 scheduler.go:454] Total Schedule Algo cumulative time:149.498035ms for 118
I0831 12:53:23.499698       1 scheduler.go:451] ScheduleAlgoTime 906.742µs Start:2018-08-31 12:53:23.498787438 +0000 UTC m=+166.169409605 End:2018-08-31 12:53:23.499694229 +0000 UTC m=+166.170316347
I0831 12:53:23.499716       1 scheduler.go:454] Total Schedule Algo cumulative time:150.404777ms for 119
I0831 12:53:23.500763       1 scheduler.go:451] ScheduleAlgoTime 974.927µs Start:2018-08-31 12:53:23.499781485 +0000 UTC m=+166.170403647 End:2018-08-31 12:53:23.500756445 +0000 UTC m=+166.171378574
I0831 12:53:23.500790       1 scheduler.go:454] Total Schedule Algo cumulative time:151.379704ms for 120
I0831 12:53:23.501604       1 scheduler.go:451] ScheduleAlgoTime 650.421µs Start:2018-08-31 12:53:23.500948481 +0000 UTC m=+166.171570652 End:2018-08-31 12:53:23.501598948 +0000 UTC m=+166.172221073
I0831 12:53:23.501624       1 scheduler.go:454] Total Schedule Algo cumulative time:152.030125ms for 121
I0831 12:53:23.507213       1 scheduler.go:451] ScheduleAlgoTime 869.168µs Start:2018-08-31 12:53:23.506332881 +0000 UTC m=+166.176955077 End:2018-08-31 12:53:23.507202032 +0000 UTC m=+166.177824245
I0831 12:53:23.507260       1 scheduler.go:454] Total Schedule Algo cumulative time:152.899293ms for 122
I0831 12:53:23.508066       1 scheduler.go:451] ScheduleAlgoTime 706.574µs Start:2018-08-31 12:53:23.507351986 +0000 UTC m=+166.177974180 End:2018-08-31 12:53:23.508058619 +0000 UTC m=+166.178680754
I0831 12:53:23.508095       1 scheduler.go:454] Total Schedule Algo cumulative time:153.605867ms for 123
I0831 12:53:23.509886       1 scheduler.go:451] ScheduleAlgoTime 770.7µs Start:2018-08-31 12:53:23.509108416 +0000 UTC m=+166.179730581 End:2018-08-31 12:53:23.509879158 +0000 UTC m=+166.180501281
I0831 12:53:23.509911       1 scheduler.go:454] Total Schedule Algo cumulative time:154.376567ms for 124
I0831 12:53:23.555006       1 scheduler.go:451] ScheduleAlgoTime 1.05525ms Start:2018-08-31 12:53:23.553940137 +0000 UTC m=+166.224562320 End:2018-08-31 12:53:23.554995441 +0000 UTC m=+166.225617570
I0831 12:53:23.555060       1 scheduler.go:454] Total Schedule Algo cumulative time:155.431817ms for 125
I0831 12:53:23.563998       1 scheduler.go:451] ScheduleAlgoTime 1.73095ms Start:2018-08-31 12:53:23.562256709 +0000 UTC m=+166.232878886 End:2018-08-31 12:53:23.563987705 +0000 UTC m=+166.234609836
I0831 12:53:23.564047       1 scheduler.go:454] Total Schedule Algo cumulative time:157.162767ms for 126
I0831 12:53:23.568640       1 scheduler.go:451] ScheduleAlgoTime 1.796748ms Start:2018-08-31 12:53:23.566833391 +0000 UTC m=+166.237455567 End:2018-08-31 12:53:23.568630181 +0000 UTC m=+166.239252315
I0831 12:53:23.568682       1 scheduler.go:454] Total Schedule Algo cumulative time:158.959515ms for 127
I0831 12:53:23.576979       1 scheduler.go:451] ScheduleAlgoTime 8.18904ms Start:2018-08-31 12:53:23.5687776 +0000 UTC m=+166.239399828 End:2018-08-31 12:53:23.576966745 +0000 UTC m=+166.247588868
I0831 12:53:23.629060       1 scheduler.go:454] Total Schedule Algo cumulative time:167.148555ms for 128
I0831 12:53:23.630228       1 scheduler.go:451] ScheduleAlgoTime 983.025µs Start:2018-08-31 12:53:23.62923787 +0000 UTC m=+166.299860026 End:2018-08-31 12:53:23.630220917 +0000 UTC m=+166.300843051
I0831 12:53:23.630274       1 scheduler.go:454] Total Schedule Algo cumulative time:168.13158ms for 129
I0831 12:53:23.631617       1 scheduler.go:451] ScheduleAlgoTime 1.162594ms Start:2018-08-31 12:53:23.630449354 +0000 UTC m=+166.301071520 End:2018-08-31 12:53:23.631611994 +0000 UTC m=+166.302234114
I0831 12:53:23.631649       1 scheduler.go:454] Total Schedule Algo cumulative time:169.294174ms for 130
I0831 12:53:23.633532       1 scheduler.go:451] ScheduleAlgoTime 1.029204ms Start:2018-08-31 12:53:23.632497049 +0000 UTC m=+166.303119232 End:2018-08-31 12:53:23.633526318 +0000 UTC m=+166.304148436
I0831 12:53:23.633575       1 scheduler.go:454] Total Schedule Algo cumulative time:170.323378ms for 131
I0831 12:53:23.634332       1 scheduler.go:451] ScheduleAlgoTime 674.311µs Start:2018-08-31 12:53:23.63365269 +0000 UTC m=+166.304274872 End:2018-08-31 12:53:23.634327064 +0000 UTC m=+166.304949183
I0831 12:53:23.634360       1 scheduler.go:454] Total Schedule Algo cumulative time:170.997689ms for 132
I0831 12:53:23.635154       1 scheduler.go:451] ScheduleAlgoTime 708.426µs Start:2018-08-31 12:53:23.634438222 +0000 UTC m=+166.305060367 End:2018-08-31 12:53:23.635146668 +0000 UTC m=+166.305768793
I0831 12:53:23.635194       1 scheduler.go:454] Total Schedule Algo cumulative time:171.706115ms for 133
I0831 12:53:23.636476       1 scheduler.go:451] ScheduleAlgoTime 1.21515ms Start:2018-08-31 12:53:23.635254732 +0000 UTC m=+166.305876869 End:2018-08-31 12:53:23.636469897 +0000 UTC m=+166.307092019
I0831 12:53:23.636504       1 scheduler.go:454] Total Schedule Algo cumulative time:172.921265ms for 134
I0831 12:53:23.651069       1 scheduler.go:451] ScheduleAlgoTime 1.718025ms Start:2018-08-31 12:53:23.649339534 +0000 UTC m=+166.319961707 End:2018-08-31 12:53:23.651057611 +0000 UTC m=+166.321679732
I0831 12:53:23.762894       1 scheduler.go:454] Total Schedule Algo cumulative time:174.63929ms for 135
I0831 12:53:23.763921       1 scheduler.go:451] ScheduleAlgoTime 895.009µs Start:2018-08-31 12:53:23.763018138 +0000 UTC m=+166.433640315 End:2018-08-31 12:53:23.763913194 +0000 UTC m=+166.434535324
I0831 12:53:23.763981       1 scheduler.go:454] Total Schedule Algo cumulative time:175.534299ms for 136
I0831 12:53:23.765565       1 scheduler.go:451] ScheduleAlgoTime 1.501802ms Start:2018-08-31 12:53:23.764056107 +0000 UTC m=+166.434678253 End:2018-08-31 12:53:23.76555793 +0000 UTC m=+166.436180055
I0831 12:53:23.765600       1 scheduler.go:454] Total Schedule Algo cumulative time:177.036101ms for 137
I0831 12:53:23.767166       1 scheduler.go:451] ScheduleAlgoTime 1.297582ms Start:2018-08-31 12:53:23.765861186 +0000 UTC m=+166.436483348 End:2018-08-31 12:53:23.767158806 +0000 UTC m=+166.437780930
I0831 12:53:23.767199       1 scheduler.go:454] Total Schedule Algo cumulative time:178.333683ms for 138
I0831 12:53:23.768499       1 scheduler.go:451] ScheduleAlgoTime 1.210888ms Start:2018-08-31 12:53:23.767281548 +0000 UTC m=+166.437903676 End:2018-08-31 12:53:23.768492435 +0000 UTC m=+166.439114564
I0831 12:53:23.768530       1 scheduler.go:454] Total Schedule Algo cumulative time:179.544571ms for 139
I0831 12:53:23.771936       1 scheduler.go:451] ScheduleAlgoTime 971.723µs Start:2018-08-31 12:53:23.770957482 +0000 UTC m=+166.441579682 End:2018-08-31 12:53:23.771929282 +0000 UTC m=+166.442551405
I0831 12:53:23.771968       1 scheduler.go:454] Total Schedule Algo cumulative time:180.516294ms for 140
I0831 12:53:23.772893       1 scheduler.go:451] ScheduleAlgoTime 857.499µs Start:2018-08-31 12:53:23.77202799 +0000 UTC m=+166.442650142 End:2018-08-31 12:53:23.772885474 +0000 UTC m=+166.443507641
I0831 12:53:23.772937       1 scheduler.go:454] Total Schedule Algo cumulative time:181.373793ms for 141
I0831 12:53:23.780362       1 scheduler.go:451] ScheduleAlgoTime 830.52µs Start:2018-08-31 12:53:23.779522864 +0000 UTC m=+166.450145034 End:2018-08-31 12:53:23.780353428 +0000 UTC m=+166.450975554
I0831 12:53:23.780401       1 scheduler.go:454] Total Schedule Algo cumulative time:182.204313ms for 142
I0831 12:53:23.781705       1 scheduler.go:451] ScheduleAlgoTime 796.556µs Start:2018-08-31 12:53:23.780901349 +0000 UTC m=+166.451523545 End:2018-08-31 12:53:23.781697963 +0000 UTC m=+166.452320101
I0831 12:53:23.839436       1 scheduler.go:454] Total Schedule Algo cumulative time:183.000869ms for 143
I0831 12:53:23.840552       1 scheduler.go:451] ScheduleAlgoTime 949.53µs Start:2018-08-31 12:53:23.839594983 +0000 UTC m=+166.510217179 End:2018-08-31 12:53:23.840544577 +0000 UTC m=+166.511166709
I0831 12:53:23.840592       1 scheduler.go:454] Total Schedule Algo cumulative time:183.950399ms for 144
I0831 12:53:23.842061       1 scheduler.go:451] ScheduleAlgoTime 1.35728ms Start:2018-08-31 12:53:23.840696616 +0000 UTC m=+166.511318782 End:2018-08-31 12:53:23.842053933 +0000 UTC m=+166.512676062
I0831 12:53:23.842095       1 scheduler.go:454] Total Schedule Algo cumulative time:185.307679ms for 145
I0831 12:53:23.843174       1 scheduler.go:451] ScheduleAlgoTime 731.843µs Start:2018-08-31 12:53:23.842426873 +0000 UTC m=+166.513058798 End:2018-08-31 12:53:23.843168517 +0000 UTC m=+166.513790641
I0831 12:53:23.843213       1 scheduler.go:454] Total Schedule Algo cumulative time:186.039522ms for 146
I0831 12:53:23.848371       1 scheduler.go:451] ScheduleAlgoTime 916.245µs Start:2018-08-31 12:53:23.847447369 +0000 UTC m=+166.518069529 End:2018-08-31 12:53:23.848363641 +0000 UTC m=+166.518985774
I0831 12:53:23.848410       1 scheduler.go:454] Total Schedule Algo cumulative time:186.955767ms for 147
I0831 12:53:23.850200       1 scheduler.go:451] ScheduleAlgoTime 1.682023ms Start:2018-08-31 12:53:23.848509702 +0000 UTC m=+166.519131860 End:2018-08-31 12:53:23.850191755 +0000 UTC m=+166.520813883
I0831 12:53:23.850236       1 scheduler.go:454] Total Schedule Algo cumulative time:188.63779ms for 148
I0831 12:53:23.851287       1 scheduler.go:451] ScheduleAlgoTime 974.515µs Start:2018-08-31 12:53:23.850305894 +0000 UTC m=+166.520928073 End:2018-08-31 12:53:23.851280456 +0000 UTC m=+166.521902588
I0831 12:53:23.851344       1 scheduler.go:454] Total Schedule Algo cumulative time:189.612305ms for 149
I0831 12:53:23.852298       1 scheduler.go:451] ScheduleAlgoTime 883.332µs Start:2018-08-31 12:53:23.851407802 +0000 UTC m=+166.522029952 End:2018-08-31 12:53:23.852291151 +0000 UTC m=+166.522913284
I0831 12:53:23.852324       1 scheduler.go:454] Total Schedule Algo cumulative time:190.495637ms for 150
I0831 12:53:23.854230       1 scheduler.go:451] ScheduleAlgoTime 728.405µs Start:2018-08-31 12:53:23.853495878 +0000 UTC m=+166.524118061 End:2018-08-31 12:53:23.854224337 +0000 UTC m=+166.524846466
I0831 12:53:23.854257       1 scheduler.go:454] Total Schedule Algo cumulative time:191.224042ms for 151
I0831 12:53:23.855472       1 scheduler.go:451] ScheduleAlgoTime 1.148466ms Start:2018-08-31 12:53:23.854317051 +0000 UTC m=+166.524939211 End:2018-08-31 12:53:23.855465544 +0000 UTC m=+166.526087677
I0831 12:53:23.855498       1 scheduler.go:454] Total Schedule Algo cumulative time:192.372508ms for 152
I0831 12:53:23.856599       1 scheduler.go:451] ScheduleAlgoTime 1.022694ms Start:2018-08-31 12:53:23.855570377 +0000 UTC m=+166.526192553 End:2018-08-31 12:53:23.85659312 +0000 UTC m=+166.527215247
I0831 12:53:23.856628       1 scheduler.go:454] Total Schedule Algo cumulative time:193.395202ms for 153
I0831 12:53:23.857781       1 scheduler.go:451] ScheduleAlgoTime 1.06169ms Start:2018-08-31 12:53:23.856712854 +0000 UTC m=+166.527335026 End:2018-08-31 12:53:23.85777459 +0000 UTC m=+166.528396716
I0831 12:53:23.857816       1 scheduler.go:454] Total Schedule Algo cumulative time:194.456892ms for 154
I0831 12:53:23.858963       1 scheduler.go:451] ScheduleAlgoTime 1.00962ms Start:2018-08-31 12:53:23.857947179 +0000 UTC m=+166.528569350 End:2018-08-31 12:53:23.858956845 +0000 UTC m=+166.529578970
I0831 12:53:23.859857       1 scheduler.go:454] Total Schedule Algo cumulative time:195.466512ms for 155
I0831 12:53:23.861209       1 scheduler.go:451] ScheduleAlgoTime 958.771µs Start:2018-08-31 12:53:23.86024467 +0000 UTC m=+166.530866843 End:2018-08-31 12:53:23.861203487 +0000 UTC m=+166.531825614
I0831 12:53:23.861234       1 scheduler.go:454] Total Schedule Algo cumulative time:196.425283ms for 156
I0831 12:53:23.862079       1 scheduler.go:451] ScheduleAlgoTime 788.282µs Start:2018-08-31 12:53:23.861284861 +0000 UTC m=+166.531907005 End:2018-08-31 12:53:23.862073152 +0000 UTC m=+166.532695287
I0831 12:53:23.862104       1 scheduler.go:454] Total Schedule Algo cumulative time:197.213565ms for 157
I0831 12:53:23.863222       1 scheduler.go:451] ScheduleAlgoTime 975.451µs Start:2018-08-31 12:53:23.862240712 +0000 UTC m=+166.532862892 End:2018-08-31 12:53:23.863216206 +0000 UTC m=+166.533838343
I0831 12:53:23.863249       1 scheduler.go:454] Total Schedule Algo cumulative time:198.189016ms for 158
I0831 12:53:23.887261       1 scheduler.go:451] ScheduleAlgoTime 1.105961ms Start:2018-08-31 12:53:23.886144776 +0000 UTC m=+166.556766944 End:2018-08-31 12:53:23.887250784 +0000 UTC m=+166.557872905
I0831 12:53:23.887305       1 scheduler.go:454] Total Schedule Algo cumulative time:199.294977ms for 159
I0831 12:53:23.893647       1 scheduler.go:451] ScheduleAlgoTime 1.055212ms Start:2018-08-31 12:53:23.892580159 +0000 UTC m=+166.563202353 End:2018-08-31 12:53:23.893635434 +0000 UTC m=+166.564257565
I0831 12:53:23.893685       1 scheduler.go:454] Total Schedule Algo cumulative time:200.350189ms for 160
I0831 12:53:23.895156       1 scheduler.go:451] ScheduleAlgoTime 1.041439ms Start:2018-08-31 12:53:23.894107871 +0000 UTC m=+166.564730047 End:2018-08-31 12:53:23.895149361 +0000 UTC m=+166.565771486
I0831 12:53:23.895195       1 scheduler.go:454] Total Schedule Algo cumulative time:201.391628ms for 161
I0831 12:53:23.927545       1 scheduler.go:451] ScheduleAlgoTime 1.359085ms Start:2018-08-31 12:53:23.926175218 +0000 UTC m=+166.596797396 End:2018-08-31 12:53:23.927534345 +0000 UTC m=+166.598156481
I0831 12:53:23.927603       1 scheduler.go:454] Total Schedule Algo cumulative time:202.750713ms for 162
I0831 12:53:23.953456       1 scheduler.go:451] ScheduleAlgoTime 3.364318ms Start:2018-08-31 12:53:23.950081054 +0000 UTC m=+166.620703222 End:2018-08-31 12:53:23.953445405 +0000 UTC m=+166.624067540
I0831 12:53:23.953508       1 scheduler.go:454] Total Schedule Algo cumulative time:206.115031ms for 163
I0831 12:53:23.961469       1 scheduler.go:451] ScheduleAlgoTime 1.762033ms Start:2018-08-31 12:53:23.959696302 +0000 UTC m=+166.630318479 End:2018-08-31 12:53:23.961458378 +0000 UTC m=+166.632080512
I0831 12:53:23.961515       1 scheduler.go:454] Total Schedule Algo cumulative time:207.877064ms for 164
I0831 12:53:23.963108       1 scheduler.go:451] ScheduleAlgoTime 962.89µs Start:2018-08-31 12:53:23.962139487 +0000 UTC m=+166.632761673 End:2018-08-31 12:53:23.963102441 +0000 UTC m=+166.633724563
I0831 12:53:23.963136       1 scheduler.go:454] Total Schedule Algo cumulative time:208.839954ms for 165
I0831 12:53:23.966348       1 scheduler.go:451] ScheduleAlgoTime 1.251507ms Start:2018-08-31 12:53:23.965087453 +0000 UTC m=+166.635709647 End:2018-08-31 12:53:23.966339022 +0000 UTC m=+166.636961154
I0831 12:53:23.966387       1 scheduler.go:454] Total Schedule Algo cumulative time:210.091461ms for 166
I0831 12:53:23.967562       1 scheduler.go:451] ScheduleAlgoTime 1.065091ms Start:2018-08-31 12:53:23.966491534 +0000 UTC m=+166.637113701 End:2018-08-31 12:53:23.967556663 +0000 UTC m=+166.638178792
I0831 12:53:23.967601       1 scheduler.go:454] Total Schedule Algo cumulative time:211.156552ms for 167
I0831 12:53:23.971201       1 scheduler.go:451] ScheduleAlgoTime 1.427435ms Start:2018-08-31 12:53:23.969766667 +0000 UTC m=+166.640388863 End:2018-08-31 12:53:23.971194168 +0000 UTC m=+166.641816298
I0831 12:53:23.971239       1 scheduler.go:454] Total Schedule Algo cumulative time:212.583987ms for 168
I0831 12:53:23.972276       1 scheduler.go:451] ScheduleAlgoTime 969.74µs Start:2018-08-31 12:53:23.971300344 +0000 UTC m=+166.641922494 End:2018-08-31 12:53:23.9722701 +0000 UTC m=+166.642892234
I0831 12:53:23.972321       1 scheduler.go:454] Total Schedule Algo cumulative time:213.553727ms for 169
I0831 12:53:23.991391       1 scheduler.go:451] ScheduleAlgoTime 1.099305ms Start:2018-08-31 12:53:23.99028177 +0000 UTC m=+166.660903950 End:2018-08-31 12:53:23.991381128 +0000 UTC m=+166.662003255
I0831 12:53:23.991445       1 scheduler.go:454] Total Schedule Algo cumulative time:214.653032ms for 170
I0831 12:53:23.993584       1 scheduler.go:451] ScheduleAlgoTime 740.262µs Start:2018-08-31 12:53:23.992838911 +0000 UTC m=+166.663461094 End:2018-08-31 12:53:23.993579233 +0000 UTC m=+166.664201356
I0831 12:53:23.993624       1 scheduler.go:454] Total Schedule Algo cumulative time:215.393294ms for 171
I0831 12:53:23.998615       1 scheduler.go:451] ScheduleAlgoTime 1.240607ms Start:2018-08-31 12:53:23.997365515 +0000 UTC m=+166.667987725 End:2018-08-31 12:53:23.998606196 +0000 UTC m=+166.669228332
I0831 12:53:23.998654       1 scheduler.go:454] Total Schedule Algo cumulative time:216.633901ms for 172
I0831 12:53:23.999651       1 scheduler.go:451] ScheduleAlgoTime 759.686µs Start:2018-08-31 12:53:23.998882946 +0000 UTC m=+166.669505095 End:2018-08-31 12:53:23.999642653 +0000 UTC m=+166.670264781
I0831 12:53:23.999703       1 scheduler.go:454] Total Schedule Algo cumulative time:217.393587ms for 173
I0831 12:53:24.003136       1 scheduler.go:451] ScheduleAlgoTime 1.018076ms Start:2018-08-31 12:53:24.002111189 +0000 UTC m=+166.672733397 End:2018-08-31 12:53:24.003129329 +0000 UTC m=+166.673751473
I0831 12:53:24.003183       1 scheduler.go:454] Total Schedule Algo cumulative time:218.411663ms for 174
I0831 12:53:24.004671       1 scheduler.go:451] ScheduleAlgoTime 1.399095ms Start:2018-08-31 12:53:24.003264934 +0000 UTC m=+166.673887077 End:2018-08-31 12:53:24.004664041 +0000 UTC m=+166.675286172
I0831 12:53:24.004711       1 scheduler.go:454] Total Schedule Algo cumulative time:219.810758ms for 175
I0831 12:53:24.007941       1 scheduler.go:451] ScheduleAlgoTime 747.696µs Start:2018-08-31 12:53:24.00718684 +0000 UTC m=+166.677809012 End:2018-08-31 12:53:24.007934591 +0000 UTC m=+166.678556708
I0831 12:53:24.007984       1 scheduler.go:454] Total Schedule Algo cumulative time:220.558454ms for 176
I0831 12:53:24.019415       1 scheduler.go:451] ScheduleAlgoTime 1.536223ms Start:2018-08-31 12:53:24.01786865 +0000 UTC m=+166.688490842 End:2018-08-31 12:53:24.019404935 +0000 UTC m=+166.690027065
I0831 12:53:24.019467       1 scheduler.go:454] Total Schedule Algo cumulative time:222.094677ms for 177
I0831 12:53:24.024791       1 scheduler.go:451] ScheduleAlgoTime 1.758443ms Start:2018-08-31 12:53:24.023022981 +0000 UTC m=+166.693645150 End:2018-08-31 12:53:24.024781463 +0000 UTC m=+166.695403593
I0831 12:53:24.024842       1 scheduler.go:454] Total Schedule Algo cumulative time:223.85312ms for 178
I0831 12:53:24.033606       1 scheduler.go:451] ScheduleAlgoTime 1.741254ms Start:2018-08-31 12:53:24.031854692 +0000 UTC m=+166.702476890 End:2018-08-31 12:53:24.033596014 +0000 UTC m=+166.704218144
I0831 12:53:24.033648       1 scheduler.go:454] Total Schedule Algo cumulative time:225.594374ms for 179
I0831 12:53:24.036521       1 scheduler.go:451] ScheduleAlgoTime 1.009358ms Start:2018-08-31 12:53:24.035494071 +0000 UTC m=+166.706116271 End:2018-08-31 12:53:24.036503494 +0000 UTC m=+166.707125629
I0831 12:53:24.036554       1 scheduler.go:454] Total Schedule Algo cumulative time:226.603732ms for 180
I0831 12:53:24.037328       1 scheduler.go:451] ScheduleAlgoTime 693.779µs Start:2018-08-31 12:53:24.036626577 +0000 UTC m=+166.707248785 End:2018-08-31 12:53:24.037320443 +0000 UTC m=+166.707942564
I0831 12:53:24.037366       1 scheduler.go:454] Total Schedule Algo cumulative time:227.297511ms for 181
I0831 12:53:24.040980       1 scheduler.go:451] ScheduleAlgoTime 1.075637ms Start:2018-08-31 12:53:24.039897036 +0000 UTC m=+166.710519225 End:2018-08-31 12:53:24.040972739 +0000 UTC m=+166.711594862
I0831 12:53:24.041015       1 scheduler.go:454] Total Schedule Algo cumulative time:228.373148ms for 182
I0831 12:53:24.049573       1 scheduler.go:451] ScheduleAlgoTime 754.378µs Start:2018-08-31 12:53:24.048812872 +0000 UTC m=+166.719435078 End:2018-08-31 12:53:24.049567333 +0000 UTC m=+166.720189456
I0831 12:53:24.049615       1 scheduler.go:454] Total Schedule Algo cumulative time:229.127526ms for 183
I0831 12:53:24.051016       1 scheduler.go:451] ScheduleAlgoTime 852.648µs Start:2018-08-31 12:53:24.05015637 +0000 UTC m=+166.720778561 End:2018-08-31 12:53:24.051009089 +0000 UTC m=+166.721631209
I0831 12:53:24.051055       1 scheduler.go:454] Total Schedule Algo cumulative time:229.980174ms for 184
I0831 12:53:24.052530       1 scheduler.go:451] ScheduleAlgoTime 1.254356ms Start:2018-08-31 12:53:24.0512686 +0000 UTC m=+166.721890727 End:2018-08-31 12:53:24.05252295 +0000 UTC m=+166.723145083
I0831 12:53:24.052569       1 scheduler.go:454] Total Schedule Algo cumulative time:231.23453ms for 185
I0831 12:53:24.054956       1 scheduler.go:451] ScheduleAlgoTime 1.341248ms Start:2018-08-31 12:53:24.053609747 +0000 UTC m=+166.724231937 End:2018-08-31 12:53:24.054951063 +0000 UTC m=+166.725573185
I0831 12:53:24.054988       1 scheduler.go:454] Total Schedule Algo cumulative time:232.575778ms for 186
I0831 12:53:24.056034       1 scheduler.go:451] ScheduleAlgoTime 965.441µs Start:2018-08-31 12:53:24.055062098 +0000 UTC m=+166.725684244 End:2018-08-31 12:53:24.056027565 +0000 UTC m=+166.726649685
I0831 12:53:24.056072       1 scheduler.go:454] Total Schedule Algo cumulative time:233.541219ms for 187
I0831 12:53:24.066137       1 scheduler.go:451] ScheduleAlgoTime 893.935µs Start:2018-08-31 12:53:24.065235898 +0000 UTC m=+166.735858050 End:2018-08-31 12:53:24.066129855 +0000 UTC m=+166.736751985
I0831 12:53:24.066174       1 scheduler.go:454] Total Schedule Algo cumulative time:234.435154ms for 188
I0831 12:53:24.067455       1 scheduler.go:451] ScheduleAlgoTime 971.504µs Start:2018-08-31 12:53:24.066476979 +0000 UTC m=+166.737099175 End:2018-08-31 12:53:24.067448555 +0000 UTC m=+166.738070679
I0831 12:53:24.067509       1 scheduler.go:454] Total Schedule Algo cumulative time:235.406658ms for 189
I0831 12:53:24.068545       1 scheduler.go:451] ScheduleAlgoTime 894.549µs Start:2018-08-31 12:53:24.067644519 +0000 UTC m=+166.738266670 End:2018-08-31 12:53:24.068539093 +0000 UTC m=+166.739161219
I0831 12:53:24.068571       1 scheduler.go:454] Total Schedule Algo cumulative time:236.301207ms for 190
I0831 12:53:24.069377       1 scheduler.go:451] ScheduleAlgoTime 750.546µs Start:2018-08-31 12:53:24.068620453 +0000 UTC m=+166.739242595 End:2018-08-31 12:53:24.069371008 +0000 UTC m=+166.739993141
I0831 12:53:24.069417       1 scheduler.go:454] Total Schedule Algo cumulative time:237.051753ms for 191
I0831 12:53:24.073509       1 scheduler.go:451] ScheduleAlgoTime 795.62µs Start:2018-08-31 12:53:24.072707736 +0000 UTC m=+166.743329919 End:2018-08-31 12:53:24.07350342 +0000 UTC m=+166.744125539
I0831 12:53:24.073544       1 scheduler.go:454] Total Schedule Algo cumulative time:237.847373ms for 192
I0831 12:53:24.074517       1 scheduler.go:451] ScheduleAlgoTime 904.807µs Start:2018-08-31 12:53:24.073605666 +0000 UTC m=+166.744227838 End:2018-08-31 12:53:24.074510521 +0000 UTC m=+166.745132645
I0831 12:53:24.074556       1 scheduler.go:454] Total Schedule Algo cumulative time:238.75218ms for 193
I0831 12:53:24.082377       1 scheduler.go:451] ScheduleAlgoTime 1.267499ms Start:2018-08-31 12:53:24.081102728 +0000 UTC m=+166.751724894 End:2018-08-31 12:53:24.082370264 +0000 UTC m=+166.752992393
I0831 12:53:24.082425       1 scheduler.go:454] Total Schedule Algo cumulative time:240.019679ms for 194
I0831 12:53:24.085326       1 scheduler.go:451] ScheduleAlgoTime 965.346µs Start:2018-08-31 12:53:24.084353307 +0000 UTC m=+166.754975467 End:2018-08-31 12:53:24.085318686 +0000 UTC m=+166.755940813
I0831 12:53:24.085360       1 scheduler.go:454] Total Schedule Algo cumulative time:240.985025ms for 195
I0831 12:53:24.087879       1 scheduler.go:451] ScheduleAlgoTime 749.984µs Start:2018-08-31 12:53:24.087122195 +0000 UTC m=+166.757744358 End:2018-08-31 12:53:24.087872215 +0000 UTC m=+166.758494342
I0831 12:53:24.087916       1 scheduler.go:454] Total Schedule Algo cumulative time:241.735009ms for 196
I0831 12:53:24.090904       1 scheduler.go:451] ScheduleAlgoTime 1.162747ms Start:2018-08-31 12:53:24.089734662 +0000 UTC m=+166.760356849 End:2018-08-31 12:53:24.090897468 +0000 UTC m=+166.761519596
I0831 12:53:24.090938       1 scheduler.go:454] Total Schedule Algo cumulative time:242.897756ms for 197
I0831 12:53:24.096624       1 scheduler.go:451] ScheduleAlgoTime 1.357796ms Start:2018-08-31 12:53:24.095256254 +0000 UTC m=+166.765878414 End:2018-08-31 12:53:24.096614088 +0000 UTC m=+166.767236210
I0831 12:53:24.096712       1 scheduler.go:454] Total Schedule Algo cumulative time:244.255552ms for 198
I0831 12:53:24.102110       1 scheduler.go:451] ScheduleAlgoTime 700.106µs Start:2018-08-31 12:53:24.101404452 +0000 UTC m=+166.772026631 End:2018-08-31 12:53:24.102104615 +0000 UTC m=+166.772726737
I0831 12:53:24.102141       1 scheduler.go:454] Total Schedule Algo cumulative time:244.955658ms for 199
I0831 12:53:24.106435       1 scheduler.go:451] ScheduleAlgoTime 757.549µs Start:2018-08-31 12:53:24.105662667 +0000 UTC m=+166.776284824 End:2018-08-31 12:53:24.10642025 +0000 UTC m=+166.777042373
I0831 12:53:24.106476       1 scheduler.go:454] Total Schedule Algo cumulative time:245.713207ms for 200
I0831 12:54:01.259121       1 scheduler.go:451] ScheduleAlgoTime 9.44085ms Start:2018-08-31 12:54:01.249670248 +0000 UTC m=+203.920292410 End:2018-08-31 12:54:01.259111141 +0000 UTC m=+203.929733260
I0831 12:54:01.259172       1 scheduler.go:454] Total Schedule Algo cumulative time:255.154057ms for 201
I0831 12:54:01.267995       1 scheduler.go:451] ScheduleAlgoTime 8.732299ms Start:2018-08-31 12:54:01.259254113 +0000 UTC m=+203.929876245 End:2018-08-31 12:54:01.267986424 +0000 UTC m=+203.938608544
I0831 12:54:01.268050       1 scheduler.go:454] Total Schedule Algo cumulative time:263.886356ms for 202
I0831 12:54:01.275616       1 scheduler.go:451] ScheduleAlgoTime 7.448718ms Start:2018-08-31 12:54:01.268152639 +0000 UTC m=+203.938774775 End:2018-08-31 12:54:01.275601374 +0000 UTC m=+203.946223493
I0831 12:54:01.275656       1 scheduler.go:454] Total Schedule Algo cumulative time:271.335074ms for 203
I0831 12:54:01.495207       1 scheduler.go:451] ScheduleAlgoTime 7.903628ms Start:2018-08-31 12:54:01.487289297 +0000 UTC m=+204.157911460 End:2018-08-31 12:54:01.49519297 +0000 UTC m=+204.165815088
I0831 12:54:01.495261       1 scheduler.go:454] Total Schedule Algo cumulative time:279.238702ms for 204
I0831 12:54:01.503979       1 scheduler.go:451] ScheduleAlgoTime 8.591155ms Start:2018-08-31 12:54:01.495377204 +0000 UTC m=+204.165999340 End:2018-08-31 12:54:01.503968377 +0000 UTC m=+204.174590495
I0831 12:54:01.504029       1 scheduler.go:454] Total Schedule Algo cumulative time:287.829857ms for 205
I0831 12:54:01.511823       1 scheduler.go:451] ScheduleAlgoTime 7.702842ms Start:2018-08-31 12:54:01.504111866 +0000 UTC m=+204.174734012 End:2018-08-31 12:54:01.511814734 +0000 UTC m=+204.182436854
I0831 12:54:01.511865       1 scheduler.go:454] Total Schedule Algo cumulative time:295.532699ms for 206
I0831 12:54:01.519953       1 scheduler.go:451] ScheduleAlgoTime 7.970038ms Start:2018-08-31 12:54:01.511970647 +0000 UTC m=+204.182592801 End:2018-08-31 12:54:01.519940716 +0000 UTC m=+204.190562839
I0831 12:54:01.520003       1 scheduler.go:454] Total Schedule Algo cumulative time:303.502737ms for 207
I0831 12:54:01.528183       1 scheduler.go:451] ScheduleAlgoTime 7.805896ms Start:2018-08-31 12:54:01.520358077 +0000 UTC m=+204.190980357 End:2018-08-31 12:54:01.528163999 +0000 UTC m=+204.198786253
I0831 12:54:01.544002       1 scheduler.go:454] Total Schedule Algo cumulative time:311.308633ms for 208
I0831 12:54:01.552277       1 scheduler.go:451] ScheduleAlgoTime 8.043619ms Start:2018-08-31 12:54:01.544221933 +0000 UTC m=+204.214844195 End:2018-08-31 12:54:01.552265695 +0000 UTC m=+204.222887814
I0831 12:54:01.552329       1 scheduler.go:454] Total Schedule Algo cumulative time:319.352252ms for 209
I0831 12:54:01.560734       1 scheduler.go:451] ScheduleAlgoTime 8.260424ms Start:2018-08-31 12:54:01.55246297 +0000 UTC m=+204.223085128 End:2018-08-31 12:54:01.560723432 +0000 UTC m=+204.231345552
I0831 12:54:01.560783       1 scheduler.go:454] Total Schedule Algo cumulative time:327.612676ms for 210
I0831 12:54:01.569030       1 scheduler.go:451] ScheduleAlgoTime 8.090187ms Start:2018-08-31 12:54:01.560931301 +0000 UTC m=+204.231553617 End:2018-08-31 12:54:01.569021681 +0000 UTC m=+204.239643804
I0831 12:54:01.569090       1 scheduler.go:454] Total Schedule Algo cumulative time:335.702863ms for 211
I0831 12:54:01.576766       1 scheduler.go:451] ScheduleAlgoTime 7.53823ms Start:2018-08-31 12:54:01.569218713 +0000 UTC m=+204.239840855 End:2018-08-31 12:54:01.576756965 +0000 UTC m=+204.247379085
I0831 12:54:01.576838       1 scheduler.go:454] Total Schedule Algo cumulative time:343.241093ms for 212
I0831 12:54:01.586719       1 scheduler.go:451] ScheduleAlgoTime 9.755876ms Start:2018-08-31 12:54:01.57695386 +0000 UTC m=+204.247576002 End:2018-08-31 12:54:01.586709759 +0000 UTC m=+204.257331878
I0831 12:54:01.586776       1 scheduler.go:454] Total Schedule Algo cumulative time:352.996969ms for 213
I0831 12:54:01.594178       1 scheduler.go:451] ScheduleAlgoTime 7.251503ms Start:2018-08-31 12:54:01.58692056 +0000 UTC m=+204.257542708 End:2018-08-31 12:54:01.59417209 +0000 UTC m=+204.264794211
I0831 12:54:01.594226       1 scheduler.go:454] Total Schedule Algo cumulative time:360.248472ms for 214
I0831 12:54:01.601951       1 scheduler.go:451] ScheduleAlgoTime 7.607259ms Start:2018-08-31 12:54:01.594337391 +0000 UTC m=+204.264959540 End:2018-08-31 12:54:01.601944679 +0000 UTC m=+204.272566799
I0831 12:54:01.601990       1 scheduler.go:454] Total Schedule Algo cumulative time:367.855731ms for 215
I0831 12:54:01.608752       1 scheduler.go:451] ScheduleAlgoTime 6.6558ms Start:2018-08-31 12:54:01.602088175 +0000 UTC m=+204.272710316 End:2018-08-31 12:54:01.608743993 +0000 UTC m=+204.279366116
I0831 12:54:01.608809       1 scheduler.go:454] Total Schedule Algo cumulative time:374.511531ms for 216
I0831 12:54:01.615577       1 scheduler.go:451] ScheduleAlgoTime 6.632502ms Start:2018-08-31 12:54:01.608937263 +0000 UTC m=+204.279559396 End:2018-08-31 12:54:01.615569779 +0000 UTC m=+204.286191898
I0831 12:54:01.615615       1 scheduler.go:454] Total Schedule Algo cumulative time:381.144033ms for 217
I0831 12:54:01.622620       1 scheduler.go:451] ScheduleAlgoTime 6.860658ms Start:2018-08-31 12:54:01.615753014 +0000 UTC m=+204.286375167 End:2018-08-31 12:54:01.622613706 +0000 UTC m=+204.293235825
I0831 12:54:01.622678       1 scheduler.go:454] Total Schedule Algo cumulative time:388.004691ms for 218
I0831 12:54:01.802626       1 scheduler.go:451] ScheduleAlgoTime 7.893246ms Start:2018-08-31 12:54:01.794722283 +0000 UTC m=+204.465344442 End:2018-08-31 12:54:01.802615569 +0000 UTC m=+204.473237688
I0831 12:54:01.827894       1 scheduler.go:454] Total Schedule Algo cumulative time:395.897937ms for 219
I0831 12:54:01.835527       1 scheduler.go:451] ScheduleAlgoTime 7.478077ms Start:2018-08-31 12:54:01.828040864 +0000 UTC m=+204.498662984 End:2018-08-31 12:54:01.835518941 +0000 UTC m=+204.506141061
I0831 12:54:01.835589       1 scheduler.go:454] Total Schedule Algo cumulative time:403.376014ms for 220
I0831 12:54:01.842302       1 scheduler.go:451] ScheduleAlgoTime 6.574937ms Start:2018-08-31 12:54:01.835719083 +0000 UTC m=+204.506341232 End:2018-08-31 12:54:01.84229405 +0000 UTC m=+204.512916169
I0831 12:54:01.842347       1 scheduler.go:454] Total Schedule Algo cumulative time:409.950951ms for 221
I0831 12:54:01.850217       1 scheduler.go:451] ScheduleAlgoTime 7.766137ms Start:2018-08-31 12:54:01.842441651 +0000 UTC m=+204.513063824 End:2018-08-31 12:54:01.85020784 +0000 UTC m=+204.520829961
I0831 12:54:01.850265       1 scheduler.go:454] Total Schedule Algo cumulative time:417.717088ms for 222
I0831 12:54:01.857569       1 scheduler.go:451] ScheduleAlgoTime 7.151009ms Start:2018-08-31 12:54:01.850409747 +0000 UTC m=+204.521031881 End:2018-08-31 12:54:01.857560771 +0000 UTC m=+204.528182890
I0831 12:54:01.857612       1 scheduler.go:454] Total Schedule Algo cumulative time:424.868097ms for 223
I0831 12:54:01.869467       1 scheduler.go:451] ScheduleAlgoTime 11.580638ms Start:2018-08-31 12:54:01.857876658 +0000 UTC m=+204.528498803 End:2018-08-31 12:54:01.869457322 +0000 UTC m=+204.540079441
I0831 12:54:01.869516       1 scheduler.go:454] Total Schedule Algo cumulative time:436.448735ms for 224
I0831 12:54:01.876999       1 scheduler.go:451] ScheduleAlgoTime 7.396516ms Start:2018-08-31 12:54:01.869594334 +0000 UTC m=+204.540216468 End:2018-08-31 12:54:01.876990866 +0000 UTC m=+204.547612984
I0831 12:54:01.877054       1 scheduler.go:454] Total Schedule Algo cumulative time:443.845251ms for 225
I0831 12:54:01.884630       1 scheduler.go:451] ScheduleAlgoTime 7.482617ms Start:2018-08-31 12:54:01.877139253 +0000 UTC m=+204.547761401 End:2018-08-31 12:54:01.884621898 +0000 UTC m=+204.555244018
I0831 12:54:01.884675       1 scheduler.go:454] Total Schedule Algo cumulative time:451.327868ms for 226
I0831 12:54:01.892359       1 scheduler.go:451] ScheduleAlgoTime 7.586681ms Start:2018-08-31 12:54:01.884761424 +0000 UTC m=+204.555383560 End:2018-08-31 12:54:01.892348121 +0000 UTC m=+204.562970241
I0831 12:54:01.892395       1 scheduler.go:454] Total Schedule Algo cumulative time:458.914549ms for 227
I0831 12:54:01.899756       1 scheduler.go:451] ScheduleAlgoTime 7.258167ms Start:2018-08-31 12:54:01.892490483 +0000 UTC m=+204.563112726 End:2018-08-31 12:54:01.899748774 +0000 UTC m=+204.570370893
I0831 12:54:01.899799       1 scheduler.go:454] Total Schedule Algo cumulative time:466.172716ms for 228
I0831 12:54:01.908502       1 scheduler.go:451] ScheduleAlgoTime 8.608998ms Start:2018-08-31 12:54:01.899879746 +0000 UTC m=+204.570501899 End:2018-08-31 12:54:01.908488728 +0000 UTC m=+204.579110897
I0831 12:54:01.908559       1 scheduler.go:454] Total Schedule Algo cumulative time:474.781714ms for 229
I0831 12:54:01.916021       1 scheduler.go:451] ScheduleAlgoTime 7.346978ms Start:2018-08-31 12:54:01.908660942 +0000 UTC m=+204.579283079 End:2018-08-31 12:54:01.916007846 +0000 UTC m=+204.586630057
I0831 12:54:01.916073       1 scheduler.go:454] Total Schedule Algo cumulative time:482.128692ms for 230
I0831 12:54:01.926239       1 scheduler.go:451] ScheduleAlgoTime 9.809832ms Start:2018-08-31 12:54:01.916421068 +0000 UTC m=+204.587043232 End:2018-08-31 12:54:01.926230943 +0000 UTC m=+204.596853064
I0831 12:54:01.926281       1 scheduler.go:454] Total Schedule Algo cumulative time:491.938524ms for 231
I0831 12:54:01.936219       1 scheduler.go:451] ScheduleAlgoTime 9.835723ms Start:2018-08-31 12:54:01.926365864 +0000 UTC m=+204.596988071 End:2018-08-31 12:54:01.936201531 +0000 UTC m=+204.606823794
I0831 12:54:01.936292       1 scheduler.go:454] Total Schedule Algo cumulative time:501.774247ms for 232
I0831 12:54:01.944967       1 scheduler.go:451] ScheduleAlgoTime 8.553684ms Start:2018-08-31 12:54:01.936407508 +0000 UTC m=+204.607029657 End:2018-08-31 12:54:01.944961222 +0000 UTC m=+204.615583341
I0831 12:54:01.945006       1 scheduler.go:454] Total Schedule Algo cumulative time:510.327931ms for 233
I0831 12:54:01.953955       1 scheduler.go:451] ScheduleAlgoTime 8.859365ms Start:2018-08-31 12:54:01.945083039 +0000 UTC m=+204.615705193 End:2018-08-31 12:54:01.953942345 +0000 UTC m=+204.624564558
I0831 12:54:01.954007       1 scheduler.go:454] Total Schedule Algo cumulative time:519.187296ms for 234
I0831 12:54:01.968221       1 scheduler.go:451] ScheduleAlgoTime 14.062701ms Start:2018-08-31 12:54:01.954149724 +0000 UTC m=+204.624771870 End:2018-08-31 12:54:01.968212448 +0000 UTC m=+204.638834571
I0831 12:54:01.968265       1 scheduler.go:454] Total Schedule Algo cumulative time:533.249997ms for 235
I0831 12:54:01.979436       1 scheduler.go:451] ScheduleAlgoTime 11.04329ms Start:2018-08-31 12:54:01.968382664 +0000 UTC m=+204.639004823 End:2018-08-31 12:54:01.979425994 +0000 UTC m=+204.650048113
I0831 12:54:02.653881       1 scheduler.go:454] Total Schedule Algo cumulative time:544.293287ms for 236
I0831 12:54:02.665337       1 scheduler.go:451] ScheduleAlgoTime 11.251459ms Start:2018-08-31 12:54:02.654070905 +0000 UTC m=+205.324693057 End:2018-08-31 12:54:02.665322393 +0000 UTC m=+205.335944516
I0831 12:54:02.665428       1 scheduler.go:454] Total Schedule Algo cumulative time:555.544746ms for 237
I0831 12:54:02.675208       1 scheduler.go:451] ScheduleAlgoTime 9.658046ms Start:2018-08-31 12:54:02.665544064 +0000 UTC m=+205.336166214 End:2018-08-31 12:54:02.675202143 +0000 UTC m=+205.345824260
I0831 12:54:02.675248       1 scheduler.go:454] Total Schedule Algo cumulative time:565.202792ms for 238
I0831 12:54:02.683211       1 scheduler.go:451] ScheduleAlgoTime 7.881495ms Start:2018-08-31 12:54:02.675322207 +0000 UTC m=+205.345944378 End:2018-08-31 12:54:02.683203753 +0000 UTC m=+205.353825873
I0831 12:54:02.683254       1 scheduler.go:454] Total Schedule Algo cumulative time:573.084287ms for 239
I0831 12:54:02.692955       1 scheduler.go:451] ScheduleAlgoTime 9.577671ms Start:2018-08-31 12:54:02.683372223 +0000 UTC m=+205.353994364 End:2018-08-31 12:54:02.692949915 +0000 UTC m=+205.363572035
I0831 12:54:02.692998       1 scheduler.go:454] Total Schedule Algo cumulative time:582.661958ms for 240
I0831 12:54:02.701807       1 scheduler.go:451] ScheduleAlgoTime 8.679376ms Start:2018-08-31 12:54:02.693121315 +0000 UTC m=+205.363743499 End:2018-08-31 12:54:02.701800754 +0000 UTC m=+205.372422875
I0831 12:54:02.701844       1 scheduler.go:454] Total Schedule Algo cumulative time:591.341334ms for 241
I0831 12:54:02.710091       1 scheduler.go:451] ScheduleAlgoTime 8.146438ms Start:2018-08-31 12:54:02.701933316 +0000 UTC m=+205.372555471 End:2018-08-31 12:54:02.710079788 +0000 UTC m=+205.380701909
I0831 12:54:02.990225       1 scheduler.go:454] Total Schedule Algo cumulative time:599.487772ms for 242
I0831 12:54:03.000939       1 scheduler.go:451] ScheduleAlgoTime 10.550712ms Start:2018-08-31 12:54:02.990378574 +0000 UTC m=+205.661000780 End:2018-08-31 12:54:03.000929339 +0000 UTC m=+205.671551492
I0831 12:54:03.000994       1 scheduler.go:454] Total Schedule Algo cumulative time:610.038484ms for 243
I0831 12:54:03.011757       1 scheduler.go:451] ScheduleAlgoTime 10.60613ms Start:2018-08-31 12:54:03.001109668 +0000 UTC m=+205.671731823 End:2018-08-31 12:54:03.01171583 +0000 UTC m=+205.682337953
I0831 12:54:03.011813       1 scheduler.go:454] Total Schedule Algo cumulative time:620.644614ms for 244
I0831 12:54:03.021567       1 scheduler.go:451] ScheduleAlgoTime 9.636506ms Start:2018-08-31 12:54:03.011920878 +0000 UTC m=+205.682543042 End:2018-08-31 12:54:03.021557379 +0000 UTC m=+205.692179548
I0831 12:54:03.021613       1 scheduler.go:454] Total Schedule Algo cumulative time:630.28112ms for 245
I0831 12:54:03.034195       1 scheduler.go:451] ScheduleAlgoTime 12.462196ms Start:2018-08-31 12:54:03.02172515 +0000 UTC m=+205.692347288 End:2018-08-31 12:54:03.034187364 +0000 UTC m=+205.704809484
I0831 12:54:03.034228       1 scheduler.go:454] Total Schedule Algo cumulative time:642.743316ms for 246
I0831 12:54:03.041743       1 scheduler.go:451] ScheduleAlgoTime 7.413262ms Start:2018-08-31 12:54:03.034324582 +0000 UTC m=+205.704946750 End:2018-08-31 12:54:03.041737891 +0000 UTC m=+205.712360012
I0831 12:54:03.041776       1 scheduler.go:454] Total Schedule Algo cumulative time:650.156578ms for 247
I0831 12:54:03.050358       1 scheduler.go:451] ScheduleAlgoTime 8.456149ms Start:2018-08-31 12:54:03.04189556 +0000 UTC m=+205.712517714 End:2018-08-31 12:54:03.050351745 +0000 UTC m=+205.720973863
I0831 12:54:03.050388       1 scheduler.go:454] Total Schedule Algo cumulative time:658.612727ms for 248
I0831 12:54:03.057361       1 scheduler.go:451] ScheduleAlgoTime 6.890329ms Start:2018-08-31 12:54:03.05046574 +0000 UTC m=+205.721087917 End:2018-08-31 12:54:03.057356127 +0000 UTC m=+205.727978246
I0831 12:54:03.057396       1 scheduler.go:454] Total Schedule Algo cumulative time:665.503056ms for 249
I0831 12:54:03.065111       1 scheduler.go:451] ScheduleAlgoTime 7.617458ms Start:2018-08-31 12:54:03.057487787 +0000 UTC m=+205.728109934 End:2018-08-31 12:54:03.065105273 +0000 UTC m=+205.735727392
I0831 12:54:03.065139       1 scheduler.go:454] Total Schedule Algo cumulative time:673.120514ms for 250
I0831 12:54:03.073365       1 scheduler.go:451] ScheduleAlgoTime 8.136125ms Start:2018-08-31 12:54:03.065222627 +0000 UTC m=+205.735844781 End:2018-08-31 12:54:03.073358786 +0000 UTC m=+205.743980906
I0831 12:54:03.073399       1 scheduler.go:454] Total Schedule Algo cumulative time:681.256639ms for 251
I0831 12:54:03.082341       1 scheduler.go:451] ScheduleAlgoTime 8.855199ms Start:2018-08-31 12:54:03.073479747 +0000 UTC m=+205.744101919 End:2018-08-31 12:54:03.082334996 +0000 UTC m=+205.752957118
I0831 12:54:03.082373       1 scheduler.go:454] Total Schedule Algo cumulative time:690.111838ms for 252
I0831 12:54:03.090144       1 scheduler.go:451] ScheduleAlgoTime 7.601885ms Start:2018-08-31 12:54:03.08253431 +0000 UTC m=+205.753156523 End:2018-08-31 12:54:03.090136279 +0000 UTC m=+205.760758408
I0831 12:54:03.090180       1 scheduler.go:454] Total Schedule Algo cumulative time:697.713723ms for 253
I0831 12:54:03.097961       1 scheduler.go:451] ScheduleAlgoTime 7.712027ms Start:2018-08-31 12:54:03.09024258 +0000 UTC m=+205.760864732 End:2018-08-31 12:54:03.09795464 +0000 UTC m=+205.768576759
I0831 12:54:03.097989       1 scheduler.go:454] Total Schedule Algo cumulative time:705.42575ms for 254
I0831 12:54:03.105861       1 scheduler.go:451] ScheduleAlgoTime 7.777834ms Start:2018-08-31 12:54:03.098078187 +0000 UTC m=+205.768700333 End:2018-08-31 12:54:03.105856048 +0000 UTC m=+205.776478167
I0831 12:54:03.105888       1 scheduler.go:454] Total Schedule Algo cumulative time:713.203584ms for 255
I0831 12:54:03.113481       1 scheduler.go:451] ScheduleAlgoTime 7.510359ms Start:2018-08-31 12:54:03.105966057 +0000 UTC m=+205.776588210 End:2018-08-31 12:54:03.113476444 +0000 UTC m=+205.784098569
I0831 12:54:03.113516       1 scheduler.go:454] Total Schedule Algo cumulative time:720.713943ms for 256
I0831 12:54:03.123870       1 scheduler.go:451] ScheduleAlgoTime 10.266403ms Start:2018-08-31 12:54:03.113597241 +0000 UTC m=+205.784219396 End:2018-08-31 12:54:03.12386368 +0000 UTC m=+205.794485799
I0831 12:54:03.123902       1 scheduler.go:454] Total Schedule Algo cumulative time:730.980346ms for 257
I0831 12:54:03.131077       1 scheduler.go:451] ScheduleAlgoTime 7.085317ms Start:2018-08-31 12:54:03.12398654 +0000 UTC m=+205.794608709 End:2018-08-31 12:54:03.131071907 +0000 UTC m=+205.801694026
I0831 12:54:03.131108       1 scheduler.go:454] Total Schedule Algo cumulative time:738.065663ms for 258
I0831 12:54:03.138102       1 scheduler.go:451] ScheduleAlgoTime 6.920622ms Start:2018-08-31 12:54:03.131176991 +0000 UTC m=+205.801799141 End:2018-08-31 12:54:03.138097644 +0000 UTC m=+205.808719763
I0831 12:54:03.138132       1 scheduler.go:454] Total Schedule Algo cumulative time:744.986285ms for 259
I0831 12:54:03.145661       1 scheduler.go:451] ScheduleAlgoTime 7.445043ms Start:2018-08-31 12:54:03.138211588 +0000 UTC m=+205.808833757 End:2018-08-31 12:54:03.145656681 +0000 UTC m=+205.816278800
I0831 12:54:03.145699       1 scheduler.go:454] Total Schedule Algo cumulative time:752.431328ms for 260
I0831 12:54:03.153912       1 scheduler.go:451] ScheduleAlgoTime 8.135885ms Start:2018-08-31 12:54:03.145770309 +0000 UTC m=+205.816392462 End:2018-08-31 12:54:03.15390623 +0000 UTC m=+205.824528347
I0831 12:54:03.153949       1 scheduler.go:454] Total Schedule Algo cumulative time:760.567213ms for 261
I0831 12:54:03.161823       1 scheduler.go:451] ScheduleAlgoTime 7.794993ms Start:2018-08-31 12:54:03.1540232 +0000 UTC m=+205.824645336 End:2018-08-31 12:54:03.16181821 +0000 UTC m=+205.832440329
I0831 12:54:03.161850       1 scheduler.go:454] Total Schedule Algo cumulative time:768.362206ms for 262
I0831 12:54:03.169243       1 scheduler.go:451] ScheduleAlgoTime 7.319657ms Start:2018-08-31 12:54:03.161917759 +0000 UTC m=+205.832539913 End:2018-08-31 12:54:03.169237447 +0000 UTC m=+205.839859570
I0831 12:54:03.169270       1 scheduler.go:454] Total Schedule Algo cumulative time:775.681863ms for 263
I0831 12:54:03.176504       1 scheduler.go:451] ScheduleAlgoTime 7.160631ms Start:2018-08-31 12:54:03.169339096 +0000 UTC m=+205.839961239 End:2018-08-31 12:54:03.17649975 +0000 UTC m=+205.847121870
I0831 12:54:03.176544       1 scheduler.go:454] Total Schedule Algo cumulative time:782.842494ms for 264
I0831 12:54:03.183828       1 scheduler.go:451] ScheduleAlgoTime 7.216465ms Start:2018-08-31 12:54:03.176606969 +0000 UTC m=+205.847229129 End:2018-08-31 12:54:03.183823472 +0000 UTC m=+205.854445594
I0831 12:54:03.183856       1 scheduler.go:454] Total Schedule Algo cumulative time:790.058959ms for 265
I0831 12:54:03.192192       1 scheduler.go:451] ScheduleAlgoTime 8.259162ms Start:2018-08-31 12:54:03.183921422 +0000 UTC m=+205.854543578 End:2018-08-31 12:54:03.192180606 +0000 UTC m=+205.862802740
I0831 12:54:03.192231       1 scheduler.go:454] Total Schedule Algo cumulative time:798.318121ms for 266
I0831 12:54:03.200206       1 scheduler.go:451] ScheduleAlgoTime 7.849112ms Start:2018-08-31 12:54:03.192350626 +0000 UTC m=+205.862972784 End:2018-08-31 12:54:03.200199775 +0000 UTC m=+205.870821896
I0831 12:54:03.200279       1 scheduler.go:454] Total Schedule Algo cumulative time:806.167233ms for 267
I0831 12:54:03.209632       1 scheduler.go:451] ScheduleAlgoTime 9.217889ms Start:2018-08-31 12:54:03.200407038 +0000 UTC m=+205.871029184 End:2018-08-31 12:54:03.209624953 +0000 UTC m=+205.880247073
I0831 12:54:03.209663       1 scheduler.go:454] Total Schedule Algo cumulative time:815.385122ms for 268
I0831 12:54:03.217147       1 scheduler.go:451] ScheduleAlgoTime 7.372747ms Start:2018-08-31 12:54:03.209767963 +0000 UTC m=+205.880390131 End:2018-08-31 12:54:03.21714076 +0000 UTC m=+205.887762878
I0831 12:54:03.217177       1 scheduler.go:454] Total Schedule Algo cumulative time:822.757869ms for 269
I0831 12:54:03.225085       1 scheduler.go:451] ScheduleAlgoTime 7.817821ms Start:2018-08-31 12:54:03.217262216 +0000 UTC m=+205.887884369 End:2018-08-31 12:54:03.225080071 +0000 UTC m=+205.895702190
I0831 12:54:03.225126       1 scheduler.go:454] Total Schedule Algo cumulative time:830.57569ms for 270
I0831 12:54:03.233642       1 scheduler.go:451] ScheduleAlgoTime 8.399867ms Start:2018-08-31 12:54:03.225236351 +0000 UTC m=+205.895858497 End:2018-08-31 12:54:03.233636244 +0000 UTC m=+205.904258364
I0831 12:54:03.233675       1 scheduler.go:454] Total Schedule Algo cumulative time:838.975557ms for 271
I0831 12:54:03.240874       1 scheduler.go:451] ScheduleAlgoTime 7.107448ms Start:2018-08-31 12:54:03.233761413 +0000 UTC m=+205.904383595 End:2018-08-31 12:54:03.240868925 +0000 UTC m=+205.911491043
I0831 12:54:03.240906       1 scheduler.go:454] Total Schedule Algo cumulative time:846.083005ms for 272
I0831 12:54:03.248442       1 scheduler.go:451] ScheduleAlgoTime 7.432879ms Start:2018-08-31 12:54:03.241003384 +0000 UTC m=+205.911625548 End:2018-08-31 12:54:03.248436304 +0000 UTC m=+205.919058427
I0831 12:54:03.248482       1 scheduler.go:454] Total Schedule Algo cumulative time:853.515884ms for 273
I0831 12:54:03.255939       1 scheduler.go:451] ScheduleAlgoTime 7.346463ms Start:2018-08-31 12:54:03.248587235 +0000 UTC m=+205.919209382 End:2018-08-31 12:54:03.255933725 +0000 UTC m=+205.926555845
I0831 12:54:03.255967       1 scheduler.go:454] Total Schedule Algo cumulative time:860.862347ms for 274
I0831 12:54:03.264263       1 scheduler.go:451] ScheduleAlgoTime 8.186445ms Start:2018-08-31 12:54:03.256069622 +0000 UTC m=+205.926691775 End:2018-08-31 12:54:03.26425574 +0000 UTC m=+205.934878220
I0831 12:54:03.264291       1 scheduler.go:454] Total Schedule Algo cumulative time:869.048792ms for 275
I0831 12:54:03.272495       1 scheduler.go:451] ScheduleAlgoTime 8.103126ms Start:2018-08-31 12:54:03.264386435 +0000 UTC m=+205.935008594 End:2018-08-31 12:54:03.2724896 +0000 UTC m=+205.943111720
I0831 12:54:03.272524       1 scheduler.go:454] Total Schedule Algo cumulative time:877.151918ms for 276
I0831 12:54:03.281811       1 scheduler.go:451] ScheduleAlgoTime 9.180884ms Start:2018-08-31 12:54:03.272621025 +0000 UTC m=+205.943243173 End:2018-08-31 12:54:03.281801937 +0000 UTC m=+205.952424057
I0831 12:54:03.281849       1 scheduler.go:454] Total Schedule Algo cumulative time:886.332802ms for 277
I0831 12:54:03.292754       1 scheduler.go:451] ScheduleAlgoTime 10.768883ms Start:2018-08-31 12:54:03.281975283 +0000 UTC m=+205.952597443 End:2018-08-31 12:54:03.292744207 +0000 UTC m=+205.963366326
I0831 12:54:03.292792       1 scheduler.go:454] Total Schedule Algo cumulative time:897.101685ms for 278
I0831 12:54:03.308539       1 scheduler.go:451] ScheduleAlgoTime 15.655184ms Start:2018-08-31 12:54:03.292873828 +0000 UTC m=+205.963495982 End:2018-08-31 12:54:03.308529045 +0000 UTC m=+205.979151166
I0831 12:54:03.308577       1 scheduler.go:454] Total Schedule Algo cumulative time:912.756869ms for 279
I0831 12:54:03.317709       1 scheduler.go:451] ScheduleAlgoTime 9.026457ms Start:2018-08-31 12:54:03.308675959 +0000 UTC m=+205.979298143 End:2018-08-31 12:54:03.317702482 +0000 UTC m=+205.988324600
I0831 12:54:03.361065       1 scheduler.go:454] Total Schedule Algo cumulative time:921.783326ms for 280
I0831 12:54:03.372727       1 scheduler.go:451] ScheduleAlgoTime 11.543809ms Start:2018-08-31 12:54:03.361173053 +0000 UTC m=+206.031795186 End:2018-08-31 12:54:03.372716873 +0000 UTC m=+206.043338995
I0831 12:54:03.372771       1 scheduler.go:454] Total Schedule Algo cumulative time:933.327135ms for 281
I0831 12:54:03.382423       1 scheduler.go:451] ScheduleAlgoTime 9.504416ms Start:2018-08-31 12:54:03.372910672 +0000 UTC m=+206.043532816 End:2018-08-31 12:54:03.382415108 +0000 UTC m=+206.053037232
I0831 12:54:03.382475       1 scheduler.go:454] Total Schedule Algo cumulative time:942.831551ms for 282
I0831 12:54:03.391252       1 scheduler.go:451] ScheduleAlgoTime 8.662669ms Start:2018-08-31 12:54:03.382581543 +0000 UTC m=+206.053203744 End:2018-08-31 12:54:03.391244293 +0000 UTC m=+206.061866413
I0831 12:54:03.391297       1 scheduler.go:454] Total Schedule Algo cumulative time:951.49422ms for 283
I0831 12:54:03.400438       1 scheduler.go:451] ScheduleAlgoTime 9.041534ms Start:2018-08-31 12:54:03.391385803 +0000 UTC m=+206.062007949 End:2018-08-31 12:54:03.400427329 +0000 UTC m=+206.071049483
I0831 12:54:03.400500       1 scheduler.go:454] Total Schedule Algo cumulative time:960.535754ms for 284
I0831 12:54:03.407917       1 scheduler.go:451] ScheduleAlgoTime 7.292982ms Start:2018-08-31 12:54:03.400616562 +0000 UTC m=+206.071238714 End:2018-08-31 12:54:03.407909577 +0000 UTC m=+206.078531696
I0831 12:54:03.407949       1 scheduler.go:454] Total Schedule Algo cumulative time:967.828736ms for 285
I0831 12:54:03.415707       1 scheduler.go:451] ScheduleAlgoTime 7.650145ms Start:2018-08-31 12:54:03.4080522 +0000 UTC m=+206.078674349 End:2018-08-31 12:54:03.415702372 +0000 UTC m=+206.086324494
I0831 12:54:03.415740       1 scheduler.go:454] Total Schedule Algo cumulative time:975.478881ms for 286
I0831 12:54:03.423201       1 scheduler.go:451] ScheduleAlgoTime 7.355865ms Start:2018-08-31 12:54:03.415839935 +0000 UTC m=+206.086462103 End:2018-08-31 12:54:03.423195846 +0000 UTC m=+206.093817968
I0831 12:54:03.423229       1 scheduler.go:454] Total Schedule Algo cumulative time:982.834746ms for 287
I0831 12:54:03.430361       1 scheduler.go:451] ScheduleAlgoTime 7.041753ms Start:2018-08-31 12:54:03.423314643 +0000 UTC m=+206.093936796 End:2018-08-31 12:54:03.430356426 +0000 UTC m=+206.100978549
I0831 12:54:03.430387       1 scheduler.go:454] Total Schedule Algo cumulative time:989.876499ms for 288
I0831 12:54:03.437350       1 scheduler.go:451] ScheduleAlgoTime 6.864234ms Start:2018-08-31 12:54:03.430481038 +0000 UTC m=+206.101103190 End:2018-08-31 12:54:03.437345301 +0000 UTC m=+206.107967424
I0831 12:54:03.437382       1 scheduler.go:454] Total Schedule Algo cumulative time:996.740733ms for 289
I0831 12:54:03.447341       1 scheduler.go:451] ScheduleAlgoTime 9.847957ms Start:2018-08-31 12:54:03.437487623 +0000 UTC m=+206.108109770 End:2018-08-31 12:54:03.447335607 +0000 UTC m=+206.117957727
I0831 12:54:03.447376       1 scheduler.go:454] Total Schedule Algo cumulative time:1.00658869s for 290
I0831 12:54:03.454512       1 scheduler.go:451] ScheduleAlgoTime 7.010051ms Start:2018-08-31 12:54:03.447497588 +0000 UTC m=+206.118119726 End:2018-08-31 12:54:03.454507656 +0000 UTC m=+206.125129777
I0831 12:54:03.454548       1 scheduler.go:454] Total Schedule Algo cumulative time:1.013598741s for 291
I0831 12:54:03.462160       1 scheduler.go:451] ScheduleAlgoTime 7.484911ms Start:2018-08-31 12:54:03.454668675 +0000 UTC m=+206.125290826 End:2018-08-31 12:54:03.462153614 +0000 UTC m=+206.132775737
I0831 12:54:03.462196       1 scheduler.go:454] Total Schedule Algo cumulative time:1.021083652s for 292
I0831 12:54:03.469279       1 scheduler.go:451] ScheduleAlgoTime 6.984092ms Start:2018-08-31 12:54:03.462289474 +0000 UTC m=+206.132911617 End:2018-08-31 12:54:03.469273591 +0000 UTC m=+206.139895709
I0831 12:54:03.469309       1 scheduler.go:454] Total Schedule Algo cumulative time:1.028067744s for 293
I0831 12:54:03.476467       1 scheduler.go:451] ScheduleAlgoTime 7.058164ms Start:2018-08-31 12:54:03.469403322 +0000 UTC m=+206.140025475 End:2018-08-31 12:54:03.47646152 +0000 UTC m=+206.147083639
I0831 12:54:03.476510       1 scheduler.go:454] Total Schedule Algo cumulative time:1.035125908s for 294
I0831 12:54:03.483799       1 scheduler.go:451] ScheduleAlgoTime 7.191412ms Start:2018-08-31 12:54:03.476602066 +0000 UTC m=+206.147224201 End:2018-08-31 12:54:03.483793495 +0000 UTC m=+206.154415613
I0831 12:54:03.483827       1 scheduler.go:454] Total Schedule Algo cumulative time:1.04231732s for 295
I0831 12:54:03.490770       1 scheduler.go:451] ScheduleAlgoTime 6.867857ms Start:2018-08-31 12:54:03.483896859 +0000 UTC m=+206.154519015 End:2018-08-31 12:54:03.490764752 +0000 UTC m=+206.161386872
I0831 12:54:03.490795       1 scheduler.go:454] Total Schedule Algo cumulative time:1.049185177s for 296
I0831 12:54:03.498144       1 scheduler.go:451] ScheduleAlgoTime 7.219392ms Start:2018-08-31 12:54:03.49091917 +0000 UTC m=+206.161541326 End:2018-08-31 12:54:03.498138599 +0000 UTC m=+206.168760718
I0831 12:54:03.498179       1 scheduler.go:454] Total Schedule Algo cumulative time:1.056404569s for 297
I0831 12:54:03.505199       1 scheduler.go:451] ScheduleAlgoTime 6.935286ms Start:2018-08-31 12:54:03.498259224 +0000 UTC m=+206.168881393 End:2018-08-31 12:54:03.505194558 +0000 UTC m=+206.175816679
I0831 12:54:03.505225       1 scheduler.go:454] Total Schedule Algo cumulative time:1.063339855s for 298
I0831 12:54:03.512350       1 scheduler.go:451] ScheduleAlgoTime 7.031255ms Start:2018-08-31 12:54:03.50531264 +0000 UTC m=+206.175934785 End:2018-08-31 12:54:03.512343912 +0000 UTC m=+206.182966040
I0831 12:54:03.512383       1 scheduler.go:454] Total Schedule Algo cumulative time:1.07037111s for 299
I0831 12:54:03.519487       1 scheduler.go:451] ScheduleAlgoTime 6.981465ms Start:2018-08-31 12:54:03.512500835 +0000 UTC m=+206.183122984 End:2018-08-31 12:54:03.519482331 +0000 UTC m=+206.190104449
I0831 12:54:03.519525       1 scheduler.go:454] Total Schedule Algo cumulative time:1.077352575s for 300
I0831 12:54:03.529103       1 scheduler.go:451] ScheduleAlgoTime 9.497581ms Start:2018-08-31 12:54:03.519601017 +0000 UTC m=+206.190223166 End:2018-08-31 12:54:03.529098624 +0000 UTC m=+206.199720747
I0831 12:54:03.529137       1 scheduler.go:454] Total Schedule Algo cumulative time:1.086850156s for 301
I0831 12:54:03.537172       1 scheduler.go:451] ScheduleAlgoTime 7.941316ms Start:2018-08-31 12:54:03.529224856 +0000 UTC m=+206.199847016 End:2018-08-31 12:54:03.537166211 +0000 UTC m=+206.207788332
I0831 12:54:03.537210       1 scheduler.go:454] Total Schedule Algo cumulative time:1.094791472s for 302
I0831 12:54:03.545370       1 scheduler.go:451] ScheduleAlgoTime 8.06425ms Start:2018-08-31 12:54:03.53729717 +0000 UTC m=+206.207919311 End:2018-08-31 12:54:03.545361433 +0000 UTC m=+206.215983561
I0831 12:54:03.545419       1 scheduler.go:454] Total Schedule Algo cumulative time:1.102855722s for 303
I0831 12:54:03.554302       1 scheduler.go:451] ScheduleAlgoTime 8.741546ms Start:2018-08-31 12:54:03.545555892 +0000 UTC m=+206.216178044 End:2018-08-31 12:54:03.554297471 +0000 UTC m=+206.224919590
I0831 12:54:03.554335       1 scheduler.go:454] Total Schedule Algo cumulative time:1.111597268s for 304
I0831 12:54:03.561901       1 scheduler.go:451] ScheduleAlgoTime 7.483029ms Start:2018-08-31 12:54:03.554411849 +0000 UTC m=+206.225034042 End:2018-08-31 12:54:03.561894947 +0000 UTC m=+206.232517071
I0831 12:54:03.561934       1 scheduler.go:454] Total Schedule Algo cumulative time:1.119080297s for 305
I0831 12:54:03.569283       1 scheduler.go:451] ScheduleAlgoTime 7.226231ms Start:2018-08-31 12:54:03.562049383 +0000 UTC m=+206.232671535 End:2018-08-31 12:54:03.569275648 +0000 UTC m=+206.239897766
I0831 12:54:03.569317       1 scheduler.go:454] Total Schedule Algo cumulative time:1.126306528s for 306
I0831 12:54:03.577230       1 scheduler.go:451] ScheduleAlgoTime 7.818651ms Start:2018-08-31 12:54:03.569404645 +0000 UTC m=+206.240026812 End:2018-08-31 12:54:03.577223345 +0000 UTC m=+206.247845463
I0831 12:54:03.577263       1 scheduler.go:454] Total Schedule Algo cumulative time:1.134125179s for 307
I0831 12:54:03.589988       1 scheduler.go:451] ScheduleAlgoTime 12.621013ms Start:2018-08-31 12:54:03.577361881 +0000 UTC m=+206.247984017 End:2018-08-31 12:54:03.589982911 +0000 UTC m=+206.260605030
I0831 12:54:03.590023       1 scheduler.go:454] Total Schedule Algo cumulative time:1.146746192s for 308
I0831 12:54:03.597163       1 scheduler.go:451] ScheduleAlgoTime 7.039739ms Start:2018-08-31 12:54:03.590118637 +0000 UTC m=+206.260740814 End:2018-08-31 12:54:03.59715843 +0000 UTC m=+206.267780553
I0831 12:54:03.597196       1 scheduler.go:454] Total Schedule Algo cumulative time:1.153785931s for 309
I0831 12:54:03.604484       1 scheduler.go:451] ScheduleAlgoTime 7.177984ms Start:2018-08-31 12:54:03.597301045 +0000 UTC m=+206.267923197 End:2018-08-31 12:54:03.604479062 +0000 UTC m=+206.275101181
I0831 12:54:03.604524       1 scheduler.go:454] Total Schedule Algo cumulative time:1.160963915s for 310
I0831 12:54:03.613080       1 scheduler.go:451] ScheduleAlgoTime 8.465743ms Start:2018-08-31 12:54:03.604608982 +0000 UTC m=+206.275231134 End:2018-08-31 12:54:03.613074758 +0000 UTC m=+206.283696877
I0831 12:54:03.613110       1 scheduler.go:454] Total Schedule Algo cumulative time:1.169429658s for 311
I0831 12:54:03.622415       1 scheduler.go:451] ScheduleAlgoTime 9.207408ms Start:2018-08-31 12:54:03.613201087 +0000 UTC m=+206.283823230 End:2018-08-31 12:54:03.622408518 +0000 UTC m=+206.293030638
I0831 12:54:03.622456       1 scheduler.go:454] Total Schedule Algo cumulative time:1.178637066s for 312
I0831 12:54:03.629458       1 scheduler.go:451] ScheduleAlgoTime 6.8957ms Start:2018-08-31 12:54:03.622550639 +0000 UTC m=+206.293172785 End:2018-08-31 12:54:03.629446366 +0000 UTC m=+206.300068485
I0831 12:54:03.629488       1 scheduler.go:454] Total Schedule Algo cumulative time:1.185532766s for 313
I0831 12:54:03.637057       1 scheduler.go:451] ScheduleAlgoTime 7.48236ms Start:2018-08-31 12:54:03.629568592 +0000 UTC m=+206.300190736 End:2018-08-31 12:54:03.637050973 +0000 UTC m=+206.307673096
I0831 12:54:03.637094       1 scheduler.go:454] Total Schedule Algo cumulative time:1.193015126s for 314
I0831 12:54:03.644080       1 scheduler.go:451] ScheduleAlgoTime 6.8863ms Start:2018-08-31 12:54:03.63718775 +0000 UTC m=+206.307809908 End:2018-08-31 12:54:03.644074089 +0000 UTC m=+206.314696208
I0831 12:54:03.644107       1 scheduler.go:454] Total Schedule Algo cumulative time:1.199901426s for 315
I0831 12:54:03.656779       1 scheduler.go:451] ScheduleAlgoTime 12.580811ms Start:2018-08-31 12:54:03.644187044 +0000 UTC m=+206.314809189 End:2018-08-31 12:54:03.656767871 +0000 UTC m=+206.327390000
I0831 12:54:03.802766       1 scheduler.go:454] Total Schedule Algo cumulative time:1.212482237s for 316
I0831 12:54:03.814587       1 scheduler.go:451] ScheduleAlgoTime 11.616522ms Start:2018-08-31 12:54:03.802931034 +0000 UTC m=+206.473553216 End:2018-08-31 12:54:03.814547606 +0000 UTC m=+206.485169738
I0831 12:54:03.814635       1 scheduler.go:454] Total Schedule Algo cumulative time:1.224098759s for 317
I0831 12:54:03.826804       1 scheduler.go:451] ScheduleAlgoTime 12.070402ms Start:2018-08-31 12:54:03.814723423 +0000 UTC m=+206.485345608 End:2018-08-31 12:54:03.82679388 +0000 UTC m=+206.497416010
I0831 12:54:03.994435       1 scheduler.go:454] Total Schedule Algo cumulative time:1.236169161s for 318
I0831 12:54:04.007090       1 scheduler.go:451] ScheduleAlgoTime 12.209221ms Start:2018-08-31 12:54:03.99486832 +0000 UTC m=+206.665490622 End:2018-08-31 12:54:04.007077709 +0000 UTC m=+206.677699843
I0831 12:54:04.007134       1 scheduler.go:454] Total Schedule Algo cumulative time:1.248378382s for 319
I0831 12:54:04.032141       1 scheduler.go:451] ScheduleAlgoTime 24.852713ms Start:2018-08-31 12:54:04.007272521 +0000 UTC m=+206.677894684 End:2018-08-31 12:54:04.032125244 +0000 UTC m=+206.702747397
I0831 12:54:04.145525       1 scheduler.go:454] Total Schedule Algo cumulative time:1.273231095s for 320
I0831 12:54:04.158443       1 scheduler.go:451] ScheduleAlgoTime 12.732914ms Start:2018-08-31 12:54:04.145699146 +0000 UTC m=+206.816321268 End:2018-08-31 12:54:04.158432053 +0000 UTC m=+206.829054182
I0831 12:54:04.158546       1 scheduler.go:454] Total Schedule Algo cumulative time:1.285964009s for 321
I0831 12:54:04.168446       1 scheduler.go:451] ScheduleAlgoTime 9.785705ms Start:2018-08-31 12:54:04.158648523 +0000 UTC m=+206.829270683 End:2018-08-31 12:54:04.168434221 +0000 UTC m=+206.839056388
I0831 12:54:04.300977       1 scheduler.go:454] Total Schedule Algo cumulative time:1.295749714s for 322
I0831 12:54:04.313604       1 scheduler.go:451] ScheduleAlgoTime 12.494273ms Start:2018-08-31 12:54:04.301098618 +0000 UTC m=+206.971720768 End:2018-08-31 12:54:04.313592856 +0000 UTC m=+206.984215041
I0831 12:54:04.313655       1 scheduler.go:454] Total Schedule Algo cumulative time:1.308243987s for 323
I0831 12:54:04.332489       1 scheduler.go:451] ScheduleAlgoTime 17.805276ms Start:2018-08-31 12:54:04.314671747 +0000 UTC m=+206.985294016 End:2018-08-31 12:54:04.332477147 +0000 UTC m=+207.003099292
I0831 12:54:04.378617       1 scheduler.go:454] Total Schedule Algo cumulative time:1.326049263s for 324
I0831 12:54:04.391413       1 scheduler.go:451] ScheduleAlgoTime 12.675469ms Start:2018-08-31 12:54:04.378727161 +0000 UTC m=+207.049349363 End:2018-08-31 12:54:04.391402694 +0000 UTC m=+207.062024832
I0831 12:54:04.391470       1 scheduler.go:454] Total Schedule Algo cumulative time:1.338724732s for 325
I0831 12:54:04.403393       1 scheduler.go:451] ScheduleAlgoTime 11.819046ms Start:2018-08-31 12:54:04.391564118 +0000 UTC m=+207.062186305 End:2018-08-31 12:54:04.403383225 +0000 UTC m=+207.074005351
I0831 12:54:04.403437       1 scheduler.go:454] Total Schedule Algo cumulative time:1.350543778s for 326
I0831 12:54:04.415845       1 scheduler.go:451] ScheduleAlgoTime 12.119211ms Start:2018-08-31 12:54:04.403715534 +0000 UTC m=+207.074337683 End:2018-08-31 12:54:04.415834766 +0000 UTC m=+207.086456894
I0831 12:54:04.415890       1 scheduler.go:454] Total Schedule Algo cumulative time:1.362662989s for 327
I0831 12:54:04.447855       1 scheduler.go:451] ScheduleAlgoTime 30.16815ms Start:2018-08-31 12:54:04.417674299 +0000 UTC m=+207.088296469 End:2018-08-31 12:54:04.447842482 +0000 UTC m=+207.118464619
I0831 12:54:04.447909       1 scheduler.go:454] Total Schedule Algo cumulative time:1.392831139s for 328
I0831 12:54:04.460821       1 scheduler.go:451] ScheduleAlgoTime 12.796763ms Start:2018-08-31 12:54:04.448013496 +0000 UTC m=+207.118635681 End:2018-08-31 12:54:04.460810315 +0000 UTC m=+207.131432444
I0831 12:54:04.513019       1 scheduler.go:454] Total Schedule Algo cumulative time:1.405627902s for 329
I0831 12:54:04.526207       1 scheduler.go:451] ScheduleAlgoTime 12.978818ms Start:2018-08-31 12:54:04.513216197 +0000 UTC m=+207.183838397 End:2018-08-31 12:54:04.526195092 +0000 UTC m=+207.196817215
I0831 12:54:04.526259       1 scheduler.go:454] Total Schedule Algo cumulative time:1.41860672s for 330
I0831 12:54:04.539236       1 scheduler.go:451] ScheduleAlgoTime 12.846623ms Start:2018-08-31 12:54:04.526378069 +0000 UTC m=+207.197000255 End:2018-08-31 12:54:04.539224755 +0000 UTC m=+207.209846878
I0831 12:54:04.551258       1 scheduler.go:454] Total Schedule Algo cumulative time:1.431453343s for 331
I0831 12:54:04.568952       1 scheduler.go:451] ScheduleAlgoTime 17.311583ms Start:2018-08-31 12:54:04.551632586 +0000 UTC m=+207.222254757 End:2018-08-31 12:54:04.56894422 +0000 UTC m=+207.239566340
I0831 12:54:04.568987       1 scheduler.go:454] Total Schedule Algo cumulative time:1.448764926s for 332
I0831 12:54:04.580529       1 scheduler.go:451] ScheduleAlgoTime 11.441556ms Start:2018-08-31 12:54:04.569075218 +0000 UTC m=+207.239697397 End:2018-08-31 12:54:04.580516821 +0000 UTC m=+207.251138953
I0831 12:54:04.580579       1 scheduler.go:454] Total Schedule Algo cumulative time:1.460206482s for 333
I0831 12:54:04.593381       1 scheduler.go:451] ScheduleAlgoTime 12.253729ms Start:2018-08-31 12:54:04.581114066 +0000 UTC m=+207.251736258 End:2018-08-31 12:54:04.593367863 +0000 UTC m=+207.263989987
I0831 12:54:04.593422       1 scheduler.go:454] Total Schedule Algo cumulative time:1.472460211s for 334
I0831 12:54:04.606255       1 scheduler.go:451] ScheduleAlgoTime 12.551817ms Start:2018-08-31 12:54:04.593694167 +0000 UTC m=+207.264316313 End:2018-08-31 12:54:04.606245992 +0000 UTC m=+207.276868130
I0831 12:54:04.606302       1 scheduler.go:454] Total Schedule Algo cumulative time:1.485012028s for 335
I0831 12:54:04.620940       1 scheduler.go:451] ScheduleAlgoTime 14.53369ms Start:2018-08-31 12:54:04.606395597 +0000 UTC m=+207.277017763 End:2018-08-31 12:54:04.620929317 +0000 UTC m=+207.291551453
I0831 12:54:04.620989       1 scheduler.go:454] Total Schedule Algo cumulative time:1.499545718s for 336
I0831 12:54:04.633280       1 scheduler.go:451] ScheduleAlgoTime 12.19476ms Start:2018-08-31 12:54:04.621074618 +0000 UTC m=+207.291696786 End:2018-08-31 12:54:04.633269415 +0000 UTC m=+207.303891546
I0831 12:54:04.633338       1 scheduler.go:454] Total Schedule Algo cumulative time:1.511740478s for 337
I0831 12:54:04.650891       1 scheduler.go:451] ScheduleAlgoTime 16.795355ms Start:2018-08-31 12:54:04.634082989 +0000 UTC m=+207.304705174 End:2018-08-31 12:54:04.650878387 +0000 UTC m=+207.321500529
I0831 12:54:04.650947       1 scheduler.go:454] Total Schedule Algo cumulative time:1.528535833s for 338
I0831 12:54:04.663495       1 scheduler.go:451] ScheduleAlgoTime 12.377758ms Start:2018-08-31 12:54:04.651106559 +0000 UTC m=+207.321728722 End:2018-08-31 12:54:04.663484303 +0000 UTC m=+207.334106480
I0831 12:54:05.016663       1 scheduler.go:454] Total Schedule Algo cumulative time:1.540913591s for 339
I0831 12:54:05.031146       1 scheduler.go:451] ScheduleAlgoTime 14.280729ms Start:2018-08-31 12:54:05.01685607 +0000 UTC m=+207.687478206 End:2018-08-31 12:54:05.031136773 +0000 UTC m=+207.701758935
I0831 12:54:05.084492       1 scheduler.go:454] Total Schedule Algo cumulative time:1.55519432s for 340
I0831 12:54:05.096217       1 scheduler.go:451] ScheduleAlgoTime 11.600386ms Start:2018-08-31 12:54:05.084604624 +0000 UTC m=+207.755226769 End:2018-08-31 12:54:05.096205031 +0000 UTC m=+207.766827155
I0831 12:54:05.096268       1 scheduler.go:454] Total Schedule Algo cumulative time:1.566794706s for 341
I0831 12:54:05.110362       1 scheduler.go:451] ScheduleAlgoTime 13.702271ms Start:2018-08-31 12:54:05.096647742 +0000 UTC m=+207.767269974 End:2018-08-31 12:54:05.110350116 +0000 UTC m=+207.780972245
I0831 12:54:05.363792       1 scheduler.go:454] Total Schedule Algo cumulative time:1.580496977s for 342
I0831 12:54:05.375805       1 scheduler.go:451] ScheduleAlgoTime 11.620843ms Start:2018-08-31 12:54:05.364175822 +0000 UTC m=+208.034797972 End:2018-08-31 12:54:05.375796696 +0000 UTC m=+208.046418815
I0831 12:54:05.375847       1 scheduler.go:454] Total Schedule Algo cumulative time:1.59211782s for 343
I0831 12:54:05.388308       1 scheduler.go:451] ScheduleAlgoTime 12.362545ms Start:2018-08-31 12:54:05.375934671 +0000 UTC m=+208.046556838 End:2018-08-31 12:54:05.388297251 +0000 UTC m=+208.058919383
I0831 12:54:05.654604       1 scheduler.go:454] Total Schedule Algo cumulative time:1.604480365s for 344
I0831 12:54:05.667798       1 scheduler.go:451] ScheduleAlgoTime 13.057287ms Start:2018-08-31 12:54:05.654729386 +0000 UTC m=+208.325351553 End:2018-08-31 12:54:05.66778664 +0000 UTC m=+208.338408840
I0831 12:54:05.667839       1 scheduler.go:454] Total Schedule Algo cumulative time:1.617537652s for 345
I0831 12:54:05.686384       1 scheduler.go:451] ScheduleAlgoTime 18.443588ms Start:2018-08-31 12:54:05.66792978 +0000 UTC m=+208.338551963 End:2018-08-31 12:54:05.686373414 +0000 UTC m=+208.356995551
I0831 12:54:05.711382       1 scheduler.go:454] Total Schedule Algo cumulative time:1.63598124s for 346
I0831 12:54:05.725427       1 scheduler.go:451] ScheduleAlgoTime 13.875676ms Start:2018-08-31 12:54:05.711539028 +0000 UTC m=+208.382161232 End:2018-08-31 12:54:05.725414761 +0000 UTC m=+208.396036908
I0831 12:54:05.725500       1 scheduler.go:454] Total Schedule Algo cumulative time:1.649856916s for 347
I0831 12:54:05.738491       1 scheduler.go:451] ScheduleAlgoTime 12.85436ms Start:2018-08-31 12:54:05.725623324 +0000 UTC m=+208.396245519 End:2018-08-31 12:54:05.738477748 +0000 UTC m=+208.409099879
I0831 12:54:05.738528       1 scheduler.go:454] Total Schedule Algo cumulative time:1.662711276s for 348
I0831 12:54:05.754804       1 scheduler.go:451] ScheduleAlgoTime 16.17268ms Start:2018-08-31 12:54:05.73862241 +0000 UTC m=+208.409244581 End:2018-08-31 12:54:05.754795125 +0000 UTC m=+208.425417261
I0831 12:54:05.754852       1 scheduler.go:454] Total Schedule Algo cumulative time:1.678883956s for 349
I0831 12:54:05.770230       1 scheduler.go:451] ScheduleAlgoTime 14.894ms Start:2018-08-31 12:54:05.755324702 +0000 UTC m=+208.425946862 End:2018-08-31 12:54:05.770218728 +0000 UTC m=+208.440840862
I0831 12:54:05.770282       1 scheduler.go:454] Total Schedule Algo cumulative time:1.693777956s for 350
I0831 12:54:05.785013       1 scheduler.go:451] ScheduleAlgoTime 14.556043ms Start:2018-08-31 12:54:05.770445929 +0000 UTC m=+208.441068074 End:2018-08-31 12:54:05.785001978 +0000 UTC m=+208.455624117
I0831 12:54:05.785054       1 scheduler.go:454] Total Schedule Algo cumulative time:1.708333999s for 351
I0831 12:54:05.797838       1 scheduler.go:451] ScheduleAlgoTime 12.266201ms Start:2018-08-31 12:54:05.785559748 +0000 UTC m=+208.456181924 End:2018-08-31 12:54:05.797826006 +0000 UTC m=+208.468448125
I0831 12:54:05.797883       1 scheduler.go:454] Total Schedule Algo cumulative time:1.7206002s for 352
I0831 12:54:05.813486       1 scheduler.go:451] ScheduleAlgoTime 15.274162ms Start:2018-08-31 12:54:05.798199706 +0000 UTC m=+208.468821839 End:2018-08-31 12:54:05.813473873 +0000 UTC m=+208.484096001
I0831 12:54:05.813540       1 scheduler.go:454] Total Schedule Algo cumulative time:1.735874362s for 353
I0831 12:54:05.838964       1 scheduler.go:451] ScheduleAlgoTime 25.30338ms Start:2018-08-31 12:54:05.813648417 +0000 UTC m=+208.484270596 End:2018-08-31 12:54:05.838951846 +0000 UTC m=+208.509573976
I0831 12:54:05.839015       1 scheduler.go:454] Total Schedule Algo cumulative time:1.761177742s for 354
I0831 12:54:05.855969       1 scheduler.go:451] ScheduleAlgoTime 16.830276ms Start:2018-08-31 12:54:05.839127261 +0000 UTC m=+208.509749413 End:2018-08-31 12:54:05.85595756 +0000 UTC m=+208.526579689
I0831 12:54:05.856026       1 scheduler.go:454] Total Schedule Algo cumulative time:1.778008018s for 355
I0831 12:54:05.871289       1 scheduler.go:451] ScheduleAlgoTime 15.140399ms Start:2018-08-31 12:54:05.856136457 +0000 UTC m=+208.526758602 End:2018-08-31 12:54:05.871276848 +0000 UTC m=+208.541899001
I0831 12:54:05.871340       1 scheduler.go:454] Total Schedule Algo cumulative time:1.793148417s for 356
I0831 12:54:05.895372       1 scheduler.go:451] ScheduleAlgoTime 23.69469ms Start:2018-08-31 12:54:05.87166852 +0000 UTC m=+208.542290740 End:2018-08-31 12:54:05.89536331 +0000 UTC m=+208.565985430
I0831 12:54:06.092415       1 scheduler.go:454] Total Schedule Algo cumulative time:1.816843107s for 357
I0831 12:54:06.110210       1 scheduler.go:451] ScheduleAlgoTime 17.612135ms Start:2018-08-31 12:54:06.092583644 +0000 UTC m=+208.763205812 End:2018-08-31 12:54:06.110195819 +0000 UTC m=+208.780817947
I0831 12:54:06.110269       1 scheduler.go:454] Total Schedule Algo cumulative time:1.834455242s for 358
I0831 12:54:06.128893       1 scheduler.go:451] ScheduleAlgoTime 18.478405ms Start:2018-08-31 12:54:06.110403618 +0000 UTC m=+208.781025819 End:2018-08-31 12:54:06.128882064 +0000 UTC m=+208.799504224
I0831 12:54:06.225491       1 scheduler.go:454] Total Schedule Algo cumulative time:1.852933647s for 359
I0831 12:54:06.238621       1 scheduler.go:451] ScheduleAlgoTime 12.988622ms Start:2018-08-31 12:54:06.225621621 +0000 UTC m=+208.896243784 End:2018-08-31 12:54:06.238610255 +0000 UTC m=+208.909232406
I0831 12:54:06.238672       1 scheduler.go:454] Total Schedule Algo cumulative time:1.865922269s for 360
I0831 12:54:06.255898       1 scheduler.go:451] ScheduleAlgoTime 17.075882ms Start:2018-08-31 12:54:06.238810321 +0000 UTC m=+208.909432512 End:2018-08-31 12:54:06.255886265 +0000 UTC m=+208.926508394
I0831 12:54:06.431214       1 scheduler.go:454] Total Schedule Algo cumulative time:1.882998151s for 361
I0831 12:54:06.447036       1 scheduler.go:451] ScheduleAlgoTime 15.668136ms Start:2018-08-31 12:54:06.43135611 +0000 UTC m=+209.101978268 End:2018-08-31 12:54:06.447024229 +0000 UTC m=+209.117646404
I0831 12:54:06.447098       1 scheduler.go:454] Total Schedule Algo cumulative time:1.898666287s for 362
I0831 12:54:06.467424       1 scheduler.go:451] ScheduleAlgoTime 20.217234ms Start:2018-08-31 12:54:06.44719732 +0000 UTC m=+209.117819490 End:2018-08-31 12:54:06.467414561 +0000 UTC m=+209.138036724
I0831 12:54:06.467482       1 scheduler.go:454] Total Schedule Algo cumulative time:1.918883521s for 363
I0831 12:54:06.483145       1 scheduler.go:451] ScheduleAlgoTime 15.165676ms Start:2018-08-31 12:54:06.467966723 +0000 UTC m=+209.138588845 End:2018-08-31 12:54:06.483132347 +0000 UTC m=+209.153754521
I0831 12:54:06.483199       1 scheduler.go:454] Total Schedule Algo cumulative time:1.934049197s for 364
I0831 12:54:06.496626       1 scheduler.go:451] ScheduleAlgoTime 12.767983ms Start:2018-08-31 12:54:06.483845288 +0000 UTC m=+209.154467459 End:2018-08-31 12:54:06.496613319 +0000 UTC m=+209.167235442
I0831 12:54:06.496661       1 scheduler.go:454] Total Schedule Algo cumulative time:1.94681718s for 365
I0831 12:54:06.508794       1 scheduler.go:451] ScheduleAlgoTime 12.015259ms Start:2018-08-31 12:54:06.496764146 +0000 UTC m=+209.167386306 End:2018-08-31 12:54:06.508779436 +0000 UTC m=+209.179401565
I0831 12:54:06.508857       1 scheduler.go:454] Total Schedule Algo cumulative time:1.958832439s for 366
I0831 12:54:06.529927       1 scheduler.go:451] ScheduleAlgoTime 20.924216ms Start:2018-08-31 12:54:06.50899383 +0000 UTC m=+209.179616027 End:2018-08-31 12:54:06.529918125 +0000 UTC m=+209.200540243
I0831 12:54:06.529966       1 scheduler.go:454] Total Schedule Algo cumulative time:1.979756655s for 367
I0831 12:54:06.541870       1 scheduler.go:451] ScheduleAlgoTime 11.786762ms Start:2018-08-31 12:54:06.530072366 +0000 UTC m=+209.200694519 End:2018-08-31 12:54:06.541859153 +0000 UTC m=+209.212481281
I0831 12:54:06.541914       1 scheduler.go:454] Total Schedule Algo cumulative time:1.991543417s for 368
I0831 12:54:06.551709       1 scheduler.go:451] ScheduleAlgoTime 9.716738ms Start:2018-08-31 12:54:06.54198609 +0000 UTC m=+209.212608244 End:2018-08-31 12:54:06.551702863 +0000 UTC m=+209.222324982
I0831 12:54:06.551748       1 scheduler.go:454] Total Schedule Algo cumulative time:2.001260155s for 369
I0831 12:54:06.561976       1 scheduler.go:451] ScheduleAlgoTime 10.12967ms Start:2018-08-31 12:54:06.551839471 +0000 UTC m=+209.222461617 End:2018-08-31 12:54:06.561969167 +0000 UTC m=+209.232591287
I0831 12:54:06.562007       1 scheduler.go:454] Total Schedule Algo cumulative time:2.011389825s for 370
I0831 12:54:06.571306       1 scheduler.go:451] ScheduleAlgoTime 9.188067ms Start:2018-08-31 12:54:06.562112196 +0000 UTC m=+209.232734365 End:2018-08-31 12:54:06.571300313 +0000 UTC m=+209.241922432
I0831 12:54:06.571341       1 scheduler.go:454] Total Schedule Algo cumulative time:2.020577892s for 371
I0831 12:54:06.581571       1 scheduler.go:451] ScheduleAlgoTime 10.105783ms Start:2018-08-31 12:54:06.571459502 +0000 UTC m=+209.242081643 End:2018-08-31 12:54:06.581565307 +0000 UTC m=+209.252187426
I0831 12:54:06.581604       1 scheduler.go:454] Total Schedule Algo cumulative time:2.030683675s for 372
I0831 12:54:06.591134       1 scheduler.go:451] ScheduleAlgoTime 9.452131ms Start:2018-08-31 12:54:06.58167543 +0000 UTC m=+209.252297611 End:2018-08-31 12:54:06.591127622 +0000 UTC m=+209.261749742
I0831 12:54:06.591168       1 scheduler.go:454] Total Schedule Algo cumulative time:2.040135806s for 373
I0831 12:54:06.601044       1 scheduler.go:451] ScheduleAlgoTime 9.780512ms Start:2018-08-31 12:54:06.591257016 +0000 UTC m=+209.261879198 End:2018-08-31 12:54:06.601037591 +0000 UTC m=+209.271659710
I0831 12:54:06.601083       1 scheduler.go:454] Total Schedule Algo cumulative time:2.049916318s for 374
I0831 12:54:06.611770       1 scheduler.go:451] ScheduleAlgoTime 10.538721ms Start:2018-08-31 12:54:06.601225735 +0000 UTC m=+209.271847898 End:2018-08-31 12:54:06.611764501 +0000 UTC m=+209.282386619
I0831 12:54:06.611800       1 scheduler.go:454] Total Schedule Algo cumulative time:2.060455039s for 375
I0831 12:54:06.621035       1 scheduler.go:451] ScheduleAlgoTime 9.168337ms Start:2018-08-31 12:54:06.611860531 +0000 UTC m=+209.282482672 End:2018-08-31 12:54:06.621028891 +0000 UTC m=+209.291651009
I0831 12:54:06.621066       1 scheduler.go:454] Total Schedule Algo cumulative time:2.069623376s for 376
I0831 12:54:06.630672       1 scheduler.go:451] ScheduleAlgoTime 9.517256ms Start:2018-08-31 12:54:06.621146275 +0000 UTC m=+209.291768420 End:2018-08-31 12:54:06.630663549 +0000 UTC m=+209.301285676
I0831 12:54:06.630715       1 scheduler.go:454] Total Schedule Algo cumulative time:2.079140632s for 377
I0831 12:54:06.640279       1 scheduler.go:451] ScheduleAlgoTime 9.463502ms Start:2018-08-31 12:54:06.63080785 +0000 UTC m=+209.301430007 End:2018-08-31 12:54:06.640271391 +0000 UTC m=+209.310893509
I0831 12:54:06.640313       1 scheduler.go:454] Total Schedule Algo cumulative time:2.088604134s for 378
I0831 12:54:06.651043       1 scheduler.go:451] ScheduleAlgoTime 10.640956ms Start:2018-08-31 12:54:06.640394708 +0000 UTC m=+209.311016865 End:2018-08-31 12:54:06.651035693 +0000 UTC m=+209.321657821
I0831 12:54:06.651078       1 scheduler.go:454] Total Schedule Algo cumulative time:2.09924509s for 379
I0831 12:54:06.661862       1 scheduler.go:451] ScheduleAlgoTime 10.705286ms Start:2018-08-31 12:54:06.651151132 +0000 UTC m=+209.321773318 End:2018-08-31 12:54:06.661856478 +0000 UTC m=+209.332478604
I0831 12:54:06.661898       1 scheduler.go:454] Total Schedule Algo cumulative time:2.109950376s for 380
I0831 12:54:06.672274       1 scheduler.go:451] ScheduleAlgoTime 10.295515ms Start:2018-08-31 12:54:06.661969654 +0000 UTC m=+209.332591799 End:2018-08-31 12:54:06.672265189 +0000 UTC m=+209.342887314
I0831 12:54:06.672316       1 scheduler.go:454] Total Schedule Algo cumulative time:2.120245891s for 381
I0831 12:54:06.681973       1 scheduler.go:451] ScheduleAlgoTime 9.508566ms Start:2018-08-31 12:54:06.672458467 +0000 UTC m=+209.343080613 End:2018-08-31 12:54:06.681967058 +0000 UTC m=+209.352589179
I0831 12:54:06.682001       1 scheduler.go:454] Total Schedule Algo cumulative time:2.129754457s for 382
I0831 12:54:06.696199       1 scheduler.go:451] ScheduleAlgoTime 14.110022ms Start:2018-08-31 12:54:06.682082068 +0000 UTC m=+209.352704221 End:2018-08-31 12:54:06.696192123 +0000 UTC m=+209.366814243
I0831 12:54:06.696235       1 scheduler.go:454] Total Schedule Algo cumulative time:2.143864479s for 383
I0831 12:54:06.708165       1 scheduler.go:451] ScheduleAlgoTime 11.83336ms Start:2018-08-31 12:54:06.696319674 +0000 UTC m=+209.366941827 End:2018-08-31 12:54:06.708152731 +0000 UTC m=+209.378775187
I0831 12:54:06.708217       1 scheduler.go:454] Total Schedule Algo cumulative time:2.155697839s for 384
I0831 12:54:06.723157       1 scheduler.go:451] ScheduleAlgoTime 14.586035ms Start:2018-08-31 12:54:06.708563282 +0000 UTC m=+209.379185412 End:2018-08-31 12:54:06.723149326 +0000 UTC m=+209.393771447
I0831 12:54:06.723197       1 scheduler.go:454] Total Schedule Algo cumulative time:2.170283874s for 385
I0831 12:54:06.737084       1 scheduler.go:451] ScheduleAlgoTime 13.788218ms Start:2018-08-31 12:54:06.723283151 +0000 UTC m=+209.393905320 End:2018-08-31 12:54:06.737071401 +0000 UTC m=+209.407693538
I0831 12:54:06.737124       1 scheduler.go:454] Total Schedule Algo cumulative time:2.184072092s for 386
I0831 12:54:06.749709       1 scheduler.go:451] ScheduleAlgoTime 12.484297ms Start:2018-08-31 12:54:06.737215407 +0000 UTC m=+209.407837569 End:2018-08-31 12:54:06.749699737 +0000 UTC m=+209.420321866
I0831 12:54:06.749752       1 scheduler.go:454] Total Schedule Algo cumulative time:2.196556389s for 387
I0831 12:54:06.763497       1 scheduler.go:451] ScheduleAlgoTime 13.634925ms Start:2018-08-31 12:54:06.749852531 +0000 UTC m=+209.420474677 End:2018-08-31 12:54:06.763487464 +0000 UTC m=+209.434109602
I0831 12:54:06.763549       1 scheduler.go:454] Total Schedule Algo cumulative time:2.210191314s for 388
I0831 12:54:06.778288       1 scheduler.go:451] ScheduleAlgoTime 14.654429ms Start:2018-08-31 12:54:06.763622886 +0000 UTC m=+209.434245038 End:2018-08-31 12:54:06.778277321 +0000 UTC m=+209.448899467
I0831 12:54:06.778334       1 scheduler.go:454] Total Schedule Algo cumulative time:2.224845743s for 389
I0831 12:54:06.793216       1 scheduler.go:451] ScheduleAlgoTime 14.801892ms Start:2018-08-31 12:54:06.778404698 +0000 UTC m=+209.449026864 End:2018-08-31 12:54:06.793206625 +0000 UTC m=+209.463828756
I0831 12:54:06.793260       1 scheduler.go:454] Total Schedule Algo cumulative time:2.239647635s for 390
I0831 12:54:06.807363       1 scheduler.go:451] ScheduleAlgoTime 14.0027ms Start:2018-08-31 12:54:06.793348824 +0000 UTC m=+209.463970991 End:2018-08-31 12:54:06.80735155 +0000 UTC m=+209.477973691
I0831 12:54:07.263257       1 scheduler.go:454] Total Schedule Algo cumulative time:2.253650335s for 391
I0831 12:54:07.280211       1 scheduler.go:451] ScheduleAlgoTime 16.796571ms Start:2018-08-31 12:54:07.263403689 +0000 UTC m=+209.934025846 End:2018-08-31 12:54:07.280200287 +0000 UTC m=+209.950822417
I0831 12:54:07.280258       1 scheduler.go:454] Total Schedule Algo cumulative time:2.270446906s for 392
I0831 12:54:07.294935       1 scheduler.go:451] ScheduleAlgoTime 14.585116ms Start:2018-08-31 12:54:07.280336754 +0000 UTC m=+209.950958918 End:2018-08-31 12:54:07.294921899 +0000 UTC m=+209.965544034
I0831 12:54:07.294976       1 scheduler.go:454] Total Schedule Algo cumulative time:2.285032022s for 393
I0831 12:54:07.310099       1 scheduler.go:451] ScheduleAlgoTime 15.012588ms Start:2018-08-31 12:54:07.29507569 +0000 UTC m=+209.965697834 End:2018-08-31 12:54:07.310088295 +0000 UTC m=+209.980710422
I0831 12:54:07.310155       1 scheduler.go:454] Total Schedule Algo cumulative time:2.30004461s for 394
I0831 12:54:07.329349       1 scheduler.go:451] ScheduleAlgoTime 19.105917ms Start:2018-08-31 12:54:07.310231132 +0000 UTC m=+209.980853289 End:2018-08-31 12:54:07.329337082 +0000 UTC m=+209.999959206
I0831 12:54:07.344708       1 scheduler.go:454] Total Schedule Algo cumulative time:2.319150527s for 395
I0831 12:54:07.363826       1 scheduler.go:451] ScheduleAlgoTime 17.18034ms Start:2018-08-31 12:54:07.346633652 +0000 UTC m=+210.017255875 End:2018-08-31 12:54:07.363814086 +0000 UTC m=+210.034436215
I0831 12:54:07.363873       1 scheduler.go:454] Total Schedule Algo cumulative time:2.336330867s for 396
I0831 12:54:07.394030       1 scheduler.go:451] ScheduleAlgoTime 29.321272ms Start:2018-08-31 12:54:07.364696404 +0000 UTC m=+210.035318601 End:2018-08-31 12:54:07.394017734 +0000 UTC m=+210.064639873
I0831 12:54:07.394080       1 scheduler.go:454] Total Schedule Algo cumulative time:2.365652139s for 397
I0831 12:54:07.414824       1 scheduler.go:451] ScheduleAlgoTime 20.617143ms Start:2018-08-31 12:54:07.394194487 +0000 UTC m=+210.064816768 End:2018-08-31 12:54:07.414811769 +0000 UTC m=+210.085433911
I0831 12:54:07.430955       1 scheduler.go:454] Total Schedule Algo cumulative time:2.386269282s for 398
I0831 12:54:07.446405       1 scheduler.go:451] ScheduleAlgoTime 15.25199ms Start:2018-08-31 12:54:07.431141598 +0000 UTC m=+210.101763776 End:2018-08-31 12:54:07.446393638 +0000 UTC m=+210.117015766
I0831 12:54:07.446472       1 scheduler.go:454] Total Schedule Algo cumulative time:2.401521272s for 399
I0831 12:54:07.462412       1 scheduler.go:451] ScheduleAlgoTime 14.545236ms Start:2018-08-31 12:54:07.447859316 +0000 UTC m=+210.118481472 End:2018-08-31 12:54:07.462404588 +0000 UTC m=+210.133026708
I0831 12:54:07.592026       1 scheduler.go:454] Total Schedule Algo cumulative time:2.416066508s for 400
I0831 12:54:07.605403       1 scheduler.go:451] ScheduleAlgoTime 12.661317ms Start:2018-08-31 12:54:07.59272833 +0000 UTC m=+210.263350555 End:2018-08-31 12:54:07.605389752 +0000 UTC m=+210.276011872
I0831 12:54:07.605470       1 scheduler.go:454] Total Schedule Algo cumulative time:2.428727825s for 401
I0831 12:54:07.616996       1 scheduler.go:451] ScheduleAlgoTime 11.41022ms Start:2018-08-31 12:54:07.605570392 +0000 UTC m=+210.276192543 End:2018-08-31 12:54:07.61698059 +0000 UTC m=+210.287602763
I0831 12:54:08.167284       1 scheduler.go:454] Total Schedule Algo cumulative time:2.440138045s for 402
I0831 12:54:08.181501       1 scheduler.go:451] ScheduleAlgoTime 14.05872ms Start:2018-08-31 12:54:08.167431677 +0000 UTC m=+210.838053848 End:2018-08-31 12:54:08.181490442 +0000 UTC m=+210.852112568
I0831 12:54:08.181546       1 scheduler.go:454] Total Schedule Algo cumulative time:2.454196765s for 403
I0831 12:54:08.199994       1 scheduler.go:451] ScheduleAlgoTime 18.326465ms Start:2018-08-31 12:54:08.181656056 +0000 UTC m=+210.852278233 End:2018-08-31 12:54:08.199982569 +0000 UTC m=+210.870604698
I0831 12:54:08.200055       1 scheduler.go:454] Total Schedule Algo cumulative time:2.47252323s for 404
I0831 12:54:08.219161       1 scheduler.go:451] ScheduleAlgoTime 16.500128ms Start:2018-08-31 12:54:08.202651459 +0000 UTC m=+210.873273636 End:2018-08-31 12:54:08.219151606 +0000 UTC m=+210.889773764
I0831 12:54:08.219204       1 scheduler.go:454] Total Schedule Algo cumulative time:2.489023358s for 405
I0831 12:54:08.234190       1 scheduler.go:451] ScheduleAlgoTime 14.902865ms Start:2018-08-31 12:54:08.219279143 +0000 UTC m=+210.889901293 End:2018-08-31 12:54:08.234182038 +0000 UTC m=+210.904804158
I0831 12:54:08.234227       1 scheduler.go:454] Total Schedule Algo cumulative time:2.503926223s for 406
I0831 12:54:08.245783       1 scheduler.go:451] ScheduleAlgoTime 11.459899ms Start:2018-08-31 12:54:08.234313485 +0000 UTC m=+210.904935624 End:2018-08-31 12:54:08.245773394 +0000 UTC m=+210.916395523
I0831 12:54:08.331662       1 scheduler.go:454] Total Schedule Algo cumulative time:2.515386122s for 407
I0831 12:54:08.355963       1 scheduler.go:451] ScheduleAlgoTime 24.167477ms Start:2018-08-31 12:54:08.331785094 +0000 UTC m=+211.002407269 End:2018-08-31 12:54:08.355952626 +0000 UTC m=+211.026574746
I0831 12:54:08.371241       1 scheduler.go:454] Total Schedule Algo cumulative time:2.539553599s for 408
I0831 12:54:08.388239       1 scheduler.go:451] ScheduleAlgoTime 16.867713ms Start:2018-08-31 12:54:08.371361027 +0000 UTC m=+211.041983175 End:2018-08-31 12:54:08.38822874 +0000 UTC m=+211.058850888
I0831 12:54:08.388286       1 scheduler.go:454] Total Schedule Algo cumulative time:2.556421312s for 409
I0831 12:54:08.403378       1 scheduler.go:451] ScheduleAlgoTime 14.998707ms Start:2018-08-31 12:54:08.388371274 +0000 UTC m=+211.058993445 End:2018-08-31 12:54:08.403370033 +0000 UTC m=+211.073992152
I0831 12:54:08.403424       1 scheduler.go:454] Total Schedule Algo cumulative time:2.571420019s for 410
I0831 12:54:08.421374       1 scheduler.go:451] ScheduleAlgoTime 17.867587ms Start:2018-08-31 12:54:08.403493566 +0000 UTC m=+211.074115715 End:2018-08-31 12:54:08.421361164 +0000 UTC m=+211.091983302
I0831 12:54:08.445791       1 scheduler.go:454] Total Schedule Algo cumulative time:2.589287606s for 411
I0831 12:54:08.460759       1 scheduler.go:451] ScheduleAlgoTime 14.109597ms Start:2018-08-31 12:54:08.446638511 +0000 UTC m=+211.117260674 End:2018-08-31 12:54:08.460748148 +0000 UTC m=+211.131370271
I0831 12:54:08.488276       1 scheduler.go:454] Total Schedule Algo cumulative time:2.603397203s for 412
I0831 12:54:08.503607       1 scheduler.go:451] ScheduleAlgoTime 15.190529ms Start:2018-08-31 12:54:08.488404397 +0000 UTC m=+211.159026574 End:2018-08-31 12:54:08.503594978 +0000 UTC m=+211.174217103
I0831 12:54:08.503654       1 scheduler.go:454] Total Schedule Algo cumulative time:2.618587732s for 413
I0831 12:54:08.518395       1 scheduler.go:451] ScheduleAlgoTime 14.64105ms Start:2018-08-31 12:54:08.503744945 +0000 UTC m=+211.174367126 End:2018-08-31 12:54:08.518386056 +0000 UTC m=+211.189008176
I0831 12:54:08.547622       1 scheduler.go:454] Total Schedule Algo cumulative time:2.633228782s for 414
I0831 12:54:08.568366       1 scheduler.go:451] ScheduleAlgoTime 20.586724ms Start:2018-08-31 12:54:08.5477695 +0000 UTC m=+211.218391662 End:2018-08-31 12:54:08.568356234 +0000 UTC m=+211.238978386
I0831 12:54:08.568417       1 scheduler.go:454] Total Schedule Algo cumulative time:2.653815506s for 415
I0831 12:54:08.585297       1 scheduler.go:451] ScheduleAlgoTime 16.70234ms Start:2018-08-31 12:54:08.568582623 +0000 UTC m=+211.239204773 End:2018-08-31 12:54:08.585284937 +0000 UTC m=+211.255907113
I0831 12:54:08.585343       1 scheduler.go:454] Total Schedule Algo cumulative time:2.670517846s for 416
I0831 12:54:08.599597       1 scheduler.go:451] ScheduleAlgoTime 13.634266ms Start:2018-08-31 12:54:08.585952702 +0000 UTC m=+211.256574895 End:2018-08-31 12:54:08.599586654 +0000 UTC m=+211.270209161
I0831 12:54:08.599646       1 scheduler.go:454] Total Schedule Algo cumulative time:2.684152112s for 417
I0831 12:54:08.619423       1 scheduler.go:451] ScheduleAlgoTime 19.649916ms Start:2018-08-31 12:54:08.599764406 +0000 UTC m=+211.270386566 End:2018-08-31 12:54:08.619414363 +0000 UTC m=+211.290036482
I0831 12:54:08.619476       1 scheduler.go:454] Total Schedule Algo cumulative time:2.703802028s for 418
I0831 12:54:08.635505       1 scheduler.go:451] ScheduleAlgoTime 15.842333ms Start:2018-08-31 12:54:08.619650919 +0000 UTC m=+211.290273085 End:2018-08-31 12:54:08.635493288 +0000 UTC m=+211.306115418
I0831 12:54:08.636550       1 scheduler.go:454] Total Schedule Algo cumulative time:2.719644361s for 419
I0831 12:54:08.652702       1 scheduler.go:451] ScheduleAlgoTime 14.532211ms Start:2018-08-31 12:54:08.638158209 +0000 UTC m=+211.308780378 End:2018-08-31 12:54:08.652690156 +0000 UTC m=+211.323312589
I0831 12:54:08.652814       1 scheduler.go:454] Total Schedule Algo cumulative time:2.734176572s for 420
I0831 12:54:08.679916       1 scheduler.go:451] ScheduleAlgoTime 26.70558ms Start:2018-08-31 12:54:08.653199677 +0000 UTC m=+211.323821827 End:2018-08-31 12:54:08.679905259 +0000 UTC m=+211.350527407
I0831 12:54:08.680019       1 scheduler.go:454] Total Schedule Algo cumulative time:2.760882152s for 421
I0831 12:54:08.698771       1 scheduler.go:451] ScheduleAlgoTime 16.012211ms Start:2018-08-31 12:54:08.682749888 +0000 UTC m=+211.353372064 End:2018-08-31 12:54:08.698762156 +0000 UTC m=+211.369384275
I0831 12:54:08.698810       1 scheduler.go:454] Total Schedule Algo cumulative time:2.776894363s for 422
I0831 12:54:08.713132       1 scheduler.go:451] ScheduleAlgoTime 14.17382ms Start:2018-08-31 12:54:08.698946579 +0000 UTC m=+211.369568764 End:2018-08-31 12:54:08.713120464 +0000 UTC m=+211.383742584
I0831 12:54:08.713284       1 scheduler.go:454] Total Schedule Algo cumulative time:2.791068183s for 423
I0831 12:54:08.727302       1 scheduler.go:451] ScheduleAlgoTime 13.865276ms Start:2018-08-31 12:54:08.71342905 +0000 UTC m=+211.384051225 End:2018-08-31 12:54:08.727294382 +0000 UTC m=+211.397916501
I0831 12:54:08.727339       1 scheduler.go:454] Total Schedule Algo cumulative time:2.804933459s for 424
I0831 12:54:08.740445       1 scheduler.go:451] ScheduleAlgoTime 12.926869ms Start:2018-08-31 12:54:08.727507443 +0000 UTC m=+211.398129596 End:2018-08-31 12:54:08.740434336 +0000 UTC m=+211.411056465
I0831 12:54:08.740525       1 scheduler.go:454] Total Schedule Algo cumulative time:2.817860328s for 425
I0831 12:54:08.753727       1 scheduler.go:451] ScheduleAlgoTime 12.90582ms Start:2018-08-31 12:54:08.740812425 +0000 UTC m=+211.411434585 End:2018-08-31 12:54:08.753718286 +0000 UTC m=+211.424340405
I0831 12:54:08.753765       1 scheduler.go:454] Total Schedule Algo cumulative time:2.830766148s for 426
I0831 12:54:08.766331       1 scheduler.go:451] ScheduleAlgoTime 12.435941ms Start:2018-08-31 12:54:08.75388399 +0000 UTC m=+211.424506153 End:2018-08-31 12:54:08.766319966 +0000 UTC m=+211.436942094
I0831 12:54:08.766376       1 scheduler.go:454] Total Schedule Algo cumulative time:2.843202089s for 427
I0831 12:54:08.779139       1 scheduler.go:451] ScheduleAlgoTime 12.641621ms Start:2018-08-31 12:54:08.766486807 +0000 UTC m=+211.437108963 End:2018-08-31 12:54:08.779128461 +0000 UTC m=+211.449750584
I0831 12:54:08.779191       1 scheduler.go:454] Total Schedule Algo cumulative time:2.85584371s for 428
I0831 12:54:08.792287       1 scheduler.go:451] ScheduleAlgoTime 12.944589ms Start:2018-08-31 12:54:08.779333338 +0000 UTC m=+211.449955490 End:2018-08-31 12:54:08.792277958 +0000 UTC m=+211.462900079
I0831 12:54:08.793042       1 scheduler.go:454] Total Schedule Algo cumulative time:2.868788299s for 429
I0831 12:54:08.805382       1 scheduler.go:451] ScheduleAlgoTime 12.220397ms Start:2018-08-31 12:54:08.79315192 +0000 UTC m=+211.463774104 End:2018-08-31 12:54:08.805372349 +0000 UTC m=+211.475994501
I0831 12:54:08.805424       1 scheduler.go:454] Total Schedule Algo cumulative time:2.881008696s for 430
I0831 12:54:08.818272       1 scheduler.go:451] ScheduleAlgoTime 12.728055ms Start:2018-08-31 12:54:08.805535337 +0000 UTC m=+211.476157500 End:2018-08-31 12:54:08.818263435 +0000 UTC m=+211.488885555
I0831 12:54:08.818320       1 scheduler.go:454] Total Schedule Algo cumulative time:2.893736751s for 431
I0831 12:54:08.830407       1 scheduler.go:451] ScheduleAlgoTime 11.978136ms Start:2018-08-31 12:54:08.818419193 +0000 UTC m=+211.489041400 End:2018-08-31 12:54:08.830397393 +0000 UTC m=+211.501019536
I0831 12:54:08.830441       1 scheduler.go:454] Total Schedule Algo cumulative time:2.905714887s for 432
I0831 12:54:08.843834       1 scheduler.go:451] ScheduleAlgoTime 13.235064ms Start:2018-08-31 12:54:08.830591427 +0000 UTC m=+211.501213590 End:2018-08-31 12:54:08.843826533 +0000 UTC m=+211.514448654
I0831 12:54:08.843879       1 scheduler.go:454] Total Schedule Algo cumulative time:2.918949951s for 433
I0831 12:54:08.857419       1 scheduler.go:451] ScheduleAlgoTime 13.370889ms Start:2018-08-31 12:54:08.844036252 +0000 UTC m=+211.514658419 End:2018-08-31 12:54:08.857407185 +0000 UTC m=+211.528029308
I0831 12:54:08.857466       1 scheduler.go:454] Total Schedule Algo cumulative time:2.93232084s for 434
I0831 12:54:08.872379       1 scheduler.go:451] ScheduleAlgoTime 14.783449ms Start:2018-08-31 12:54:08.857585307 +0000 UTC m=+211.528207486 End:2018-08-31 12:54:08.872368802 +0000 UTC m=+211.542990935
I0831 12:54:08.872424       1 scheduler.go:454] Total Schedule Algo cumulative time:2.947104289s for 435
I0831 12:54:08.886922       1 scheduler.go:451] ScheduleAlgoTime 14.337425ms Start:2018-08-31 12:54:08.872574802 +0000 UTC m=+211.543196971 End:2018-08-31 12:54:08.886912275 +0000 UTC m=+211.557534396
I0831 12:54:08.887010       1 scheduler.go:454] Total Schedule Algo cumulative time:2.961441714s for 436
I0831 12:54:08.903715       1 scheduler.go:451] ScheduleAlgoTime 16.581322ms Start:2018-08-31 12:54:08.88712357 +0000 UTC m=+211.557745718 End:2018-08-31 12:54:08.903704897 +0000 UTC m=+211.574327040
I0831 12:54:08.903796       1 scheduler.go:454] Total Schedule Algo cumulative time:2.978023036s for 437
I0831 12:54:08.917964       1 scheduler.go:451] ScheduleAlgoTime 14.041605ms Start:2018-08-31 12:54:08.903913508 +0000 UTC m=+211.574535679 End:2018-08-31 12:54:08.917955163 +0000 UTC m=+211.588577284
I0831 12:54:08.918022       1 scheduler.go:454] Total Schedule Algo cumulative time:2.992064641s for 438
I0831 12:54:08.940328       1 scheduler.go:451] ScheduleAlgoTime 22.073663ms Start:2018-08-31 12:54:08.918242989 +0000 UTC m=+211.588865155 End:2018-08-31 12:54:08.940316682 +0000 UTC m=+211.610938818
I0831 12:54:08.940375       1 scheduler.go:454] Total Schedule Algo cumulative time:3.014138304s for 439
I0831 12:54:08.954002       1 scheduler.go:451] ScheduleAlgoTime 13.501941ms Start:2018-08-31 12:54:08.940491686 +0000 UTC m=+211.611113874 End:2018-08-31 12:54:08.953993696 +0000 UTC m=+211.624615815
I0831 12:54:08.954045       1 scheduler.go:454] Total Schedule Algo cumulative time:3.027640245s for 440
I0831 12:54:08.965936       1 scheduler.go:451] ScheduleAlgoTime 11.766697ms Start:2018-08-31 12:54:08.95415307 +0000 UTC m=+211.624775227 End:2018-08-31 12:54:08.965919769 +0000 UTC m=+211.636541924
I0831 12:54:08.965985       1 scheduler.go:454] Total Schedule Algo cumulative time:3.039406942s for 441
I0831 12:54:08.979874       1 scheduler.go:451] ScheduleAlgoTime 13.73274ms Start:2018-08-31 12:54:08.966130062 +0000 UTC m=+211.636752219 End:2018-08-31 12:54:08.979862815 +0000 UTC m=+211.650484959
I0831 12:54:08.979928       1 scheduler.go:454] Total Schedule Algo cumulative time:3.053139682s for 442
I0831 12:54:08.992689       1 scheduler.go:451] ScheduleAlgoTime 12.665616ms Start:2018-08-31 12:54:08.980013773 +0000 UTC m=+211.650635949 End:2018-08-31 12:54:08.992679446 +0000 UTC m=+211.663301565
I0831 12:54:08.992737       1 scheduler.go:454] Total Schedule Algo cumulative time:3.065805298s for 443
I0831 12:54:09.005558       1 scheduler.go:451] ScheduleAlgoTime 12.706559ms Start:2018-08-31 12:54:08.99284003 +0000 UTC m=+211.663462186 End:2018-08-31 12:54:09.00554661 +0000 UTC m=+211.676168745
I0831 12:54:09.005655       1 scheduler.go:454] Total Schedule Algo cumulative time:3.078511857s for 444
I0831 12:54:09.020878       1 scheduler.go:451] ScheduleAlgoTime 15.081031ms Start:2018-08-31 12:54:09.005789853 +0000 UTC m=+211.676412016 End:2018-08-31 12:54:09.020870928 +0000 UTC m=+211.691493047
I0831 12:54:09.020923       1 scheduler.go:454] Total Schedule Algo cumulative time:3.093592888s for 445
I0831 12:54:09.032830       1 scheduler.go:451] ScheduleAlgoTime 11.808867ms Start:2018-08-31 12:54:09.021011394 +0000 UTC m=+211.691633564 End:2018-08-31 12:54:09.032820271 +0000 UTC m=+211.703442431
I0831 12:54:09.032888       1 scheduler.go:454] Total Schedule Algo cumulative time:3.105401755s for 446
I0831 12:54:09.045051       1 scheduler.go:451] ScheduleAlgoTime 11.999885ms Start:2018-08-31 12:54:09.033031589 +0000 UTC m=+211.703653746 End:2018-08-31 12:54:09.045031498 +0000 UTC m=+211.715653631
I0831 12:54:09.045098       1 scheduler.go:454] Total Schedule Algo cumulative time:3.11740164s for 447
I0831 12:54:09.057970       1 scheduler.go:451] ScheduleAlgoTime 12.77888ms Start:2018-08-31 12:54:09.045184365 +0000 UTC m=+211.715806506 End:2018-08-31 12:54:09.057963266 +0000 UTC m=+211.728585386
I0831 12:54:09.058008       1 scheduler.go:454] Total Schedule Algo cumulative time:3.13018052s for 448
I0831 12:54:09.071500       1 scheduler.go:451] ScheduleAlgoTime 13.367606ms Start:2018-08-31 12:54:09.058124494 +0000 UTC m=+211.728746660 End:2018-08-31 12:54:09.071492146 +0000 UTC m=+211.742114266
I0831 12:54:09.071542       1 scheduler.go:454] Total Schedule Algo cumulative time:3.143548126s for 449
I0831 12:54:09.085115       1 scheduler.go:451] ScheduleAlgoTime 13.457012ms Start:2018-08-31 12:54:09.071649422 +0000 UTC m=+211.742271613 End:2018-08-31 12:54:09.085106492 +0000 UTC m=+211.755728625
I0831 12:54:09.085153       1 scheduler.go:454] Total Schedule Algo cumulative time:3.157005138s for 450
I0831 12:54:09.097291       1 scheduler.go:451] ScheduleAlgoTime 11.998023ms Start:2018-08-31 12:54:09.085286703 +0000 UTC m=+211.755908860 End:2018-08-31 12:54:09.097284762 +0000 UTC m=+211.767906883
I0831 12:54:09.097326       1 scheduler.go:454] Total Schedule Algo cumulative time:3.169003161s for 451
I0831 12:54:09.111489       1 scheduler.go:451] ScheduleAlgoTime 10.620917ms Start:2018-08-31 12:54:09.100851601 +0000 UTC m=+211.771473796 End:2018-08-31 12:54:09.111472587 +0000 UTC m=+211.782094713
I0831 12:54:09.111541       1 scheduler.go:454] Total Schedule Algo cumulative time:3.179624078s for 452
I0831 12:54:09.126239       1 scheduler.go:451] ScheduleAlgoTime 14.583005ms Start:2018-08-31 12:54:09.111646388 +0000 UTC m=+211.782268558 End:2018-08-31 12:54:09.126229442 +0000 UTC m=+211.796851563
I0831 12:54:09.126373       1 scheduler.go:454] Total Schedule Algo cumulative time:3.194207083s for 453
I0831 12:54:09.145428       1 scheduler.go:451] ScheduleAlgoTime 18.872808ms Start:2018-08-31 12:54:09.126544083 +0000 UTC m=+211.797166222 End:2018-08-31 12:54:09.145416867 +0000 UTC m=+211.816039030
I0831 12:54:09.145585       1 scheduler.go:454] Total Schedule Algo cumulative time:3.213079891s for 454
I0831 12:54:09.158005       1 scheduler.go:451] ScheduleAlgoTime 12.266815ms Start:2018-08-31 12:54:09.145731776 +0000 UTC m=+211.816353947 End:2018-08-31 12:54:09.157998641 +0000 UTC m=+211.828620762
I0831 12:54:09.158041       1 scheduler.go:454] Total Schedule Algo cumulative time:3.225346706s for 455
I0831 12:54:09.179335       1 scheduler.go:451] ScheduleAlgoTime 21.190434ms Start:2018-08-31 12:54:09.158136677 +0000 UTC m=+211.828758822 End:2018-08-31 12:54:09.179327136 +0000 UTC m=+211.849949256
I0831 12:54:09.179375       1 scheduler.go:454] Total Schedule Algo cumulative time:3.24653714s for 456
I0831 12:54:09.191932       1 scheduler.go:451] ScheduleAlgoTime 12.428642ms Start:2018-08-31 12:54:09.179493744 +0000 UTC m=+211.850115934 End:2018-08-31 12:54:09.19192245 +0000 UTC m=+211.862544576
I0831 12:54:09.191986       1 scheduler.go:454] Total Schedule Algo cumulative time:3.258965782s for 457
I0831 12:54:09.203819       1 scheduler.go:451] ScheduleAlgoTime 11.729047ms Start:2018-08-31 12:54:09.19208289 +0000 UTC m=+211.862705059 End:2018-08-31 12:54:09.203811987 +0000 UTC m=+211.874434106
I0831 12:54:09.203862       1 scheduler.go:454] Total Schedule Algo cumulative time:3.270694829s for 458
I0831 12:54:09.216749       1 scheduler.go:451] ScheduleAlgoTime 12.784188ms Start:2018-08-31 12:54:09.203957373 +0000 UTC m=+211.874579533 End:2018-08-31 12:54:09.2167416 +0000 UTC m=+211.887363721
I0831 12:54:09.216793       1 scheduler.go:454] Total Schedule Algo cumulative time:3.283479017s for 459
I0831 12:54:09.228673       1 scheduler.go:451] ScheduleAlgoTime 11.785884ms Start:2018-08-31 12:54:09.216881736 +0000 UTC m=+211.887503892 End:2018-08-31 12:54:09.228667652 +0000 UTC m=+211.899289776
I0831 12:54:09.228712       1 scheduler.go:454] Total Schedule Algo cumulative time:3.295264901s for 460
I0831 12:54:09.242286       1 scheduler.go:451] ScheduleAlgoTime 13.43216ms Start:2018-08-31 12:54:09.228847818 +0000 UTC m=+211.899470000 End:2018-08-31 12:54:09.242280038 +0000 UTC m=+211.912902160
I0831 12:54:09.242322       1 scheduler.go:454] Total Schedule Algo cumulative time:3.308697061s for 461
I0831 12:54:09.253831       1 scheduler.go:451] ScheduleAlgoTime 11.403329ms Start:2018-08-31 12:54:09.242420195 +0000 UTC m=+211.913042348 End:2018-08-31 12:54:09.253823542 +0000 UTC m=+211.924445677
I0831 12:54:09.253880       1 scheduler.go:454] Total Schedule Algo cumulative time:3.32010039s for 462
I0831 12:54:09.265017       1 scheduler.go:451] ScheduleAlgoTime 11.009471ms Start:2018-08-31 12:54:09.254000593 +0000 UTC m=+211.924622740 End:2018-08-31 12:54:09.265010089 +0000 UTC m=+211.935632211
I0831 12:54:09.265048       1 scheduler.go:454] Total Schedule Algo cumulative time:3.331109861s for 463
I0831 12:54:09.276569       1 scheduler.go:451] ScheduleAlgoTime 11.401253ms Start:2018-08-31 12:54:09.265160351 +0000 UTC m=+211.935782534 End:2018-08-31 12:54:09.276561661 +0000 UTC m=+211.947183787
I0831 12:54:09.276607       1 scheduler.go:454] Total Schedule Algo cumulative time:3.342511114s for 464
I0831 12:54:09.288097       1 scheduler.go:451] ScheduleAlgoTime 11.326409ms Start:2018-08-31 12:54:09.276764663 +0000 UTC m=+211.947386810 End:2018-08-31 12:54:09.2880911 +0000 UTC m=+211.958713219
I0831 12:54:09.288127       1 scheduler.go:454] Total Schedule Algo cumulative time:3.353837523s for 465
I0831 12:54:09.299636       1 scheduler.go:451] ScheduleAlgoTime 11.420428ms Start:2018-08-31 12:54:09.288208058 +0000 UTC m=+211.958830213 End:2018-08-31 12:54:09.299628499 +0000 UTC m=+211.970250641
I0831 12:54:09.299673       1 scheduler.go:454] Total Schedule Algo cumulative time:3.365257951s for 466
I0831 12:54:09.310206       1 scheduler.go:451] ScheduleAlgoTime 10.434435ms Start:2018-08-31 12:54:09.299766648 +0000 UTC m=+211.970388796 End:2018-08-31 12:54:09.310201113 +0000 UTC m=+211.980823231
I0831 12:54:09.310234       1 scheduler.go:454] Total Schedule Algo cumulative time:3.375692386s for 467
I0831 12:54:09.322472       1 scheduler.go:451] ScheduleAlgoTime 12.143587ms Start:2018-08-31 12:54:09.310319765 +0000 UTC m=+211.980941944 End:2018-08-31 12:54:09.322463408 +0000 UTC m=+211.993085531
I0831 12:54:09.322518       1 scheduler.go:454] Total Schedule Algo cumulative time:3.387835973s for 468
I0831 12:54:09.334070       1 scheduler.go:451] ScheduleAlgoTime 11.45661ms Start:2018-08-31 12:54:09.322606782 +0000 UTC m=+211.993228941 End:2018-08-31 12:54:09.334063433 +0000 UTC m=+212.004685551
I0831 12:54:09.334101       1 scheduler.go:454] Total Schedule Algo cumulative time:3.399292583s for 469
I0831 12:54:09.345175       1 scheduler.go:451] ScheduleAlgoTime 10.98797ms Start:2018-08-31 12:54:09.334180799 +0000 UTC m=+212.004802953 End:2018-08-31 12:54:09.3451688 +0000 UTC m=+212.015790923
I0831 12:54:09.345207       1 scheduler.go:454] Total Schedule Algo cumulative time:3.410280553s for 470
I0831 12:54:09.357094       1 scheduler.go:451] ScheduleAlgoTime 11.789142ms Start:2018-08-31 12:54:09.345299057 +0000 UTC m=+212.015921224 End:2018-08-31 12:54:09.357088245 +0000 UTC m=+212.027710366
I0831 12:54:09.357132       1 scheduler.go:454] Total Schedule Algo cumulative time:3.422069695s for 471
I0831 12:54:09.367739       1 scheduler.go:451] ScheduleAlgoTime 10.5101ms Start:2018-08-31 12:54:09.357220437 +0000 UTC m=+212.027842601 End:2018-08-31 12:54:09.36773057 +0000 UTC m=+212.038352701
I0831 12:54:09.367772       1 scheduler.go:454] Total Schedule Algo cumulative time:3.432579795s for 472
I0831 12:54:09.378945       1 scheduler.go:451] ScheduleAlgoTime 11.067957ms Start:2018-08-31 12:54:09.367869596 +0000 UTC m=+212.038491768 End:2018-08-31 12:54:09.378937594 +0000 UTC m=+212.049559725
I0831 12:54:09.378975       1 scheduler.go:454] Total Schedule Algo cumulative time:3.443647752s for 473
I0831 12:54:09.396977       1 scheduler.go:451] ScheduleAlgoTime 17.899081ms Start:2018-08-31 12:54:09.379069338 +0000 UTC m=+212.049691531 End:2018-08-31 12:54:09.396968493 +0000 UTC m=+212.067590612
I0831 12:54:09.397016       1 scheduler.go:454] Total Schedule Algo cumulative time:3.461546833s for 474
I0831 12:54:09.408315       1 scheduler.go:451] ScheduleAlgoTime 11.199949ms Start:2018-08-31 12:54:09.397106038 +0000 UTC m=+212.067728208 End:2018-08-31 12:54:09.408306028 +0000 UTC m=+212.078928157
I0831 12:54:09.408363       1 scheduler.go:454] Total Schedule Algo cumulative time:3.472746782s for 475
I0831 12:54:09.419550       1 scheduler.go:451] ScheduleAlgoTime 11.066098ms Start:2018-08-31 12:54:09.408477612 +0000 UTC m=+212.079099782 End:2018-08-31 12:54:09.419543761 +0000 UTC m=+212.090165880
I0831 12:54:09.419588       1 scheduler.go:454] Total Schedule Algo cumulative time:3.48381288s for 476
I0831 12:54:09.432292       1 scheduler.go:451] ScheduleAlgoTime 12.597571ms Start:2018-08-31 12:54:09.419683024 +0000 UTC m=+212.090305173 End:2018-08-31 12:54:09.432280624 +0000 UTC m=+212.102902744
I0831 12:54:09.432325       1 scheduler.go:454] Total Schedule Algo cumulative time:3.496410451s for 477
I0831 12:54:09.444485       1 scheduler.go:451] ScheduleAlgoTime 12.065153ms Start:2018-08-31 12:54:09.432412499 +0000 UTC m=+212.103034655 End:2018-08-31 12:54:09.444477686 +0000 UTC m=+212.115099808
I0831 12:54:09.444523       1 scheduler.go:454] Total Schedule Algo cumulative time:3.508475604s for 478
I0831 12:54:09.456614       1 scheduler.go:451] ScheduleAlgoTime 11.985748ms Start:2018-08-31 12:54:09.444622364 +0000 UTC m=+212.115244513 End:2018-08-31 12:54:09.456608141 +0000 UTC m=+212.127230261
I0831 12:54:09.456653       1 scheduler.go:454] Total Schedule Algo cumulative time:3.520461352s for 479
I0831 12:54:09.467266       1 scheduler.go:451] ScheduleAlgoTime 10.516366ms Start:2018-08-31 12:54:09.456743987 +0000 UTC m=+212.127366141 End:2018-08-31 12:54:09.467260388 +0000 UTC m=+212.137882507
I0831 12:54:09.467302       1 scheduler.go:454] Total Schedule Algo cumulative time:3.530977718s for 480
I0831 12:54:09.479953       1 scheduler.go:451] ScheduleAlgoTime 12.549596ms Start:2018-08-31 12:54:09.467398165 +0000 UTC m=+212.138020317 End:2018-08-31 12:54:09.479947794 +0000 UTC m=+212.150569913
I0831 12:54:09.479985       1 scheduler.go:454] Total Schedule Algo cumulative time:3.543527314s for 481
I0831 12:54:09.490636       1 scheduler.go:451] ScheduleAlgoTime 10.560746ms Start:2018-08-31 12:54:09.480067281 +0000 UTC m=+212.150689433 End:2018-08-31 12:54:09.490628057 +0000 UTC m=+212.161250179
I0831 12:54:09.490671       1 scheduler.go:454] Total Schedule Algo cumulative time:3.55408806s for 482
I0831 12:54:09.502844       1 scheduler.go:451] ScheduleAlgoTime 12.076254ms Start:2018-08-31 12:54:09.490761825 +0000 UTC m=+212.161383974 End:2018-08-31 12:54:09.502838109 +0000 UTC m=+212.173460228
I0831 12:54:09.502875       1 scheduler.go:454] Total Schedule Algo cumulative time:3.566164314s for 483
I0831 12:54:09.513803       1 scheduler.go:451] ScheduleAlgoTime 10.832967ms Start:2018-08-31 12:54:09.502964377 +0000 UTC m=+212.173586519 End:2018-08-31 12:54:09.513797367 +0000 UTC m=+212.184419486
I0831 12:54:09.513834       1 scheduler.go:454] Total Schedule Algo cumulative time:3.576997281s for 484
I0831 12:54:09.525789       1 scheduler.go:451] ScheduleAlgoTime 11.861778ms Start:2018-08-31 12:54:09.513922027 +0000 UTC m=+212.184544189 End:2018-08-31 12:54:09.525783842 +0000 UTC m=+212.196405967
I0831 12:54:09.525822       1 scheduler.go:454] Total Schedule Algo cumulative time:3.588859059s for 485
I0831 12:54:09.536639       1 scheduler.go:451] ScheduleAlgoTime 10.71193ms Start:2018-08-31 12:54:09.525921546 +0000 UTC m=+212.196543704 End:2018-08-31 12:54:09.536633515 +0000 UTC m=+212.207255634
I0831 12:54:09.536670       1 scheduler.go:454] Total Schedule Algo cumulative time:3.599570989s for 486
I0831 12:54:09.555758       1 scheduler.go:451] ScheduleAlgoTime 18.995094ms Start:2018-08-31 12:54:09.536755998 +0000 UTC m=+212.207378182 End:2018-08-31 12:54:09.555751158 +0000 UTC m=+212.226373276
I0831 12:54:09.555791       1 scheduler.go:454] Total Schedule Algo cumulative time:3.618566083s for 487
I0831 12:54:09.566965       1 scheduler.go:451] ScheduleAlgoTime 11.073482ms Start:2018-08-31 12:54:09.555882596 +0000 UTC m=+212.226504742 End:2018-08-31 12:54:09.566956091 +0000 UTC m=+212.237578224
I0831 12:54:09.567005       1 scheduler.go:454] Total Schedule Algo cumulative time:3.629639565s for 488
I0831 12:54:09.577968       1 scheduler.go:451] ScheduleAlgoTime 10.862604ms Start:2018-08-31 12:54:09.567096495 +0000 UTC m=+212.237718658 End:2018-08-31 12:54:09.577959133 +0000 UTC m=+212.248581262
I0831 12:54:09.578006       1 scheduler.go:454] Total Schedule Algo cumulative time:3.640502169s for 489
I0831 12:54:09.588754       1 scheduler.go:451] ScheduleAlgoTime 10.653437ms Start:2018-08-31 12:54:09.57809423 +0000 UTC m=+212.248716379 End:2018-08-31 12:54:09.588747696 +0000 UTC m=+212.259369816
I0831 12:54:09.588818       1 scheduler.go:454] Total Schedule Algo cumulative time:3.651155606s for 490
I0831 12:54:09.606500       1 scheduler.go:451] ScheduleAlgoTime 17.590323ms Start:2018-08-31 12:54:09.588900694 +0000 UTC m=+212.259522850 End:2018-08-31 12:54:09.606491053 +0000 UTC m=+212.277113173
I0831 12:54:09.606549       1 scheduler.go:454] Total Schedule Algo cumulative time:3.668745929s for 491
I0831 12:54:09.619157       1 scheduler.go:451] ScheduleAlgoTime 12.472836ms Start:2018-08-31 12:54:09.606676138 +0000 UTC m=+212.277298303 End:2018-08-31 12:54:09.61914902 +0000 UTC m=+212.289771139
I0831 12:54:09.619200       1 scheduler.go:454] Total Schedule Algo cumulative time:3.681218765s for 492
I0831 12:54:09.630952       1 scheduler.go:451] ScheduleAlgoTime 11.649816ms Start:2018-08-31 12:54:09.619295911 +0000 UTC m=+212.289918068 End:2018-08-31 12:54:09.630945764 +0000 UTC m=+212.301567884
I0831 12:54:09.630994       1 scheduler.go:454] Total Schedule Algo cumulative time:3.692868581s for 493
I0831 12:54:09.644374       1 scheduler.go:451] ScheduleAlgoTime 13.277599ms Start:2018-08-31 12:54:09.631089302 +0000 UTC m=+212.301711455 End:2018-08-31 12:54:09.644366934 +0000 UTC m=+212.314989054
I0831 12:54:09.644416       1 scheduler.go:454] Total Schedule Algo cumulative time:3.70614618s for 494
I0831 12:54:09.663020       1 scheduler.go:451] ScheduleAlgoTime 16.362658ms Start:2018-08-31 12:54:09.646647352 +0000 UTC m=+212.317269516 End:2018-08-31 12:54:09.663010041 +0000 UTC m=+212.333632174
I0831 12:54:09.663063       1 scheduler.go:454] Total Schedule Algo cumulative time:3.722508838s for 495
I0831 12:54:09.679016       1 scheduler.go:451] ScheduleAlgoTime 14.119257ms Start:2018-08-31 12:54:09.664886408 +0000 UTC m=+212.335508558 End:2018-08-31 12:54:09.679005695 +0000 UTC m=+212.349627815
I0831 12:54:09.679066       1 scheduler.go:454] Total Schedule Algo cumulative time:3.736628095s for 496
I0831 12:54:09.691771       1 scheduler.go:451] ScheduleAlgoTime 12.595425ms Start:2018-08-31 12:54:09.679169398 +0000 UTC m=+212.349791550 End:2018-08-31 12:54:09.691764856 +0000 UTC m=+212.362386975
I0831 12:54:09.691814       1 scheduler.go:454] Total Schedule Algo cumulative time:3.74922352s for 497
I0831 12:54:09.702876       1 scheduler.go:451] ScheduleAlgoTime 10.953303ms Start:2018-08-31 12:54:09.691916937 +0000 UTC m=+212.362539116 End:2018-08-31 12:54:09.702870298 +0000 UTC m=+212.373492419
I0831 12:54:09.702917       1 scheduler.go:454] Total Schedule Algo cumulative time:3.760176823s for 498
I0831 12:54:09.714003       1 scheduler.go:451] ScheduleAlgoTime 10.989612ms Start:2018-08-31 12:54:09.703008216 +0000 UTC m=+212.373630385 End:2018-08-31 12:54:09.713997877 +0000 UTC m=+212.384619997
I0831 12:54:09.714039       1 scheduler.go:454] Total Schedule Algo cumulative time:3.771166435s for 499
I0831 12:54:09.726890       1 scheduler.go:451] ScheduleAlgoTime 12.749985ms Start:2018-08-31 12:54:09.714133427 +0000 UTC m=+212.384755590 End:2018-08-31 12:54:09.726883454 +0000 UTC m=+212.397505575
I0831 12:54:09.726926       1 scheduler.go:454] Total Schedule Algo cumulative time:3.78391642s for 500
I0831 12:54:09.739636       1 scheduler.go:451] ScheduleAlgoTime 12.584648ms Start:2018-08-31 12:54:09.727043797 +0000 UTC m=+212.397665976 End:2018-08-31 12:54:09.739628498 +0000 UTC m=+212.410250624
I0831 12:54:09.739676       1 scheduler.go:454] Total Schedule Algo cumulative time:3.796501068s for 501
I0831 12:54:09.752624       1 scheduler.go:451] ScheduleAlgoTime 12.854112ms Start:2018-08-31 12:54:09.739765136 +0000 UTC m=+212.410387298 End:2018-08-31 12:54:09.752619287 +0000 UTC m=+212.423241410
I0831 12:54:09.752654       1 scheduler.go:454] Total Schedule Algo cumulative time:3.80935518s for 502
I0831 12:54:09.764547       1 scheduler.go:451] ScheduleAlgoTime 11.794293ms Start:2018-08-31 12:54:09.752745294 +0000 UTC m=+212.423367467 End:2018-08-31 12:54:09.76453963 +0000 UTC m=+212.435161760
I0831 12:54:09.764583       1 scheduler.go:454] Total Schedule Algo cumulative time:3.821149473s for 503
I0831 12:54:09.775173       1 scheduler.go:451] ScheduleAlgoTime 10.487217ms Start:2018-08-31 12:54:09.764680466 +0000 UTC m=+212.435302630 End:2018-08-31 12:54:09.775167729 +0000 UTC m=+212.445789847
I0831 12:54:09.775201       1 scheduler.go:454] Total Schedule Algo cumulative time:3.83163669s for 504
I0831 12:54:09.786889       1 scheduler.go:451] ScheduleAlgoTime 11.58502ms Start:2018-08-31 12:54:09.775296962 +0000 UTC m=+212.445919118 End:2018-08-31 12:54:09.786881996 +0000 UTC m=+212.457504138
I0831 12:54:09.786933       1 scheduler.go:454] Total Schedule Algo cumulative time:3.84322171s for 505
I0831 12:54:09.799495       1 scheduler.go:451] ScheduleAlgoTime 12.437629ms Start:2018-08-31 12:54:09.787051304 +0000 UTC m=+212.457673484 End:2018-08-31 12:54:09.799488993 +0000 UTC m=+212.470111113
I0831 12:54:09.799524       1 scheduler.go:454] Total Schedule Algo cumulative time:3.855659339s for 506
I0831 12:54:09.812217       1 scheduler.go:451] ScheduleAlgoTime 12.580259ms Start:2018-08-31 12:54:09.799630333 +0000 UTC m=+212.470252504 End:2018-08-31 12:54:09.812210639 +0000 UTC m=+212.482832763
I0831 12:54:09.812253       1 scheduler.go:454] Total Schedule Algo cumulative time:3.868239598s for 507
I0831 12:54:09.826923       1 scheduler.go:451] ScheduleAlgoTime 14.561036ms Start:2018-08-31 12:54:09.812351357 +0000 UTC m=+212.482973525 End:2018-08-31 12:54:09.826912419 +0000 UTC m=+212.497534561
I0831 12:54:09.827019       1 scheduler.go:454] Total Schedule Algo cumulative time:3.882800634s for 508
I0831 12:54:09.862673       1 scheduler.go:451] ScheduleAlgoTime 31.475451ms Start:2018-08-31 12:54:09.831188987 +0000 UTC m=+212.501811159 End:2018-08-31 12:54:09.862664493 +0000 UTC m=+212.533286610
I0831 12:54:09.862713       1 scheduler.go:454] Total Schedule Algo cumulative time:3.914276085s for 509
I0831 12:54:09.874845       1 scheduler.go:451] ScheduleAlgoTime 12.032638ms Start:2018-08-31 12:54:09.862804519 +0000 UTC m=+212.533426678 End:2018-08-31 12:54:09.874837195 +0000 UTC m=+212.545459316
I0831 12:54:09.874883       1 scheduler.go:454] Total Schedule Algo cumulative time:3.926308723s for 510
I0831 12:54:09.887961       1 scheduler.go:451] ScheduleAlgoTime 12.984426ms Start:2018-08-31 12:54:09.874970139 +0000 UTC m=+212.545592307 End:2018-08-31 12:54:09.887954613 +0000 UTC m=+212.558576733
I0831 12:54:09.888005       1 scheduler.go:454] Total Schedule Algo cumulative time:3.939293149s for 511
I0831 12:54:09.899944       1 scheduler.go:451] ScheduleAlgoTime 11.805252ms Start:2018-08-31 12:54:09.88813201 +0000 UTC m=+212.558754184 End:2018-08-31 12:54:09.899937317 +0000 UTC m=+212.570559436
I0831 12:54:09.899994       1 scheduler.go:454] Total Schedule Algo cumulative time:3.951098401s for 512
I0831 12:54:09.912598       1 scheduler.go:451] ScheduleAlgoTime 12.499626ms Start:2018-08-31 12:54:09.900092471 +0000 UTC m=+212.570714627 End:2018-08-31 12:54:09.912592134 +0000 UTC m=+212.583214253
I0831 12:54:09.912637       1 scheduler.go:454] Total Schedule Algo cumulative time:3.963598027s for 513
I0831 12:54:09.926541       1 scheduler.go:451] ScheduleAlgoTime 13.823209ms Start:2018-08-31 12:54:09.91270915 +0000 UTC m=+212.583331304 End:2018-08-31 12:54:09.926532379 +0000 UTC m=+212.597154513
I0831 12:54:09.926625       1 scheduler.go:454] Total Schedule Algo cumulative time:3.977421236s for 514
I0831 12:54:09.939792       1 scheduler.go:451] ScheduleAlgoTime 13.055854ms Start:2018-08-31 12:54:09.926730276 +0000 UTC m=+212.597352447 End:2018-08-31 12:54:09.939786182 +0000 UTC m=+212.610408301
I0831 12:54:09.939825       1 scheduler.go:454] Total Schedule Algo cumulative time:3.99047709s for 515
I0831 12:54:09.952175       1 scheduler.go:451] ScheduleAlgoTime 12.236118ms Start:2018-08-31 12:54:09.93993286 +0000 UTC m=+212.610555035 End:2018-08-31 12:54:09.95216903 +0000 UTC m=+212.622791153
I0831 12:54:09.952207       1 scheduler.go:454] Total Schedule Algo cumulative time:4.002713208s for 516
I0831 12:54:09.963224       1 scheduler.go:451] ScheduleAlgoTime 10.922562ms Start:2018-08-31 12:54:09.952293958 +0000 UTC m=+212.622916121 End:2018-08-31 12:54:09.963216556 +0000 UTC m=+212.633838683
I0831 12:54:09.963259       1 scheduler.go:454] Total Schedule Algo cumulative time:4.01363577s for 517
I0831 12:54:09.974506       1 scheduler.go:451] ScheduleAlgoTime 11.143544ms Start:2018-08-31 12:54:09.963356961 +0000 UTC m=+212.633979110 End:2018-08-31 12:54:09.974500534 +0000 UTC m=+212.645122654
I0831 12:54:09.974540       1 scheduler.go:454] Total Schedule Algo cumulative time:4.024779314s for 518
I0831 12:54:09.986000       1 scheduler.go:451] ScheduleAlgoTime 11.311587ms Start:2018-08-31 12:54:09.974683526 +0000 UTC m=+212.645305688 End:2018-08-31 12:54:09.985995156 +0000 UTC m=+212.656617275
I0831 12:54:09.986030       1 scheduler.go:454] Total Schedule Algo cumulative time:4.036090901s for 519
I0831 12:54:09.998060       1 scheduler.go:451] ScheduleAlgoTime 11.938498ms Start:2018-08-31 12:54:09.986117004 +0000 UTC m=+212.656739160 End:2018-08-31 12:54:09.998055539 +0000 UTC m=+212.668677658
I0831 12:54:09.998104       1 scheduler.go:454] Total Schedule Algo cumulative time:4.048029399s for 520
I0831 12:54:10.010682       1 scheduler.go:451] ScheduleAlgoTime 12.482451ms Start:2018-08-31 12:54:09.998194626 +0000 UTC m=+212.668816799 End:2018-08-31 12:54:10.01067713 +0000 UTC m=+212.681299250
I0831 12:54:10.010712       1 scheduler.go:454] Total Schedule Algo cumulative time:4.06051185s for 521
I0831 12:54:10.020958       1 scheduler.go:451] ScheduleAlgoTime 10.150564ms Start:2018-08-31 12:54:10.010800075 +0000 UTC m=+212.681422237 End:2018-08-31 12:54:10.020950673 +0000 UTC m=+212.691572801
I0831 12:54:10.020992       1 scheduler.go:454] Total Schedule Algo cumulative time:4.070662414s for 522
I0831 12:54:10.031325       1 scheduler.go:451] ScheduleAlgoTime 10.257163ms Start:2018-08-31 12:54:10.021062473 +0000 UTC m=+212.691684627 End:2018-08-31 12:54:10.031319666 +0000 UTC m=+212.701941790
I0831 12:54:10.031355       1 scheduler.go:454] Total Schedule Algo cumulative time:4.080919577s for 523
I0831 12:54:10.044442       1 scheduler.go:451] ScheduleAlgoTime 12.991982ms Start:2018-08-31 12:54:10.03144433 +0000 UTC m=+212.702066476 End:2018-08-31 12:54:10.044436338 +0000 UTC m=+212.715058458
I0831 12:54:10.044487       1 scheduler.go:454] Total Schedule Algo cumulative time:4.093911559s for 524
I0831 12:54:10.061770       1 scheduler.go:451] ScheduleAlgoTime 17.173933ms Start:2018-08-31 12:54:10.044589537 +0000 UTC m=+212.715211707 End:2018-08-31 12:54:10.061763516 +0000 UTC m=+212.732385640
I0831 12:54:10.061817       1 scheduler.go:454] Total Schedule Algo cumulative time:4.111085492s for 525
I0831 12:54:10.073983       1 scheduler.go:451] ScheduleAlgoTime 12.039849ms Start:2018-08-31 12:54:10.061936788 +0000 UTC m=+212.732558947 End:2018-08-31 12:54:10.073976676 +0000 UTC m=+212.744598796
I0831 12:54:10.074018       1 scheduler.go:454] Total Schedule Algo cumulative time:4.123125341s for 526
I0831 12:54:10.086429       1 scheduler.go:451] ScheduleAlgoTime 12.314844ms Start:2018-08-31 12:54:10.07410699 +0000 UTC m=+212.744729175 End:2018-08-31 12:54:10.086421893 +0000 UTC m=+212.757044019
I0831 12:54:10.086478       1 scheduler.go:454] Total Schedule Algo cumulative time:4.135440185s for 527
I0831 12:54:10.100101       1 scheduler.go:451] ScheduleAlgoTime 13.504151ms Start:2018-08-31 12:54:10.086591058 +0000 UTC m=+212.757213211 End:2018-08-31 12:54:10.100095241 +0000 UTC m=+212.770717362
I0831 12:54:10.100130       1 scheduler.go:454] Total Schedule Algo cumulative time:4.148944336s for 528
I0831 12:54:10.112471       1 scheduler.go:451] ScheduleAlgoTime 12.261715ms Start:2018-08-31 12:54:10.10020309 +0000 UTC m=+212.770825248 End:2018-08-31 12:54:10.112464836 +0000 UTC m=+212.783086963
I0831 12:54:10.112513       1 scheduler.go:454] Total Schedule Algo cumulative time:4.161206051s for 529
I0831 12:54:10.126379       1 scheduler.go:451] ScheduleAlgoTime 13.760718ms Start:2018-08-31 12:54:10.112609888 +0000 UTC m=+212.783232057 End:2018-08-31 12:54:10.12637063 +0000 UTC m=+212.796992775
I0831 12:54:10.126419       1 scheduler.go:454] Total Schedule Algo cumulative time:4.174966769s for 530
I0831 12:54:10.138442       1 scheduler.go:451] ScheduleAlgoTime 11.908362ms Start:2018-08-31 12:54:10.126527478 +0000 UTC m=+212.797149647 End:2018-08-31 12:54:10.138435888 +0000 UTC m=+212.809058009
I0831 12:54:10.138486       1 scheduler.go:454] Total Schedule Algo cumulative time:4.186875131s for 531
I0831 12:54:10.151545       1 scheduler.go:451] ScheduleAlgoTime 12.955235ms Start:2018-08-31 12:54:10.138582589 +0000 UTC m=+212.809204758 End:2018-08-31 12:54:10.151537872 +0000 UTC m=+212.822159993
I0831 12:54:10.151575       1 scheduler.go:454] Total Schedule Algo cumulative time:4.199830366s for 532
I0831 12:54:10.164337       1 scheduler.go:451] ScheduleAlgoTime 12.660348ms Start:2018-08-31 12:54:10.151670601 +0000 UTC m=+212.822292761 End:2018-08-31 12:54:10.164330989 +0000 UTC m=+212.834953109
I0831 12:54:10.164371       1 scheduler.go:454] Total Schedule Algo cumulative time:4.212490714s for 533
I0831 12:54:10.175957       1 scheduler.go:451] ScheduleAlgoTime 11.4357ms Start:2018-08-31 12:54:10.164515622 +0000 UTC m=+212.835137772 End:2018-08-31 12:54:10.175951352 +0000 UTC m=+212.846573472
I0831 12:54:10.175987       1 scheduler.go:454] Total Schedule Algo cumulative time:4.223926414s for 534
I0831 12:54:10.189875       1 scheduler.go:451] ScheduleAlgoTime 13.793432ms Start:2018-08-31 12:54:10.176073159 +0000 UTC m=+212.846695315 End:2018-08-31 12:54:10.189866619 +0000 UTC m=+212.860488747
I0831 12:54:10.189912       1 scheduler.go:454] Total Schedule Algo cumulative time:4.237719846s for 535
I0831 12:54:10.202342       1 scheduler.go:451] ScheduleAlgoTime 12.343706ms Start:2018-08-31 12:54:10.189992474 +0000 UTC m=+212.860614626 End:2018-08-31 12:54:10.202336213 +0000 UTC m=+212.872958332
I0831 12:54:10.202372       1 scheduler.go:454] Total Schedule Algo cumulative time:4.250063552s for 536
I0831 12:54:10.214264       1 scheduler.go:451] ScheduleAlgoTime 11.808387ms Start:2018-08-31 12:54:10.202450168 +0000 UTC m=+212.873072344 End:2018-08-31 12:54:10.214258612 +0000 UTC m=+212.884880731
I0831 12:54:10.214294       1 scheduler.go:454] Total Schedule Algo cumulative time:4.261871939s for 537
I0831 12:54:10.226478       1 scheduler.go:451] ScheduleAlgoTime 12.11846ms Start:2018-08-31 12:54:10.214353666 +0000 UTC m=+212.884975814 End:2018-08-31 12:54:10.226472153 +0000 UTC m=+212.897094274
I0831 12:54:10.226518       1 scheduler.go:454] Total Schedule Algo cumulative time:4.273990399s for 538
I0831 12:54:10.239535       1 scheduler.go:451] ScheduleAlgoTime 12.900716ms Start:2018-08-31 12:54:10.226627521 +0000 UTC m=+212.897249671 End:2018-08-31 12:54:10.239528268 +0000 UTC m=+212.910150387
I0831 12:54:10.239572       1 scheduler.go:454] Total Schedule Algo cumulative time:4.286891115s for 539
I0831 12:54:10.253443       1 scheduler.go:451] ScheduleAlgoTime 13.770709ms Start:2018-08-31 12:54:10.239666604 +0000 UTC m=+212.910288755 End:2018-08-31 12:54:10.253437341 +0000 UTC m=+212.924059464
I0831 12:54:10.253482       1 scheduler.go:454] Total Schedule Algo cumulative time:4.300661824s for 540
I0831 12:54:10.270645       1 scheduler.go:451] ScheduleAlgoTime 17.040135ms Start:2018-08-31 12:54:10.253597154 +0000 UTC m=+212.924219311 End:2018-08-31 12:54:10.270637324 +0000 UTC m=+212.941259446
I0831 12:54:10.270684       1 scheduler.go:454] Total Schedule Algo cumulative time:4.317701959s for 541
I0831 12:54:10.284903       1 scheduler.go:451] ScheduleAlgoTime 14.121141ms Start:2018-08-31 12:54:10.270774663 +0000 UTC m=+212.941396814 End:2018-08-31 12:54:10.284895835 +0000 UTC m=+212.955517955
I0831 12:54:10.284938       1 scheduler.go:454] Total Schedule Algo cumulative time:4.3318231s for 542
I0831 12:54:10.297065       1 scheduler.go:451] ScheduleAlgoTime 12.04228ms Start:2018-08-31 12:54:10.285017264 +0000 UTC m=+212.955639423 End:2018-08-31 12:54:10.297059582 +0000 UTC m=+212.967681703
I0831 12:54:10.297096       1 scheduler.go:454] Total Schedule Algo cumulative time:4.34386538s for 543
I0831 12:54:10.310347       1 scheduler.go:451] ScheduleAlgoTime 13.152919ms Start:2018-08-31 12:54:10.297187911 +0000 UTC m=+212.967810051 End:2018-08-31 12:54:10.31034085 +0000 UTC m=+212.980962970
I0831 12:54:10.310383       1 scheduler.go:454] Total Schedule Algo cumulative time:4.357018299s for 544
I0831 12:54:10.323661       1 scheduler.go:451] ScheduleAlgoTime 13.157944ms Start:2018-08-31 12:54:10.310495939 +0000 UTC m=+212.981118109 End:2018-08-31 12:54:10.323653934 +0000 UTC m=+212.994276053
I0831 12:54:10.323693       1 scheduler.go:454] Total Schedule Algo cumulative time:4.370176243s for 545
I0831 12:54:10.337201       1 scheduler.go:451] ScheduleAlgoTime 13.411057ms Start:2018-08-31 12:54:10.323784252 +0000 UTC m=+212.994406406 End:2018-08-31 12:54:10.337195344 +0000 UTC m=+213.007817463
I0831 12:54:10.337234       1 scheduler.go:454] Total Schedule Algo cumulative time:4.3835873s for 546
I0831 12:54:10.349775       1 scheduler.go:451] ScheduleAlgoTime 12.454995ms Start:2018-08-31 12:54:10.337311656 +0000 UTC m=+213.007933816 End:2018-08-31 12:54:10.34976667 +0000 UTC m=+213.020388811
I0831 12:54:10.349809       1 scheduler.go:454] Total Schedule Algo cumulative time:4.396042295s for 547
I0831 12:54:10.362646       1 scheduler.go:451] ScheduleAlgoTime 12.728651ms Start:2018-08-31 12:54:10.349911925 +0000 UTC m=+213.020534105 End:2018-08-31 12:54:10.362640636 +0000 UTC m=+213.033262756
I0831 12:54:10.362679       1 scheduler.go:454] Total Schedule Algo cumulative time:4.408770946s for 548
I0831 12:54:10.379856       1 scheduler.go:451] ScheduleAlgoTime 17.059231ms Start:2018-08-31 12:54:10.362786011 +0000 UTC m=+213.033408188 End:2018-08-31 12:54:10.379845292 +0000 UTC m=+213.050467419
I0831 12:54:10.379908       1 scheduler.go:454] Total Schedule Algo cumulative time:4.425830177s for 549
I0831 12:54:10.399720       1 scheduler.go:451] ScheduleAlgoTime 18.884074ms Start:2018-08-31 12:54:10.380826948 +0000 UTC m=+213.051449104 End:2018-08-31 12:54:10.399711055 +0000 UTC m=+213.070333178
I0831 12:54:10.399772       1 scheduler.go:454] Total Schedule Algo cumulative time:4.444714251s for 550
I0831 12:54:10.412551       1 scheduler.go:451] ScheduleAlgoTime 12.645945ms Start:2018-08-31 12:54:10.399894668 +0000 UTC m=+213.070516829 End:2018-08-31 12:54:10.412540647 +0000 UTC m=+213.083162774
I0831 12:54:10.412593       1 scheduler.go:454] Total Schedule Algo cumulative time:4.457360196s for 551
I0831 12:54:10.425565       1 scheduler.go:451] ScheduleAlgoTime 12.841164ms Start:2018-08-31 12:54:10.412717171 +0000 UTC m=+213.083339323 End:2018-08-31 12:54:10.425558353 +0000 UTC m=+213.096180487
I0831 12:54:10.425611       1 scheduler.go:454] Total Schedule Algo cumulative time:4.47020136s for 552
I0831 12:54:10.437774       1 scheduler.go:451] ScheduleAlgoTime 12.041779ms Start:2018-08-31 12:54:10.425725965 +0000 UTC m=+213.096348141 End:2018-08-31 12:54:10.4377678 +0000 UTC m=+213.108389920
I0831 12:54:10.437803       1 scheduler.go:454] Total Schedule Algo cumulative time:4.482243139s for 553
I0831 12:54:10.449631       1 scheduler.go:451] ScheduleAlgoTime 11.734216ms Start:2018-08-31 12:54:10.437891036 +0000 UTC m=+213.108513190 End:2018-08-31 12:54:10.449625278 +0000 UTC m=+213.120247406
I0831 12:54:10.449662       1 scheduler.go:454] Total Schedule Algo cumulative time:4.493977355s for 554
I0831 12:54:10.463436       1 scheduler.go:451] ScheduleAlgoTime 13.677221ms Start:2018-08-31 12:54:10.449753124 +0000 UTC m=+213.120375312 End:2018-08-31 12:54:10.463430414 +0000 UTC m=+213.134052533
I0831 12:54:10.463475       1 scheduler.go:454] Total Schedule Algo cumulative time:4.507654576s for 555
I0831 12:54:10.476439       1 scheduler.go:451] ScheduleAlgoTime 12.86934ms Start:2018-08-31 12:54:10.463564336 +0000 UTC m=+213.134186503 End:2018-08-31 12:54:10.47643372 +0000 UTC m=+213.147055843
I0831 12:54:10.476485       1 scheduler.go:454] Total Schedule Algo cumulative time:4.520523916s for 556
I0831 12:54:10.488375       1 scheduler.go:451] ScheduleAlgoTime 11.781329ms Start:2018-08-31 12:54:10.476586816 +0000 UTC m=+213.147208963 End:2018-08-31 12:54:10.488368155 +0000 UTC m=+213.158990292
I0831 12:54:10.488418       1 scheduler.go:454] Total Schedule Algo cumulative time:4.532305245s for 557
I0831 12:54:10.506031       1 scheduler.go:451] ScheduleAlgoTime 17.493579ms Start:2018-08-31 12:54:10.488529941 +0000 UTC m=+213.159152116 End:2018-08-31 12:54:10.506023574 +0000 UTC m=+213.176645695
I0831 12:54:10.506069       1 scheduler.go:454] Total Schedule Algo cumulative time:4.549798824s for 558
I0831 12:54:10.518010       1 scheduler.go:451] ScheduleAlgoTime 11.841125ms Start:2018-08-31 12:54:10.506161076 +0000 UTC m=+213.176783232 End:2018-08-31 12:54:10.518002238 +0000 UTC m=+213.188624357
I0831 12:54:10.518052       1 scheduler.go:454] Total Schedule Algo cumulative time:4.561639949s for 559
I0831 12:54:10.530773       1 scheduler.go:451] ScheduleAlgoTime 12.615408ms Start:2018-08-31 12:54:10.518152044 +0000 UTC m=+213.188774220 End:2018-08-31 12:54:10.530767509 +0000 UTC m=+213.201389628
I0831 12:54:10.530811       1 scheduler.go:454] Total Schedule Algo cumulative time:4.574255357s for 560
I0831 12:54:10.543772       1 scheduler.go:451] ScheduleAlgoTime 12.87331ms Start:2018-08-31 12:54:10.530890526 +0000 UTC m=+213.201512686 End:2018-08-31 12:54:10.543763869 +0000 UTC m=+213.214385996
I0831 12:54:10.543813       1 scheduler.go:454] Total Schedule Algo cumulative time:4.587128667s for 561
I0831 12:54:10.556572       1 scheduler.go:451] ScheduleAlgoTime 12.662986ms Start:2018-08-31 12:54:10.54390364 +0000 UTC m=+213.214525834 End:2018-08-31 12:54:10.556566699 +0000 UTC m=+213.227188820
I0831 12:54:10.556603       1 scheduler.go:454] Total Schedule Algo cumulative time:4.599791653s for 562
I0831 12:54:10.568631       1 scheduler.go:451] ScheduleAlgoTime 11.934034ms Start:2018-08-31 12:54:10.556689981 +0000 UTC m=+213.227312122 End:2018-08-31 12:54:10.568624025 +0000 UTC m=+213.239246156
I0831 12:54:10.568671       1 scheduler.go:454] Total Schedule Algo cumulative time:4.611725687s for 563
I0831 12:54:10.580319       1 scheduler.go:451] ScheduleAlgoTime 11.538268ms Start:2018-08-31 12:54:10.56877487 +0000 UTC m=+213.239397027 End:2018-08-31 12:54:10.580313177 +0000 UTC m=+213.250935295
I0831 12:54:10.580351       1 scheduler.go:454] Total Schedule Algo cumulative time:4.623263955s for 564
I0831 12:54:10.593044       1 scheduler.go:451] ScheduleAlgoTime 12.612286ms Start:2018-08-31 12:54:10.580424674 +0000 UTC m=+213.251046833 End:2018-08-31 12:54:10.593036993 +0000 UTC m=+213.263659119
I0831 12:54:10.593096       1 scheduler.go:454] Total Schedule Algo cumulative time:4.635876241s for 565
I0831 12:54:10.606036       1 scheduler.go:451] ScheduleAlgoTime 12.844485ms Start:2018-08-31 12:54:10.593183091 +0000 UTC m=+213.263805241 End:2018-08-31 12:54:10.606027601 +0000 UTC m=+213.276649726
I0831 12:54:10.606099       1 scheduler.go:454] Total Schedule Algo cumulative time:4.648720726s for 566
I0831 12:54:10.619617       1 scheduler.go:451] ScheduleAlgoTime 13.410329ms Start:2018-08-31 12:54:10.606197751 +0000 UTC m=+213.276819911 End:2018-08-31 12:54:10.619608111 +0000 UTC m=+213.290230240
I0831 12:54:10.619650       1 scheduler.go:454] Total Schedule Algo cumulative time:4.662131055s for 567
I0831 12:54:10.632580       1 scheduler.go:451] ScheduleAlgoTime 12.783162ms Start:2018-08-31 12:54:10.619789726 +0000 UTC m=+213.290411907 End:2018-08-31 12:54:10.632572949 +0000 UTC m=+213.303195069
I0831 12:54:10.632614       1 scheduler.go:454] Total Schedule Algo cumulative time:4.674914217s for 568
I0831 12:54:10.646512       1 scheduler.go:451] ScheduleAlgoTime 13.785793ms Start:2018-08-31 12:54:10.632719177 +0000 UTC m=+213.303341358 End:2018-08-31 12:54:10.646505032 +0000 UTC m=+213.317127151
I0831 12:54:10.646546       1 scheduler.go:454] Total Schedule Algo cumulative time:4.68870001s for 569
I0831 12:54:10.660100       1 scheduler.go:451] ScheduleAlgoTime 13.443013ms Start:2018-08-31 12:54:10.64665088 +0000 UTC m=+213.317273051 End:2018-08-31 12:54:10.660093941 +0000 UTC m=+213.330716064
I0831 12:54:10.660136       1 scheduler.go:454] Total Schedule Algo cumulative time:4.702143023s for 570
I0831 12:54:10.673088       1 scheduler.go:451] ScheduleAlgoTime 12.847542ms Start:2018-08-31 12:54:10.660233867 +0000 UTC m=+213.330856013 End:2018-08-31 12:54:10.673081436 +0000 UTC m=+213.343703555
I0831 12:54:10.673130       1 scheduler.go:454] Total Schedule Algo cumulative time:4.714990565s for 571
I0831 12:54:10.687632       1 scheduler.go:451] ScheduleAlgoTime 14.411146ms Start:2018-08-31 12:54:10.673215004 +0000 UTC m=+213.343837177 End:2018-08-31 12:54:10.687626204 +0000 UTC m=+213.358248323
I0831 12:54:10.687667       1 scheduler.go:454] Total Schedule Algo cumulative time:4.729401711s for 572
I0831 12:54:10.699850       1 scheduler.go:451] ScheduleAlgoTime 12.081679ms Start:2018-08-31 12:54:10.687762214 +0000 UTC m=+213.358384374 End:2018-08-31 12:54:10.699843935 +0000 UTC m=+213.370466053
I0831 12:54:10.699882       1 scheduler.go:454] Total Schedule Algo cumulative time:4.74148339s for 573
I0831 12:54:10.716987       1 scheduler.go:451] ScheduleAlgoTime 17.002566ms Start:2018-08-31 12:54:10.699978085 +0000 UTC m=+213.370600240 End:2018-08-31 12:54:10.716980687 +0000 UTC m=+213.387602806
I0831 12:54:10.717024       1 scheduler.go:454] Total Schedule Algo cumulative time:4.758485956s for 574
I0831 12:54:10.731052       1 scheduler.go:451] ScheduleAlgoTime 13.939995ms Start:2018-08-31 12:54:10.717106289 +0000 UTC m=+213.387728453 End:2018-08-31 12:54:10.731046329 +0000 UTC m=+213.401668448
I0831 12:54:10.731091       1 scheduler.go:454] Total Schedule Algo cumulative time:4.772425951s for 575
I0831 12:54:10.743364       1 scheduler.go:451] ScheduleAlgoTime 12.178743ms Start:2018-08-31 12:54:10.731178642 +0000 UTC m=+213.401800795 End:2018-08-31 12:54:10.74335742 +0000 UTC m=+213.413979538
I0831 12:54:10.743405       1 scheduler.go:454] Total Schedule Algo cumulative time:4.784604694s for 576
I0831 12:54:10.756748       1 scheduler.go:451] ScheduleAlgoTime 13.229997ms Start:2018-08-31 12:54:10.743513582 +0000 UTC m=+213.414135728 End:2018-08-31 12:54:10.756743606 +0000 UTC m=+213.427365725
I0831 12:54:10.756784       1 scheduler.go:454] Total Schedule Algo cumulative time:4.797834691s for 577
I0831 12:54:10.768669       1 scheduler.go:451] ScheduleAlgoTime 11.785867ms Start:2018-08-31 12:54:10.756873838 +0000 UTC m=+213.427495998 End:2018-08-31 12:54:10.768659736 +0000 UTC m=+213.439281865
I0831 12:54:10.768731       1 scheduler.go:454] Total Schedule Algo cumulative time:4.809620558s for 578
I0831 12:54:10.782403       1 scheduler.go:451] ScheduleAlgoTime 13.577243ms Start:2018-08-31 12:54:10.768816994 +0000 UTC m=+213.439439136 End:2018-08-31 12:54:10.782394248 +0000 UTC m=+213.453016379
I0831 12:54:10.782450       1 scheduler.go:454] Total Schedule Algo cumulative time:4.823197801s for 579
I0831 12:54:10.795583       1 scheduler.go:451] ScheduleAlgoTime 13.016239ms Start:2018-08-31 12:54:10.782559658 +0000 UTC m=+213.453181822 End:2018-08-31 12:54:10.795575943 +0000 UTC m=+213.466198061
I0831 12:54:10.795615       1 scheduler.go:454] Total Schedule Algo cumulative time:4.83621404s for 580
I0831 12:54:10.807937       1 scheduler.go:451] ScheduleAlgoTime 12.21895ms Start:2018-08-31 12:54:10.79571189 +0000 UTC m=+213.466334041 End:2018-08-31 12:54:10.807930868 +0000 UTC m=+213.478552991
I0831 12:54:10.807969       1 scheduler.go:454] Total Schedule Algo cumulative time:4.84843299s for 581
I0831 12:54:10.820985       1 scheduler.go:451] ScheduleAlgoTime 12.908179ms Start:2018-08-31 12:54:10.808069997 +0000 UTC m=+213.478692149 End:2018-08-31 12:54:10.820978209 +0000 UTC m=+213.491600328
I0831 12:54:10.821036       1 scheduler.go:454] Total Schedule Algo cumulative time:4.861341169s for 582
I0831 12:54:10.834207       1 scheduler.go:451] ScheduleAlgoTime 13.059849ms Start:2018-08-31 12:54:10.821139236 +0000 UTC m=+213.491761399 End:2018-08-31 12:54:10.834199123 +0000 UTC m=+213.504821248
I0831 12:54:10.834238       1 scheduler.go:454] Total Schedule Algo cumulative time:4.874401018s for 583
I0831 12:54:10.846702       1 scheduler.go:451] ScheduleAlgoTime 12.376922ms Start:2018-08-31 12:54:10.834319863 +0000 UTC m=+213.504942003 End:2018-08-31 12:54:10.846696805 +0000 UTC m=+213.517318925
I0831 12:54:10.846730       1 scheduler.go:454] Total Schedule Algo cumulative time:4.88677794s for 584
I0831 12:54:10.858354       1 scheduler.go:451] ScheduleAlgoTime 11.528258ms Start:2018-08-31 12:54:10.846817563 +0000 UTC m=+213.517439715 End:2018-08-31 12:54:10.858345846 +0000 UTC m=+213.528967973
I0831 12:54:10.858389       1 scheduler.go:454] Total Schedule Algo cumulative time:4.898306198s for 585
I0831 12:54:10.871647       1 scheduler.go:451] ScheduleAlgoTime 13.171406ms Start:2018-08-31 12:54:10.858468839 +0000 UTC m=+213.529090987 End:2018-08-31 12:54:10.871640274 +0000 UTC m=+213.542262393
I0831 12:54:10.871676       1 scheduler.go:454] Total Schedule Algo cumulative time:4.911477604s for 586
I0831 12:54:10.883218       1 scheduler.go:451] ScheduleAlgoTime 11.444293ms Start:2018-08-31 12:54:10.871768581 +0000 UTC m=+213.542390740 End:2018-08-31 12:54:10.883212914 +0000 UTC m=+213.553835033
I0831 12:54:10.883251       1 scheduler.go:454] Total Schedule Algo cumulative time:4.922921897s for 587
I0831 12:54:10.897082       1 scheduler.go:451] ScheduleAlgoTime 13.724348ms Start:2018-08-31 12:54:10.883348536 +0000 UTC m=+213.553970704 End:2018-08-31 12:54:10.897072925 +0000 UTC m=+213.567695052
I0831 12:54:10.897122       1 scheduler.go:454] Total Schedule Algo cumulative time:4.936646245s for 588
I0831 12:54:10.908839       1 scheduler.go:451] ScheduleAlgoTime 11.608202ms Start:2018-08-31 12:54:10.8972252 +0000 UTC m=+213.567847367 End:2018-08-31 12:54:10.90883345 +0000 UTC m=+213.579455569
I0831 12:54:10.908869       1 scheduler.go:454] Total Schedule Algo cumulative time:4.948254447s for 589
I0831 12:54:10.926657       1 scheduler.go:451] ScheduleAlgoTime 17.685931ms Start:2018-08-31 12:54:10.908964224 +0000 UTC m=+213.579586385 End:2018-08-31 12:54:10.926650197 +0000 UTC m=+213.597272316
I0831 12:54:10.926696       1 scheduler.go:454] Total Schedule Algo cumulative time:4.965940378s for 590
I0831 12:54:10.938963       1 scheduler.go:451] ScheduleAlgoTime 12.170406ms Start:2018-08-31 12:54:10.926785806 +0000 UTC m=+213.597407982 End:2018-08-31 12:54:10.938956268 +0000 UTC m=+213.609578388
I0831 12:54:10.939018       1 scheduler.go:454] Total Schedule Algo cumulative time:4.978110784s for 591
I0831 12:54:10.952460       1 scheduler.go:451] ScheduleAlgoTime 13.333781ms Start:2018-08-31 12:54:10.939110591 +0000 UTC m=+213.609732741 End:2018-08-31 12:54:10.952444402 +0000 UTC m=+213.623066522
I0831 12:54:10.952507       1 scheduler.go:454] Total Schedule Algo cumulative time:4.991444565s for 592
I0831 12:54:10.965411       1 scheduler.go:451] ScheduleAlgoTime 12.804013ms Start:2018-08-31 12:54:10.952600872 +0000 UTC m=+213.623223029 End:2018-08-31 12:54:10.965404922 +0000 UTC m=+213.636027042
I0831 12:54:10.965443       1 scheduler.go:454] Total Schedule Algo cumulative time:5.004248578s for 593
I0831 12:54:10.977876       1 scheduler.go:451] ScheduleAlgoTime 12.298409ms Start:2018-08-31 12:54:10.965569498 +0000 UTC m=+213.636191661 End:2018-08-31 12:54:10.977867941 +0000 UTC m=+213.648490070
I0831 12:54:10.977916       1 scheduler.go:454] Total Schedule Algo cumulative time:5.016546987s for 594
I0831 12:54:10.990548       1 scheduler.go:451] ScheduleAlgoTime 12.521224ms Start:2018-08-31 12:54:10.978020425 +0000 UTC m=+213.648642590 End:2018-08-31 12:54:10.990541695 +0000 UTC m=+213.661163814
I0831 12:54:10.990608       1 scheduler.go:454] Total Schedule Algo cumulative time:5.029068211s for 595
I0831 12:54:11.002099       1 scheduler.go:451] ScheduleAlgoTime 11.408ms Start:2018-08-31 12:54:10.99068312 +0000 UTC m=+213.661305288 End:2018-08-31 12:54:11.002091159 +0000 UTC m=+213.672713288
I0831 12:54:11.002139       1 scheduler.go:454] Total Schedule Algo cumulative time:5.040476211s for 596
I0831 12:54:11.015383       1 scheduler.go:451] ScheduleAlgoTime 13.127689ms Start:2018-08-31 12:54:11.002249999 +0000 UTC m=+213.672872189 End:2018-08-31 12:54:11.015377758 +0000 UTC m=+213.685999878
I0831 12:54:11.015413       1 scheduler.go:454] Total Schedule Algo cumulative time:5.0536039s for 597
I0831 12:54:11.027940       1 scheduler.go:451] ScheduleAlgoTime 12.432571ms Start:2018-08-31 12:54:11.015501475 +0000 UTC m=+213.686123622 End:2018-08-31 12:54:11.027934072 +0000 UTC m=+213.698556193
I0831 12:54:11.027973       1 scheduler.go:454] Total Schedule Algo cumulative time:5.066036471s for 598
I0831 12:54:11.041552       1 scheduler.go:451] ScheduleAlgoTime 13.428669ms Start:2018-08-31 12:54:11.028116239 +0000 UTC m=+213.698738379 End:2018-08-31 12:54:11.041544929 +0000 UTC m=+213.712167048
I0831 12:54:11.041587       1 scheduler.go:454] Total Schedule Algo cumulative time:5.07946514s for 599
I0831 12:54:11.053874       1 scheduler.go:451] ScheduleAlgoTime 12.131838ms Start:2018-08-31 12:54:11.041735443 +0000 UTC m=+213.712357597 End:2018-08-31 12:54:11.053867314 +0000 UTC m=+213.724489435
I0831 12:54:11.053907       1 scheduler.go:454] Total Schedule Algo cumulative time:5.091596978s for 600
I0831 12:54:11.067165       1 scheduler.go:451] ScheduleAlgoTime 13.15446ms Start:2018-08-31 12:54:11.054004231 +0000 UTC m=+213.724626383 End:2018-08-31 12:54:11.067158725 +0000 UTC m=+213.737780843
I0831 12:54:11.067194       1 scheduler.go:454] Total Schedule Algo cumulative time:5.104751438s for 601
I0831 12:54:11.078119       1 scheduler.go:451] ScheduleAlgoTime 10.839984ms Start:2018-08-31 12:54:11.067273372 +0000 UTC m=+213.737895521 End:2018-08-31 12:54:11.078113385 +0000 UTC m=+213.748735505
I0831 12:54:11.078151       1 scheduler.go:454] Total Schedule Algo cumulative time:5.115591422s for 602
I0831 12:54:11.089143       1 scheduler.go:451] ScheduleAlgoTime 10.892169ms Start:2018-08-31 12:54:11.078246143 +0000 UTC m=+213.748868294 End:2018-08-31 12:54:11.089138335 +0000 UTC m=+213.759760463
I0831 12:54:11.089176       1 scheduler.go:454] Total Schedule Algo cumulative time:5.126483591s for 603
I0831 12:54:11.101512       1 scheduler.go:451] ScheduleAlgoTime 12.245444ms Start:2018-08-31 12:54:11.089258237 +0000 UTC m=+213.759880382 End:2018-08-31 12:54:11.101503697 +0000 UTC m=+213.772125826
I0831 12:54:11.101564       1 scheduler.go:454] Total Schedule Algo cumulative time:5.138729035s for 604
I0831 12:54:11.118434       1 scheduler.go:451] ScheduleAlgoTime 16.767983ms Start:2018-08-31 12:54:11.101656558 +0000 UTC m=+213.772278703 End:2018-08-31 12:54:11.118424492 +0000 UTC m=+213.789046686
I0831 12:54:11.118524       1 scheduler.go:454] Total Schedule Algo cumulative time:5.155497018s for 605
I0831 12:54:11.145297       1 scheduler.go:451] ScheduleAlgoTime 22.651983ms Start:2018-08-31 12:54:11.122636921 +0000 UTC m=+213.793259111 End:2018-08-31 12:54:11.145288974 +0000 UTC m=+213.815911094
I0831 12:54:11.145337       1 scheduler.go:454] Total Schedule Algo cumulative time:5.178149001s for 606
I0831 12:54:11.158044       1 scheduler.go:451] ScheduleAlgoTime 12.613925ms Start:2018-08-31 12:54:11.145422737 +0000 UTC m=+213.816044889 End:2018-08-31 12:54:11.158036693 +0000 UTC m=+213.828658814
I0831 12:54:11.158086       1 scheduler.go:454] Total Schedule Algo cumulative time:5.190762926s for 607
I0831 12:54:11.170980       1 scheduler.go:451] ScheduleAlgoTime 12.802831ms Start:2018-08-31 12:54:11.158169969 +0000 UTC m=+213.828792126 End:2018-08-31 12:54:11.170972836 +0000 UTC m=+213.841594957
I0831 12:54:11.171013       1 scheduler.go:454] Total Schedule Algo cumulative time:5.203565757s for 608
I0831 12:54:11.181954       1 scheduler.go:451] ScheduleAlgoTime 10.840655ms Start:2018-08-31 12:54:11.171106931 +0000 UTC m=+213.841729078 End:2018-08-31 12:54:11.181947613 +0000 UTC m=+213.852569733
I0831 12:54:11.181994       1 scheduler.go:454] Total Schedule Algo cumulative time:5.214406412s for 609
I0831 12:54:11.193836       1 scheduler.go:451] ScheduleAlgoTime 11.738374ms Start:2018-08-31 12:54:11.182092622 +0000 UTC m=+213.852714778 End:2018-08-31 12:54:11.193831033 +0000 UTC m=+213.864453152
I0831 12:54:11.193867       1 scheduler.go:454] Total Schedule Algo cumulative time:5.226144786s for 610
I0831 12:54:11.206021       1 scheduler.go:451] ScheduleAlgoTime 12.063023ms Start:2018-08-31 12:54:11.193951419 +0000 UTC m=+213.864573561 End:2018-08-31 12:54:11.206014464 +0000 UTC m=+213.876636584
I0831 12:54:11.206052       1 scheduler.go:454] Total Schedule Algo cumulative time:5.238207809s for 611
I0831 12:54:11.217659       1 scheduler.go:451] ScheduleAlgoTime 11.509202ms Start:2018-08-31 12:54:11.206141082 +0000 UTC m=+213.876763235 End:2018-08-31 12:54:11.217650317 +0000 UTC m=+213.888272437
I0831 12:54:11.217688       1 scheduler.go:454] Total Schedule Algo cumulative time:5.249717011s for 612
I0831 12:54:11.228940       1 scheduler.go:451] ScheduleAlgoTime 11.154736ms Start:2018-08-31 12:54:11.217779881 +0000 UTC m=+213.888402034 End:2018-08-31 12:54:11.22893465 +0000 UTC m=+213.899556770
I0831 12:54:11.228972       1 scheduler.go:454] Total Schedule Algo cumulative time:5.260871747s for 613
I0831 12:54:11.241476       1 scheduler.go:451] ScheduleAlgoTime 12.415629ms Start:2018-08-31 12:54:11.22905362 +0000 UTC m=+213.899675779 End:2018-08-31 12:54:11.241469289 +0000 UTC m=+213.912091408
I0831 12:54:11.241512       1 scheduler.go:454] Total Schedule Algo cumulative time:5.273287376s for 614
I0831 12:54:11.253573       1 scheduler.go:451] ScheduleAlgoTime 11.960409ms Start:2018-08-31 12:54:11.241606047 +0000 UTC m=+213.912228212 End:2018-08-31 12:54:11.253566495 +0000 UTC m=+213.924188621
I0831 12:54:11.253601       1 scheduler.go:454] Total Schedule Algo cumulative time:5.285247785s for 615
I0831 12:54:11.264850       1 scheduler.go:451] ScheduleAlgoTime 11.163021ms Start:2018-08-31 12:54:11.253678914 +0000 UTC m=+213.924301075 End:2018-08-31 12:54:11.264841965 +0000 UTC m=+213.935464096
I0831 12:54:11.264888       1 scheduler.go:454] Total Schedule Algo cumulative time:5.296410806s for 616
I0831 12:54:11.276562       1 scheduler.go:451] ScheduleAlgoTime 11.604793ms Start:2018-08-31 12:54:11.264948701 +0000 UTC m=+213.935570854 End:2018-08-31 12:54:11.276553506 +0000 UTC m=+213.947175647
I0831 12:54:11.276602       1 scheduler.go:454] Total Schedule Algo cumulative time:5.308015599s for 617
I0831 12:54:11.290394       1 scheduler.go:451] ScheduleAlgoTime 13.699462ms Start:2018-08-31 12:54:11.276689014 +0000 UTC m=+213.947311172 End:2018-08-31 12:54:11.290388514 +0000 UTC m=+213.961010634
I0831 12:54:11.290425       1 scheduler.go:454] Total Schedule Algo cumulative time:5.321715061s for 618
I0831 12:54:11.302214       1 scheduler.go:451] ScheduleAlgoTime 11.648259ms Start:2018-08-31 12:54:11.290559705 +0000 UTC m=+213.961181851 End:2018-08-31 12:54:11.302207989 +0000 UTC m=+213.972830110
I0831 12:54:11.302252       1 scheduler.go:454] Total Schedule Algo cumulative time:5.33336332s for 619
I0831 12:54:11.314191       1 scheduler.go:451] ScheduleAlgoTime 11.824527ms Start:2018-08-31 12:54:11.302360188 +0000 UTC m=+213.972982363 End:2018-08-31 12:54:11.31418477 +0000 UTC m=+213.984806890
I0831 12:54:11.314220       1 scheduler.go:454] Total Schedule Algo cumulative time:5.345187847s for 620
I0831 12:54:11.325837       1 scheduler.go:451] ScheduleAlgoTime 11.518821ms Start:2018-08-31 12:54:11.314313715 +0000 UTC m=+213.984935868 End:2018-08-31 12:54:11.325832569 +0000 UTC m=+213.996454689
I0831 12:54:11.325864       1 scheduler.go:454] Total Schedule Algo cumulative time:5.356706668s for 621
I0831 12:54:11.343363       1 scheduler.go:451] ScheduleAlgoTime 17.408649ms Start:2018-08-31 12:54:11.325947189 +0000 UTC m=+213.996569338 End:2018-08-31 12:54:11.34335587 +0000 UTC m=+214.013977987
I0831 12:54:11.343402       1 scheduler.go:454] Total Schedule Algo cumulative time:5.374115317s for 622
I0831 12:54:11.355479       1 scheduler.go:451] ScheduleAlgoTime 11.953139ms Start:2018-08-31 12:54:11.343517604 +0000 UTC m=+214.014139765 End:2018-08-31 12:54:11.355470775 +0000 UTC m=+214.026092904
I0831 12:54:11.355527       1 scheduler.go:454] Total Schedule Algo cumulative time:5.386068456s for 623
I0831 12:54:11.368370       1 scheduler.go:451] ScheduleAlgoTime 12.732992ms Start:2018-08-31 12:54:11.355627772 +0000 UTC m=+214.026249928 End:2018-08-31 12:54:11.368360793 +0000 UTC m=+214.038982920
I0831 12:54:11.368414       1 scheduler.go:454] Total Schedule Algo cumulative time:5.398801448s for 624
I0831 12:54:11.379902       1 scheduler.go:451] ScheduleAlgoTime 11.367162ms Start:2018-08-31 12:54:11.368526601 +0000 UTC m=+214.039148753 End:2018-08-31 12:54:11.379893795 +0000 UTC m=+214.050515915
I0831 12:54:11.379943       1 scheduler.go:454] Total Schedule Algo cumulative time:5.41016861s for 625
I0831 12:54:11.393673       1 scheduler.go:451] ScheduleAlgoTime 13.627912ms Start:2018-08-31 12:54:11.380038522 +0000 UTC m=+214.050660678 End:2018-08-31 12:54:11.393666472 +0000 UTC m=+214.064288590
I0831 12:54:11.393704       1 scheduler.go:454] Total Schedule Algo cumulative time:5.423796522s for 626
I0831 12:54:11.405693       1 scheduler.go:451] ScheduleAlgoTime 11.897947ms Start:2018-08-31 12:54:11.393786056 +0000 UTC m=+214.064408201 End:2018-08-31 12:54:11.405684012 +0000 UTC m=+214.076306148
I0831 12:54:11.405736       1 scheduler.go:454] Total Schedule Algo cumulative time:5.435694469s for 627
I0831 12:54:11.419113       1 scheduler.go:451] ScheduleAlgoTime 13.298757ms Start:2018-08-31 12:54:11.405807003 +0000 UTC m=+214.076429152 End:2018-08-31 12:54:11.419105791 +0000 UTC m=+214.089727909
I0831 12:54:11.419151       1 scheduler.go:454] Total Schedule Algo cumulative time:5.448993226s for 628
I0831 12:54:11.432088       1 scheduler.go:451] ScheduleAlgoTime 12.840862ms Start:2018-08-31 12:54:11.419241013 +0000 UTC m=+214.089863148 End:2018-08-31 12:54:11.43208189 +0000 UTC m=+214.102704010
I0831 12:54:11.432119       1 scheduler.go:454] Total Schedule Algo cumulative time:5.461834088s for 629
I0831 12:54:11.444711       1 scheduler.go:451] ScheduleAlgoTime 12.498452ms Start:2018-08-31 12:54:11.432206023 +0000 UTC m=+214.102828176 End:2018-08-31 12:54:11.444704508 +0000 UTC m=+214.115326628
I0831 12:54:11.444750       1 scheduler.go:454] Total Schedule Algo cumulative time:5.47433254s for 630
I0831 12:54:11.456324       1 scheduler.go:451] ScheduleAlgoTime 11.477559ms Start:2018-08-31 12:54:11.444838153 +0000 UTC m=+214.115460327 End:2018-08-31 12:54:11.456315762 +0000 UTC m=+214.126937886
I0831 12:54:11.456361       1 scheduler.go:454] Total Schedule Algo cumulative time:5.485810099s for 631
I0831 12:54:11.468410       1 scheduler.go:451] ScheduleAlgoTime 11.961575ms Start:2018-08-31 12:54:11.456440377 +0000 UTC m=+214.127062524 End:2018-08-31 12:54:11.468401944 +0000 UTC m=+214.139024099
I0831 12:54:11.468464       1 scheduler.go:454] Total Schedule Algo cumulative time:5.497771674s for 632
I0831 12:54:11.480903       1 scheduler.go:451] ScheduleAlgoTime 12.343656ms Start:2018-08-31 12:54:11.468552727 +0000 UTC m=+214.139174879 End:2018-08-31 12:54:11.480896415 +0000 UTC m=+214.151518535
I0831 12:54:11.480937       1 scheduler.go:454] Total Schedule Algo cumulative time:5.51011533s for 633
I0831 12:54:11.493094       1 scheduler.go:451] ScheduleAlgoTime 12.062869ms Start:2018-08-31 12:54:11.481025005 +0000 UTC m=+214.151647169 End:2018-08-31 12:54:11.493087913 +0000 UTC m=+214.163710038
I0831 12:54:11.493127       1 scheduler.go:454] Total Schedule Algo cumulative time:5.522178199s for 634
I0831 12:54:11.507556       1 scheduler.go:451] ScheduleAlgoTime 14.307397ms Start:2018-08-31 12:54:11.493241875 +0000 UTC m=+214.163864054 End:2018-08-31 12:54:11.507549329 +0000 UTC m=+214.178171451
I0831 12:54:11.507590       1 scheduler.go:454] Total Schedule Algo cumulative time:5.536485596s for 635
I0831 12:54:11.520511       1 scheduler.go:451] ScheduleAlgoTime 12.808101ms Start:2018-08-31 12:54:11.507696701 +0000 UTC m=+214.178318858 End:2018-08-31 12:54:11.52050484 +0000 UTC m=+214.191126959
I0831 12:54:11.520546       1 scheduler.go:454] Total Schedule Algo cumulative time:5.549293697s for 636
I0831 12:54:11.539038       1 scheduler.go:451] ScheduleAlgoTime 18.376066ms Start:2018-08-31 12:54:11.520655369 +0000 UTC m=+214.191277528 End:2018-08-31 12:54:11.539031474 +0000 UTC m=+214.209653594
I0831 12:54:11.539080       1 scheduler.go:454] Total Schedule Algo cumulative time:5.567669763s for 637
I0831 12:54:11.553163       1 scheduler.go:451] ScheduleAlgoTime 13.986245ms Start:2018-08-31 12:54:11.539169102 +0000 UTC m=+214.209791267 End:2018-08-31 12:54:11.553155389 +0000 UTC m=+214.223777512
I0831 12:54:11.553193       1 scheduler.go:454] Total Schedule Algo cumulative time:5.581656008s for 638
I0831 12:54:11.565726       1 scheduler.go:451] ScheduleAlgoTime 12.44697ms Start:2018-08-31 12:54:11.55327146 +0000 UTC m=+214.223893634 End:2018-08-31 12:54:11.565718484 +0000 UTC m=+214.236340604
I0831 12:54:11.565769       1 scheduler.go:454] Total Schedule Algo cumulative time:5.594102978s for 639
I0831 12:54:11.578132       1 scheduler.go:451] ScheduleAlgoTime 12.258071ms Start:2018-08-31 12:54:11.565867471 +0000 UTC m=+214.236489617 End:2018-08-31 12:54:11.578125564 +0000 UTC m=+214.248747688
I0831 12:54:11.578172       1 scheduler.go:454] Total Schedule Algo cumulative time:5.606361049s for 640
I0831 12:54:11.590498       1 scheduler.go:451] ScheduleAlgoTime 12.228452ms Start:2018-08-31 12:54:11.578263428 +0000 UTC m=+214.248885622 End:2018-08-31 12:54:11.590491951 +0000 UTC m=+214.261114074
I0831 12:54:11.590528       1 scheduler.go:454] Total Schedule Algo cumulative time:5.618589501s for 641
I0831 12:54:11.602188       1 scheduler.go:451] ScheduleAlgoTime 11.566846ms Start:2018-08-31 12:54:11.590614531 +0000 UTC m=+214.261236677 End:2018-08-31 12:54:11.602181403 +0000 UTC m=+214.272803523
I0831 12:54:11.602218       1 scheduler.go:454] Total Schedule Algo cumulative time:5.630156347s for 642
I0831 12:54:11.613832       1 scheduler.go:451] ScheduleAlgoTime 11.497079ms Start:2018-08-31 12:54:11.602329764 +0000 UTC m=+214.272951958 End:2018-08-31 12:54:11.613826914 +0000 UTC m=+214.284449037
I0831 12:54:11.613862       1 scheduler.go:454] Total Schedule Algo cumulative time:5.641653426s for 643
I0831 12:54:11.625357       1 scheduler.go:451] ScheduleAlgoTime 11.412614ms Start:2018-08-31 12:54:11.613939597 +0000 UTC m=+214.284561750 End:2018-08-31 12:54:11.625352246 +0000 UTC m=+214.295974364
I0831 12:54:11.625387       1 scheduler.go:454] Total Schedule Algo cumulative time:5.65306604s for 644
I0831 12:54:11.636844       1 scheduler.go:451] ScheduleAlgoTime 11.366341ms Start:2018-08-31 12:54:11.6254724 +0000 UTC m=+214.296094542 End:2018-08-31 12:54:11.636838763 +0000 UTC m=+214.307460883
I0831 12:54:11.636876       1 scheduler.go:454] Total Schedule Algo cumulative time:5.664432381s for 645
I0831 12:54:11.649362       1 scheduler.go:451] ScheduleAlgoTime 12.371928ms Start:2018-08-31 12:54:11.636984945 +0000 UTC m=+214.307607101 End:2018-08-31 12:54:11.649356911 +0000 UTC m=+214.319979029
I0831 12:54:11.649392       1 scheduler.go:454] Total Schedule Algo cumulative time:5.676804309s for 646
I0831 12:54:11.661653       1 scheduler.go:451] ScheduleAlgoTime 12.109508ms Start:2018-08-31 12:54:11.649537261 +0000 UTC m=+214.320159407 End:2018-08-31 12:54:11.661646797 +0000 UTC m=+214.332268915
I0831 12:54:11.661682       1 scheduler.go:454] Total Schedule Algo cumulative time:5.688913817s for 647
I0831 12:54:11.673473       1 scheduler.go:451] ScheduleAlgoTime 11.691258ms Start:2018-08-31 12:54:11.66177752 +0000 UTC m=+214.332399682 End:2018-08-31 12:54:11.67346882 +0000 UTC m=+214.344090940
I0831 12:54:11.673518       1 scheduler.go:454] Total Schedule Algo cumulative time:5.700605075s for 648
I0831 12:54:11.685422       1 scheduler.go:451] ScheduleAlgoTime 11.809528ms Start:2018-08-31 12:54:11.67360636 +0000 UTC m=+214.344228514 End:2018-08-31 12:54:11.685415923 +0000 UTC m=+214.356038042
I0831 12:54:11.685463       1 scheduler.go:454] Total Schedule Algo cumulative time:5.712414603s for 649
I0831 12:54:11.697392       1 scheduler.go:451] ScheduleAlgoTime 11.842577ms Start:2018-08-31 12:54:11.685543951 +0000 UTC m=+214.356166081 End:2018-08-31 12:54:11.697386537 +0000 UTC m=+214.368008658
I0831 12:54:11.697424       1 scheduler.go:454] Total Schedule Algo cumulative time:5.72425718s for 650
I0831 12:54:11.711059       1 scheduler.go:451] ScheduleAlgoTime 13.524313ms Start:2018-08-31 12:54:11.697522134 +0000 UTC m=+214.368144292 End:2018-08-31 12:54:11.711046486 +0000 UTC m=+214.381668605
I0831 12:54:11.711087       1 scheduler.go:454] Total Schedule Algo cumulative time:5.737781493s for 651
I0831 12:54:11.726830       1 scheduler.go:451] ScheduleAlgoTime 15.653162ms Start:2018-08-31 12:54:11.711171147 +0000 UTC m=+214.381793294 End:2018-08-31 12:54:11.726824333 +0000 UTC m=+214.397446456
I0831 12:54:11.726869       1 scheduler.go:454] Total Schedule Algo cumulative time:5.753434655s for 652
I0831 12:54:11.739532       1 scheduler.go:451] ScheduleAlgoTime 12.561029ms Start:2018-08-31 12:54:11.72696601 +0000 UTC m=+214.397588174 End:2018-08-31 12:54:11.739527084 +0000 UTC m=+214.410149203
I0831 12:54:11.739585       1 scheduler.go:454] Total Schedule Algo cumulative time:5.765995684s for 653
I0831 12:54:11.752193       1 scheduler.go:451] ScheduleAlgoTime 12.518195ms Start:2018-08-31 12:54:11.739669767 +0000 UTC m=+214.410291909 End:2018-08-31 12:54:11.752187984 +0000 UTC m=+214.422810104
I0831 12:54:11.752231       1 scheduler.go:454] Total Schedule Algo cumulative time:5.778513879s for 654
I0831 12:54:11.764054       1 scheduler.go:451] ScheduleAlgoTime 11.612726ms Start:2018-08-31 12:54:11.752435211 +0000 UTC m=+214.423057365 End:2018-08-31 12:54:11.764047969 +0000 UTC m=+214.434670091
I0831 12:54:11.764095       1 scheduler.go:454] Total Schedule Algo cumulative time:5.790126605s for 655
I0831 12:54:11.776923       1 scheduler.go:451] ScheduleAlgoTime 12.744233ms Start:2018-08-31 12:54:11.764172574 +0000 UTC m=+214.434794715 End:2018-08-31 12:54:11.776916828 +0000 UTC m=+214.447538948
I0831 12:54:11.776955       1 scheduler.go:454] Total Schedule Algo cumulative time:5.802870838s for 656
I0831 12:54:11.789977       1 scheduler.go:451] ScheduleAlgoTime 12.920479ms Start:2018-08-31 12:54:11.77705133 +0000 UTC m=+214.447673493 End:2018-08-31 12:54:11.789971852 +0000 UTC m=+214.460593972
I0831 12:54:11.790009       1 scheduler.go:454] Total Schedule Algo cumulative time:5.815791317s for 657
I0831 12:54:11.802818       1 scheduler.go:451] ScheduleAlgoTime 12.714289ms Start:2018-08-31 12:54:11.790097621 +0000 UTC m=+214.460719824 End:2018-08-31 12:54:11.802811993 +0000 UTC m=+214.473434113
I0831 12:54:11.802857       1 scheduler.go:454] Total Schedule Algo cumulative time:5.828505606s for 658
I0831 12:54:11.815058       1 scheduler.go:451] ScheduleAlgoTime 12.088843ms Start:2018-08-31 12:54:11.802962375 +0000 UTC m=+214.473584517 End:2018-08-31 12:54:11.815051233 +0000 UTC m=+214.485673360
I0831 12:54:11.815117       1 scheduler.go:454] Total Schedule Algo cumulative time:5.840594449s for 659
I0831 12:54:11.828782       1 scheduler.go:451] ScheduleAlgoTime 13.536996ms Start:2018-08-31 12:54:11.815239741 +0000 UTC m=+214.485861902 End:2018-08-31 12:54:11.828776777 +0000 UTC m=+214.499398898
I0831 12:54:11.828815       1 scheduler.go:454] Total Schedule Algo cumulative time:5.854131445s for 660
I0831 12:54:11.841517       1 scheduler.go:451] ScheduleAlgoTime 12.602793ms Start:2018-08-31 12:54:11.828906148 +0000 UTC m=+214.499528297 End:2018-08-31 12:54:11.841508953 +0000 UTC m=+214.512131090
I0831 12:54:11.841556       1 scheduler.go:454] Total Schedule Algo cumulative time:5.866734238s for 661
I0831 12:54:11.855386       1 scheduler.go:451] ScheduleAlgoTime 13.732995ms Start:2018-08-31 12:54:11.841646622 +0000 UTC m=+214.512268817 End:2018-08-31 12:54:11.85537969 +0000 UTC m=+214.526001812
I0831 12:54:11.855422       1 scheduler.go:454] Total Schedule Algo cumulative time:5.880467233s for 662
I0831 12:54:11.871888       1 scheduler.go:451] ScheduleAlgoTime 16.367237ms Start:2018-08-31 12:54:11.855513893 +0000 UTC m=+214.526136049 End:2018-08-31 12:54:11.871881166 +0000 UTC m=+214.542503286
I0831 12:54:11.871932       1 scheduler.go:454] Total Schedule Algo cumulative time:5.89683447s for 663
I0831 12:54:11.898444       1 scheduler.go:451] ScheduleAlgoTime 26.39139ms Start:2018-08-31 12:54:11.872040541 +0000 UTC m=+214.542662699 End:2018-08-31 12:54:11.898431957 +0000 UTC m=+214.569054089
I0831 12:54:11.898600       1 scheduler.go:454] Total Schedule Algo cumulative time:5.92322586s for 664
I0831 12:54:11.914916       1 scheduler.go:451] ScheduleAlgoTime 15.154715ms Start:2018-08-31 12:54:11.899754177 +0000 UTC m=+214.570376358 End:2018-08-31 12:54:11.914908954 +0000 UTC m=+214.585531073
I0831 12:54:11.914963       1 scheduler.go:454] Total Schedule Algo cumulative time:5.938380575s for 665
I0831 12:54:11.927916       1 scheduler.go:451] ScheduleAlgoTime 12.862738ms Start:2018-08-31 12:54:11.915047245 +0000 UTC m=+214.585669412 End:2018-08-31 12:54:11.927910025 +0000 UTC m=+214.598532150
I0831 12:54:11.927948       1 scheduler.go:454] Total Schedule Algo cumulative time:5.951243313s for 666
I0831 12:54:11.946802       1 scheduler.go:451] ScheduleAlgoTime 18.767661ms Start:2018-08-31 12:54:11.928026138 +0000 UTC m=+214.598648303 End:2018-08-31 12:54:11.946793837 +0000 UTC m=+214.617415964
I0831 12:54:11.946842       1 scheduler.go:454] Total Schedule Algo cumulative time:5.970010974s for 667
I0831 12:54:11.959107       1 scheduler.go:451] ScheduleAlgoTime 12.171489ms Start:2018-08-31 12:54:11.946930421 +0000 UTC m=+214.617552586 End:2018-08-31 12:54:11.959101955 +0000 UTC m=+214.629724075
I0831 12:54:11.959140       1 scheduler.go:454] Total Schedule Algo cumulative time:5.982182463s for 668
I0831 12:54:11.971763       1 scheduler.go:451] ScheduleAlgoTime 12.522405ms Start:2018-08-31 12:54:11.959234109 +0000 UTC m=+214.629856269 End:2018-08-31 12:54:11.971756555 +0000 UTC m=+214.642378674
I0831 12:54:11.971804       1 scheduler.go:454] Total Schedule Algo cumulative time:5.994704868s for 669
I0831 12:54:11.985838       1 scheduler.go:451] ScheduleAlgoTime 13.936581ms Start:2018-08-31 12:54:11.971893869 +0000 UTC m=+214.642516017 End:2018-08-31 12:54:11.985830476 +0000 UTC m=+214.656452598
I0831 12:54:11.985889       1 scheduler.go:454] Total Schedule Algo cumulative time:6.008641449s for 670
I0831 12:54:11.999669       1 scheduler.go:451] ScheduleAlgoTime 13.67313ms Start:2018-08-31 12:54:11.985989306 +0000 UTC m=+214.656611467 End:2018-08-31 12:54:11.999662476 +0000 UTC m=+214.670284597
I0831 12:54:11.999705       1 scheduler.go:454] Total Schedule Algo cumulative time:6.022314579s for 671
I0831 12:54:12.013406       1 scheduler.go:451] ScheduleAlgoTime 13.607797ms Start:2018-08-31 12:54:11.99979106 +0000 UTC m=+214.670413213 End:2018-08-31 12:54:12.013398889 +0000 UTC m=+214.684021010
I0831 12:54:12.013461       1 scheduler.go:454] Total Schedule Algo cumulative time:6.035922376s for 672
I0831 12:54:12.025989       1 scheduler.go:451] ScheduleAlgoTime 12.437124ms Start:2018-08-31 12:54:12.013546812 +0000 UTC m=+214.684168964 End:2018-08-31 12:54:12.025983968 +0000 UTC m=+214.696606088
I0831 12:54:12.026024       1 scheduler.go:454] Total Schedule Algo cumulative time:6.0483595s for 673
I0831 12:54:12.038866       1 scheduler.go:451] ScheduleAlgoTime 12.738629ms Start:2018-08-31 12:54:12.026121612 +0000 UTC m=+214.696743763 End:2018-08-31 12:54:12.038860269 +0000 UTC m=+214.709482392
I0831 12:54:12.038901       1 scheduler.go:454] Total Schedule Algo cumulative time:6.061098129s for 674
I0831 12:54:12.050925       1 scheduler.go:451] ScheduleAlgoTime 11.931105ms Start:2018-08-31 12:54:12.038988075 +0000 UTC m=+214.709610227 End:2018-08-31 12:54:12.050919209 +0000 UTC m=+214.721541332
I0831 12:54:12.050953       1 scheduler.go:454] Total Schedule Algo cumulative time:6.073029234s for 675
I0831 12:54:12.063068       1 scheduler.go:451] ScheduleAlgoTime 12.021568ms Start:2018-08-31 12:54:12.051040166 +0000 UTC m=+214.721662323 End:2018-08-31 12:54:12.063061773 +0000 UTC m=+214.733683891
I0831 12:54:12.063102       1 scheduler.go:454] Total Schedule Algo cumulative time:6.085050802s for 676
I0831 12:54:12.076894       1 scheduler.go:451] ScheduleAlgoTime 13.682241ms Start:2018-08-31 12:54:12.063206108 +0000 UTC m=+214.733828262 End:2018-08-31 12:54:12.076888383 +0000 UTC m=+214.747510503
I0831 12:54:12.076927       1 scheduler.go:454] Total Schedule Algo cumulative time:6.098733043s for 677
I0831 12:54:12.089598       1 scheduler.go:451] ScheduleAlgoTime 12.56904ms Start:2018-08-31 12:54:12.077023418 +0000 UTC m=+214.747645574 End:2018-08-31 12:54:12.089592493 +0000 UTC m=+214.760214614
I0831 12:54:12.089634       1 scheduler.go:454] Total Schedule Algo cumulative time:6.111302083s for 678
I0831 12:54:12.103706       1 scheduler.go:451] ScheduleAlgoTime 13.969033ms Start:2018-08-31 12:54:12.089731122 +0000 UTC m=+214.760353289 End:2018-08-31 12:54:12.103700199 +0000 UTC m=+214.774322322
I0831 12:54:12.103737       1 scheduler.go:454] Total Schedule Algo cumulative time:6.125271116s for 679
I0831 12:54:12.118078       1 scheduler.go:451] ScheduleAlgoTime 14.247327ms Start:2018-08-31 12:54:12.103824461 +0000 UTC m=+214.774446638 End:2018-08-31 12:54:12.118071841 +0000 UTC m=+214.788693965
I0831 12:54:12.118109       1 scheduler.go:454] Total Schedule Algo cumulative time:6.139518443s for 680
I0831 12:54:12.135190       1 scheduler.go:451] ScheduleAlgoTime 16.989616ms Start:2018-08-31 12:54:12.118194964 +0000 UTC m=+214.788817106 End:2018-08-31 12:54:12.135184604 +0000 UTC m=+214.805806722
I0831 12:54:12.135221       1 scheduler.go:454] Total Schedule Algo cumulative time:6.156508059s for 681
I0831 12:54:12.147566       1 scheduler.go:451] ScheduleAlgoTime 12.236725ms Start:2018-08-31 12:54:12.135321316 +0000 UTC m=+214.805943478 End:2018-08-31 12:54:12.147558061 +0000 UTC m=+214.818180203
I0831 12:54:12.147604       1 scheduler.go:454] Total Schedule Algo cumulative time:6.168744784s for 682
I0831 12:54:12.160042       1 scheduler.go:451] ScheduleAlgoTime 12.360588ms Start:2018-08-31 12:54:12.147674568 +0000 UTC m=+214.818296732 End:2018-08-31 12:54:12.160035201 +0000 UTC m=+214.830657320
I0831 12:54:12.160085       1 scheduler.go:454] Total Schedule Algo cumulative time:6.181105372s for 683
I0831 12:54:12.172015       1 scheduler.go:451] ScheduleAlgoTime 11.839578ms Start:2018-08-31 12:54:12.16017041 +0000 UTC m=+214.830792555 End:2018-08-31 12:54:12.172010015 +0000 UTC m=+214.842632133
I0831 12:54:12.172043       1 scheduler.go:454] Total Schedule Algo cumulative time:6.19294495s for 684
I0831 12:54:12.185973       1 scheduler.go:451] ScheduleAlgoTime 13.827505ms Start:2018-08-31 12:54:12.17214052 +0000 UTC m=+214.842762678 End:2018-08-31 12:54:12.185968065 +0000 UTC m=+214.856590183
I0831 12:54:12.186007       1 scheduler.go:454] Total Schedule Algo cumulative time:6.206772455s for 685
I0831 12:54:12.199837       1 scheduler.go:451] ScheduleAlgoTime 13.728224ms Start:2018-08-31 12:54:12.186101233 +0000 UTC m=+214.856723390 End:2018-08-31 12:54:12.199829491 +0000 UTC m=+214.870451614
I0831 12:54:12.199877       1 scheduler.go:454] Total Schedule Algo cumulative time:6.220500679s for 686
I0831 12:54:12.214273       1 scheduler.go:451] ScheduleAlgoTime 14.259706ms Start:2018-08-31 12:54:12.200007386 +0000 UTC m=+214.870629550 End:2018-08-31 12:54:12.214267137 +0000 UTC m=+214.884889256
I0831 12:54:12.214305       1 scheduler.go:454] Total Schedule Algo cumulative time:6.234760385s for 687
I0831 12:54:12.227572       1 scheduler.go:451] ScheduleAlgoTime 13.18139ms Start:2018-08-31 12:54:12.214385094 +0000 UTC m=+214.885007234 End:2018-08-31 12:54:12.227566504 +0000 UTC m=+214.898188624
I0831 12:54:12.227601       1 scheduler.go:454] Total Schedule Algo cumulative time:6.247941775s for 688
I0831 12:54:12.241425       1 scheduler.go:451] ScheduleAlgoTime 13.729653ms Start:2018-08-31 12:54:12.227690517 +0000 UTC m=+214.898312673 End:2018-08-31 12:54:12.241420203 +0000 UTC m=+214.912042326
I0831 12:54:12.241468       1 scheduler.go:454] Total Schedule Algo cumulative time:6.261671428s for 689
I0831 12:54:12.254341       1 scheduler.go:451] ScheduleAlgoTime 12.791127ms Start:2018-08-31 12:54:12.24154459 +0000 UTC m=+214.912166750 End:2018-08-31 12:54:12.254335758 +0000 UTC m=+214.924957877
I0831 12:54:12.254376       1 scheduler.go:454] Total Schedule Algo cumulative time:6.274462555s for 690
I0831 12:54:12.268354       1 scheduler.go:451] ScheduleAlgoTime 13.887622ms Start:2018-08-31 12:54:12.25446146 +0000 UTC m=+214.925083613 End:2018-08-31 12:54:12.268349112 +0000 UTC m=+214.938971235
I0831 12:54:12.268383       1 scheduler.go:454] Total Schedule Algo cumulative time:6.288350177s for 691
I0831 12:54:12.281207       1 scheduler.go:451] ScheduleAlgoTime 12.724839ms Start:2018-08-31 12:54:12.268476451 +0000 UTC m=+214.939098607 End:2018-08-31 12:54:12.281201325 +0000 UTC m=+214.951823446
I0831 12:54:12.281236       1 scheduler.go:454] Total Schedule Algo cumulative time:6.301075016s for 692
I0831 12:54:12.294322       1 scheduler.go:451] ScheduleAlgoTime 13.008681ms Start:2018-08-31 12:54:12.281306982 +0000 UTC m=+214.951929130 End:2018-08-31 12:54:12.294315689 +0000 UTC m=+214.964937811
I0831 12:54:12.294350       1 scheduler.go:454] Total Schedule Algo cumulative time:6.314083697s for 693
I0831 12:54:12.308427       1 scheduler.go:451] ScheduleAlgoTime 13.992461ms Start:2018-08-31 12:54:12.29442907 +0000 UTC m=+214.965051222 End:2018-08-31 12:54:12.308421564 +0000 UTC m=+214.979043683
I0831 12:54:12.308464       1 scheduler.go:454] Total Schedule Algo cumulative time:6.328076158s for 694
I0831 12:54:12.324788       1 scheduler.go:451] ScheduleAlgoTime 16.218595ms Start:2018-08-31 12:54:12.308562278 +0000 UTC m=+214.979184427 End:2018-08-31 12:54:12.324780902 +0000 UTC m=+214.995403022
I0831 12:54:12.324824       1 scheduler.go:454] Total Schedule Algo cumulative time:6.344294753s for 695
I0831 12:54:12.337199       1 scheduler.go:451] ScheduleAlgoTime 12.272851ms Start:2018-08-31 12:54:12.324918778 +0000 UTC m=+214.995540934 End:2018-08-31 12:54:12.337191655 +0000 UTC m=+215.007813785
I0831 12:54:12.337241       1 scheduler.go:454] Total Schedule Algo cumulative time:6.356567604s for 696
I0831 12:54:12.349178       1 scheduler.go:451] ScheduleAlgoTime 11.841437ms Start:2018-08-31 12:54:12.33733183 +0000 UTC m=+215.007954025 End:2018-08-31 12:54:12.349173342 +0000 UTC m=+215.019795462
I0831 12:54:12.349212       1 scheduler.go:454] Total Schedule Algo cumulative time:6.368409041s for 697
I0831 12:54:12.362798       1 scheduler.go:451] ScheduleAlgoTime 13.509086ms Start:2018-08-31 12:54:12.349281031 +0000 UTC m=+215.019903190 End:2018-08-31 12:54:12.362790156 +0000 UTC m=+215.033412276
I0831 12:54:12.362839       1 scheduler.go:454] Total Schedule Algo cumulative time:6.381918127s for 698
I0831 12:54:12.376884       1 scheduler.go:451] ScheduleAlgoTime 13.947473ms Start:2018-08-31 12:54:12.362931184 +0000 UTC m=+215.033553345 End:2018-08-31 12:54:12.376878695 +0000 UTC m=+215.047500818
I0831 12:54:12.376927       1 scheduler.go:454] Total Schedule Algo cumulative time:6.3958656s for 699
I0831 12:54:12.389572       1 scheduler.go:451] ScheduleAlgoTime 12.506664ms Start:2018-08-31 12:54:12.377057937 +0000 UTC m=+215.047680086 End:2018-08-31 12:54:12.389564626 +0000 UTC m=+215.060186750
I0831 12:54:12.389618       1 scheduler.go:454] Total Schedule Algo cumulative time:6.408372264s for 700
I0831 12:54:12.401952       1 scheduler.go:451] ScheduleAlgoTime 12.215386ms Start:2018-08-31 12:54:12.389731202 +0000 UTC m=+215.060353362 End:2018-08-31 12:54:12.40194663 +0000 UTC m=+215.072568748
I0831 12:54:12.401986       1 scheduler.go:454] Total Schedule Algo cumulative time:6.42058765s for 701
I0831 12:54:12.416623       1 scheduler.go:451] ScheduleAlgoTime 14.535424ms Start:2018-08-31 12:54:12.402082614 +0000 UTC m=+215.072704779 End:2018-08-31 12:54:12.416618085 +0000 UTC m=+215.087240203
I0831 12:54:12.416652       1 scheduler.go:454] Total Schedule Algo cumulative time:6.435123074s for 702
I0831 12:54:12.429887       1 scheduler.go:451] ScheduleAlgoTime 13.143695ms Start:2018-08-31 12:54:12.416738216 +0000 UTC m=+215.087360363 End:2018-08-31 12:54:12.429881936 +0000 UTC m=+215.100504058
I0831 12:54:12.429918       1 scheduler.go:454] Total Schedule Algo cumulative time:6.448266769s for 703
I0831 12:54:12.442309       1 scheduler.go:451] ScheduleAlgoTime 12.302552ms Start:2018-08-31 12:54:12.429998176 +0000 UTC m=+215.100620340 End:2018-08-31 12:54:12.442300765 +0000 UTC m=+215.112922892
I0831 12:54:12.442344       1 scheduler.go:454] Total Schedule Algo cumulative time:6.460569321s for 704
I0831 12:54:12.456234       1 scheduler.go:451] ScheduleAlgoTime 13.781156ms Start:2018-08-31 12:54:12.442446802 +0000 UTC m=+215.113068951 End:2018-08-31 12:54:12.456227987 +0000 UTC m=+215.126850107
I0831 12:54:12.456265       1 scheduler.go:454] Total Schedule Algo cumulative time:6.474350477s for 705
I0831 12:54:12.468567       1 scheduler.go:451] ScheduleAlgoTime 12.201133ms Start:2018-08-31 12:54:12.4563607 +0000 UTC m=+215.126982879 End:2018-08-31 12:54:12.468561892 +0000 UTC m=+215.139184012
I0831 12:54:12.468598       1 scheduler.go:454] Total Schedule Algo cumulative time:6.48655161s for 706
I0831 12:54:12.482738       1 scheduler.go:451] ScheduleAlgoTime 14.040653ms Start:2018-08-31 12:54:12.468690487 +0000 UTC m=+215.139312638 End:2018-08-31 12:54:12.482731165 +0000 UTC m=+215.153353291
I0831 12:54:12.482780       1 scheduler.go:454] Total Schedule Algo cumulative time:6.500592263s for 707
I0831 12:54:12.494650       1 scheduler.go:451] ScheduleAlgoTime 11.787318ms Start:2018-08-31 12:54:12.482856389 +0000 UTC m=+215.153478557 End:2018-08-31 12:54:12.494643755 +0000 UTC m=+215.165265875
I0831 12:54:12.494679       1 scheduler.go:454] Total Schedule Algo cumulative time:6.512379581s for 708
I0831 12:54:12.510922       1 scheduler.go:451] ScheduleAlgoTime 16.156737ms Start:2018-08-31 12:54:12.494757013 +0000 UTC m=+215.165379153 End:2018-08-31 12:54:12.510913745 +0000 UTC m=+215.181535890
I0831 12:54:12.510982       1 scheduler.go:454] Total Schedule Algo cumulative time:6.528536318s for 709
I0831 12:54:12.532358       1 scheduler.go:451] ScheduleAlgoTime 21.252073ms Start:2018-08-31 12:54:12.51109624 +0000 UTC m=+215.181718377 End:2018-08-31 12:54:12.532348323 +0000 UTC m=+215.202970450
I0831 12:54:12.532409       1 scheduler.go:454] Total Schedule Algo cumulative time:6.549788391s for 710
I0831 12:54:12.553141       1 scheduler.go:451] ScheduleAlgoTime 20.601213ms Start:2018-08-31 12:54:12.532529898 +0000 UTC m=+215.203152039 End:2018-08-31 12:54:12.553131029 +0000 UTC m=+215.223753252
I0831 12:54:12.553881       1 scheduler.go:454] Total Schedule Algo cumulative time:6.570389604s for 711
I0831 12:54:12.570951       1 scheduler.go:451] ScheduleAlgoTime 16.772335ms Start:2018-08-31 12:54:12.55417022 +0000 UTC m=+215.224792350 End:2018-08-31 12:54:12.570942555 +0000 UTC m=+215.241564685
I0831 12:54:12.571008       1 scheduler.go:454] Total Schedule Algo cumulative time:6.587161939s for 712
I0831 12:54:12.585370       1 scheduler.go:451] ScheduleAlgoTime 14.213299ms Start:2018-08-31 12:54:12.571149834 +0000 UTC m=+215.241771987 End:2018-08-31 12:54:12.585363168 +0000 UTC m=+215.255985286
I0831 12:54:12.585407       1 scheduler.go:454] Total Schedule Algo cumulative time:6.601375238s for 713
I0831 12:54:12.600661       1 scheduler.go:451] ScheduleAlgoTime 15.158006ms Start:2018-08-31 12:54:12.585497148 +0000 UTC m=+215.256119294 End:2018-08-31 12:54:12.60065518 +0000 UTC m=+215.271277300
I0831 12:54:12.600700       1 scheduler.go:454] Total Schedule Algo cumulative time:6.616533244s for 714
I0831 12:54:12.615494       1 scheduler.go:451] ScheduleAlgoTime 14.665229ms Start:2018-08-31 12:54:12.600803403 +0000 UTC m=+215.271425551 End:2018-08-31 12:54:12.615468641 +0000 UTC m=+215.286090780
I0831 12:54:12.615538       1 scheduler.go:454] Total Schedule Algo cumulative time:6.631198473s for 715
I0831 12:54:12.634628       1 scheduler.go:451] ScheduleAlgoTime 18.969554ms Start:2018-08-31 12:54:12.615650063 +0000 UTC m=+215.286272208 End:2018-08-31 12:54:12.634619612 +0000 UTC m=+215.305241762
I0831 12:54:12.634675       1 scheduler.go:454] Total Schedule Algo cumulative time:6.650168027s for 716
I0831 12:54:12.650047       1 scheduler.go:451] ScheduleAlgoTime 15.255982ms Start:2018-08-31 12:54:12.634783735 +0000 UTC m=+215.305405937 End:2018-08-31 12:54:12.650039798 +0000 UTC m=+215.320661919
I0831 12:54:12.650082       1 scheduler.go:454] Total Schedule Algo cumulative time:6.665424009s for 717
I0831 12:54:12.663624       1 scheduler.go:451] ScheduleAlgoTime 13.444672ms Start:2018-08-31 12:54:12.650173186 +0000 UTC m=+215.320795339 End:2018-08-31 12:54:12.663617887 +0000 UTC m=+215.334240011
I0831 12:54:12.663656       1 scheduler.go:454] Total Schedule Algo cumulative time:6.678868681s for 718
I0831 12:54:12.677133       1 scheduler.go:451] ScheduleAlgoTime 13.378371ms Start:2018-08-31 12:54:12.663749719 +0000 UTC m=+215.334371890 End:2018-08-31 12:54:12.677128143 +0000 UTC m=+215.347750261
I0831 12:54:12.677163       1 scheduler.go:454] Total Schedule Algo cumulative time:6.692247052s for 719
I0831 12:54:12.690964       1 scheduler.go:451] ScheduleAlgoTime 13.714173ms Start:2018-08-31 12:54:12.67724519 +0000 UTC m=+215.347867338 End:2018-08-31 12:54:12.690959392 +0000 UTC m=+215.361581511
I0831 12:54:12.690997       1 scheduler.go:454] Total Schedule Algo cumulative time:6.705961225s for 720
I0831 12:54:12.703042       1 scheduler.go:451] ScheduleAlgoTime 11.95463ms Start:2018-08-31 12:54:12.691081184 +0000 UTC m=+215.361703339 End:2018-08-31 12:54:12.703035844 +0000 UTC m=+215.373657969
I0831 12:54:12.703080       1 scheduler.go:454] Total Schedule Algo cumulative time:6.717915855s for 721
I0831 12:54:12.715776       1 scheduler.go:451] ScheduleAlgoTime 12.600843ms Start:2018-08-31 12:54:12.703169875 +0000 UTC m=+215.373792047 End:2018-08-31 12:54:12.715770771 +0000 UTC m=+215.386392890
I0831 12:54:12.715812       1 scheduler.go:454] Total Schedule Algo cumulative time:6.730516698s for 722
I0831 12:54:12.729846       1 scheduler.go:451] ScheduleAlgoTime 13.941215ms Start:2018-08-31 12:54:12.715897429 +0000 UTC m=+215.386519575 End:2018-08-31 12:54:12.729838667 +0000 UTC m=+215.400460790
I0831 12:54:12.729880       1 scheduler.go:454] Total Schedule Algo cumulative time:6.744457913s for 723
I0831 12:54:12.747501       1 scheduler.go:451] ScheduleAlgoTime 17.53849ms Start:2018-08-31 12:54:12.729957306 +0000 UTC m=+215.400579476 End:2018-08-31 12:54:12.747495846 +0000 UTC m=+215.418117966
I0831 12:54:12.747536       1 scheduler.go:454] Total Schedule Algo cumulative time:6.761996403s for 724
I0831 12:54:12.762752       1 scheduler.go:451] ScheduleAlgoTime 15.107088ms Start:2018-08-31 12:54:12.747636852 +0000 UTC m=+215.418258994 End:2018-08-31 12:54:12.762743948 +0000 UTC m=+215.433366082
I0831 12:54:12.762793       1 scheduler.go:454] Total Schedule Algo cumulative time:6.777103491s for 725
I0831 12:54:12.775765       1 scheduler.go:451] ScheduleAlgoTime 12.870686ms Start:2018-08-31 12:54:12.762888088 +0000 UTC m=+215.433510236 End:2018-08-31 12:54:12.7757588 +0000 UTC m=+215.446380922
I0831 12:54:12.775803       1 scheduler.go:454] Total Schedule Algo cumulative time:6.789974177s for 726
I0831 12:54:12.789382       1 scheduler.go:451] ScheduleAlgoTime 13.476412ms Start:2018-08-31 12:54:12.775900745 +0000 UTC m=+215.446522927 End:2018-08-31 12:54:12.789377216 +0000 UTC m=+215.459999339
I0831 12:54:12.789420       1 scheduler.go:454] Total Schedule Algo cumulative time:6.803450589s for 727
I0831 12:54:12.802902       1 scheduler.go:451] ScheduleAlgoTime 13.377035ms Start:2018-08-31 12:54:12.789519385 +0000 UTC m=+215.460141546 End:2018-08-31 12:54:12.802896458 +0000 UTC m=+215.473518581
I0831 12:54:12.802933       1 scheduler.go:454] Total Schedule Algo cumulative time:6.816827624s for 728
I0831 12:54:12.814702       1 scheduler.go:451] ScheduleAlgoTime 11.67795ms Start:2018-08-31 12:54:12.803019177 +0000 UTC m=+215.473641329 End:2018-08-31 12:54:12.814697158 +0000 UTC m=+215.485319279
I0831 12:54:12.814728       1 scheduler.go:454] Total Schedule Algo cumulative time:6.828505574s for 729
I0831 12:54:12.829681       1 scheduler.go:451] ScheduleAlgoTime 14.855749ms Start:2018-08-31 12:54:12.814817455 +0000 UTC m=+215.485439619 End:2018-08-31 12:54:12.829673247 +0000 UTC m=+215.500295368
I0831 12:54:12.829719       1 scheduler.go:454] Total Schedule Algo cumulative time:6.843361323s for 730
I0831 12:54:12.842586       1 scheduler.go:451] ScheduleAlgoTime 12.787298ms Start:2018-08-31 12:54:12.829778352 +0000 UTC m=+215.500400505 End:2018-08-31 12:54:12.842565677 +0000 UTC m=+215.513187803
I0831 12:54:12.842614       1 scheduler.go:454] Total Schedule Algo cumulative time:6.856148621s for 731
I0831 12:54:12.856338       1 scheduler.go:451] ScheduleAlgoTime 13.644903ms Start:2018-08-31 12:54:12.842687687 +0000 UTC m=+215.513309873 End:2018-08-31 12:54:12.856332657 +0000 UTC m=+215.526954776
I0831 12:54:12.856370       1 scheduler.go:454] Total Schedule Algo cumulative time:6.869793524s for 732
I0831 12:54:12.869545       1 scheduler.go:451] ScheduleAlgoTime 13.090421ms Start:2018-08-31 12:54:12.856450288 +0000 UTC m=+215.527072440 End:2018-08-31 12:54:12.869540741 +0000 UTC m=+215.540162861
I0831 12:54:12.869582       1 scheduler.go:454] Total Schedule Algo cumulative time:6.882883945s for 733
I0831 12:54:12.883687       1 scheduler.go:451] ScheduleAlgoTime 14.020296ms Start:2018-08-31 12:54:12.869661878 +0000 UTC m=+215.540284026 End:2018-08-31 12:54:12.883682203 +0000 UTC m=+215.554304322
I0831 12:54:12.883717       1 scheduler.go:454] Total Schedule Algo cumulative time:6.896904241s for 734
I0831 12:54:12.896767       1 scheduler.go:451] ScheduleAlgoTime 12.912573ms Start:2018-08-31 12:54:12.883846667 +0000 UTC m=+215.554468867 End:2018-08-31 12:54:12.896759296 +0000 UTC m=+215.567381440
I0831 12:54:12.896802       1 scheduler.go:454] Total Schedule Algo cumulative time:6.909816814s for 735
I0831 12:54:12.911052       1 scheduler.go:451] ScheduleAlgoTime 14.159447ms Start:2018-08-31 12:54:12.896887478 +0000 UTC m=+215.567509643 End:2018-08-31 12:54:12.91104697 +0000 UTC m=+215.581669090
I0831 12:54:12.911083       1 scheduler.go:454] Total Schedule Algo cumulative time:6.923976261s for 736
I0831 12:54:12.922880       1 scheduler.go:451] ScheduleAlgoTime 11.699561ms Start:2018-08-31 12:54:12.911175094 +0000 UTC m=+215.581797245 End:2018-08-31 12:54:12.922874687 +0000 UTC m=+215.593496806
I0831 12:54:12.922908       1 scheduler.go:454] Total Schedule Algo cumulative time:6.935675822s for 737
I0831 12:54:12.941875       1 scheduler.go:451] ScheduleAlgoTime 18.884146ms Start:2018-08-31 12:54:12.922984398 +0000 UTC m=+215.593606571 End:2018-08-31 12:54:12.941868592 +0000 UTC m=+215.612490717
I0831 12:54:12.941911       1 scheduler.go:454] Total Schedule Algo cumulative time:6.954559968s for 738
I0831 12:54:12.955846       1 scheduler.go:451] ScheduleAlgoTime 13.840192ms Start:2018-08-31 12:54:12.941998763 +0000 UTC m=+215.612620933 End:2018-08-31 12:54:12.955839002 +0000 UTC m=+215.626461125
I0831 12:54:12.955892       1 scheduler.go:454] Total Schedule Algo cumulative time:6.96840016s for 739
I0831 12:54:12.967978       1 scheduler.go:451] ScheduleAlgoTime 11.981684ms Start:2018-08-31 12:54:12.955989924 +0000 UTC m=+215.626612061 End:2018-08-31 12:54:12.967971625 +0000 UTC m=+215.638593745
I0831 12:54:12.968017       1 scheduler.go:454] Total Schedule Algo cumulative time:6.980381844s for 740
I0831 12:54:12.981897       1 scheduler.go:451] ScheduleAlgoTime 13.778462ms Start:2018-08-31 12:54:12.968111365 +0000 UTC m=+215.638733539 End:2018-08-31 12:54:12.981889881 +0000 UTC m=+215.652512001
I0831 12:54:12.981931       1 scheduler.go:454] Total Schedule Algo cumulative time:6.994160306s for 741
I0831 12:54:12.994061       1 scheduler.go:451] ScheduleAlgoTime 12.032709ms Start:2018-08-31 12:54:12.982019822 +0000 UTC m=+215.652641982 End:2018-08-31 12:54:12.994052565 +0000 UTC m=+215.664674691
I0831 12:54:12.994104       1 scheduler.go:454] Total Schedule Algo cumulative time:7.006193015s for 742
I0831 12:54:13.007050       1 scheduler.go:451] ScheduleAlgoTime 12.837076ms Start:2018-08-31 12:54:12.994207188 +0000 UTC m=+215.664829351 End:2018-08-31 12:54:13.007044307 +0000 UTC m=+215.677666427
I0831 12:54:13.007083       1 scheduler.go:454] Total Schedule Algo cumulative time:7.019030091s for 743
I0831 12:54:13.020927       1 scheduler.go:451] ScheduleAlgoTime 13.747895ms Start:2018-08-31 12:54:13.007173729 +0000 UTC m=+215.677795871 End:2018-08-31 12:54:13.020921645 +0000 UTC m=+215.691543766
I0831 12:54:13.020957       1 scheduler.go:454] Total Schedule Algo cumulative time:7.032777986s for 744
I0831 12:54:13.034541       1 scheduler.go:451] ScheduleAlgoTime 13.477882ms Start:2018-08-31 12:54:13.021057024 +0000 UTC m=+215.691679177 End:2018-08-31 12:54:13.034534939 +0000 UTC m=+215.705157059
I0831 12:54:13.034591       1 scheduler.go:454] Total Schedule Algo cumulative time:7.046255868s for 745
I0831 12:54:13.047797       1 scheduler.go:451] ScheduleAlgoTime 13.110991ms Start:2018-08-31 12:54:13.034678522 +0000 UTC m=+215.705300711 End:2018-08-31 12:54:13.04778957 +0000 UTC m=+215.718411702
I0831 12:54:13.047840       1 scheduler.go:454] Total Schedule Algo cumulative time:7.059366859s for 746
I0831 12:54:13.061975       1 scheduler.go:451] ScheduleAlgoTime 14.053867ms Start:2018-08-31 12:54:13.047912534 +0000 UTC m=+215.718534686 End:2018-08-31 12:54:13.061966426 +0000 UTC m=+215.732588553
I0831 12:54:13.062017       1 scheduler.go:454] Total Schedule Algo cumulative time:7.073420726s for 747
I0831 12:54:13.076972       1 scheduler.go:451] ScheduleAlgoTime 14.860726ms Start:2018-08-31 12:54:13.062105502 +0000 UTC m=+215.732727660 End:2018-08-31 12:54:13.076966266 +0000 UTC m=+215.747588386
I0831 12:54:13.077011       1 scheduler.go:454] Total Schedule Algo cumulative time:7.088281452s for 748
I0831 12:54:13.091074       1 scheduler.go:451] ScheduleAlgoTime 13.960583ms Start:2018-08-31 12:54:13.077108071 +0000 UTC m=+215.747730224 End:2018-08-31 12:54:13.091068688 +0000 UTC m=+215.761690807
I0831 12:54:13.091111       1 scheduler.go:454] Total Schedule Algo cumulative time:7.102242035s for 749
I0831 12:54:13.103996       1 scheduler.go:451] ScheduleAlgoTime 12.773452ms Start:2018-08-31 12:54:13.091216769 +0000 UTC m=+215.761838932 End:2018-08-31 12:54:13.103990263 +0000 UTC m=+215.774612384
I0831 12:54:13.104030       1 scheduler.go:454] Total Schedule Algo cumulative time:7.115015487s for 750
I0831 12:54:13.117501       1 scheduler.go:451] ScheduleAlgoTime 13.37405ms Start:2018-08-31 12:54:13.104121007 +0000 UTC m=+215.774743161 End:2018-08-31 12:54:13.117495088 +0000 UTC m=+215.788117211
I0831 12:54:13.117540       1 scheduler.go:454] Total Schedule Algo cumulative time:7.128389537s for 751
I0831 12:54:13.136132       1 scheduler.go:451] ScheduleAlgoTime 18.498515ms Start:2018-08-31 12:54:13.117624532 +0000 UTC m=+215.788246692 End:2018-08-31 12:54:13.136123079 +0000 UTC m=+215.806745207
I0831 12:54:13.136176       1 scheduler.go:454] Total Schedule Algo cumulative time:7.146888052s for 752
I0831 12:54:13.164203       1 scheduler.go:451] ScheduleAlgoTime 27.906219ms Start:2018-08-31 12:54:13.136286749 +0000 UTC m=+215.806908926 End:2018-08-31 12:54:13.164193026 +0000 UTC m=+215.834815145
I0831 12:54:13.164295       1 scheduler.go:454] Total Schedule Algo cumulative time:7.174794271s for 753
I0831 12:54:13.182393       1 scheduler.go:451] ScheduleAlgoTime 17.681463ms Start:2018-08-31 12:54:13.164704335 +0000 UTC m=+215.835326472 End:2018-08-31 12:54:13.182385815 +0000 UTC m=+215.853007935
I0831 12:54:13.182432       1 scheduler.go:454] Total Schedule Algo cumulative time:7.192475734s for 754
I0831 12:54:13.198323       1 scheduler.go:451] ScheduleAlgoTime 15.708219ms Start:2018-08-31 12:54:13.182603937 +0000 UTC m=+215.853226091 End:2018-08-31 12:54:13.198311843 +0000 UTC m=+215.868934310
I0831 12:54:13.198364       1 scheduler.go:454] Total Schedule Algo cumulative time:7.208183953s for 755
I0831 12:54:13.211333       1 scheduler.go:451] ScheduleAlgoTime 12.848314ms Start:2018-08-31 12:54:13.198477094 +0000 UTC m=+215.869099267 End:2018-08-31 12:54:13.211325462 +0000 UTC m=+215.881947581
I0831 12:54:13.211369       1 scheduler.go:454] Total Schedule Algo cumulative time:7.221032267s for 756
I0831 12:54:13.224381       1 scheduler.go:451] ScheduleAlgoTime 12.94005ms Start:2018-08-31 12:54:13.211433318 +0000 UTC m=+215.882055473 End:2018-08-31 12:54:13.2243734 +0000 UTC m=+215.894995523
I0831 12:54:13.224422       1 scheduler.go:454] Total Schedule Algo cumulative time:7.233972317s for 757
I0831 12:54:13.237791       1 scheduler.go:451] ScheduleAlgoTime 13.266039ms Start:2018-08-31 12:54:13.224517951 +0000 UTC m=+215.895140105 End:2018-08-31 12:54:13.237784015 +0000 UTC m=+215.908406144
I0831 12:54:13.237830       1 scheduler.go:454] Total Schedule Algo cumulative time:7.247238356s for 758
I0831 12:54:13.251392       1 scheduler.go:451] ScheduleAlgoTime 13.481883ms Start:2018-08-31 12:54:13.237905407 +0000 UTC m=+215.908527572 End:2018-08-31 12:54:13.251387335 +0000 UTC m=+215.922009455
I0831 12:54:13.251422       1 scheduler.go:454] Total Schedule Algo cumulative time:7.260720239s for 759
I0831 12:54:13.266051       1 scheduler.go:451] ScheduleAlgoTime 14.5289ms Start:2018-08-31 12:54:13.251515477 +0000 UTC m=+215.922137653 End:2018-08-31 12:54:13.266044435 +0000 UTC m=+215.936666553
I0831 12:54:13.266095       1 scheduler.go:454] Total Schedule Algo cumulative time:7.275249139s for 760
I0831 12:54:13.280586       1 scheduler.go:451] ScheduleAlgoTime 14.409097ms Start:2018-08-31 12:54:13.266171444 +0000 UTC m=+215.936793607 End:2018-08-31 12:54:13.280580581 +0000 UTC m=+215.951202704
I0831 12:54:13.280616       1 scheduler.go:454] Total Schedule Algo cumulative time:7.289658236s for 761
I0831 12:54:13.295509       1 scheduler.go:451] ScheduleAlgoTime 14.798918ms Start:2018-08-31 12:54:13.280704042 +0000 UTC m=+215.951326182 End:2018-08-31 12:54:13.295502981 +0000 UTC m=+215.966125100
I0831 12:54:13.295540       1 scheduler.go:454] Total Schedule Algo cumulative time:7.304457154s for 762
I0831 12:54:13.308573       1 scheduler.go:451] ScheduleAlgoTime 12.925877ms Start:2018-08-31 12:54:13.295639038 +0000 UTC m=+215.966261220 End:2018-08-31 12:54:13.308564965 +0000 UTC m=+215.979187097
I0831 12:54:13.308611       1 scheduler.go:454] Total Schedule Algo cumulative time:7.317383031s for 763
I0831 12:54:13.322702       1 scheduler.go:451] ScheduleAlgoTime 13.986398ms Start:2018-08-31 12:54:13.308706894 +0000 UTC m=+215.979329071 End:2018-08-31 12:54:13.322693336 +0000 UTC m=+215.993315469
I0831 12:54:13.322740       1 scheduler.go:454] Total Schedule Algo cumulative time:7.331369429s for 764
I0831 12:54:13.337191       1 scheduler.go:451] ScheduleAlgoTime 14.351406ms Start:2018-08-31 12:54:13.322833713 +0000 UTC m=+215.993455862 End:2018-08-31 12:54:13.337185145 +0000 UTC m=+216.007807268
I0831 12:54:13.337227       1 scheduler.go:454] Total Schedule Algo cumulative time:7.345720835s for 765
I0831 12:54:13.354811       1 scheduler.go:451] ScheduleAlgoTime 17.473647ms Start:2018-08-31 12:54:13.337328557 +0000 UTC m=+216.007950705 End:2018-08-31 12:54:13.354802226 +0000 UTC m=+216.025424352
I0831 12:54:13.354866       1 scheduler.go:454] Total Schedule Algo cumulative time:7.363194482s for 766
I0831 12:54:13.373755       1 scheduler.go:451] ScheduleAlgoTime 18.778885ms Start:2018-08-31 12:54:13.354965187 +0000 UTC m=+216.025587329 End:2018-08-31 12:54:13.373744091 +0000 UTC m=+216.044366214
I0831 12:54:13.378603       1 scheduler.go:454] Total Schedule Algo cumulative time:7.381973367s for 767
I0831 12:54:13.402600       1 scheduler.go:451] ScheduleAlgoTime 16.415157ms Start:2018-08-31 12:54:13.386173872 +0000 UTC m=+216.056796042 End:2018-08-31 12:54:13.40258908 +0000 UTC m=+216.073211199
I0831 12:54:13.402658       1 scheduler.go:454] Total Schedule Algo cumulative time:7.398388524s for 768
I0831 12:54:13.417769       1 scheduler.go:451] ScheduleAlgoTime 14.908649ms Start:2018-08-31 12:54:13.402850122 +0000 UTC m=+216.073472296 End:2018-08-31 12:54:13.417758815 +0000 UTC m=+216.088380945
I0831 12:54:13.417814       1 scheduler.go:454] Total Schedule Algo cumulative time:7.413297173s for 769
I0831 12:54:13.432342       1 scheduler.go:451] ScheduleAlgoTime 14.423671ms Start:2018-08-31 12:54:13.417912316 +0000 UTC m=+216.088534482 End:2018-08-31 12:54:13.432336035 +0000 UTC m=+216.102958153
I0831 12:54:13.432378       1 scheduler.go:454] Total Schedule Algo cumulative time:7.427720844s for 770
I0831 12:54:13.446142       1 scheduler.go:451] ScheduleAlgoTime 13.653749ms Start:2018-08-31 12:54:13.43248114 +0000 UTC m=+216.103103293 End:2018-08-31 12:54:13.446134922 +0000 UTC m=+216.116757042
I0831 12:54:13.446183       1 scheduler.go:454] Total Schedule Algo cumulative time:7.441374593s for 771
I0831 12:54:13.458963       1 scheduler.go:451] ScheduleAlgoTime 12.688812ms Start:2018-08-31 12:54:13.446268086 +0000 UTC m=+216.116890261 End:2018-08-31 12:54:13.458956952 +0000 UTC m=+216.129579073
I0831 12:54:13.458993       1 scheduler.go:454] Total Schedule Algo cumulative time:7.454063405s for 772
I0831 12:54:13.473448       1 scheduler.go:451] ScheduleAlgoTime 14.363173ms Start:2018-08-31 12:54:13.459078163 +0000 UTC m=+216.129700340 End:2018-08-31 12:54:13.473441394 +0000 UTC m=+216.144063513
I0831 12:54:13.473488       1 scheduler.go:454] Total Schedule Algo cumulative time:7.468426578s for 773
I0831 12:54:13.486369       1 scheduler.go:451] ScheduleAlgoTime 12.787738ms Start:2018-08-31 12:54:13.473575336 +0000 UTC m=+216.144197490 End:2018-08-31 12:54:13.486363109 +0000 UTC m=+216.156985228
I0831 12:54:13.486403       1 scheduler.go:454] Total Schedule Algo cumulative time:7.481214316s for 774
I0831 12:54:13.499707       1 scheduler.go:451] ScheduleAlgoTime 13.211124ms Start:2018-08-31 12:54:13.48649021 +0000 UTC m=+216.157112362 End:2018-08-31 12:54:13.499701366 +0000 UTC m=+216.170323486
I0831 12:54:13.499739       1 scheduler.go:454] Total Schedule Algo cumulative time:7.49442544s for 775
I0831 12:54:13.512168       1 scheduler.go:451] ScheduleAlgoTime 12.341673ms Start:2018-08-31 12:54:13.499821747 +0000 UTC m=+216.170443900 End:2018-08-31 12:54:13.51216345 +0000 UTC m=+216.182785573
I0831 12:54:13.512195       1 scheduler.go:454] Total Schedule Algo cumulative time:7.506767113s for 776
I0831 12:54:13.526779       1 scheduler.go:451] ScheduleAlgoTime 14.503415ms Start:2018-08-31 12:54:13.512269853 +0000 UTC m=+216.182892012 End:2018-08-31 12:54:13.526773306 +0000 UTC m=+216.197395427
I0831 12:54:13.526810       1 scheduler.go:454] Total Schedule Algo cumulative time:7.521270528s for 777
I0831 12:54:13.541254       1 scheduler.go:451] ScheduleAlgoTime 14.350303ms Start:2018-08-31 12:54:13.526897138 +0000 UTC m=+216.197519284 End:2018-08-31 12:54:13.541247468 +0000 UTC m=+216.211869587
I0831 12:54:13.541284       1 scheduler.go:454] Total Schedule Algo cumulative time:7.535620831s for 778
I0831 12:54:13.554420       1 scheduler.go:451] ScheduleAlgoTime 13.05408ms Start:2018-08-31 12:54:13.541358125 +0000 UTC m=+216.211980270 End:2018-08-31 12:54:13.554412221 +0000 UTC m=+216.225034350
I0831 12:54:13.554462       1 scheduler.go:454] Total Schedule Algo cumulative time:7.548674911s for 779
I0831 12:54:13.575295       1 scheduler.go:451] ScheduleAlgoTime 20.732857ms Start:2018-08-31 12:54:13.554553112 +0000 UTC m=+216.225175258 End:2018-08-31 12:54:13.575285991 +0000 UTC m=+216.245908115
I0831 12:54:13.575338       1 scheduler.go:454] Total Schedule Algo cumulative time:7.569407768s for 780
I0831 12:54:13.587681       1 scheduler.go:451] ScheduleAlgoTime 12.187208ms Start:2018-08-31 12:54:13.575486884 +0000 UTC m=+216.246109062 End:2018-08-31 12:54:13.587674148 +0000 UTC m=+216.258296270
I0831 12:54:13.587714       1 scheduler.go:454] Total Schedule Algo cumulative time:7.581594976s for 781
I0831 12:54:13.600611       1 scheduler.go:451] ScheduleAlgoTime 12.804867ms Start:2018-08-31 12:54:13.587799779 +0000 UTC m=+216.258421918 End:2018-08-31 12:54:13.600604663 +0000 UTC m=+216.271226785
I0831 12:54:13.600644       1 scheduler.go:454] Total Schedule Algo cumulative time:7.594399843s for 782
I0831 12:54:13.615495       1 scheduler.go:451] ScheduleAlgoTime 14.752066ms Start:2018-08-31 12:54:13.600734124 +0000 UTC m=+216.271356301 End:2018-08-31 12:54:13.615486232 +0000 UTC m=+216.286108367
I0831 12:54:13.615542       1 scheduler.go:454] Total Schedule Algo cumulative time:7.609151909s for 783
I0831 12:54:13.628907       1 scheduler.go:451] ScheduleAlgoTime 13.255765ms Start:2018-08-31 12:54:13.615644054 +0000 UTC m=+216.286266222 End:2018-08-31 12:54:13.628899861 +0000 UTC m=+216.299521987
I0831 12:54:13.628947       1 scheduler.go:454] Total Schedule Algo cumulative time:7.622407674s for 784
I0831 12:54:13.642609       1 scheduler.go:451] ScheduleAlgoTime 13.567633ms Start:2018-08-31 12:54:13.629035376 +0000 UTC m=+216.299657545 End:2018-08-31 12:54:13.642603059 +0000 UTC m=+216.313225178
I0831 12:54:13.642648       1 scheduler.go:454] Total Schedule Algo cumulative time:7.635975307s for 785
I0831 12:54:13.657505       1 scheduler.go:451] ScheduleAlgoTime 14.779361ms Start:2018-08-31 12:54:13.642719727 +0000 UTC m=+216.313341905 End:2018-08-31 12:54:13.657499146 +0000 UTC m=+216.328121266
I0831 12:54:13.657536       1 scheduler.go:454] Total Schedule Algo cumulative time:7.650754668s for 786
I0831 12:54:13.672768       1 scheduler.go:451] ScheduleAlgoTime 15.126419ms Start:2018-08-31 12:54:13.657635514 +0000 UTC m=+216.328257666 End:2018-08-31 12:54:13.672761966 +0000 UTC m=+216.343384085
I0831 12:54:13.672802       1 scheduler.go:454] Total Schedule Algo cumulative time:7.665881087s for 787
I0831 12:54:13.687646       1 scheduler.go:451] ScheduleAlgoTime 14.751367ms Start:2018-08-31 12:54:13.672890042 +0000 UTC m=+216.343512198 End:2018-08-31 12:54:13.687641446 +0000 UTC m=+216.358263565
I0831 12:54:13.687677       1 scheduler.go:454] Total Schedule Algo cumulative time:7.680632454s for 788
I0831 12:54:13.702564       1 scheduler.go:451] ScheduleAlgoTime 14.791717ms Start:2018-08-31 12:54:13.687765867 +0000 UTC m=+216.358388030 End:2018-08-31 12:54:13.702557628 +0000 UTC m=+216.373179747
I0831 12:54:13.702612       1 scheduler.go:454] Total Schedule Algo cumulative time:7.695424171s for 789
I0831 12:54:13.717823       1 scheduler.go:451] ScheduleAlgoTime 15.11538ms Start:2018-08-31 12:54:13.702699964 +0000 UTC m=+216.373322120 End:2018-08-31 12:54:13.717815372 +0000 UTC m=+216.388437500
I0831 12:54:13.717864       1 scheduler.go:454] Total Schedule Algo cumulative time:7.710539551s for 790
I0831 12:54:13.733681       1 scheduler.go:451] ScheduleAlgoTime 15.726278ms Start:2018-08-31 12:54:13.717946208 +0000 UTC m=+216.388568358 End:2018-08-31 12:54:13.733672504 +0000 UTC m=+216.404294636
I0831 12:54:13.733817       1 scheduler.go:454] Total Schedule Algo cumulative time:7.726265829s for 791
I0831 12:54:13.762163       1 scheduler.go:451] ScheduleAlgoTime 15.467933ms Start:2018-08-31 12:54:13.74668741 +0000 UTC m=+216.417309597 End:2018-08-31 12:54:13.762155411 +0000 UTC m=+216.432777530
I0831 12:54:13.762196       1 scheduler.go:454] Total Schedule Algo cumulative time:7.741733762s for 792
I0831 12:54:13.782377       1 scheduler.go:451] ScheduleAlgoTime 20.096508ms Start:2018-08-31 12:54:13.762273064 +0000 UTC m=+216.432895220 End:2018-08-31 12:54:13.782369604 +0000 UTC m=+216.452991728
I0831 12:54:13.782424       1 scheduler.go:454] Total Schedule Algo cumulative time:7.76183027s for 793
I0831 12:54:13.796768       1 scheduler.go:451] ScheduleAlgoTime 14.230886ms Start:2018-08-31 12:54:13.782530425 +0000 UTC m=+216.453152602 End:2018-08-31 12:54:13.796761364 +0000 UTC m=+216.467383488
I0831 12:54:13.796807       1 scheduler.go:454] Total Schedule Algo cumulative time:7.776061156s for 794
I0831 12:54:13.809667       1 scheduler.go:451] ScheduleAlgoTime 12.766037ms Start:2018-08-31 12:54:13.796893797 +0000 UTC m=+216.467515959 End:2018-08-31 12:54:13.809659865 +0000 UTC m=+216.480281996
I0831 12:54:13.809698       1 scheduler.go:454] Total Schedule Algo cumulative time:7.788827193s for 795
I0831 12:54:13.823943       1 scheduler.go:451] ScheduleAlgoTime 14.145533ms Start:2018-08-31 12:54:13.809791314 +0000 UTC m=+216.480413484 End:2018-08-31 12:54:13.823936899 +0000 UTC m=+216.494559017
I0831 12:54:13.823976       1 scheduler.go:454] Total Schedule Algo cumulative time:7.802972726s for 796
I0831 12:54:13.839193       1 scheduler.go:451] ScheduleAlgoTime 15.082098ms Start:2018-08-31 12:54:13.824104602 +0000 UTC m=+216.494726751 End:2018-08-31 12:54:13.839186728 +0000 UTC m=+216.509808849
I0831 12:54:13.839235       1 scheduler.go:454] Total Schedule Algo cumulative time:7.818054824s for 797
I0831 12:54:13.853008       1 scheduler.go:451] ScheduleAlgoTime 13.681242ms Start:2018-08-31 12:54:13.839321306 +0000 UTC m=+216.509943475 End:2018-08-31 12:54:13.853002594 +0000 UTC m=+216.523624717
I0831 12:54:13.853040       1 scheduler.go:454] Total Schedule Algo cumulative time:7.831736066s for 798
I0831 12:54:13.866265       1 scheduler.go:451] ScheduleAlgoTime 13.13649ms Start:2018-08-31 12:54:13.853120801 +0000 UTC m=+216.523742947 End:2018-08-31 12:54:13.866257304 +0000 UTC m=+216.536879437
I0831 12:54:13.866307       1 scheduler.go:454] Total Schedule Algo cumulative time:7.844872556s for 799
I0831 12:54:13.880162       1 scheduler.go:451] ScheduleAlgoTime 13.744789ms Start:2018-08-31 12:54:13.866411638 +0000 UTC m=+216.537033801 End:2018-08-31 12:54:13.880156471 +0000 UTC m=+216.550778590
I0831 12:54:13.880196       1 scheduler.go:454] Total Schedule Algo cumulative time:7.858617345s for 800
I0831 12:54:13.893781       1 scheduler.go:451] ScheduleAlgoTime 13.500714ms Start:2018-08-31 12:54:13.880272023 +0000 UTC m=+216.550894169 End:2018-08-31 12:54:13.893772755 +0000 UTC m=+216.564394883
I0831 12:54:13.893841       1 scheduler.go:454] Total Schedule Algo cumulative time:7.872118059s for 801
I0831 12:54:13.907952       1 scheduler.go:451] ScheduleAlgoTime 14.003083ms Start:2018-08-31 12:54:13.893942371 +0000 UTC m=+216.564564517 End:2018-08-31 12:54:13.90794548 +0000 UTC m=+216.578567600
I0831 12:54:13.907983       1 scheduler.go:454] Total Schedule Algo cumulative time:7.886121142s for 802
I0831 12:54:13.922084       1 scheduler.go:451] ScheduleAlgoTime 14.015651ms Start:2018-08-31 12:54:13.908059708 +0000 UTC m=+216.578681857 End:2018-08-31 12:54:13.922075374 +0000 UTC m=+216.592697508
I0831 12:54:13.922126       1 scheduler.go:454] Total Schedule Algo cumulative time:7.900136793s for 803
I0831 12:54:13.935910       1 scheduler.go:451] ScheduleAlgoTime 13.679425ms Start:2018-08-31 12:54:13.922223975 +0000 UTC m=+216.592846151 End:2018-08-31 12:54:13.935903457 +0000 UTC m=+216.606525576
I0831 12:54:13.935942       1 scheduler.go:454] Total Schedule Algo cumulative time:7.913816218s for 804
I0831 12:54:13.949731       1 scheduler.go:451] ScheduleAlgoTime 13.685411ms Start:2018-08-31 12:54:13.936038142 +0000 UTC m=+216.606660287 End:2018-08-31 12:54:13.949723578 +0000 UTC m=+216.620345698
I0831 12:54:13.949773       1 scheduler.go:454] Total Schedule Algo cumulative time:7.927501629s for 805
I0831 12:54:13.963877       1 scheduler.go:451] ScheduleAlgoTime 13.980174ms Start:2018-08-31 12:54:13.949890325 +0000 UTC m=+216.620512485 End:2018-08-31 12:54:13.96387054 +0000 UTC m=+216.634492659
I0831 12:54:13.963919       1 scheduler.go:454] Total Schedule Algo cumulative time:7.941481803s for 806
I0831 12:54:13.986936       1 scheduler.go:451] ScheduleAlgoTime 22.925019ms Start:2018-08-31 12:54:13.964003611 +0000 UTC m=+216.634625756 End:2018-08-31 12:54:13.986928654 +0000 UTC m=+216.657550775
I0831 12:54:13.986987       1 scheduler.go:454] Total Schedule Algo cumulative time:7.964406822s for 807
I0831 12:54:14.001356       1 scheduler.go:451] ScheduleAlgoTime 14.267352ms Start:2018-08-31 12:54:13.987080308 +0000 UTC m=+216.657702461 End:2018-08-31 12:54:14.001347683 +0000 UTC m=+216.671969813
I0831 12:54:14.001394       1 scheduler.go:454] Total Schedule Algo cumulative time:7.978674174s for 808
I0831 12:54:14.014831       1 scheduler.go:451] ScheduleAlgoTime 13.32766ms Start:2018-08-31 12:54:14.001496165 +0000 UTC m=+216.672118324 End:2018-08-31 12:54:14.014823864 +0000 UTC m=+216.685445984
I0831 12:54:14.014862       1 scheduler.go:454] Total Schedule Algo cumulative time:7.992001834s for 809
I0831 12:54:14.027738       1 scheduler.go:451] ScheduleAlgoTime 12.775273ms Start:2018-08-31 12:54:14.014955776 +0000 UTC m=+216.685577928 End:2018-08-31 12:54:14.027731074 +0000 UTC m=+216.698353201
I0831 12:54:14.027789       1 scheduler.go:454] Total Schedule Algo cumulative time:8.004777107s for 810
I0831 12:54:14.043523       1 scheduler.go:451] ScheduleAlgoTime 15.62997ms Start:2018-08-31 12:54:14.027887033 +0000 UTC m=+216.698509188 End:2018-08-31 12:54:14.043517038 +0000 UTC m=+216.714139158
I0831 12:54:14.043566       1 scheduler.go:454] Total Schedule Algo cumulative time:8.020407077s for 811
I0831 12:54:14.058926       1 scheduler.go:451] ScheduleAlgoTime 15.256167ms Start:2018-08-31 12:54:14.043662687 +0000 UTC m=+216.714284833 End:2018-08-31 12:54:14.058918878 +0000 UTC m=+216.729541000
I0831 12:54:14.058956       1 scheduler.go:454] Total Schedule Algo cumulative time:8.035663244s for 812
I0831 12:54:14.073400       1 scheduler.go:451] ScheduleAlgoTime 14.363343ms Start:2018-08-31 12:54:14.059031325 +0000 UTC m=+216.729653522 End:2018-08-31 12:54:14.073394741 +0000 UTC m=+216.744016865
I0831 12:54:14.073430       1 scheduler.go:454] Total Schedule Algo cumulative time:8.050026587s for 813
I0831 12:54:14.090868       1 scheduler.go:451] ScheduleAlgoTime 17.326225ms Start:2018-08-31 12:54:14.073535863 +0000 UTC m=+216.744158023 End:2018-08-31 12:54:14.09086213 +0000 UTC m=+216.761484248
I0831 12:54:14.090899       1 scheduler.go:454] Total Schedule Algo cumulative time:8.067352812s for 814
I0831 12:54:14.106617       1 scheduler.go:451] ScheduleAlgoTime 15.627803ms Start:2018-08-31 12:54:14.090982639 +0000 UTC m=+216.761604790 End:2018-08-31 12:54:14.106610473 +0000 UTC m=+216.777232593
I0831 12:54:14.106657       1 scheduler.go:454] Total Schedule Algo cumulative time:8.082980615s for 815
I0831 12:54:14.119641       1 scheduler.go:451] ScheduleAlgoTime 12.889076ms Start:2018-08-31 12:54:14.106746412 +0000 UTC m=+216.777368569 End:2018-08-31 12:54:14.119635525 +0000 UTC m=+216.790257645
I0831 12:54:14.119669       1 scheduler.go:454] Total Schedule Algo cumulative time:8.095869691s for 816
I0831 12:54:14.133446       1 scheduler.go:451] ScheduleAlgoTime 13.691945ms Start:2018-08-31 12:54:14.119747373 +0000 UTC m=+216.790369510 End:2018-08-31 12:54:14.133439326 +0000 UTC m=+216.804061455
I0831 12:54:14.133507       1 scheduler.go:454] Total Schedule Algo cumulative time:8.109561636s for 817
I0831 12:54:14.147787       1 scheduler.go:451] ScheduleAlgoTime 14.184245ms Start:2018-08-31 12:54:14.133598018 +0000 UTC m=+216.804220165 End:2018-08-31 12:54:14.147782288 +0000 UTC m=+216.818404410
I0831 12:54:14.147820       1 scheduler.go:454] Total Schedule Algo cumulative time:8.123745881s for 818
I0831 12:54:14.162491       1 scheduler.go:451] ScheduleAlgoTime 14.561915ms Start:2018-08-31 12:54:14.147919966 +0000 UTC m=+216.818542119 End:2018-08-31 12:54:14.16248191 +0000 UTC m=+216.833104034
I0831 12:54:14.162530       1 scheduler.go:454] Total Schedule Algo cumulative time:8.138307796s for 819
I0831 12:54:14.185110       1 scheduler.go:451] ScheduleAlgoTime 22.456744ms Start:2018-08-31 12:54:14.16264629 +0000 UTC m=+216.833268466 End:2018-08-31 12:54:14.185103091 +0000 UTC m=+216.855725210
I0831 12:54:14.185146       1 scheduler.go:454] Total Schedule Algo cumulative time:8.16076454s for 820
I0831 12:54:14.200155       1 scheduler.go:451] ScheduleAlgoTime 14.862701ms Start:2018-08-31 12:54:14.18528571 +0000 UTC m=+216.855907890 End:2018-08-31 12:54:14.200148472 +0000 UTC m=+216.870770591
I0831 12:54:14.200191       1 scheduler.go:454] Total Schedule Algo cumulative time:8.175627241s for 821
I0831 12:54:14.214539       1 scheduler.go:451] ScheduleAlgoTime 14.267437ms Start:2018-08-31 12:54:14.200265358 +0000 UTC m=+216.870887503 End:2018-08-31 12:54:14.214532821 +0000 UTC m=+216.885154940
I0831 12:54:14.214595       1 scheduler.go:454] Total Schedule Algo cumulative time:8.189894678s for 822
I0831 12:54:14.230629       1 scheduler.go:451] ScheduleAlgoTime 15.945163ms Start:2018-08-31 12:54:14.214676974 +0000 UTC m=+216.885299119 End:2018-08-31 12:54:14.230622155 +0000 UTC m=+216.901244282
I0831 12:54:14.230670       1 scheduler.go:454] Total Schedule Algo cumulative time:8.205839841s for 823
I0831 12:54:14.243365       1 scheduler.go:451] ScheduleAlgoTime 12.605743ms Start:2018-08-31 12:54:14.230753336 +0000 UTC m=+216.901375480 End:2018-08-31 12:54:14.243359103 +0000 UTC m=+216.913981223
I0831 12:54:14.243409       1 scheduler.go:454] Total Schedule Algo cumulative time:8.218445584s for 824
I0831 12:54:14.257119       1 scheduler.go:451] ScheduleAlgoTime 13.590858ms Start:2018-08-31 12:54:14.24352249 +0000 UTC m=+216.914144644 End:2018-08-31 12:54:14.257113381 +0000 UTC m=+216.927735502
I0831 12:54:14.257150       1 scheduler.go:454] Total Schedule Algo cumulative time:8.232036442s for 825
I0831 12:54:14.269839       1 scheduler.go:451] ScheduleAlgoTime 12.603363ms Start:2018-08-31 12:54:14.257230497 +0000 UTC m=+216.927852684 End:2018-08-31 12:54:14.269833923 +0000 UTC m=+216.940456047
I0831 12:54:14.269884       1 scheduler.go:454] Total Schedule Algo cumulative time:8.244639805s for 826
I0831 12:54:14.283300       1 scheduler.go:451] ScheduleAlgoTime 13.288279ms Start:2018-08-31 12:54:14.270006449 +0000 UTC m=+216.940628615 End:2018-08-31 12:54:14.283294774 +0000 UTC m=+216.953916894
I0831 12:54:14.283328       1 scheduler.go:454] Total Schedule Algo cumulative time:8.257928084s for 827
I0831 12:54:14.297182       1 scheduler.go:451] ScheduleAlgoTime 13.772661ms Start:2018-08-31 12:54:14.28340457 +0000 UTC m=+216.954026719 End:2018-08-31 12:54:14.297177262 +0000 UTC m=+216.967799380
I0831 12:54:14.297212       1 scheduler.go:454] Total Schedule Algo cumulative time:8.271700745s for 828
I0831 12:54:14.311061       1 scheduler.go:451] ScheduleAlgoTime 13.748135ms Start:2018-08-31 12:54:14.297305415 +0000 UTC m=+216.967927564 End:2018-08-31 12:54:14.311053573 +0000 UTC m=+216.981675699
I0831 12:54:14.311104       1 scheduler.go:454] Total Schedule Algo cumulative time:8.28544888s for 829
I0831 12:54:14.324256       1 scheduler.go:451] ScheduleAlgoTime 13.062469ms Start:2018-08-31 12:54:14.31118646 +0000 UTC m=+216.981808677 End:2018-08-31 12:54:14.324249003 +0000 UTC m=+216.994871146
I0831 12:54:14.324292       1 scheduler.go:454] Total Schedule Algo cumulative time:8.298511349s for 830
I0831 12:54:14.339244       1 scheduler.go:451] ScheduleAlgoTime 14.853728ms Start:2018-08-31 12:54:14.324383399 +0000 UTC m=+216.995005544 End:2018-08-31 12:54:14.339237149 +0000 UTC m=+217.009859272
I0831 12:54:14.339276       1 scheduler.go:454] Total Schedule Algo cumulative time:8.313365077s for 831
I0831 12:54:14.352820       1 scheduler.go:451] ScheduleAlgoTime 13.468133ms Start:2018-08-31 12:54:14.339346154 +0000 UTC m=+217.009968312 End:2018-08-31 12:54:14.352814326 +0000 UTC m=+217.023436445
I0831 12:54:14.352850       1 scheduler.go:454] Total Schedule Algo cumulative time:8.32683321s for 832
I0831 12:54:14.367564       1 scheduler.go:451] ScheduleAlgoTime 14.612899ms Start:2018-08-31 12:54:14.352944734 +0000 UTC m=+217.023566898 End:2018-08-31 12:54:14.367557678 +0000 UTC m=+217.038179797
I0831 12:54:14.367606       1 scheduler.go:454] Total Schedule Algo cumulative time:8.341446109s for 833
I0831 12:54:14.393513       1 scheduler.go:451] ScheduleAlgoTime 25.732524ms Start:2018-08-31 12:54:14.367770709 +0000 UTC m=+217.038392861 End:2018-08-31 12:54:14.39350325 +0000 UTC m=+217.064125385
I0831 12:54:14.393610       1 scheduler.go:454] Total Schedule Algo cumulative time:8.367178633s for 834
I0831 12:54:14.416148       1 scheduler.go:451] ScheduleAlgoTime 19.979362ms Start:2018-08-31 12:54:14.396159563 +0000 UTC m=+217.066781727 End:2018-08-31 12:54:14.416138969 +0000 UTC m=+217.086761089
I0831 12:54:14.416191       1 scheduler.go:454] Total Schedule Algo cumulative time:8.387157995s for 835
I0831 12:54:14.430973       1 scheduler.go:451] ScheduleAlgoTime 14.63916ms Start:2018-08-31 12:54:14.416327351 +0000 UTC m=+217.086949518 End:2018-08-31 12:54:14.430966559 +0000 UTC m=+217.101588678
I0831 12:54:14.431020       1 scheduler.go:454] Total Schedule Algo cumulative time:8.401797155s for 836
I0831 12:54:14.447126       1 scheduler.go:451] ScheduleAlgoTime 15.943441ms Start:2018-08-31 12:54:14.431177184 +0000 UTC m=+217.101799337 End:2018-08-31 12:54:14.44712066 +0000 UTC m=+217.117742778
I0831 12:54:14.447162       1 scheduler.go:454] Total Schedule Algo cumulative time:8.417740596s for 837
I0831 12:54:14.461598       1 scheduler.go:451] ScheduleAlgoTime 14.288156ms Start:2018-08-31 12:54:14.447302679 +0000 UTC m=+217.117924817 End:2018-08-31 12:54:14.461590853 +0000 UTC m=+217.132212973
I0831 12:54:14.461639       1 scheduler.go:454] Total Schedule Algo cumulative time:8.432028752s for 838
I0831 12:54:14.476833       1 scheduler.go:451] ScheduleAlgoTime 15.040892ms Start:2018-08-31 12:54:14.461784341 +0000 UTC m=+217.132406495 End:2018-08-31 12:54:14.476825244 +0000 UTC m=+217.147447387
I0831 12:54:14.476871       1 scheduler.go:454] Total Schedule Algo cumulative time:8.447069644s for 839
I0831 12:54:14.491828       1 scheduler.go:451] ScheduleAlgoTime 14.878864ms Start:2018-08-31 12:54:14.476944447 +0000 UTC m=+217.147566599 End:2018-08-31 12:54:14.491823343 +0000 UTC m=+217.162445463
I0831 12:54:14.491861       1 scheduler.go:454] Total Schedule Algo cumulative time:8.461948508s for 840
I0831 12:54:14.505997       1 scheduler.go:451] ScheduleAlgoTime 14.037393ms Start:2018-08-31 12:54:14.491954612 +0000 UTC m=+217.162576795 End:2018-08-31 12:54:14.505992068 +0000 UTC m=+217.176614188
I0831 12:54:14.506027       1 scheduler.go:454] Total Schedule Algo cumulative time:8.475985901s for 841
I0831 12:54:14.519996       1 scheduler.go:451] ScheduleAlgoTime 13.87286ms Start:2018-08-31 12:54:14.506116168 +0000 UTC m=+217.176738313 End:2018-08-31 12:54:14.519989051 +0000 UTC m=+217.190611173
I0831 12:54:14.520024       1 scheduler.go:454] Total Schedule Algo cumulative time:8.489858761s for 842
I0831 12:54:14.534714       1 scheduler.go:451] ScheduleAlgoTime 14.517885ms Start:2018-08-31 12:54:14.520190753 +0000 UTC m=+217.190812900 End:2018-08-31 12:54:14.534708661 +0000 UTC m=+217.205330785
I0831 12:54:14.534751       1 scheduler.go:454] Total Schedule Algo cumulative time:8.504376646s for 843
I0831 12:54:14.552507       1 scheduler.go:451] ScheduleAlgoTime 17.616647ms Start:2018-08-31 12:54:14.534883228 +0000 UTC m=+217.205505400 End:2018-08-31 12:54:14.552499921 +0000 UTC m=+217.223122047
I0831 12:54:14.552570       1 scheduler.go:454] Total Schedule Algo cumulative time:8.521993293s for 844
I0831 12:54:14.567034       1 scheduler.go:451] ScheduleAlgoTime 14.374049ms Start:2018-08-31 12:54:14.552653973 +0000 UTC m=+217.223276133 End:2018-08-31 12:54:14.567028062 +0000 UTC m=+217.237650182
I0831 12:54:14.567064       1 scheduler.go:454] Total Schedule Algo cumulative time:8.536367342s for 845
I0831 12:54:14.580450       1 scheduler.go:451] ScheduleAlgoTime 13.299169ms Start:2018-08-31 12:54:14.567145322 +0000 UTC m=+217.237767487 End:2018-08-31 12:54:14.580444533 +0000 UTC m=+217.251066656
I0831 12:54:14.580486       1 scheduler.go:454] Total Schedule Algo cumulative time:8.549666511s for 846
I0831 12:54:14.600439       1 scheduler.go:451] ScheduleAlgoTime 19.834877ms Start:2018-08-31 12:54:14.58059733 +0000 UTC m=+217.251219485 End:2018-08-31 12:54:14.600432243 +0000 UTC m=+217.271054362
I0831 12:54:14.600485       1 scheduler.go:454] Total Schedule Algo cumulative time:8.569501388s for 847
I0831 12:54:14.615061       1 scheduler.go:451] ScheduleAlgoTime 14.444124ms Start:2018-08-31 12:54:14.600607601 +0000 UTC m=+217.271229759 End:2018-08-31 12:54:14.615051756 +0000 UTC m=+217.285673883
I0831 12:54:14.615113       1 scheduler.go:454] Total Schedule Algo cumulative time:8.583945512s for 848
I0831 12:54:14.629262       1 scheduler.go:451] ScheduleAlgoTime 14.050704ms Start:2018-08-31 12:54:14.615205582 +0000 UTC m=+217.285827752 End:2018-08-31 12:54:14.629256337 +0000 UTC m=+217.299878456
I0831 12:54:14.629299       1 scheduler.go:454] Total Schedule Algo cumulative time:8.597996216s for 849
I0831 12:54:14.646544       1 scheduler.go:451] ScheduleAlgoTime 17.148669ms Start:2018-08-31 12:54:14.629388033 +0000 UTC m=+217.300010186 End:2018-08-31 12:54:14.646536736 +0000 UTC m=+217.317158855
I0831 12:54:14.646617       1 scheduler.go:454] Total Schedule Algo cumulative time:8.615144885s for 850
I0831 12:54:14.663304       1 scheduler.go:451] ScheduleAlgoTime 16.596381ms Start:2018-08-31 12:54:14.646701219 +0000 UTC m=+217.317323372 End:2018-08-31 12:54:14.663297634 +0000 UTC m=+217.333919753
I0831 12:54:14.663339       1 scheduler.go:454] Total Schedule Algo cumulative time:8.631741266s for 851
I0831 12:54:14.678348       1 scheduler.go:451] ScheduleAlgoTime 14.893865ms Start:2018-08-31 12:54:14.663445749 +0000 UTC m=+217.334067924 End:2018-08-31 12:54:14.67833966 +0000 UTC m=+217.348961789
I0831 12:54:14.678389       1 scheduler.go:454] Total Schedule Algo cumulative time:8.646635131s for 852
I0831 12:54:14.692138       1 scheduler.go:451] ScheduleAlgoTime 13.644168ms Start:2018-08-31 12:54:14.678487304 +0000 UTC m=+217.349109457 End:2018-08-31 12:54:14.692131505 +0000 UTC m=+217.362753625
I0831 12:54:14.692175       1 scheduler.go:454] Total Schedule Algo cumulative time:8.660279299s for 853
I0831 12:54:14.705912       1 scheduler.go:451] ScheduleAlgoTime 13.643769ms Start:2018-08-31 12:54:14.692263109 +0000 UTC m=+217.362885271 End:2018-08-31 12:54:14.705906921 +0000 UTC m=+217.376529040
I0831 12:54:14.705943       1 scheduler.go:454] Total Schedule Algo cumulative time:8.673923068s for 854
I0831 12:54:14.721001       1 scheduler.go:451] ScheduleAlgoTime 14.952453ms Start:2018-08-31 12:54:14.706042834 +0000 UTC m=+217.376664972 End:2018-08-31 12:54:14.720995306 +0000 UTC m=+217.391617425
I0831 12:54:14.721034       1 scheduler.go:454] Total Schedule Algo cumulative time:8.688875521s for 855
I0831 12:54:14.737777       1 scheduler.go:451] ScheduleAlgoTime 16.659197ms Start:2018-08-31 12:54:14.721109608 +0000 UTC m=+217.391731771 End:2018-08-31 12:54:14.737768843 +0000 UTC m=+217.408390968
I0831 12:54:14.737818       1 scheduler.go:454] Total Schedule Algo cumulative time:8.705534718s for 856
I0831 12:54:14.753291       1 scheduler.go:451] ScheduleAlgoTime 15.37519ms Start:2018-08-31 12:54:14.737910029 +0000 UTC m=+217.408532194 End:2018-08-31 12:54:14.753285265 +0000 UTC m=+217.423907384
I0831 12:54:14.753322       1 scheduler.go:454] Total Schedule Algo cumulative time:8.720909908s for 857
I0831 12:54:14.767723       1 scheduler.go:451] ScheduleAlgoTime 14.316477ms Start:2018-08-31 12:54:14.753400259 +0000 UTC m=+217.424022422 End:2018-08-31 12:54:14.767716779 +0000 UTC m=+217.438338899
I0831 12:54:14.767760       1 scheduler.go:454] Total Schedule Algo cumulative time:8.735226385s for 858
I0831 12:54:14.783033       1 scheduler.go:451] ScheduleAlgoTime 15.174303ms Start:2018-08-31 12:54:14.767852811 +0000 UTC m=+217.438474995 End:2018-08-31 12:54:14.78302718 +0000 UTC m=+217.453649298
I0831 12:54:14.783060       1 scheduler.go:454] Total Schedule Algo cumulative time:8.750400688s for 859
I0831 12:54:14.802894       1 scheduler.go:451] ScheduleAlgoTime 19.738605ms Start:2018-08-31 12:54:14.783148339 +0000 UTC m=+217.453770481 End:2018-08-31 12:54:14.802886965 +0000 UTC m=+217.473509086
I0831 12:54:14.802936       1 scheduler.go:454] Total Schedule Algo cumulative time:8.770139293s for 860
I0831 12:54:14.816710       1 scheduler.go:451] ScheduleAlgoTime 13.66908ms Start:2018-08-31 12:54:14.803034048 +0000 UTC m=+217.473656197 End:2018-08-31 12:54:14.816703155 +0000 UTC m=+217.487325277
I0831 12:54:14.816747       1 scheduler.go:454] Total Schedule Algo cumulative time:8.783808373s for 861
I0831 12:54:14.830121       1 scheduler.go:451] ScheduleAlgoTime 13.288023ms Start:2018-08-31 12:54:14.816826795 +0000 UTC m=+217.487448952 End:2018-08-31 12:54:14.830114848 +0000 UTC m=+217.500736975
I0831 12:54:14.830162       1 scheduler.go:454] Total Schedule Algo cumulative time:8.797096396s for 862
I0831 12:54:14.844337       1 scheduler.go:451] ScheduleAlgoTime 14.090857ms Start:2018-08-31 12:54:14.830241112 +0000 UTC m=+217.500863247 End:2018-08-31 12:54:14.844331985 +0000 UTC m=+217.514954104
I0831 12:54:14.844369       1 scheduler.go:454] Total Schedule Algo cumulative time:8.811187253s for 863
I0831 12:54:14.858193       1 scheduler.go:451] ScheduleAlgoTime 13.719463ms Start:2018-08-31 12:54:14.84446788 +0000 UTC m=+217.515090029 End:2018-08-31 12:54:14.858187372 +0000 UTC m=+217.528809492
I0831 12:54:14.858222       1 scheduler.go:454] Total Schedule Algo cumulative time:8.824906716s for 864
I0831 12:54:14.872154       1 scheduler.go:451] ScheduleAlgoTime 13.815178ms Start:2018-08-31 12:54:14.85833088 +0000 UTC m=+217.528953026 End:2018-08-31 12:54:14.872146036 +0000 UTC m=+217.542768204
I0831 12:54:14.872195       1 scheduler.go:454] Total Schedule Algo cumulative time:8.838721894s for 865
I0831 12:54:14.886501       1 scheduler.go:451] ScheduleAlgoTime 14.213029ms Start:2018-08-31 12:54:14.872282438 +0000 UTC m=+217.542904590 End:2018-08-31 12:54:14.886495495 +0000 UTC m=+217.557117619
I0831 12:54:14.886532       1 scheduler.go:454] Total Schedule Algo cumulative time:8.852934923s for 866
I0831 12:54:14.901938       1 scheduler.go:451] ScheduleAlgoTime 15.319233ms Start:2018-08-31 12:54:14.886613971 +0000 UTC m=+217.557236124 End:2018-08-31 12:54:14.901933238 +0000 UTC m=+217.572555357
I0831 12:54:14.901967       1 scheduler.go:454] Total Schedule Algo cumulative time:8.868254156s for 867
I0831 12:54:14.916569       1 scheduler.go:451] ScheduleAlgoTime 14.496349ms Start:2018-08-31 12:54:14.902057419 +0000 UTC m=+217.572679565 End:2018-08-31 12:54:14.916553793 +0000 UTC m=+217.587175914
I0831 12:54:14.916598       1 scheduler.go:454] Total Schedule Algo cumulative time:8.882750505s for 868
I0831 12:54:14.930279       1 scheduler.go:451] ScheduleAlgoTime 13.585223ms Start:2018-08-31 12:54:14.916687451 +0000 UTC m=+217.587309599 End:2018-08-31 12:54:14.930272702 +0000 UTC m=+217.600894822
I0831 12:54:14.930319       1 scheduler.go:454] Total Schedule Algo cumulative time:8.896335728s for 869
I0831 12:54:14.944955       1 scheduler.go:451] ScheduleAlgoTime 14.551914ms Start:2018-08-31 12:54:14.930397476 +0000 UTC m=+217.601019634 End:2018-08-31 12:54:14.944949424 +0000 UTC m=+217.615571548
I0831 12:54:14.944984       1 scheduler.go:454] Total Schedule Algo cumulative time:8.910887642s for 870
I0831 12:54:14.958235       1 scheduler.go:451] ScheduleAlgoTime 13.161661ms Start:2018-08-31 12:54:14.945068201 +0000 UTC m=+217.615690353 End:2018-08-31 12:54:14.958229894 +0000 UTC m=+217.628852014
I0831 12:54:14.958265       1 scheduler.go:454] Total Schedule Algo cumulative time:8.924049303s for 871
I0831 12:54:14.979030       1 scheduler.go:451] ScheduleAlgoTime 20.676847ms Start:2018-08-31 12:54:14.958346917 +0000 UTC m=+217.628969063 End:2018-08-31 12:54:14.979023792 +0000 UTC m=+217.649645910
I0831 12:54:14.979068       1 scheduler.go:454] Total Schedule Algo cumulative time:8.94472615s for 872
I0831 12:54:14.996203       1 scheduler.go:451] ScheduleAlgoTime 17.054899ms Start:2018-08-31 12:54:14.979141916 +0000 UTC m=+217.649764063 End:2018-08-31 12:54:14.996196839 +0000 UTC m=+217.666818962
I0831 12:54:14.996242       1 scheduler.go:454] Total Schedule Algo cumulative time:8.961781049s for 873
I0831 12:54:15.009584       1 scheduler.go:451] ScheduleAlgoTime 13.247174ms Start:2018-08-31 12:54:14.996331964 +0000 UTC m=+217.666954123 End:2018-08-31 12:54:15.009579179 +0000 UTC m=+217.680201297
I0831 12:54:15.009614       1 scheduler.go:454] Total Schedule Algo cumulative time:8.975028223s for 874
I0831 12:54:15.027116       1 scheduler.go:451] ScheduleAlgoTime 17.400466ms Start:2018-08-31 12:54:15.00970931 +0000 UTC m=+217.680331469 End:2018-08-31 12:54:15.027109816 +0000 UTC m=+217.697731935
I0831 12:54:15.027145       1 scheduler.go:454] Total Schedule Algo cumulative time:8.992428689s for 875
I0831 12:54:15.043726       1 scheduler.go:451] ScheduleAlgoTime 16.511377ms Start:2018-08-31 12:54:15.027209051 +0000 UTC m=+217.697831204 End:2018-08-31 12:54:15.04372046 +0000 UTC m=+217.714342581
I0831 12:54:15.043757       1 scheduler.go:454] Total Schedule Algo cumulative time:9.008940066s for 876
I0831 12:54:15.059608       1 scheduler.go:451] ScheduleAlgoTime 15.756659ms Start:2018-08-31 12:54:15.043846277 +0000 UTC m=+217.714468440 End:2018-08-31 12:54:15.059602978 +0000 UTC m=+217.730225099
I0831 12:54:15.059644       1 scheduler.go:454] Total Schedule Algo cumulative time:9.024696725s for 877
I0831 12:54:15.074837       1 scheduler.go:451] ScheduleAlgoTime 15.099121ms Start:2018-08-31 12:54:15.059730939 +0000 UTC m=+217.730353104 End:2018-08-31 12:54:15.074830105 +0000 UTC m=+217.745452225
I0831 12:54:15.074868       1 scheduler.go:454] Total Schedule Algo cumulative time:9.039795846s for 878
I0831 12:54:15.089141       1 scheduler.go:451] ScheduleAlgoTime 14.185185ms Start:2018-08-31 12:54:15.07494864 +0000 UTC m=+217.745570786 End:2018-08-31 12:54:15.089133842 +0000 UTC m=+217.759755971
I0831 12:54:15.089178       1 scheduler.go:454] Total Schedule Algo cumulative time:9.053981031s for 879
I0831 12:54:15.106185       1 scheduler.go:451] ScheduleAlgoTime 16.935019ms Start:2018-08-31 12:54:15.089243887 +0000 UTC m=+217.759866041 End:2018-08-31 12:54:15.10617894 +0000 UTC m=+217.776801060
I0831 12:54:15.106213       1 scheduler.go:454] Total Schedule Algo cumulative time:9.07091605s for 880
I0831 12:54:15.120806       1 scheduler.go:451] ScheduleAlgoTime 14.505057ms Start:2018-08-31 12:54:15.106295289 +0000 UTC m=+217.776917438 End:2018-08-31 12:54:15.120800375 +0000 UTC m=+217.791422495
I0831 12:54:15.120839       1 scheduler.go:454] Total Schedule Algo cumulative time:9.085421107s for 881
I0831 12:54:15.136358       1 scheduler.go:451] ScheduleAlgoTime 15.416937ms Start:2018-08-31 12:54:15.120936236 +0000 UTC m=+217.791558395 End:2018-08-31 12:54:15.13635321 +0000 UTC m=+217.806975332
I0831 12:54:15.136388       1 scheduler.go:454] Total Schedule Algo cumulative time:9.100838044s for 882
I0831 12:54:15.151132       1 scheduler.go:451] ScheduleAlgoTime 14.652024ms Start:2018-08-31 12:54:15.136474562 +0000 UTC m=+217.807096711 End:2018-08-31 12:54:15.15112661 +0000 UTC m=+217.821748735
I0831 12:54:15.151161       1 scheduler.go:454] Total Schedule Algo cumulative time:9.115490068s for 883
I0831 12:54:15.166660       1 scheduler.go:451] ScheduleAlgoTime 15.39415ms Start:2018-08-31 12:54:15.15125827 +0000 UTC m=+217.821880434 End:2018-08-31 12:54:15.166652456 +0000 UTC m=+217.837274584
I0831 12:54:15.166763       1 scheduler.go:454] Total Schedule Algo cumulative time:9.130884218s for 884
I0831 12:54:15.189211       1 scheduler.go:451] ScheduleAlgoTime 22.291533ms Start:2018-08-31 12:54:15.166912783 +0000 UTC m=+217.837534921 End:2018-08-31 12:54:15.189204333 +0000 UTC m=+217.859826454
I0831 12:54:15.189246       1 scheduler.go:454] Total Schedule Algo cumulative time:9.153175751s for 885
I0831 12:54:15.205145       1 scheduler.go:451] ScheduleAlgoTime 15.805472ms Start:2018-08-31 12:54:15.189333583 +0000 UTC m=+217.859955747 End:2018-08-31 12:54:15.205139098 +0000 UTC m=+217.875761219
I0831 12:54:15.205177       1 scheduler.go:454] Total Schedule Algo cumulative time:9.168981223s for 886
I0831 12:54:15.220995       1 scheduler.go:451] ScheduleAlgoTime 15.709448ms Start:2018-08-31 12:54:15.205278508 +0000 UTC m=+217.875900669 End:2018-08-31 12:54:15.220987998 +0000 UTC m=+217.891610117
I0831 12:54:15.221034       1 scheduler.go:454] Total Schedule Algo cumulative time:9.184690671s for 887
I0831 12:54:15.236564       1 scheduler.go:451] ScheduleAlgoTime 15.427395ms Start:2018-08-31 12:54:15.22113143 +0000 UTC m=+217.891753570 End:2018-08-31 12:54:15.236558846 +0000 UTC m=+217.907180965
I0831 12:54:15.236595       1 scheduler.go:454] Total Schedule Algo cumulative time:9.200118066s for 888
I0831 12:54:15.253505       1 scheduler.go:451] ScheduleAlgoTime 16.808722ms Start:2018-08-31 12:54:15.23669074 +0000 UTC m=+217.907312894 End:2018-08-31 12:54:15.253499496 +0000 UTC m=+217.924121616
I0831 12:54:15.253534       1 scheduler.go:454] Total Schedule Algo cumulative time:9.216926788s for 889
I0831 12:54:15.268665       1 scheduler.go:451] ScheduleAlgoTime 15.038646ms Start:2018-08-31 12:54:15.253621047 +0000 UTC m=+217.924243193 End:2018-08-31 12:54:15.268659719 +0000 UTC m=+217.939281839
I0831 12:54:15.268693       1 scheduler.go:454] Total Schedule Algo cumulative time:9.231965434s for 890
I0831 12:54:15.284412       1 scheduler.go:451] ScheduleAlgoTime 15.627965ms Start:2018-08-31 12:54:15.268778542 +0000 UTC m=+217.939400697 End:2018-08-31 12:54:15.284406539 +0000 UTC m=+217.955028662
I0831 12:54:15.284449       1 scheduler.go:454] Total Schedule Algo cumulative time:9.247593399s for 891
I0831 12:54:15.303631       1 scheduler.go:451] ScheduleAlgoTime 19.011677ms Start:2018-08-31 12:54:15.284610806 +0000 UTC m=+217.955232954 End:2018-08-31 12:54:15.303622511 +0000 UTC m=+217.974244631
I0831 12:54:15.303680       1 scheduler.go:454] Total Schedule Algo cumulative time:9.266605076s for 892
I0831 12:54:15.325798       1 scheduler.go:451] ScheduleAlgoTime 21.960007ms Start:2018-08-31 12:54:15.303830185 +0000 UTC m=+217.974452347 End:2018-08-31 12:54:15.325790235 +0000 UTC m=+217.996412354
I0831 12:54:15.325842       1 scheduler.go:454] Total Schedule Algo cumulative time:9.288565083s for 893
I0831 12:54:15.341611       1 scheduler.go:451] ScheduleAlgoTime 15.639652ms Start:2018-08-31 12:54:15.325964881 +0000 UTC m=+217.996587044 End:2018-08-31 12:54:15.341604574 +0000 UTC m=+218.012226696
I0831 12:54:15.341645       1 scheduler.go:454] Total Schedule Algo cumulative time:9.304204735s for 894
I0831 12:54:15.356731       1 scheduler.go:451] ScheduleAlgoTime 14.979341ms Start:2018-08-31 12:54:15.341745629 +0000 UTC m=+218.012367770 End:2018-08-31 12:54:15.356724988 +0000 UTC m=+218.027347111
I0831 12:54:15.356768       1 scheduler.go:454] Total Schedule Algo cumulative time:9.319184076s for 895
I0831 12:54:15.374005       1 scheduler.go:451] ScheduleAlgoTime 17.091922ms Start:2018-08-31 12:54:15.35690491 +0000 UTC m=+218.027527073 End:2018-08-31 12:54:15.373996865 +0000 UTC m=+218.044618995
I0831 12:54:15.374045       1 scheduler.go:454] Total Schedule Algo cumulative time:9.336275998s for 896
I0831 12:54:15.400342       1 scheduler.go:451] ScheduleAlgoTime 26.187829ms Start:2018-08-31 12:54:15.374145902 +0000 UTC m=+218.044768059 End:2018-08-31 12:54:15.40033376 +0000 UTC m=+218.070955888
I0831 12:54:15.400383       1 scheduler.go:454] Total Schedule Algo cumulative time:9.362463827s for 897
I0831 12:54:15.415366       1 scheduler.go:451] ScheduleAlgoTime 14.876944ms Start:2018-08-31 12:54:15.400479646 +0000 UTC m=+218.071101792 End:2018-08-31 12:54:15.415356605 +0000 UTC m=+218.085978736
I0831 12:54:15.415420       1 scheduler.go:454] Total Schedule Algo cumulative time:9.377340771s for 898
I0831 12:54:15.429627       1 scheduler.go:451] ScheduleAlgoTime 14.081289ms Start:2018-08-31 12:54:15.415540515 +0000 UTC m=+218.086162676 End:2018-08-31 12:54:15.429621844 +0000 UTC m=+218.100243965
I0831 12:54:15.429657       1 scheduler.go:454] Total Schedule Algo cumulative time:9.39142206s for 899
I0831 12:54:15.445831       1 scheduler.go:451] ScheduleAlgoTime 16.036153ms Start:2018-08-31 12:54:15.429788566 +0000 UTC m=+218.100410719 End:2018-08-31 12:54:15.44582475 +0000 UTC m=+218.116446872
I0831 12:54:15.445869       1 scheduler.go:454] Total Schedule Algo cumulative time:9.407458213s for 900
I0831 12:54:15.461145       1 scheduler.go:451] ScheduleAlgoTime 15.165954ms Start:2018-08-31 12:54:15.44597358 +0000 UTC m=+218.116595727 End:2018-08-31 12:54:15.461139561 +0000 UTC m=+218.131761681
I0831 12:54:15.461177       1 scheduler.go:454] Total Schedule Algo cumulative time:9.422624167s for 901
I0831 12:54:15.476831       1 scheduler.go:451] ScheduleAlgoTime 15.495232ms Start:2018-08-31 12:54:15.461330473 +0000 UTC m=+218.131952619 End:2018-08-31 12:54:15.476825731 +0000 UTC m=+218.147447851
I0831 12:54:15.476861       1 scheduler.go:454] Total Schedule Algo cumulative time:9.438119399s for 902
I0831 12:54:15.490928       1 scheduler.go:451] ScheduleAlgoTime 13.95672ms Start:2018-08-31 12:54:15.476964677 +0000 UTC m=+218.147586836 End:2018-08-31 12:54:15.49092142 +0000 UTC m=+218.161543556
I0831 12:54:15.490959       1 scheduler.go:454] Total Schedule Algo cumulative time:9.452076119s for 903
I0831 12:54:15.505417       1 scheduler.go:451] ScheduleAlgoTime 14.375474ms Start:2018-08-31 12:54:15.491036348 +0000 UTC m=+218.161658497 End:2018-08-31 12:54:15.505411852 +0000 UTC m=+218.176033971
I0831 12:54:15.505448       1 scheduler.go:454] Total Schedule Algo cumulative time:9.466451593s for 904
I0831 12:54:15.522110       1 scheduler.go:451] ScheduleAlgoTime 16.569702ms Start:2018-08-31 12:54:15.505534272 +0000 UTC m=+218.176156428 End:2018-08-31 12:54:15.522104009 +0000 UTC m=+218.192726130
I0831 12:54:15.522139       1 scheduler.go:454] Total Schedule Algo cumulative time:9.483021295s for 905
I0831 12:54:15.538150       1 scheduler.go:451] ScheduleAlgoTime 15.916169ms Start:2018-08-31 12:54:15.522227178 +0000 UTC m=+218.192849324 End:2018-08-31 12:54:15.538143372 +0000 UTC m=+218.208765493
I0831 12:54:15.538188       1 scheduler.go:454] Total Schedule Algo cumulative time:9.498937464s for 906
I0831 12:54:15.551853       1 scheduler.go:451] ScheduleAlgoTime 13.562894ms Start:2018-08-31 12:54:15.538284727 +0000 UTC m=+218.208906878 End:2018-08-31 12:54:15.551847653 +0000 UTC m=+218.222469772
I0831 12:54:15.551886       1 scheduler.go:454] Total Schedule Algo cumulative time:9.512500358s for 907
I0831 12:54:15.565934       1 scheduler.go:451] ScheduleAlgoTime 13.943476ms Start:2018-08-31 12:54:15.551983083 +0000 UTC m=+218.222605240 End:2018-08-31 12:54:15.565926575 +0000 UTC m=+218.236548716
I0831 12:54:15.565974       1 scheduler.go:454] Total Schedule Algo cumulative time:9.526443834s for 908
I0831 12:54:15.586819       1 scheduler.go:451] ScheduleAlgoTime 20.737944ms Start:2018-08-31 12:54:15.566075191 +0000 UTC m=+218.236697340 End:2018-08-31 12:54:15.586813161 +0000 UTC m=+218.257435284
I0831 12:54:15.586859       1 scheduler.go:454] Total Schedule Algo cumulative time:9.547181778s for 909
I0831 12:54:15.604116       1 scheduler.go:451] ScheduleAlgoTime 17.155859ms Start:2018-08-31 12:54:15.58695334 +0000 UTC m=+218.257575483 End:2018-08-31 12:54:15.604109224 +0000 UTC m=+218.274731342
I0831 12:54:15.604157       1 scheduler.go:454] Total Schedule Algo cumulative time:9.564337637s for 910
I0831 12:54:15.618595       1 scheduler.go:451] ScheduleAlgoTime 14.343583ms Start:2018-08-31 12:54:15.604245958 +0000 UTC m=+218.274868127 End:2018-08-31 12:54:15.61858959 +0000 UTC m=+218.289211710
I0831 12:54:15.618633       1 scheduler.go:454] Total Schedule Algo cumulative time:9.57868122s for 911
I0831 12:54:15.635116       1 scheduler.go:451] ScheduleAlgoTime 16.387256ms Start:2018-08-31 12:54:15.618722728 +0000 UTC m=+218.289344880 End:2018-08-31 12:54:15.635110013 +0000 UTC m=+218.305732136
I0831 12:54:15.635149       1 scheduler.go:454] Total Schedule Algo cumulative time:9.595068476s for 912
I0831 12:54:15.649678       1 scheduler.go:451] ScheduleAlgoTime 14.438151ms Start:2018-08-31 12:54:15.635234919 +0000 UTC m=+218.305857088 End:2018-08-31 12:54:15.64967312 +0000 UTC m=+218.320295239
I0831 12:54:15.649718       1 scheduler.go:454] Total Schedule Algo cumulative time:9.609506627s for 913
I0831 12:54:15.665133       1 scheduler.go:451] ScheduleAlgoTime 15.306927ms Start:2018-08-31 12:54:15.64981969 +0000 UTC m=+218.320441836 End:2018-08-31 12:54:15.665126644 +0000 UTC m=+218.335748763
I0831 12:54:15.665170       1 scheduler.go:454] Total Schedule Algo cumulative time:9.624813554s for 914
I0831 12:54:15.680394       1 scheduler.go:451] ScheduleAlgoTime 15.106004ms Start:2018-08-31 12:54:15.665283165 +0000 UTC m=+218.335905307 End:2018-08-31 12:54:15.680389193 +0000 UTC m=+218.351011311
I0831 12:54:15.680431       1 scheduler.go:454] Total Schedule Algo cumulative time:9.639919558s for 915
I0831 12:54:15.694432       1 scheduler.go:451] ScheduleAlgoTime 13.877729ms Start:2018-08-31 12:54:15.680548357 +0000 UTC m=+218.351170508 End:2018-08-31 12:54:15.694426113 +0000 UTC m=+218.365048237
I0831 12:54:15.694469       1 scheduler.go:454] Total Schedule Algo cumulative time:9.653797287s for 916
I0831 12:54:15.710508       1 scheduler.go:451] ScheduleAlgoTime 15.95594ms Start:2018-08-31 12:54:15.694547255 +0000 UTC m=+218.365169408 End:2018-08-31 12:54:15.710503225 +0000 UTC m=+218.381125348
I0831 12:54:15.710538       1 scheduler.go:454] Total Schedule Algo cumulative time:9.669753227s for 917
I0831 12:54:15.725913       1 scheduler.go:451] ScheduleAlgoTime 15.210615ms Start:2018-08-31 12:54:15.710697372 +0000 UTC m=+218.381319535 End:2018-08-31 12:54:15.725908032 +0000 UTC m=+218.396530150
I0831 12:54:15.725950       1 scheduler.go:454] Total Schedule Algo cumulative time:9.684963842s for 918
I0831 12:54:15.740466       1 scheduler.go:451] ScheduleAlgoTime 14.403714ms Start:2018-08-31 12:54:15.726048572 +0000 UTC m=+218.396670735 End:2018-08-31 12:54:15.740452329 +0000 UTC m=+218.411074449
I0831 12:54:15.740495       1 scheduler.go:454] Total Schedule Algo cumulative time:9.699367556s for 919
I0831 12:54:15.757770       1 scheduler.go:451] ScheduleAlgoTime 17.174372ms Start:2018-08-31 12:54:15.740591451 +0000 UTC m=+218.411213604 End:2018-08-31 12:54:15.757765853 +0000 UTC m=+218.428387976
I0831 12:54:15.757801       1 scheduler.go:454] Total Schedule Algo cumulative time:9.716541928s for 920
I0831 12:54:15.777194       1 scheduler.go:451] ScheduleAlgoTime 19.277551ms Start:2018-08-31 12:54:15.757910669 +0000 UTC m=+218.428532812 End:2018-08-31 12:54:15.777188241 +0000 UTC m=+218.447810363
I0831 12:54:15.777233       1 scheduler.go:454] Total Schedule Algo cumulative time:9.735819479s for 921
I0831 12:54:15.793354       1 scheduler.go:451] ScheduleAlgoTime 16.020451ms Start:2018-08-31 12:54:15.777326703 +0000 UTC m=+218.447948839 End:2018-08-31 12:54:15.793347172 +0000 UTC m=+218.463969290
I0831 12:54:15.793394       1 scheduler.go:454] Total Schedule Algo cumulative time:9.75183993s for 922
I0831 12:54:15.808000       1 scheduler.go:451] ScheduleAlgoTime 14.503606ms Start:2018-08-31 12:54:15.793491608 +0000 UTC m=+218.464113757 End:2018-08-31 12:54:15.807995244 +0000 UTC m=+218.478617363
I0831 12:54:15.808043       1 scheduler.go:454] Total Schedule Algo cumulative time:9.766343536s for 923
I0831 12:54:15.823482       1 scheduler.go:451] ScheduleAlgoTime 15.27707ms Start:2018-08-31 12:54:15.808198919 +0000 UTC m=+218.478821067 End:2018-08-31 12:54:15.823476017 +0000 UTC m=+218.494098137
I0831 12:54:15.823511       1 scheduler.go:454] Total Schedule Algo cumulative time:9.781620606s for 924
I0831 12:54:15.839107       1 scheduler.go:451] ScheduleAlgoTime 15.509989ms Start:2018-08-31 12:54:15.823591183 +0000 UTC m=+218.494213329 End:2018-08-31 12:54:15.839101196 +0000 UTC m=+218.509723318
I0831 12:54:15.839138       1 scheduler.go:454] Total Schedule Algo cumulative time:9.797130595s for 925
I0831 12:54:15.853398       1 scheduler.go:451] ScheduleAlgoTime 14.170867ms Start:2018-08-31 12:54:15.839220483 +0000 UTC m=+218.509842636 End:2018-08-31 12:54:15.85339138 +0000 UTC m=+218.524013503
I0831 12:54:15.853438       1 scheduler.go:454] Total Schedule Algo cumulative time:9.811301462s for 926
I0831 12:54:15.869217       1 scheduler.go:451] ScheduleAlgoTime 15.696341ms Start:2018-08-31 12:54:15.853515093 +0000 UTC m=+218.524137249 End:2018-08-31 12:54:15.869211472 +0000 UTC m=+218.539833590
I0831 12:54:15.869253       1 scheduler.go:454] Total Schedule Algo cumulative time:9.826997803s for 927
I0831 12:54:15.887567       1 scheduler.go:451] ScheduleAlgoTime 18.210386ms Start:2018-08-31 12:54:15.869350939 +0000 UTC m=+218.539973102 End:2018-08-31 12:54:15.887561369 +0000 UTC m=+218.558183488
I0831 12:54:15.887599       1 scheduler.go:454] Total Schedule Algo cumulative time:9.845208189s for 928
I0831 12:54:15.904177       1 scheduler.go:451] ScheduleAlgoTime 16.488415ms Start:2018-08-31 12:54:15.887682424 +0000 UTC m=+218.558304551 End:2018-08-31 12:54:15.904170843 +0000 UTC m=+218.574792966
I0831 12:54:15.904213       1 scheduler.go:454] Total Schedule Algo cumulative time:9.861696604s for 929
I0831 12:54:15.921400       1 scheduler.go:451] ScheduleAlgoTime 17.107332ms Start:2018-08-31 12:54:15.904284544 +0000 UTC m=+218.574906691 End:2018-08-31 12:54:15.921391892 +0000 UTC m=+218.592014023
I0831 12:54:15.921441       1 scheduler.go:454] Total Schedule Algo cumulative time:9.878803936s for 930
I0831 12:54:15.937740       1 scheduler.go:451] ScheduleAlgoTime 16.179345ms Start:2018-08-31 12:54:15.92155403 +0000 UTC m=+218.592176183 End:2018-08-31 12:54:15.937733399 +0000 UTC m=+218.608355528
I0831 12:54:15.937777       1 scheduler.go:454] Total Schedule Algo cumulative time:9.894983281s for 931
I0831 12:54:15.953088       1 scheduler.go:451] ScheduleAlgoTime 15.227899ms Start:2018-08-31 12:54:15.937854943 +0000 UTC m=+218.608477109 End:2018-08-31 12:54:15.953082887 +0000 UTC m=+218.623705008
I0831 12:54:15.953119       1 scheduler.go:454] Total Schedule Algo cumulative time:9.91021118s for 932
I0831 12:54:15.973690       1 scheduler.go:451] ScheduleAlgoTime 20.47327ms Start:2018-08-31 12:54:15.953210456 +0000 UTC m=+218.623832594 End:2018-08-31 12:54:15.973683743 +0000 UTC m=+218.644305864
I0831 12:54:15.973724       1 scheduler.go:454] Total Schedule Algo cumulative time:9.93068445s for 933
I0831 12:54:15.987844       1 scheduler.go:451] ScheduleAlgoTime 13.978353ms Start:2018-08-31 12:54:15.973859629 +0000 UTC m=+218.644481786 End:2018-08-31 12:54:15.987838019 +0000 UTC m=+218.658460139
I0831 12:54:15.987873       1 scheduler.go:454] Total Schedule Algo cumulative time:9.944662803s for 934
I0831 12:54:16.002705       1 scheduler.go:451] ScheduleAlgoTime 14.737175ms Start:2018-08-31 12:54:15.987961311 +0000 UTC m=+218.658583458 End:2018-08-31 12:54:16.002698514 +0000 UTC m=+218.673320633
I0831 12:54:16.002742       1 scheduler.go:454] Total Schedule Algo cumulative time:9.959399978s for 935
I0831 12:54:16.018061       1 scheduler.go:451] ScheduleAlgoTime 15.21876ms Start:2018-08-31 12:54:16.002836578 +0000 UTC m=+218.673458752 End:2018-08-31 12:54:16.018055392 +0000 UTC m=+218.688677512
I0831 12:54:16.018094       1 scheduler.go:454] Total Schedule Algo cumulative time:9.974618738s for 936
I0831 12:54:16.034587       1 scheduler.go:451] ScheduleAlgoTime 16.370597ms Start:2018-08-31 12:54:16.01819395 +0000 UTC m=+218.688816106 End:2018-08-31 12:54:16.034564579 +0000 UTC m=+218.705186703
I0831 12:54:16.034617       1 scheduler.go:454] Total Schedule Algo cumulative time:9.990989335s for 937
I0831 12:54:16.049625       1 scheduler.go:451] ScheduleAlgoTime 14.923135ms Start:2018-08-31 12:54:16.034693878 +0000 UTC m=+218.705316025 End:2018-08-31 12:54:16.049617033 +0000 UTC m=+218.720239160
I0831 12:54:16.049662       1 scheduler.go:454] Total Schedule Algo cumulative time:10.00591247s for 938
I0831 12:54:16.066208       1 scheduler.go:451] ScheduleAlgoTime 16.456889ms Start:2018-08-31 12:54:16.049744314 +0000 UTC m=+218.720366467 End:2018-08-31 12:54:16.066201237 +0000 UTC m=+218.736823356
I0831 12:54:16.066252       1 scheduler.go:454] Total Schedule Algo cumulative time:10.022369359s for 939
I0831 12:54:16.083254       1 scheduler.go:451] ScheduleAlgoTime 16.902641ms Start:2018-08-31 12:54:16.06634381 +0000 UTC m=+218.736965962 End:2018-08-31 12:54:16.08324648 +0000 UTC m=+218.753868603
I0831 12:54:16.083296       1 scheduler.go:454] Total Schedule Algo cumulative time:10.039272s for 940
I0831 12:54:16.099202       1 scheduler.go:451] ScheduleAlgoTime 15.811054ms Start:2018-08-31 12:54:16.08338474 +0000 UTC m=+218.754006887 End:2018-08-31 12:54:16.099195817 +0000 UTC m=+218.769817941
I0831 12:54:16.099235       1 scheduler.go:454] Total Schedule Algo cumulative time:10.055083054s for 941
I0831 12:54:16.116718       1 scheduler.go:451] ScheduleAlgoTime 17.378528ms Start:2018-08-31 12:54:16.09933169 +0000 UTC m=+218.769953849 End:2018-08-31 12:54:16.11671025 +0000 UTC m=+218.787332377
I0831 12:54:16.116754       1 scheduler.go:454] Total Schedule Algo cumulative time:10.072461582s for 942
I0831 12:54:16.132018       1 scheduler.go:451] ScheduleAlgoTime 15.154258ms Start:2018-08-31 12:54:16.116857947 +0000 UTC m=+218.787480133 End:2018-08-31 12:54:16.132012265 +0000 UTC m=+218.802634391
I0831 12:54:16.132051       1 scheduler.go:454] Total Schedule Algo cumulative time:10.08761584s for 943
I0831 12:54:16.147192       1 scheduler.go:451] ScheduleAlgoTime 15.037149ms Start:2018-08-31 12:54:16.132149547 +0000 UTC m=+218.802771712 End:2018-08-31 12:54:16.147186742 +0000 UTC m=+218.817808861
I0831 12:54:16.147227       1 scheduler.go:454] Total Schedule Algo cumulative time:10.102652989s for 944
I0831 12:54:16.171219       1 scheduler.go:451] ScheduleAlgoTime 23.868907ms Start:2018-08-31 12:54:16.147342682 +0000 UTC m=+218.817964843 End:2018-08-31 12:54:16.17121163 +0000 UTC m=+218.841833750
I0831 12:54:16.171253       1 scheduler.go:454] Total Schedule Algo cumulative time:10.126521896s for 945
I0831 12:54:16.190829       1 scheduler.go:451] ScheduleAlgoTime 19.483744ms Start:2018-08-31 12:54:16.171334461 +0000 UTC m=+218.841956609 End:2018-08-31 12:54:16.190818222 +0000 UTC m=+218.861440353
I0831 12:54:16.190925       1 scheduler.go:454] Total Schedule Algo cumulative time:10.14600564s for 946
I0831 12:54:16.212419       1 scheduler.go:451] ScheduleAlgoTime 21.398527ms Start:2018-08-31 12:54:16.191013354 +0000 UTC m=+218.861635479 End:2018-08-31 12:54:16.212411883 +0000 UTC m=+218.883034006
I0831 12:54:16.212464       1 scheduler.go:454] Total Schedule Algo cumulative time:10.167404167s for 947
I0831 12:54:16.230466       1 scheduler.go:451] ScheduleAlgoTime 17.907996ms Start:2018-08-31 12:54:16.212539439 +0000 UTC m=+218.883161580 End:2018-08-31 12:54:16.230447448 +0000 UTC m=+218.901069576
I0831 12:54:16.230508       1 scheduler.go:454] Total Schedule Algo cumulative time:10.185312163s for 948
I0831 12:54:16.245096       1 scheduler.go:451] ScheduleAlgoTime 14.486644ms Start:2018-08-31 12:54:16.230603801 +0000 UTC m=+218.901225973 End:2018-08-31 12:54:16.245090494 +0000 UTC m=+218.915712617
I0831 12:54:16.245128       1 scheduler.go:454] Total Schedule Algo cumulative time:10.199798807s for 949
I0831 12:54:16.260114       1 scheduler.go:451] ScheduleAlgoTime 14.896001ms Start:2018-08-31 12:54:16.245210016 +0000 UTC m=+218.915832160 End:2018-08-31 12:54:16.260106038 +0000 UTC m=+218.930728161
I0831 12:54:16.260152       1 scheduler.go:454] Total Schedule Algo cumulative time:10.214694808s for 950
I0831 12:54:16.275045       1 scheduler.go:451] ScheduleAlgoTime 14.806049ms Start:2018-08-31 12:54:16.260232961 +0000 UTC m=+218.930855113 End:2018-08-31 12:54:16.275039042 +0000 UTC m=+218.945661162
I0831 12:54:16.275091       1 scheduler.go:454] Total Schedule Algo cumulative time:10.229500857s for 951
I0831 12:54:16.290413       1 scheduler.go:451] ScheduleAlgoTime 15.1898ms Start:2018-08-31 12:54:16.27521767 +0000 UTC m=+218.945839851 End:2018-08-31 12:54:16.290407533 +0000 UTC m=+218.961029651
I0831 12:54:16.290443       1 scheduler.go:454] Total Schedule Algo cumulative time:10.244690657s for 952
I0831 12:54:16.306444       1 scheduler.go:451] ScheduleAlgoTime 15.893314ms Start:2018-08-31 12:54:16.290543261 +0000 UTC m=+218.961165410 End:2018-08-31 12:54:16.306436605 +0000 UTC m=+218.977058724
I0831 12:54:16.306489       1 scheduler.go:454] Total Schedule Algo cumulative time:10.260583971s for 953
I0831 12:54:16.324265       1 scheduler.go:451] ScheduleAlgoTime 17.646967ms Start:2018-08-31 12:54:16.306611562 +0000 UTC m=+218.977233718 End:2018-08-31 12:54:16.324258564 +0000 UTC m=+218.994880685
I0831 12:54:16.324295       1 scheduler.go:454] Total Schedule Algo cumulative time:10.278230938s for 954
I0831 12:54:16.341435       1 scheduler.go:451] ScheduleAlgoTime 17.040496ms Start:2018-08-31 12:54:16.324388098 +0000 UTC m=+218.995010250 End:2018-08-31 12:54:16.341428625 +0000 UTC m=+219.012050746
I0831 12:54:16.341474       1 scheduler.go:454] Total Schedule Algo cumulative time:10.295271434s for 955
I0831 12:54:16.356894       1 scheduler.go:451] ScheduleAlgoTime 15.320901ms Start:2018-08-31 12:54:16.341568383 +0000 UTC m=+219.012190532 End:2018-08-31 12:54:16.356889313 +0000 UTC m=+219.027511433
I0831 12:54:16.356938       1 scheduler.go:454] Total Schedule Algo cumulative time:10.310592335s for 956
I0831 12:54:16.374958       1 scheduler.go:451] ScheduleAlgoTime 17.904066ms Start:2018-08-31 12:54:16.357048654 +0000 UTC m=+219.027670796 End:2018-08-31 12:54:16.374952743 +0000 UTC m=+219.045574862
I0831 12:54:16.374996       1 scheduler.go:454] Total Schedule Algo cumulative time:10.328496401s for 957
I0831 12:54:16.389699       1 scheduler.go:451] ScheduleAlgoTime 14.616177ms Start:2018-08-31 12:54:16.375077529 +0000 UTC m=+219.045699676 End:2018-08-31 12:54:16.389693732 +0000 UTC m=+219.060315853
I0831 12:54:16.389737       1 scheduler.go:454] Total Schedule Algo cumulative time:10.343112578s for 958
I0831 12:54:16.406198       1 scheduler.go:451] ScheduleAlgoTime 16.380245ms Start:2018-08-31 12:54:16.389813008 +0000 UTC m=+219.060435178 End:2018-08-31 12:54:16.406193303 +0000 UTC m=+219.076815423
I0831 12:54:16.406230       1 scheduler.go:454] Total Schedule Algo cumulative time:10.359492823s for 959
I0831 12:54:16.421527       1 scheduler.go:451] ScheduleAlgoTime 15.173222ms Start:2018-08-31 12:54:16.406348461 +0000 UTC m=+219.076970610 End:2018-08-31 12:54:16.421521713 +0000 UTC m=+219.092143832
I0831 12:54:16.421556       1 scheduler.go:454] Total Schedule Algo cumulative time:10.374666045s for 960
I0831 12:54:16.437309       1 scheduler.go:451] ScheduleAlgoTime 15.657504ms Start:2018-08-31 12:54:16.421646008 +0000 UTC m=+219.092268157 End:2018-08-31 12:54:16.437303541 +0000 UTC m=+219.107925661
I0831 12:54:16.437340       1 scheduler.go:454] Total Schedule Algo cumulative time:10.390323549s for 961
I0831 12:54:16.454824       1 scheduler.go:451] ScheduleAlgoTime 17.386796ms Start:2018-08-31 12:54:16.437431347 +0000 UTC m=+219.108053499 End:2018-08-31 12:54:16.454818174 +0000 UTC m=+219.125440295
I0831 12:54:16.454856       1 scheduler.go:454] Total Schedule Algo cumulative time:10.407710345s for 962
I0831 12:54:16.470037       1 scheduler.go:451] ScheduleAlgoTime 15.081844ms Start:2018-08-31 12:54:16.454948752 +0000 UTC m=+219.125570893 End:2018-08-31 12:54:16.470030609 +0000 UTC m=+219.140652737
I0831 12:54:16.470071       1 scheduler.go:454] Total Schedule Algo cumulative time:10.422792189s for 963
I0831 12:54:16.484130       1 scheduler.go:451] ScheduleAlgoTime 13.957174ms Start:2018-08-31 12:54:16.470167079 +0000 UTC m=+219.140789222 End:2018-08-31 12:54:16.484124276 +0000 UTC m=+219.154746396
I0831 12:54:16.484159       1 scheduler.go:454] Total Schedule Algo cumulative time:10.436749363s for 964
I0831 12:54:16.499825       1 scheduler.go:451] ScheduleAlgoTime 15.596682ms Start:2018-08-31 12:54:16.484222382 +0000 UTC m=+219.154844532 End:2018-08-31 12:54:16.499819091 +0000 UTC m=+219.170441214
I0831 12:54:16.499861       1 scheduler.go:454] Total Schedule Algo cumulative time:10.452346045s for 965
I0831 12:54:16.516163       1 scheduler.go:451] ScheduleAlgoTime 16.171656ms Start:2018-08-31 12:54:16.499985443 +0000 UTC m=+219.170607583 End:2018-08-31 12:54:16.516157121 +0000 UTC m=+219.186779239
I0831 12:54:16.516203       1 scheduler.go:454] Total Schedule Algo cumulative time:10.468517701s for 966
I0831 12:54:16.530934       1 scheduler.go:451] ScheduleAlgoTime 14.620936ms Start:2018-08-31 12:54:16.51630694 +0000 UTC m=+219.186929089 End:2018-08-31 12:54:16.530927904 +0000 UTC m=+219.201550025
I0831 12:54:16.530978       1 scheduler.go:454] Total Schedule Algo cumulative time:10.483138637s for 967
I0831 12:54:16.545685       1 scheduler.go:451] ScheduleAlgoTime 14.606051ms Start:2018-08-31 12:54:16.53107224 +0000 UTC m=+219.201694389 End:2018-08-31 12:54:16.54567832 +0000 UTC m=+219.216300440
I0831 12:54:16.545721       1 scheduler.go:454] Total Schedule Algo cumulative time:10.497744688s for 968
I0831 12:54:16.564248       1 scheduler.go:451] ScheduleAlgoTime 18.421845ms Start:2018-08-31 12:54:16.545816721 +0000 UTC m=+219.216438869 End:2018-08-31 12:54:16.564238504 +0000 UTC m=+219.234860714
I0831 12:54:16.564309       1 scheduler.go:454] Total Schedule Algo cumulative time:10.516166533s for 969
I0831 12:54:16.580513       1 scheduler.go:451] ScheduleAlgoTime 15.471254ms Start:2018-08-31 12:54:16.565031852 +0000 UTC m=+219.235654001 End:2018-08-31 12:54:16.580503134 +0000 UTC m=+219.251125255
I0831 12:54:16.580559       1 scheduler.go:454] Total Schedule Algo cumulative time:10.531637787s for 970
I0831 12:54:16.595565       1 scheduler.go:451] ScheduleAlgoTime 14.89554ms Start:2018-08-31 12:54:16.580663333 +0000 UTC m=+219.251285507 End:2018-08-31 12:54:16.595558926 +0000 UTC m=+219.266181047
I0831 12:54:16.595600       1 scheduler.go:454] Total Schedule Algo cumulative time:10.546533327s for 971
I0831 12:54:16.613569       1 scheduler.go:451] ScheduleAlgoTime 17.877704ms Start:2018-08-31 12:54:16.595683873 +0000 UTC m=+219.266306011 End:2018-08-31 12:54:16.613561586 +0000 UTC m=+219.284183715
I0831 12:54:16.613606       1 scheduler.go:454] Total Schedule Algo cumulative time:10.564411031s for 972
I0831 12:54:16.627860       1 scheduler.go:451] ScheduleAlgoTime 14.151261ms Start:2018-08-31 12:54:16.613702281 +0000 UTC m=+219.284324457 End:2018-08-31 12:54:16.627853599 +0000 UTC m=+219.298475718
I0831 12:54:16.627897       1 scheduler.go:454] Total Schedule Algo cumulative time:10.578562292s for 973
I0831 12:54:16.643745       1 scheduler.go:451] ScheduleAlgoTime 15.753898ms Start:2018-08-31 12:54:16.627984725 +0000 UTC m=+219.298606871 End:2018-08-31 12:54:16.643738651 +0000 UTC m=+219.314360769
I0831 12:54:16.643775       1 scheduler.go:454] Total Schedule Algo cumulative time:10.59431619s for 974
I0831 12:54:16.659556       1 scheduler.go:451] ScheduleAlgoTime 15.700455ms Start:2018-08-31 12:54:16.643850619 +0000 UTC m=+219.314472771 End:2018-08-31 12:54:16.659551105 +0000 UTC m=+219.330173226
I0831 12:54:16.659588       1 scheduler.go:454] Total Schedule Algo cumulative time:10.610016645s for 975
I0831 12:54:16.675020       1 scheduler.go:451] ScheduleAlgoTime 15.339444ms Start:2018-08-31 12:54:16.65967594 +0000 UTC m=+219.330298087 End:2018-08-31 12:54:16.675015407 +0000 UTC m=+219.345637531
I0831 12:54:16.675052       1 scheduler.go:454] Total Schedule Algo cumulative time:10.625356089s for 976
I0831 12:54:16.691893       1 scheduler.go:451] ScheduleAlgoTime 16.751421ms Start:2018-08-31 12:54:16.675134985 +0000 UTC m=+219.345757149 End:2018-08-31 12:54:16.691886451 +0000 UTC m=+219.362508570
I0831 12:54:16.691924       1 scheduler.go:454] Total Schedule Algo cumulative time:10.64210751s for 977
I0831 12:54:16.707405       1 scheduler.go:451] ScheduleAlgoTime 15.397499ms Start:2018-08-31 12:54:16.692001485 +0000 UTC m=+219.362623628 End:2018-08-31 12:54:16.707399002 +0000 UTC m=+219.378021127
I0831 12:54:16.707435       1 scheduler.go:454] Total Schedule Algo cumulative time:10.657505009s for 978
I0831 12:54:16.724769       1 scheduler.go:451] ScheduleAlgoTime 17.224166ms Start:2018-08-31 12:54:16.707537055 +0000 UTC m=+219.378159186 End:2018-08-31 12:54:16.724761233 +0000 UTC m=+219.395383352
I0831 12:54:16.724812       1 scheduler.go:454] Total Schedule Algo cumulative time:10.674729175s for 979
I0831 12:54:16.741350       1 scheduler.go:451] ScheduleAlgoTime 16.441888ms Start:2018-08-31 12:54:16.724902002 +0000 UTC m=+219.395524167 End:2018-08-31 12:54:16.741343937 +0000 UTC m=+219.411966055
I0831 12:54:16.741388       1 scheduler.go:454] Total Schedule Algo cumulative time:10.691171063s for 980
I0831 12:54:16.756405       1 scheduler.go:451] ScheduleAlgoTime 14.928016ms Start:2018-08-31 12:54:16.741472149 +0000 UTC m=+219.412094298 End:2018-08-31 12:54:16.756400191 +0000 UTC m=+219.427022314
I0831 12:54:16.756442       1 scheduler.go:454] Total Schedule Algo cumulative time:10.706099079s for 981
I0831 12:54:16.781111       1 scheduler.go:451] ScheduleAlgoTime 24.563585ms Start:2018-08-31 12:54:16.756540032 +0000 UTC m=+219.427162179 End:2018-08-31 12:54:16.781103644 +0000 UTC m=+219.451725764
I0831 12:54:16.781148       1 scheduler.go:454] Total Schedule Algo cumulative time:10.730662664s for 982
I0831 12:54:16.795283       1 scheduler.go:451] ScheduleAlgoTime 14.04672ms Start:2018-08-31 12:54:16.781231105 +0000 UTC m=+219.451853288 End:2018-08-31 12:54:16.795277889 +0000 UTC m=+219.465900008
I0831 12:54:16.795319       1 scheduler.go:454] Total Schedule Algo cumulative time:10.744709384s for 983
I0831 12:54:16.812135       1 scheduler.go:451] ScheduleAlgoTime 16.723367ms Start:2018-08-31 12:54:16.795405253 +0000 UTC m=+219.466027406 End:2018-08-31 12:54:16.812128651 +0000 UTC m=+219.482750773
I0831 12:54:16.812167       1 scheduler.go:454] Total Schedule Algo cumulative time:10.761432751s for 984
I0831 12:54:16.826558       1 scheduler.go:451] ScheduleAlgoTime 14.316396ms Start:2018-08-31 12:54:16.812234585 +0000 UTC m=+219.482856733 End:2018-08-31 12:54:16.826551007 +0000 UTC m=+219.497173129
I0831 12:54:16.826603       1 scheduler.go:454] Total Schedule Algo cumulative time:10.775749147s for 985
I0831 12:54:16.841636       1 scheduler.go:451] ScheduleAlgoTime 14.95535ms Start:2018-08-31 12:54:16.826675382 +0000 UTC m=+219.497297537 End:2018-08-31 12:54:16.841630769 +0000 UTC m=+219.512252887
I0831 12:54:16.841673       1 scheduler.go:454] Total Schedule Algo cumulative time:10.790704497s for 986
I0831 12:54:16.857278       1 scheduler.go:451] ScheduleAlgoTime 15.517434ms Start:2018-08-31 12:54:16.841754705 +0000 UTC m=+219.512376848 End:2018-08-31 12:54:16.857272164 +0000 UTC m=+219.527894282
I0831 12:54:16.857307       1 scheduler.go:454] Total Schedule Algo cumulative time:10.806221931s for 987
I0831 12:54:16.873026       1 scheduler.go:451] ScheduleAlgoTime 15.641719ms Start:2018-08-31 12:54:16.857379479 +0000 UTC m=+219.528001643 End:2018-08-31 12:54:16.873021242 +0000 UTC m=+219.543643362
I0831 12:54:16.873059       1 scheduler.go:454] Total Schedule Algo cumulative time:10.82186365s for 988
I0831 12:54:16.889332       1 scheduler.go:451] ScheduleAlgoTime 16.192879ms Start:2018-08-31 12:54:16.873130155 +0000 UTC m=+219.543752308 End:2018-08-31 12:54:16.889323054 +0000 UTC m=+219.559945187
I0831 12:54:16.889367       1 scheduler.go:454] Total Schedule Algo cumulative time:10.838056529s for 989
I0831 12:54:16.906828       1 scheduler.go:451] ScheduleAlgoTime 17.376861ms Start:2018-08-31 12:54:16.889444711 +0000 UTC m=+219.560066901 End:2018-08-31 12:54:16.906821641 +0000 UTC m=+219.577443762
I0831 12:54:16.906858       1 scheduler.go:454] Total Schedule Algo cumulative time:10.85543339s for 990
I0831 12:54:16.921077       1 scheduler.go:451] ScheduleAlgoTime 14.126597ms Start:2018-08-31 12:54:16.906943821 +0000 UTC m=+219.577566006 End:2018-08-31 12:54:16.921070484 +0000 UTC m=+219.591692603
I0831 12:54:16.921108       1 scheduler.go:454] Total Schedule Algo cumulative time:10.869559987s for 991
I0831 12:54:16.936105       1 scheduler.go:451] ScheduleAlgoTime 14.898215ms Start:2018-08-31 12:54:16.921201184 +0000 UTC m=+219.591823372 End:2018-08-31 12:54:16.936099467 +0000 UTC m=+219.606721587
I0831 12:54:16.936135       1 scheduler.go:454] Total Schedule Algo cumulative time:10.884458202s for 992
I0831 12:54:16.951853       1 scheduler.go:451] ScheduleAlgoTime 15.627312ms Start:2018-08-31 12:54:16.936217994 +0000 UTC m=+219.606840137 End:2018-08-31 12:54:16.951845323 +0000 UTC m=+219.622467449
I0831 12:54:16.951890       1 scheduler.go:454] Total Schedule Algo cumulative time:10.900085514s for 993
I0831 12:54:16.973554       1 scheduler.go:451] ScheduleAlgoTime 21.561938ms Start:2018-08-31 12:54:16.951985421 +0000 UTC m=+219.622607576 End:2018-08-31 12:54:16.973547396 +0000 UTC m=+219.644169514
I0831 12:54:16.973589       1 scheduler.go:454] Total Schedule Algo cumulative time:10.921647452s for 994
I0831 12:54:16.991854       1 scheduler.go:451] ScheduleAlgoTime 18.164293ms Start:2018-08-31 12:54:16.973681871 +0000 UTC m=+219.644304024 End:2018-08-31 12:54:16.991846191 +0000 UTC m=+219.662468317
I0831 12:54:16.991902       1 scheduler.go:454] Total Schedule Algo cumulative time:10.939811745s for 995
I0831 12:54:17.006191       1 scheduler.go:451] ScheduleAlgoTime 14.19301ms Start:2018-08-31 12:54:16.991992751 +0000 UTC m=+219.662614886 End:2018-08-31 12:54:17.006185776 +0000 UTC m=+219.676807896
I0831 12:54:17.006223       1 scheduler.go:454] Total Schedule Algo cumulative time:10.954004755s for 996
I0831 12:54:17.023017       1 scheduler.go:451] ScheduleAlgoTime 16.706349ms Start:2018-08-31 12:54:17.006304822 +0000 UTC m=+219.676926966 End:2018-08-31 12:54:17.023011194 +0000 UTC m=+219.693633315
I0831 12:54:17.023055       1 scheduler.go:454] Total Schedule Algo cumulative time:10.970711104s for 997
I0831 12:54:17.037481       1 scheduler.go:451] ScheduleAlgoTime 14.33104ms Start:2018-08-31 12:54:17.02314531 +0000 UTC m=+219.693767452 End:2018-08-31 12:54:17.037476373 +0000 UTC m=+219.708098492
I0831 12:54:17.037509       1 scheduler.go:454] Total Schedule Algo cumulative time:10.985042144s for 998
I0831 12:54:17.055352       1 scheduler.go:451] ScheduleAlgoTime 17.743539ms Start:2018-08-31 12:54:17.037600172 +0000 UTC m=+219.708222318 End:2018-08-31 12:54:17.055343728 +0000 UTC m=+219.725965857
I0831 12:54:17.055392       1 scheduler.go:454] Total Schedule Algo cumulative time:11.002785683s for 999
I0831 12:54:17.071502       1 scheduler.go:451] ScheduleAlgoTime 16.034523ms Start:2018-08-31 12:54:17.055462472 +0000 UTC m=+219.726084625 End:2018-08-31 12:54:17.071497027 +0000 UTC m=+219.742119148
I0831 12:54:17.071532       1 scheduler.go:454] Total Schedule Algo cumulative time:11.018820206s for 1000
I0831 12:54:17.087733       1 scheduler.go:451] ScheduleAlgoTime 16.104392ms Start:2018-08-31 12:54:17.07162137 +0000 UTC m=+219.742243517 End:2018-08-31 12:54:17.08772577 +0000 UTC m=+219.758347909
I0831 12:54:17.087783       1 scheduler.go:454] Total Schedule Algo cumulative time:11.034924598s for 1001
I0831 12:54:17.102932       1 scheduler.go:451] ScheduleAlgoTime 15.050191ms Start:2018-08-31 12:54:17.087875873 +0000 UTC m=+219.758498015 End:2018-08-31 12:54:17.102926083 +0000 UTC m=+219.773548206
I0831 12:54:17.102963       1 scheduler.go:454] Total Schedule Algo cumulative time:11.049974789s for 1002
I0831 12:54:17.119426       1 scheduler.go:451] ScheduleAlgoTime 16.371406ms Start:2018-08-31 12:54:17.103049247 +0000 UTC m=+219.773671400 End:2018-08-31 12:54:17.119420686 +0000 UTC m=+219.790042806
I0831 12:54:17.119480       1 scheduler.go:454] Total Schedule Algo cumulative time:11.066346195s for 1003
I0831 12:54:17.133909       1 scheduler.go:451] ScheduleAlgoTime 14.317643ms Start:2018-08-31 12:54:17.119585267 +0000 UTC m=+219.790207560 End:2018-08-31 12:54:17.13390308 +0000 UTC m=+219.804525203
I0831 12:54:17.133945       1 scheduler.go:454] Total Schedule Algo cumulative time:11.080663838s for 1004
I0831 12:54:17.148378       1 scheduler.go:451] ScheduleAlgoTime 14.321531ms Start:2018-08-31 12:54:17.134050753 +0000 UTC m=+219.804672903 End:2018-08-31 12:54:17.148372315 +0000 UTC m=+219.818994434
I0831 12:54:17.148407       1 scheduler.go:454] Total Schedule Algo cumulative time:11.094985369s for 1005
I0831 12:54:17.170706       1 scheduler.go:451] ScheduleAlgoTime 22.198499ms Start:2018-08-31 12:54:17.148500399 +0000 UTC m=+219.819122555 End:2018-08-31 12:54:17.170698934 +0000 UTC m=+219.841321054
I0831 12:54:17.170746       1 scheduler.go:454] Total Schedule Algo cumulative time:11.117183868s for 1006
I0831 12:54:17.195328       1 scheduler.go:451] ScheduleAlgoTime 24.491831ms Start:2018-08-31 12:54:17.170825717 +0000 UTC m=+219.841447863 End:2018-08-31 12:54:17.195317574 +0000 UTC m=+219.865939694
I0831 12:54:17.195497       1 scheduler.go:454] Total Schedule Algo cumulative time:11.141675699s for 1007
I0831 12:54:17.220438       1 scheduler.go:451] ScheduleAlgoTime 24.810581ms Start:2018-08-31 12:54:17.195619977 +0000 UTC m=+219.866242126 End:2018-08-31 12:54:17.220430589 +0000 UTC m=+219.891052707
I0831 12:54:17.220486       1 scheduler.go:454] Total Schedule Algo cumulative time:11.16648628s for 1008
I0831 12:54:17.235586       1 scheduler.go:451] ScheduleAlgoTime 15.001463ms Start:2018-08-31 12:54:17.220577887 +0000 UTC m=+219.891200022 End:2018-08-31 12:54:17.235579364 +0000 UTC m=+219.906201485
I0831 12:54:17.235618       1 scheduler.go:454] Total Schedule Algo cumulative time:11.181487743s for 1009
I0831 12:54:17.249852       1 scheduler.go:451] ScheduleAlgoTime 14.146725ms Start:2018-08-31 12:54:17.235698657 +0000 UTC m=+219.906320814 End:2018-08-31 12:54:17.249845419 +0000 UTC m=+219.920467539
I0831 12:54:17.249894       1 scheduler.go:454] Total Schedule Algo cumulative time:11.195634468s for 1010
I0831 12:54:17.265566       1 scheduler.go:451] ScheduleAlgoTime 15.465307ms Start:2018-08-31 12:54:17.250094757 +0000 UTC m=+219.920716918 End:2018-08-31 12:54:17.265560101 +0000 UTC m=+219.936182225
I0831 12:54:17.265596       1 scheduler.go:454] Total Schedule Algo cumulative time:11.211099775s for 1011
I0831 12:54:17.281341       1 scheduler.go:451] ScheduleAlgoTime 15.676084ms Start:2018-08-31 12:54:17.265658058 +0000 UTC m=+219.936280207 End:2018-08-31 12:54:17.281334174 +0000 UTC m=+219.951956291
I0831 12:54:17.281380       1 scheduler.go:454] Total Schedule Algo cumulative time:11.226775859s for 1012
I0831 12:54:17.299521       1 scheduler.go:451] ScheduleAlgoTime 18.047736ms Start:2018-08-31 12:54:17.281465078 +0000 UTC m=+219.952087244 End:2018-08-31 12:54:17.299512846 +0000 UTC m=+219.970134980
I0831 12:54:17.299563       1 scheduler.go:454] Total Schedule Algo cumulative time:11.244823595s for 1013
I0831 12:54:17.316584       1 scheduler.go:451] ScheduleAlgoTime 16.913784ms Start:2018-08-31 12:54:17.29966349 +0000 UTC m=+219.970285653 End:2018-08-31 12:54:17.316577316 +0000 UTC m=+219.987199437
I0831 12:54:17.316616       1 scheduler.go:454] Total Schedule Algo cumulative time:11.261737379s for 1014
I0831 12:54:17.332546       1 scheduler.go:451] ScheduleAlgoTime 15.846757ms Start:2018-08-31 12:54:17.316691931 +0000 UTC m=+219.987314090 End:2018-08-31 12:54:17.332538712 +0000 UTC m=+220.003160847
I0831 12:54:17.332593       1 scheduler.go:454] Total Schedule Algo cumulative time:11.277584136s for 1015
I0831 12:54:17.346814       1 scheduler.go:451] ScheduleAlgoTime 14.123422ms Start:2018-08-31 12:54:17.332682047 +0000 UTC m=+220.003304210 End:2018-08-31 12:54:17.346805506 +0000 UTC m=+220.017427632
I0831 12:54:17.346860       1 scheduler.go:454] Total Schedule Algo cumulative time:11.291707558s for 1016
I0831 12:54:17.365891       1 scheduler.go:451] ScheduleAlgoTime 18.92675ms Start:2018-08-31 12:54:17.346957317 +0000 UTC m=+220.017579469 End:2018-08-31 12:54:17.365884082 +0000 UTC m=+220.036506219
I0831 12:54:17.365923       1 scheduler.go:454] Total Schedule Algo cumulative time:11.310634308s for 1017
I0831 12:54:17.389787       1 scheduler.go:451] ScheduleAlgoTime 23.767282ms Start:2018-08-31 12:54:17.366009296 +0000 UTC m=+220.036631447 End:2018-08-31 12:54:17.389776604 +0000 UTC m=+220.060398729
I0831 12:54:17.389832       1 scheduler.go:454] Total Schedule Algo cumulative time:11.33440159s for 1018
I0831 12:54:17.410507       1 scheduler.go:451] ScheduleAlgoTime 20.586721ms Start:2018-08-31 12:54:17.389911257 +0000 UTC m=+220.060533434 End:2018-08-31 12:54:17.410498025 +0000 UTC m=+220.081120155
I0831 12:54:17.410564       1 scheduler.go:454] Total Schedule Algo cumulative time:11.354988311s for 1019
I0831 12:54:17.427233       1 scheduler.go:451] ScheduleAlgoTime 16.520736ms Start:2018-08-31 12:54:17.41070594 +0000 UTC m=+220.081328110 End:2018-08-31 12:54:17.427226728 +0000 UTC m=+220.097848846
I0831 12:54:17.427286       1 scheduler.go:454] Total Schedule Algo cumulative time:11.371509047s for 1020
I0831 12:54:17.443136       1 scheduler.go:451] ScheduleAlgoTime 15.723213ms Start:2018-08-31 12:54:17.427402318 +0000 UTC m=+220.098024486 End:2018-08-31 12:54:17.443125573 +0000 UTC m=+220.113747699
I0831 12:54:17.443188       1 scheduler.go:454] Total Schedule Algo cumulative time:11.38723226s for 1021
I0831 12:54:17.459731       1 scheduler.go:451] ScheduleAlgoTime 16.434714ms Start:2018-08-31 12:54:17.443290151 +0000 UTC m=+220.113912298 End:2018-08-31 12:54:17.459724893 +0000 UTC m=+220.130347012
I0831 12:54:17.459763       1 scheduler.go:454] Total Schedule Algo cumulative time:11.403666974s for 1022
I0831 12:54:17.476850       1 scheduler.go:451] ScheduleAlgoTime 16.991343ms Start:2018-08-31 12:54:17.459852236 +0000 UTC m=+220.130474382 End:2018-08-31 12:54:17.476843606 +0000 UTC m=+220.147465725
I0831 12:54:17.476884       1 scheduler.go:454] Total Schedule Algo cumulative time:11.420658317s for 1023
I0831 12:54:17.493754       1 scheduler.go:451] ScheduleAlgoTime 16.790233ms Start:2018-08-31 12:54:17.476957489 +0000 UTC m=+220.147579641 End:2018-08-31 12:54:17.493747754 +0000 UTC m=+220.164369874
I0831 12:54:17.493793       1 scheduler.go:454] Total Schedule Algo cumulative time:11.43744855s for 1024
I0831 12:54:17.510857       1 scheduler.go:451] ScheduleAlgoTime 16.974051ms Start:2018-08-31 12:54:17.49387471 +0000 UTC m=+220.164496880 End:2018-08-31 12:54:17.510848808 +0000 UTC m=+220.181470931
I0831 12:54:17.510899       1 scheduler.go:454] Total Schedule Algo cumulative time:11.454422601s for 1025
I0831 12:54:17.529480       1 scheduler.go:451] ScheduleAlgoTime 18.502892ms Start:2018-08-31 12:54:17.510969691 +0000 UTC m=+220.181591843 End:2018-08-31 12:54:17.529472615 +0000 UTC m=+220.200094735
I0831 12:54:17.529512       1 scheduler.go:454] Total Schedule Algo cumulative time:11.472925493s for 1026
I0831 12:54:17.547884       1 scheduler.go:451] ScheduleAlgoTime 18.282897ms Start:2018-08-31 12:54:17.52959533 +0000 UTC m=+220.200217509 End:2018-08-31 12:54:17.547878283 +0000 UTC m=+220.218500406
I0831 12:54:17.547916       1 scheduler.go:454] Total Schedule Algo cumulative time:11.49120839s for 1027
I0831 12:54:17.567552       1 scheduler.go:451] ScheduleAlgoTime 19.553658ms Start:2018-08-31 12:54:17.547991699 +0000 UTC m=+220.218613848 End:2018-08-31 12:54:17.567545386 +0000 UTC m=+220.238167506
I0831 12:54:17.567588       1 scheduler.go:454] Total Schedule Algo cumulative time:11.510762048s for 1028
I0831 12:54:17.588967       1 scheduler.go:451] ScheduleAlgoTime 21.277583ms Start:2018-08-31 12:54:17.567683284 +0000 UTC m=+220.238305432 End:2018-08-31 12:54:17.588960897 +0000 UTC m=+220.259583015
I0831 12:54:17.589001       1 scheduler.go:454] Total Schedule Algo cumulative time:11.532039631s for 1029
I0831 12:54:17.605202       1 scheduler.go:451] ScheduleAlgoTime 16.097244ms Start:2018-08-31 12:54:17.589097837 +0000 UTC m=+220.259720020 End:2018-08-31 12:54:17.605195144 +0000 UTC m=+220.275817264
I0831 12:54:17.605239       1 scheduler.go:454] Total Schedule Algo cumulative time:11.548136875s for 1030
I0831 12:54:17.624032       1 scheduler.go:451] ScheduleAlgoTime 18.697565ms Start:2018-08-31 12:54:17.605327011 +0000 UTC m=+220.275949153 End:2018-08-31 12:54:17.624024595 +0000 UTC m=+220.294646718
I0831 12:54:17.624073       1 scheduler.go:454] Total Schedule Algo cumulative time:11.56683444s for 1031
I0831 12:54:17.639754       1 scheduler.go:451] ScheduleAlgoTime 15.589117ms Start:2018-08-31 12:54:17.624159088 +0000 UTC m=+220.294781240 End:2018-08-31 12:54:17.639748236 +0000 UTC m=+220.310370357
I0831 12:54:17.639790       1 scheduler.go:454] Total Schedule Algo cumulative time:11.582423557s for 1032
I0831 12:54:17.657155       1 scheduler.go:451] ScheduleAlgoTime 17.270456ms Start:2018-08-31 12:54:17.639874156 +0000 UTC m=+220.310496312 End:2018-08-31 12:54:17.657144647 +0000 UTC m=+220.327766768
I0831 12:54:17.657209       1 scheduler.go:454] Total Schedule Algo cumulative time:11.599694013s for 1033
I0831 12:54:17.674446       1 scheduler.go:451] ScheduleAlgoTime 17.135087ms Start:2018-08-31 12:54:17.657304879 +0000 UTC m=+220.327927042 End:2018-08-31 12:54:17.674440007 +0000 UTC m=+220.345062129
I0831 12:54:17.674486       1 scheduler.go:454] Total Schedule Algo cumulative time:11.6168291s for 1034
I0831 12:54:17.690664       1 scheduler.go:451] ScheduleAlgoTime 16.074874ms Start:2018-08-31 12:54:17.67458391 +0000 UTC m=+220.345206069 End:2018-08-31 12:54:17.690658818 +0000 UTC m=+220.361280943
I0831 12:54:17.690695       1 scheduler.go:454] Total Schedule Algo cumulative time:11.632903974s for 1035
I0831 12:54:17.707427       1 scheduler.go:451] ScheduleAlgoTime 16.630165ms Start:2018-08-31 12:54:17.690789772 +0000 UTC m=+220.361411930 End:2018-08-31 12:54:17.707419974 +0000 UTC m=+220.378042095
I0831 12:54:17.707474       1 scheduler.go:454] Total Schedule Algo cumulative time:11.649534139s for 1036
I0831 12:54:17.723869       1 scheduler.go:451] ScheduleAlgoTime 16.294024ms Start:2018-08-31 12:54:17.707568101 +0000 UTC m=+220.378190249 End:2018-08-31 12:54:17.723862155 +0000 UTC m=+220.394484273
I0831 12:54:17.723904       1 scheduler.go:454] Total Schedule Algo cumulative time:11.665828163s for 1037
I0831 12:54:17.741167       1 scheduler.go:451] ScheduleAlgoTime 17.160525ms Start:2018-08-31 12:54:17.72399987 +0000 UTC m=+220.394622012 End:2018-08-31 12:54:17.741160416 +0000 UTC m=+220.411782537
I0831 12:54:17.741202       1 scheduler.go:454] Total Schedule Algo cumulative time:11.682988688s for 1038
I0831 12:54:17.758285       1 scheduler.go:451] ScheduleAlgoTime 16.983027ms Start:2018-08-31 12:54:17.741295818 +0000 UTC m=+220.411917960 End:2018-08-31 12:54:17.758278867 +0000 UTC m=+220.428900987
I0831 12:54:17.758315       1 scheduler.go:454] Total Schedule Algo cumulative time:11.699971715s for 1039
I0831 12:54:17.781429       1 scheduler.go:451] ScheduleAlgoTime 23.038891ms Start:2018-08-31 12:54:17.758383425 +0000 UTC m=+220.429005581 End:2018-08-31 12:54:17.781422352 +0000 UTC m=+220.452044472
I0831 12:54:17.781473       1 scheduler.go:454] Total Schedule Algo cumulative time:11.723010606s for 1040
I0831 12:54:17.797386       1 scheduler.go:451] ScheduleAlgoTime 15.807789ms Start:2018-08-31 12:54:17.781572494 +0000 UTC m=+220.452194655 End:2018-08-31 12:54:17.797380325 +0000 UTC m=+220.468002444
I0831 12:54:17.797420       1 scheduler.go:454] Total Schedule Algo cumulative time:11.738818395s for 1041
I0831 12:54:17.811854       1 scheduler.go:451] ScheduleAlgoTime 14.340177ms Start:2018-08-31 12:54:17.797508598 +0000 UTC m=+220.468130754 End:2018-08-31 12:54:17.81184881 +0000 UTC m=+220.482470931
I0831 12:54:17.811895       1 scheduler.go:454] Total Schedule Algo cumulative time:11.753158572s for 1042
I0831 12:54:17.828056       1 scheduler.go:451] ScheduleAlgoTime 16.073857ms Start:2018-08-31 12:54:17.811975454 +0000 UTC m=+220.482597616 End:2018-08-31 12:54:17.828049348 +0000 UTC m=+220.498671473
I0831 12:54:17.828086       1 scheduler.go:454] Total Schedule Algo cumulative time:11.769232429s for 1043
I0831 12:54:17.844178       1 scheduler.go:451] ScheduleAlgoTime 15.976922ms Start:2018-08-31 12:54:17.828194553 +0000 UTC m=+220.498816706 End:2018-08-31 12:54:17.844171507 +0000 UTC m=+220.514793628
I0831 12:54:17.844214       1 scheduler.go:454] Total Schedule Algo cumulative time:11.785209351s for 1044
I0831 12:54:17.861529       1 scheduler.go:451] ScheduleAlgoTime 17.224434ms Start:2018-08-31 12:54:17.844298187 +0000 UTC m=+220.514920327 End:2018-08-31 12:54:17.861522639 +0000 UTC m=+220.532144761
I0831 12:54:17.861561       1 scheduler.go:454] Total Schedule Algo cumulative time:11.802433785s for 1045
I0831 12:54:17.877175       1 scheduler.go:451] ScheduleAlgoTime 15.530727ms Start:2018-08-31 12:54:17.861637303 +0000 UTC m=+220.532259455 End:2018-08-31 12:54:17.877168062 +0000 UTC m=+220.547790182
I0831 12:54:17.877209       1 scheduler.go:454] Total Schedule Algo cumulative time:11.817964512s for 1046
I0831 12:54:17.893857       1 scheduler.go:451] ScheduleAlgoTime 16.487427ms Start:2018-08-31 12:54:17.877363885 +0000 UTC m=+220.547986005 End:2018-08-31 12:54:17.893851311 +0000 UTC m=+220.564473432
I0831 12:54:17.893899       1 scheduler.go:454] Total Schedule Algo cumulative time:11.834451939s for 1047
I0831 12:54:17.914176       1 scheduler.go:451] ScheduleAlgoTime 20.181501ms Start:2018-08-31 12:54:17.893987913 +0000 UTC m=+220.564610059 End:2018-08-31 12:54:17.91416944 +0000 UTC m=+220.584791560
I0831 12:54:17.914211       1 scheduler.go:454] Total Schedule Algo cumulative time:11.85463344s for 1048
I0831 12:54:17.929437       1 scheduler.go:451] ScheduleAlgoTime 15.128321ms Start:2018-08-31 12:54:17.914301047 +0000 UTC m=+220.584923200 End:2018-08-31 12:54:17.929429389 +0000 UTC m=+220.600051521
I0831 12:54:17.929491       1 scheduler.go:454] Total Schedule Algo cumulative time:11.869761761s for 1049
I0831 12:54:17.947142       1 scheduler.go:451] ScheduleAlgoTime 17.542265ms Start:2018-08-31 12:54:17.929593207 +0000 UTC m=+220.600215358 End:2018-08-31 12:54:17.947135502 +0000 UTC m=+220.617757623
I0831 12:54:17.947173       1 scheduler.go:454] Total Schedule Algo cumulative time:11.887304026s for 1050
I0831 12:54:17.968858       1 scheduler.go:451] ScheduleAlgoTime 21.588218ms Start:2018-08-31 12:54:17.947262345 +0000 UTC m=+220.617884486 End:2018-08-31 12:54:17.968850584 +0000 UTC m=+220.639472704
I0831 12:54:17.968897       1 scheduler.go:454] Total Schedule Algo cumulative time:11.908892244s for 1051
I0831 12:54:17.988318       1 scheduler.go:451] ScheduleAlgoTime 19.343735ms Start:2018-08-31 12:54:17.968968023 +0000 UTC m=+220.639590169 End:2018-08-31 12:54:17.988311785 +0000 UTC m=+220.658933904
I0831 12:54:17.988360       1 scheduler.go:454] Total Schedule Algo cumulative time:11.928235979s for 1052
I0831 12:54:18.004999       1 scheduler.go:451] ScheduleAlgoTime 16.541932ms Start:2018-08-31 12:54:17.988450064 +0000 UTC m=+220.659072213 End:2018-08-31 12:54:18.004992026 +0000 UTC m=+220.675614145
I0831 12:54:18.005043       1 scheduler.go:454] Total Schedule Algo cumulative time:11.944777911s for 1053
I0831 12:54:18.022398       1 scheduler.go:451] ScheduleAlgoTime 17.259804ms Start:2018-08-31 12:54:18.005131978 +0000 UTC m=+220.675754131 End:2018-08-31 12:54:18.022391814 +0000 UTC m=+220.693013935
I0831 12:54:18.022438       1 scheduler.go:454] Total Schedule Algo cumulative time:11.962037715s for 1054
I0831 12:54:18.039903       1 scheduler.go:451] ScheduleAlgoTime 17.361706ms Start:2018-08-31 12:54:18.022535243 +0000 UTC m=+220.693157378 End:2018-08-31 12:54:18.039896963 +0000 UTC m=+220.710519084
I0831 12:54:18.039936       1 scheduler.go:454] Total Schedule Algo cumulative time:11.979399421s for 1055
I0831 12:54:18.055110       1 scheduler.go:451] ScheduleAlgoTime 15.072853ms Start:2018-08-31 12:54:18.040030974 +0000 UTC m=+220.710653121 End:2018-08-31 12:54:18.055103855 +0000 UTC m=+220.725725974
I0831 12:54:18.055143       1 scheduler.go:454] Total Schedule Algo cumulative time:11.994472274s for 1056
I0831 12:54:18.072084       1 scheduler.go:451] ScheduleAlgoTime 16.845681ms Start:2018-08-31 12:54:18.055230715 +0000 UTC m=+220.725852866 End:2018-08-31 12:54:18.072076418 +0000 UTC m=+220.742698547
I0831 12:54:18.072122       1 scheduler.go:454] Total Schedule Algo cumulative time:12.011317955s for 1057
I0831 12:54:18.089521       1 scheduler.go:451] ScheduleAlgoTime 17.303589ms Start:2018-08-31 12:54:18.072209997 +0000 UTC m=+220.742832183 End:2018-08-31 12:54:18.089513642 +0000 UTC m=+220.760135772
I0831 12:54:18.089585       1 scheduler.go:454] Total Schedule Algo cumulative time:12.028621544s for 1058
I0831 12:54:18.114355       1 scheduler.go:451] ScheduleAlgoTime 24.685226ms Start:2018-08-31 12:54:18.089662046 +0000 UTC m=+220.760284197 End:2018-08-31 12:54:18.114347303 +0000 UTC m=+220.784969423
I0831 12:54:18.114392       1 scheduler.go:454] Total Schedule Algo cumulative time:12.05330677s for 1059
I0831 12:54:18.132031       1 scheduler.go:451] ScheduleAlgoTime 17.527592ms Start:2018-08-31 12:54:18.114496914 +0000 UTC m=+220.785119051 End:2018-08-31 12:54:18.132024525 +0000 UTC m=+220.802646643
I0831 12:54:18.132084       1 scheduler.go:454] Total Schedule Algo cumulative time:12.070834362s for 1060
I0831 12:54:18.147768       1 scheduler.go:451] ScheduleAlgoTime 15.584095ms Start:2018-08-31 12:54:18.132175412 +0000 UTC m=+220.802797614 End:2018-08-31 12:54:18.147759585 +0000 UTC m=+220.818381709
I0831 12:54:18.147828       1 scheduler.go:454] Total Schedule Algo cumulative time:12.086418457s for 1061
I0831 12:54:18.170516       1 scheduler.go:451] ScheduleAlgoTime 22.59223ms Start:2018-08-31 12:54:18.147916756 +0000 UTC m=+220.818538912 End:2018-08-31 12:54:18.17050902 +0000 UTC m=+220.841131142
I0831 12:54:18.170557       1 scheduler.go:454] Total Schedule Algo cumulative time:12.109010687s for 1062
I0831 12:54:18.189653       1 scheduler.go:451] ScheduleAlgoTime 18.987352ms Start:2018-08-31 12:54:18.170655432 +0000 UTC m=+220.841277584 End:2018-08-31 12:54:18.18964279 +0000 UTC m=+220.860264936
I0831 12:54:18.189700       1 scheduler.go:454] Total Schedule Algo cumulative time:12.127998039s for 1063
I0831 12:54:18.205626       1 scheduler.go:451] ScheduleAlgoTime 15.830615ms Start:2018-08-31 12:54:18.189789719 +0000 UTC m=+220.860411889 End:2018-08-31 12:54:18.205620385 +0000 UTC m=+220.876242504
I0831 12:54:18.205661       1 scheduler.go:454] Total Schedule Algo cumulative time:12.143828654s for 1064
I0831 12:54:18.232079       1 scheduler.go:451] ScheduleAlgoTime 26.316787ms Start:2018-08-31 12:54:18.205751956 +0000 UTC m=+220.876374137 End:2018-08-31 12:54:18.232068802 +0000 UTC m=+220.902690924
I0831 12:54:18.232238       1 scheduler.go:454] Total Schedule Algo cumulative time:12.170145441s for 1065
I0831 12:54:18.251229       1 scheduler.go:451] ScheduleAlgoTime 18.828808ms Start:2018-08-31 12:54:18.232393087 +0000 UTC m=+220.903015240 End:2018-08-31 12:54:18.251221929 +0000 UTC m=+220.921844048
I0831 12:54:18.251273       1 scheduler.go:454] Total Schedule Algo cumulative time:12.188974249s for 1066
I0831 12:54:18.269126       1 scheduler.go:451] ScheduleAlgoTime 17.742901ms Start:2018-08-31 12:54:18.251376648 +0000 UTC m=+220.921998813 End:2018-08-31 12:54:18.269119595 +0000 UTC m=+220.939741714
I0831 12:54:18.269160       1 scheduler.go:454] Total Schedule Algo cumulative time:12.20671715s for 1067
I0831 12:54:18.284625       1 scheduler.go:451] ScheduleAlgoTime 15.37844ms Start:2018-08-31 12:54:18.269237903 +0000 UTC m=+220.939860053 End:2018-08-31 12:54:18.284616364 +0000 UTC m=+220.955238493
I0831 12:54:18.284666       1 scheduler.go:454] Total Schedule Algo cumulative time:12.22209559s for 1068
I0831 12:54:18.300954       1 scheduler.go:451] ScheduleAlgoTime 16.172929ms Start:2018-08-31 12:54:18.284774168 +0000 UTC m=+220.955396324 End:2018-08-31 12:54:18.300947134 +0000 UTC m=+220.971569253
I0831 12:54:18.300992       1 scheduler.go:454] Total Schedule Algo cumulative time:12.238268519s for 1069
I0831 12:54:18.319783       1 scheduler.go:451] ScheduleAlgoTime 18.697773ms Start:2018-08-31 12:54:18.301078563 +0000 UTC m=+220.971700729 End:2018-08-31 12:54:18.319776384 +0000 UTC m=+220.990398502
I0831 12:54:18.319816       1 scheduler.go:454] Total Schedule Algo cumulative time:12.256966292s for 1070
I0831 12:54:18.337493       1 scheduler.go:451] ScheduleAlgoTime 17.578628ms Start:2018-08-31 12:54:18.319907574 +0000 UTC m=+220.990529768 End:2018-08-31 12:54:18.337486275 +0000 UTC m=+221.008108396
I0831 12:54:18.337523       1 scheduler.go:454] Total Schedule Algo cumulative time:12.27454492s for 1071
I0831 12:54:18.354091       1 scheduler.go:451] ScheduleAlgoTime 16.463905ms Start:2018-08-31 12:54:18.337619628 +0000 UTC m=+221.008241767 End:2018-08-31 12:54:18.354083553 +0000 UTC m=+221.024705672
I0831 12:54:18.354123       1 scheduler.go:454] Total Schedule Algo cumulative time:12.291008825s for 1072
I0831 12:54:18.376990       1 scheduler.go:451] ScheduleAlgoTime 22.747264ms Start:2018-08-31 12:54:18.354234506 +0000 UTC m=+221.024856651 End:2018-08-31 12:54:18.376981794 +0000 UTC m=+221.047603915
I0831 12:54:18.377029       1 scheduler.go:454] Total Schedule Algo cumulative time:12.313756089s for 1073
I0831 12:54:18.392667       1 scheduler.go:451] ScheduleAlgoTime 15.552563ms Start:2018-08-31 12:54:18.377108537 +0000 UTC m=+221.047730696 End:2018-08-31 12:54:18.392661138 +0000 UTC m=+221.063283259
I0831 12:54:18.392700       1 scheduler.go:454] Total Schedule Algo cumulative time:12.329308652s for 1074
I0831 12:54:18.408288       1 scheduler.go:451] ScheduleAlgoTime 15.504457ms Start:2018-08-31 12:54:18.392777745 +0000 UTC m=+221.063399875 End:2018-08-31 12:54:18.408282207 +0000 UTC m=+221.078904332
I0831 12:54:18.408331       1 scheduler.go:454] Total Schedule Algo cumulative time:12.344813109s for 1075
I0831 12:54:18.427836       1 scheduler.go:451] ScheduleAlgoTime 19.404853ms Start:2018-08-31 12:54:18.408423986 +0000 UTC m=+221.079046126 End:2018-08-31 12:54:18.42782886 +0000 UTC m=+221.098450979
I0831 12:54:18.427869       1 scheduler.go:454] Total Schedule Algo cumulative time:12.364217962s for 1076
I0831 12:54:18.444862       1 scheduler.go:451] ScheduleAlgoTime 16.896773ms Start:2018-08-31 12:54:18.427956545 +0000 UTC m=+221.098578697 End:2018-08-31 12:54:18.444853345 +0000 UTC m=+221.115475470
I0831 12:54:18.444907       1 scheduler.go:454] Total Schedule Algo cumulative time:12.381114735s for 1077
I0831 12:54:18.461629       1 scheduler.go:451] ScheduleAlgoTime 16.614874ms Start:2018-08-31 12:54:18.4450067 +0000 UTC m=+221.115628849 End:2018-08-31 12:54:18.461621605 +0000 UTC m=+221.132243723
I0831 12:54:18.461673       1 scheduler.go:454] Total Schedule Algo cumulative time:12.397729609s for 1078
I0831 12:54:18.476946       1 scheduler.go:451] ScheduleAlgoTime 15.177858ms Start:2018-08-31 12:54:18.461762271 +0000 UTC m=+221.132384423 End:2018-08-31 12:54:18.476940155 +0000 UTC m=+221.147562281
I0831 12:54:18.476979       1 scheduler.go:454] Total Schedule Algo cumulative time:12.412907467s for 1079
I0831 12:54:18.496281       1 scheduler.go:451] ScheduleAlgoTime 19.21209ms Start:2018-08-31 12:54:18.477062807 +0000 UTC m=+221.147684987 End:2018-08-31 12:54:18.496274958 +0000 UTC m=+221.166897077
I0831 12:54:18.496316       1 scheduler.go:454] Total Schedule Algo cumulative time:12.432119557s for 1080
I0831 12:54:18.511836       1 scheduler.go:451] ScheduleAlgoTime 15.436763ms Start:2018-08-31 12:54:18.496393873 +0000 UTC m=+221.167016036 End:2018-08-31 12:54:18.511830678 +0000 UTC m=+221.182452799
I0831 12:54:18.511869       1 scheduler.go:454] Total Schedule Algo cumulative time:12.44755632s for 1081
I0831 12:54:18.527094       1 scheduler.go:451] ScheduleAlgoTime 15.07605ms Start:2018-08-31 12:54:18.512012839 +0000 UTC m=+221.182635004 End:2018-08-31 12:54:18.527088935 +0000 UTC m=+221.197711054
I0831 12:54:18.527120       1 scheduler.go:454] Total Schedule Algo cumulative time:12.46263237s for 1082
I0831 12:54:18.544577       1 scheduler.go:451] ScheduleAlgoTime 17.368819ms Start:2018-08-31 12:54:18.527202446 +0000 UTC m=+221.197824597 End:2018-08-31 12:54:18.544571297 +0000 UTC m=+221.215193416
I0831 12:54:18.544607       1 scheduler.go:454] Total Schedule Algo cumulative time:12.480001189s for 1083
I0831 12:54:18.568729       1 scheduler.go:451] ScheduleAlgoTime 24.029832ms Start:2018-08-31 12:54:18.544692243 +0000 UTC m=+221.215314440 End:2018-08-31 12:54:18.568722152 +0000 UTC m=+221.239344272
I0831 12:54:18.568763       1 scheduler.go:454] Total Schedule Algo cumulative time:12.504031021s for 1084
I0831 12:54:18.586413       1 scheduler.go:451] ScheduleAlgoTime 17.561779ms Start:2018-08-31 12:54:18.568844203 +0000 UTC m=+221.239466364 End:2018-08-31 12:54:18.586406022 +0000 UTC m=+221.257028143
I0831 12:54:18.586449       1 scheduler.go:454] Total Schedule Algo cumulative time:12.5215928s for 1085
I0831 12:54:18.604900       1 scheduler.go:451] ScheduleAlgoTime 18.34175ms Start:2018-08-31 12:54:18.586551973 +0000 UTC m=+221.257174129 End:2018-08-31 12:54:18.604893756 +0000 UTC m=+221.275515879
I0831 12:54:18.604932       1 scheduler.go:454] Total Schedule Algo cumulative time:12.53993455s for 1086
I0831 12:54:18.621184       1 scheduler.go:451] ScheduleAlgoTime 16.161533ms Start:2018-08-31 12:54:18.605016175 +0000 UTC m=+221.275638331 End:2018-08-31 12:54:18.621177743 +0000 UTC m=+221.291799864
I0831 12:54:18.621225       1 scheduler.go:454] Total Schedule Algo cumulative time:12.556096083s for 1087
I0831 12:54:18.640335       1 scheduler.go:451] ScheduleAlgoTime 18.994013ms Start:2018-08-31 12:54:18.621335636 +0000 UTC m=+221.291957788 End:2018-08-31 12:54:18.640329682 +0000 UTC m=+221.310951801
I0831 12:54:18.640370       1 scheduler.go:454] Total Schedule Algo cumulative time:12.575090096s for 1088
I0831 12:54:18.657223       1 scheduler.go:451] ScheduleAlgoTime 16.695193ms Start:2018-08-31 12:54:18.640521289 +0000 UTC m=+221.311143441 End:2018-08-31 12:54:18.657216513 +0000 UTC m=+221.327838634
I0831 12:54:18.657252       1 scheduler.go:454] Total Schedule Algo cumulative time:12.591785289s for 1089
I0831 12:54:18.676864       1 scheduler.go:451] ScheduleAlgoTime 19.52181ms Start:2018-08-31 12:54:18.657336856 +0000 UTC m=+221.327959005 End:2018-08-31 12:54:18.676858695 +0000 UTC m=+221.347480815
I0831 12:54:18.676896       1 scheduler.go:454] Total Schedule Algo cumulative time:12.611307099s for 1090
I0831 12:54:18.692648       1 scheduler.go:451] ScheduleAlgoTime 15.662284ms Start:2018-08-31 12:54:18.676979771 +0000 UTC m=+221.347601918 End:2018-08-31 12:54:18.692642077 +0000 UTC m=+221.363264202
I0831 12:54:18.692689       1 scheduler.go:454] Total Schedule Algo cumulative time:12.626969383s for 1091
I0831 12:54:18.711220       1 scheduler.go:451] ScheduleAlgoTime 18.444817ms Start:2018-08-31 12:54:18.692769751 +0000 UTC m=+221.363391937 End:2018-08-31 12:54:18.711214634 +0000 UTC m=+221.381836754
I0831 12:54:18.711250       1 scheduler.go:454] Total Schedule Algo cumulative time:12.6454142s for 1092
I0831 12:54:18.727267       1 scheduler.go:451] ScheduleAlgoTime 15.933843ms Start:2018-08-31 12:54:18.711326574 +0000 UTC m=+221.381948779 End:2018-08-31 12:54:18.727260503 +0000 UTC m=+221.397882622
I0831 12:54:18.727304       1 scheduler.go:454] Total Schedule Algo cumulative time:12.661348043s for 1093
I0831 12:54:18.743094       1 scheduler.go:451] ScheduleAlgoTime 15.678482ms Start:2018-08-31 12:54:18.727410035 +0000 UTC m=+221.398032187 End:2018-08-31 12:54:18.74308855 +0000 UTC m=+221.413710669
I0831 12:54:18.743123       1 scheduler.go:454] Total Schedule Algo cumulative time:12.677026525s for 1094
I0831 12:54:18.763612       1 scheduler.go:451] ScheduleAlgoTime 20.415079ms Start:2018-08-31 12:54:18.74319113 +0000 UTC m=+221.413813288 End:2018-08-31 12:54:18.763606243 +0000 UTC m=+221.434228367
I0831 12:54:18.763649       1 scheduler.go:454] Total Schedule Algo cumulative time:12.697441604s for 1095
I0831 12:54:18.782030       1 scheduler.go:451] ScheduleAlgoTime 18.303853ms Start:2018-08-31 12:54:18.763715565 +0000 UTC m=+221.434337718 End:2018-08-31 12:54:18.782019441 +0000 UTC m=+221.452641571
I0831 12:54:18.782072       1 scheduler.go:454] Total Schedule Algo cumulative time:12.715745457s for 1096
I0831 12:54:18.799387       1 scheduler.go:451] ScheduleAlgoTime 17.204663ms Start:2018-08-31 12:54:18.782176303 +0000 UTC m=+221.452798452 End:2018-08-31 12:54:18.799380992 +0000 UTC m=+221.470003115
I0831 12:54:18.799419       1 scheduler.go:454] Total Schedule Algo cumulative time:12.73295012s for 1097
I0831 12:54:18.818359       1 scheduler.go:451] ScheduleAlgoTime 18.83147ms Start:2018-08-31 12:54:18.799520969 +0000 UTC m=+221.470143103 End:2018-08-31 12:54:18.818352453 +0000 UTC m=+221.488974573
I0831 12:54:18.818392       1 scheduler.go:454] Total Schedule Algo cumulative time:12.75178159s for 1098
I0831 12:54:18.836615       1 scheduler.go:451] ScheduleAlgoTime 18.113472ms Start:2018-08-31 12:54:18.818496309 +0000 UTC m=+221.489118455 End:2018-08-31 12:54:18.836609809 +0000 UTC m=+221.507231927
I0831 12:54:18.836648       1 scheduler.go:454] Total Schedule Algo cumulative time:12.769895062s for 1099
I0831 12:54:18.853109       1 scheduler.go:451] ScheduleAlgoTime 16.366621ms Start:2018-08-31 12:54:18.836733217 +0000 UTC m=+221.507355393 End:2018-08-31 12:54:18.853099892 +0000 UTC m=+221.523722014
I0831 12:54:18.853170       1 scheduler.go:454] Total Schedule Algo cumulative time:12.786261683s for 1100
I0831 12:54:18.869327       1 scheduler.go:451] ScheduleAlgoTime 16.07237ms Start:2018-08-31 12:54:18.853246307 +0000 UTC m=+221.523868455 End:2018-08-31 12:54:18.869318703 +0000 UTC m=+221.539940825
I0831 12:54:18.869368       1 scheduler.go:454] Total Schedule Algo cumulative time:12.802334053s for 1101
I0831 12:54:18.885727       1 scheduler.go:451] ScheduleAlgoTime 16.241652ms Start:2018-08-31 12:54:18.869478784 +0000 UTC m=+221.540100982 End:2018-08-31 12:54:18.885720509 +0000 UTC m=+221.556342634
I0831 12:54:18.885756       1 scheduler.go:454] Total Schedule Algo cumulative time:12.818575705s for 1102
I0831 12:54:18.902811       1 scheduler.go:451] ScheduleAlgoTime 16.985994ms Start:2018-08-31 12:54:18.885818671 +0000 UTC m=+221.556440825 End:2018-08-31 12:54:18.902804697 +0000 UTC m=+221.573426819
I0831 12:54:18.902844       1 scheduler.go:454] Total Schedule Algo cumulative time:12.835561699s for 1103
I0831 12:54:18.919797       1 scheduler.go:451] ScheduleAlgoTime 16.858985ms Start:2018-08-31 12:54:18.90293025 +0000 UTC m=+221.573552404 End:2018-08-31 12:54:18.919789258 +0000 UTC m=+221.590411389
I0831 12:54:18.919838       1 scheduler.go:454] Total Schedule Algo cumulative time:12.852420684s for 1104
I0831 12:54:18.940121       1 scheduler.go:451] ScheduleAlgoTime 20.169019ms Start:2018-08-31 12:54:18.919943698 +0000 UTC m=+221.590565862 End:2018-08-31 12:54:18.940112762 +0000 UTC m=+221.610734881
I0831 12:54:18.940161       1 scheduler.go:454] Total Schedule Algo cumulative time:12.872589703s for 1105
I0831 12:54:18.957527       1 scheduler.go:451] ScheduleAlgoTime 17.238417ms Start:2018-08-31 12:54:18.94028312 +0000 UTC m=+221.610905267 End:2018-08-31 12:54:18.957521565 +0000 UTC m=+221.628143684
I0831 12:54:18.957558       1 scheduler.go:454] Total Schedule Algo cumulative time:12.88982812s for 1106
I0831 12:54:18.975194       1 scheduler.go:451] ScheduleAlgoTime 17.548332ms Start:2018-08-31 12:54:18.957637022 +0000 UTC m=+221.628259160 End:2018-08-31 12:54:18.97518537 +0000 UTC m=+221.645807492
I0831 12:54:18.975238       1 scheduler.go:454] Total Schedule Algo cumulative time:12.907376452s for 1107
I0831 12:54:19.004633       1 scheduler.go:451] ScheduleAlgoTime 25.999679ms Start:2018-08-31 12:54:18.9786269 +0000 UTC m=+221.649249069 End:2018-08-31 12:54:19.004626628 +0000 UTC m=+221.675248748
I0831 12:54:19.004680       1 scheduler.go:454] Total Schedule Algo cumulative time:12.933376131s for 1108
I0831 12:54:19.022328       1 scheduler.go:451] ScheduleAlgoTime 17.538212ms Start:2018-08-31 12:54:19.004782871 +0000 UTC m=+221.675405017 End:2018-08-31 12:54:19.02232111 +0000 UTC m=+221.692943229
I0831 12:54:19.022366       1 scheduler.go:454] Total Schedule Algo cumulative time:12.950914343s for 1109
I0831 12:54:19.041688       1 scheduler.go:451] ScheduleAlgoTime 19.227044ms Start:2018-08-31 12:54:19.022453946 +0000 UTC m=+221.693076095 End:2018-08-31 12:54:19.041681019 +0000 UTC m=+221.712303139
I0831 12:54:19.041734       1 scheduler.go:454] Total Schedule Algo cumulative time:12.970141387s for 1110
I0831 12:54:19.059488       1 scheduler.go:451] ScheduleAlgoTime 17.666273ms Start:2018-08-31 12:54:19.041816166 +0000 UTC m=+221.712438318 End:2018-08-31 12:54:19.059482471 +0000 UTC m=+221.730104591
I0831 12:54:19.059524       1 scheduler.go:454] Total Schedule Algo cumulative time:12.98780766s for 1111
I0831 12:54:19.075345       1 scheduler.go:451] ScheduleAlgoTime 15.732098ms Start:2018-08-31 12:54:19.059606603 +0000 UTC m=+221.730228752 End:2018-08-31 12:54:19.075338731 +0000 UTC m=+221.745960850
I0831 12:54:19.075375       1 scheduler.go:454] Total Schedule Algo cumulative time:13.003539758s for 1112
I0831 12:54:19.092197       1 scheduler.go:451] ScheduleAlgoTime 16.748683ms Start:2018-08-31 12:54:19.075441974 +0000 UTC m=+221.746064117 End:2018-08-31 12:54:19.092190677 +0000 UTC m=+221.762812800
I0831 12:54:19.092227       1 scheduler.go:454] Total Schedule Algo cumulative time:13.020288441s for 1113
I0831 12:54:19.107982       1 scheduler.go:451] ScheduleAlgoTime 15.646812ms Start:2018-08-31 12:54:19.09232997 +0000 UTC m=+221.762952106 End:2018-08-31 12:54:19.107976799 +0000 UTC m=+221.778598918
I0831 12:54:19.108027       1 scheduler.go:454] Total Schedule Algo cumulative time:13.035935253s for 1114
I0831 12:54:19.123325       1 scheduler.go:451] ScheduleAlgoTime 15.221698ms Start:2018-08-31 12:54:19.108097291 +0000 UTC m=+221.778719434 End:2018-08-31 12:54:19.123319013 +0000 UTC m=+221.793941132
I0831 12:54:19.123355       1 scheduler.go:454] Total Schedule Algo cumulative time:13.051156951s for 1115
I0831 12:54:19.145307       1 scheduler.go:451] ScheduleAlgoTime 21.857888ms Start:2018-08-31 12:54:19.123441697 +0000 UTC m=+221.794063851 End:2018-08-31 12:54:19.14529962 +0000 UTC m=+221.815921739
I0831 12:54:19.145344       1 scheduler.go:454] Total Schedule Algo cumulative time:13.073014839s for 1116
I0831 12:54:19.162304       1 scheduler.go:451] ScheduleAlgoTime 16.867256ms Start:2018-08-31 12:54:19.145430244 +0000 UTC m=+221.816052382 End:2018-08-31 12:54:19.16229752 +0000 UTC m=+221.832919638
I0831 12:54:19.162343       1 scheduler.go:454] Total Schedule Algo cumulative time:13.089882095s for 1117
I0831 12:54:19.179868       1 scheduler.go:451] ScheduleAlgoTime 17.443499ms Start:2018-08-31 12:54:19.162419259 +0000 UTC m=+221.833041406 End:2018-08-31 12:54:19.179862784 +0000 UTC m=+221.850484905
I0831 12:54:19.179901       1 scheduler.go:454] Total Schedule Algo cumulative time:13.107325594s for 1118
I0831 12:54:19.199865       1 scheduler.go:451] ScheduleAlgoTime 19.868665ms Start:2018-08-31 12:54:19.179990702 +0000 UTC m=+221.850612856 End:2018-08-31 12:54:19.199859401 +0000 UTC m=+221.870481521
I0831 12:54:19.199900       1 scheduler.go:454] Total Schedule Algo cumulative time:13.127194259s for 1119
I0831 12:54:19.216056       1 scheduler.go:451] ScheduleAlgoTime 16.065295ms Start:2018-08-31 12:54:19.199982931 +0000 UTC m=+221.870605083 End:2018-08-31 12:54:19.216048258 +0000 UTC m=+221.886670378
I0831 12:54:19.216095       1 scheduler.go:454] Total Schedule Algo cumulative time:13.143259554s for 1120
I0831 12:54:19.233042       1 scheduler.go:451] ScheduleAlgoTime 16.850688ms Start:2018-08-31 12:54:19.21618459 +0000 UTC m=+221.886806743 End:2018-08-31 12:54:19.233035313 +0000 UTC m=+221.903657431
I0831 12:54:19.233072       1 scheduler.go:454] Total Schedule Algo cumulative time:13.160110242s for 1121
I0831 12:54:19.249265       1 scheduler.go:451] ScheduleAlgoTime 16.112419ms Start:2018-08-31 12:54:19.23314678 +0000 UTC m=+221.903768946 End:2018-08-31 12:54:19.249259247 +0000 UTC m=+221.919881365
I0831 12:54:19.249300       1 scheduler.go:454] Total Schedule Algo cumulative time:13.176222661s for 1122
I0831 12:54:19.265884       1 scheduler.go:451] ScheduleAlgoTime 16.472073ms Start:2018-08-31 12:54:19.249405099 +0000 UTC m=+221.920027249 End:2018-08-31 12:54:19.265877188 +0000 UTC m=+221.936499322
I0831 12:54:19.265918       1 scheduler.go:454] Total Schedule Algo cumulative time:13.192694734s for 1123
I0831 12:54:19.282815       1 scheduler.go:451] ScheduleAlgoTime 16.801125ms Start:2018-08-31 12:54:19.266007131 +0000 UTC m=+221.936629315 End:2018-08-31 12:54:19.282808316 +0000 UTC m=+221.953430440
I0831 12:54:19.282843       1 scheduler.go:454] Total Schedule Algo cumulative time:13.209495859s for 1124
I0831 12:54:19.299180       1 scheduler.go:451] ScheduleAlgoTime 16.234079ms Start:2018-08-31 12:54:19.282937733 +0000 UTC m=+221.953559902 End:2018-08-31 12:54:19.299171859 +0000 UTC m=+221.969793981
I0831 12:54:19.299219       1 scheduler.go:454] Total Schedule Algo cumulative time:13.225729938s for 1125
I0831 12:54:19.318448       1 scheduler.go:451] ScheduleAlgoTime 19.128019ms Start:2018-08-31 12:54:19.299314066 +0000 UTC m=+221.969936222 End:2018-08-31 12:54:19.318442121 +0000 UTC m=+221.989064241
I0831 12:54:19.318486       1 scheduler.go:454] Total Schedule Algo cumulative time:13.244857957s for 1126
I0831 12:54:19.343125       1 scheduler.go:451] ScheduleAlgoTime 24.539054ms Start:2018-08-31 12:54:19.31858014 +0000 UTC m=+221.989202293 End:2018-08-31 12:54:19.343119227 +0000 UTC m=+222.013741347
I0831 12:54:19.343169       1 scheduler.go:454] Total Schedule Algo cumulative time:13.269397011s for 1127
I0831 12:54:19.359991       1 scheduler.go:451] ScheduleAlgoTime 16.72916ms Start:2018-08-31 12:54:19.343256331 +0000 UTC m=+222.013878495 End:2018-08-31 12:54:19.359985534 +0000 UTC m=+222.030607655
I0831 12:54:19.360023       1 scheduler.go:454] Total Schedule Algo cumulative time:13.286126171s for 1128
I0831 12:54:19.377598       1 scheduler.go:451] ScheduleAlgoTime 17.490962ms Start:2018-08-31 12:54:19.360099727 +0000 UTC m=+222.030721881 End:2018-08-31 12:54:19.377590724 +0000 UTC m=+222.048212843
I0831 12:54:19.377639       1 scheduler.go:454] Total Schedule Algo cumulative time:13.303617133s for 1129
I0831 12:54:19.395247       1 scheduler.go:451] ScheduleAlgoTime 17.505849ms Start:2018-08-31 12:54:19.377735252 +0000 UTC m=+222.048357405 End:2018-08-31 12:54:19.395241131 +0000 UTC m=+222.065863254
I0831 12:54:19.395280       1 scheduler.go:454] Total Schedule Algo cumulative time:13.321122982s for 1130
I0831 12:54:19.413445       1 scheduler.go:451] ScheduleAlgoTime 18.070188ms Start:2018-08-31 12:54:19.395368056 +0000 UTC m=+222.065990226 End:2018-08-31 12:54:19.413438294 +0000 UTC m=+222.084060414
I0831 12:54:19.413485       1 scheduler.go:454] Total Schedule Algo cumulative time:13.33919317s for 1131
I0831 12:54:19.431258       1 scheduler.go:451] ScheduleAlgoTime 17.669428ms Start:2018-08-31 12:54:19.413580863 +0000 UTC m=+222.084203029 End:2018-08-31 12:54:19.431250325 +0000 UTC m=+222.101872457
I0831 12:54:19.431302       1 scheduler.go:454] Total Schedule Algo cumulative time:13.356862598s for 1132
I0831 12:54:19.449700       1 scheduler.go:451] ScheduleAlgoTime 18.284823ms Start:2018-08-31 12:54:19.431408591 +0000 UTC m=+222.102030754 End:2018-08-31 12:54:19.449693456 +0000 UTC m=+222.120315577
I0831 12:54:19.449741       1 scheduler.go:454] Total Schedule Algo cumulative time:13.375147421s for 1133
I0831 12:54:19.466495       1 scheduler.go:451] ScheduleAlgoTime 16.671478ms Start:2018-08-31 12:54:19.449813072 +0000 UTC m=+222.120435225 End:2018-08-31 12:54:19.466484557 +0000 UTC m=+222.137106703
I0831 12:54:19.466538       1 scheduler.go:454] Total Schedule Algo cumulative time:13.391818899s for 1134
I0831 12:54:19.484477       1 scheduler.go:451] ScheduleAlgoTime 17.816145ms Start:2018-08-31 12:54:19.466655054 +0000 UTC m=+222.137277216 End:2018-08-31 12:54:19.484471243 +0000 UTC m=+222.155093361
I0831 12:54:19.484521       1 scheduler.go:454] Total Schedule Algo cumulative time:13.409635044s for 1135
I0831 12:54:19.502434       1 scheduler.go:451] ScheduleAlgoTime 17.809704ms Start:2018-08-31 12:54:19.484617594 +0000 UTC m=+222.155239742 End:2018-08-31 12:54:19.502427327 +0000 UTC m=+222.173049446
I0831 12:54:19.502480       1 scheduler.go:454] Total Schedule Algo cumulative time:13.427444748s for 1136
I0831 12:54:19.521147       1 scheduler.go:451] ScheduleAlgoTime 18.529453ms Start:2018-08-31 12:54:19.502610074 +0000 UTC m=+222.173232224 End:2018-08-31 12:54:19.52113953 +0000 UTC m=+222.191761677
I0831 12:54:19.521189       1 scheduler.go:454] Total Schedule Algo cumulative time:13.445974201s for 1137
I0831 12:54:19.542439       1 scheduler.go:451] ScheduleAlgoTime 21.158099ms Start:2018-08-31 12:54:19.521269942 +0000 UTC m=+222.191892095 End:2018-08-31 12:54:19.542428063 +0000 UTC m=+222.213050194
I0831 12:54:19.542496       1 scheduler.go:454] Total Schedule Algo cumulative time:13.4671323s for 1138
I0831 12:54:19.561352       1 scheduler.go:451] ScheduleAlgoTime 18.713877ms Start:2018-08-31 12:54:19.542631619 +0000 UTC m=+222.213253755 End:2018-08-31 12:54:19.561345513 +0000 UTC m=+222.231967632
I0831 12:54:19.561390       1 scheduler.go:454] Total Schedule Algo cumulative time:13.485846177s for 1139
I0831 12:54:19.579824       1 scheduler.go:451] ScheduleAlgoTime 18.331335ms Start:2018-08-31 12:54:19.561485143 +0000 UTC m=+222.232107307 End:2018-08-31 12:54:19.579816523 +0000 UTC m=+222.250438642
I0831 12:54:19.579873       1 scheduler.go:454] Total Schedule Algo cumulative time:13.504177512s for 1140
I0831 12:54:19.597997       1 scheduler.go:451] ScheduleAlgoTime 18.032046ms Start:2018-08-31 12:54:19.57995901 +0000 UTC m=+222.250581163 End:2018-08-31 12:54:19.597991091 +0000 UTC m=+222.268613209
I0831 12:54:19.598029       1 scheduler.go:454] Total Schedule Algo cumulative time:13.522209558s for 1141
I0831 12:54:19.613704       1 scheduler.go:451] ScheduleAlgoTime 15.582878ms Start:2018-08-31 12:54:19.598113384 +0000 UTC m=+222.268735531 End:2018-08-31 12:54:19.613696282 +0000 UTC m=+222.284318409
I0831 12:54:19.613749       1 scheduler.go:454] Total Schedule Algo cumulative time:13.537792436s for 1142
I0831 12:54:19.632664       1 scheduler.go:451] ScheduleAlgoTime 18.826493ms Start:2018-08-31 12:54:19.613830891 +0000 UTC m=+222.284453057 End:2018-08-31 12:54:19.632657427 +0000 UTC m=+222.303279550
I0831 12:54:19.632694       1 scheduler.go:454] Total Schedule Algo cumulative time:13.556618929s for 1143
I0831 12:54:19.648299       1 scheduler.go:451] ScheduleAlgoTime 15.527778ms Start:2018-08-31 12:54:19.632765263 +0000 UTC m=+222.303387410 End:2018-08-31 12:54:19.648293068 +0000 UTC m=+222.318915188
I0831 12:54:19.648326       1 scheduler.go:454] Total Schedule Algo cumulative time:13.572146707s for 1144
I0831 12:54:19.663726       1 scheduler.go:451] ScheduleAlgoTime 15.327522ms Start:2018-08-31 12:54:19.648391776 +0000 UTC m=+222.319013945 End:2018-08-31 12:54:19.663719347 +0000 UTC m=+222.334341467
I0831 12:54:19.663755       1 scheduler.go:454] Total Schedule Algo cumulative time:13.587474229s for 1145
I0831 12:54:19.682547       1 scheduler.go:451] ScheduleAlgoTime 18.701874ms Start:2018-08-31 12:54:19.663839859 +0000 UTC m=+222.334462050 End:2018-08-31 12:54:19.682541803 +0000 UTC m=+222.353163924
I0831 12:54:19.682598       1 scheduler.go:454] Total Schedule Algo cumulative time:13.606176103s for 1146
I0831 12:54:19.698346       1 scheduler.go:451] ScheduleAlgoTime 15.649664ms Start:2018-08-31 12:54:19.68269079 +0000 UTC m=+222.353312946 End:2018-08-31 12:54:19.698340491 +0000 UTC m=+222.368962610
I0831 12:54:19.698378       1 scheduler.go:454] Total Schedule Algo cumulative time:13.621825767s for 1147
I0831 12:54:19.715074       1 scheduler.go:451] ScheduleAlgoTime 16.598574ms Start:2018-08-31 12:54:19.698469791 +0000 UTC m=+222.369091937 End:2018-08-31 12:54:19.715068391 +0000 UTC m=+222.385690511
I0831 12:54:19.715102       1 scheduler.go:454] Total Schedule Algo cumulative time:13.638424341s for 1148
I0831 12:54:19.735764       1 scheduler.go:451] ScheduleAlgoTime 20.561117ms Start:2018-08-31 12:54:19.715197032 +0000 UTC m=+222.385819186 End:2018-08-31 12:54:19.735758184 +0000 UTC m=+222.406380303
I0831 12:54:19.735800       1 scheduler.go:454] Total Schedule Algo cumulative time:13.658985458s for 1149
I0831 12:54:19.752489       1 scheduler.go:451] ScheduleAlgoTime 16.596545ms Start:2018-08-31 12:54:19.735885834 +0000 UTC m=+222.406507983 End:2018-08-31 12:54:19.752482411 +0000 UTC m=+222.423104528
I0831 12:54:19.752534       1 scheduler.go:454] Total Schedule Algo cumulative time:13.675582003s for 1150
I0831 12:54:19.770561       1 scheduler.go:451] ScheduleAlgoTime 17.929413ms Start:2018-08-31 12:54:19.752626331 +0000 UTC m=+222.423248487 End:2018-08-31 12:54:19.77055578 +0000 UTC m=+222.441177900
I0831 12:54:19.770606       1 scheduler.go:454] Total Schedule Algo cumulative time:13.693511416s for 1151
I0831 12:54:19.785969       1 scheduler.go:451] ScheduleAlgoTime 15.25842ms Start:2018-08-31 12:54:19.770706036 +0000 UTC m=+222.441328220 End:2018-08-31 12:54:19.785964518 +0000 UTC m=+222.456586640
I0831 12:54:19.786001       1 scheduler.go:454] Total Schedule Algo cumulative time:13.708769836s for 1152
I0831 12:54:19.803625       1 scheduler.go:451] ScheduleAlgoTime 17.539411ms Start:2018-08-31 12:54:19.786080795 +0000 UTC m=+222.456702943 End:2018-08-31 12:54:19.803620234 +0000 UTC m=+222.474242354
I0831 12:54:19.803657       1 scheduler.go:454] Total Schedule Algo cumulative time:13.726309247s for 1153
I0831 12:54:19.820529       1 scheduler.go:451] ScheduleAlgoTime 16.773335ms Start:2018-08-31 12:54:19.803746623 +0000 UTC m=+222.474368757 End:2018-08-31 12:54:19.820519962 +0000 UTC m=+222.491142092
I0831 12:54:19.820580       1 scheduler.go:454] Total Schedule Algo cumulative time:13.743082582s for 1154
I0831 12:54:19.841130       1 scheduler.go:451] ScheduleAlgoTime 20.43289ms Start:2018-08-31 12:54:19.820691783 +0000 UTC m=+222.491313946 End:2018-08-31 12:54:19.841124717 +0000 UTC m=+222.511746836
I0831 12:54:19.841159       1 scheduler.go:454] Total Schedule Algo cumulative time:13.763515472s for 1155
I0831 12:54:19.861007       1 scheduler.go:451] ScheduleAlgoTime 19.755773ms Start:2018-08-31 12:54:19.841244651 +0000 UTC m=+222.511866804 End:2018-08-31 12:54:19.861000454 +0000 UTC m=+222.531622577
I0831 12:54:19.861040       1 scheduler.go:454] Total Schedule Algo cumulative time:13.783271245s for 1156
I0831 12:54:19.884614       1 scheduler.go:451] ScheduleAlgoTime 23.483629ms Start:2018-08-31 12:54:19.861120972 +0000 UTC m=+222.531743124 End:2018-08-31 12:54:19.884604226 +0000 UTC m=+222.555226753
I0831 12:54:19.884759       1 scheduler.go:454] Total Schedule Algo cumulative time:13.806754874s for 1157
I0831 12:54:19.914268       1 scheduler.go:451] ScheduleAlgoTime 27.600837ms Start:2018-08-31 12:54:19.886659428 +0000 UTC m=+222.557281597 End:2018-08-31 12:54:19.914260313 +0000 UTC m=+222.584882434
I0831 12:54:19.914308       1 scheduler.go:454] Total Schedule Algo cumulative time:13.834355711s for 1158
I0831 12:54:19.932060       1 scheduler.go:451] ScheduleAlgoTime 17.653637ms Start:2018-08-31 12:54:19.914400237 +0000 UTC m=+222.585022400 End:2018-08-31 12:54:19.93205392 +0000 UTC m=+222.602676037
I0831 12:54:19.932097       1 scheduler.go:454] Total Schedule Algo cumulative time:13.852009348s for 1159
I0831 12:54:19.954093       1 scheduler.go:451] ScheduleAlgoTime 21.89433ms Start:2018-08-31 12:54:19.93219059 +0000 UTC m=+222.602812746 End:2018-08-31 12:54:19.954084958 +0000 UTC m=+222.624707076
I0831 12:54:19.954135       1 scheduler.go:454] Total Schedule Algo cumulative time:13.873903678s for 1160
I0831 12:54:19.974593       1 scheduler.go:451] ScheduleAlgoTime 20.338315ms Start:2018-08-31 12:54:19.954225459 +0000 UTC m=+222.624847618 End:2018-08-31 12:54:19.974563798 +0000 UTC m=+222.645185933
I0831 12:54:19.974634       1 scheduler.go:454] Total Schedule Algo cumulative time:13.894241993s for 1161
I0831 12:54:19.990647       1 scheduler.go:451] ScheduleAlgoTime 15.916192ms Start:2018-08-31 12:54:19.974725598 +0000 UTC m=+222.645347739 End:2018-08-31 12:54:19.99064181 +0000 UTC m=+222.661263931
I0831 12:54:19.990680       1 scheduler.go:454] Total Schedule Algo cumulative time:13.910158185s for 1162
I0831 12:54:20.006654       1 scheduler.go:451] ScheduleAlgoTime 15.889297ms Start:2018-08-31 12:54:19.990757797 +0000 UTC m=+222.661379951 End:2018-08-31 12:54:20.006647127 +0000 UTC m=+222.677269248
I0831 12:54:20.006692       1 scheduler.go:454] Total Schedule Algo cumulative time:13.926047482s for 1163
I0831 12:54:20.025378       1 scheduler.go:451] ScheduleAlgoTime 18.597489ms Start:2018-08-31 12:54:20.006774456 +0000 UTC m=+222.677396605 End:2018-08-31 12:54:20.025371975 +0000 UTC m=+222.695994094
I0831 12:54:20.025407       1 scheduler.go:454] Total Schedule Algo cumulative time:13.944644971s for 1164
I0831 12:54:20.044927       1 scheduler.go:451] ScheduleAlgoTime 19.426338ms Start:2018-08-31 12:54:20.025494658 +0000 UTC m=+222.696116818 End:2018-08-31 12:54:20.044921037 +0000 UTC m=+222.715543156
I0831 12:54:20.044958       1 scheduler.go:454] Total Schedule Algo cumulative time:13.964071309s for 1165
I0831 12:54:20.063969       1 scheduler.go:451] ScheduleAlgoTime 18.895545ms Start:2018-08-31 12:54:20.045064517 +0000 UTC m=+222.715686672 End:2018-08-31 12:54:20.063960078 +0000 UTC m=+222.734582217
I0831 12:54:20.064020       1 scheduler.go:454] Total Schedule Algo cumulative time:13.982966854s for 1166
I0831 12:54:20.081067       1 scheduler.go:451] ScheduleAlgoTime 16.926858ms Start:2018-08-31 12:54:20.064132676 +0000 UTC m=+222.734754828 End:2018-08-31 12:54:20.081059564 +0000 UTC m=+222.751681686
I0831 12:54:20.081112       1 scheduler.go:454] Total Schedule Algo cumulative time:13.999893712s for 1167
I0831 12:54:20.097623       1 scheduler.go:451] ScheduleAlgoTime 16.423242ms Start:2018-08-31 12:54:20.081192859 +0000 UTC m=+222.751815052 End:2018-08-31 12:54:20.097616174 +0000 UTC m=+222.768238294
I0831 12:54:20.097654       1 scheduler.go:454] Total Schedule Algo cumulative time:14.016316954s for 1168
I0831 12:54:20.117726       1 scheduler.go:451] ScheduleAlgoTime 19.981803ms Start:2018-08-31 12:54:20.097737596 +0000 UTC m=+222.768359737 End:2018-08-31 12:54:20.117719422 +0000 UTC m=+222.788341540
I0831 12:54:20.117760       1 scheduler.go:454] Total Schedule Algo cumulative time:14.036298757s for 1169
I0831 12:54:20.138921       1 scheduler.go:451] ScheduleAlgoTime 21.077256ms Start:2018-08-31 12:54:20.117832632 +0000 UTC m=+222.788454774 End:2018-08-31 12:54:20.138909899 +0000 UTC m=+222.809532030
I0831 12:54:20.139015       1 scheduler.go:454] Total Schedule Algo cumulative time:14.057376013s for 1170
I0831 12:54:20.157691       1 scheduler.go:451] ScheduleAlgoTime 18.529656ms Start:2018-08-31 12:54:20.139155641 +0000 UTC m=+222.809777792 End:2018-08-31 12:54:20.157685328 +0000 UTC m=+222.828307448
I0831 12:54:20.157725       1 scheduler.go:454] Total Schedule Algo cumulative time:14.075905669s for 1171
I0831 12:54:20.175567       1 scheduler.go:451] ScheduleAlgoTime 17.728918ms Start:2018-08-31 12:54:20.157823559 +0000 UTC m=+222.828445717 End:2018-08-31 12:54:20.175552515 +0000 UTC m=+222.846174635
I0831 12:54:20.175616       1 scheduler.go:454] Total Schedule Algo cumulative time:14.093634587s for 1172
I0831 12:54:20.191715       1 scheduler.go:451] ScheduleAlgoTime 15.991784ms Start:2018-08-31 12:54:20.175717289 +0000 UTC m=+222.846339442 End:2018-08-31 12:54:20.191709108 +0000 UTC m=+222.862331226
I0831 12:54:20.191765       1 scheduler.go:454] Total Schedule Algo cumulative time:14.109626371s for 1173
I0831 12:54:20.209049       1 scheduler.go:451] ScheduleAlgoTime 17.162952ms Start:2018-08-31 12:54:20.19187756 +0000 UTC m=+222.862499706 End:2018-08-31 12:54:20.209040528 +0000 UTC m=+222.879662658
I0831 12:54:20.209078       1 scheduler.go:454] Total Schedule Algo cumulative time:14.126789323s for 1174
I0831 12:54:20.226339       1 scheduler.go:451] ScheduleAlgoTime 17.176204ms Start:2018-08-31 12:54:20.209156888 +0000 UTC m=+222.879779057 End:2018-08-31 12:54:20.226333142 +0000 UTC m=+222.896955261
I0831 12:54:20.226370       1 scheduler.go:454] Total Schedule Algo cumulative time:14.143965527s for 1175
I0831 12:54:20.243400       1 scheduler.go:451] ScheduleAlgoTime 16.925964ms Start:2018-08-31 12:54:20.226468098 +0000 UTC m=+222.897090251 End:2018-08-31 12:54:20.243394096 +0000 UTC m=+222.914016215
I0831 12:54:20.243432       1 scheduler.go:454] Total Schedule Algo cumulative time:14.160891491s for 1176
I0831 12:54:20.261103       1 scheduler.go:451] ScheduleAlgoTime 17.557884ms Start:2018-08-31 12:54:20.243538545 +0000 UTC m=+222.914160715 End:2018-08-31 12:54:20.261096479 +0000 UTC m=+222.931718599
I0831 12:54:20.261134       1 scheduler.go:454] Total Schedule Algo cumulative time:14.178449375s for 1177
I0831 12:54:20.277417       1 scheduler.go:451] ScheduleAlgoTime 16.193574ms Start:2018-08-31 12:54:20.261218228 +0000 UTC m=+222.931840375 End:2018-08-31 12:54:20.277411828 +0000 UTC m=+222.948033949
I0831 12:54:20.277445       1 scheduler.go:454] Total Schedule Algo cumulative time:14.194642949s for 1178
I0831 12:54:20.292949       1 scheduler.go:451] ScheduleAlgoTime 15.399856ms Start:2018-08-31 12:54:20.277541125 +0000 UTC m=+222.948163273 End:2018-08-31 12:54:20.292941002 +0000 UTC m=+222.963563129
I0831 12:54:20.292986       1 scheduler.go:454] Total Schedule Algo cumulative time:14.210042805s for 1179
I0831 12:54:20.310813       1 scheduler.go:451] ScheduleAlgoTime 17.712018ms Start:2018-08-31 12:54:20.293093327 +0000 UTC m=+222.963715490 End:2018-08-31 12:54:20.310805377 +0000 UTC m=+222.981427508
I0831 12:54:20.310866       1 scheduler.go:454] Total Schedule Algo cumulative time:14.227754823s for 1180
I0831 12:54:20.327814       1 scheduler.go:451] ScheduleAlgoTime 16.854082ms Start:2018-08-31 12:54:20.310952409 +0000 UTC m=+222.981574562 End:2018-08-31 12:54:20.327806525 +0000 UTC m=+222.998428644
I0831 12:54:20.327849       1 scheduler.go:454] Total Schedule Algo cumulative time:14.244608905s for 1181
I0831 12:54:20.352730       1 scheduler.go:451] ScheduleAlgoTime 24.784515ms Start:2018-08-31 12:54:20.32793886 +0000 UTC m=+222.998561006 End:2018-08-31 12:54:20.352723401 +0000 UTC m=+223.023345521
I0831 12:54:20.352777       1 scheduler.go:454] Total Schedule Algo cumulative time:14.26939342s for 1182
I0831 12:54:20.372123       1 scheduler.go:451] ScheduleAlgoTime 19.243345ms Start:2018-08-31 12:54:20.352869309 +0000 UTC m=+223.023491461 End:2018-08-31 12:54:20.372112642 +0000 UTC m=+223.042734806
I0831 12:54:20.372166       1 scheduler.go:454] Total Schedule Algo cumulative time:14.288636765s for 1183
I0831 12:54:20.389150       1 scheduler.go:451] ScheduleAlgoTime 16.881896ms Start:2018-08-31 12:54:20.372259607 +0000 UTC m=+223.042881753 End:2018-08-31 12:54:20.389141522 +0000 UTC m=+223.059763649
I0831 12:54:20.389202       1 scheduler.go:454] Total Schedule Algo cumulative time:14.305518661s for 1184
I0831 12:54:20.405542       1 scheduler.go:451] ScheduleAlgoTime 16.225244ms Start:2018-08-31 12:54:20.389311227 +0000 UTC m=+223.059933397 End:2018-08-31 12:54:20.405536522 +0000 UTC m=+223.076158641
I0831 12:54:20.405581       1 scheduler.go:454] Total Schedule Algo cumulative time:14.321743905s for 1185
I0831 12:54:20.422951       1 scheduler.go:451] ScheduleAlgoTime 17.274956ms Start:2018-08-31 12:54:20.405667203 +0000 UTC m=+223.076289359 End:2018-08-31 12:54:20.422942184 +0000 UTC m=+223.093564315
I0831 12:54:20.422993       1 scheduler.go:454] Total Schedule Algo cumulative time:14.339018861s for 1186
I0831 12:54:20.440215       1 scheduler.go:451] ScheduleAlgoTime 17.145053ms Start:2018-08-31 12:54:20.423062887 +0000 UTC m=+223.093685039 End:2018-08-31 12:54:20.440207973 +0000 UTC m=+223.110830092
I0831 12:54:20.440247       1 scheduler.go:454] Total Schedule Algo cumulative time:14.356163914s for 1187
I0831 12:54:20.459912       1 scheduler.go:451] ScheduleAlgoTime 19.587472ms Start:2018-08-31 12:54:20.440318038 +0000 UTC m=+223.110940194 End:2018-08-31 12:54:20.459905547 +0000 UTC m=+223.130527666
I0831 12:54:20.459944       1 scheduler.go:454] Total Schedule Algo cumulative time:14.375751386s for 1188
I0831 12:54:20.477244       1 scheduler.go:451] ScheduleAlgoTime 17.19684ms Start:2018-08-31 12:54:20.460040432 +0000 UTC m=+223.130662586 End:2018-08-31 12:54:20.477237305 +0000 UTC m=+223.147859426
I0831 12:54:20.477277       1 scheduler.go:454] Total Schedule Algo cumulative time:14.392948226s for 1189
I0831 12:54:20.496579       1 scheduler.go:451] ScheduleAlgoTime 19.207951ms Start:2018-08-31 12:54:20.477364384 +0000 UTC m=+223.147986554 End:2018-08-31 12:54:20.496572385 +0000 UTC m=+223.167194505
I0831 12:54:20.496610       1 scheduler.go:454] Total Schedule Algo cumulative time:14.412156177s for 1190
I0831 12:54:20.514946       1 scheduler.go:451] ScheduleAlgoTime 18.237982ms Start:2018-08-31 12:54:20.496701211 +0000 UTC m=+223.167323346 End:2018-08-31 12:54:20.514939208 +0000 UTC m=+223.185561328
I0831 12:54:20.514978       1 scheduler.go:454] Total Schedule Algo cumulative time:14.430394159s for 1191
I0831 12:54:20.532841       1 scheduler.go:451] ScheduleAlgoTime 17.764838ms Start:2018-08-31 12:54:20.515068377 +0000 UTC m=+223.185690526 End:2018-08-31 12:54:20.532833241 +0000 UTC m=+223.203455364
I0831 12:54:20.532908       1 scheduler.go:454] Total Schedule Algo cumulative time:14.448158997s for 1192
I0831 12:54:20.557428       1 scheduler.go:451] ScheduleAlgoTime 24.412053ms Start:2018-08-31 12:54:20.533007939 +0000 UTC m=+223.203630099 End:2018-08-31 12:54:20.557420031 +0000 UTC m=+223.228042152
I0831 12:54:20.557477       1 scheduler.go:454] Total Schedule Algo cumulative time:14.47257105s for 1193
I0831 12:54:20.577135       1 scheduler.go:451] ScheduleAlgoTime 19.545234ms Start:2018-08-31 12:54:20.557582609 +0000 UTC m=+223.228204757 End:2018-08-31 12:54:20.577127871 +0000 UTC m=+223.247749991
I0831 12:54:20.577178       1 scheduler.go:454] Total Schedule Algo cumulative time:14.492116284s for 1194
I0831 12:54:20.594901       1 scheduler.go:451] ScheduleAlgoTime 17.622886ms Start:2018-08-31 12:54:20.577270835 +0000 UTC m=+223.247892977 End:2018-08-31 12:54:20.594893746 +0000 UTC m=+223.265515863
I0831 12:54:20.594943       1 scheduler.go:454] Total Schedule Algo cumulative time:14.50973917s for 1195
I0831 12:54:20.611284       1 scheduler.go:451] ScheduleAlgoTime 16.24947ms Start:2018-08-31 12:54:20.595025394 +0000 UTC m=+223.265647586 End:2018-08-31 12:54:20.611274925 +0000 UTC m=+223.281897056
I0831 12:54:20.611332       1 scheduler.go:454] Total Schedule Algo cumulative time:14.52598864s for 1196
I0831 12:54:20.627382       1 scheduler.go:451] ScheduleAlgoTime 15.939119ms Start:2018-08-31 12:54:20.611436984 +0000 UTC m=+223.282059141 End:2018-08-31 12:54:20.627376139 +0000 UTC m=+223.297998260
I0831 12:54:20.627415       1 scheduler.go:454] Total Schedule Algo cumulative time:14.541927759s for 1197
I0831 12:54:20.644424       1 scheduler.go:451] ScheduleAlgoTime 16.913049ms Start:2018-08-31 12:54:20.62750549 +0000 UTC m=+223.298127636 End:2018-08-31 12:54:20.644418567 +0000 UTC m=+223.315040685
I0831 12:54:20.644466       1 scheduler.go:454] Total Schedule Algo cumulative time:14.558840808s for 1198
I0831 12:54:20.664286       1 scheduler.go:451] ScheduleAlgoTime 19.721515ms Start:2018-08-31 12:54:20.644557963 +0000 UTC m=+223.315180145 End:2018-08-31 12:54:20.664279541 +0000 UTC m=+223.334901660
I0831 12:54:20.664323       1 scheduler.go:454] Total Schedule Algo cumulative time:14.578562323s for 1199
I0831 12:54:20.683332       1 scheduler.go:451] ScheduleAlgoTime 18.921849ms Start:2018-08-31 12:54:20.664403681 +0000 UTC m=+223.335025895 End:2018-08-31 12:54:20.683325623 +0000 UTC m=+223.353947744
I0831 12:54:20.683361       1 scheduler.go:454] Total Schedule Algo cumulative time:14.597484172s for 1200
I0831 12:54:20.701752       1 scheduler.go:451] ScheduleAlgoTime 18.303032ms Start:2018-08-31 12:54:20.683442331 +0000 UTC m=+223.354064491 End:2018-08-31 12:54:20.701745403 +0000 UTC m=+223.372367523
I0831 12:54:20.701786       1 scheduler.go:454] Total Schedule Algo cumulative time:14.615787204s for 1201
I0831 12:54:20.720724       1 scheduler.go:451] ScheduleAlgoTime 18.846568ms Start:2018-08-31 12:54:20.701869379 +0000 UTC m=+223.372491541 End:2018-08-31 12:54:20.720715979 +0000 UTC m=+223.391338109
I0831 12:54:20.720768       1 scheduler.go:454] Total Schedule Algo cumulative time:14.634633772s for 1202
I0831 12:54:20.741967       1 scheduler.go:451] ScheduleAlgoTime 21.072028ms Start:2018-08-31 12:54:20.720886231 +0000 UTC m=+223.391508400 End:2018-08-31 12:54:20.741958304 +0000 UTC m=+223.412580428
I0831 12:54:20.742012       1 scheduler.go:454] Total Schedule Algo cumulative time:14.6557058s for 1203
I0831 12:54:20.788834       1 scheduler.go:451] ScheduleAlgoTime 46.730913ms Start:2018-08-31 12:54:20.742093266 +0000 UTC m=+223.412715426 End:2018-08-31 12:54:20.788824206 +0000 UTC m=+223.459446339
I0831 12:54:20.788890       1 scheduler.go:454] Total Schedule Algo cumulative time:14.702436713s for 1204
I0831 12:54:20.808028       1 scheduler.go:451] ScheduleAlgoTime 19.032606ms Start:2018-08-31 12:54:20.788987222 +0000 UTC m=+223.459609372 End:2018-08-31 12:54:20.808019855 +0000 UTC m=+223.478641978
I0831 12:54:20.808070       1 scheduler.go:454] Total Schedule Algo cumulative time:14.721469319s for 1205
I0831 12:54:20.825678       1 scheduler.go:451] ScheduleAlgoTime 17.471812ms Start:2018-08-31 12:54:20.808199946 +0000 UTC m=+223.478822109 End:2018-08-31 12:54:20.8256718 +0000 UTC m=+223.496293921
I0831 12:54:20.825709       1 scheduler.go:454] Total Schedule Algo cumulative time:14.738941131s for 1206
I0831 12:54:20.844521       1 scheduler.go:451] ScheduleAlgoTime 18.72413ms Start:2018-08-31 12:54:20.825791232 +0000 UTC m=+223.496413385 End:2018-08-31 12:54:20.844515394 +0000 UTC m=+223.515137515
I0831 12:54:20.844563       1 scheduler.go:454] Total Schedule Algo cumulative time:14.757665261s for 1207
I0831 12:54:20.860832       1 scheduler.go:451] ScheduleAlgoTime 16.173526ms Start:2018-08-31 12:54:20.844653344 +0000 UTC m=+223.515275510 End:2018-08-31 12:54:20.860826917 +0000 UTC m=+223.531449036
I0831 12:54:20.860868       1 scheduler.go:454] Total Schedule Algo cumulative time:14.773838787s for 1208
I0831 12:54:20.877873       1 scheduler.go:451] ScheduleAlgoTime 16.915399ms Start:2018-08-31 12:54:20.86095209 +0000 UTC m=+223.531574242 End:2018-08-31 12:54:20.87786752 +0000 UTC m=+223.548489641
I0831 12:54:20.877903       1 scheduler.go:454] Total Schedule Algo cumulative time:14.790754186s for 1209
I0831 12:54:20.896732       1 scheduler.go:451] ScheduleAlgoTime 18.73583ms Start:2018-08-31 12:54:20.877990223 +0000 UTC m=+223.548612411 End:2018-08-31 12:54:20.89672612 +0000 UTC m=+223.567348241
I0831 12:54:20.896761       1 scheduler.go:454] Total Schedule Algo cumulative time:14.809490016s for 1210
I0831 12:54:20.913464       1 scheduler.go:451] ScheduleAlgoTime 16.604143ms Start:2018-08-31 12:54:20.896846052 +0000 UTC m=+223.567468187 End:2018-08-31 12:54:20.91345021 +0000 UTC m=+223.584072330
I0831 12:54:20.913493       1 scheduler.go:454] Total Schedule Algo cumulative time:14.826094159s for 1211
I0831 12:54:20.932093       1 scheduler.go:451] ScheduleAlgoTime 18.509507ms Start:2018-08-31 12:54:20.913577765 +0000 UTC m=+223.584199920 End:2018-08-31 12:54:20.932087304 +0000 UTC m=+223.602709427
I0831 12:54:20.932129       1 scheduler.go:454] Total Schedule Algo cumulative time:14.844603666s for 1212
I0831 12:54:20.951424       1 scheduler.go:451] ScheduleAlgoTime 19.154259ms Start:2018-08-31 12:54:20.932264548 +0000 UTC m=+223.602886702 End:2018-08-31 12:54:20.951418841 +0000 UTC m=+223.622040961
I0831 12:54:20.951475       1 scheduler.go:454] Total Schedule Algo cumulative time:14.863757925s for 1213
I0831 12:54:20.972455       1 scheduler.go:451] ScheduleAlgoTime 20.891941ms Start:2018-08-31 12:54:20.951554189 +0000 UTC m=+223.622176334 End:2018-08-31 12:54:20.972446153 +0000 UTC m=+223.643068275
I0831 12:54:20.972518       1 scheduler.go:454] Total Schedule Algo cumulative time:14.884649866s for 1214
I0831 12:54:20.994556       1 scheduler.go:451] ScheduleAlgoTime 21.869745ms Start:2018-08-31 12:54:20.972676681 +0000 UTC m=+223.643298848 End:2018-08-31 12:54:20.99454647 +0000 UTC m=+223.665168593
I0831 12:54:20.994635       1 scheduler.go:454] Total Schedule Algo cumulative time:14.906519611s for 1215
I0831 12:54:21.012299       1 scheduler.go:451] ScheduleAlgoTime 17.514782ms Start:2018-08-31 12:54:20.994776846 +0000 UTC m=+223.665398989 End:2018-08-31 12:54:21.01229165 +0000 UTC m=+223.682913771
I0831 12:54:21.012345       1 scheduler.go:454] Total Schedule Algo cumulative time:14.924034393s for 1216
I0831 12:54:21.029803       1 scheduler.go:451] ScheduleAlgoTime 17.264658ms Start:2018-08-31 12:54:21.012527667 +0000 UTC m=+223.683149813 End:2018-08-31 12:54:21.029792352 +0000 UTC m=+223.700414471
I0831 12:54:21.029865       1 scheduler.go:454] Total Schedule Algo cumulative time:14.941299051s for 1217
I0831 12:54:21.047446       1 scheduler.go:451] ScheduleAlgoTime 17.47025ms Start:2018-08-31 12:54:21.029967622 +0000 UTC m=+223.700589784 End:2018-08-31 12:54:21.047437915 +0000 UTC m=+223.718060034
I0831 12:54:21.047501       1 scheduler.go:454] Total Schedule Algo cumulative time:14.958769301s for 1218
I0831 12:54:21.066945       1 scheduler.go:451] ScheduleAlgoTime 19.246548ms Start:2018-08-31 12:54:21.047688316 +0000 UTC m=+223.718310465 End:2018-08-31 12:54:21.066934893 +0000 UTC m=+223.737557013
I0831 12:54:21.067007       1 scheduler.go:454] Total Schedule Algo cumulative time:14.978015849s for 1219
I0831 12:54:21.087511       1 scheduler.go:451] ScheduleAlgoTime 20.350992ms Start:2018-08-31 12:54:21.06715173 +0000 UTC m=+223.737773861 End:2018-08-31 12:54:21.087502734 +0000 UTC m=+223.758124853
I0831 12:54:21.087560       1 scheduler.go:454] Total Schedule Algo cumulative time:14.998366841s for 1220
I0831 12:54:21.108051       1 scheduler.go:451] ScheduleAlgoTime 20.364662ms Start:2018-08-31 12:54:21.087677431 +0000 UTC m=+223.758299587 End:2018-08-31 12:54:21.108042125 +0000 UTC m=+223.778664249
I0831 12:54:21.108097       1 scheduler.go:454] Total Schedule Algo cumulative time:15.018731503s for 1221
I0831 12:54:21.128889       1 scheduler.go:451] ScheduleAlgoTime 20.661813ms Start:2018-08-31 12:54:21.108219184 +0000 UTC m=+223.778841313 End:2018-08-31 12:54:21.128881007 +0000 UTC m=+223.799503126
I0831 12:54:21.128930       1 scheduler.go:454] Total Schedule Algo cumulative time:15.039393316s for 1222
I0831 12:54:21.148388       1 scheduler.go:451] ScheduleAlgoTime 19.362179ms Start:2018-08-31 12:54:21.129017639 +0000 UTC m=+223.799639784 End:2018-08-31 12:54:21.14837984 +0000 UTC m=+223.819001963
I0831 12:54:21.148430       1 scheduler.go:454] Total Schedule Algo cumulative time:15.058755495s for 1223
I0831 12:54:21.167152       1 scheduler.go:451] ScheduleAlgoTime 18.590604ms Start:2018-08-31 12:54:21.148554433 +0000 UTC m=+223.819176554 End:2018-08-31 12:54:21.16714504 +0000 UTC m=+223.837767158
I0831 12:54:21.167196       1 scheduler.go:454] Total Schedule Algo cumulative time:15.077346099s for 1224
I0831 12:54:21.185727       1 scheduler.go:451] ScheduleAlgoTime 18.419726ms Start:2018-08-31 12:54:21.16730099 +0000 UTC m=+223.837923135 End:2018-08-31 12:54:21.18572074 +0000 UTC m=+223.856342861
I0831 12:54:21.185764       1 scheduler.go:454] Total Schedule Algo cumulative time:15.095765825s for 1225
I0831 12:54:21.211488       1 scheduler.go:451] ScheduleAlgoTime 25.600314ms Start:2018-08-31 12:54:21.185879317 +0000 UTC m=+223.856501458 End:2018-08-31 12:54:21.211479652 +0000 UTC m=+223.882101772
I0831 12:54:21.211537       1 scheduler.go:454] Total Schedule Algo cumulative time:15.121366139s for 1226
I0831 12:54:21.229743       1 scheduler.go:451] ScheduleAlgoTime 18.052548ms Start:2018-08-31 12:54:21.211683015 +0000 UTC m=+223.882305160 End:2018-08-31 12:54:21.229735572 +0000 UTC m=+223.900357708
I0831 12:54:21.229781       1 scheduler.go:454] Total Schedule Algo cumulative time:15.139418687s for 1227
I0831 12:54:21.249441       1 scheduler.go:451] ScheduleAlgoTime 19.516729ms Start:2018-08-31 12:54:21.229916527 +0000 UTC m=+223.900538675 End:2018-08-31 12:54:21.249433285 +0000 UTC m=+223.920055404
I0831 12:54:21.249499       1 scheduler.go:454] Total Schedule Algo cumulative time:15.158935416s for 1228
I0831 12:54:21.267608       1 scheduler.go:451] ScheduleAlgoTime 17.990222ms Start:2018-08-31 12:54:21.249611513 +0000 UTC m=+223.920233675 End:2018-08-31 12:54:21.267601772 +0000 UTC m=+223.938223897
I0831 12:54:21.267654       1 scheduler.go:454] Total Schedule Algo cumulative time:15.176925638s for 1229
I0831 12:54:21.286493       1 scheduler.go:451] ScheduleAlgoTime 18.7336ms Start:2018-08-31 12:54:21.267752937 +0000 UTC m=+223.938375066 End:2018-08-31 12:54:21.286486542 +0000 UTC m=+223.957108666
I0831 12:54:21.286534       1 scheduler.go:454] Total Schedule Algo cumulative time:15.195659238s for 1230
I0831 12:54:21.305415       1 scheduler.go:451] ScheduleAlgoTime 18.738619ms Start:2018-08-31 12:54:21.286666688 +0000 UTC m=+223.957288837 End:2018-08-31 12:54:21.305405334 +0000 UTC m=+223.976027456
I0831 12:54:21.305485       1 scheduler.go:454] Total Schedule Algo cumulative time:15.214397857s for 1231
I0831 12:54:21.323943       1 scheduler.go:451] ScheduleAlgoTime 18.310042ms Start:2018-08-31 12:54:21.305624825 +0000 UTC m=+223.976246974 End:2018-08-31 12:54:21.323934894 +0000 UTC m=+223.994557016
I0831 12:54:21.323994       1 scheduler.go:454] Total Schedule Algo cumulative time:15.232707899s for 1232
I0831 12:54:21.343175       1 scheduler.go:451] ScheduleAlgoTime 19.056422ms Start:2018-08-31 12:54:21.324108942 +0000 UTC m=+223.994731099 End:2018-08-31 12:54:21.343165392 +0000 UTC m=+224.013787521
I0831 12:54:21.343225       1 scheduler.go:454] Total Schedule Algo cumulative time:15.251764321s for 1233
I0831 12:54:21.362138       1 scheduler.go:451] ScheduleAlgoTime 18.764734ms Start:2018-08-31 12:54:21.343366527 +0000 UTC m=+224.013988704 End:2018-08-31 12:54:21.362131319 +0000 UTC m=+224.032753438
I0831 12:54:21.362179       1 scheduler.go:454] Total Schedule Algo cumulative time:15.270529055s for 1234
I0831 12:54:21.384427       1 scheduler.go:451] ScheduleAlgoTime 22.115919ms Start:2018-08-31 12:54:21.362302363 +0000 UTC m=+224.032924540 End:2018-08-31 12:54:21.384418338 +0000 UTC m=+224.055040459
I0831 12:54:21.384489       1 scheduler.go:454] Total Schedule Algo cumulative time:15.292644974s for 1235
I0831 12:54:21.409217       1 scheduler.go:451] ScheduleAlgoTime 24.558337ms Start:2018-08-31 12:54:21.384649809 +0000 UTC m=+224.055271960 End:2018-08-31 12:54:21.409208175 +0000 UTC m=+224.079830297
I0831 12:54:21.409269       1 scheduler.go:454] Total Schedule Algo cumulative time:15.317203311s for 1236
I0831 12:54:21.432609       1 scheduler.go:451] ScheduleAlgoTime 22.90234ms Start:2018-08-31 12:54:21.409698958 +0000 UTC m=+224.080321106 End:2018-08-31 12:54:21.432601324 +0000 UTC m=+224.103223446
I0831 12:54:21.432650       1 scheduler.go:454] Total Schedule Algo cumulative time:15.340105651s for 1237
I0831 12:54:21.452130       1 scheduler.go:451] ScheduleAlgoTime 19.367173ms Start:2018-08-31 12:54:21.43275714 +0000 UTC m=+224.103379298 End:2018-08-31 12:54:21.452124354 +0000 UTC m=+224.122746471
I0831 12:54:21.452166       1 scheduler.go:454] Total Schedule Algo cumulative time:15.359472824s for 1238
I0831 12:54:21.471713       1 scheduler.go:451] ScheduleAlgoTime 19.419298ms Start:2018-08-31 12:54:21.452287622 +0000 UTC m=+224.122909787 End:2018-08-31 12:54:21.471706964 +0000 UTC m=+224.142329085
I0831 12:54:21.471760       1 scheduler.go:454] Total Schedule Algo cumulative time:15.378892122s for 1239
I0831 12:54:21.492233       1 scheduler.go:451] ScheduleAlgoTime 20.366597ms Start:2018-08-31 12:54:21.471860311 +0000 UTC m=+224.142482469 End:2018-08-31 12:54:21.492226946 +0000 UTC m=+224.162849066
I0831 12:54:21.492265       1 scheduler.go:454] Total Schedule Algo cumulative time:15.399258719s for 1240
I0831 12:54:21.510948       1 scheduler.go:451] ScheduleAlgoTime 18.52469ms Start:2018-08-31 12:54:21.492417996 +0000 UTC m=+224.163040128 End:2018-08-31 12:54:21.510942694 +0000 UTC m=+224.181564818
I0831 12:54:21.510990       1 scheduler.go:454] Total Schedule Algo cumulative time:15.417783409s for 1241
I0831 12:54:21.528337       1 scheduler.go:451] ScheduleAlgoTime 17.242344ms Start:2018-08-31 12:54:21.511085636 +0000 UTC m=+224.181707784 End:2018-08-31 12:54:21.528328008 +0000 UTC m=+224.198950128
I0831 12:54:21.528384       1 scheduler.go:454] Total Schedule Algo cumulative time:15.435025753s for 1242
I0831 12:54:21.546529       1 scheduler.go:451] ScheduleAlgoTime 17.984537ms Start:2018-08-31 12:54:21.528538643 +0000 UTC m=+224.199160785 End:2018-08-31 12:54:21.546523203 +0000 UTC m=+224.217145322
I0831 12:54:21.546583       1 scheduler.go:454] Total Schedule Algo cumulative time:15.45301029s for 1243
I0831 12:54:21.566407       1 scheduler.go:451] ScheduleAlgoTime 19.691343ms Start:2018-08-31 12:54:21.546709966 +0000 UTC m=+224.217332126 End:2018-08-31 12:54:21.566401348 +0000 UTC m=+224.237023469
I0831 12:54:21.566436       1 scheduler.go:454] Total Schedule Algo cumulative time:15.472701633s for 1244
I0831 12:54:21.585318       1 scheduler.go:451] ScheduleAlgoTime 18.700183ms Start:2018-08-31 12:54:21.56660825 +0000 UTC m=+224.237230370 End:2018-08-31 12:54:21.585308435 +0000 UTC m=+224.255930553
I0831 12:54:21.585381       1 scheduler.go:454] Total Schedule Algo cumulative time:15.491401816s for 1245
I0831 12:54:21.606081       1 scheduler.go:451] ScheduleAlgoTime 20.590244ms Start:2018-08-31 12:54:21.58548312 +0000 UTC m=+224.256105273 End:2018-08-31 12:54:21.606073396 +0000 UTC m=+224.276695517
I0831 12:54:21.606119       1 scheduler.go:454] Total Schedule Algo cumulative time:15.51199206s for 1246
I0831 12:54:21.630981       1 scheduler.go:451] ScheduleAlgoTime 24.74972ms Start:2018-08-31 12:54:21.606224407 +0000 UTC m=+224.276846597 End:2018-08-31 12:54:21.630974199 +0000 UTC m=+224.301596317
I0831 12:54:21.631043       1 scheduler.go:454] Total Schedule Algo cumulative time:15.53674178s for 1247
I0831 12:54:21.649058       1 scheduler.go:451] ScheduleAlgoTime 17.900459ms Start:2018-08-31 12:54:21.631151727 +0000 UTC m=+224.301773893 End:2018-08-31 12:54:21.649052228 +0000 UTC m=+224.319674352
I0831 12:54:21.649093       1 scheduler.go:454] Total Schedule Algo cumulative time:15.554642239s for 1248
I0831 12:54:21.667223       1 scheduler.go:451] ScheduleAlgoTime 18.034951ms Start:2018-08-31 12:54:21.649182103 +0000 UTC m=+224.319804246 End:2018-08-31 12:54:21.667217063 +0000 UTC m=+224.337839197
I0831 12:54:21.667259       1 scheduler.go:454] Total Schedule Algo cumulative time:15.57267719s for 1249
I0831 12:54:21.686644       1 scheduler.go:451] ScheduleAlgoTime 19.273863ms Start:2018-08-31 12:54:21.667364921 +0000 UTC m=+224.337987084 End:2018-08-31 12:54:21.686638827 +0000 UTC m=+224.357260947
I0831 12:54:21.686675       1 scheduler.go:454] Total Schedule Algo cumulative time:15.591951053s for 1250
I0831 12:54:21.705586       1 scheduler.go:451] ScheduleAlgoTime 18.784195ms Start:2018-08-31 12:54:21.686792047 +0000 UTC m=+224.357414196 End:2018-08-31 12:54:21.705576268 +0000 UTC m=+224.376198391
I0831 12:54:21.705643       1 scheduler.go:454] Total Schedule Algo cumulative time:15.610735248s for 1251
I0831 12:54:21.724319       1 scheduler.go:451] ScheduleAlgoTime 18.552282ms Start:2018-08-31 12:54:21.705755135 +0000 UTC m=+224.376377291 End:2018-08-31 12:54:21.724307453 +0000 UTC m=+224.394929573
I0831 12:54:21.724377       1 scheduler.go:454] Total Schedule Algo cumulative time:15.62928753s for 1252
I0831 12:54:21.751766       1 scheduler.go:451] ScheduleAlgoTime 27.211336ms Start:2018-08-31 12:54:21.724545466 +0000 UTC m=+224.395167612 End:2018-08-31 12:54:21.751756826 +0000 UTC m=+224.422378948
I0831 12:54:21.751861       1 scheduler.go:454] Total Schedule Algo cumulative time:15.656498866s for 1253
I0831 12:54:21.781568       1 scheduler.go:451] ScheduleAlgoTime 29.421417ms Start:2018-08-31 12:54:21.752135624 +0000 UTC m=+224.422757742 End:2018-08-31 12:54:21.781557035 +0000 UTC m=+224.452179159
I0831 12:54:21.781618       1 scheduler.go:454] Total Schedule Algo cumulative time:15.685920283s for 1254
I0831 12:54:21.802061       1 scheduler.go:451] ScheduleAlgoTime 20.263865ms Start:2018-08-31 12:54:21.781787365 +0000 UTC m=+224.452409533 End:2018-08-31 12:54:21.802051276 +0000 UTC m=+224.472673398
I0831 12:54:21.802120       1 scheduler.go:454] Total Schedule Algo cumulative time:15.706184148s for 1255
I0831 12:54:21.821713       1 scheduler.go:451] ScheduleAlgoTime 19.437408ms Start:2018-08-31 12:54:21.802267727 +0000 UTC m=+224.472889889 End:2018-08-31 12:54:21.821705178 +0000 UTC m=+224.492327297
I0831 12:54:21.821754       1 scheduler.go:454] Total Schedule Algo cumulative time:15.725621556s for 1256
I0831 12:54:21.843907       1 scheduler.go:451] ScheduleAlgoTime 22.039596ms Start:2018-08-31 12:54:21.821859828 +0000 UTC m=+224.492481987 End:2018-08-31 12:54:21.843899459 +0000 UTC m=+224.514521583
I0831 12:54:21.843962       1 scheduler.go:454] Total Schedule Algo cumulative time:15.747661152s for 1257
I0831 12:54:21.869379       1 scheduler.go:451] ScheduleAlgoTime 25.293892ms Start:2018-08-31 12:54:21.844077062 +0000 UTC m=+224.514699219 End:2018-08-31 12:54:21.869370991 +0000 UTC m=+224.539993111
I0831 12:54:21.869421       1 scheduler.go:454] Total Schedule Algo cumulative time:15.772955044s for 1258
I0831 12:54:21.888737       1 scheduler.go:451] ScheduleAlgoTime 19.187612ms Start:2018-08-31 12:54:21.86954117 +0000 UTC m=+224.540163325 End:2018-08-31 12:54:21.888728807 +0000 UTC m=+224.559350937
I0831 12:54:21.888781       1 scheduler.go:454] Total Schedule Algo cumulative time:15.792142656s for 1259
I0831 12:54:21.910328       1 scheduler.go:451] ScheduleAlgoTime 21.425008ms Start:2018-08-31 12:54:21.888895703 +0000 UTC m=+224.559517852 End:2018-08-31 12:54:21.910320741 +0000 UTC m=+224.580942860
I0831 12:54:21.910413       1 scheduler.go:454] Total Schedule Algo cumulative time:15.813567664s for 1260
I0831 12:54:21.930178       1 scheduler.go:451] ScheduleAlgoTime 19.608234ms Start:2018-08-31 12:54:21.910562744 +0000 UTC m=+224.581184892 End:2018-08-31 12:54:21.930171005 +0000 UTC m=+224.600793126
I0831 12:54:21.930220       1 scheduler.go:454] Total Schedule Algo cumulative time:15.833175898s for 1261
I0831 12:54:21.951950       1 scheduler.go:451] ScheduleAlgoTime 21.648971ms Start:2018-08-31 12:54:21.93029368 +0000 UTC m=+224.600915837 End:2018-08-31 12:54:21.951942688 +0000 UTC m=+224.622564808
I0831 12:54:21.951997       1 scheduler.go:454] Total Schedule Algo cumulative time:15.854824869s for 1262
I0831 12:54:21.972122       1 scheduler.go:451] ScheduleAlgoTime 19.99883ms Start:2018-08-31 12:54:21.952115389 +0000 UTC m=+224.622737552 End:2018-08-31 12:54:21.972114261 +0000 UTC m=+224.642736382
I0831 12:54:21.972168       1 scheduler.go:454] Total Schedule Algo cumulative time:15.874823699s for 1263
I0831 12:54:21.991958       1 scheduler.go:451] ScheduleAlgoTime 19.682148ms Start:2018-08-31 12:54:21.972270426 +0000 UTC m=+224.642892577 End:2018-08-31 12:54:21.991952604 +0000 UTC m=+224.662574725
I0831 12:54:21.992010       1 scheduler.go:454] Total Schedule Algo cumulative time:15.894505847s for 1264
I0831 12:54:22.014438       1 scheduler.go:451] ScheduleAlgoTime 22.317309ms Start:2018-08-31 12:54:21.992113151 +0000 UTC m=+224.662735287 End:2018-08-31 12:54:22.014430476 +0000 UTC m=+224.685052596
I0831 12:54:22.014501       1 scheduler.go:454] Total Schedule Algo cumulative time:15.916823156s for 1265
I0831 12:54:22.033785       1 scheduler.go:451] ScheduleAlgoTime 19.144922ms Start:2018-08-31 12:54:22.014631524 +0000 UTC m=+224.685253680 End:2018-08-31 12:54:22.033776481 +0000 UTC m=+224.704398602
I0831 12:54:22.033831       1 scheduler.go:454] Total Schedule Algo cumulative time:15.935968078s for 1266
I0831 12:54:22.055967       1 scheduler.go:451] ScheduleAlgoTime 22.006227ms Start:2018-08-31 12:54:22.033952232 +0000 UTC m=+224.704574386 End:2018-08-31 12:54:22.055958484 +0000 UTC m=+224.726580613
I0831 12:54:22.056015       1 scheduler.go:454] Total Schedule Algo cumulative time:15.957974305s for 1267
I0831 12:54:22.075147       1 scheduler.go:451] ScheduleAlgoTime 18.994031ms Start:2018-08-31 12:54:22.056146559 +0000 UTC m=+224.726768721 End:2018-08-31 12:54:22.075140629 +0000 UTC m=+224.745762752
I0831 12:54:22.075189       1 scheduler.go:454] Total Schedule Algo cumulative time:15.976968336s for 1268
I0831 12:54:22.103051       1 scheduler.go:451] ScheduleAlgoTime 27.750144ms Start:2018-08-31 12:54:22.075290196 +0000 UTC m=+224.745912342 End:2018-08-31 12:54:22.103040367 +0000 UTC m=+224.773662486
I0831 12:54:22.103102       1 scheduler.go:454] Total Schedule Algo cumulative time:16.00471848s for 1269
I0831 12:54:22.123707       1 scheduler.go:451] ScheduleAlgoTime 20.468961ms Start:2018-08-31 12:54:22.103228076 +0000 UTC m=+224.773850222 End:2018-08-31 12:54:22.123697063 +0000 UTC m=+224.794319183
I0831 12:54:22.123768       1 scheduler.go:454] Total Schedule Algo cumulative time:16.025187441s for 1270
I0831 12:54:22.142837       1 scheduler.go:451] ScheduleAlgoTime 18.837688ms Start:2018-08-31 12:54:22.123989209 +0000 UTC m=+224.794611356 End:2018-08-31 12:54:22.142826924 +0000 UTC m=+224.813449044
I0831 12:54:22.142890       1 scheduler.go:454] Total Schedule Algo cumulative time:16.044025129s for 1271
I0831 12:54:22.167209       1 scheduler.go:451] ScheduleAlgoTime 24.171758ms Start:2018-08-31 12:54:22.143028755 +0000 UTC m=+224.813650914 End:2018-08-31 12:54:22.167200551 +0000 UTC m=+224.837822672
I0831 12:54:22.167251       1 scheduler.go:454] Total Schedule Algo cumulative time:16.068196887s for 1272
I0831 12:54:22.186874       1 scheduler.go:451] ScheduleAlgoTime 19.518106ms Start:2018-08-31 12:54:22.167346689 +0000 UTC m=+224.837968844 End:2018-08-31 12:54:22.186864831 +0000 UTC m=+224.857486950
I0831 12:54:22.186928       1 scheduler.go:454] Total Schedule Algo cumulative time:16.087714993s for 1273
I0831 12:54:22.207535       1 scheduler.go:451] ScheduleAlgoTime 20.438831ms Start:2018-08-31 12:54:22.187084496 +0000 UTC m=+224.857706645 End:2018-08-31 12:54:22.207523347 +0000 UTC m=+224.878145476
I0831 12:54:22.207596       1 scheduler.go:454] Total Schedule Algo cumulative time:16.108153824s for 1274
I0831 12:54:22.227649       1 scheduler.go:451] ScheduleAlgoTime 19.924264ms Start:2018-08-31 12:54:22.207717923 +0000 UTC m=+224.878340076 End:2018-08-31 12:54:22.227642222 +0000 UTC m=+224.898264340
I0831 12:54:22.227688       1 scheduler.go:454] Total Schedule Algo cumulative time:16.128078088s for 1275
I0831 12:54:22.248162       1 scheduler.go:451] ScheduleAlgoTime 20.365354ms Start:2018-08-31 12:54:22.227788131 +0000 UTC m=+224.898410288 End:2018-08-31 12:54:22.248153524 +0000 UTC m=+224.918775642
I0831 12:54:22.248213       1 scheduler.go:454] Total Schedule Algo cumulative time:16.148443442s for 1276
I0831 12:54:22.271822       1 scheduler.go:451] ScheduleAlgoTime 23.499781ms Start:2018-08-31 12:54:22.248312221 +0000 UTC m=+224.918934391 End:2018-08-31 12:54:22.271811843 +0000 UTC m=+224.942434172
I0831 12:54:22.271883       1 scheduler.go:454] Total Schedule Algo cumulative time:16.171943223s for 1277
I0831 12:54:22.293507       1 scheduler.go:451] ScheduleAlgoTime 21.467444ms Start:2018-08-31 12:54:22.272031208 +0000 UTC m=+224.942653354 End:2018-08-31 12:54:22.293498679 +0000 UTC m=+224.964120798
I0831 12:54:22.293560       1 scheduler.go:454] Total Schedule Algo cumulative time:16.193410667s for 1278
I0831 12:54:22.323928       1 scheduler.go:451] ScheduleAlgoTime 30.205813ms Start:2018-08-31 12:54:22.293709254 +0000 UTC m=+224.964331403 End:2018-08-31 12:54:22.323915094 +0000 UTC m=+224.994537216
I0831 12:54:22.323984       1 scheduler.go:454] Total Schedule Algo cumulative time:16.22361648s for 1279
I0831 12:54:22.343499       1 scheduler.go:451] ScheduleAlgoTime 19.356118ms Start:2018-08-31 12:54:22.324132678 +0000 UTC m=+224.994754835 End:2018-08-31 12:54:22.34348883 +0000 UTC m=+225.014110953
I0831 12:54:22.343560       1 scheduler.go:454] Total Schedule Algo cumulative time:16.242972598s for 1280
I0831 12:54:22.363720       1 scheduler.go:451] ScheduleAlgoTime 20.002809ms Start:2018-08-31 12:54:22.343707357 +0000 UTC m=+225.014329510 End:2018-08-31 12:54:22.363710167 +0000 UTC m=+225.034332319
I0831 12:54:22.363789       1 scheduler.go:454] Total Schedule Algo cumulative time:16.262975407s for 1281
I0831 12:54:22.384090       1 scheduler.go:451] ScheduleAlgoTime 20.16143ms Start:2018-08-31 12:54:22.363921138 +0000 UTC m=+225.034543294 End:2018-08-31 12:54:22.384082602 +0000 UTC m=+225.054704724
I0831 12:54:22.384142       1 scheduler.go:454] Total Schedule Algo cumulative time:16.283136837s for 1282
I0831 12:54:22.403915       1 scheduler.go:451] ScheduleAlgoTime 19.700309ms Start:2018-08-31 12:54:22.384208412 +0000 UTC m=+225.054830602 End:2018-08-31 12:54:22.403908793 +0000 UTC m=+225.074530911
I0831 12:54:22.403962       1 scheduler.go:454] Total Schedule Algo cumulative time:16.302837146s for 1283
I0831 12:54:22.422771       1 scheduler.go:451] ScheduleAlgoTime 18.680623ms Start:2018-08-31 12:54:22.404084856 +0000 UTC m=+225.074707012 End:2018-08-31 12:54:22.422765513 +0000 UTC m=+225.093387635
I0831 12:54:22.422812       1 scheduler.go:454] Total Schedule Algo cumulative time:16.321517769s for 1284
I0831 12:54:22.443447       1 scheduler.go:451] ScheduleAlgoTime 20.522653ms Start:2018-08-31 12:54:22.422917426 +0000 UTC m=+225.093539597 End:2018-08-31 12:54:22.443440132 +0000 UTC m=+225.114062250
I0831 12:54:22.443494       1 scheduler.go:454] Total Schedule Algo cumulative time:16.342040422s for 1285
I0831 12:54:22.462596       1 scheduler.go:451] ScheduleAlgoTime 18.991699ms Start:2018-08-31 12:54:22.443599031 +0000 UTC m=+225.114221190 End:2018-08-31 12:54:22.462590769 +0000 UTC m=+225.133212889
I0831 12:54:22.462638       1 scheduler.go:454] Total Schedule Algo cumulative time:16.361032121s for 1286
I0831 12:54:22.484024       1 scheduler.go:451] ScheduleAlgoTime 21.257467ms Start:2018-08-31 12:54:22.462759224 +0000 UTC m=+225.133381384 End:2018-08-31 12:54:22.484016729 +0000 UTC m=+225.154638851
I0831 12:54:22.484073       1 scheduler.go:454] Total Schedule Algo cumulative time:16.382289588s for 1287
I0831 12:54:22.504936       1 scheduler.go:451] ScheduleAlgoTime 20.713652ms Start:2018-08-31 12:54:22.484215006 +0000 UTC m=+225.154837135 End:2018-08-31 12:54:22.504928668 +0000 UTC m=+225.175550787
I0831 12:54:22.504968       1 scheduler.go:454] Total Schedule Algo cumulative time:16.40300324s for 1288
I0831 12:54:22.523934       1 scheduler.go:451] ScheduleAlgoTime 18.838987ms Start:2018-08-31 12:54:22.505085888 +0000 UTC m=+225.175708088 End:2018-08-31 12:54:22.523924951 +0000 UTC m=+225.194547075
I0831 12:54:22.523985       1 scheduler.go:454] Total Schedule Algo cumulative time:16.421842227s for 1289
I0831 12:54:22.554089       1 scheduler.go:451] ScheduleAlgoTime 29.955405ms Start:2018-08-31 12:54:22.524125658 +0000 UTC m=+225.194747809 End:2018-08-31 12:54:22.554081094 +0000 UTC m=+225.224703214
I0831 12:54:22.554139       1 scheduler.go:454] Total Schedule Algo cumulative time:16.451797632s for 1290
I0831 12:54:22.573700       1 scheduler.go:451] ScheduleAlgoTime 19.430344ms Start:2018-08-31 12:54:22.554260348 +0000 UTC m=+225.224882509 End:2018-08-31 12:54:22.573690735 +0000 UTC m=+225.244312853
I0831 12:54:22.573761       1 scheduler.go:454] Total Schedule Algo cumulative time:16.471227976s for 1291
I0831 12:54:22.593679       1 scheduler.go:451] ScheduleAlgoTime 19.766646ms Start:2018-08-31 12:54:22.573905319 +0000 UTC m=+225.244527475 End:2018-08-31 12:54:22.593672002 +0000 UTC m=+225.264294121
I0831 12:54:22.593727       1 scheduler.go:454] Total Schedule Algo cumulative time:16.490994622s for 1292
I0831 12:54:22.613576       1 scheduler.go:451] ScheduleAlgoTime 19.727353ms Start:2018-08-31 12:54:22.593838827 +0000 UTC m=+225.264460969 End:2018-08-31 12:54:22.613566202 +0000 UTC m=+225.284188322
I0831 12:54:22.613628       1 scheduler.go:454] Total Schedule Algo cumulative time:16.510721975s for 1293
I0831 12:54:22.634216       1 scheduler.go:451] ScheduleAlgoTime 20.443091ms Start:2018-08-31 12:54:22.613763359 +0000 UTC m=+225.284385550 End:2018-08-31 12:54:22.634206521 +0000 UTC m=+225.304828641
I0831 12:54:22.634273       1 scheduler.go:454] Total Schedule Algo cumulative time:16.531165066s for 1294
I0831 12:54:22.655252       1 scheduler.go:451] ScheduleAlgoTime 20.86262ms Start:2018-08-31 12:54:22.634380234 +0000 UTC m=+225.305002383 End:2018-08-31 12:54:22.655242883 +0000 UTC m=+225.325865003
I0831 12:54:22.655293       1 scheduler.go:454] Total Schedule Algo cumulative time:16.552027686s for 1295
